2016-08-21 14:51:16,548 INFO org.apache.hadoop.yarn.server.resourcemanager.ResourceManager: STARTUP_MSG: 
/************************************************************
STARTUP_MSG: Starting ResourceManager
STARTUP_MSG:   host = nm.yarn-perf.yarnrm-pg0.wisc.cloudlab.us/128.104.222.71
STARTUP_MSG:   args = []
STARTUP_MSG:   version = 2.7.2
STARTUP_MSG:   build = https://github.com/lenhattan86/ccra -r 16f5bdcdc9cf7fbc099e2d9480eaf286876f593e; compiled by 'tan' on 2016-08-21T20:29Z
STARTUP_MSG:   java = 1.7.0_80
************************************************************/
2016-08-21 14:51:16,563 INFO org.apache.hadoop.yarn.server.resourcemanager.ResourceManager: registered UNIX signal handlers for [TERM, HUP, INT]
2016-08-21 14:51:16,942 INFO org.apache.hadoop.conf.Configuration: found resource core-site.xml at file:/users/tanle/hadoop/etc/hadoop/core-site.xml
2016-08-21 14:51:17,050 WARN org.apache.hadoop.util.NativeCodeLoader: Unable to load native-hadoop library for your platform... using builtin-java classes where applicable
2016-08-21 14:51:17,086 INFO org.apache.hadoop.security.Groups: clearing userToGroupsMap cache
2016-08-21 14:51:17,167 INFO org.apache.hadoop.conf.Configuration: found resource yarn-site.xml at file:/users/tanle/hadoop/etc/hadoop/yarn-site.xml
2016-08-21 14:51:17,377 INFO org.apache.hadoop.yarn.event.AsyncDispatcher: Registering class org.apache.hadoop.yarn.server.resourcemanager.RMFatalEventType for class org.apache.hadoop.yarn.server.resourcemanager.ResourceManager$RMFatalEventDispatcher
2016-08-21 14:51:17,540 INFO org.apache.hadoop.yarn.server.resourcemanager.security.NMTokenSecretManagerInRM: NMTokenKeyRollingInterval: 86400000ms and NMTokenKeyActivationDelay: 900000ms
2016-08-21 14:51:17,544 INFO org.apache.hadoop.yarn.server.resourcemanager.security.RMContainerTokenSecretManager: ContainerTokenKeyRollingInterval: 86400000ms and ContainerTokenKeyActivationDelay: 900000ms
2016-08-21 14:51:17,551 INFO org.apache.hadoop.yarn.server.resourcemanager.security.AMRMTokenSecretManager: AMRMTokenKeyRollingInterval: 86400000ms and AMRMTokenKeyActivationDelay: 900000 ms
2016-08-21 14:51:17,603 INFO org.apache.hadoop.yarn.event.AsyncDispatcher: Registering class org.apache.hadoop.yarn.server.resourcemanager.recovery.RMStateStoreEventType for class org.apache.hadoop.yarn.server.resourcemanager.recovery.RMStateStore$ForwardingEventHandler
2016-08-21 14:51:17,605 INFO org.apache.hadoop.yarn.event.AsyncDispatcher: Registering class org.apache.hadoop.yarn.server.resourcemanager.NodesListManagerEventType for class org.apache.hadoop.yarn.server.resourcemanager.NodesListManager
2016-08-21 14:51:17,605 INFO org.apache.hadoop.yarn.server.resourcemanager.ResourceManager: Using Scheduler: org.apache.hadoop.yarn.server.resourcemanager.scheduler.fair.FairScheduler
2016-08-21 14:51:17,644 INFO org.apache.hadoop.yarn.event.AsyncDispatcher: Registering class org.apache.hadoop.yarn.server.resourcemanager.scheduler.event.SchedulerEventType for class org.apache.hadoop.yarn.server.resourcemanager.ResourceManager$SchedulerEventDispatcher
2016-08-21 14:51:17,645 INFO org.apache.hadoop.yarn.event.AsyncDispatcher: Registering class org.apache.hadoop.yarn.server.resourcemanager.rmapp.RMAppEventType for class org.apache.hadoop.yarn.server.resourcemanager.ResourceManager$ApplicationEventDispatcher
2016-08-21 14:51:17,647 INFO org.apache.hadoop.yarn.event.AsyncDispatcher: Registering class org.apache.hadoop.yarn.server.resourcemanager.rmapp.attempt.RMAppAttemptEventType for class org.apache.hadoop.yarn.server.resourcemanager.ResourceManager$ApplicationAttemptEventDispatcher
2016-08-21 14:51:17,648 INFO org.apache.hadoop.yarn.event.AsyncDispatcher: Registering class org.apache.hadoop.yarn.server.resourcemanager.rmnode.RMNodeEventType for class org.apache.hadoop.yarn.server.resourcemanager.ResourceManager$NodeEventDispatcher
2016-08-21 14:51:17,719 INFO org.apache.hadoop.metrics2.impl.MetricsConfig: loaded properties from hadoop-metrics2.properties
2016-08-21 14:51:17,776 INFO org.apache.hadoop.metrics2.impl.MetricsSystemImpl: Scheduled snapshot period at 10 second(s).
2016-08-21 14:51:17,776 INFO org.apache.hadoop.metrics2.impl.MetricsSystemImpl: ResourceManager metrics system started
2016-08-21 14:51:17,791 INFO org.apache.hadoop.yarn.event.AsyncDispatcher: Registering class org.apache.hadoop.yarn.server.resourcemanager.RMAppManagerEventType for class org.apache.hadoop.yarn.server.resourcemanager.RMAppManager
2016-08-21 14:51:17,799 INFO org.apache.hadoop.yarn.event.AsyncDispatcher: Registering class org.apache.hadoop.yarn.server.resourcemanager.amlauncher.AMLauncherEventType for class org.apache.hadoop.yarn.server.resourcemanager.amlauncher.ApplicationMasterLauncher
2016-08-21 14:51:17,801 INFO org.apache.hadoop.yarn.server.resourcemanager.RMNMInfo: Registered RMNMInfo MBean
2016-08-21 14:51:17,803 INFO org.apache.hadoop.yarn.security.YarnAuthorizationProvider: org.apache.hadoop.yarn.security.ConfiguredYarnAuthorizer is instiantiated.
2016-08-21 14:51:17,804 INFO org.apache.hadoop.util.HostsFileReader: Refreshing hosts (include/exclude) list
2016-08-21 14:51:17,844 INFO org.apache.hadoop.yarn.server.resourcemanager.scheduler.fair.AllocationFileLoaderService: Loading allocation file /users/tanle/hadoop/etc/fair-scheduler.xml
2016-08-21 14:51:17,891 INFO org.apache.hadoop.yarn.server.resourcemanager.metrics.SystemMetricsPublisher: YARN system metrics publishing service is not enabled
2016-08-21 14:51:17,891 INFO org.apache.hadoop.yarn.server.resourcemanager.ResourceManager: Transitioning to active state
2016-08-21 14:51:17,904 INFO org.apache.hadoop.yarn.server.resourcemanager.recovery.RMStateStore: Updating AMRMToken
2016-08-21 14:51:17,904 INFO org.apache.hadoop.yarn.server.resourcemanager.security.RMContainerTokenSecretManager: Rolling master-key for container-tokens
2016-08-21 14:51:17,905 INFO org.apache.hadoop.yarn.server.resourcemanager.security.NMTokenSecretManagerInRM: Rolling master-key for nm-tokens
2016-08-21 14:51:17,905 INFO org.apache.hadoop.security.token.delegation.AbstractDelegationTokenSecretManager: Updating the current master key for generating delegation tokens
2016-08-21 14:51:17,905 INFO org.apache.hadoop.yarn.server.resourcemanager.security.RMDelegationTokenSecretManager: storing master key with keyID 1
2016-08-21 14:51:17,905 INFO org.apache.hadoop.yarn.server.resourcemanager.recovery.RMStateStore: Storing RMDTMasterKey.
2016-08-21 14:51:17,907 INFO org.apache.hadoop.security.token.delegation.AbstractDelegationTokenSecretManager: Starting expired delegation token remover thread, tokenRemoverScanInterval=60 min(s)
2016-08-21 14:51:17,907 INFO org.apache.hadoop.security.token.delegation.AbstractDelegationTokenSecretManager: Updating the current master key for generating delegation tokens
2016-08-21 14:51:17,907 INFO org.apache.hadoop.yarn.server.resourcemanager.security.RMDelegationTokenSecretManager: storing master key with keyID 2
2016-08-21 14:51:17,907 INFO org.apache.hadoop.yarn.server.resourcemanager.recovery.RMStateStore: Storing RMDTMasterKey.
2016-08-21 14:51:17,909 INFO org.apache.hadoop.yarn.event.AsyncDispatcher: Registering class org.apache.hadoop.yarn.nodelabels.event.NodeLabelsStoreEventType for class org.apache.hadoop.yarn.nodelabels.CommonNodeLabelsManager$ForwardingEventHandler
2016-08-21 14:51:17,938 INFO org.apache.hadoop.ipc.CallQueueManager: Using callQueue class java.util.concurrent.LinkedBlockingQueue
2016-08-21 14:51:17,949 INFO org.apache.hadoop.ipc.Server: Starting Socket Reader #1 for port 8031
2016-08-21 14:51:17,965 INFO org.apache.hadoop.yarn.factories.impl.pb.RpcServerFactoryPBImpl: Adding protocol org.apache.hadoop.yarn.server.api.ResourceTrackerPB to the server
2016-08-21 14:51:17,966 INFO org.apache.hadoop.ipc.Server: IPC Server Responder: starting
2016-08-21 14:51:17,966 INFO org.apache.hadoop.ipc.Server: IPC Server listener on 8031: starting
2016-08-21 14:51:18,039 INFO org.apache.hadoop.ipc.CallQueueManager: Using callQueue class java.util.concurrent.LinkedBlockingQueue
2016-08-21 14:51:18,049 INFO org.apache.hadoop.ipc.Server: Starting Socket Reader #1 for port 8030
2016-08-21 14:51:18,060 INFO org.apache.hadoop.yarn.factories.impl.pb.RpcServerFactoryPBImpl: Adding protocol org.apache.hadoop.yarn.api.ApplicationMasterProtocolPB to the server
2016-08-21 14:51:18,060 INFO org.apache.hadoop.ipc.Server: IPC Server Responder: starting
2016-08-21 14:51:18,060 INFO org.apache.hadoop.ipc.Server: IPC Server listener on 8030: starting
2016-08-21 14:51:18,143 INFO org.apache.hadoop.ipc.CallQueueManager: Using callQueue class java.util.concurrent.LinkedBlockingQueue
2016-08-21 14:51:18,144 INFO org.apache.hadoop.ipc.Server: Starting Socket Reader #1 for port 8032
2016-08-21 14:51:18,149 INFO org.apache.hadoop.yarn.factories.impl.pb.RpcServerFactoryPBImpl: Adding protocol org.apache.hadoop.yarn.api.ApplicationClientProtocolPB to the server
2016-08-21 14:51:18,149 INFO org.apache.hadoop.ipc.Server: IPC Server Responder: starting
2016-08-21 14:51:18,150 INFO org.apache.hadoop.ipc.Server: IPC Server listener on 8032: starting
2016-08-21 14:51:18,158 INFO org.apache.hadoop.yarn.server.resourcemanager.ResourceManager: Transitioned to active state
2016-08-21 14:51:18,271 INFO org.mortbay.log: Logging to org.slf4j.impl.Log4jLoggerAdapter(org.mortbay.log) via org.mortbay.log.Slf4jLog
2016-08-21 14:51:18,280 INFO org.apache.hadoop.security.authentication.server.AuthenticationFilter: Unable to initialize FileSignerSecretProvider, falling back to use random secrets.
2016-08-21 14:51:18,285 INFO org.apache.hadoop.http.HttpRequestLog: Http request log for http.requests.resourcemanager is not defined
2016-08-21 14:51:18,293 INFO org.apache.hadoop.http.HttpServer2: Added global filter 'safety' (class=org.apache.hadoop.http.HttpServer2$QuotingInputFilter)
2016-08-21 14:51:18,297 INFO org.apache.hadoop.http.HttpServer2: Added filter RMAuthenticationFilter (class=org.apache.hadoop.yarn.server.security.http.RMAuthenticationFilter) to context cluster
2016-08-21 14:51:18,297 INFO org.apache.hadoop.http.HttpServer2: Added filter RMAuthenticationFilter (class=org.apache.hadoop.yarn.server.security.http.RMAuthenticationFilter) to context logs
2016-08-21 14:51:18,297 INFO org.apache.hadoop.http.HttpServer2: Added filter RMAuthenticationFilter (class=org.apache.hadoop.yarn.server.security.http.RMAuthenticationFilter) to context static
2016-08-21 14:51:18,297 INFO org.apache.hadoop.http.HttpServer2: Added filter static_user_filter (class=org.apache.hadoop.http.lib.StaticUserWebFilter$StaticUserFilter) to context cluster
2016-08-21 14:51:18,298 INFO org.apache.hadoop.http.HttpServer2: Added filter static_user_filter (class=org.apache.hadoop.http.lib.StaticUserWebFilter$StaticUserFilter) to context logs
2016-08-21 14:51:18,298 INFO org.apache.hadoop.http.HttpServer2: Added filter static_user_filter (class=org.apache.hadoop.http.lib.StaticUserWebFilter$StaticUserFilter) to context static
2016-08-21 14:51:18,301 INFO org.apache.hadoop.http.HttpServer2: adding path spec: /cluster/*
2016-08-21 14:51:18,302 INFO org.apache.hadoop.http.HttpServer2: adding path spec: /ws/*
2016-08-21 14:51:18,637 INFO org.apache.hadoop.yarn.webapp.WebApps: Registered webapp guice modules
2016-08-21 14:51:18,639 INFO org.apache.hadoop.http.HttpServer2: Jetty bound to port 8088
2016-08-21 14:51:18,639 INFO org.mortbay.log: jetty-6.1.26
2016-08-21 14:51:18,663 INFO org.mortbay.log: Extract jar:file:/users/tanle/hadoop/share/hadoop/yarn/hadoop-yarn-common-2.7.2.jar!/webapps/cluster to /tmp/Jetty_nm_yarn.perf_yarnrm.pg0_wisc_cloudlab_us_8088_cluster____.pro683/webapp
2016-08-21 14:51:18,867 INFO org.apache.hadoop.security.token.delegation.AbstractDelegationTokenSecretManager: Updating the current master key for generating delegation tokens
2016-08-21 14:51:18,868 INFO org.apache.hadoop.security.token.delegation.AbstractDelegationTokenSecretManager: Starting expired delegation token remover thread, tokenRemoverScanInterval=60 min(s)
2016-08-21 14:51:18,868 INFO org.apache.hadoop.security.token.delegation.AbstractDelegationTokenSecretManager: Updating the current master key for generating delegation tokens
2016-08-21 14:51:19,619 INFO org.mortbay.log: Started HttpServer2$SelectChannelConnectorWithSafeStartup@nm.yarn-perf.yarnrm-pg0.wisc.cloudlab.us:8088
2016-08-21 14:51:19,620 INFO org.apache.hadoop.yarn.webapp.WebApps: Web app cluster started at 8088
2016-08-21 14:51:19,637 INFO org.apache.hadoop.ipc.CallQueueManager: Using callQueue class java.util.concurrent.LinkedBlockingQueue
2016-08-21 14:51:19,637 INFO org.apache.hadoop.ipc.Server: Starting Socket Reader #1 for port 8033
2016-08-21 14:51:19,639 INFO org.apache.hadoop.yarn.factories.impl.pb.RpcServerFactoryPBImpl: Adding protocol org.apache.hadoop.yarn.server.api.ResourceManagerAdministrationProtocolPB to the server
2016-08-21 14:51:19,639 INFO org.apache.hadoop.ipc.Server: IPC Server Responder: starting
2016-08-21 14:51:19,640 INFO org.apache.hadoop.ipc.Server: IPC Server listener on 8033: starting
2016-08-21 14:51:21,655 INFO org.apache.hadoop.yarn.util.RackResolver: Resolved c220g1-031106.wisc.cloudlab.us to /default-rack
2016-08-21 14:51:21,655 INFO org.apache.hadoop.yarn.util.RackResolver: Resolved cp-1.yarn-perf.yarnrm-PG0.wisc.cloudlab.us to /default-rack
2016-08-21 14:51:21,658 INFO org.apache.hadoop.yarn.server.resourcemanager.ResourceTrackerService: NodeManager from node c220g1-031106.wisc.cloudlab.us(cmPort: 33388 httpPort: 8042) registered with capability: <memory:8192, vCores:4>, assigned nodeId c220g1-031106.wisc.cloudlab.us:33388
2016-08-21 14:51:21,658 INFO org.apache.hadoop.yarn.server.resourcemanager.ResourceTrackerService: NodeManager from node cp-1.yarn-perf.yarnrm-PG0.wisc.cloudlab.us(cmPort: 39022 httpPort: 8042) registered with capability: <memory:8192, vCores:4>, assigned nodeId cp-1.yarn-perf.yarnrm-PG0.wisc.cloudlab.us:39022
2016-08-21 14:51:21,661 INFO org.apache.hadoop.yarn.server.resourcemanager.rmnode.RMNodeImpl: c220g1-031106.wisc.cloudlab.us:33388 Node Transitioned from NEW to RUNNING
2016-08-21 14:51:21,661 INFO org.apache.hadoop.yarn.server.resourcemanager.rmnode.RMNodeImpl: cp-1.yarn-perf.yarnrm-PG0.wisc.cloudlab.us:39022 Node Transitioned from NEW to RUNNING
2016-08-21 14:51:21,667 INFO org.apache.hadoop.yarn.server.resourcemanager.scheduler.fair.FairScheduler: Added node c220g1-031106.wisc.cloudlab.us:33388 cluster capacity: <memory:8192, vCores:4>
2016-08-21 14:51:21,670 INFO org.apache.hadoop.yarn.server.resourcemanager.scheduler.fair.FairScheduler: Added node cp-1.yarn-perf.yarnrm-PG0.wisc.cloudlab.us:39022 cluster capacity: <memory:16384, vCores:8>
2016-08-21 14:53:01,186 INFO org.apache.hadoop.yarn.server.resourcemanager.ClientRMService: Allocated new applicationId: 1
2016-08-21 14:53:10,917 WARN org.apache.hadoop.yarn.server.resourcemanager.rmapp.RMAppImpl: The specific max attempts: 0 for application: 1 is invalid, because it is out of the range [1, 2]. Use the global max attempts instead.
2016-08-21 14:53:10,918 INFO org.apache.hadoop.yarn.server.resourcemanager.ClientRMService: Application with id 1 submitted by user tanle
2016-08-21 14:53:10,919 INFO org.apache.hadoop.yarn.server.resourcemanager.rmapp.RMAppImpl: Storing application with id application_1471812677892_0001
2016-08-21 14:53:10,920 INFO org.apache.hadoop.yarn.server.resourcemanager.RMAuditLogger: USER=tanle	IP=128.104.222.71	OPERATION=Submit Application Request	TARGET=ClientRMService	RESULT=SUCCESS	APPID=application_1471812677892_0001
2016-08-21 14:53:10,931 INFO org.apache.hadoop.yarn.server.resourcemanager.recovery.RMStateStore: Storing info for app: application_1471812677892_0001
2016-08-21 14:53:10,944 INFO org.apache.hadoop.yarn.server.resourcemanager.scheduler.fair.FairScheduler: Accepted application application_1471812677892_0001 from user: tanle, in queue: batch, currently num of applications: 1
2016-08-21 14:53:11,011 INFO org.apache.hadoop.yarn.server.resourcemanager.ApplicationMasterService: Registering app attempt : appattempt_1471812677892_0001_000001
2016-08-21 14:53:11,012 INFO org.apache.hadoop.yarn.server.resourcemanager.rmapp.attempt.RMAppAttemptImpl: appattempt_1471812677892_0001_000001 State change from NEW to SUBMITTED
2016-08-21 14:53:11,035 INFO org.apache.hadoop.yarn.server.resourcemanager.scheduler.fair.FairScheduler: Added Application Attempt appattempt_1471812677892_0001_000001 to scheduler from user: tanle
2016-08-21 14:53:11,035 INFO org.apache.hadoop.yarn.server.resourcemanager.rmapp.attempt.RMAppAttemptImpl: ScheduleTransition.transition(appattempt_1471812677892_0001_000001,EventType: ATTEMPT_ADDED)
2016-08-21 14:53:11,036 INFO org.apache.hadoop.yarn.server.resourcemanager.scheduler.fair.FairScheduler: allocate(appattempt_1471812677892_0001_000001 [{Priority: 0, Capability: <memory:2048, vCores:1>, # Containers: 1, Location: *, Relax Locality: true}] [] null null
2016-08-21 14:53:11,036 INFO org.apache.hadoop.yarn.server.resourcemanager.scheduler.fair.FSAppAttempt: appattempt_1471812677892_0001_000001 minReqResource: <memory:0, vCores:0> flexibleResource: <memory:16384, vCores:8>
2016-08-21 14:53:11,037 INFO org.apache.hadoop.yarn.server.resourcemanager.scheduler.fair.FairScheduler: allocate resource to application attempt: appattempt_1471812677892_0001_000001 queue:root.batch isRunning=true 
2016-08-21 14:53:11,039 INFO org.apache.hadoop.yarn.server.resourcemanager.scheduler.fair.FairScheduler: iglf: 1.getHeadroom()=<memory:0, vCores:0>
2016-08-21 14:53:11,039 INFO org.apache.hadoop.yarn.server.resourcemanager.rmapp.attempt.RMAppAttemptImpl: appattempt_1471812677892_0001_000001 State change from SUBMITTED to SCHEDULED
2016-08-21 14:53:11,106 INFO org.apache.hadoop.yarn.server.resourcemanager.scheduler.fair.FSAppAttempt: assignContainer(FSSchedulerNode node:c220g1-031106.wisc.cloudlab.us, boolean reserved=false) for appattempt_1471812677892_0001_000001
2016-08-21 14:53:11,107 INFO org.apache.hadoop.yarn.server.resourcemanager.scheduler.fair.FSAppAttempt: assignContainer(FSSchedulerNode:c220g1-031106.wisc.cloudlab.us, ResourceRequest request, NodeType type, boolean reserved=false
2016-08-21 14:53:11,123 INFO org.apache.hadoop.yarn.server.resourcemanager.scheduler.fair.FSAppAttempt: allocate container: container_1471812677892_0001_01_000001 priority 0
2016-08-21 14:53:11,137 INFO org.apache.hadoop.yarn.server.resourcemanager.rmcontainer.RMContainerImpl: Processing container_1471812677892_0001_01_000001 of event START
2016-08-21 14:53:11,137 INFO org.apache.hadoop.yarn.server.resourcemanager.rmcontainer.RMContainerImpl: container_1471812677892_0001_01_000001 Container Transitioned from NEW to ALLOCATED
2016-08-21 14:53:11,137 INFO org.apache.hadoop.yarn.server.resourcemanager.RMAuditLogger: USER=tanle	OPERATION=AM Allocated Container	TARGET=SchedulerApp	RESULT=SUCCESS	APPID=application_1471812677892_0001	CONTAINERID=container_1471812677892_0001_01_000001
2016-08-21 14:53:11,137 INFO org.apache.hadoop.yarn.server.resourcemanager.rmapp.attempt.RMAppAttemptImpl: AMContainerAllocatedTransition.transition(appattempt_1471812677892_0001_000001,EventType: CONTAINER_ALLOCATED)
2016-08-21 14:53:11,137 INFO org.apache.hadoop.yarn.server.resourcemanager.scheduler.SchedulerNode: Assigned container container_1471812677892_0001_01_000001 of capacity <memory:2048, vCores:1> on host c220g1-031106.wisc.cloudlab.us:33388, which has 1 containers, <memory:2048, vCores:1> used and <memory:6144, vCores:3> available after allocation
2016-08-21 14:53:11,137 INFO org.apache.hadoop.yarn.server.resourcemanager.scheduler.fair.FairScheduler: allocate(appattempt_1471812677892_0001_000001 [] [] null null
2016-08-21 14:53:11,138 INFO org.apache.hadoop.yarn.server.resourcemanager.scheduler.fair.FSAppAttempt: root.batch: <memory:2048, vCores:1>
2016-08-21 14:53:11,138 INFO org.apache.hadoop.yarn.server.resourcemanager.scheduler.fair.FSAppAttempt: appattempt_1471812677892_0001_000001 minReqResource: <memory:0, vCores:0> flexibleResource: <memory:16384, vCores:8>
2016-08-21 14:53:11,138 INFO org.apache.hadoop.yarn.server.resourcemanager.scheduler.fair.FairScheduler: allocate resource to application attempt: appattempt_1471812677892_0001_000001 queue:root.batch isRunning=true 
2016-08-21 14:53:11,138 INFO org.apache.hadoop.yarn.server.resourcemanager.scheduler.fair.FSAppAttempt: assignContainer(FSSchedulerNode node:cp-1.yarn-perf.yarnrm-PG0.wisc.cloudlab.us, boolean reserved=false) for appattempt_1471812677892_0001_000001
2016-08-21 14:53:11,167 INFO org.apache.hadoop.yarn.server.resourcemanager.security.NMTokenSecretManagerInRM: Sending NMToken for nodeId : c220g1-031106.wisc.cloudlab.us:33388 for container : container_1471812677892_0001_01_000001
2016-08-21 14:53:11,180 INFO org.apache.hadoop.yarn.server.resourcemanager.rmcontainer.RMContainerImpl: Processing container_1471812677892_0001_01_000001 of event ACQUIRED
2016-08-21 14:53:11,181 INFO org.apache.hadoop.yarn.server.resourcemanager.rmcontainer.RMContainerImpl: container_1471812677892_0001_01_000001 Container Transitioned from ALLOCATED to ACQUIRED
2016-08-21 14:53:11,181 INFO org.apache.hadoop.yarn.server.resourcemanager.scheduler.fair.FairScheduler: iglf: 1.getHeadroom()=<memory:14336, vCores:7>
2016-08-21 14:53:11,181 INFO org.apache.hadoop.yarn.server.resourcemanager.security.NMTokenSecretManagerInRM: Clear node set for appattempt_1471812677892_0001_000001
2016-08-21 14:53:11,186 INFO org.apache.hadoop.yarn.server.resourcemanager.rmapp.attempt.RMAppAttemptImpl: Storing attempt: AppId: application_1471812677892_0001 AttemptId: appattempt_1471812677892_0001_000001 MasterContainer: Container: [ContainerId: container_1471812677892_0001_01_000001, NodeId: c220g1-031106.wisc.cloudlab.us:33388, NodeHttpAddress: c220g1-031106.wisc.cloudlab.us:8042, Resource: <memory:2048, vCores:1>, Priority: 0, Token: Token { kind: ContainerToken, service: 128.104.222.16:33388 }, ]
2016-08-21 14:53:11,202 INFO org.apache.hadoop.yarn.server.resourcemanager.rmapp.attempt.RMAppAttemptImpl: appattempt_1471812677892_0001_000001 State change from SCHEDULED to ALLOCATED_SAVING
2016-08-21 14:53:11,204 INFO org.apache.hadoop.yarn.server.resourcemanager.rmapp.attempt.RMAppAttemptImpl: appattempt_1471812677892_0001_000001 State change from ALLOCATED_SAVING to ALLOCATED
2016-08-21 14:53:11,208 INFO org.apache.hadoop.yarn.server.resourcemanager.amlauncher.AMLauncher: Launching masterappattempt_1471812677892_0001_000001
2016-08-21 14:53:11,261 INFO org.apache.hadoop.yarn.server.resourcemanager.amlauncher.AMLauncher: Setting up container Container: [ContainerId: container_1471812677892_0001_01_000001, NodeId: c220g1-031106.wisc.cloudlab.us:33388, NodeHttpAddress: c220g1-031106.wisc.cloudlab.us:8042, Resource: <memory:2048, vCores:1>, Priority: 0, Token: Token { kind: ContainerToken, service: 128.104.222.16:33388 }, ] for AM appattempt_1471812677892_0001_000001
2016-08-21 14:53:11,262 INFO org.apache.hadoop.yarn.server.resourcemanager.amlauncher.AMLauncher: Command to launch container container_1471812677892_0001_01_000001 : {{JAVA_HOME}}/bin/java,-server,-Xmx1536m,-Djava.io.tmpdir={{PWD}}/tmp,-Dspark.yarn.app.container.log.dir=<LOG_DIR>,-XX:MaxPermSize=256m,org.apache.spark.deploy.yarn.ApplicationMaster,--class,'org.apache.spark.examples.SparkPi',--jar,file:/users/tanle/./spark/examples/jars/spark-examples_2.11-2.0.0-preview.jar,--arg,'10000',--properties-file,{{PWD}}/__spark_conf__/__spark_conf__.properties,1>,<LOG_DIR>/stdout,2>,<LOG_DIR>/stderr
2016-08-21 14:53:11,264 INFO org.apache.hadoop.yarn.server.resourcemanager.security.AMRMTokenSecretManager: Create AMRMToken for ApplicationAttempt: appattempt_1471812677892_0001_000001
2016-08-21 14:53:11,268 INFO org.apache.hadoop.yarn.server.resourcemanager.security.AMRMTokenSecretManager: Creating password for appattempt_1471812677892_0001_000001
2016-08-21 14:53:11,662 INFO org.apache.hadoop.yarn.server.resourcemanager.amlauncher.AMLauncher: Done launching container Container: [ContainerId: container_1471812677892_0001_01_000001, NodeId: c220g1-031106.wisc.cloudlab.us:33388, NodeHttpAddress: c220g1-031106.wisc.cloudlab.us:8042, Resource: <memory:2048, vCores:1>, Priority: 0, Token: Token { kind: ContainerToken, service: 128.104.222.16:33388 }, ] for AM appattempt_1471812677892_0001_000001
2016-08-21 14:53:11,663 INFO org.apache.hadoop.yarn.server.resourcemanager.rmapp.attempt.RMAppAttemptImpl: appattempt_1471812677892_0001_000001 State change from ALLOCATED to LAUNCHED
2016-08-21 14:53:12,107 INFO org.apache.hadoop.yarn.server.resourcemanager.scheduler.fair.FSAppAttempt: assignContainer(FSSchedulerNode node:cp-1.yarn-perf.yarnrm-PG0.wisc.cloudlab.us, boolean reserved=false) for appattempt_1471812677892_0001_000001
2016-08-21 14:53:12,123 INFO org.apache.hadoop.yarn.server.resourcemanager.rmcontainer.RMContainerImpl: Processing container_1471812677892_0001_01_000001 of event LAUNCHED
2016-08-21 14:53:12,123 INFO org.apache.hadoop.yarn.server.resourcemanager.rmcontainer.RMContainerImpl: container_1471812677892_0001_01_000001 Container Transitioned from ACQUIRED to RUNNING
2016-08-21 14:53:12,124 INFO org.apache.hadoop.yarn.server.resourcemanager.scheduler.fair.FSAppAttempt: assignContainer(FSSchedulerNode node:c220g1-031106.wisc.cloudlab.us, boolean reserved=false) for appattempt_1471812677892_0001_000001
2016-08-21 14:53:13,110 INFO org.apache.hadoop.yarn.server.resourcemanager.scheduler.fair.FSAppAttempt: assignContainer(FSSchedulerNode node:cp-1.yarn-perf.yarnrm-PG0.wisc.cloudlab.us, boolean reserved=false) for appattempt_1471812677892_0001_000001
2016-08-21 14:53:13,124 INFO org.apache.hadoop.yarn.server.resourcemanager.scheduler.fair.FSAppAttempt: assignContainer(FSSchedulerNode node:c220g1-031106.wisc.cloudlab.us, boolean reserved=false) for appattempt_1471812677892_0001_000001
2016-08-21 14:53:14,113 INFO org.apache.hadoop.yarn.server.resourcemanager.scheduler.fair.FSAppAttempt: assignContainer(FSSchedulerNode node:cp-1.yarn-perf.yarnrm-PG0.wisc.cloudlab.us, boolean reserved=false) for appattempt_1471812677892_0001_000001
2016-08-21 14:53:14,127 INFO org.apache.hadoop.yarn.server.resourcemanager.scheduler.fair.FSAppAttempt: assignContainer(FSSchedulerNode node:c220g1-031106.wisc.cloudlab.us, boolean reserved=false) for appattempt_1471812677892_0001_000001
2016-08-21 14:53:15,116 INFO org.apache.hadoop.yarn.server.resourcemanager.scheduler.fair.FSAppAttempt: assignContainer(FSSchedulerNode node:cp-1.yarn-perf.yarnrm-PG0.wisc.cloudlab.us, boolean reserved=false) for appattempt_1471812677892_0001_000001
2016-08-21 14:53:15,130 INFO org.apache.hadoop.yarn.server.resourcemanager.scheduler.fair.FSAppAttempt: assignContainer(FSSchedulerNode node:c220g1-031106.wisc.cloudlab.us, boolean reserved=false) for appattempt_1471812677892_0001_000001
2016-08-21 14:53:16,119 INFO org.apache.hadoop.yarn.server.resourcemanager.scheduler.fair.FSAppAttempt: assignContainer(FSSchedulerNode node:cp-1.yarn-perf.yarnrm-PG0.wisc.cloudlab.us, boolean reserved=false) for appattempt_1471812677892_0001_000001
2016-08-21 14:53:16,133 INFO org.apache.hadoop.yarn.server.resourcemanager.scheduler.fair.FSAppAttempt: assignContainer(FSSchedulerNode node:c220g1-031106.wisc.cloudlab.us, boolean reserved=false) for appattempt_1471812677892_0001_000001
2016-08-21 14:53:17,123 INFO org.apache.hadoop.yarn.server.resourcemanager.scheduler.fair.FSAppAttempt: assignContainer(FSSchedulerNode node:cp-1.yarn-perf.yarnrm-PG0.wisc.cloudlab.us, boolean reserved=false) for appattempt_1471812677892_0001_000001
2016-08-21 14:53:17,136 INFO org.apache.hadoop.yarn.server.resourcemanager.scheduler.fair.FSAppAttempt: assignContainer(FSSchedulerNode node:c220g1-031106.wisc.cloudlab.us, boolean reserved=false) for appattempt_1471812677892_0001_000001
2016-08-21 14:53:18,125 INFO org.apache.hadoop.yarn.server.resourcemanager.scheduler.fair.FSAppAttempt: assignContainer(FSSchedulerNode node:cp-1.yarn-perf.yarnrm-PG0.wisc.cloudlab.us, boolean reserved=false) for appattempt_1471812677892_0001_000001
2016-08-21 14:53:18,139 INFO org.apache.hadoop.yarn.server.resourcemanager.scheduler.fair.FSAppAttempt: assignContainer(FSSchedulerNode node:c220g1-031106.wisc.cloudlab.us, boolean reserved=false) for appattempt_1471812677892_0001_000001
2016-08-21 14:53:19,105 INFO SecurityLogger.org.apache.hadoop.ipc.Server: Auth successful for appattempt_1471812677892_0001_000001 (auth:SIMPLE)
2016-08-21 14:53:19,114 INFO org.apache.hadoop.yarn.server.resourcemanager.ApplicationMasterService: AM registration appattempt_1471812677892_0001_000001
2016-08-21 14:53:19,116 INFO org.apache.hadoop.yarn.server.resourcemanager.RMAuditLogger: USER=tanle	IP=128.104.222.16	OPERATION=Register App Master	TARGET=ApplicationMasterService	RESULT=SUCCESS	APPID=application_1471812677892_0001	APPATTEMPTID=appattempt_1471812677892_0001_000001
2016-08-21 14:53:19,116 INFO org.apache.hadoop.yarn.server.resourcemanager.rmapp.attempt.RMAppAttemptImpl: appattempt_1471812677892_0001_000001 State change from LAUNCHED to RUNNING
2016-08-21 14:53:19,128 INFO org.apache.hadoop.yarn.server.resourcemanager.scheduler.fair.FSAppAttempt: assignContainer(FSSchedulerNode node:cp-1.yarn-perf.yarnrm-PG0.wisc.cloudlab.us, boolean reserved=false) for appattempt_1471812677892_0001_000001
2016-08-21 14:53:19,141 INFO org.apache.hadoop.yarn.server.resourcemanager.scheduler.fair.FSAppAttempt: assignContainer(FSSchedulerNode node:c220g1-031106.wisc.cloudlab.us, boolean reserved=false) for appattempt_1471812677892_0001_000001
2016-08-21 14:53:19,212 INFO org.apache.hadoop.yarn.server.resourcemanager.scheduler.fair.FairScheduler: allocate(appattempt_1471812677892_0001_000001 [] [] [] []
2016-08-21 14:53:19,212 INFO org.apache.hadoop.yarn.server.resourcemanager.scheduler.fair.FSAppAttempt: root.batch: <memory:2048, vCores:1>
2016-08-21 14:53:19,212 INFO org.apache.hadoop.yarn.server.resourcemanager.scheduler.fair.FSAppAttempt: appattempt_1471812677892_0001_000001 minReqResource: <memory:0, vCores:0> flexibleResource: <memory:16384, vCores:8>
2016-08-21 14:53:19,212 INFO org.apache.hadoop.yarn.server.resourcemanager.scheduler.fair.FairScheduler: allocate resource to application attempt: appattempt_1471812677892_0001_000001 queue:root.batch isRunning=true 
2016-08-21 14:53:19,212 INFO org.apache.hadoop.yarn.server.resourcemanager.scheduler.fair.FairScheduler: iglf: 1.getHeadroom()=<memory:14336, vCores:7>
2016-08-21 14:53:19,258 INFO org.apache.hadoop.yarn.server.resourcemanager.scheduler.fair.FairScheduler: allocate(appattempt_1471812677892_0001_000001 [] [] [] []
2016-08-21 14:53:19,258 INFO org.apache.hadoop.yarn.server.resourcemanager.scheduler.fair.FSAppAttempt: root.batch: <memory:2048, vCores:1>
2016-08-21 14:53:19,258 INFO org.apache.hadoop.yarn.server.resourcemanager.scheduler.fair.FSAppAttempt: appattempt_1471812677892_0001_000001 minReqResource: <memory:0, vCores:0> flexibleResource: <memory:16384, vCores:8>
2016-08-21 14:53:19,258 INFO org.apache.hadoop.yarn.server.resourcemanager.scheduler.fair.FairScheduler: allocate resource to application attempt: appattempt_1471812677892_0001_000001 queue:root.batch isRunning=true 
2016-08-21 14:53:19,258 INFO org.apache.hadoop.yarn.server.resourcemanager.scheduler.fair.FairScheduler: iglf: 1.getHeadroom()=<memory:14336, vCores:7>
2016-08-21 14:53:20,131 INFO org.apache.hadoop.yarn.server.resourcemanager.scheduler.fair.FSAppAttempt: assignContainer(FSSchedulerNode node:cp-1.yarn-perf.yarnrm-PG0.wisc.cloudlab.us, boolean reserved=false) for appattempt_1471812677892_0001_000001
2016-08-21 14:53:20,144 INFO org.apache.hadoop.yarn.server.resourcemanager.scheduler.fair.FSAppAttempt: assignContainer(FSSchedulerNode node:c220g1-031106.wisc.cloudlab.us, boolean reserved=false) for appattempt_1471812677892_0001_000001
2016-08-21 14:53:20,935 INFO org.apache.hadoop.yarn.server.resourcemanager.ClientRMService: Allocated new applicationId: 2
2016-08-21 14:53:21,134 INFO org.apache.hadoop.yarn.server.resourcemanager.scheduler.fair.FSAppAttempt: assignContainer(FSSchedulerNode node:cp-1.yarn-perf.yarnrm-PG0.wisc.cloudlab.us, boolean reserved=false) for appattempt_1471812677892_0001_000001
2016-08-21 14:53:21,146 INFO org.apache.hadoop.yarn.server.resourcemanager.scheduler.fair.FSAppAttempt: assignContainer(FSSchedulerNode node:c220g1-031106.wisc.cloudlab.us, boolean reserved=false) for appattempt_1471812677892_0001_000001
2016-08-21 14:53:22,138 INFO org.apache.hadoop.yarn.server.resourcemanager.scheduler.fair.FSAppAttempt: assignContainer(FSSchedulerNode node:cp-1.yarn-perf.yarnrm-PG0.wisc.cloudlab.us, boolean reserved=false) for appattempt_1471812677892_0001_000001
2016-08-21 14:53:22,150 INFO org.apache.hadoop.yarn.server.resourcemanager.scheduler.fair.FSAppAttempt: assignContainer(FSSchedulerNode node:c220g1-031106.wisc.cloudlab.us, boolean reserved=false) for appattempt_1471812677892_0001_000001
2016-08-21 14:53:22,262 INFO org.apache.hadoop.yarn.server.resourcemanager.scheduler.fair.FairScheduler: allocate(appattempt_1471812677892_0001_000001 [] [] [] []
2016-08-21 14:53:22,263 INFO org.apache.hadoop.yarn.server.resourcemanager.scheduler.fair.FSAppAttempt: root.batch: <memory:2048, vCores:1>
2016-08-21 14:53:22,263 INFO org.apache.hadoop.yarn.server.resourcemanager.scheduler.fair.FSAppAttempt: appattempt_1471812677892_0001_000001 minReqResource: <memory:0, vCores:0> flexibleResource: <memory:16384, vCores:8>
2016-08-21 14:53:22,263 INFO org.apache.hadoop.yarn.server.resourcemanager.scheduler.fair.FairScheduler: allocate resource to application attempt: appattempt_1471812677892_0001_000001 queue:root.batch isRunning=true 
2016-08-21 14:53:22,263 INFO org.apache.hadoop.yarn.server.resourcemanager.scheduler.fair.FairScheduler: iglf: 1.getHeadroom()=<memory:14336, vCores:7>
2016-08-21 14:53:23,141 INFO org.apache.hadoop.yarn.server.resourcemanager.scheduler.fair.FSAppAttempt: assignContainer(FSSchedulerNode node:cp-1.yarn-perf.yarnrm-PG0.wisc.cloudlab.us, boolean reserved=false) for appattempt_1471812677892_0001_000001
2016-08-21 14:53:23,153 INFO org.apache.hadoop.yarn.server.resourcemanager.scheduler.fair.FSAppAttempt: assignContainer(FSSchedulerNode node:c220g1-031106.wisc.cloudlab.us, boolean reserved=false) for appattempt_1471812677892_0001_000001
2016-08-21 14:53:24,143 INFO org.apache.hadoop.yarn.server.resourcemanager.scheduler.fair.FSAppAttempt: assignContainer(FSSchedulerNode node:cp-1.yarn-perf.yarnrm-PG0.wisc.cloudlab.us, boolean reserved=false) for appattempt_1471812677892_0001_000001
2016-08-21 14:53:24,155 INFO org.apache.hadoop.yarn.server.resourcemanager.scheduler.fair.FSAppAttempt: assignContainer(FSSchedulerNode node:c220g1-031106.wisc.cloudlab.us, boolean reserved=false) for appattempt_1471812677892_0001_000001
2016-08-21 14:53:25,018 INFO org.apache.hadoop.yarn.server.resourcemanager.scheduler.fair.FairScheduler: allocate(appattempt_1471812677892_0001_000001 [{Priority: 1, Capability: <memory:1920, vCores:1>, # Containers: 1, Location: *, Relax Locality: true}] [] [] []
2016-08-21 14:53:25,018 INFO org.apache.hadoop.yarn.server.resourcemanager.scheduler.fair.FSAppAttempt: root.batch: <memory:2048, vCores:1>
2016-08-21 14:53:25,018 INFO org.apache.hadoop.yarn.server.resourcemanager.scheduler.fair.FSAppAttempt: appattempt_1471812677892_0001_000001 minReqResource: <memory:0, vCores:0> flexibleResource: <memory:16384, vCores:8>
2016-08-21 14:53:25,018 INFO org.apache.hadoop.yarn.server.resourcemanager.scheduler.fair.FairScheduler: allocate resource to application attempt: appattempt_1471812677892_0001_000001 queue:root.batch isRunning=true 
2016-08-21 14:53:25,019 INFO org.apache.hadoop.yarn.server.resourcemanager.scheduler.fair.FairScheduler: iglf: 1.getHeadroom()=<memory:14336, vCores:7>
2016-08-21 14:53:25,146 INFO org.apache.hadoop.yarn.server.resourcemanager.scheduler.fair.FSAppAttempt: assignContainer(FSSchedulerNode node:cp-1.yarn-perf.yarnrm-PG0.wisc.cloudlab.us, boolean reserved=false) for appattempt_1471812677892_0001_000001
2016-08-21 14:53:25,146 INFO org.apache.hadoop.yarn.server.resourcemanager.scheduler.fair.FSAppAttempt: assignContainer(FSSchedulerNode:cp-1.yarn-perf.yarnrm-PG0.wisc.cloudlab.us, ResourceRequest request, NodeType type, boolean reserved=false
2016-08-21 14:53:25,146 INFO org.apache.hadoop.yarn.server.resourcemanager.scheduler.fair.FSAppAttempt: allocate container: container_1471812677892_0001_01_000002 priority 1
2016-08-21 14:53:25,146 INFO org.apache.hadoop.yarn.server.resourcemanager.rmcontainer.RMContainerImpl: Processing container_1471812677892_0001_01_000002 of event START
2016-08-21 14:53:25,146 INFO org.apache.hadoop.yarn.server.resourcemanager.rmcontainer.RMContainerImpl: container_1471812677892_0001_01_000002 Container Transitioned from NEW to ALLOCATED
2016-08-21 14:53:25,147 INFO org.apache.hadoop.yarn.server.resourcemanager.RMAuditLogger: USER=tanle	OPERATION=AM Allocated Container	TARGET=SchedulerApp	RESULT=SUCCESS	APPID=application_1471812677892_0001	CONTAINERID=container_1471812677892_0001_01_000002
2016-08-21 14:53:25,147 INFO org.apache.hadoop.yarn.server.resourcemanager.scheduler.SchedulerNode: Assigned container container_1471812677892_0001_01_000002 of capacity <memory:2048, vCores:1> on host cp-1.yarn-perf.yarnrm-PG0.wisc.cloudlab.us:39022, which has 1 containers, <memory:2048, vCores:1> used and <memory:6144, vCores:3> available after allocation
2016-08-21 14:53:25,158 INFO org.apache.hadoop.yarn.server.resourcemanager.scheduler.fair.FSAppAttempt: assignContainer(FSSchedulerNode node:c220g1-031106.wisc.cloudlab.us, boolean reserved=false) for appattempt_1471812677892_0001_000001
2016-08-21 14:53:25,222 INFO org.apache.hadoop.yarn.server.resourcemanager.scheduler.fair.FairScheduler: allocate(appattempt_1471812677892_0001_000001 [] [] [] []
2016-08-21 14:53:25,222 INFO org.apache.hadoop.yarn.server.resourcemanager.scheduler.fair.FSAppAttempt: root.batch: <memory:4096, vCores:2>
2016-08-21 14:53:25,222 INFO org.apache.hadoop.yarn.server.resourcemanager.scheduler.fair.FSAppAttempt: appattempt_1471812677892_0001_000001 minReqResource: <memory:0, vCores:0> flexibleResource: <memory:16384, vCores:8>
2016-08-21 14:53:25,222 INFO org.apache.hadoop.yarn.server.resourcemanager.scheduler.fair.FairScheduler: allocate resource to application attempt: appattempt_1471812677892_0001_000001 queue:root.batch isRunning=true 
2016-08-21 14:53:25,226 INFO org.apache.hadoop.yarn.server.resourcemanager.security.NMTokenSecretManagerInRM: Sending NMToken for nodeId : cp-1.yarn-perf.yarnrm-PG0.wisc.cloudlab.us:39022 for container : container_1471812677892_0001_01_000002
2016-08-21 14:53:25,228 INFO org.apache.hadoop.yarn.server.resourcemanager.rmcontainer.RMContainerImpl: Processing container_1471812677892_0001_01_000002 of event ACQUIRED
2016-08-21 14:53:25,228 INFO org.apache.hadoop.yarn.server.resourcemanager.rmcontainer.RMContainerImpl: container_1471812677892_0001_01_000002 Container Transitioned from ALLOCATED to ACQUIRED
2016-08-21 14:53:25,228 INFO org.apache.hadoop.yarn.server.resourcemanager.scheduler.fair.FairScheduler: iglf: 1.getHeadroom()=<memory:12288, vCores:6>
2016-08-21 14:53:26,155 INFO org.apache.hadoop.yarn.server.resourcemanager.rmcontainer.RMContainerImpl: Processing container_1471812677892_0001_01_000002 of event LAUNCHED
2016-08-21 14:53:26,155 INFO org.apache.hadoop.yarn.server.resourcemanager.rmcontainer.RMContainerImpl: container_1471812677892_0001_01_000002 Container Transitioned from ACQUIRED to RUNNING
2016-08-21 14:53:26,156 INFO org.apache.hadoop.yarn.server.resourcemanager.scheduler.fair.FSAppAttempt: assignContainer(FSSchedulerNode node:cp-1.yarn-perf.yarnrm-PG0.wisc.cloudlab.us, boolean reserved=false) for appattempt_1471812677892_0001_000001
2016-08-21 14:53:26,161 INFO org.apache.hadoop.yarn.server.resourcemanager.scheduler.fair.FSAppAttempt: assignContainer(FSSchedulerNode node:c220g1-031106.wisc.cloudlab.us, boolean reserved=false) for appattempt_1471812677892_0001_000001
2016-08-21 14:53:27,159 INFO org.apache.hadoop.yarn.server.resourcemanager.scheduler.fair.FSAppAttempt: assignContainer(FSSchedulerNode node:cp-1.yarn-perf.yarnrm-PG0.wisc.cloudlab.us, boolean reserved=false) for appattempt_1471812677892_0001_000001
2016-08-21 14:53:27,164 INFO org.apache.hadoop.yarn.server.resourcemanager.scheduler.fair.FSAppAttempt: assignContainer(FSSchedulerNode node:c220g1-031106.wisc.cloudlab.us, boolean reserved=false) for appattempt_1471812677892_0001_000001
2016-08-21 14:53:28,162 INFO org.apache.hadoop.yarn.server.resourcemanager.scheduler.fair.FSAppAttempt: assignContainer(FSSchedulerNode node:cp-1.yarn-perf.yarnrm-PG0.wisc.cloudlab.us, boolean reserved=false) for appattempt_1471812677892_0001_000001
2016-08-21 14:53:28,167 INFO org.apache.hadoop.yarn.server.resourcemanager.scheduler.fair.FSAppAttempt: assignContainer(FSSchedulerNode node:c220g1-031106.wisc.cloudlab.us, boolean reserved=false) for appattempt_1471812677892_0001_000001
2016-08-21 14:53:28,264 INFO org.apache.hadoop.yarn.server.resourcemanager.scheduler.fair.FairScheduler: allocate(appattempt_1471812677892_0001_000001 [{Priority: 1, Capability: <memory:1920, vCores:1>, # Containers: 0, Location: *, Relax Locality: true}] [] [] []
2016-08-21 14:53:28,264 INFO org.apache.hadoop.yarn.server.resourcemanager.scheduler.fair.FSAppAttempt: root.batch: <memory:4096, vCores:2>
2016-08-21 14:53:28,264 INFO org.apache.hadoop.yarn.server.resourcemanager.scheduler.fair.FSAppAttempt: appattempt_1471812677892_0001_000001 minReqResource: <memory:0, vCores:0> flexibleResource: <memory:16384, vCores:8>
2016-08-21 14:53:28,265 INFO org.apache.hadoop.yarn.server.resourcemanager.scheduler.fair.FairScheduler: allocate resource to application attempt: appattempt_1471812677892_0001_000001 queue:root.batch isRunning=true 
2016-08-21 14:53:28,265 INFO org.apache.hadoop.yarn.server.resourcemanager.scheduler.AppSchedulingInfo: checking for deactivate of application :application_1471812677892_0001
2016-08-21 14:53:28,265 INFO org.apache.hadoop.yarn.server.resourcemanager.scheduler.fair.FairScheduler: iglf: 1.getHeadroom()=<memory:12288, vCores:6>
2016-08-21 14:53:29,165 INFO org.apache.hadoop.yarn.server.resourcemanager.scheduler.fair.FSAppAttempt: assignContainer(FSSchedulerNode node:cp-1.yarn-perf.yarnrm-PG0.wisc.cloudlab.us, boolean reserved=false) for appattempt_1471812677892_0001_000001
2016-08-21 14:53:29,170 INFO org.apache.hadoop.yarn.server.resourcemanager.scheduler.fair.FSAppAttempt: assignContainer(FSSchedulerNode node:c220g1-031106.wisc.cloudlab.us, boolean reserved=false) for appattempt_1471812677892_0001_000001
2016-08-21 14:53:29,987 INFO org.apache.hadoop.yarn.server.resourcemanager.scheduler.fair.FairScheduler: allocate(appattempt_1471812677892_0001_000001 [{Priority: 1, Capability: <memory:1920, vCores:1>, # Containers: 2, Location: *, Relax Locality: true}] [] [] []
2016-08-21 14:53:29,988 INFO org.apache.hadoop.yarn.server.resourcemanager.scheduler.fair.FSAppAttempt: root.batch: <memory:4096, vCores:2>
2016-08-21 14:53:29,988 INFO org.apache.hadoop.yarn.server.resourcemanager.scheduler.fair.FSAppAttempt: appattempt_1471812677892_0001_000001 minReqResource: <memory:0, vCores:0> flexibleResource: <memory:16384, vCores:8>
2016-08-21 14:53:29,988 INFO org.apache.hadoop.yarn.server.resourcemanager.scheduler.fair.FairScheduler: allocate resource to application attempt: appattempt_1471812677892_0001_000001 queue:root.batch isRunning=true 
2016-08-21 14:53:29,988 INFO org.apache.hadoop.yarn.server.resourcemanager.scheduler.fair.FairScheduler: iglf: 1.getHeadroom()=<memory:12288, vCores:6>
2016-08-21 14:53:30,168 INFO org.apache.hadoop.yarn.server.resourcemanager.scheduler.fair.FSAppAttempt: assignContainer(FSSchedulerNode node:cp-1.yarn-perf.yarnrm-PG0.wisc.cloudlab.us, boolean reserved=false) for appattempt_1471812677892_0001_000001
2016-08-21 14:53:30,168 INFO org.apache.hadoop.yarn.server.resourcemanager.scheduler.fair.FSAppAttempt: assignContainer(FSSchedulerNode:cp-1.yarn-perf.yarnrm-PG0.wisc.cloudlab.us, ResourceRequest request, NodeType type, boolean reserved=false
2016-08-21 14:53:30,168 INFO org.apache.hadoop.yarn.server.resourcemanager.scheduler.fair.FSAppAttempt: allocate container: container_1471812677892_0001_01_000003 priority 1
2016-08-21 14:53:30,168 INFO org.apache.hadoop.yarn.server.resourcemanager.rmcontainer.RMContainerImpl: Processing container_1471812677892_0001_01_000003 of event START
2016-08-21 14:53:30,168 INFO org.apache.hadoop.yarn.server.resourcemanager.rmcontainer.RMContainerImpl: container_1471812677892_0001_01_000003 Container Transitioned from NEW to ALLOCATED
2016-08-21 14:53:30,169 INFO org.apache.hadoop.yarn.server.resourcemanager.RMAuditLogger: USER=tanle	OPERATION=AM Allocated Container	TARGET=SchedulerApp	RESULT=SUCCESS	APPID=application_1471812677892_0001	CONTAINERID=container_1471812677892_0001_01_000003
2016-08-21 14:53:30,169 INFO org.apache.hadoop.yarn.server.resourcemanager.scheduler.SchedulerNode: Assigned container container_1471812677892_0001_01_000003 of capacity <memory:2048, vCores:1> on host cp-1.yarn-perf.yarnrm-PG0.wisc.cloudlab.us:39022, which has 2 containers, <memory:4096, vCores:2> used and <memory:4096, vCores:2> available after allocation
2016-08-21 14:53:30,173 INFO org.apache.hadoop.yarn.server.resourcemanager.scheduler.fair.FSAppAttempt: assignContainer(FSSchedulerNode node:c220g1-031106.wisc.cloudlab.us, boolean reserved=false) for appattempt_1471812677892_0001_000001
2016-08-21 14:53:30,173 INFO org.apache.hadoop.yarn.server.resourcemanager.scheduler.fair.FSAppAttempt: assignContainer(FSSchedulerNode:c220g1-031106.wisc.cloudlab.us, ResourceRequest request, NodeType type, boolean reserved=false
2016-08-21 14:53:30,173 INFO org.apache.hadoop.yarn.server.resourcemanager.scheduler.fair.FSAppAttempt: allocate container: container_1471812677892_0001_01_000004 priority 1
2016-08-21 14:53:30,173 INFO org.apache.hadoop.yarn.server.resourcemanager.rmcontainer.RMContainerImpl: Processing container_1471812677892_0001_01_000004 of event START
2016-08-21 14:53:30,173 INFO org.apache.hadoop.yarn.server.resourcemanager.rmcontainer.RMContainerImpl: container_1471812677892_0001_01_000004 Container Transitioned from NEW to ALLOCATED
2016-08-21 14:53:30,173 INFO org.apache.hadoop.yarn.server.resourcemanager.RMAuditLogger: USER=tanle	OPERATION=AM Allocated Container	TARGET=SchedulerApp	RESULT=SUCCESS	APPID=application_1471812677892_0001	CONTAINERID=container_1471812677892_0001_01_000004
2016-08-21 14:53:30,174 INFO org.apache.hadoop.yarn.server.resourcemanager.scheduler.SchedulerNode: Assigned container container_1471812677892_0001_01_000004 of capacity <memory:2048, vCores:1> on host c220g1-031106.wisc.cloudlab.us:33388, which has 2 containers, <memory:4096, vCores:2> used and <memory:4096, vCores:2> available after allocation
2016-08-21 14:53:30,191 INFO org.apache.hadoop.yarn.server.resourcemanager.scheduler.fair.FairScheduler: allocate(appattempt_1471812677892_0001_000001 [] [] [] []
2016-08-21 14:53:30,191 INFO org.apache.hadoop.yarn.server.resourcemanager.scheduler.fair.FSAppAttempt: root.batch: <memory:8192, vCores:4>
2016-08-21 14:53:30,191 INFO org.apache.hadoop.yarn.server.resourcemanager.scheduler.fair.FSAppAttempt: appattempt_1471812677892_0001_000001 minReqResource: <memory:0, vCores:0> flexibleResource: <memory:16384, vCores:8>
2016-08-21 14:53:30,191 INFO org.apache.hadoop.yarn.server.resourcemanager.scheduler.fair.FairScheduler: allocate resource to application attempt: appattempt_1471812677892_0001_000001 queue:root.batch isRunning=true 
2016-08-21 14:53:30,193 INFO org.apache.hadoop.yarn.server.resourcemanager.rmcontainer.RMContainerImpl: Processing container_1471812677892_0001_01_000003 of event ACQUIRED
2016-08-21 14:53:30,193 INFO org.apache.hadoop.yarn.server.resourcemanager.rmcontainer.RMContainerImpl: container_1471812677892_0001_01_000003 Container Transitioned from ALLOCATED to ACQUIRED
2016-08-21 14:53:30,195 INFO org.apache.hadoop.yarn.server.resourcemanager.security.NMTokenSecretManagerInRM: Sending NMToken for nodeId : c220g1-031106.wisc.cloudlab.us:33388 for container : container_1471812677892_0001_01_000004
2016-08-21 14:53:30,198 INFO org.apache.hadoop.yarn.server.resourcemanager.rmcontainer.RMContainerImpl: Processing container_1471812677892_0001_01_000004 of event ACQUIRED
2016-08-21 14:53:30,199 INFO org.apache.hadoop.yarn.server.resourcemanager.rmcontainer.RMContainerImpl: container_1471812677892_0001_01_000004 Container Transitioned from ALLOCATED to ACQUIRED
2016-08-21 14:53:30,199 INFO org.apache.hadoop.yarn.server.resourcemanager.scheduler.fair.FairScheduler: iglf: 1.getHeadroom()=<memory:8192, vCores:4>
2016-08-21 14:53:31,172 INFO org.apache.hadoop.yarn.server.resourcemanager.rmcontainer.RMContainerImpl: Processing container_1471812677892_0001_01_000003 of event LAUNCHED
2016-08-21 14:53:31,172 INFO org.apache.hadoop.yarn.server.resourcemanager.rmcontainer.RMContainerImpl: container_1471812677892_0001_01_000003 Container Transitioned from ACQUIRED to RUNNING
2016-08-21 14:53:31,172 INFO org.apache.hadoop.yarn.server.resourcemanager.scheduler.fair.FSAppAttempt: assignContainer(FSSchedulerNode node:cp-1.yarn-perf.yarnrm-PG0.wisc.cloudlab.us, boolean reserved=false) for appattempt_1471812677892_0001_000001
2016-08-21 14:53:31,176 INFO org.apache.hadoop.yarn.server.resourcemanager.rmcontainer.RMContainerImpl: Processing container_1471812677892_0001_01_000004 of event LAUNCHED
2016-08-21 14:53:31,176 INFO org.apache.hadoop.yarn.server.resourcemanager.rmcontainer.RMContainerImpl: container_1471812677892_0001_01_000004 Container Transitioned from ACQUIRED to RUNNING
2016-08-21 14:53:31,176 INFO org.apache.hadoop.yarn.server.resourcemanager.scheduler.fair.FSAppAttempt: assignContainer(FSSchedulerNode node:c220g1-031106.wisc.cloudlab.us, boolean reserved=false) for appattempt_1471812677892_0001_000001
2016-08-21 14:53:32,174 INFO org.apache.hadoop.yarn.server.resourcemanager.scheduler.fair.FSAppAttempt: assignContainer(FSSchedulerNode node:cp-1.yarn-perf.yarnrm-PG0.wisc.cloudlab.us, boolean reserved=false) for appattempt_1471812677892_0001_000001
2016-08-21 14:53:32,178 INFO org.apache.hadoop.yarn.server.resourcemanager.scheduler.fair.FSAppAttempt: assignContainer(FSSchedulerNode node:c220g1-031106.wisc.cloudlab.us, boolean reserved=false) for appattempt_1471812677892_0001_000001
2016-08-21 14:53:33,178 INFO org.apache.hadoop.yarn.server.resourcemanager.scheduler.fair.FSAppAttempt: assignContainer(FSSchedulerNode node:cp-1.yarn-perf.yarnrm-PG0.wisc.cloudlab.us, boolean reserved=false) for appattempt_1471812677892_0001_000001
2016-08-21 14:53:33,181 INFO org.apache.hadoop.yarn.server.resourcemanager.scheduler.fair.FSAppAttempt: assignContainer(FSSchedulerNode node:c220g1-031106.wisc.cloudlab.us, boolean reserved=false) for appattempt_1471812677892_0001_000001
2016-08-21 14:53:33,210 INFO org.apache.hadoop.yarn.server.resourcemanager.scheduler.fair.FairScheduler: allocate(appattempt_1471812677892_0001_000001 [{Priority: 1, Capability: <memory:1920, vCores:1>, # Containers: 0, Location: *, Relax Locality: true}] [] [] []
2016-08-21 14:53:33,210 INFO org.apache.hadoop.yarn.server.resourcemanager.scheduler.fair.FSAppAttempt: root.batch: <memory:8192, vCores:4>
2016-08-21 14:53:33,211 INFO org.apache.hadoop.yarn.server.resourcemanager.scheduler.fair.FSAppAttempt: appattempt_1471812677892_0001_000001 minReqResource: <memory:0, vCores:0> flexibleResource: <memory:16384, vCores:8>
2016-08-21 14:53:33,211 INFO org.apache.hadoop.yarn.server.resourcemanager.scheduler.fair.FairScheduler: allocate resource to application attempt: appattempt_1471812677892_0001_000001 queue:root.batch isRunning=true 
2016-08-21 14:53:33,211 INFO org.apache.hadoop.yarn.server.resourcemanager.scheduler.AppSchedulingInfo: checking for deactivate of application :application_1471812677892_0001
2016-08-21 14:53:33,211 INFO org.apache.hadoop.yarn.server.resourcemanager.scheduler.fair.FairScheduler: iglf: 1.getHeadroom()=<memory:8192, vCores:4>
2016-08-21 14:53:34,181 INFO org.apache.hadoop.yarn.server.resourcemanager.scheduler.fair.FSAppAttempt: assignContainer(FSSchedulerNode node:cp-1.yarn-perf.yarnrm-PG0.wisc.cloudlab.us, boolean reserved=false) for appattempt_1471812677892_0001_000001
2016-08-21 14:53:34,184 INFO org.apache.hadoop.yarn.server.resourcemanager.scheduler.fair.FSAppAttempt: assignContainer(FSSchedulerNode node:c220g1-031106.wisc.cloudlab.us, boolean reserved=false) for appattempt_1471812677892_0001_000001
2016-08-21 14:53:34,987 INFO org.apache.hadoop.yarn.server.resourcemanager.scheduler.fair.FairScheduler: allocate(appattempt_1471812677892_0001_000001 [{Priority: 1, Capability: <memory:1920, vCores:1>, # Containers: 4, Location: *, Relax Locality: true}] [] [] []
2016-08-21 14:53:34,987 INFO org.apache.hadoop.yarn.server.resourcemanager.scheduler.fair.FSAppAttempt: root.batch: <memory:8192, vCores:4>
2016-08-21 14:53:34,987 INFO org.apache.hadoop.yarn.server.resourcemanager.scheduler.fair.FSAppAttempt: appattempt_1471812677892_0001_000001 minReqResource: <memory:0, vCores:0> flexibleResource: <memory:16384, vCores:8>
2016-08-21 14:53:34,987 INFO org.apache.hadoop.yarn.server.resourcemanager.scheduler.fair.FairScheduler: allocate resource to application attempt: appattempt_1471812677892_0001_000001 queue:root.batch isRunning=true 
2016-08-21 14:53:34,987 INFO org.apache.hadoop.yarn.server.resourcemanager.scheduler.fair.FairScheduler: iglf: 1.getHeadroom()=<memory:8192, vCores:4>
2016-08-21 14:53:35,183 INFO org.apache.hadoop.yarn.server.resourcemanager.scheduler.fair.FSAppAttempt: assignContainer(FSSchedulerNode node:cp-1.yarn-perf.yarnrm-PG0.wisc.cloudlab.us, boolean reserved=false) for appattempt_1471812677892_0001_000001
2016-08-21 14:53:35,183 INFO org.apache.hadoop.yarn.server.resourcemanager.scheduler.fair.FSAppAttempt: assignContainer(FSSchedulerNode:cp-1.yarn-perf.yarnrm-PG0.wisc.cloudlab.us, ResourceRequest request, NodeType type, boolean reserved=false
2016-08-21 14:53:35,184 INFO org.apache.hadoop.yarn.server.resourcemanager.scheduler.fair.FSAppAttempt: allocate container: container_1471812677892_0001_01_000005 priority 1
2016-08-21 14:53:35,184 INFO org.apache.hadoop.yarn.server.resourcemanager.rmcontainer.RMContainerImpl: Processing container_1471812677892_0001_01_000005 of event START
2016-08-21 14:53:35,184 INFO org.apache.hadoop.yarn.server.resourcemanager.rmcontainer.RMContainerImpl: container_1471812677892_0001_01_000005 Container Transitioned from NEW to ALLOCATED
2016-08-21 14:53:35,184 INFO org.apache.hadoop.yarn.server.resourcemanager.RMAuditLogger: USER=tanle	OPERATION=AM Allocated Container	TARGET=SchedulerApp	RESULT=SUCCESS	APPID=application_1471812677892_0001	CONTAINERID=container_1471812677892_0001_01_000005
2016-08-21 14:53:35,184 INFO org.apache.hadoop.yarn.server.resourcemanager.scheduler.SchedulerNode: Assigned container container_1471812677892_0001_01_000005 of capacity <memory:2048, vCores:1> on host cp-1.yarn-perf.yarnrm-PG0.wisc.cloudlab.us:39022, which has 3 containers, <memory:6144, vCores:3> used and <memory:2048, vCores:1> available after allocation
2016-08-21 14:53:35,187 INFO org.apache.hadoop.yarn.server.resourcemanager.scheduler.fair.FSAppAttempt: assignContainer(FSSchedulerNode node:c220g1-031106.wisc.cloudlab.us, boolean reserved=false) for appattempt_1471812677892_0001_000001
2016-08-21 14:53:35,187 INFO org.apache.hadoop.yarn.server.resourcemanager.scheduler.fair.FSAppAttempt: assignContainer(FSSchedulerNode:c220g1-031106.wisc.cloudlab.us, ResourceRequest request, NodeType type, boolean reserved=false
2016-08-21 14:53:35,187 INFO org.apache.hadoop.yarn.server.resourcemanager.scheduler.fair.FSAppAttempt: allocate container: container_1471812677892_0001_01_000006 priority 1
2016-08-21 14:53:35,188 INFO org.apache.hadoop.yarn.server.resourcemanager.rmcontainer.RMContainerImpl: Processing container_1471812677892_0001_01_000006 of event START
2016-08-21 14:53:35,188 INFO org.apache.hadoop.yarn.server.resourcemanager.rmcontainer.RMContainerImpl: container_1471812677892_0001_01_000006 Container Transitioned from NEW to ALLOCATED
2016-08-21 14:53:35,188 INFO org.apache.hadoop.yarn.server.resourcemanager.RMAuditLogger: USER=tanle	OPERATION=AM Allocated Container	TARGET=SchedulerApp	RESULT=SUCCESS	APPID=application_1471812677892_0001	CONTAINERID=container_1471812677892_0001_01_000006
2016-08-21 14:53:35,188 INFO org.apache.hadoop.yarn.server.resourcemanager.scheduler.SchedulerNode: Assigned container container_1471812677892_0001_01_000006 of capacity <memory:2048, vCores:1> on host c220g1-031106.wisc.cloudlab.us:33388, which has 3 containers, <memory:6144, vCores:3> used and <memory:2048, vCores:1> available after allocation
2016-08-21 14:53:35,190 INFO org.apache.hadoop.yarn.server.resourcemanager.scheduler.fair.FairScheduler: allocate(appattempt_1471812677892_0001_000001 [] [] [] []
2016-08-21 14:53:35,190 INFO org.apache.hadoop.yarn.server.resourcemanager.scheduler.fair.FSAppAttempt: root.batch: <memory:12288, vCores:6>
2016-08-21 14:53:35,190 INFO org.apache.hadoop.yarn.server.resourcemanager.scheduler.fair.FSAppAttempt: appattempt_1471812677892_0001_000001 minReqResource: <memory:0, vCores:0> flexibleResource: <memory:16384, vCores:8>
2016-08-21 14:53:35,191 INFO org.apache.hadoop.yarn.server.resourcemanager.scheduler.fair.FairScheduler: allocate resource to application attempt: appattempt_1471812677892_0001_000001 queue:root.batch isRunning=true 
2016-08-21 14:53:35,192 INFO org.apache.hadoop.yarn.server.resourcemanager.rmcontainer.RMContainerImpl: Processing container_1471812677892_0001_01_000005 of event ACQUIRED
2016-08-21 14:53:35,193 INFO org.apache.hadoop.yarn.server.resourcemanager.rmcontainer.RMContainerImpl: container_1471812677892_0001_01_000005 Container Transitioned from ALLOCATED to ACQUIRED
2016-08-21 14:53:35,194 INFO org.apache.hadoop.yarn.server.resourcemanager.rmcontainer.RMContainerImpl: Processing container_1471812677892_0001_01_000006 of event ACQUIRED
2016-08-21 14:53:35,194 INFO org.apache.hadoop.yarn.server.resourcemanager.rmcontainer.RMContainerImpl: container_1471812677892_0001_01_000006 Container Transitioned from ALLOCATED to ACQUIRED
2016-08-21 14:53:35,195 INFO org.apache.hadoop.yarn.server.resourcemanager.scheduler.fair.FairScheduler: iglf: 1.getHeadroom()=<memory:4096, vCores:2>
2016-08-21 14:53:35,606 INFO org.apache.hadoop.yarn.server.resourcemanager.scheduler.fair.FairScheduler: allocate(appattempt_1471812677892_0001_000001 [{Priority: 1, Capability: <memory:1920, vCores:1>, # Containers: 2, Location: *, Relax Locality: true}] [] [] []
2016-08-21 14:53:35,606 INFO org.apache.hadoop.yarn.server.resourcemanager.scheduler.fair.FSAppAttempt: root.batch: <memory:12288, vCores:6>
2016-08-21 14:53:35,606 INFO org.apache.hadoop.yarn.server.resourcemanager.scheduler.fair.FSAppAttempt: appattempt_1471812677892_0001_000001 minReqResource: <memory:0, vCores:0> flexibleResource: <memory:16384, vCores:8>
2016-08-21 14:53:35,606 INFO org.apache.hadoop.yarn.server.resourcemanager.scheduler.fair.FairScheduler: allocate resource to application attempt: appattempt_1471812677892_0001_000001 queue:root.batch isRunning=true 
2016-08-21 14:53:35,607 INFO org.apache.hadoop.yarn.server.resourcemanager.scheduler.fair.FairScheduler: iglf: 1.getHeadroom()=<memory:4096, vCores:2>
2016-08-21 14:53:36,187 INFO org.apache.hadoop.yarn.server.resourcemanager.rmcontainer.RMContainerImpl: Processing container_1471812677892_0001_01_000005 of event LAUNCHED
2016-08-21 14:53:36,187 INFO org.apache.hadoop.yarn.server.resourcemanager.rmcontainer.RMContainerImpl: container_1471812677892_0001_01_000005 Container Transitioned from ACQUIRED to RUNNING
2016-08-21 14:53:36,187 INFO org.apache.hadoop.yarn.server.resourcemanager.scheduler.fair.FSAppAttempt: assignContainer(FSSchedulerNode node:cp-1.yarn-perf.yarnrm-PG0.wisc.cloudlab.us, boolean reserved=false) for appattempt_1471812677892_0001_000001
2016-08-21 14:53:36,187 INFO org.apache.hadoop.yarn.server.resourcemanager.scheduler.fair.FSAppAttempt: assignContainer(FSSchedulerNode:cp-1.yarn-perf.yarnrm-PG0.wisc.cloudlab.us, ResourceRequest request, NodeType type, boolean reserved=false
2016-08-21 14:53:36,188 INFO org.apache.hadoop.yarn.server.resourcemanager.scheduler.fair.FSAppAttempt: allocate container: container_1471812677892_0001_01_000007 priority 1
2016-08-21 14:53:36,188 INFO org.apache.hadoop.yarn.server.resourcemanager.rmcontainer.RMContainerImpl: Processing container_1471812677892_0001_01_000007 of event START
2016-08-21 14:53:36,188 INFO org.apache.hadoop.yarn.server.resourcemanager.rmcontainer.RMContainerImpl: container_1471812677892_0001_01_000007 Container Transitioned from NEW to ALLOCATED
2016-08-21 14:53:36,188 INFO org.apache.hadoop.yarn.server.resourcemanager.RMAuditLogger: USER=tanle	OPERATION=AM Allocated Container	TARGET=SchedulerApp	RESULT=SUCCESS	APPID=application_1471812677892_0001	CONTAINERID=container_1471812677892_0001_01_000007
2016-08-21 14:53:36,188 INFO org.apache.hadoop.yarn.server.resourcemanager.scheduler.SchedulerNode: Assigned container container_1471812677892_0001_01_000007 of capacity <memory:2048, vCores:1> on host cp-1.yarn-perf.yarnrm-PG0.wisc.cloudlab.us:39022, which has 4 containers, <memory:8192, vCores:4> used and <memory:0, vCores:0> available after allocation
2016-08-21 14:53:36,190 INFO org.apache.hadoop.yarn.server.resourcemanager.rmcontainer.RMContainerImpl: Processing container_1471812677892_0001_01_000006 of event LAUNCHED
2016-08-21 14:53:36,190 INFO org.apache.hadoop.yarn.server.resourcemanager.rmcontainer.RMContainerImpl: container_1471812677892_0001_01_000006 Container Transitioned from ACQUIRED to RUNNING
2016-08-21 14:53:36,191 INFO org.apache.hadoop.yarn.server.resourcemanager.scheduler.fair.FSAppAttempt: assignContainer(FSSchedulerNode node:c220g1-031106.wisc.cloudlab.us, boolean reserved=false) for appattempt_1471812677892_0001_000001
2016-08-21 14:53:36,191 INFO org.apache.hadoop.yarn.server.resourcemanager.scheduler.fair.FSAppAttempt: assignContainer(FSSchedulerNode:c220g1-031106.wisc.cloudlab.us, ResourceRequest request, NodeType type, boolean reserved=false
2016-08-21 14:53:36,191 INFO org.apache.hadoop.yarn.server.resourcemanager.scheduler.fair.FSAppAttempt: allocate container: container_1471812677892_0001_01_000008 priority 1
2016-08-21 14:53:36,191 INFO org.apache.hadoop.yarn.server.resourcemanager.rmcontainer.RMContainerImpl: Processing container_1471812677892_0001_01_000008 of event START
2016-08-21 14:53:36,191 INFO org.apache.hadoop.yarn.server.resourcemanager.rmcontainer.RMContainerImpl: container_1471812677892_0001_01_000008 Container Transitioned from NEW to ALLOCATED
2016-08-21 14:53:36,191 INFO org.apache.hadoop.yarn.server.resourcemanager.RMAuditLogger: USER=tanle	OPERATION=AM Allocated Container	TARGET=SchedulerApp	RESULT=SUCCESS	APPID=application_1471812677892_0001	CONTAINERID=container_1471812677892_0001_01_000008
2016-08-21 14:53:36,191 INFO org.apache.hadoop.yarn.server.resourcemanager.scheduler.SchedulerNode: Assigned container container_1471812677892_0001_01_000008 of capacity <memory:2048, vCores:1> on host c220g1-031106.wisc.cloudlab.us:33388, which has 4 containers, <memory:8192, vCores:4> used and <memory:0, vCores:0> available after allocation
2016-08-21 14:53:36,410 INFO org.apache.hadoop.yarn.server.resourcemanager.scheduler.fair.FairScheduler: allocate(appattempt_1471812677892_0001_000001 [] [] [] []
2016-08-21 14:53:36,410 INFO org.apache.hadoop.yarn.server.resourcemanager.scheduler.fair.FSAppAttempt: root.batch: <memory:16384, vCores:8>
2016-08-21 14:53:36,410 INFO org.apache.hadoop.yarn.server.resourcemanager.scheduler.fair.FSAppAttempt: appattempt_1471812677892_0001_000001 minReqResource: <memory:0, vCores:0> flexibleResource: <memory:16384, vCores:8>
2016-08-21 14:53:36,410 INFO org.apache.hadoop.yarn.server.resourcemanager.scheduler.fair.FairScheduler: allocate resource to application attempt: appattempt_1471812677892_0001_000001 queue:root.batch isRunning=true 
2016-08-21 14:53:36,413 INFO org.apache.hadoop.yarn.server.resourcemanager.rmcontainer.RMContainerImpl: Processing container_1471812677892_0001_01_000007 of event ACQUIRED
2016-08-21 14:53:36,413 INFO org.apache.hadoop.yarn.server.resourcemanager.rmcontainer.RMContainerImpl: container_1471812677892_0001_01_000007 Container Transitioned from ALLOCATED to ACQUIRED
2016-08-21 14:53:36,427 INFO org.apache.hadoop.yarn.server.resourcemanager.rmcontainer.RMContainerImpl: Processing container_1471812677892_0001_01_000008 of event ACQUIRED
2016-08-21 14:53:36,427 INFO org.apache.hadoop.yarn.server.resourcemanager.rmcontainer.RMContainerImpl: container_1471812677892_0001_01_000008 Container Transitioned from ALLOCATED to ACQUIRED
2016-08-21 14:53:36,427 INFO org.apache.hadoop.yarn.server.resourcemanager.scheduler.fair.FairScheduler: iglf: 1.getHeadroom()=<memory:0, vCores:0>
2016-08-21 14:53:37,190 INFO org.apache.hadoop.yarn.server.resourcemanager.rmcontainer.RMContainerImpl: Processing container_1471812677892_0001_01_000007 of event LAUNCHED
2016-08-21 14:53:37,191 INFO org.apache.hadoop.yarn.server.resourcemanager.rmcontainer.RMContainerImpl: container_1471812677892_0001_01_000007 Container Transitioned from ACQUIRED to RUNNING
2016-08-21 14:53:37,205 INFO org.apache.hadoop.yarn.server.resourcemanager.scheduler.fair.FSAppAttempt: assignContainer(FSSchedulerNode node:cp-1.yarn-perf.yarnrm-PG0.wisc.cloudlab.us, boolean reserved=false) for appattempt_1471812677892_0001_000001
2016-08-21 14:53:37,206 INFO org.apache.hadoop.yarn.server.resourcemanager.rmcontainer.RMContainerImpl: Processing container_1471812677892_0001_01_000008 of event LAUNCHED
2016-08-21 14:53:37,206 INFO org.apache.hadoop.yarn.server.resourcemanager.rmcontainer.RMContainerImpl: container_1471812677892_0001_01_000008 Container Transitioned from ACQUIRED to RUNNING
2016-08-21 14:53:37,206 INFO org.apache.hadoop.yarn.server.resourcemanager.scheduler.fair.FSAppAttempt: assignContainer(FSSchedulerNode node:c220g1-031106.wisc.cloudlab.us, boolean reserved=false) for appattempt_1471812677892_0001_000001
2016-08-21 14:53:37,800 WARN org.apache.hadoop.yarn.server.resourcemanager.rmapp.RMAppImpl: The specific max attempts: 0 for application: 2 is invalid, because it is out of the range [1, 2]. Use the global max attempts instead.
2016-08-21 14:53:37,801 INFO org.apache.hadoop.yarn.server.resourcemanager.ClientRMService: Application with id 2 submitted by user tanle
2016-08-21 14:53:37,801 INFO org.apache.hadoop.yarn.server.resourcemanager.rmapp.RMAppImpl: Storing application with id application_1471812677892_0002
2016-08-21 14:53:37,801 INFO org.apache.hadoop.yarn.server.resourcemanager.RMAuditLogger: USER=tanle	IP=128.104.222.71	OPERATION=Submit Application Request	TARGET=ClientRMService	RESULT=SUCCESS	APPID=application_1471812677892_0002
2016-08-21 14:53:37,802 INFO org.apache.hadoop.yarn.server.resourcemanager.recovery.RMStateStore: Storing info for app: application_1471812677892_0002
2016-08-21 14:53:37,802 INFO org.apache.hadoop.yarn.server.resourcemanager.scheduler.fair.FairScheduler: Accepted application application_1471812677892_0002 from user: tanle, in queue: batch, currently num of applications: 2
2016-08-21 14:53:37,803 INFO org.apache.hadoop.yarn.server.resourcemanager.ApplicationMasterService: Registering app attempt : appattempt_1471812677892_0002_000001
2016-08-21 14:53:37,803 INFO org.apache.hadoop.yarn.server.resourcemanager.rmapp.attempt.RMAppAttemptImpl: appattempt_1471812677892_0002_000001 State change from NEW to SUBMITTED
2016-08-21 14:53:37,804 INFO org.apache.hadoop.yarn.server.resourcemanager.scheduler.fair.FairScheduler: Added Application Attempt appattempt_1471812677892_0002_000001 to scheduler from user: tanle
2016-08-21 14:53:37,804 INFO org.apache.hadoop.yarn.server.resourcemanager.rmapp.attempt.RMAppAttemptImpl: ScheduleTransition.transition(appattempt_1471812677892_0002_000001,EventType: ATTEMPT_ADDED)
2016-08-21 14:53:37,804 INFO org.apache.hadoop.yarn.server.resourcemanager.scheduler.fair.FairScheduler: allocate(appattempt_1471812677892_0002_000001 [{Priority: 0, Capability: <memory:2048, vCores:1>, # Containers: 1, Location: *, Relax Locality: true}] [] null null
2016-08-21 14:53:37,804 INFO org.apache.hadoop.yarn.server.resourcemanager.scheduler.fair.FSAppAttempt: root.batch: <memory:16384, vCores:8>
2016-08-21 14:53:37,804 INFO org.apache.hadoop.yarn.server.resourcemanager.scheduler.fair.FSAppAttempt: appattempt_1471812677892_0002_000001 minReqResource: <memory:0, vCores:0> flexibleResource: <memory:16384, vCores:8>
2016-08-21 14:53:37,804 INFO org.apache.hadoop.yarn.server.resourcemanager.scheduler.fair.FairScheduler: allocate resource to application attempt: appattempt_1471812677892_0002_000001 queue:root.batch isRunning=true 
2016-08-21 14:53:37,805 INFO org.apache.hadoop.yarn.server.resourcemanager.scheduler.fair.FairScheduler: iglf: 2.getHeadroom()=<memory:0, vCores:0>
2016-08-21 14:53:37,805 INFO org.apache.hadoop.yarn.server.resourcemanager.rmapp.attempt.RMAppAttemptImpl: appattempt_1471812677892_0002_000001 State change from SUBMITTED to SCHEDULED
2016-08-21 14:53:38,193 INFO org.apache.hadoop.yarn.server.resourcemanager.scheduler.fair.FSAppAttempt: assignContainer(FSSchedulerNode node:cp-1.yarn-perf.yarnrm-PG0.wisc.cloudlab.us, boolean reserved=false) for appattempt_1471812677892_0002_000001
2016-08-21 14:53:38,193 INFO org.apache.hadoop.yarn.server.resourcemanager.scheduler.fair.FSAppAttempt: assignContainer(FSSchedulerNode:cp-1.yarn-perf.yarnrm-PG0.wisc.cloudlab.us, ResourceRequest request, NodeType type, boolean reserved=false
2016-08-21 14:53:38,193 INFO org.apache.hadoop.yarn.server.resourcemanager.scheduler.fair.FSAppAttempt: Making reservation: node=cp-1.yarn-perf.yarnrm-PG0.wisc.cloudlab.us app_id=application_1471812677892_0002
2016-08-21 14:53:38,197 INFO org.apache.hadoop.yarn.server.resourcemanager.rmcontainer.RMContainerImpl: Processing container_1471812677892_0002_01_000001 of event RESERVED
2016-08-21 14:53:38,197 INFO org.apache.hadoop.yarn.server.resourcemanager.rmcontainer.RMContainerImpl: container_1471812677892_0002_01_000001 Container Transitioned from NEW to RESERVED
2016-08-21 14:53:38,197 INFO org.apache.hadoop.yarn.server.resourcemanager.scheduler.fair.FSSchedulerNode: Reserved container container_1471812677892_0002_01_000001 on node host: cp-1.yarn-perf.yarnrm-PG0.wisc.cloudlab.us:39022 #containers=4 available=<memory:0, vCores:0> used=<memory:8192, vCores:4> for application org.apache.hadoop.yarn.server.resourcemanager.scheduler.fair.FSAppAttempt@5f3ad072
2016-08-21 14:53:38,198 INFO org.apache.hadoop.yarn.server.resourcemanager.scheduler.fair.FSAppAttempt: assignContainer(FSSchedulerNode node:c220g1-031106.wisc.cloudlab.us, boolean reserved=false) for appattempt_1471812677892_0002_000001
2016-08-21 14:53:38,198 INFO org.apache.hadoop.yarn.server.resourcemanager.scheduler.fair.FSAppAttempt: assignContainer(FSSchedulerNode:c220g1-031106.wisc.cloudlab.us, ResourceRequest request, NodeType type, boolean reserved=false
2016-08-21 14:53:38,198 INFO org.apache.hadoop.yarn.server.resourcemanager.scheduler.fair.FSAppAttempt: Making reservation: node=c220g1-031106.wisc.cloudlab.us app_id=application_1471812677892_0002
2016-08-21 14:53:38,198 INFO org.apache.hadoop.yarn.server.resourcemanager.rmcontainer.RMContainerImpl: Processing container_1471812677892_0002_01_000002 of event RESERVED
2016-08-21 14:53:38,198 INFO org.apache.hadoop.yarn.server.resourcemanager.rmcontainer.RMContainerImpl: container_1471812677892_0002_01_000002 Container Transitioned from NEW to RESERVED
2016-08-21 14:53:38,198 INFO org.apache.hadoop.yarn.server.resourcemanager.scheduler.fair.FSSchedulerNode: Reserved container container_1471812677892_0002_01_000002 on node host: c220g1-031106.wisc.cloudlab.us:33388 #containers=4 available=<memory:0, vCores:0> used=<memory:8192, vCores:4> for application org.apache.hadoop.yarn.server.resourcemanager.scheduler.fair.FSAppAttempt@5f3ad072
2016-08-21 14:53:39,437 INFO org.apache.hadoop.yarn.server.resourcemanager.scheduler.fair.FairScheduler: allocate(appattempt_1471812677892_0001_000001 [{Priority: 1, Capability: <memory:1920, vCores:1>, # Containers: 0, Location: *, Relax Locality: true}] [] [] []
2016-08-21 14:53:39,437 INFO org.apache.hadoop.yarn.server.resourcemanager.scheduler.fair.FSAppAttempt: root.batch: <memory:16384, vCores:8>
2016-08-21 14:53:39,437 INFO org.apache.hadoop.yarn.server.resourcemanager.scheduler.fair.FSAppAttempt: appattempt_1471812677892_0001_000001 minReqResource: <memory:0, vCores:0> flexibleResource: <memory:16384, vCores:8>
2016-08-21 14:53:39,437 INFO org.apache.hadoop.yarn.server.resourcemanager.scheduler.fair.FairScheduler: allocate resource to application attempt: appattempt_1471812677892_0001_000001 queue:root.batch isRunning=true 
2016-08-21 14:53:39,437 INFO org.apache.hadoop.yarn.server.resourcemanager.scheduler.AppSchedulingInfo: checking for deactivate of application :application_1471812677892_0001
2016-08-21 14:53:39,437 INFO org.apache.hadoop.yarn.server.resourcemanager.scheduler.fair.FairScheduler: iglf: 1.getHeadroom()=<memory:0, vCores:0>
2016-08-21 14:53:39,987 INFO org.apache.hadoop.yarn.server.resourcemanager.scheduler.fair.FairScheduler: allocate(appattempt_1471812677892_0001_000001 [{Priority: 1, Capability: <memory:1920, vCores:1>, # Containers: 8, Location: *, Relax Locality: true}] [] [] []
2016-08-21 14:53:39,987 INFO org.apache.hadoop.yarn.server.resourcemanager.scheduler.fair.FSAppAttempt: root.batch: <memory:16384, vCores:8>
2016-08-21 14:53:39,987 INFO org.apache.hadoop.yarn.server.resourcemanager.scheduler.fair.FSAppAttempt: appattempt_1471812677892_0001_000001 minReqResource: <memory:0, vCores:0> flexibleResource: <memory:16384, vCores:8>
2016-08-21 14:53:39,987 INFO org.apache.hadoop.yarn.server.resourcemanager.scheduler.fair.FairScheduler: allocate resource to application attempt: appattempt_1471812677892_0001_000001 queue:root.batch isRunning=true 
2016-08-21 14:53:39,988 INFO org.apache.hadoop.yarn.server.resourcemanager.scheduler.fair.FairScheduler: iglf: 1.getHeadroom()=<memory:0, vCores:0>
2016-08-21 14:53:40,192 INFO org.apache.hadoop.yarn.server.resourcemanager.scheduler.fair.FairScheduler: allocate(appattempt_1471812677892_0001_000001 [] [] [] []
2016-08-21 14:53:40,192 INFO org.apache.hadoop.yarn.server.resourcemanager.scheduler.fair.FSAppAttempt: root.batch: <memory:16384, vCores:8>
2016-08-21 14:53:40,192 INFO org.apache.hadoop.yarn.server.resourcemanager.scheduler.fair.FSAppAttempt: appattempt_1471812677892_0001_000001 minReqResource: <memory:0, vCores:0> flexibleResource: <memory:16384, vCores:8>
2016-08-21 14:53:40,193 INFO org.apache.hadoop.yarn.server.resourcemanager.scheduler.fair.FairScheduler: allocate resource to application attempt: appattempt_1471812677892_0001_000001 queue:root.batch isRunning=true 
2016-08-21 14:53:40,193 INFO org.apache.hadoop.yarn.server.resourcemanager.scheduler.fair.FairScheduler: iglf: 1.getHeadroom()=<memory:0, vCores:0>
2016-08-21 14:53:40,597 INFO org.apache.hadoop.yarn.server.resourcemanager.scheduler.fair.FairScheduler: allocate(appattempt_1471812677892_0001_000001 [] [] [] []
2016-08-21 14:53:40,598 INFO org.apache.hadoop.yarn.server.resourcemanager.scheduler.fair.FSAppAttempt: root.batch: <memory:16384, vCores:8>
2016-08-21 14:53:40,598 INFO org.apache.hadoop.yarn.server.resourcemanager.scheduler.fair.FSAppAttempt: appattempt_1471812677892_0001_000001 minReqResource: <memory:0, vCores:0> flexibleResource: <memory:16384, vCores:8>
2016-08-21 14:53:40,598 INFO org.apache.hadoop.yarn.server.resourcemanager.scheduler.fair.FairScheduler: allocate resource to application attempt: appattempt_1471812677892_0001_000001 queue:root.batch isRunning=true 
2016-08-21 14:53:40,598 INFO org.apache.hadoop.yarn.server.resourcemanager.scheduler.fair.FairScheduler: iglf: 1.getHeadroom()=<memory:0, vCores:0>
2016-08-21 14:53:41,401 INFO org.apache.hadoop.yarn.server.resourcemanager.scheduler.fair.FairScheduler: allocate(appattempt_1471812677892_0001_000001 [] [] [] []
2016-08-21 14:53:41,401 INFO org.apache.hadoop.yarn.server.resourcemanager.scheduler.fair.FSAppAttempt: root.batch: <memory:16384, vCores:8>
2016-08-21 14:53:41,401 INFO org.apache.hadoop.yarn.server.resourcemanager.scheduler.fair.FSAppAttempt: appattempt_1471812677892_0001_000001 minReqResource: <memory:0, vCores:0> flexibleResource: <memory:16384, vCores:8>
2016-08-21 14:53:41,402 INFO org.apache.hadoop.yarn.server.resourcemanager.scheduler.fair.FairScheduler: allocate resource to application attempt: appattempt_1471812677892_0001_000001 queue:root.batch isRunning=true 
2016-08-21 14:53:41,402 INFO org.apache.hadoop.yarn.server.resourcemanager.scheduler.fair.FairScheduler: iglf: 1.getHeadroom()=<memory:0, vCores:0>
2016-08-21 14:53:43,006 INFO org.apache.hadoop.yarn.server.resourcemanager.scheduler.fair.FairScheduler: allocate(appattempt_1471812677892_0001_000001 [] [] [] []
2016-08-21 14:53:43,006 INFO org.apache.hadoop.yarn.server.resourcemanager.scheduler.fair.FSAppAttempt: root.batch: <memory:16384, vCores:8>
2016-08-21 14:53:43,006 INFO org.apache.hadoop.yarn.server.resourcemanager.scheduler.fair.FSAppAttempt: appattempt_1471812677892_0001_000001 minReqResource: <memory:0, vCores:0> flexibleResource: <memory:16384, vCores:8>
2016-08-21 14:53:43,006 INFO org.apache.hadoop.yarn.server.resourcemanager.scheduler.fair.FairScheduler: allocate resource to application attempt: appattempt_1471812677892_0001_000001 queue:root.batch isRunning=true 
2016-08-21 14:53:43,006 INFO org.apache.hadoop.yarn.server.resourcemanager.scheduler.fair.FairScheduler: iglf: 1.getHeadroom()=<memory:0, vCores:0>
2016-08-21 14:53:44,990 INFO org.apache.hadoop.yarn.server.resourcemanager.scheduler.fair.FairScheduler: allocate(appattempt_1471812677892_0001_000001 [{Priority: 1, Capability: <memory:1920, vCores:1>, # Containers: 24, Location: *, Relax Locality: true}] [] [] []
2016-08-21 14:53:44,990 INFO org.apache.hadoop.yarn.server.resourcemanager.scheduler.fair.FSAppAttempt: root.batch: <memory:16384, vCores:8>
2016-08-21 14:53:44,990 INFO org.apache.hadoop.yarn.server.resourcemanager.scheduler.fair.FSAppAttempt: appattempt_1471812677892_0001_000001 minReqResource: <memory:0, vCores:0> flexibleResource: <memory:16384, vCores:8>
2016-08-21 14:53:44,990 INFO org.apache.hadoop.yarn.server.resourcemanager.scheduler.fair.FairScheduler: allocate resource to application attempt: appattempt_1471812677892_0001_000001 queue:root.batch isRunning=true 
2016-08-21 14:53:44,991 INFO org.apache.hadoop.yarn.server.resourcemanager.scheduler.fair.FairScheduler: iglf: 1.getHeadroom()=<memory:0, vCores:0>
2016-08-21 14:53:45,195 INFO org.apache.hadoop.yarn.server.resourcemanager.scheduler.fair.FairScheduler: allocate(appattempt_1471812677892_0001_000001 [] [] [] []
2016-08-21 14:53:45,195 INFO org.apache.hadoop.yarn.server.resourcemanager.scheduler.fair.FSAppAttempt: root.batch: <memory:16384, vCores:8>
2016-08-21 14:53:45,195 INFO org.apache.hadoop.yarn.server.resourcemanager.scheduler.fair.FSAppAttempt: appattempt_1471812677892_0001_000001 minReqResource: <memory:0, vCores:0> flexibleResource: <memory:16384, vCores:8>
2016-08-21 14:53:45,195 INFO org.apache.hadoop.yarn.server.resourcemanager.scheduler.fair.FairScheduler: allocate resource to application attempt: appattempt_1471812677892_0001_000001 queue:root.batch isRunning=true 
2016-08-21 14:53:45,195 INFO org.apache.hadoop.yarn.server.resourcemanager.scheduler.fair.FairScheduler: iglf: 1.getHeadroom()=<memory:0, vCores:0>
2016-08-21 14:53:45,599 INFO org.apache.hadoop.yarn.server.resourcemanager.scheduler.fair.FairScheduler: allocate(appattempt_1471812677892_0001_000001 [] [] [] []
2016-08-21 14:53:45,599 INFO org.apache.hadoop.yarn.server.resourcemanager.scheduler.fair.FSAppAttempt: root.batch: <memory:16384, vCores:8>
2016-08-21 14:53:45,600 INFO org.apache.hadoop.yarn.server.resourcemanager.scheduler.fair.FSAppAttempt: appattempt_1471812677892_0001_000001 minReqResource: <memory:0, vCores:0> flexibleResource: <memory:16384, vCores:8>
2016-08-21 14:53:45,600 INFO org.apache.hadoop.yarn.server.resourcemanager.scheduler.fair.FairScheduler: allocate resource to application attempt: appattempt_1471812677892_0001_000001 queue:root.batch isRunning=true 
2016-08-21 14:53:45,600 INFO org.apache.hadoop.yarn.server.resourcemanager.scheduler.fair.FairScheduler: iglf: 1.getHeadroom()=<memory:0, vCores:0>
2016-08-21 14:53:46,404 INFO org.apache.hadoop.yarn.server.resourcemanager.scheduler.fair.FairScheduler: allocate(appattempt_1471812677892_0001_000001 [] [] [] []
2016-08-21 14:53:46,404 INFO org.apache.hadoop.yarn.server.resourcemanager.scheduler.fair.FSAppAttempt: root.batch: <memory:16384, vCores:8>
2016-08-21 14:53:46,404 INFO org.apache.hadoop.yarn.server.resourcemanager.scheduler.fair.FSAppAttempt: appattempt_1471812677892_0001_000001 minReqResource: <memory:0, vCores:0> flexibleResource: <memory:16384, vCores:8>
2016-08-21 14:53:46,404 INFO org.apache.hadoop.yarn.server.resourcemanager.scheduler.fair.FairScheduler: allocate resource to application attempt: appattempt_1471812677892_0001_000001 queue:root.batch isRunning=true 
2016-08-21 14:53:46,404 INFO org.apache.hadoop.yarn.server.resourcemanager.scheduler.fair.FairScheduler: iglf: 1.getHeadroom()=<memory:0, vCores:0>
2016-08-21 14:53:48,009 INFO org.apache.hadoop.yarn.server.resourcemanager.scheduler.fair.FairScheduler: allocate(appattempt_1471812677892_0001_000001 [] [] [] []
2016-08-21 14:53:48,009 INFO org.apache.hadoop.yarn.server.resourcemanager.scheduler.fair.FSAppAttempt: root.batch: <memory:16384, vCores:8>
2016-08-21 14:53:48,009 INFO org.apache.hadoop.yarn.server.resourcemanager.scheduler.fair.FSAppAttempt: appattempt_1471812677892_0001_000001 minReqResource: <memory:0, vCores:0> flexibleResource: <memory:16384, vCores:8>
2016-08-21 14:53:48,009 INFO org.apache.hadoop.yarn.server.resourcemanager.scheduler.fair.FairScheduler: allocate resource to application attempt: appattempt_1471812677892_0001_000001 queue:root.batch isRunning=true 
2016-08-21 14:53:48,009 INFO org.apache.hadoop.yarn.server.resourcemanager.scheduler.fair.FairScheduler: iglf: 1.getHeadroom()=<memory:0, vCores:0>
2016-08-21 14:53:49,990 INFO org.apache.hadoop.yarn.server.resourcemanager.scheduler.fair.FairScheduler: allocate(appattempt_1471812677892_0001_000001 [{Priority: 1, Capability: <memory:1920, vCores:1>, # Containers: 56, Location: *, Relax Locality: true}] [] [] []
2016-08-21 14:53:49,990 INFO org.apache.hadoop.yarn.server.resourcemanager.scheduler.fair.FSAppAttempt: root.batch: <memory:16384, vCores:8>
2016-08-21 14:53:49,990 INFO org.apache.hadoop.yarn.server.resourcemanager.scheduler.fair.FSAppAttempt: appattempt_1471812677892_0001_000001 minReqResource: <memory:0, vCores:0> flexibleResource: <memory:16384, vCores:8>
2016-08-21 14:53:49,990 INFO org.apache.hadoop.yarn.server.resourcemanager.scheduler.fair.FairScheduler: allocate resource to application attempt: appattempt_1471812677892_0001_000001 queue:root.batch isRunning=true 
2016-08-21 14:53:49,991 INFO org.apache.hadoop.yarn.server.resourcemanager.scheduler.fair.FairScheduler: iglf: 1.getHeadroom()=<memory:0, vCores:0>
2016-08-21 14:53:50,194 INFO org.apache.hadoop.yarn.server.resourcemanager.scheduler.fair.FairScheduler: allocate(appattempt_1471812677892_0001_000001 [] [] [] []
2016-08-21 14:53:50,194 INFO org.apache.hadoop.yarn.server.resourcemanager.scheduler.fair.FSAppAttempt: root.batch: <memory:16384, vCores:8>
2016-08-21 14:53:50,194 INFO org.apache.hadoop.yarn.server.resourcemanager.scheduler.fair.FSAppAttempt: appattempt_1471812677892_0001_000001 minReqResource: <memory:0, vCores:0> flexibleResource: <memory:16384, vCores:8>
2016-08-21 14:53:50,194 INFO org.apache.hadoop.yarn.server.resourcemanager.scheduler.fair.FairScheduler: allocate resource to application attempt: appattempt_1471812677892_0001_000001 queue:root.batch isRunning=true 
2016-08-21 14:53:50,194 INFO org.apache.hadoop.yarn.server.resourcemanager.scheduler.fair.FairScheduler: iglf: 1.getHeadroom()=<memory:0, vCores:0>
2016-08-21 14:53:50,599 INFO org.apache.hadoop.yarn.server.resourcemanager.scheduler.fair.FairScheduler: allocate(appattempt_1471812677892_0001_000001 [] [] [] []
2016-08-21 14:53:50,599 INFO org.apache.hadoop.yarn.server.resourcemanager.scheduler.fair.FSAppAttempt: root.batch: <memory:16384, vCores:8>
2016-08-21 14:53:50,599 INFO org.apache.hadoop.yarn.server.resourcemanager.scheduler.fair.FSAppAttempt: appattempt_1471812677892_0001_000001 minReqResource: <memory:0, vCores:0> flexibleResource: <memory:16384, vCores:8>
2016-08-21 14:53:50,599 INFO org.apache.hadoop.yarn.server.resourcemanager.scheduler.fair.FairScheduler: allocate resource to application attempt: appattempt_1471812677892_0001_000001 queue:root.batch isRunning=true 
2016-08-21 14:53:50,599 INFO org.apache.hadoop.yarn.server.resourcemanager.scheduler.fair.FairScheduler: iglf: 1.getHeadroom()=<memory:0, vCores:0>
2016-08-21 14:53:51,403 INFO org.apache.hadoop.yarn.server.resourcemanager.scheduler.fair.FairScheduler: allocate(appattempt_1471812677892_0001_000001 [] [] [] []
2016-08-21 14:53:51,403 INFO org.apache.hadoop.yarn.server.resourcemanager.scheduler.fair.FSAppAttempt: root.batch: <memory:16384, vCores:8>
2016-08-21 14:53:51,403 INFO org.apache.hadoop.yarn.server.resourcemanager.scheduler.fair.FSAppAttempt: appattempt_1471812677892_0001_000001 minReqResource: <memory:0, vCores:0> flexibleResource: <memory:16384, vCores:8>
2016-08-21 14:53:51,403 INFO org.apache.hadoop.yarn.server.resourcemanager.scheduler.fair.FairScheduler: allocate resource to application attempt: appattempt_1471812677892_0001_000001 queue:root.batch isRunning=true 
2016-08-21 14:53:51,403 INFO org.apache.hadoop.yarn.server.resourcemanager.scheduler.fair.FairScheduler: iglf: 1.getHeadroom()=<memory:0, vCores:0>
2016-08-21 14:53:53,008 INFO org.apache.hadoop.yarn.server.resourcemanager.scheduler.fair.FairScheduler: allocate(appattempt_1471812677892_0001_000001 [] [] [] []
2016-08-21 14:53:53,008 INFO org.apache.hadoop.yarn.server.resourcemanager.scheduler.fair.FSAppAttempt: root.batch: <memory:16384, vCores:8>
2016-08-21 14:53:53,008 INFO org.apache.hadoop.yarn.server.resourcemanager.scheduler.fair.FSAppAttempt: appattempt_1471812677892_0001_000001 minReqResource: <memory:0, vCores:0> flexibleResource: <memory:16384, vCores:8>
2016-08-21 14:53:53,008 INFO org.apache.hadoop.yarn.server.resourcemanager.scheduler.fair.FairScheduler: allocate resource to application attempt: appattempt_1471812677892_0001_000001 queue:root.batch isRunning=true 
2016-08-21 14:53:53,008 INFO org.apache.hadoop.yarn.server.resourcemanager.scheduler.fair.FairScheduler: iglf: 1.getHeadroom()=<memory:0, vCores:0>
2016-08-21 14:53:54,992 INFO org.apache.hadoop.yarn.server.resourcemanager.scheduler.fair.FairScheduler: allocate(appattempt_1471812677892_0001_000001 [{Priority: 1, Capability: <memory:1920, vCores:1>, # Containers: 120, Location: *, Relax Locality: true}] [] [] []
2016-08-21 14:53:54,992 INFO org.apache.hadoop.yarn.server.resourcemanager.scheduler.fair.FSAppAttempt: root.batch: <memory:16384, vCores:8>
2016-08-21 14:53:54,993 INFO org.apache.hadoop.yarn.server.resourcemanager.scheduler.fair.FSAppAttempt: appattempt_1471812677892_0001_000001 minReqResource: <memory:0, vCores:0> flexibleResource: <memory:16384, vCores:8>
2016-08-21 14:53:54,993 INFO org.apache.hadoop.yarn.server.resourcemanager.scheduler.fair.FairScheduler: allocate resource to application attempt: appattempt_1471812677892_0001_000001 queue:root.batch isRunning=true 
2016-08-21 14:53:54,993 INFO org.apache.hadoop.yarn.server.resourcemanager.scheduler.fair.FairScheduler: iglf: 1.getHeadroom()=<memory:0, vCores:0>
2016-08-21 14:53:55,197 INFO org.apache.hadoop.yarn.server.resourcemanager.scheduler.fair.FairScheduler: allocate(appattempt_1471812677892_0001_000001 [] [] [] []
2016-08-21 14:53:55,197 INFO org.apache.hadoop.yarn.server.resourcemanager.scheduler.fair.FSAppAttempt: root.batch: <memory:16384, vCores:8>
2016-08-21 14:53:55,197 INFO org.apache.hadoop.yarn.server.resourcemanager.scheduler.fair.FSAppAttempt: appattempt_1471812677892_0001_000001 minReqResource: <memory:0, vCores:0> flexibleResource: <memory:16384, vCores:8>
2016-08-21 14:53:55,197 INFO org.apache.hadoop.yarn.server.resourcemanager.scheduler.fair.FairScheduler: allocate resource to application attempt: appattempt_1471812677892_0001_000001 queue:root.batch isRunning=true 
2016-08-21 14:53:55,197 INFO org.apache.hadoop.yarn.server.resourcemanager.scheduler.fair.FairScheduler: iglf: 1.getHeadroom()=<memory:0, vCores:0>
2016-08-21 14:53:55,601 INFO org.apache.hadoop.yarn.server.resourcemanager.scheduler.fair.FairScheduler: allocate(appattempt_1471812677892_0001_000001 [] [] [] []
2016-08-21 14:53:55,601 INFO org.apache.hadoop.yarn.server.resourcemanager.scheduler.fair.FSAppAttempt: root.batch: <memory:16384, vCores:8>
2016-08-21 14:53:55,601 INFO org.apache.hadoop.yarn.server.resourcemanager.scheduler.fair.FSAppAttempt: appattempt_1471812677892_0001_000001 minReqResource: <memory:0, vCores:0> flexibleResource: <memory:16384, vCores:8>
2016-08-21 14:53:55,602 INFO org.apache.hadoop.yarn.server.resourcemanager.scheduler.fair.FairScheduler: allocate resource to application attempt: appattempt_1471812677892_0001_000001 queue:root.batch isRunning=true 
2016-08-21 14:53:55,602 INFO org.apache.hadoop.yarn.server.resourcemanager.scheduler.fair.FairScheduler: iglf: 1.getHeadroom()=<memory:0, vCores:0>
2016-08-21 14:53:56,406 INFO org.apache.hadoop.yarn.server.resourcemanager.scheduler.fair.FairScheduler: allocate(appattempt_1471812677892_0001_000001 [] [] [] []
2016-08-21 14:53:56,406 INFO org.apache.hadoop.yarn.server.resourcemanager.scheduler.fair.FSAppAttempt: root.batch: <memory:16384, vCores:8>
2016-08-21 14:53:56,406 INFO org.apache.hadoop.yarn.server.resourcemanager.scheduler.fair.FSAppAttempt: appattempt_1471812677892_0001_000001 minReqResource: <memory:0, vCores:0> flexibleResource: <memory:16384, vCores:8>
2016-08-21 14:53:56,406 INFO org.apache.hadoop.yarn.server.resourcemanager.scheduler.fair.FairScheduler: allocate resource to application attempt: appattempt_1471812677892_0001_000001 queue:root.batch isRunning=true 
2016-08-21 14:53:56,406 INFO org.apache.hadoop.yarn.server.resourcemanager.scheduler.fair.FairScheduler: iglf: 1.getHeadroom()=<memory:0, vCores:0>
2016-08-21 14:53:58,011 INFO org.apache.hadoop.yarn.server.resourcemanager.scheduler.fair.FairScheduler: allocate(appattempt_1471812677892_0001_000001 [] [] [] []
2016-08-21 14:53:58,011 INFO org.apache.hadoop.yarn.server.resourcemanager.scheduler.fair.FSAppAttempt: root.batch: <memory:16384, vCores:8>
2016-08-21 14:53:58,011 INFO org.apache.hadoop.yarn.server.resourcemanager.scheduler.fair.FSAppAttempt: appattempt_1471812677892_0001_000001 minReqResource: <memory:0, vCores:0> flexibleResource: <memory:16384, vCores:8>
2016-08-21 14:53:58,011 INFO org.apache.hadoop.yarn.server.resourcemanager.scheduler.fair.FairScheduler: allocate resource to application attempt: appattempt_1471812677892_0001_000001 queue:root.batch isRunning=true 
2016-08-21 14:53:58,011 INFO org.apache.hadoop.yarn.server.resourcemanager.scheduler.fair.FairScheduler: iglf: 1.getHeadroom()=<memory:0, vCores:0>
2016-08-21 14:53:59,997 INFO org.apache.hadoop.yarn.server.resourcemanager.scheduler.fair.FairScheduler: allocate(appattempt_1471812677892_0001_000001 [{Priority: 1, Capability: <memory:1920, vCores:1>, # Containers: 248, Location: *, Relax Locality: true}] [] [] []
2016-08-21 14:53:59,998 INFO org.apache.hadoop.yarn.server.resourcemanager.scheduler.fair.FSAppAttempt: root.batch: <memory:16384, vCores:8>
2016-08-21 14:53:59,998 INFO org.apache.hadoop.yarn.server.resourcemanager.scheduler.fair.FSAppAttempt: appattempt_1471812677892_0001_000001 minReqResource: <memory:0, vCores:0> flexibleResource: <memory:16384, vCores:8>
2016-08-21 14:53:59,998 INFO org.apache.hadoop.yarn.server.resourcemanager.scheduler.fair.FairScheduler: allocate resource to application attempt: appattempt_1471812677892_0001_000001 queue:root.batch isRunning=true 
2016-08-21 14:53:59,998 INFO org.apache.hadoop.yarn.server.resourcemanager.scheduler.fair.FairScheduler: iglf: 1.getHeadroom()=<memory:0, vCores:0>
2016-08-21 14:54:00,201 INFO org.apache.hadoop.yarn.server.resourcemanager.scheduler.fair.FairScheduler: allocate(appattempt_1471812677892_0001_000001 [] [] [] []
2016-08-21 14:54:00,202 INFO org.apache.hadoop.yarn.server.resourcemanager.scheduler.fair.FSAppAttempt: root.batch: <memory:16384, vCores:8>
2016-08-21 14:54:00,202 INFO org.apache.hadoop.yarn.server.resourcemanager.scheduler.fair.FSAppAttempt: appattempt_1471812677892_0001_000001 minReqResource: <memory:0, vCores:0> flexibleResource: <memory:16384, vCores:8>
2016-08-21 14:54:00,202 INFO org.apache.hadoop.yarn.server.resourcemanager.scheduler.fair.FairScheduler: allocate resource to application attempt: appattempt_1471812677892_0001_000001 queue:root.batch isRunning=true 
2016-08-21 14:54:00,202 INFO org.apache.hadoop.yarn.server.resourcemanager.scheduler.fair.FairScheduler: iglf: 1.getHeadroom()=<memory:0, vCores:0>
2016-08-21 14:54:00,606 INFO org.apache.hadoop.yarn.server.resourcemanager.scheduler.fair.FairScheduler: allocate(appattempt_1471812677892_0001_000001 [] [] [] []
2016-08-21 14:54:00,606 INFO org.apache.hadoop.yarn.server.resourcemanager.scheduler.fair.FSAppAttempt: root.batch: <memory:16384, vCores:8>
2016-08-21 14:54:00,606 INFO org.apache.hadoop.yarn.server.resourcemanager.scheduler.fair.FSAppAttempt: appattempt_1471812677892_0001_000001 minReqResource: <memory:0, vCores:0> flexibleResource: <memory:16384, vCores:8>
2016-08-21 14:54:00,606 INFO org.apache.hadoop.yarn.server.resourcemanager.scheduler.fair.FairScheduler: allocate resource to application attempt: appattempt_1471812677892_0001_000001 queue:root.batch isRunning=true 
2016-08-21 14:54:00,606 INFO org.apache.hadoop.yarn.server.resourcemanager.scheduler.fair.FairScheduler: iglf: 1.getHeadroom()=<memory:0, vCores:0>
2016-08-21 14:54:00,804 INFO org.apache.hadoop.yarn.server.resourcemanager.ClientRMService: Allocated new applicationId: 3
2016-08-21 14:54:01,055 INFO org.apache.hadoop.yarn.server.resourcemanager.ClientRMService: Allocated new applicationId: 4
2016-08-21 14:54:01,283 INFO org.apache.hadoop.yarn.server.resourcemanager.ClientRMService: Allocated new applicationId: 5
2016-08-21 14:54:01,409 INFO org.apache.hadoop.yarn.server.resourcemanager.scheduler.fair.FairScheduler: allocate(appattempt_1471812677892_0001_000001 [] [] [] []
2016-08-21 14:54:01,410 INFO org.apache.hadoop.yarn.server.resourcemanager.scheduler.fair.FSAppAttempt: root.batch: <memory:16384, vCores:8>
2016-08-21 14:54:01,410 INFO org.apache.hadoop.yarn.server.resourcemanager.scheduler.fair.FSAppAttempt: appattempt_1471812677892_0001_000001 minReqResource: <memory:0, vCores:0> flexibleResource: <memory:16384, vCores:8>
2016-08-21 14:54:01,410 INFO org.apache.hadoop.yarn.server.resourcemanager.scheduler.fair.FairScheduler: allocate resource to application attempt: appattempt_1471812677892_0001_000001 queue:root.batch isRunning=true 
2016-08-21 14:54:01,410 INFO org.apache.hadoop.yarn.server.resourcemanager.scheduler.fair.FairScheduler: iglf: 1.getHeadroom()=<memory:0, vCores:0>
2016-08-21 14:54:01,694 INFO org.apache.hadoop.yarn.server.resourcemanager.scheduler.fair.FairScheduler: allocate(appattempt_1471812677892_0001_000001 [{Priority: 1, Capability: <memory:1920, vCores:1>, # Containers: 242, Location: *, Relax Locality: true}] [] [] []
2016-08-21 14:54:01,695 INFO org.apache.hadoop.yarn.server.resourcemanager.scheduler.fair.FSAppAttempt: root.batch: <memory:16384, vCores:8>
2016-08-21 14:54:01,695 INFO org.apache.hadoop.yarn.server.resourcemanager.scheduler.fair.FSAppAttempt: appattempt_1471812677892_0001_000001 minReqResource: <memory:0, vCores:0> flexibleResource: <memory:16384, vCores:8>
2016-08-21 14:54:01,695 INFO org.apache.hadoop.yarn.server.resourcemanager.scheduler.fair.FairScheduler: allocate resource to application attempt: appattempt_1471812677892_0001_000001 queue:root.batch isRunning=true 
2016-08-21 14:54:01,695 INFO org.apache.hadoop.yarn.server.resourcemanager.scheduler.fair.FairScheduler: iglf: 1.getHeadroom()=<memory:0, vCores:0>
2016-08-21 14:54:01,788 INFO org.apache.hadoop.yarn.server.resourcemanager.scheduler.fair.FairScheduler: allocate(appattempt_1471812677892_0001_000001 [{Priority: 1, Capability: <memory:1920, vCores:1>, # Containers: 192, Location: *, Relax Locality: true}] [] [] []
2016-08-21 14:54:01,788 INFO org.apache.hadoop.yarn.server.resourcemanager.scheduler.fair.FSAppAttempt: root.batch: <memory:16384, vCores:8>
2016-08-21 14:54:01,788 INFO org.apache.hadoop.yarn.server.resourcemanager.scheduler.fair.FSAppAttempt: appattempt_1471812677892_0001_000001 minReqResource: <memory:0, vCores:0> flexibleResource: <memory:16384, vCores:8>
2016-08-21 14:54:01,788 INFO org.apache.hadoop.yarn.server.resourcemanager.scheduler.fair.FairScheduler: allocate resource to application attempt: appattempt_1471812677892_0001_000001 queue:root.batch isRunning=true 
2016-08-21 14:54:01,789 INFO org.apache.hadoop.yarn.server.resourcemanager.scheduler.fair.FairScheduler: iglf: 1.getHeadroom()=<memory:0, vCores:0>
2016-08-21 14:54:01,887 INFO org.apache.hadoop.yarn.server.resourcemanager.scheduler.fair.FairScheduler: allocate(appattempt_1471812677892_0001_000001 [{Priority: 1, Capability: <memory:1920, vCores:1>, # Containers: 144, Location: *, Relax Locality: true}] [] [] []
2016-08-21 14:54:01,887 INFO org.apache.hadoop.yarn.server.resourcemanager.scheduler.fair.FSAppAttempt: root.batch: <memory:16384, vCores:8>
2016-08-21 14:54:01,887 INFO org.apache.hadoop.yarn.server.resourcemanager.scheduler.fair.FSAppAttempt: appattempt_1471812677892_0001_000001 minReqResource: <memory:0, vCores:0> flexibleResource: <memory:16384, vCores:8>
2016-08-21 14:54:01,887 INFO org.apache.hadoop.yarn.server.resourcemanager.scheduler.fair.FairScheduler: allocate resource to application attempt: appattempt_1471812677892_0001_000001 queue:root.batch isRunning=true 
2016-08-21 14:54:01,888 INFO org.apache.hadoop.yarn.server.resourcemanager.scheduler.fair.FairScheduler: iglf: 1.getHeadroom()=<memory:0, vCores:0>
2016-08-21 14:54:01,988 INFO org.apache.hadoop.yarn.server.resourcemanager.scheduler.fair.FairScheduler: allocate(appattempt_1471812677892_0001_000001 [{Priority: 1, Capability: <memory:1920, vCores:1>, # Containers: 97, Location: *, Relax Locality: true}] [] [] []
2016-08-21 14:54:01,988 INFO org.apache.hadoop.yarn.server.resourcemanager.scheduler.fair.FSAppAttempt: root.batch: <memory:16384, vCores:8>
2016-08-21 14:54:01,988 INFO org.apache.hadoop.yarn.server.resourcemanager.scheduler.fair.FSAppAttempt: appattempt_1471812677892_0001_000001 minReqResource: <memory:0, vCores:0> flexibleResource: <memory:16384, vCores:8>
2016-08-21 14:54:01,988 INFO org.apache.hadoop.yarn.server.resourcemanager.scheduler.fair.FairScheduler: allocate resource to application attempt: appattempt_1471812677892_0001_000001 queue:root.batch isRunning=true 
2016-08-21 14:54:01,988 INFO org.apache.hadoop.yarn.server.resourcemanager.scheduler.fair.FairScheduler: iglf: 1.getHeadroom()=<memory:0, vCores:0>
2016-08-21 14:54:02,088 INFO org.apache.hadoop.yarn.server.resourcemanager.scheduler.fair.FairScheduler: allocate(appattempt_1471812677892_0001_000001 [{Priority: 1, Capability: <memory:1920, vCores:1>, # Containers: 53, Location: *, Relax Locality: true}] [] [] []
2016-08-21 14:54:02,088 INFO org.apache.hadoop.yarn.server.resourcemanager.scheduler.fair.FSAppAttempt: root.batch: <memory:16384, vCores:8>
2016-08-21 14:54:02,088 INFO org.apache.hadoop.yarn.server.resourcemanager.scheduler.fair.FSAppAttempt: appattempt_1471812677892_0001_000001 minReqResource: <memory:0, vCores:0> flexibleResource: <memory:16384, vCores:8>
2016-08-21 14:54:02,088 INFO org.apache.hadoop.yarn.server.resourcemanager.scheduler.fair.FairScheduler: allocate resource to application attempt: appattempt_1471812677892_0001_000001 queue:root.batch isRunning=true 
2016-08-21 14:54:02,089 INFO org.apache.hadoop.yarn.server.resourcemanager.scheduler.fair.FairScheduler: iglf: 1.getHeadroom()=<memory:0, vCores:0>
2016-08-21 14:54:02,187 INFO org.apache.hadoop.yarn.server.resourcemanager.scheduler.fair.FairScheduler: allocate(appattempt_1471812677892_0001_000001 [{Priority: 1, Capability: <memory:1920, vCores:1>, # Containers: 6, Location: *, Relax Locality: true}] [] [] []
2016-08-21 14:54:02,187 INFO org.apache.hadoop.yarn.server.resourcemanager.scheduler.fair.FSAppAttempt: root.batch: <memory:16384, vCores:8>
2016-08-21 14:54:02,187 INFO org.apache.hadoop.yarn.server.resourcemanager.scheduler.fair.FSAppAttempt: appattempt_1471812677892_0001_000001 minReqResource: <memory:0, vCores:0> flexibleResource: <memory:16384, vCores:8>
2016-08-21 14:54:02,187 INFO org.apache.hadoop.yarn.server.resourcemanager.scheduler.fair.FairScheduler: allocate resource to application attempt: appattempt_1471812677892_0001_000001 queue:root.batch isRunning=true 
2016-08-21 14:54:02,187 INFO org.apache.hadoop.yarn.server.resourcemanager.scheduler.fair.FairScheduler: iglf: 1.getHeadroom()=<memory:0, vCores:0>
2016-08-21 14:54:02,273 INFO org.apache.hadoop.yarn.server.resourcemanager.scheduler.fair.FairScheduler: allocate(appattempt_1471812677892_0001_000001 [{Priority: 1, Capability: <memory:1920, vCores:1>, # Containers: 0, Location: *, Relax Locality: true}] [] [] []
2016-08-21 14:54:02,273 INFO org.apache.hadoop.yarn.server.resourcemanager.scheduler.fair.FSAppAttempt: root.batch: <memory:16384, vCores:8>
2016-08-21 14:54:02,273 INFO org.apache.hadoop.yarn.server.resourcemanager.scheduler.fair.FSAppAttempt: appattempt_1471812677892_0001_000001 minReqResource: <memory:0, vCores:0> flexibleResource: <memory:16384, vCores:8>
2016-08-21 14:54:02,273 INFO org.apache.hadoop.yarn.server.resourcemanager.scheduler.fair.FairScheduler: allocate resource to application attempt: appattempt_1471812677892_0001_000001 queue:root.batch isRunning=true 
2016-08-21 14:54:02,273 INFO org.apache.hadoop.yarn.server.resourcemanager.scheduler.AppSchedulingInfo: checking for deactivate of application :application_1471812677892_0001
2016-08-21 14:54:02,273 INFO org.apache.hadoop.yarn.server.resourcemanager.scheduler.fair.FairScheduler: iglf: 1.getHeadroom()=<memory:0, vCores:0>
2016-08-21 14:54:02,337 INFO org.apache.hadoop.yarn.server.resourcemanager.rmapp.attempt.RMAppAttemptImpl: Updating application attempt appattempt_1471812677892_0001_000001 with final state: FINISHING, and exit status: -1000
2016-08-21 14:54:02,337 INFO org.apache.hadoop.yarn.server.resourcemanager.rmapp.attempt.RMAppAttemptImpl: appattempt_1471812677892_0001_000001 State change from RUNNING to FINAL_SAVING
2016-08-21 14:54:02,338 INFO org.apache.hadoop.yarn.server.resourcemanager.rmapp.RMAppImpl: Updating application application_1471812677892_0001 with final state: FINISHING
2016-08-21 14:54:02,339 INFO org.apache.hadoop.yarn.server.resourcemanager.recovery.RMStateStore: Updating info for app: application_1471812677892_0001
2016-08-21 14:54:02,339 INFO org.apache.hadoop.yarn.server.resourcemanager.rmapp.attempt.RMAppAttemptImpl: appattempt_1471812677892_0001_000001 State change from FINAL_SAVING to FINISHING
2016-08-21 14:54:02,444 INFO org.apache.hadoop.yarn.server.resourcemanager.ApplicationMasterService: application_1471812677892_0001 unregistered successfully. 
2016-08-21 14:54:03,274 INFO org.apache.hadoop.yarn.server.resourcemanager.rmcontainer.RMContainerImpl: Processing container_1471812677892_0001_01_000006 of event FINISHED
2016-08-21 14:54:03,274 INFO org.apache.hadoop.yarn.server.resourcemanager.rmcontainer.RMContainerImpl: container_1471812677892_0001_01_000006 Container Transitioned from RUNNING to COMPLETED
2016-08-21 14:54:03,275 INFO org.apache.hadoop.yarn.server.resourcemanager.scheduler.fair.FSAppAttempt: Completed container: container_1471812677892_0001_01_000006 in state: COMPLETED event:FINISHED
2016-08-21 14:54:03,275 INFO org.apache.hadoop.yarn.server.resourcemanager.RMAuditLogger: USER=tanle	OPERATION=AM Released Container	TARGET=SchedulerApp	RESULT=SUCCESS	APPID=application_1471812677892_0001	CONTAINERID=container_1471812677892_0001_01_000006
2016-08-21 14:54:03,275 INFO org.apache.hadoop.yarn.server.resourcemanager.scheduler.SchedulerNode: Released container container_1471812677892_0001_01_000006 of capacity <memory:2048, vCores:1> on host c220g1-031106.wisc.cloudlab.us:33388, which currently has 3 containers, <memory:6144, vCores:3> used and <memory:2048, vCores:1> available, release resources=true
2016-08-21 14:54:03,275 INFO org.apache.hadoop.yarn.server.resourcemanager.scheduler.fair.FairScheduler: Application attempt appattempt_1471812677892_0001_000001 released container container_1471812677892_0001_01_000006 on node: host: c220g1-031106.wisc.cloudlab.us:33388 #containers=3 available=<memory:2048, vCores:1> used=<memory:6144, vCores:3> with event: FINISHED
2016-08-21 14:54:03,275 INFO org.apache.hadoop.yarn.server.resourcemanager.rmcontainer.RMContainerImpl: Processing container_1471812677892_0001_01_000008 of event FINISHED
2016-08-21 14:54:03,275 INFO org.apache.hadoop.yarn.server.resourcemanager.rmcontainer.RMContainerImpl: container_1471812677892_0001_01_000008 Container Transitioned from RUNNING to COMPLETED
2016-08-21 14:54:03,275 INFO org.apache.hadoop.yarn.server.resourcemanager.scheduler.fair.FSAppAttempt: Completed container: container_1471812677892_0001_01_000008 in state: COMPLETED event:FINISHED
2016-08-21 14:54:03,275 INFO org.apache.hadoop.yarn.server.resourcemanager.RMAuditLogger: USER=tanle	OPERATION=AM Released Container	TARGET=SchedulerApp	RESULT=SUCCESS	APPID=application_1471812677892_0001	CONTAINERID=container_1471812677892_0001_01_000008
2016-08-21 14:54:03,276 INFO org.apache.hadoop.yarn.server.resourcemanager.scheduler.SchedulerNode: Released container container_1471812677892_0001_01_000008 of capacity <memory:2048, vCores:1> on host c220g1-031106.wisc.cloudlab.us:33388, which currently has 2 containers, <memory:4096, vCores:2> used and <memory:4096, vCores:2> available, release resources=true
2016-08-21 14:54:03,276 INFO org.apache.hadoop.yarn.server.resourcemanager.scheduler.fair.FairScheduler: Application attempt appattempt_1471812677892_0001_000001 released container container_1471812677892_0001_01_000008 on node: host: c220g1-031106.wisc.cloudlab.us:33388 #containers=2 available=<memory:4096, vCores:2> used=<memory:4096, vCores:2> with event: FINISHED
2016-08-21 14:54:03,276 INFO org.apache.hadoop.yarn.server.resourcemanager.rmcontainer.RMContainerImpl: Processing container_1471812677892_0001_01_000001 of event FINISHED
2016-08-21 14:54:03,276 INFO org.apache.hadoop.yarn.server.resourcemanager.rmcontainer.RMContainerImpl: container_1471812677892_0001_01_000001 Container Transitioned from RUNNING to COMPLETED
2016-08-21 14:54:03,276 INFO org.apache.hadoop.yarn.server.resourcemanager.ApplicationMasterService: Unregistering app attempt : appattempt_1471812677892_0001_000001
2016-08-21 14:54:03,276 INFO org.apache.hadoop.yarn.server.resourcemanager.scheduler.fair.FSAppAttempt: Completed container: container_1471812677892_0001_01_000001 in state: COMPLETED event:FINISHED
2016-08-21 14:54:03,276 INFO org.apache.hadoop.yarn.server.resourcemanager.RMAuditLogger: USER=tanle	OPERATION=AM Released Container	TARGET=SchedulerApp	RESULT=SUCCESS	APPID=application_1471812677892_0001	CONTAINERID=container_1471812677892_0001_01_000001
2016-08-21 14:54:03,276 INFO org.apache.hadoop.yarn.server.resourcemanager.scheduler.SchedulerNode: Released container container_1471812677892_0001_01_000001 of capacity <memory:2048, vCores:1> on host c220g1-031106.wisc.cloudlab.us:33388, which currently has 1 containers, <memory:2048, vCores:1> used and <memory:6144, vCores:3> available, release resources=true
2016-08-21 14:54:03,276 INFO org.apache.hadoop.yarn.server.resourcemanager.scheduler.fair.FairScheduler: Application attempt appattempt_1471812677892_0001_000001 released container container_1471812677892_0001_01_000001 on node: host: c220g1-031106.wisc.cloudlab.us:33388 #containers=1 available=<memory:6144, vCores:3> used=<memory:2048, vCores:1> with event: FINISHED
2016-08-21 14:54:03,277 INFO org.apache.hadoop.yarn.server.resourcemanager.rmcontainer.RMContainerImpl: Processing container_1471812677892_0001_01_000004 of event FINISHED
2016-08-21 14:54:03,277 INFO org.apache.hadoop.yarn.server.resourcemanager.rmcontainer.RMContainerImpl: container_1471812677892_0001_01_000004 Container Transitioned from RUNNING to COMPLETED
2016-08-21 14:54:03,277 INFO org.apache.hadoop.yarn.server.resourcemanager.scheduler.fair.FSAppAttempt: Completed container: container_1471812677892_0001_01_000004 in state: COMPLETED event:FINISHED
2016-08-21 14:54:03,277 INFO org.apache.hadoop.yarn.server.resourcemanager.RMAuditLogger: USER=tanle	OPERATION=AM Released Container	TARGET=SchedulerApp	RESULT=SUCCESS	APPID=application_1471812677892_0001	CONTAINERID=container_1471812677892_0001_01_000004
2016-08-21 14:54:03,277 INFO org.apache.hadoop.yarn.server.resourcemanager.scheduler.SchedulerNode: Released container container_1471812677892_0001_01_000004 of capacity <memory:2048, vCores:1> on host c220g1-031106.wisc.cloudlab.us:33388, which currently has 0 containers, <memory:0, vCores:0> used and <memory:8192, vCores:4> available, release resources=true
2016-08-21 14:54:03,277 INFO org.apache.hadoop.yarn.server.resourcemanager.scheduler.fair.FairScheduler: Application attempt appattempt_1471812677892_0001_000001 released container container_1471812677892_0001_01_000004 on node: host: c220g1-031106.wisc.cloudlab.us:33388 #containers=0 available=<memory:8192, vCores:4> used=<memory:0, vCores:0> with event: FINISHED
2016-08-21 14:54:03,277 INFO org.apache.hadoop.yarn.server.resourcemanager.scheduler.fair.FSAppAttempt: assignContainer(FSSchedulerNode node:c220g1-031106.wisc.cloudlab.us, boolean reserved=true) for appattempt_1471812677892_0002_000001
2016-08-21 14:54:03,277 INFO org.apache.hadoop.yarn.server.resourcemanager.security.AMRMTokenSecretManager: Application finished, removing password for appattempt_1471812677892_0001_000001
2016-08-21 14:54:03,278 INFO org.apache.hadoop.yarn.server.resourcemanager.scheduler.fair.FSAppAttempt: assignContainer(FSSchedulerNode:c220g1-031106.wisc.cloudlab.us, ResourceRequest request, NodeType type, boolean reserved=true
2016-08-21 14:54:03,278 INFO org.apache.hadoop.yarn.server.resourcemanager.scheduler.fair.FSAppAttempt: allocate container: container_1471812677892_0002_01_000002 priority 0
2016-08-21 14:54:03,278 INFO org.apache.hadoop.yarn.server.resourcemanager.rmcontainer.RMContainerImpl: Processing container_1471812677892_0002_01_000002 of event START
2016-08-21 14:54:03,278 INFO org.apache.hadoop.yarn.server.resourcemanager.rmcontainer.RMContainerImpl: container_1471812677892_0002_01_000002 Container Transitioned from NEW to ALLOCATED
2016-08-21 14:54:03,278 INFO org.apache.hadoop.yarn.server.resourcemanager.RMAuditLogger: USER=tanle	OPERATION=AM Allocated Container	TARGET=SchedulerApp	RESULT=SUCCESS	APPID=application_1471812677892_0002	CONTAINERID=container_1471812677892_0002_01_000002
2016-08-21 14:54:03,278 INFO org.apache.hadoop.yarn.server.resourcemanager.scheduler.fair.FSAppAttempt: Application application_1471812677892_0002 unreserved  on node host: c220g1-031106.wisc.cloudlab.us:33388 #containers=0 available=<memory:8192, vCores:4> used=<memory:0, vCores:0>, currently has 1 at priority 0; currentReservation <memory:2048, vCores:1>
2016-08-21 14:54:03,279 INFO org.apache.hadoop.yarn.server.resourcemanager.scheduler.SchedulerNode: Assigned container container_1471812677892_0002_01_000002 of capacity <memory:2048, vCores:1> on host c220g1-031106.wisc.cloudlab.us:33388, which has 1 containers, <memory:2048, vCores:1> used and <memory:6144, vCores:3> available after allocation
2016-08-21 14:54:03,279 INFO org.apache.hadoop.yarn.server.resourcemanager.rmapp.attempt.RMAppAttemptImpl: appattempt_1471812677892_0001_000001 State change from FINISHING to FINISHED
2016-08-21 14:54:03,279 INFO org.apache.hadoop.yarn.server.resourcemanager.rmcontainer.RMContainerImpl: Processing container_1471812677892_0001_01_000002 of event FINISHED
2016-08-21 14:54:03,279 INFO org.apache.hadoop.yarn.server.resourcemanager.rmcontainer.RMContainerImpl: container_1471812677892_0001_01_000002 Container Transitioned from RUNNING to COMPLETED
2016-08-21 14:54:03,279 INFO org.apache.hadoop.yarn.server.resourcemanager.scheduler.fair.FSAppAttempt: Completed container: container_1471812677892_0001_01_000002 in state: COMPLETED event:FINISHED
2016-08-21 14:54:03,279 INFO org.apache.hadoop.yarn.server.resourcemanager.RMAuditLogger: USER=tanle	OPERATION=AM Released Container	TARGET=SchedulerApp	RESULT=SUCCESS	APPID=application_1471812677892_0001	CONTAINERID=container_1471812677892_0001_01_000002
2016-08-21 14:54:03,279 INFO org.apache.hadoop.yarn.server.resourcemanager.scheduler.SchedulerNode: Released container container_1471812677892_0001_01_000002 of capacity <memory:2048, vCores:1> on host cp-1.yarn-perf.yarnrm-PG0.wisc.cloudlab.us:39022, which currently has 3 containers, <memory:6144, vCores:3> used and <memory:2048, vCores:1> available, release resources=true
2016-08-21 14:54:03,279 INFO org.apache.hadoop.yarn.server.resourcemanager.scheduler.fair.FairScheduler: Application attempt appattempt_1471812677892_0001_000001 released container container_1471812677892_0001_01_000002 on node: host: cp-1.yarn-perf.yarnrm-PG0.wisc.cloudlab.us:39022 #containers=3 available=<memory:2048, vCores:1> used=<memory:6144, vCores:3> with event: FINISHED
2016-08-21 14:54:03,280 INFO org.apache.hadoop.yarn.server.resourcemanager.rmcontainer.RMContainerImpl: Processing container_1471812677892_0001_01_000007 of event FINISHED
2016-08-21 14:54:03,280 INFO org.apache.hadoop.yarn.server.resourcemanager.rmcontainer.RMContainerImpl: container_1471812677892_0001_01_000007 Container Transitioned from RUNNING to COMPLETED
2016-08-21 14:54:03,280 INFO org.apache.hadoop.yarn.server.resourcemanager.scheduler.fair.FSAppAttempt: Completed container: container_1471812677892_0001_01_000007 in state: COMPLETED event:FINISHED
2016-08-21 14:54:03,280 INFO org.apache.hadoop.yarn.server.resourcemanager.RMAuditLogger: USER=tanle	OPERATION=AM Released Container	TARGET=SchedulerApp	RESULT=SUCCESS	APPID=application_1471812677892_0001	CONTAINERID=container_1471812677892_0001_01_000007
2016-08-21 14:54:03,280 INFO org.apache.hadoop.yarn.server.resourcemanager.scheduler.SchedulerNode: Released container container_1471812677892_0001_01_000007 of capacity <memory:2048, vCores:1> on host cp-1.yarn-perf.yarnrm-PG0.wisc.cloudlab.us:39022, which currently has 2 containers, <memory:4096, vCores:2> used and <memory:4096, vCores:2> available, release resources=true
2016-08-21 14:54:03,280 INFO org.apache.hadoop.yarn.server.resourcemanager.scheduler.fair.FairScheduler: Application attempt appattempt_1471812677892_0001_000001 released container container_1471812677892_0001_01_000007 on node: host: cp-1.yarn-perf.yarnrm-PG0.wisc.cloudlab.us:39022 #containers=2 available=<memory:4096, vCores:2> used=<memory:4096, vCores:2> with event: FINISHED
2016-08-21 14:54:03,280 INFO org.apache.hadoop.yarn.server.resourcemanager.rmcontainer.RMContainerImpl: Processing container_1471812677892_0001_01_000005 of event FINISHED
2016-08-21 14:54:03,281 INFO org.apache.hadoop.yarn.server.resourcemanager.rmcontainer.RMContainerImpl: container_1471812677892_0001_01_000005 Container Transitioned from RUNNING to COMPLETED
2016-08-21 14:54:03,281 INFO org.apache.hadoop.yarn.server.resourcemanager.scheduler.fair.FSAppAttempt: Completed container: container_1471812677892_0001_01_000005 in state: COMPLETED event:FINISHED
2016-08-21 14:54:03,281 INFO org.apache.hadoop.yarn.server.resourcemanager.RMAuditLogger: USER=tanle	OPERATION=AM Released Container	TARGET=SchedulerApp	RESULT=SUCCESS	APPID=application_1471812677892_0001	CONTAINERID=container_1471812677892_0001_01_000005
2016-08-21 14:54:03,281 INFO org.apache.hadoop.yarn.server.resourcemanager.scheduler.SchedulerNode: Released container container_1471812677892_0001_01_000005 of capacity <memory:2048, vCores:1> on host cp-1.yarn-perf.yarnrm-PG0.wisc.cloudlab.us:39022, which currently has 1 containers, <memory:2048, vCores:1> used and <memory:6144, vCores:3> available, release resources=true
2016-08-21 14:54:03,281 INFO org.apache.hadoop.yarn.server.resourcemanager.scheduler.fair.FairScheduler: Application attempt appattempt_1471812677892_0001_000001 released container container_1471812677892_0001_01_000005 on node: host: cp-1.yarn-perf.yarnrm-PG0.wisc.cloudlab.us:39022 #containers=1 available=<memory:6144, vCores:3> used=<memory:2048, vCores:1> with event: FINISHED
2016-08-21 14:54:03,281 INFO org.apache.hadoop.yarn.server.resourcemanager.rmcontainer.RMContainerImpl: Processing container_1471812677892_0001_01_000003 of event FINISHED
2016-08-21 14:54:03,281 INFO org.apache.hadoop.yarn.server.resourcemanager.rmcontainer.RMContainerImpl: container_1471812677892_0001_01_000003 Container Transitioned from RUNNING to COMPLETED
2016-08-21 14:54:03,281 INFO org.apache.hadoop.yarn.server.resourcemanager.scheduler.fair.FSAppAttempt: Completed container: container_1471812677892_0001_01_000003 in state: COMPLETED event:FINISHED
2016-08-21 14:54:03,281 INFO org.apache.hadoop.yarn.server.resourcemanager.RMAuditLogger: USER=tanle	OPERATION=AM Released Container	TARGET=SchedulerApp	RESULT=SUCCESS	APPID=application_1471812677892_0001	CONTAINERID=container_1471812677892_0001_01_000003
2016-08-21 14:54:03,281 INFO org.apache.hadoop.yarn.server.resourcemanager.scheduler.SchedulerNode: Released container container_1471812677892_0001_01_000003 of capacity <memory:2048, vCores:1> on host cp-1.yarn-perf.yarnrm-PG0.wisc.cloudlab.us:39022, which currently has 0 containers, <memory:0, vCores:0> used and <memory:8192, vCores:4> available, release resources=true
2016-08-21 14:54:03,282 INFO org.apache.hadoop.yarn.server.resourcemanager.rmapp.attempt.RMAppAttemptImpl: AMContainerAllocatedTransition.transition(appattempt_1471812677892_0002_000001,EventType: CONTAINER_ALLOCATED)
2016-08-21 14:54:03,282 INFO org.apache.hadoop.yarn.server.resourcemanager.scheduler.fair.FairScheduler: Application attempt appattempt_1471812677892_0001_000001 released container container_1471812677892_0001_01_000003 on node: host: cp-1.yarn-perf.yarnrm-PG0.wisc.cloudlab.us:39022 #containers=0 available=<memory:8192, vCores:4> used=<memory:0, vCores:0> with event: FINISHED
2016-08-21 14:54:03,282 INFO org.apache.hadoop.yarn.server.resourcemanager.scheduler.fair.FairScheduler: allocate(appattempt_1471812677892_0002_000001 [] [] null null
2016-08-21 14:54:03,282 INFO org.apache.hadoop.yarn.server.resourcemanager.scheduler.fair.FairScheduler: Releasing reservation that cannot be satisfied for application appattempt_1471812677892_0002_000001 on node host: cp-1.yarn-perf.yarnrm-PG0.wisc.cloudlab.us:39022 #containers=0 available=<memory:8192, vCores:4> used=<memory:0, vCores:0>
2016-08-21 14:54:03,282 INFO org.apache.hadoop.yarn.server.resourcemanager.scheduler.fair.FSAppAttempt: root.batch: <memory:2048, vCores:1>
2016-08-21 14:54:03,282 INFO org.apache.hadoop.yarn.server.resourcemanager.scheduler.fair.FSAppAttempt: appattempt_1471812677892_0002_000001 minReqResource: <memory:0, vCores:0> flexibleResource: <memory:16384, vCores:8>
2016-08-21 14:54:03,282 INFO org.apache.hadoop.yarn.server.resourcemanager.scheduler.fair.FSAppAttempt: Application application_1471812677892_0002 unreserved  on node host: cp-1.yarn-perf.yarnrm-PG0.wisc.cloudlab.us:39022 #containers=0 available=<memory:8192, vCores:4> used=<memory:0, vCores:0>, currently has 0 at priority 0; currentReservation <memory:0, vCores:0>
2016-08-21 14:54:03,282 INFO org.apache.hadoop.yarn.server.resourcemanager.scheduler.fair.FairScheduler: allocate resource to application attempt: appattempt_1471812677892_0002_000001 queue:root.batch isRunning=true 
2016-08-21 14:54:03,282 INFO org.apache.hadoop.yarn.server.resourcemanager.amlauncher.AMLauncher: Cleaning master appattempt_1471812677892_0001_000001
2016-08-21 14:54:03,282 INFO org.apache.hadoop.yarn.server.resourcemanager.scheduler.fair.FSAppAttempt: assignContainer(FSSchedulerNode node:cp-1.yarn-perf.yarnrm-PG0.wisc.cloudlab.us, boolean reserved=false) for appattempt_1471812677892_0001_000001
2016-08-21 14:54:03,282 INFO org.apache.hadoop.yarn.server.resourcemanager.scheduler.fair.FSAppAttempt: assignContainer(FSSchedulerNode node:cp-1.yarn-perf.yarnrm-PG0.wisc.cloudlab.us, boolean reserved=false) for appattempt_1471812677892_0002_000001
2016-08-21 14:54:03,284 INFO org.apache.hadoop.yarn.server.resourcemanager.security.NMTokenSecretManagerInRM: Sending NMToken for nodeId : c220g1-031106.wisc.cloudlab.us:33388 for container : container_1471812677892_0002_01_000002
2016-08-21 14:54:03,284 INFO org.apache.hadoop.yarn.server.resourcemanager.rmcontainer.RMContainerImpl: Processing container_1471812677892_0002_01_000002 of event ACQUIRED
2016-08-21 14:54:03,284 INFO org.apache.hadoop.yarn.server.resourcemanager.rmcontainer.RMContainerImpl: container_1471812677892_0002_01_000002 Container Transitioned from ALLOCATED to ACQUIRED
2016-08-21 14:54:03,285 INFO org.apache.hadoop.yarn.server.resourcemanager.scheduler.fair.FairScheduler: iglf: 2.getHeadroom()=<memory:14336, vCores:7>
2016-08-21 14:54:03,285 INFO org.apache.hadoop.yarn.server.resourcemanager.security.NMTokenSecretManagerInRM: Clear node set for appattempt_1471812677892_0002_000001
2016-08-21 14:54:03,285 INFO org.apache.hadoop.yarn.server.resourcemanager.scheduler.fair.FairScheduler: Application appattempt_1471812677892_0001_000001 is done. finalState=FINISHED
2016-08-21 14:54:03,285 INFO org.apache.hadoop.yarn.server.resourcemanager.rmapp.attempt.RMAppAttemptImpl: Storing attempt: AppId: application_1471812677892_0002 AttemptId: appattempt_1471812677892_0002_000001 MasterContainer: Container: [ContainerId: container_1471812677892_0002_01_000002, NodeId: c220g1-031106.wisc.cloudlab.us:33388, NodeHttpAddress: c220g1-031106.wisc.cloudlab.us:8042, Resource: <memory:2048, vCores:1>, Priority: 0, Token: Token { kind: ContainerToken, service: 128.104.222.16:33388 }, ]
2016-08-21 14:54:03,285 INFO org.apache.hadoop.yarn.server.resourcemanager.rmapp.attempt.RMAppAttemptImpl: appattempt_1471812677892_0002_000001 State change from SCHEDULED to ALLOCATED_SAVING
2016-08-21 14:54:03,285 INFO org.apache.hadoop.yarn.server.resourcemanager.scheduler.AppSchedulingInfo: Application application_1471812677892_0001 requests cleared
2016-08-21 14:54:03,285 INFO org.apache.hadoop.yarn.server.resourcemanager.scheduler.fair.FSLeafQueue: queue: root.batch include 1 active apps: [org.apache.hadoop.yarn.server.resourcemanager.scheduler.fair.FSAppAttempt@5f3ad072]
2016-08-21 14:54:03,286 INFO org.apache.hadoop.yarn.server.resourcemanager.RMAuditLogger: USER=tanle	OPERATION=Application Finished - Succeeded	TARGET=RMAppManager	RESULT=SUCCESS	APPID=application_1471812677892_0001
2016-08-21 14:54:03,286 INFO org.apache.hadoop.yarn.server.resourcemanager.scheduler.fair.FairScheduler: remove application attempt appattempt_1471812677892_0001_000001 in queue: [root.batch, demand=<memory:18432, vCores:9>, running=<memory:2048, vCores:1>, share=<memory:16384, vCores:8>, w=<memory weight=1.0, cpu weight=1.0>]
2016-08-21 14:54:03,287 INFO org.apache.hadoop.yarn.server.resourcemanager.RMAppManager$ApplicationSummary: appId=application_1471812677892_0001,name=org.apache.spark.examples.SparkPi,user=tanle,queue=root.batch,state=FINISHED,trackingUrl=http://nm.yarn-perf.yarnrm-pg0.wisc.cloudlab.us:8088/proxy/application_1471812677892_0001/,appMasterHost=128.104.222.16,startTime=1471812790917,finishTime=1471812842338,finalStatus=SUCCEEDED,memorySeconds=546503,vcoreSeconds=266,preemptedAMContainers=0,preemptedNonAMContainers=0,preemptedResources=<memory:0\, vCores:0>,applicationType=SPARK
2016-08-21 14:54:03,287 INFO org.apache.hadoop.yarn.server.resourcemanager.rmapp.attempt.RMAppAttemptImpl: appattempt_1471812677892_0002_000001 State change from ALLOCATED_SAVING to ALLOCATED
2016-08-21 14:54:03,288 INFO org.apache.hadoop.yarn.server.resourcemanager.amlauncher.AMLauncher: Launching masterappattempt_1471812677892_0002_000001
2016-08-21 14:54:03,291 INFO org.apache.hadoop.yarn.server.resourcemanager.amlauncher.AMLauncher: Setting up container Container: [ContainerId: container_1471812677892_0002_01_000002, NodeId: c220g1-031106.wisc.cloudlab.us:33388, NodeHttpAddress: c220g1-031106.wisc.cloudlab.us:8042, Resource: <memory:2048, vCores:1>, Priority: 0, Token: Token { kind: ContainerToken, service: 128.104.222.16:33388 }, ] for AM appattempt_1471812677892_0002_000001
2016-08-21 14:54:03,292 INFO org.apache.hadoop.yarn.server.resourcemanager.amlauncher.AMLauncher: Command to launch container container_1471812677892_0002_01_000002 : {{JAVA_HOME}}/bin/java,-server,-Xmx1536m,-Djava.io.tmpdir={{PWD}}/tmp,-Dspark.yarn.app.container.log.dir=<LOG_DIR>,-XX:MaxPermSize=256m,org.apache.spark.deploy.yarn.ApplicationMaster,--class,'org.apache.spark.examples.SparkPi',--jar,file:/users/tanle/./spark/examples/jars/spark-examples_2.11-2.0.0-preview.jar,--arg,'10000',--properties-file,{{PWD}}/__spark_conf__/__spark_conf__.properties,1>,<LOG_DIR>/stdout,2>,<LOG_DIR>/stderr
2016-08-21 14:54:03,292 INFO org.apache.hadoop.yarn.server.resourcemanager.security.AMRMTokenSecretManager: Create AMRMToken for ApplicationAttempt: appattempt_1471812677892_0002_000001
2016-08-21 14:54:03,292 INFO org.apache.hadoop.yarn.server.resourcemanager.security.AMRMTokenSecretManager: Creating password for appattempt_1471812677892_0002_000001
2016-08-21 14:54:03,345 INFO org.apache.hadoop.yarn.server.resourcemanager.scheduler.fair.FSAppAttempt: assignContainer(FSSchedulerNode node:c220g1-031106.wisc.cloudlab.us, boolean reserved=false) for appattempt_1471812677892_0002_000001
2016-08-21 14:54:03,346 INFO org.apache.hadoop.yarn.server.resourcemanager.amlauncher.AMLauncher: Done launching container Container: [ContainerId: container_1471812677892_0002_01_000002, NodeId: c220g1-031106.wisc.cloudlab.us:33388, NodeHttpAddress: c220g1-031106.wisc.cloudlab.us:8042, Resource: <memory:2048, vCores:1>, Priority: 0, Token: Token { kind: ContainerToken, service: 128.104.222.16:33388 }, ] for AM appattempt_1471812677892_0002_000001
2016-08-21 14:54:03,347 INFO org.apache.hadoop.yarn.server.resourcemanager.rmapp.attempt.RMAppAttemptImpl: appattempt_1471812677892_0002_000001 State change from ALLOCATED to LAUNCHED
2016-08-21 14:54:04,277 INFO org.apache.hadoop.yarn.server.resourcemanager.scheduler.fair.FSAppAttempt: assignContainer(FSSchedulerNode node:cp-1.yarn-perf.yarnrm-PG0.wisc.cloudlab.us, boolean reserved=false) for appattempt_1471812677892_0002_000001
2016-08-21 14:54:04,351 INFO org.apache.hadoop.yarn.server.resourcemanager.rmcontainer.RMContainerImpl: Processing container_1471812677892_0002_01_000002 of event LAUNCHED
2016-08-21 14:54:04,351 INFO org.apache.hadoop.yarn.server.resourcemanager.rmcontainer.RMContainerImpl: container_1471812677892_0002_01_000002 Container Transitioned from ACQUIRED to RUNNING
2016-08-21 14:54:04,352 INFO org.apache.hadoop.yarn.server.resourcemanager.scheduler.fair.FairScheduler: Null container completed...
2016-08-21 14:54:04,352 INFO org.apache.hadoop.yarn.server.resourcemanager.scheduler.fair.FairScheduler: Null container completed...
2016-08-21 14:54:04,353 INFO org.apache.hadoop.yarn.server.resourcemanager.scheduler.fair.FairScheduler: Null container completed...
2016-08-21 14:54:04,353 INFO org.apache.hadoop.yarn.server.resourcemanager.scheduler.fair.FSAppAttempt: assignContainer(FSSchedulerNode node:c220g1-031106.wisc.cloudlab.us, boolean reserved=false) for appattempt_1471812677892_0002_000001
2016-08-21 14:54:05,274 INFO org.apache.hadoop.yarn.server.resourcemanager.ClientRMService: Allocated new applicationId: 6
2016-08-21 14:54:05,283 INFO org.apache.hadoop.yarn.server.resourcemanager.scheduler.fair.FairScheduler: Null container completed...
2016-08-21 14:54:05,283 INFO org.apache.hadoop.yarn.server.resourcemanager.scheduler.fair.FairScheduler: Null container completed...
2016-08-21 14:54:05,284 INFO org.apache.hadoop.yarn.server.resourcemanager.scheduler.fair.FairScheduler: Null container completed...
2016-08-21 14:54:05,284 INFO org.apache.hadoop.yarn.server.resourcemanager.scheduler.fair.FairScheduler: Null container completed...
2016-08-21 14:54:05,284 INFO org.apache.hadoop.yarn.server.resourcemanager.scheduler.fair.FSAppAttempt: assignContainer(FSSchedulerNode node:cp-1.yarn-perf.yarnrm-PG0.wisc.cloudlab.us, boolean reserved=false) for appattempt_1471812677892_0002_000001
2016-08-21 14:54:05,354 INFO org.apache.hadoop.yarn.server.resourcemanager.scheduler.fair.FSAppAttempt: assignContainer(FSSchedulerNode node:c220g1-031106.wisc.cloudlab.us, boolean reserved=false) for appattempt_1471812677892_0002_000001
2016-08-21 14:54:06,286 INFO org.apache.hadoop.yarn.server.resourcemanager.scheduler.fair.FSAppAttempt: assignContainer(FSSchedulerNode node:cp-1.yarn-perf.yarnrm-PG0.wisc.cloudlab.us, boolean reserved=false) for appattempt_1471812677892_0002_000001
2016-08-21 14:54:06,356 INFO org.apache.hadoop.yarn.server.resourcemanager.scheduler.fair.FSAppAttempt: assignContainer(FSSchedulerNode node:c220g1-031106.wisc.cloudlab.us, boolean reserved=false) for appattempt_1471812677892_0002_000001
2016-08-21 14:54:07,288 INFO org.apache.hadoop.yarn.server.resourcemanager.scheduler.fair.FSAppAttempt: assignContainer(FSSchedulerNode node:cp-1.yarn-perf.yarnrm-PG0.wisc.cloudlab.us, boolean reserved=false) for appattempt_1471812677892_0002_000001
2016-08-21 14:54:07,360 INFO org.apache.hadoop.yarn.server.resourcemanager.scheduler.fair.FSAppAttempt: assignContainer(FSSchedulerNode node:c220g1-031106.wisc.cloudlab.us, boolean reserved=false) for appattempt_1471812677892_0002_000001
2016-08-21 14:54:08,291 INFO org.apache.hadoop.yarn.server.resourcemanager.scheduler.fair.FSAppAttempt: assignContainer(FSSchedulerNode node:cp-1.yarn-perf.yarnrm-PG0.wisc.cloudlab.us, boolean reserved=false) for appattempt_1471812677892_0002_000001
2016-08-21 14:54:08,363 INFO org.apache.hadoop.yarn.server.resourcemanager.scheduler.fair.FSAppAttempt: assignContainer(FSSchedulerNode node:c220g1-031106.wisc.cloudlab.us, boolean reserved=false) for appattempt_1471812677892_0002_000001
2016-08-21 14:54:09,294 INFO org.apache.hadoop.yarn.server.resourcemanager.scheduler.fair.FSAppAttempt: assignContainer(FSSchedulerNode node:cp-1.yarn-perf.yarnrm-PG0.wisc.cloudlab.us, boolean reserved=false) for appattempt_1471812677892_0002_000001
2016-08-21 14:54:09,365 INFO org.apache.hadoop.yarn.server.resourcemanager.scheduler.fair.FSAppAttempt: assignContainer(FSSchedulerNode node:c220g1-031106.wisc.cloudlab.us, boolean reserved=false) for appattempt_1471812677892_0002_000001
2016-08-21 14:54:10,296 INFO org.apache.hadoop.yarn.server.resourcemanager.scheduler.fair.FSAppAttempt: assignContainer(FSSchedulerNode node:cp-1.yarn-perf.yarnrm-PG0.wisc.cloudlab.us, boolean reserved=false) for appattempt_1471812677892_0002_000001
2016-08-21 14:54:10,367 INFO org.apache.hadoop.yarn.server.resourcemanager.scheduler.fair.FSAppAttempt: assignContainer(FSSchedulerNode node:c220g1-031106.wisc.cloudlab.us, boolean reserved=false) for appattempt_1471812677892_0002_000001
2016-08-21 14:54:11,300 INFO org.apache.hadoop.yarn.server.resourcemanager.scheduler.fair.FSAppAttempt: assignContainer(FSSchedulerNode node:cp-1.yarn-perf.yarnrm-PG0.wisc.cloudlab.us, boolean reserved=false) for appattempt_1471812677892_0002_000001
2016-08-21 14:54:11,370 INFO org.apache.hadoop.yarn.server.resourcemanager.scheduler.fair.FSAppAttempt: assignContainer(FSSchedulerNode node:c220g1-031106.wisc.cloudlab.us, boolean reserved=false) for appattempt_1471812677892_0002_000001
2016-08-21 14:54:12,302 INFO org.apache.hadoop.yarn.server.resourcemanager.scheduler.fair.FSAppAttempt: assignContainer(FSSchedulerNode node:cp-1.yarn-perf.yarnrm-PG0.wisc.cloudlab.us, boolean reserved=false) for appattempt_1471812677892_0002_000001
2016-08-21 14:54:12,373 INFO org.apache.hadoop.yarn.server.resourcemanager.scheduler.fair.FSAppAttempt: assignContainer(FSSchedulerNode node:c220g1-031106.wisc.cloudlab.us, boolean reserved=false) for appattempt_1471812677892_0002_000001
2016-08-21 14:54:13,305 INFO org.apache.hadoop.yarn.server.resourcemanager.scheduler.fair.FSAppAttempt: assignContainer(FSSchedulerNode node:cp-1.yarn-perf.yarnrm-PG0.wisc.cloudlab.us, boolean reserved=false) for appattempt_1471812677892_0002_000001
2016-08-21 14:54:13,375 INFO org.apache.hadoop.yarn.server.resourcemanager.scheduler.fair.FSAppAttempt: assignContainer(FSSchedulerNode node:c220g1-031106.wisc.cloudlab.us, boolean reserved=false) for appattempt_1471812677892_0002_000001
2016-08-21 14:54:14,308 INFO org.apache.hadoop.yarn.server.resourcemanager.scheduler.fair.FSAppAttempt: assignContainer(FSSchedulerNode node:cp-1.yarn-perf.yarnrm-PG0.wisc.cloudlab.us, boolean reserved=false) for appattempt_1471812677892_0002_000001
2016-08-21 14:54:14,378 INFO org.apache.hadoop.yarn.server.resourcemanager.scheduler.fair.FSAppAttempt: assignContainer(FSSchedulerNode node:c220g1-031106.wisc.cloudlab.us, boolean reserved=false) for appattempt_1471812677892_0002_000001
2016-08-21 14:54:15,311 INFO org.apache.hadoop.yarn.server.resourcemanager.scheduler.fair.FSAppAttempt: assignContainer(FSSchedulerNode node:cp-1.yarn-perf.yarnrm-PG0.wisc.cloudlab.us, boolean reserved=false) for appattempt_1471812677892_0002_000001
2016-08-21 14:54:15,380 INFO org.apache.hadoop.yarn.server.resourcemanager.scheduler.fair.FSAppAttempt: assignContainer(FSSchedulerNode node:c220g1-031106.wisc.cloudlab.us, boolean reserved=false) for appattempt_1471812677892_0002_000001
2016-08-21 14:54:16,314 INFO org.apache.hadoop.yarn.server.resourcemanager.scheduler.fair.FSAppAttempt: assignContainer(FSSchedulerNode node:cp-1.yarn-perf.yarnrm-PG0.wisc.cloudlab.us, boolean reserved=false) for appattempt_1471812677892_0002_000001
2016-08-21 14:54:16,382 INFO org.apache.hadoop.yarn.server.resourcemanager.scheduler.fair.FSAppAttempt: assignContainer(FSSchedulerNode node:c220g1-031106.wisc.cloudlab.us, boolean reserved=false) for appattempt_1471812677892_0002_000001
2016-08-21 14:54:17,316 INFO org.apache.hadoop.yarn.server.resourcemanager.scheduler.fair.FSAppAttempt: assignContainer(FSSchedulerNode node:cp-1.yarn-perf.yarnrm-PG0.wisc.cloudlab.us, boolean reserved=false) for appattempt_1471812677892_0002_000001
2016-08-21 14:54:17,385 INFO org.apache.hadoop.yarn.server.resourcemanager.scheduler.fair.FSAppAttempt: assignContainer(FSSchedulerNode node:c220g1-031106.wisc.cloudlab.us, boolean reserved=false) for appattempt_1471812677892_0002_000001
2016-08-21 14:54:17,761 INFO SecurityLogger.org.apache.hadoop.ipc.Server: Auth successful for appattempt_1471812677892_0002_000001 (auth:SIMPLE)
2016-08-21 14:54:17,765 INFO org.apache.hadoop.yarn.server.resourcemanager.ApplicationMasterService: AM registration appattempt_1471812677892_0002_000001
2016-08-21 14:54:17,766 INFO org.apache.hadoop.yarn.server.resourcemanager.RMAuditLogger: USER=tanle	IP=128.104.222.16	OPERATION=Register App Master	TARGET=ApplicationMasterService	RESULT=SUCCESS	APPID=application_1471812677892_0002	APPATTEMPTID=appattempt_1471812677892_0002_000001
2016-08-21 14:54:17,766 INFO org.apache.hadoop.yarn.server.resourcemanager.rmapp.attempt.RMAppAttemptImpl: appattempt_1471812677892_0002_000001 State change from LAUNCHED to RUNNING
2016-08-21 14:54:17,816 INFO org.apache.hadoop.yarn.server.resourcemanager.scheduler.fair.FairScheduler: allocate(appattempt_1471812677892_0002_000001 [] [] [] []
2016-08-21 14:54:17,816 INFO org.apache.hadoop.yarn.server.resourcemanager.scheduler.fair.FSAppAttempt: root.batch: <memory:2048, vCores:1>
2016-08-21 14:54:17,816 INFO org.apache.hadoop.yarn.server.resourcemanager.scheduler.fair.FSAppAttempt: appattempt_1471812677892_0002_000001 minReqResource: <memory:0, vCores:0> flexibleResource: <memory:16384, vCores:8>
2016-08-21 14:54:17,816 INFO org.apache.hadoop.yarn.server.resourcemanager.scheduler.fair.FairScheduler: allocate resource to application attempt: appattempt_1471812677892_0002_000001 queue:root.batch isRunning=true 
2016-08-21 14:54:17,816 INFO org.apache.hadoop.yarn.server.resourcemanager.scheduler.fair.FairScheduler: iglf: 2.getHeadroom()=<memory:14336, vCores:7>
2016-08-21 14:54:17,837 INFO org.apache.hadoop.yarn.server.resourcemanager.scheduler.fair.FairScheduler: allocate(appattempt_1471812677892_0002_000001 [] [] [] []
2016-08-21 14:54:17,837 INFO org.apache.hadoop.yarn.server.resourcemanager.scheduler.fair.FSAppAttempt: root.batch: <memory:2048, vCores:1>
2016-08-21 14:54:17,837 INFO org.apache.hadoop.yarn.server.resourcemanager.scheduler.fair.FSAppAttempt: appattempt_1471812677892_0002_000001 minReqResource: <memory:0, vCores:0> flexibleResource: <memory:16384, vCores:8>
2016-08-21 14:54:17,837 INFO org.apache.hadoop.yarn.server.resourcemanager.scheduler.fair.FairScheduler: allocate resource to application attempt: appattempt_1471812677892_0002_000001 queue:root.batch isRunning=true 
2016-08-21 14:54:17,838 INFO org.apache.hadoop.yarn.server.resourcemanager.scheduler.fair.FairScheduler: iglf: 2.getHeadroom()=<memory:14336, vCores:7>
2016-08-21 14:54:18,319 INFO org.apache.hadoop.yarn.server.resourcemanager.scheduler.fair.FSAppAttempt: assignContainer(FSSchedulerNode node:cp-1.yarn-perf.yarnrm-PG0.wisc.cloudlab.us, boolean reserved=false) for appattempt_1471812677892_0002_000001
2016-08-21 14:54:18,387 INFO org.apache.hadoop.yarn.server.resourcemanager.scheduler.fair.FSAppAttempt: assignContainer(FSSchedulerNode node:c220g1-031106.wisc.cloudlab.us, boolean reserved=false) for appattempt_1471812677892_0002_000001
2016-08-21 14:54:19,322 INFO org.apache.hadoop.yarn.server.resourcemanager.scheduler.fair.FSAppAttempt: assignContainer(FSSchedulerNode node:cp-1.yarn-perf.yarnrm-PG0.wisc.cloudlab.us, boolean reserved=false) for appattempt_1471812677892_0002_000001
2016-08-21 14:54:19,390 INFO org.apache.hadoop.yarn.server.resourcemanager.scheduler.fair.FSAppAttempt: assignContainer(FSSchedulerNode node:c220g1-031106.wisc.cloudlab.us, boolean reserved=false) for appattempt_1471812677892_0002_000001
2016-08-21 14:54:20,324 INFO org.apache.hadoop.yarn.server.resourcemanager.scheduler.fair.FSAppAttempt: assignContainer(FSSchedulerNode node:cp-1.yarn-perf.yarnrm-PG0.wisc.cloudlab.us, boolean reserved=false) for appattempt_1471812677892_0002_000001
2016-08-21 14:54:20,392 INFO org.apache.hadoop.yarn.server.resourcemanager.scheduler.fair.FSAppAttempt: assignContainer(FSSchedulerNode node:c220g1-031106.wisc.cloudlab.us, boolean reserved=false) for appattempt_1471812677892_0002_000001
2016-08-21 14:54:20,842 INFO org.apache.hadoop.yarn.server.resourcemanager.scheduler.fair.FairScheduler: allocate(appattempt_1471812677892_0002_000001 [] [] [] []
2016-08-21 14:54:20,842 INFO org.apache.hadoop.yarn.server.resourcemanager.scheduler.fair.FSAppAttempt: root.batch: <memory:2048, vCores:1>
2016-08-21 14:54:20,842 INFO org.apache.hadoop.yarn.server.resourcemanager.scheduler.fair.FSAppAttempt: appattempt_1471812677892_0002_000001 minReqResource: <memory:0, vCores:0> flexibleResource: <memory:16384, vCores:8>
2016-08-21 14:54:20,842 INFO org.apache.hadoop.yarn.server.resourcemanager.scheduler.fair.FairScheduler: allocate resource to application attempt: appattempt_1471812677892_0002_000001 queue:root.batch isRunning=true 
2016-08-21 14:54:20,842 INFO org.apache.hadoop.yarn.server.resourcemanager.scheduler.fair.FairScheduler: iglf: 2.getHeadroom()=<memory:14336, vCores:7>
2016-08-21 14:54:21,326 INFO org.apache.hadoop.yarn.server.resourcemanager.scheduler.fair.FSAppAttempt: assignContainer(FSSchedulerNode node:cp-1.yarn-perf.yarnrm-PG0.wisc.cloudlab.us, boolean reserved=false) for appattempt_1471812677892_0002_000001
2016-08-21 14:54:21,395 INFO org.apache.hadoop.yarn.server.resourcemanager.scheduler.fair.FSAppAttempt: assignContainer(FSSchedulerNode node:c220g1-031106.wisc.cloudlab.us, boolean reserved=false) for appattempt_1471812677892_0002_000001
2016-08-21 14:54:22,330 INFO org.apache.hadoop.yarn.server.resourcemanager.scheduler.fair.FSAppAttempt: assignContainer(FSSchedulerNode node:cp-1.yarn-perf.yarnrm-PG0.wisc.cloudlab.us, boolean reserved=false) for appattempt_1471812677892_0002_000001
2016-08-21 14:54:22,399 INFO org.apache.hadoop.yarn.server.resourcemanager.scheduler.fair.FSAppAttempt: assignContainer(FSSchedulerNode node:c220g1-031106.wisc.cloudlab.us, boolean reserved=false) for appattempt_1471812677892_0002_000001
2016-08-21 14:54:23,333 INFO org.apache.hadoop.yarn.server.resourcemanager.scheduler.fair.FSAppAttempt: assignContainer(FSSchedulerNode node:cp-1.yarn-perf.yarnrm-PG0.wisc.cloudlab.us, boolean reserved=false) for appattempt_1471812677892_0002_000001
2016-08-21 14:54:23,402 INFO org.apache.hadoop.yarn.server.resourcemanager.scheduler.fair.FSAppAttempt: assignContainer(FSSchedulerNode node:c220g1-031106.wisc.cloudlab.us, boolean reserved=false) for appattempt_1471812677892_0002_000001
2016-08-21 14:54:23,773 INFO org.apache.hadoop.yarn.server.resourcemanager.scheduler.fair.FairScheduler: allocate(appattempt_1471812677892_0002_000001 [{Priority: 1, Capability: <memory:1920, vCores:1>, # Containers: 1, Location: *, Relax Locality: true}] [] [] []
2016-08-21 14:54:23,773 INFO org.apache.hadoop.yarn.server.resourcemanager.scheduler.fair.FSAppAttempt: root.batch: <memory:2048, vCores:1>
2016-08-21 14:54:23,773 INFO org.apache.hadoop.yarn.server.resourcemanager.scheduler.fair.FSAppAttempt: appattempt_1471812677892_0002_000001 minReqResource: <memory:0, vCores:0> flexibleResource: <memory:16384, vCores:8>
2016-08-21 14:54:23,773 INFO org.apache.hadoop.yarn.server.resourcemanager.scheduler.fair.FairScheduler: allocate resource to application attempt: appattempt_1471812677892_0002_000001 queue:root.batch isRunning=true 
2016-08-21 14:54:23,773 INFO org.apache.hadoop.yarn.server.resourcemanager.scheduler.fair.FairScheduler: iglf: 2.getHeadroom()=<memory:14336, vCores:7>
2016-08-21 14:54:23,977 INFO org.apache.hadoop.yarn.server.resourcemanager.scheduler.fair.FairScheduler: allocate(appattempt_1471812677892_0002_000001 [] [] [] []
2016-08-21 14:54:23,977 INFO org.apache.hadoop.yarn.server.resourcemanager.scheduler.fair.FSAppAttempt: root.batch: <memory:2048, vCores:1>
2016-08-21 14:54:23,977 INFO org.apache.hadoop.yarn.server.resourcemanager.scheduler.fair.FSAppAttempt: appattempt_1471812677892_0002_000001 minReqResource: <memory:0, vCores:0> flexibleResource: <memory:16384, vCores:8>
2016-08-21 14:54:23,977 INFO org.apache.hadoop.yarn.server.resourcemanager.scheduler.fair.FairScheduler: allocate resource to application attempt: appattempt_1471812677892_0002_000001 queue:root.batch isRunning=true 
2016-08-21 14:54:23,977 INFO org.apache.hadoop.yarn.server.resourcemanager.scheduler.fair.FairScheduler: iglf: 2.getHeadroom()=<memory:14336, vCores:7>
2016-08-21 14:54:24,336 INFO org.apache.hadoop.yarn.server.resourcemanager.scheduler.fair.FSAppAttempt: assignContainer(FSSchedulerNode node:cp-1.yarn-perf.yarnrm-PG0.wisc.cloudlab.us, boolean reserved=false) for appattempt_1471812677892_0002_000001
2016-08-21 14:54:24,336 INFO org.apache.hadoop.yarn.server.resourcemanager.scheduler.fair.FSAppAttempt: assignContainer(FSSchedulerNode:cp-1.yarn-perf.yarnrm-PG0.wisc.cloudlab.us, ResourceRequest request, NodeType type, boolean reserved=false
2016-08-21 14:54:24,336 INFO org.apache.hadoop.yarn.server.resourcemanager.scheduler.fair.FSAppAttempt: allocate container: container_1471812677892_0002_01_000003 priority 1
2016-08-21 14:54:24,336 INFO org.apache.hadoop.yarn.server.resourcemanager.rmcontainer.RMContainerImpl: Processing container_1471812677892_0002_01_000003 of event START
2016-08-21 14:54:24,337 INFO org.apache.hadoop.yarn.server.resourcemanager.rmcontainer.RMContainerImpl: container_1471812677892_0002_01_000003 Container Transitioned from NEW to ALLOCATED
2016-08-21 14:54:24,337 INFO org.apache.hadoop.yarn.server.resourcemanager.RMAuditLogger: USER=tanle	OPERATION=AM Allocated Container	TARGET=SchedulerApp	RESULT=SUCCESS	APPID=application_1471812677892_0002	CONTAINERID=container_1471812677892_0002_01_000003
2016-08-21 14:54:24,337 INFO org.apache.hadoop.yarn.server.resourcemanager.scheduler.SchedulerNode: Assigned container container_1471812677892_0002_01_000003 of capacity <memory:2048, vCores:1> on host cp-1.yarn-perf.yarnrm-PG0.wisc.cloudlab.us:39022, which has 1 containers, <memory:2048, vCores:1> used and <memory:6144, vCores:3> available after allocation
2016-08-21 14:54:24,380 INFO org.apache.hadoop.yarn.server.resourcemanager.scheduler.fair.FairScheduler: allocate(appattempt_1471812677892_0002_000001 [] [] [] []
2016-08-21 14:54:24,381 INFO org.apache.hadoop.yarn.server.resourcemanager.scheduler.fair.FSAppAttempt: root.batch: <memory:4096, vCores:2>
2016-08-21 14:54:24,381 INFO org.apache.hadoop.yarn.server.resourcemanager.scheduler.fair.FSAppAttempt: appattempt_1471812677892_0002_000001 minReqResource: <memory:0, vCores:0> flexibleResource: <memory:16384, vCores:8>
2016-08-21 14:54:24,381 INFO org.apache.hadoop.yarn.server.resourcemanager.scheduler.fair.FairScheduler: allocate resource to application attempt: appattempt_1471812677892_0002_000001 queue:root.batch isRunning=true 
2016-08-21 14:54:24,383 INFO org.apache.hadoop.yarn.server.resourcemanager.security.NMTokenSecretManagerInRM: Sending NMToken for nodeId : cp-1.yarn-perf.yarnrm-PG0.wisc.cloudlab.us:39022 for container : container_1471812677892_0002_01_000003
2016-08-21 14:54:24,390 INFO org.apache.hadoop.yarn.server.resourcemanager.rmcontainer.RMContainerImpl: Processing container_1471812677892_0002_01_000003 of event ACQUIRED
2016-08-21 14:54:24,391 INFO org.apache.hadoop.yarn.server.resourcemanager.rmcontainer.RMContainerImpl: container_1471812677892_0002_01_000003 Container Transitioned from ALLOCATED to ACQUIRED
2016-08-21 14:54:24,391 INFO org.apache.hadoop.yarn.server.resourcemanager.scheduler.fair.FairScheduler: iglf: 2.getHeadroom()=<memory:12288, vCores:6>
2016-08-21 14:54:24,404 INFO org.apache.hadoop.yarn.server.resourcemanager.scheduler.fair.FSAppAttempt: assignContainer(FSSchedulerNode node:c220g1-031106.wisc.cloudlab.us, boolean reserved=false) for appattempt_1471812677892_0002_000001
2016-08-21 14:54:25,340 INFO org.apache.hadoop.yarn.server.resourcemanager.rmcontainer.RMContainerImpl: Processing container_1471812677892_0002_01_000003 of event LAUNCHED
2016-08-21 14:54:25,340 INFO org.apache.hadoop.yarn.server.resourcemanager.rmcontainer.RMContainerImpl: container_1471812677892_0002_01_000003 Container Transitioned from ACQUIRED to RUNNING
2016-08-21 14:54:25,341 INFO org.apache.hadoop.yarn.server.resourcemanager.scheduler.fair.FSAppAttempt: assignContainer(FSSchedulerNode node:cp-1.yarn-perf.yarnrm-PG0.wisc.cloudlab.us, boolean reserved=false) for appattempt_1471812677892_0002_000001
2016-08-21 14:54:25,408 INFO org.apache.hadoop.yarn.server.resourcemanager.scheduler.fair.FSAppAttempt: assignContainer(FSSchedulerNode node:c220g1-031106.wisc.cloudlab.us, boolean reserved=false) for appattempt_1471812677892_0002_000001
2016-08-21 14:54:25,459 INFO org.apache.hadoop.yarn.server.resourcemanager.ClientRMService: Allocated new applicationId: 7
2016-08-21 14:54:26,343 INFO org.apache.hadoop.yarn.server.resourcemanager.scheduler.fair.FSAppAttempt: assignContainer(FSSchedulerNode node:cp-1.yarn-perf.yarnrm-PG0.wisc.cloudlab.us, boolean reserved=false) for appattempt_1471812677892_0002_000001
2016-08-21 14:54:26,411 INFO org.apache.hadoop.yarn.server.resourcemanager.scheduler.fair.FSAppAttempt: assignContainer(FSSchedulerNode node:c220g1-031106.wisc.cloudlab.us, boolean reserved=false) for appattempt_1471812677892_0002_000001
2016-08-21 14:54:27,345 INFO org.apache.hadoop.yarn.server.resourcemanager.scheduler.fair.FSAppAttempt: assignContainer(FSSchedulerNode node:cp-1.yarn-perf.yarnrm-PG0.wisc.cloudlab.us, boolean reserved=false) for appattempt_1471812677892_0002_000001
2016-08-21 14:54:27,413 INFO org.apache.hadoop.yarn.server.resourcemanager.scheduler.fair.FSAppAttempt: assignContainer(FSSchedulerNode node:c220g1-031106.wisc.cloudlab.us, boolean reserved=false) for appattempt_1471812677892_0002_000001
2016-08-21 14:54:27,426 INFO org.apache.hadoop.yarn.server.resourcemanager.scheduler.fair.FairScheduler: allocate(appattempt_1471812677892_0002_000001 [{Priority: 1, Capability: <memory:1920, vCores:1>, # Containers: 0, Location: *, Relax Locality: true}] [] [] []
2016-08-21 14:54:27,426 INFO org.apache.hadoop.yarn.server.resourcemanager.scheduler.fair.FSAppAttempt: root.batch: <memory:4096, vCores:2>
2016-08-21 14:54:27,426 INFO org.apache.hadoop.yarn.server.resourcemanager.scheduler.fair.FSAppAttempt: appattempt_1471812677892_0002_000001 minReqResource: <memory:0, vCores:0> flexibleResource: <memory:16384, vCores:8>
2016-08-21 14:54:27,426 INFO org.apache.hadoop.yarn.server.resourcemanager.scheduler.fair.FairScheduler: allocate resource to application attempt: appattempt_1471812677892_0002_000001 queue:root.batch isRunning=true 
2016-08-21 14:54:27,426 INFO org.apache.hadoop.yarn.server.resourcemanager.scheduler.AppSchedulingInfo: checking for deactivate of application :application_1471812677892_0002
2016-08-21 14:54:27,426 INFO org.apache.hadoop.yarn.server.resourcemanager.scheduler.fair.FairScheduler: iglf: 2.getHeadroom()=<memory:12288, vCores:6>
2016-08-21 14:54:28,348 INFO org.apache.hadoop.yarn.server.resourcemanager.scheduler.fair.FSAppAttempt: assignContainer(FSSchedulerNode node:cp-1.yarn-perf.yarnrm-PG0.wisc.cloudlab.us, boolean reserved=false) for appattempt_1471812677892_0002_000001
2016-08-21 14:54:28,416 INFO org.apache.hadoop.yarn.server.resourcemanager.scheduler.fair.FSAppAttempt: assignContainer(FSSchedulerNode node:c220g1-031106.wisc.cloudlab.us, boolean reserved=false) for appattempt_1471812677892_0002_000001
2016-08-21 14:54:28,700 INFO org.apache.hadoop.yarn.server.resourcemanager.scheduler.fair.FairScheduler: allocate(appattempt_1471812677892_0002_000001 [{Priority: 1, Capability: <memory:1920, vCores:1>, # Containers: 2, Location: *, Relax Locality: true}] [] [] []
2016-08-21 14:54:28,700 INFO org.apache.hadoop.yarn.server.resourcemanager.scheduler.fair.FSAppAttempt: root.batch: <memory:4096, vCores:2>
2016-08-21 14:54:28,700 INFO org.apache.hadoop.yarn.server.resourcemanager.scheduler.fair.FSAppAttempt: appattempt_1471812677892_0002_000001 minReqResource: <memory:0, vCores:0> flexibleResource: <memory:16384, vCores:8>
2016-08-21 14:54:28,700 INFO org.apache.hadoop.yarn.server.resourcemanager.scheduler.fair.FairScheduler: allocate resource to application attempt: appattempt_1471812677892_0002_000001 queue:root.batch isRunning=true 
2016-08-21 14:54:28,700 INFO org.apache.hadoop.yarn.server.resourcemanager.scheduler.fair.FairScheduler: iglf: 2.getHeadroom()=<memory:12288, vCores:6>
2016-08-21 14:54:28,903 INFO org.apache.hadoop.yarn.server.resourcemanager.scheduler.fair.FairScheduler: allocate(appattempt_1471812677892_0002_000001 [] [] [] []
2016-08-21 14:54:28,904 INFO org.apache.hadoop.yarn.server.resourcemanager.scheduler.fair.FSAppAttempt: root.batch: <memory:4096, vCores:2>
2016-08-21 14:54:28,904 INFO org.apache.hadoop.yarn.server.resourcemanager.scheduler.fair.FSAppAttempt: appattempt_1471812677892_0002_000001 minReqResource: <memory:0, vCores:0> flexibleResource: <memory:16384, vCores:8>
2016-08-21 14:54:28,904 INFO org.apache.hadoop.yarn.server.resourcemanager.scheduler.fair.FairScheduler: allocate resource to application attempt: appattempt_1471812677892_0002_000001 queue:root.batch isRunning=true 
2016-08-21 14:54:28,904 INFO org.apache.hadoop.yarn.server.resourcemanager.scheduler.fair.FairScheduler: iglf: 2.getHeadroom()=<memory:12288, vCores:6>
2016-08-21 14:54:29,307 INFO org.apache.hadoop.yarn.server.resourcemanager.scheduler.fair.FairScheduler: allocate(appattempt_1471812677892_0002_000001 [] [] [] []
2016-08-21 14:54:29,307 INFO org.apache.hadoop.yarn.server.resourcemanager.scheduler.fair.FSAppAttempt: root.batch: <memory:4096, vCores:2>
2016-08-21 14:54:29,307 INFO org.apache.hadoop.yarn.server.resourcemanager.scheduler.fair.FSAppAttempt: appattempt_1471812677892_0002_000001 minReqResource: <memory:0, vCores:0> flexibleResource: <memory:16384, vCores:8>
2016-08-21 14:54:29,307 INFO org.apache.hadoop.yarn.server.resourcemanager.scheduler.fair.FairScheduler: allocate resource to application attempt: appattempt_1471812677892_0002_000001 queue:root.batch isRunning=true 
2016-08-21 14:54:29,308 INFO org.apache.hadoop.yarn.server.resourcemanager.scheduler.fair.FairScheduler: iglf: 2.getHeadroom()=<memory:12288, vCores:6>
2016-08-21 14:54:29,351 INFO org.apache.hadoop.yarn.server.resourcemanager.scheduler.fair.FSAppAttempt: assignContainer(FSSchedulerNode node:cp-1.yarn-perf.yarnrm-PG0.wisc.cloudlab.us, boolean reserved=false) for appattempt_1471812677892_0002_000001
2016-08-21 14:54:29,351 INFO org.apache.hadoop.yarn.server.resourcemanager.scheduler.fair.FSAppAttempt: assignContainer(FSSchedulerNode:cp-1.yarn-perf.yarnrm-PG0.wisc.cloudlab.us, ResourceRequest request, NodeType type, boolean reserved=false
2016-08-21 14:54:29,352 INFO org.apache.hadoop.yarn.server.resourcemanager.scheduler.fair.FSAppAttempt: allocate container: container_1471812677892_0002_01_000004 priority 1
2016-08-21 14:54:29,352 INFO org.apache.hadoop.yarn.server.resourcemanager.rmcontainer.RMContainerImpl: Processing container_1471812677892_0002_01_000004 of event START
2016-08-21 14:54:29,352 INFO org.apache.hadoop.yarn.server.resourcemanager.rmcontainer.RMContainerImpl: container_1471812677892_0002_01_000004 Container Transitioned from NEW to ALLOCATED
2016-08-21 14:54:29,352 INFO org.apache.hadoop.yarn.server.resourcemanager.RMAuditLogger: USER=tanle	OPERATION=AM Allocated Container	TARGET=SchedulerApp	RESULT=SUCCESS	APPID=application_1471812677892_0002	CONTAINERID=container_1471812677892_0002_01_000004
2016-08-21 14:54:29,352 INFO org.apache.hadoop.yarn.server.resourcemanager.scheduler.SchedulerNode: Assigned container container_1471812677892_0002_01_000004 of capacity <memory:2048, vCores:1> on host cp-1.yarn-perf.yarnrm-PG0.wisc.cloudlab.us:39022, which has 2 containers, <memory:4096, vCores:2> used and <memory:4096, vCores:2> available after allocation
2016-08-21 14:54:29,419 INFO org.apache.hadoop.yarn.server.resourcemanager.scheduler.fair.FSAppAttempt: assignContainer(FSSchedulerNode node:c220g1-031106.wisc.cloudlab.us, boolean reserved=false) for appattempt_1471812677892_0002_000001
2016-08-21 14:54:29,419 INFO org.apache.hadoop.yarn.server.resourcemanager.scheduler.fair.FSAppAttempt: assignContainer(FSSchedulerNode:c220g1-031106.wisc.cloudlab.us, ResourceRequest request, NodeType type, boolean reserved=false
2016-08-21 14:54:29,419 INFO org.apache.hadoop.yarn.server.resourcemanager.scheduler.fair.FSAppAttempt: allocate container: container_1471812677892_0002_01_000005 priority 1
2016-08-21 14:54:29,419 INFO org.apache.hadoop.yarn.server.resourcemanager.rmcontainer.RMContainerImpl: Processing container_1471812677892_0002_01_000005 of event START
2016-08-21 14:54:29,419 INFO org.apache.hadoop.yarn.server.resourcemanager.rmcontainer.RMContainerImpl: container_1471812677892_0002_01_000005 Container Transitioned from NEW to ALLOCATED
2016-08-21 14:54:29,420 INFO org.apache.hadoop.yarn.server.resourcemanager.RMAuditLogger: USER=tanle	OPERATION=AM Allocated Container	TARGET=SchedulerApp	RESULT=SUCCESS	APPID=application_1471812677892_0002	CONTAINERID=container_1471812677892_0002_01_000005
2016-08-21 14:54:29,420 INFO org.apache.hadoop.yarn.server.resourcemanager.scheduler.SchedulerNode: Assigned container container_1471812677892_0002_01_000005 of capacity <memory:2048, vCores:1> on host c220g1-031106.wisc.cloudlab.us:33388, which has 2 containers, <memory:4096, vCores:2> used and <memory:4096, vCores:2> available after allocation
2016-08-21 14:54:30,111 INFO org.apache.hadoop.yarn.server.resourcemanager.scheduler.fair.FairScheduler: allocate(appattempt_1471812677892_0002_000001 [] [] [] []
2016-08-21 14:54:30,111 INFO org.apache.hadoop.yarn.server.resourcemanager.scheduler.fair.FSAppAttempt: root.batch: <memory:8192, vCores:4>
2016-08-21 14:54:30,111 INFO org.apache.hadoop.yarn.server.resourcemanager.scheduler.fair.FSAppAttempt: appattempt_1471812677892_0002_000001 minReqResource: <memory:0, vCores:0> flexibleResource: <memory:16384, vCores:8>
2016-08-21 14:54:30,111 INFO org.apache.hadoop.yarn.server.resourcemanager.scheduler.fair.FairScheduler: allocate resource to application attempt: appattempt_1471812677892_0002_000001 queue:root.batch isRunning=true 
2016-08-21 14:54:30,114 INFO org.apache.hadoop.yarn.server.resourcemanager.rmcontainer.RMContainerImpl: Processing container_1471812677892_0002_01_000004 of event ACQUIRED
2016-08-21 14:54:30,115 INFO org.apache.hadoop.yarn.server.resourcemanager.rmcontainer.RMContainerImpl: container_1471812677892_0002_01_000004 Container Transitioned from ALLOCATED to ACQUIRED
2016-08-21 14:54:30,116 INFO org.apache.hadoop.yarn.server.resourcemanager.security.NMTokenSecretManagerInRM: Sending NMToken for nodeId : c220g1-031106.wisc.cloudlab.us:33388 for container : container_1471812677892_0002_01_000005
2016-08-21 14:54:30,118 INFO org.apache.hadoop.yarn.server.resourcemanager.rmcontainer.RMContainerImpl: Processing container_1471812677892_0002_01_000005 of event ACQUIRED
2016-08-21 14:54:30,118 INFO org.apache.hadoop.yarn.server.resourcemanager.rmcontainer.RMContainerImpl: container_1471812677892_0002_01_000005 Container Transitioned from ALLOCATED to ACQUIRED
2016-08-21 14:54:30,118 INFO org.apache.hadoop.yarn.server.resourcemanager.scheduler.fair.FairScheduler: iglf: 2.getHeadroom()=<memory:8192, vCores:4>
2016-08-21 14:54:30,355 INFO org.apache.hadoop.yarn.server.resourcemanager.rmcontainer.RMContainerImpl: Processing container_1471812677892_0002_01_000004 of event LAUNCHED
2016-08-21 14:54:30,355 INFO org.apache.hadoop.yarn.server.resourcemanager.rmcontainer.RMContainerImpl: container_1471812677892_0002_01_000004 Container Transitioned from ACQUIRED to RUNNING
2016-08-21 14:54:30,356 INFO org.apache.hadoop.yarn.server.resourcemanager.scheduler.fair.FSAppAttempt: assignContainer(FSSchedulerNode node:cp-1.yarn-perf.yarnrm-PG0.wisc.cloudlab.us, boolean reserved=false) for appattempt_1471812677892_0002_000001
2016-08-21 14:54:30,422 INFO org.apache.hadoop.yarn.server.resourcemanager.rmcontainer.RMContainerImpl: Processing container_1471812677892_0002_01_000005 of event LAUNCHED
2016-08-21 14:54:30,422 INFO org.apache.hadoop.yarn.server.resourcemanager.rmcontainer.RMContainerImpl: container_1471812677892_0002_01_000005 Container Transitioned from ACQUIRED to RUNNING
2016-08-21 14:54:30,422 INFO org.apache.hadoop.yarn.server.resourcemanager.scheduler.fair.FSAppAttempt: assignContainer(FSSchedulerNode node:c220g1-031106.wisc.cloudlab.us, boolean reserved=false) for appattempt_1471812677892_0002_000001
2016-08-21 14:54:31,359 INFO org.apache.hadoop.yarn.server.resourcemanager.scheduler.fair.FSAppAttempt: assignContainer(FSSchedulerNode node:cp-1.yarn-perf.yarnrm-PG0.wisc.cloudlab.us, boolean reserved=false) for appattempt_1471812677892_0002_000001
2016-08-21 14:54:31,425 INFO org.apache.hadoop.yarn.server.resourcemanager.scheduler.fair.FSAppAttempt: assignContainer(FSSchedulerNode node:c220g1-031106.wisc.cloudlab.us, boolean reserved=false) for appattempt_1471812677892_0002_000001
2016-08-21 14:54:32,361 INFO org.apache.hadoop.yarn.server.resourcemanager.scheduler.fair.FSAppAttempt: assignContainer(FSSchedulerNode node:cp-1.yarn-perf.yarnrm-PG0.wisc.cloudlab.us, boolean reserved=false) for appattempt_1471812677892_0002_000001
2016-08-21 14:54:32,427 INFO org.apache.hadoop.yarn.server.resourcemanager.scheduler.fair.FSAppAttempt: assignContainer(FSSchedulerNode node:c220g1-031106.wisc.cloudlab.us, boolean reserved=false) for appattempt_1471812677892_0002_000001
2016-08-21 14:54:33,130 INFO org.apache.hadoop.yarn.server.resourcemanager.scheduler.fair.FairScheduler: allocate(appattempt_1471812677892_0002_000001 [{Priority: 1, Capability: <memory:1920, vCores:1>, # Containers: 0, Location: *, Relax Locality: true}] [] [] []
2016-08-21 14:54:33,130 INFO org.apache.hadoop.yarn.server.resourcemanager.scheduler.fair.FSAppAttempt: root.batch: <memory:8192, vCores:4>
2016-08-21 14:54:33,130 INFO org.apache.hadoop.yarn.server.resourcemanager.scheduler.fair.FSAppAttempt: appattempt_1471812677892_0002_000001 minReqResource: <memory:0, vCores:0> flexibleResource: <memory:16384, vCores:8>
2016-08-21 14:54:33,130 INFO org.apache.hadoop.yarn.server.resourcemanager.scheduler.fair.FairScheduler: allocate resource to application attempt: appattempt_1471812677892_0002_000001 queue:root.batch isRunning=true 
2016-08-21 14:54:33,130 INFO org.apache.hadoop.yarn.server.resourcemanager.scheduler.AppSchedulingInfo: checking for deactivate of application :application_1471812677892_0002
2016-08-21 14:54:33,130 INFO org.apache.hadoop.yarn.server.resourcemanager.scheduler.fair.FairScheduler: iglf: 2.getHeadroom()=<memory:8192, vCores:4>
2016-08-21 14:54:33,364 INFO org.apache.hadoop.yarn.server.resourcemanager.scheduler.fair.FSAppAttempt: assignContainer(FSSchedulerNode node:cp-1.yarn-perf.yarnrm-PG0.wisc.cloudlab.us, boolean reserved=false) for appattempt_1471812677892_0002_000001
2016-08-21 14:54:33,430 INFO org.apache.hadoop.yarn.server.resourcemanager.scheduler.fair.FSAppAttempt: assignContainer(FSSchedulerNode node:c220g1-031106.wisc.cloudlab.us, boolean reserved=false) for appattempt_1471812677892_0002_000001
2016-08-21 14:54:33,698 INFO org.apache.hadoop.yarn.server.resourcemanager.scheduler.fair.FairScheduler: allocate(appattempt_1471812677892_0002_000001 [{Priority: 1, Capability: <memory:1920, vCores:1>, # Containers: 4, Location: *, Relax Locality: true}] [] [] []
2016-08-21 14:54:33,698 INFO org.apache.hadoop.yarn.server.resourcemanager.scheduler.fair.FSAppAttempt: root.batch: <memory:8192, vCores:4>
2016-08-21 14:54:33,698 INFO org.apache.hadoop.yarn.server.resourcemanager.scheduler.fair.FSAppAttempt: appattempt_1471812677892_0002_000001 minReqResource: <memory:0, vCores:0> flexibleResource: <memory:16384, vCores:8>
2016-08-21 14:54:33,698 INFO org.apache.hadoop.yarn.server.resourcemanager.scheduler.fair.FairScheduler: allocate resource to application attempt: appattempt_1471812677892_0002_000001 queue:root.batch isRunning=true 
2016-08-21 14:54:33,699 INFO org.apache.hadoop.yarn.server.resourcemanager.scheduler.fair.FairScheduler: iglf: 2.getHeadroom()=<memory:8192, vCores:4>
2016-08-21 14:54:33,902 INFO org.apache.hadoop.yarn.server.resourcemanager.scheduler.fair.FairScheduler: allocate(appattempt_1471812677892_0002_000001 [] [] [] []
2016-08-21 14:54:33,902 INFO org.apache.hadoop.yarn.server.resourcemanager.scheduler.fair.FSAppAttempt: root.batch: <memory:8192, vCores:4>
2016-08-21 14:54:33,902 INFO org.apache.hadoop.yarn.server.resourcemanager.scheduler.fair.FSAppAttempt: appattempt_1471812677892_0002_000001 minReqResource: <memory:0, vCores:0> flexibleResource: <memory:16384, vCores:8>
2016-08-21 14:54:33,902 INFO org.apache.hadoop.yarn.server.resourcemanager.scheduler.fair.FairScheduler: allocate resource to application attempt: appattempt_1471812677892_0002_000001 queue:root.batch isRunning=true 
2016-08-21 14:54:33,902 INFO org.apache.hadoop.yarn.server.resourcemanager.scheduler.fair.FairScheduler: iglf: 2.getHeadroom()=<memory:8192, vCores:4>
2016-08-21 14:54:34,305 INFO org.apache.hadoop.yarn.server.resourcemanager.scheduler.fair.FairScheduler: allocate(appattempt_1471812677892_0002_000001 [] [] [] []
2016-08-21 14:54:34,305 INFO org.apache.hadoop.yarn.server.resourcemanager.scheduler.fair.FSAppAttempt: root.batch: <memory:8192, vCores:4>
2016-08-21 14:54:34,305 INFO org.apache.hadoop.yarn.server.resourcemanager.scheduler.fair.FSAppAttempt: appattempt_1471812677892_0002_000001 minReqResource: <memory:0, vCores:0> flexibleResource: <memory:16384, vCores:8>
2016-08-21 14:54:34,305 INFO org.apache.hadoop.yarn.server.resourcemanager.scheduler.fair.FairScheduler: allocate resource to application attempt: appattempt_1471812677892_0002_000001 queue:root.batch isRunning=true 
2016-08-21 14:54:34,305 INFO org.apache.hadoop.yarn.server.resourcemanager.scheduler.fair.FairScheduler: iglf: 2.getHeadroom()=<memory:8192, vCores:4>
2016-08-21 14:54:34,367 INFO org.apache.hadoop.yarn.server.resourcemanager.scheduler.fair.FSAppAttempt: assignContainer(FSSchedulerNode node:cp-1.yarn-perf.yarnrm-PG0.wisc.cloudlab.us, boolean reserved=false) for appattempt_1471812677892_0002_000001
2016-08-21 14:54:34,367 INFO org.apache.hadoop.yarn.server.resourcemanager.scheduler.fair.FSAppAttempt: assignContainer(FSSchedulerNode:cp-1.yarn-perf.yarnrm-PG0.wisc.cloudlab.us, ResourceRequest request, NodeType type, boolean reserved=false
2016-08-21 14:54:34,368 INFO org.apache.hadoop.yarn.server.resourcemanager.scheduler.fair.FSAppAttempt: allocate container: container_1471812677892_0002_01_000006 priority 1
2016-08-21 14:54:34,368 INFO org.apache.hadoop.yarn.server.resourcemanager.rmcontainer.RMContainerImpl: Processing container_1471812677892_0002_01_000006 of event START
2016-08-21 14:54:34,368 INFO org.apache.hadoop.yarn.server.resourcemanager.rmcontainer.RMContainerImpl: container_1471812677892_0002_01_000006 Container Transitioned from NEW to ALLOCATED
2016-08-21 14:54:34,368 INFO org.apache.hadoop.yarn.server.resourcemanager.RMAuditLogger: USER=tanle	OPERATION=AM Allocated Container	TARGET=SchedulerApp	RESULT=SUCCESS	APPID=application_1471812677892_0002	CONTAINERID=container_1471812677892_0002_01_000006
2016-08-21 14:54:34,368 INFO org.apache.hadoop.yarn.server.resourcemanager.scheduler.SchedulerNode: Assigned container container_1471812677892_0002_01_000006 of capacity <memory:2048, vCores:1> on host cp-1.yarn-perf.yarnrm-PG0.wisc.cloudlab.us:39022, which has 3 containers, <memory:6144, vCores:3> used and <memory:2048, vCores:1> available after allocation
2016-08-21 14:54:34,432 INFO org.apache.hadoop.yarn.server.resourcemanager.scheduler.fair.FSAppAttempt: assignContainer(FSSchedulerNode node:c220g1-031106.wisc.cloudlab.us, boolean reserved=false) for appattempt_1471812677892_0002_000001
2016-08-21 14:54:34,433 INFO org.apache.hadoop.yarn.server.resourcemanager.scheduler.fair.FSAppAttempt: assignContainer(FSSchedulerNode:c220g1-031106.wisc.cloudlab.us, ResourceRequest request, NodeType type, boolean reserved=false
2016-08-21 14:54:34,433 INFO org.apache.hadoop.yarn.server.resourcemanager.scheduler.fair.FSAppAttempt: allocate container: container_1471812677892_0002_01_000007 priority 1
2016-08-21 14:54:34,433 INFO org.apache.hadoop.yarn.server.resourcemanager.rmcontainer.RMContainerImpl: Processing container_1471812677892_0002_01_000007 of event START
2016-08-21 14:54:34,434 INFO org.apache.hadoop.yarn.server.resourcemanager.rmcontainer.RMContainerImpl: container_1471812677892_0002_01_000007 Container Transitioned from NEW to ALLOCATED
2016-08-21 14:54:34,434 INFO org.apache.hadoop.yarn.server.resourcemanager.RMAuditLogger: USER=tanle	OPERATION=AM Allocated Container	TARGET=SchedulerApp	RESULT=SUCCESS	APPID=application_1471812677892_0002	CONTAINERID=container_1471812677892_0002_01_000007
2016-08-21 14:54:34,434 INFO org.apache.hadoop.yarn.server.resourcemanager.scheduler.SchedulerNode: Assigned container container_1471812677892_0002_01_000007 of capacity <memory:2048, vCores:1> on host c220g1-031106.wisc.cloudlab.us:33388, which has 3 containers, <memory:6144, vCores:3> used and <memory:2048, vCores:1> available after allocation
2016-08-21 14:54:35,110 INFO org.apache.hadoop.yarn.server.resourcemanager.scheduler.fair.FairScheduler: allocate(appattempt_1471812677892_0002_000001 [] [] [] []
2016-08-21 14:54:35,110 INFO org.apache.hadoop.yarn.server.resourcemanager.scheduler.fair.FSAppAttempt: root.batch: <memory:12288, vCores:6>
2016-08-21 14:54:35,110 INFO org.apache.hadoop.yarn.server.resourcemanager.scheduler.fair.FSAppAttempt: appattempt_1471812677892_0002_000001 minReqResource: <memory:0, vCores:0> flexibleResource: <memory:16384, vCores:8>
2016-08-21 14:54:35,110 INFO org.apache.hadoop.yarn.server.resourcemanager.scheduler.fair.FairScheduler: allocate resource to application attempt: appattempt_1471812677892_0002_000001 queue:root.batch isRunning=true 
2016-08-21 14:54:35,112 INFO org.apache.hadoop.yarn.server.resourcemanager.rmcontainer.RMContainerImpl: Processing container_1471812677892_0002_01_000006 of event ACQUIRED
2016-08-21 14:54:35,113 INFO org.apache.hadoop.yarn.server.resourcemanager.rmcontainer.RMContainerImpl: container_1471812677892_0002_01_000006 Container Transitioned from ALLOCATED to ACQUIRED
2016-08-21 14:54:35,115 INFO org.apache.hadoop.yarn.server.resourcemanager.rmcontainer.RMContainerImpl: Processing container_1471812677892_0002_01_000007 of event ACQUIRED
2016-08-21 14:54:35,115 INFO org.apache.hadoop.yarn.server.resourcemanager.rmcontainer.RMContainerImpl: container_1471812677892_0002_01_000007 Container Transitioned from ALLOCATED to ACQUIRED
2016-08-21 14:54:35,115 INFO org.apache.hadoop.yarn.server.resourcemanager.scheduler.fair.FairScheduler: iglf: 2.getHeadroom()=<memory:4096, vCores:2>
2016-08-21 14:54:35,370 INFO org.apache.hadoop.yarn.server.resourcemanager.rmcontainer.RMContainerImpl: Processing container_1471812677892_0002_01_000006 of event LAUNCHED
2016-08-21 14:54:35,370 INFO org.apache.hadoop.yarn.server.resourcemanager.rmcontainer.RMContainerImpl: container_1471812677892_0002_01_000006 Container Transitioned from ACQUIRED to RUNNING
2016-08-21 14:54:35,370 INFO org.apache.hadoop.yarn.server.resourcemanager.scheduler.fair.FSAppAttempt: assignContainer(FSSchedulerNode node:cp-1.yarn-perf.yarnrm-PG0.wisc.cloudlab.us, boolean reserved=false) for appattempt_1471812677892_0002_000001
2016-08-21 14:54:35,370 INFO org.apache.hadoop.yarn.server.resourcemanager.scheduler.fair.FSAppAttempt: assignContainer(FSSchedulerNode:cp-1.yarn-perf.yarnrm-PG0.wisc.cloudlab.us, ResourceRequest request, NodeType type, boolean reserved=false
2016-08-21 14:54:35,371 INFO org.apache.hadoop.yarn.server.resourcemanager.scheduler.fair.FSAppAttempt: allocate container: container_1471812677892_0002_01_000008 priority 1
2016-08-21 14:54:35,372 INFO org.apache.hadoop.yarn.server.resourcemanager.rmcontainer.RMContainerImpl: Processing container_1471812677892_0002_01_000008 of event START
2016-08-21 14:54:35,372 INFO org.apache.hadoop.yarn.server.resourcemanager.rmcontainer.RMContainerImpl: container_1471812677892_0002_01_000008 Container Transitioned from NEW to ALLOCATED
2016-08-21 14:54:35,372 INFO org.apache.hadoop.yarn.server.resourcemanager.RMAuditLogger: USER=tanle	OPERATION=AM Allocated Container	TARGET=SchedulerApp	RESULT=SUCCESS	APPID=application_1471812677892_0002	CONTAINERID=container_1471812677892_0002_01_000008
2016-08-21 14:54:35,372 INFO org.apache.hadoop.yarn.server.resourcemanager.scheduler.SchedulerNode: Assigned container container_1471812677892_0002_01_000008 of capacity <memory:2048, vCores:1> on host cp-1.yarn-perf.yarnrm-PG0.wisc.cloudlab.us:39022, which has 4 containers, <memory:8192, vCores:4> used and <memory:0, vCores:0> available after allocation
2016-08-21 14:54:35,435 INFO org.apache.hadoop.yarn.server.resourcemanager.rmcontainer.RMContainerImpl: Processing container_1471812677892_0002_01_000007 of event LAUNCHED
2016-08-21 14:54:35,435 INFO org.apache.hadoop.yarn.server.resourcemanager.rmcontainer.RMContainerImpl: container_1471812677892_0002_01_000007 Container Transitioned from ACQUIRED to RUNNING
2016-08-21 14:54:35,436 INFO org.apache.hadoop.yarn.server.resourcemanager.scheduler.fair.FSAppAttempt: assignContainer(FSSchedulerNode node:c220g1-031106.wisc.cloudlab.us, boolean reserved=false) for appattempt_1471812677892_0002_000001
2016-08-21 14:54:35,436 INFO org.apache.hadoop.yarn.server.resourcemanager.scheduler.fair.FSAppAttempt: assignContainer(FSSchedulerNode:c220g1-031106.wisc.cloudlab.us, ResourceRequest request, NodeType type, boolean reserved=false
2016-08-21 14:54:35,436 INFO org.apache.hadoop.yarn.server.resourcemanager.scheduler.fair.FSAppAttempt: allocate container: container_1471812677892_0002_01_000009 priority 1
2016-08-21 14:54:35,436 INFO org.apache.hadoop.yarn.server.resourcemanager.rmcontainer.RMContainerImpl: Processing container_1471812677892_0002_01_000009 of event START
2016-08-21 14:54:35,436 INFO org.apache.hadoop.yarn.server.resourcemanager.rmcontainer.RMContainerImpl: container_1471812677892_0002_01_000009 Container Transitioned from NEW to ALLOCATED
2016-08-21 14:54:35,436 INFO org.apache.hadoop.yarn.server.resourcemanager.RMAuditLogger: USER=tanle	OPERATION=AM Allocated Container	TARGET=SchedulerApp	RESULT=SUCCESS	APPID=application_1471812677892_0002	CONTAINERID=container_1471812677892_0002_01_000009
2016-08-21 14:54:35,436 INFO org.apache.hadoop.yarn.server.resourcemanager.scheduler.SchedulerNode: Assigned container container_1471812677892_0002_01_000009 of capacity <memory:2048, vCores:1> on host c220g1-031106.wisc.cloudlab.us:33388, which has 4 containers, <memory:8192, vCores:4> used and <memory:0, vCores:0> available after allocation
2016-08-21 14:54:36,373 INFO org.apache.hadoop.yarn.server.resourcemanager.scheduler.fair.FSAppAttempt: assignContainer(FSSchedulerNode node:cp-1.yarn-perf.yarnrm-PG0.wisc.cloudlab.us, boolean reserved=false) for appattempt_1471812677892_0002_000001
2016-08-21 14:54:36,438 INFO org.apache.hadoop.yarn.server.resourcemanager.scheduler.fair.FSAppAttempt: assignContainer(FSSchedulerNode node:c220g1-031106.wisc.cloudlab.us, boolean reserved=false) for appattempt_1471812677892_0002_000001
2016-08-21 14:54:36,726 INFO org.apache.hadoop.yarn.server.resourcemanager.scheduler.fair.FairScheduler: allocate(appattempt_1471812677892_0002_000001 [{Priority: 1, Capability: <memory:1920, vCores:1>, # Containers: 2, Location: *, Relax Locality: true}] [] [] []
2016-08-21 14:54:36,726 INFO org.apache.hadoop.yarn.server.resourcemanager.scheduler.fair.FSAppAttempt: root.batch: <memory:16384, vCores:8>
2016-08-21 14:54:36,726 INFO org.apache.hadoop.yarn.server.resourcemanager.scheduler.fair.FSAppAttempt: appattempt_1471812677892_0002_000001 minReqResource: <memory:0, vCores:0> flexibleResource: <memory:16384, vCores:8>
2016-08-21 14:54:36,726 INFO org.apache.hadoop.yarn.server.resourcemanager.scheduler.fair.FairScheduler: allocate resource to application attempt: appattempt_1471812677892_0002_000001 queue:root.batch isRunning=true 
2016-08-21 14:54:36,728 INFO org.apache.hadoop.yarn.server.resourcemanager.rmcontainer.RMContainerImpl: Processing container_1471812677892_0002_01_000008 of event ACQUIRED
2016-08-21 14:54:36,729 INFO org.apache.hadoop.yarn.server.resourcemanager.rmcontainer.RMContainerImpl: container_1471812677892_0002_01_000008 Container Transitioned from ALLOCATED to ACQUIRED
2016-08-21 14:54:36,731 INFO org.apache.hadoop.yarn.server.resourcemanager.rmcontainer.RMContainerImpl: Processing container_1471812677892_0002_01_000009 of event ACQUIRED
2016-08-21 14:54:36,732 INFO org.apache.hadoop.yarn.server.resourcemanager.rmcontainer.RMContainerImpl: container_1471812677892_0002_01_000009 Container Transitioned from ALLOCATED to ACQUIRED
2016-08-21 14:54:36,733 INFO org.apache.hadoop.yarn.server.resourcemanager.scheduler.fair.FairScheduler: iglf: 2.getHeadroom()=<memory:0, vCores:0>
2016-08-21 14:54:37,375 INFO org.apache.hadoop.yarn.server.resourcemanager.rmcontainer.RMContainerImpl: Processing container_1471812677892_0002_01_000008 of event LAUNCHED
2016-08-21 14:54:37,376 INFO org.apache.hadoop.yarn.server.resourcemanager.rmcontainer.RMContainerImpl: container_1471812677892_0002_01_000008 Container Transitioned from ACQUIRED to RUNNING
2016-08-21 14:54:37,376 INFO org.apache.hadoop.yarn.server.resourcemanager.scheduler.fair.FSAppAttempt: assignContainer(FSSchedulerNode node:cp-1.yarn-perf.yarnrm-PG0.wisc.cloudlab.us, boolean reserved=false) for appattempt_1471812677892_0002_000001
2016-08-21 14:54:37,376 INFO org.apache.hadoop.yarn.server.resourcemanager.scheduler.fair.FSAppAttempt: assignContainer(FSSchedulerNode:cp-1.yarn-perf.yarnrm-PG0.wisc.cloudlab.us, ResourceRequest request, NodeType type, boolean reserved=false
2016-08-21 14:54:37,376 INFO org.apache.hadoop.yarn.server.resourcemanager.scheduler.fair.FSAppAttempt: Making reservation: node=cp-1.yarn-perf.yarnrm-PG0.wisc.cloudlab.us app_id=application_1471812677892_0002
2016-08-21 14:54:37,377 INFO org.apache.hadoop.yarn.server.resourcemanager.rmcontainer.RMContainerImpl: Processing container_1471812677892_0002_01_000010 of event RESERVED
2016-08-21 14:54:37,377 INFO org.apache.hadoop.yarn.server.resourcemanager.rmcontainer.RMContainerImpl: container_1471812677892_0002_01_000010 Container Transitioned from NEW to RESERVED
2016-08-21 14:54:37,377 INFO org.apache.hadoop.yarn.server.resourcemanager.scheduler.fair.FSSchedulerNode: Reserved container container_1471812677892_0002_01_000010 on node host: cp-1.yarn-perf.yarnrm-PG0.wisc.cloudlab.us:39022 #containers=4 available=<memory:0, vCores:0> used=<memory:8192, vCores:4> for application org.apache.hadoop.yarn.server.resourcemanager.scheduler.fair.FSAppAttempt@5f3ad072
2016-08-21 14:54:37,441 INFO org.apache.hadoop.yarn.server.resourcemanager.rmcontainer.RMContainerImpl: Processing container_1471812677892_0002_01_000009 of event LAUNCHED
2016-08-21 14:54:37,441 INFO org.apache.hadoop.yarn.server.resourcemanager.rmcontainer.RMContainerImpl: container_1471812677892_0002_01_000009 Container Transitioned from ACQUIRED to RUNNING
2016-08-21 14:54:37,442 INFO org.apache.hadoop.yarn.server.resourcemanager.scheduler.fair.FSAppAttempt: assignContainer(FSSchedulerNode node:c220g1-031106.wisc.cloudlab.us, boolean reserved=false) for appattempt_1471812677892_0002_000001
2016-08-21 14:54:37,442 INFO org.apache.hadoop.yarn.server.resourcemanager.scheduler.fair.FSAppAttempt: assignContainer(FSSchedulerNode:c220g1-031106.wisc.cloudlab.us, ResourceRequest request, NodeType type, boolean reserved=false
2016-08-21 14:54:37,442 INFO org.apache.hadoop.yarn.server.resourcemanager.scheduler.fair.FSAppAttempt: Making reservation: node=c220g1-031106.wisc.cloudlab.us app_id=application_1471812677892_0002
2016-08-21 14:54:37,442 INFO org.apache.hadoop.yarn.server.resourcemanager.rmcontainer.RMContainerImpl: Processing container_1471812677892_0002_01_000011 of event RESERVED
2016-08-21 14:54:37,442 INFO org.apache.hadoop.yarn.server.resourcemanager.rmcontainer.RMContainerImpl: container_1471812677892_0002_01_000011 Container Transitioned from NEW to RESERVED
2016-08-21 14:54:37,442 INFO org.apache.hadoop.yarn.server.resourcemanager.scheduler.fair.FSSchedulerNode: Reserved container container_1471812677892_0002_01_000011 on node host: c220g1-031106.wisc.cloudlab.us:33388 #containers=4 available=<memory:0, vCores:0> used=<memory:8192, vCores:4> for application org.apache.hadoop.yarn.server.resourcemanager.scheduler.fair.FSAppAttempt@5f3ad072
2016-08-21 14:54:37,757 WARN org.apache.hadoop.yarn.server.resourcemanager.rmapp.RMAppImpl: The specific max attempts: 0 for application: 5 is invalid, because it is out of the range [1, 2]. Use the global max attempts instead.
2016-08-21 14:54:37,758 INFO org.apache.hadoop.yarn.server.resourcemanager.ClientRMService: Application with id 5 submitted by user tanle
2016-08-21 14:54:37,758 INFO org.apache.hadoop.yarn.server.resourcemanager.RMAuditLogger: USER=tanle	IP=128.104.222.71	OPERATION=Submit Application Request	TARGET=ClientRMService	RESULT=SUCCESS	APPID=application_1471812677892_0005
2016-08-21 14:54:37,758 INFO org.apache.hadoop.yarn.server.resourcemanager.rmapp.RMAppImpl: Storing application with id application_1471812677892_0005
2016-08-21 14:54:37,759 INFO org.apache.hadoop.yarn.server.resourcemanager.recovery.RMStateStore: Storing info for app: application_1471812677892_0005
2016-08-21 14:54:37,763 INFO org.apache.hadoop.yarn.server.resourcemanager.scheduler.fair.FairScheduler: Accepted application application_1471812677892_0005 from user: tanle, in queue: interactive2, currently num of applications: 2
2016-08-21 14:54:37,764 INFO org.apache.hadoop.yarn.server.resourcemanager.ApplicationMasterService: Registering app attempt : appattempt_1471812677892_0005_000001
2016-08-21 14:54:37,764 INFO org.apache.hadoop.yarn.server.resourcemanager.rmapp.attempt.RMAppAttemptImpl: appattempt_1471812677892_0005_000001 State change from NEW to SUBMITTED
2016-08-21 14:54:37,764 INFO org.apache.hadoop.yarn.server.resourcemanager.scheduler.fair.FairScheduler: Added Application Attempt appattempt_1471812677892_0005_000001 to scheduler from user: tanle
2016-08-21 14:54:37,764 INFO org.apache.hadoop.yarn.server.resourcemanager.rmapp.attempt.RMAppAttemptImpl: ScheduleTransition.transition(appattempt_1471812677892_0005_000001,EventType: ATTEMPT_ADDED)
2016-08-21 14:54:37,765 INFO org.apache.hadoop.yarn.server.resourcemanager.scheduler.fair.FairScheduler: allocate(appattempt_1471812677892_0005_000001 [{Priority: 0, Capability: <memory:2048, vCores:1>, # Containers: 1, Location: *, Relax Locality: true}] [] null null
2016-08-21 14:54:37,765 INFO org.apache.hadoop.yarn.server.resourcemanager.scheduler.fair.FSAppAttempt: root.batch: <memory:16384, vCores:8>
2016-08-21 14:54:37,765 INFO org.apache.hadoop.yarn.server.resourcemanager.scheduler.fair.FSAppAttempt: appattempt_1471812677892_0005_000001 minReqResource: <memory:0, vCores:0> flexibleResource: <memory:16384, vCores:8>
2016-08-21 14:54:37,765 INFO org.apache.hadoop.yarn.server.resourcemanager.scheduler.fair.FairScheduler: allocate resource to application attempt: appattempt_1471812677892_0005_000001 queue:root.interactive2 isRunning=true 
2016-08-21 14:54:37,766 INFO org.apache.hadoop.yarn.server.resourcemanager.scheduler.fair.FairScheduler: iglf: 5.getHeadroom()=<memory:0, vCores:0>
2016-08-21 14:54:37,766 INFO org.apache.hadoop.yarn.server.resourcemanager.rmapp.attempt.RMAppAttemptImpl: appattempt_1471812677892_0005_000001 State change from SUBMITTED to SCHEDULED
2016-08-21 14:54:38,597 WARN org.apache.hadoop.yarn.server.resourcemanager.rmapp.RMAppImpl: The specific max attempts: 0 for application: 3 is invalid, because it is out of the range [1, 2]. Use the global max attempts instead.
2016-08-21 14:54:38,598 INFO org.apache.hadoop.yarn.server.resourcemanager.ClientRMService: Application with id 3 submitted by user tanle
2016-08-21 14:54:38,598 INFO org.apache.hadoop.yarn.server.resourcemanager.RMAuditLogger: USER=tanle	IP=128.104.222.71	OPERATION=Submit Application Request	TARGET=ClientRMService	RESULT=SUCCESS	APPID=application_1471812677892_0003
2016-08-21 14:54:38,598 INFO org.apache.hadoop.yarn.server.resourcemanager.rmapp.RMAppImpl: Storing application with id application_1471812677892_0003
2016-08-21 14:54:38,598 INFO org.apache.hadoop.yarn.server.resourcemanager.recovery.RMStateStore: Storing info for app: application_1471812677892_0003
2016-08-21 14:54:38,603 INFO org.apache.hadoop.yarn.server.resourcemanager.scheduler.fair.FairScheduler: Accepted application application_1471812677892_0003 from user: tanle, in queue: interactive1, currently num of applications: 3
2016-08-21 14:54:38,604 INFO org.apache.hadoop.yarn.server.resourcemanager.ApplicationMasterService: Registering app attempt : appattempt_1471812677892_0003_000001
2016-08-21 14:54:38,604 INFO org.apache.hadoop.yarn.server.resourcemanager.rmapp.attempt.RMAppAttemptImpl: appattempt_1471812677892_0003_000001 State change from NEW to SUBMITTED
2016-08-21 14:54:38,605 INFO org.apache.hadoop.yarn.server.resourcemanager.scheduler.fair.FairScheduler: Added Application Attempt appattempt_1471812677892_0003_000001 to scheduler from user: tanle
2016-08-21 14:54:38,605 INFO org.apache.hadoop.yarn.server.resourcemanager.rmapp.attempt.RMAppAttemptImpl: ScheduleTransition.transition(appattempt_1471812677892_0003_000001,EventType: ATTEMPT_ADDED)
2016-08-21 14:54:38,605 INFO org.apache.hadoop.yarn.server.resourcemanager.scheduler.fair.FairScheduler: allocate(appattempt_1471812677892_0003_000001 [{Priority: 0, Capability: <memory:2048, vCores:1>, # Containers: 1, Location: *, Relax Locality: true}] [] null null
2016-08-21 14:54:38,606 INFO org.apache.hadoop.yarn.server.resourcemanager.scheduler.fair.FSAppAttempt: root.interactive2: <memory:0, vCores:0>
2016-08-21 14:54:38,606 INFO org.apache.hadoop.yarn.server.resourcemanager.scheduler.fair.FSAppAttempt: root.batch: <memory:16384, vCores:8>
2016-08-21 14:54:38,606 INFO org.apache.hadoop.yarn.server.resourcemanager.scheduler.fair.FSAppAttempt: appattempt_1471812677892_0003_000001 minReqResource: <memory:8192, vCores:4> flexibleResource: <memory:8192, vCores:4>
2016-08-21 14:54:38,606 INFO org.apache.hadoop.yarn.server.resourcemanager.scheduler.fair.FairScheduler: allocate resource to application attempt: appattempt_1471812677892_0003_000001 queue:root.interactive1 isRunning=true 
2016-08-21 14:54:38,606 INFO org.apache.hadoop.yarn.server.resourcemanager.scheduler.fair.FairScheduler: iglf: 3.getHeadroom()=<memory:0, vCores:0>
2016-08-21 14:54:38,606 INFO org.apache.hadoop.yarn.server.resourcemanager.rmapp.attempt.RMAppAttemptImpl: appattempt_1471812677892_0003_000001 State change from SUBMITTED to SCHEDULED
2016-08-21 14:54:38,625 WARN org.apache.hadoop.yarn.server.resourcemanager.rmapp.RMAppImpl: The specific max attempts: 0 for application: 4 is invalid, because it is out of the range [1, 2]. Use the global max attempts instead.
2016-08-21 14:54:38,626 INFO org.apache.hadoop.yarn.server.resourcemanager.ClientRMService: Application with id 4 submitted by user tanle
2016-08-21 14:54:38,626 INFO org.apache.hadoop.yarn.server.resourcemanager.rmapp.RMAppImpl: Storing application with id application_1471812677892_0004
2016-08-21 14:54:38,626 INFO org.apache.hadoop.yarn.server.resourcemanager.RMAuditLogger: USER=tanle	IP=128.104.222.71	OPERATION=Submit Application Request	TARGET=ClientRMService	RESULT=SUCCESS	APPID=application_1471812677892_0004
2016-08-21 14:54:38,626 INFO org.apache.hadoop.yarn.server.resourcemanager.recovery.RMStateStore: Storing info for app: application_1471812677892_0004
2016-08-21 14:54:38,631 INFO org.apache.hadoop.yarn.server.resourcemanager.scheduler.fair.FairScheduler: Accepted application application_1471812677892_0004 from user: tanle, in queue: interactive3, currently num of applications: 4
2016-08-21 14:54:38,631 INFO org.apache.hadoop.yarn.server.resourcemanager.ApplicationMasterService: Registering app attempt : appattempt_1471812677892_0004_000001
2016-08-21 14:54:38,631 INFO org.apache.hadoop.yarn.server.resourcemanager.rmapp.attempt.RMAppAttemptImpl: appattempt_1471812677892_0004_000001 State change from NEW to SUBMITTED
2016-08-21 14:54:38,632 INFO org.apache.hadoop.yarn.server.resourcemanager.scheduler.fair.FairScheduler: Added Application Attempt appattempt_1471812677892_0004_000001 to scheduler from user: tanle
2016-08-21 14:54:38,632 INFO org.apache.hadoop.yarn.server.resourcemanager.rmapp.attempt.RMAppAttemptImpl: ScheduleTransition.transition(appattempt_1471812677892_0004_000001,EventType: ATTEMPT_ADDED)
2016-08-21 14:54:38,632 INFO org.apache.hadoop.yarn.server.resourcemanager.scheduler.fair.FairScheduler: allocate(appattempt_1471812677892_0004_000001 [{Priority: 0, Capability: <memory:2048, vCores:1>, # Containers: 1, Location: *, Relax Locality: true}] [] null null
2016-08-21 14:54:38,632 INFO org.apache.hadoop.yarn.server.resourcemanager.scheduler.fair.FSAppAttempt: root.interactive1: <memory:0, vCores:0>
2016-08-21 14:54:38,633 INFO org.apache.hadoop.yarn.server.resourcemanager.scheduler.fair.FSAppAttempt: root.interactive2: <memory:0, vCores:0>
2016-08-21 14:54:38,633 INFO org.apache.hadoop.yarn.server.resourcemanager.scheduler.fair.FSAppAttempt: root.batch: <memory:16384, vCores:8>
2016-08-21 14:54:38,633 INFO org.apache.hadoop.yarn.server.resourcemanager.scheduler.fair.FSAppAttempt: appattempt_1471812677892_0004_000001 minReqResource: <memory:16384, vCores:8> flexibleResource: <memory:0, vCores:0>
2016-08-21 14:54:38,633 INFO org.apache.hadoop.yarn.server.resourcemanager.scheduler.fair.FairScheduler: Cannot allocate appattempt_1471812677892_0004_000001 because there is NO flexible resource left
2016-08-21 14:54:38,698 INFO org.apache.hadoop.yarn.server.resourcemanager.scheduler.fair.FairScheduler: allocate(appattempt_1471812677892_0002_000001 [{Priority: 1, Capability: <memory:1920, vCores:1>, # Containers: 8, Location: *, Relax Locality: true}] [] [] []
2016-08-21 14:54:38,698 INFO org.apache.hadoop.yarn.server.resourcemanager.scheduler.fair.FSAppAttempt: root.interactive1: <memory:0, vCores:0>
2016-08-21 14:54:38,698 INFO org.apache.hadoop.yarn.server.resourcemanager.scheduler.fair.FSAppAttempt: root.interactive2: <memory:0, vCores:0>
2016-08-21 14:54:38,698 INFO org.apache.hadoop.yarn.server.resourcemanager.scheduler.fair.FSAppAttempt: root.batch: <memory:16384, vCores:8>
2016-08-21 14:54:38,698 INFO org.apache.hadoop.yarn.server.resourcemanager.scheduler.fair.FSAppAttempt: appattempt_1471812677892_0002_000001 minReqResource: <memory:16384, vCores:8> flexibleResource: <memory:0, vCores:0>
2016-08-21 14:54:38,698 INFO org.apache.hadoop.yarn.server.resourcemanager.scheduler.fair.FairScheduler: allocate resource to application attempt: appattempt_1471812677892_0002_000001 queue:root.batch isRunning=true 
2016-08-21 14:54:38,699 INFO org.apache.hadoop.yarn.server.resourcemanager.scheduler.fair.FairScheduler: iglf: 2.getHeadroom()=<memory:0, vCores:0>
2016-08-21 14:54:38,784 WARN org.apache.hadoop.yarn.server.resourcemanager.rmapp.RMAppImpl: The specific max attempts: 0 for application: 6 is invalid, because it is out of the range [1, 2]. Use the global max attempts instead.
2016-08-21 14:54:38,784 INFO org.apache.hadoop.yarn.server.resourcemanager.ClientRMService: Application with id 6 submitted by user tanle
2016-08-21 14:54:38,784 INFO org.apache.hadoop.yarn.server.resourcemanager.RMAuditLogger: USER=tanle	IP=128.104.222.71	OPERATION=Submit Application Request	TARGET=ClientRMService	RESULT=SUCCESS	APPID=application_1471812677892_0006
2016-08-21 14:54:38,784 INFO org.apache.hadoop.yarn.server.resourcemanager.rmapp.RMAppImpl: Storing application with id application_1471812677892_0006
2016-08-21 14:54:38,785 INFO org.apache.hadoop.yarn.server.resourcemanager.recovery.RMStateStore: Storing info for app: application_1471812677892_0006
2016-08-21 14:54:38,785 INFO org.apache.hadoop.yarn.server.resourcemanager.scheduler.fair.FairScheduler: Accepted application application_1471812677892_0006 from user: tanle, in queue: batch, currently num of applications: 5
2016-08-21 14:54:38,786 INFO org.apache.hadoop.yarn.server.resourcemanager.ApplicationMasterService: Registering app attempt : appattempt_1471812677892_0006_000001
2016-08-21 14:54:38,786 INFO org.apache.hadoop.yarn.server.resourcemanager.rmapp.attempt.RMAppAttemptImpl: appattempt_1471812677892_0006_000001 State change from NEW to SUBMITTED
2016-08-21 14:54:38,786 INFO org.apache.hadoop.yarn.server.resourcemanager.scheduler.fair.FairScheduler: Added Application Attempt appattempt_1471812677892_0006_000001 to scheduler from user: tanle
2016-08-21 14:54:38,787 INFO org.apache.hadoop.yarn.server.resourcemanager.rmapp.attempt.RMAppAttemptImpl: ScheduleTransition.transition(appattempt_1471812677892_0006_000001,EventType: ATTEMPT_ADDED)
2016-08-21 14:54:38,787 INFO org.apache.hadoop.yarn.server.resourcemanager.scheduler.fair.FairScheduler: allocate(appattempt_1471812677892_0006_000001 [{Priority: 0, Capability: <memory:2048, vCores:1>, # Containers: 1, Location: *, Relax Locality: true}] [] null null
2016-08-21 14:54:38,787 INFO org.apache.hadoop.yarn.server.resourcemanager.scheduler.fair.FSAppAttempt: root.interactive1: <memory:0, vCores:0>
2016-08-21 14:54:38,787 INFO org.apache.hadoop.yarn.server.resourcemanager.scheduler.fair.FSAppAttempt: root.interactive2: <memory:0, vCores:0>
2016-08-21 14:54:38,787 INFO org.apache.hadoop.yarn.server.resourcemanager.scheduler.fair.FSAppAttempt: root.batch: <memory:16384, vCores:8>
2016-08-21 14:54:38,787 INFO org.apache.hadoop.yarn.server.resourcemanager.scheduler.fair.FSAppAttempt: appattempt_1471812677892_0006_000001 minReqResource: <memory:16384, vCores:8> flexibleResource: <memory:0, vCores:0>
2016-08-21 14:54:38,787 INFO org.apache.hadoop.yarn.server.resourcemanager.scheduler.fair.FairScheduler: allocate resource to application attempt: appattempt_1471812677892_0006_000001 queue:root.batch isRunning=true 
2016-08-21 14:54:38,788 INFO org.apache.hadoop.yarn.server.resourcemanager.scheduler.fair.FairScheduler: iglf: 6.getHeadroom()=<memory:0, vCores:0>
2016-08-21 14:54:38,788 INFO org.apache.hadoop.yarn.server.resourcemanager.rmapp.attempt.RMAppAttemptImpl: appattempt_1471812677892_0006_000001 State change from SUBMITTED to SCHEDULED
2016-08-21 14:54:38,901 INFO org.apache.hadoop.yarn.server.resourcemanager.scheduler.fair.FairScheduler: allocate(appattempt_1471812677892_0002_000001 [] [] [] []
2016-08-21 14:54:38,901 INFO org.apache.hadoop.yarn.server.resourcemanager.scheduler.fair.FSAppAttempt: root.interactive1: <memory:0, vCores:0>
2016-08-21 14:54:38,901 INFO org.apache.hadoop.yarn.server.resourcemanager.scheduler.fair.FSAppAttempt: root.interactive2: <memory:0, vCores:0>
2016-08-21 14:54:38,901 INFO org.apache.hadoop.yarn.server.resourcemanager.scheduler.fair.FSAppAttempt: root.batch: <memory:16384, vCores:8>
2016-08-21 14:54:38,902 INFO org.apache.hadoop.yarn.server.resourcemanager.scheduler.fair.FSAppAttempt: appattempt_1471812677892_0002_000001 minReqResource: <memory:16384, vCores:8> flexibleResource: <memory:0, vCores:0>
2016-08-21 14:54:38,902 INFO org.apache.hadoop.yarn.server.resourcemanager.scheduler.fair.FairScheduler: allocate resource to application attempt: appattempt_1471812677892_0002_000001 queue:root.batch isRunning=true 
2016-08-21 14:54:38,902 INFO org.apache.hadoop.yarn.server.resourcemanager.scheduler.fair.FairScheduler: iglf: 2.getHeadroom()=<memory:0, vCores:0>
2016-08-21 14:54:39,304 INFO org.apache.hadoop.yarn.server.resourcemanager.scheduler.fair.FairScheduler: allocate(appattempt_1471812677892_0002_000001 [] [] [] []
2016-08-21 14:54:39,304 INFO org.apache.hadoop.yarn.server.resourcemanager.scheduler.fair.FSAppAttempt: root.interactive1: <memory:0, vCores:0>
2016-08-21 14:54:39,305 INFO org.apache.hadoop.yarn.server.resourcemanager.scheduler.fair.FSAppAttempt: root.interactive2: <memory:0, vCores:0>
2016-08-21 14:54:39,305 INFO org.apache.hadoop.yarn.server.resourcemanager.scheduler.fair.FSAppAttempt: root.batch: <memory:16384, vCores:8>
2016-08-21 14:54:39,305 INFO org.apache.hadoop.yarn.server.resourcemanager.scheduler.fair.FSAppAttempt: appattempt_1471812677892_0002_000001 minReqResource: <memory:16384, vCores:8> flexibleResource: <memory:0, vCores:0>
2016-08-21 14:54:39,305 INFO org.apache.hadoop.yarn.server.resourcemanager.scheduler.fair.FairScheduler: allocate resource to application attempt: appattempt_1471812677892_0002_000001 queue:root.batch isRunning=true 
2016-08-21 14:54:39,305 INFO org.apache.hadoop.yarn.server.resourcemanager.scheduler.fair.FairScheduler: iglf: 2.getHeadroom()=<memory:0, vCores:0>
2016-08-21 14:54:39,636 INFO org.apache.hadoop.yarn.server.resourcemanager.rmapp.attempt.RMAppAttemptImpl: ScheduleTransition.transition(appattempt_1471812677892_0004_000001,EventType: ATTEMPT_ADDED)
2016-08-21 14:54:39,636 INFO org.apache.hadoop.yarn.server.resourcemanager.scheduler.fair.FairScheduler: allocate(appattempt_1471812677892_0004_000001 [{Priority: 0, Capability: <memory:2048, vCores:1>, # Containers: 1, Location: *, Relax Locality: true}] [] null null
2016-08-21 14:54:39,636 INFO org.apache.hadoop.yarn.server.resourcemanager.scheduler.fair.FSAppAttempt: root.interactive1: <memory:0, vCores:0>
2016-08-21 14:54:39,636 INFO org.apache.hadoop.yarn.server.resourcemanager.scheduler.fair.FSAppAttempt: root.interactive2: <memory:0, vCores:0>
2016-08-21 14:54:39,636 INFO org.apache.hadoop.yarn.server.resourcemanager.scheduler.fair.FSAppAttempt: root.batch: <memory:16384, vCores:8>
2016-08-21 14:54:39,636 INFO org.apache.hadoop.yarn.server.resourcemanager.scheduler.fair.FSAppAttempt: appattempt_1471812677892_0004_000001 minReqResource: <memory:16384, vCores:8> flexibleResource: <memory:0, vCores:0>
2016-08-21 14:54:39,636 INFO org.apache.hadoop.yarn.server.resourcemanager.scheduler.fair.FairScheduler: Cannot allocate appattempt_1471812677892_0004_000001 because there is NO flexible resource left
2016-08-21 14:54:40,107 INFO org.apache.hadoop.yarn.server.resourcemanager.scheduler.fair.FairScheduler: allocate(appattempt_1471812677892_0002_000001 [] [] [] []
2016-08-21 14:54:40,108 INFO org.apache.hadoop.yarn.server.resourcemanager.scheduler.fair.FSAppAttempt: root.interactive1: <memory:0, vCores:0>
2016-08-21 14:54:40,108 INFO org.apache.hadoop.yarn.server.resourcemanager.scheduler.fair.FSAppAttempt: root.interactive2: <memory:0, vCores:0>
2016-08-21 14:54:40,108 INFO org.apache.hadoop.yarn.server.resourcemanager.scheduler.fair.FSAppAttempt: root.batch: <memory:16384, vCores:8>
2016-08-21 14:54:40,108 INFO org.apache.hadoop.yarn.server.resourcemanager.scheduler.fair.FSAppAttempt: appattempt_1471812677892_0002_000001 minReqResource: <memory:16384, vCores:8> flexibleResource: <memory:0, vCores:0>
2016-08-21 14:54:40,108 INFO org.apache.hadoop.yarn.server.resourcemanager.scheduler.fair.FairScheduler: allocate resource to application attempt: appattempt_1471812677892_0002_000001 queue:root.batch isRunning=true 
2016-08-21 14:54:40,108 INFO org.apache.hadoop.yarn.server.resourcemanager.scheduler.fair.FairScheduler: iglf: 2.getHeadroom()=<memory:0, vCores:0>
2016-08-21 14:54:40,638 INFO org.apache.hadoop.yarn.server.resourcemanager.rmapp.attempt.RMAppAttemptImpl: ScheduleTransition.transition(appattempt_1471812677892_0004_000001,EventType: ATTEMPT_ADDED)
2016-08-21 14:54:40,638 INFO org.apache.hadoop.yarn.server.resourcemanager.scheduler.fair.FairScheduler: allocate(appattempt_1471812677892_0004_000001 [{Priority: 0, Capability: <memory:2048, vCores:1>, # Containers: 1, Location: *, Relax Locality: true}] [] null null
2016-08-21 14:54:40,638 INFO org.apache.hadoop.yarn.server.resourcemanager.scheduler.fair.FSAppAttempt: root.interactive1: <memory:0, vCores:0>
2016-08-21 14:54:40,638 INFO org.apache.hadoop.yarn.server.resourcemanager.scheduler.fair.FSAppAttempt: root.interactive2: <memory:0, vCores:0>
2016-08-21 14:54:40,638 INFO org.apache.hadoop.yarn.server.resourcemanager.scheduler.fair.FSAppAttempt: root.batch: <memory:16384, vCores:8>
2016-08-21 14:54:40,638 INFO org.apache.hadoop.yarn.server.resourcemanager.scheduler.fair.FSAppAttempt: appattempt_1471812677892_0004_000001 minReqResource: <memory:16384, vCores:8> flexibleResource: <memory:0, vCores:0>
2016-08-21 14:54:40,638 INFO org.apache.hadoop.yarn.server.resourcemanager.scheduler.fair.FairScheduler: Cannot allocate appattempt_1471812677892_0004_000001 because there is NO flexible resource left
2016-08-21 14:54:41,640 INFO org.apache.hadoop.yarn.server.resourcemanager.rmapp.attempt.RMAppAttemptImpl: ScheduleTransition.transition(appattempt_1471812677892_0004_000001,EventType: ATTEMPT_ADDED)
2016-08-21 14:54:41,640 INFO org.apache.hadoop.yarn.server.resourcemanager.scheduler.fair.FairScheduler: allocate(appattempt_1471812677892_0004_000001 [{Priority: 0, Capability: <memory:2048, vCores:1>, # Containers: 1, Location: *, Relax Locality: true}] [] null null
2016-08-21 14:54:41,640 INFO org.apache.hadoop.yarn.server.resourcemanager.scheduler.fair.FSAppAttempt: root.interactive1: <memory:0, vCores:0>
2016-08-21 14:54:41,640 INFO org.apache.hadoop.yarn.server.resourcemanager.scheduler.fair.FSAppAttempt: root.interactive2: <memory:0, vCores:0>
2016-08-21 14:54:41,640 INFO org.apache.hadoop.yarn.server.resourcemanager.scheduler.fair.FSAppAttempt: root.batch: <memory:16384, vCores:8>
2016-08-21 14:54:41,641 INFO org.apache.hadoop.yarn.server.resourcemanager.scheduler.fair.FSAppAttempt: appattempt_1471812677892_0004_000001 minReqResource: <memory:16384, vCores:8> flexibleResource: <memory:0, vCores:0>
2016-08-21 14:54:41,641 INFO org.apache.hadoop.yarn.server.resourcemanager.scheduler.fair.FairScheduler: Cannot allocate appattempt_1471812677892_0004_000001 because there is NO flexible resource left
2016-08-21 14:54:41,711 INFO org.apache.hadoop.yarn.server.resourcemanager.scheduler.fair.FairScheduler: allocate(appattempt_1471812677892_0002_000001 [] [] [] []
2016-08-21 14:54:41,711 INFO org.apache.hadoop.yarn.server.resourcemanager.scheduler.fair.FSAppAttempt: root.interactive1: <memory:0, vCores:0>
2016-08-21 14:54:41,711 INFO org.apache.hadoop.yarn.server.resourcemanager.scheduler.fair.FSAppAttempt: root.interactive2: <memory:0, vCores:0>
2016-08-21 14:54:41,711 INFO org.apache.hadoop.yarn.server.resourcemanager.scheduler.fair.FSAppAttempt: root.batch: <memory:16384, vCores:8>
2016-08-21 14:54:41,711 INFO org.apache.hadoop.yarn.server.resourcemanager.scheduler.fair.FSAppAttempt: appattempt_1471812677892_0002_000001 minReqResource: <memory:16384, vCores:8> flexibleResource: <memory:0, vCores:0>
2016-08-21 14:54:41,711 INFO org.apache.hadoop.yarn.server.resourcemanager.scheduler.fair.FairScheduler: allocate resource to application attempt: appattempt_1471812677892_0002_000001 queue:root.batch isRunning=true 
2016-08-21 14:54:41,711 INFO org.apache.hadoop.yarn.server.resourcemanager.scheduler.fair.FairScheduler: iglf: 2.getHeadroom()=<memory:0, vCores:0>
2016-08-21 14:54:42,642 INFO org.apache.hadoop.yarn.server.resourcemanager.rmapp.attempt.RMAppAttemptImpl: ScheduleTransition.transition(appattempt_1471812677892_0004_000001,EventType: ATTEMPT_ADDED)
2016-08-21 14:54:42,642 INFO org.apache.hadoop.yarn.server.resourcemanager.scheduler.fair.FairScheduler: allocate(appattempt_1471812677892_0004_000001 [{Priority: 0, Capability: <memory:2048, vCores:1>, # Containers: 1, Location: *, Relax Locality: true}] [] null null
2016-08-21 14:54:42,642 INFO org.apache.hadoop.yarn.server.resourcemanager.scheduler.fair.FSAppAttempt: root.interactive1: <memory:0, vCores:0>
2016-08-21 14:54:42,642 INFO org.apache.hadoop.yarn.server.resourcemanager.scheduler.fair.FSAppAttempt: root.interactive2: <memory:0, vCores:0>
2016-08-21 14:54:42,642 INFO org.apache.hadoop.yarn.server.resourcemanager.scheduler.fair.FSAppAttempt: root.batch: <memory:16384, vCores:8>
2016-08-21 14:54:42,642 INFO org.apache.hadoop.yarn.server.resourcemanager.scheduler.fair.FSAppAttempt: appattempt_1471812677892_0004_000001 minReqResource: <memory:16384, vCores:8> flexibleResource: <memory:0, vCores:0>
2016-08-21 14:54:42,642 INFO org.apache.hadoop.yarn.server.resourcemanager.scheduler.fair.FairScheduler: Cannot allocate appattempt_1471812677892_0004_000001 because there is NO flexible resource left
2016-08-21 14:54:42,958 WARN org.apache.hadoop.yarn.server.resourcemanager.rmapp.RMAppImpl: The specific max attempts: 0 for application: 7 is invalid, because it is out of the range [1, 2]. Use the global max attempts instead.
2016-08-21 14:54:42,958 INFO org.apache.hadoop.yarn.server.resourcemanager.ClientRMService: Application with id 7 submitted by user tanle
2016-08-21 14:54:42,958 INFO org.apache.hadoop.yarn.server.resourcemanager.RMAuditLogger: USER=tanle	IP=128.104.222.71	OPERATION=Submit Application Request	TARGET=ClientRMService	RESULT=SUCCESS	APPID=application_1471812677892_0007
2016-08-21 14:54:42,958 INFO org.apache.hadoop.yarn.server.resourcemanager.rmapp.RMAppImpl: Storing application with id application_1471812677892_0007
2016-08-21 14:54:42,959 INFO org.apache.hadoop.yarn.server.resourcemanager.recovery.RMStateStore: Storing info for app: application_1471812677892_0007
2016-08-21 14:54:42,959 INFO org.apache.hadoop.yarn.server.resourcemanager.scheduler.fair.FairScheduler: Accepted application application_1471812677892_0007 from user: tanle, in queue: batch, currently num of applications: 6
2016-08-21 14:54:42,960 INFO org.apache.hadoop.yarn.server.resourcemanager.ApplicationMasterService: Registering app attempt : appattempt_1471812677892_0007_000001
2016-08-21 14:54:42,960 INFO org.apache.hadoop.yarn.server.resourcemanager.rmapp.attempt.RMAppAttemptImpl: appattempt_1471812677892_0007_000001 State change from NEW to SUBMITTED
2016-08-21 14:54:42,961 INFO org.apache.hadoop.yarn.server.resourcemanager.scheduler.fair.FairScheduler: Added Application Attempt appattempt_1471812677892_0007_000001 to scheduler from user: tanle
2016-08-21 14:54:42,961 INFO org.apache.hadoop.yarn.server.resourcemanager.rmapp.attempt.RMAppAttemptImpl: ScheduleTransition.transition(appattempt_1471812677892_0007_000001,EventType: ATTEMPT_ADDED)
2016-08-21 14:54:42,961 INFO org.apache.hadoop.yarn.server.resourcemanager.scheduler.fair.FairScheduler: allocate(appattempt_1471812677892_0007_000001 [{Priority: 0, Capability: <memory:2048, vCores:1>, # Containers: 1, Location: *, Relax Locality: true}] [] null null
2016-08-21 14:54:42,961 INFO org.apache.hadoop.yarn.server.resourcemanager.scheduler.fair.FSAppAttempt: root.interactive1: <memory:0, vCores:0>
2016-08-21 14:54:42,961 INFO org.apache.hadoop.yarn.server.resourcemanager.scheduler.fair.FSAppAttempt: root.interactive2: <memory:0, vCores:0>
2016-08-21 14:54:42,961 INFO org.apache.hadoop.yarn.server.resourcemanager.scheduler.fair.FSAppAttempt: root.batch: <memory:16384, vCores:8>
2016-08-21 14:54:42,961 INFO org.apache.hadoop.yarn.server.resourcemanager.scheduler.fair.FSAppAttempt: appattempt_1471812677892_0007_000001 minReqResource: <memory:16384, vCores:8> flexibleResource: <memory:0, vCores:0>
2016-08-21 14:54:42,962 INFO org.apache.hadoop.yarn.server.resourcemanager.scheduler.fair.FairScheduler: allocate resource to application attempt: appattempt_1471812677892_0007_000001 queue:root.batch isRunning=true 
2016-08-21 14:54:42,962 INFO org.apache.hadoop.yarn.server.resourcemanager.scheduler.fair.FairScheduler: iglf: 7.getHeadroom()=<memory:0, vCores:0>
2016-08-21 14:54:42,962 INFO org.apache.hadoop.yarn.server.resourcemanager.rmapp.attempt.RMAppAttemptImpl: appattempt_1471812677892_0007_000001 State change from SUBMITTED to SCHEDULED
2016-08-21 14:54:43,643 INFO org.apache.hadoop.yarn.server.resourcemanager.rmapp.attempt.RMAppAttemptImpl: ScheduleTransition.transition(appattempt_1471812677892_0004_000001,EventType: ATTEMPT_ADDED)
2016-08-21 14:54:43,644 INFO org.apache.hadoop.yarn.server.resourcemanager.scheduler.fair.FairScheduler: allocate(appattempt_1471812677892_0004_000001 [{Priority: 0, Capability: <memory:2048, vCores:1>, # Containers: 1, Location: *, Relax Locality: true}] [] null null
2016-08-21 14:54:43,644 INFO org.apache.hadoop.yarn.server.resourcemanager.scheduler.fair.FSAppAttempt: root.interactive1: <memory:0, vCores:0>
2016-08-21 14:54:43,644 INFO org.apache.hadoop.yarn.server.resourcemanager.scheduler.fair.FSAppAttempt: root.interactive2: <memory:0, vCores:0>
2016-08-21 14:54:43,644 INFO org.apache.hadoop.yarn.server.resourcemanager.scheduler.fair.FSAppAttempt: root.batch: <memory:16384, vCores:8>
2016-08-21 14:54:43,644 INFO org.apache.hadoop.yarn.server.resourcemanager.scheduler.fair.FSAppAttempt: appattempt_1471812677892_0004_000001 minReqResource: <memory:16384, vCores:8> flexibleResource: <memory:0, vCores:0>
2016-08-21 14:54:43,644 INFO org.apache.hadoop.yarn.server.resourcemanager.scheduler.fair.FairScheduler: Cannot allocate appattempt_1471812677892_0004_000001 because there is NO flexible resource left
2016-08-21 14:54:43,700 INFO org.apache.hadoop.yarn.server.resourcemanager.scheduler.fair.FairScheduler: allocate(appattempt_1471812677892_0002_000001 [{Priority: 1, Capability: <memory:1920, vCores:1>, # Containers: 24, Location: *, Relax Locality: true}] [] [] []
2016-08-21 14:54:43,700 INFO org.apache.hadoop.yarn.server.resourcemanager.scheduler.fair.FSAppAttempt: root.interactive1: <memory:0, vCores:0>
2016-08-21 14:54:43,700 INFO org.apache.hadoop.yarn.server.resourcemanager.scheduler.fair.FSAppAttempt: root.interactive2: <memory:0, vCores:0>
2016-08-21 14:54:43,700 INFO org.apache.hadoop.yarn.server.resourcemanager.scheduler.fair.FSAppAttempt: root.batch: <memory:16384, vCores:8>
2016-08-21 14:54:43,700 INFO org.apache.hadoop.yarn.server.resourcemanager.scheduler.fair.FSAppAttempt: appattempt_1471812677892_0002_000001 minReqResource: <memory:16384, vCores:8> flexibleResource: <memory:0, vCores:0>
2016-08-21 14:54:43,700 INFO org.apache.hadoop.yarn.server.resourcemanager.scheduler.fair.FairScheduler: allocate resource to application attempt: appattempt_1471812677892_0002_000001 queue:root.batch isRunning=true 
2016-08-21 14:54:43,701 INFO org.apache.hadoop.yarn.server.resourcemanager.scheduler.fair.FairScheduler: iglf: 2.getHeadroom()=<memory:0, vCores:0>
2016-08-21 14:54:43,904 INFO org.apache.hadoop.yarn.server.resourcemanager.scheduler.fair.FairScheduler: allocate(appattempt_1471812677892_0002_000001 [] [] [] []
2016-08-21 14:54:43,904 INFO org.apache.hadoop.yarn.server.resourcemanager.scheduler.fair.FSAppAttempt: root.interactive1: <memory:0, vCores:0>
2016-08-21 14:54:43,904 INFO org.apache.hadoop.yarn.server.resourcemanager.scheduler.fair.FSAppAttempt: root.interactive2: <memory:0, vCores:0>
2016-08-21 14:54:43,904 INFO org.apache.hadoop.yarn.server.resourcemanager.scheduler.fair.FSAppAttempt: root.batch: <memory:16384, vCores:8>
2016-08-21 14:54:43,904 INFO org.apache.hadoop.yarn.server.resourcemanager.scheduler.fair.FSAppAttempt: appattempt_1471812677892_0002_000001 minReqResource: <memory:16384, vCores:8> flexibleResource: <memory:0, vCores:0>
2016-08-21 14:54:43,904 INFO org.apache.hadoop.yarn.server.resourcemanager.scheduler.fair.FairScheduler: allocate resource to application attempt: appattempt_1471812677892_0002_000001 queue:root.batch isRunning=true 
2016-08-21 14:54:43,904 INFO org.apache.hadoop.yarn.server.resourcemanager.scheduler.fair.FairScheduler: iglf: 2.getHeadroom()=<memory:0, vCores:0>
2016-08-21 14:54:44,307 INFO org.apache.hadoop.yarn.server.resourcemanager.scheduler.fair.FairScheduler: allocate(appattempt_1471812677892_0002_000001 [] [] [] []
2016-08-21 14:54:44,307 INFO org.apache.hadoop.yarn.server.resourcemanager.scheduler.fair.FSAppAttempt: root.interactive1: <memory:0, vCores:0>
2016-08-21 14:54:44,307 INFO org.apache.hadoop.yarn.server.resourcemanager.scheduler.fair.FSAppAttempt: root.interactive2: <memory:0, vCores:0>
2016-08-21 14:54:44,307 INFO org.apache.hadoop.yarn.server.resourcemanager.scheduler.fair.FSAppAttempt: root.batch: <memory:16384, vCores:8>
2016-08-21 14:54:44,308 INFO org.apache.hadoop.yarn.server.resourcemanager.scheduler.fair.FSAppAttempt: appattempt_1471812677892_0002_000001 minReqResource: <memory:16384, vCores:8> flexibleResource: <memory:0, vCores:0>
2016-08-21 14:54:44,308 INFO org.apache.hadoop.yarn.server.resourcemanager.scheduler.fair.FairScheduler: allocate resource to application attempt: appattempt_1471812677892_0002_000001 queue:root.batch isRunning=true 
2016-08-21 14:54:44,308 INFO org.apache.hadoop.yarn.server.resourcemanager.scheduler.fair.FairScheduler: iglf: 2.getHeadroom()=<memory:0, vCores:0>
2016-08-21 14:54:44,646 INFO org.apache.hadoop.yarn.server.resourcemanager.rmapp.attempt.RMAppAttemptImpl: ScheduleTransition.transition(appattempt_1471812677892_0004_000001,EventType: ATTEMPT_ADDED)
2016-08-21 14:54:44,646 INFO org.apache.hadoop.yarn.server.resourcemanager.scheduler.fair.FairScheduler: allocate(appattempt_1471812677892_0004_000001 [{Priority: 0, Capability: <memory:2048, vCores:1>, # Containers: 1, Location: *, Relax Locality: true}] [] null null
2016-08-21 14:54:44,646 INFO org.apache.hadoop.yarn.server.resourcemanager.scheduler.fair.FSAppAttempt: root.interactive1: <memory:0, vCores:0>
2016-08-21 14:54:44,646 INFO org.apache.hadoop.yarn.server.resourcemanager.scheduler.fair.FSAppAttempt: root.interactive2: <memory:0, vCores:0>
2016-08-21 14:54:44,646 INFO org.apache.hadoop.yarn.server.resourcemanager.scheduler.fair.FSAppAttempt: root.batch: <memory:16384, vCores:8>
2016-08-21 14:54:44,646 INFO org.apache.hadoop.yarn.server.resourcemanager.scheduler.fair.FSAppAttempt: appattempt_1471812677892_0004_000001 minReqResource: <memory:16384, vCores:8> flexibleResource: <memory:0, vCores:0>
2016-08-21 14:54:44,646 INFO org.apache.hadoop.yarn.server.resourcemanager.scheduler.fair.FairScheduler: Cannot allocate appattempt_1471812677892_0004_000001 because there is NO flexible resource left
2016-08-21 14:54:45,111 INFO org.apache.hadoop.yarn.server.resourcemanager.scheduler.fair.FairScheduler: allocate(appattempt_1471812677892_0002_000001 [] [] [] []
2016-08-21 14:54:45,111 INFO org.apache.hadoop.yarn.server.resourcemanager.scheduler.fair.FSAppAttempt: root.interactive1: <memory:0, vCores:0>
2016-08-21 14:54:45,111 INFO org.apache.hadoop.yarn.server.resourcemanager.scheduler.fair.FSAppAttempt: root.interactive2: <memory:0, vCores:0>
2016-08-21 14:54:45,111 INFO org.apache.hadoop.yarn.server.resourcemanager.scheduler.fair.FSAppAttempt: root.batch: <memory:16384, vCores:8>
2016-08-21 14:54:45,111 INFO org.apache.hadoop.yarn.server.resourcemanager.scheduler.fair.FSAppAttempt: appattempt_1471812677892_0002_000001 minReqResource: <memory:16384, vCores:8> flexibleResource: <memory:0, vCores:0>
2016-08-21 14:54:45,111 INFO org.apache.hadoop.yarn.server.resourcemanager.scheduler.fair.FairScheduler: allocate resource to application attempt: appattempt_1471812677892_0002_000001 queue:root.batch isRunning=true 
2016-08-21 14:54:45,112 INFO org.apache.hadoop.yarn.server.resourcemanager.scheduler.fair.FairScheduler: iglf: 2.getHeadroom()=<memory:0, vCores:0>
2016-08-21 14:54:45,648 INFO org.apache.hadoop.yarn.server.resourcemanager.rmapp.attempt.RMAppAttemptImpl: ScheduleTransition.transition(appattempt_1471812677892_0004_000001,EventType: ATTEMPT_ADDED)
2016-08-21 14:54:45,648 INFO org.apache.hadoop.yarn.server.resourcemanager.scheduler.fair.FairScheduler: allocate(appattempt_1471812677892_0004_000001 [{Priority: 0, Capability: <memory:2048, vCores:1>, # Containers: 1, Location: *, Relax Locality: true}] [] null null
2016-08-21 14:54:45,648 INFO org.apache.hadoop.yarn.server.resourcemanager.scheduler.fair.FSAppAttempt: root.interactive1: <memory:0, vCores:0>
2016-08-21 14:54:45,648 INFO org.apache.hadoop.yarn.server.resourcemanager.scheduler.fair.FSAppAttempt: root.interactive2: <memory:0, vCores:0>
2016-08-21 14:54:45,648 INFO org.apache.hadoop.yarn.server.resourcemanager.scheduler.fair.FSAppAttempt: root.batch: <memory:16384, vCores:8>
2016-08-21 14:54:45,648 INFO org.apache.hadoop.yarn.server.resourcemanager.scheduler.fair.FSAppAttempt: appattempt_1471812677892_0004_000001 minReqResource: <memory:16384, vCores:8> flexibleResource: <memory:0, vCores:0>
2016-08-21 14:54:45,648 INFO org.apache.hadoop.yarn.server.resourcemanager.scheduler.fair.FairScheduler: Cannot allocate appattempt_1471812677892_0004_000001 because there is NO flexible resource left
2016-08-21 14:54:46,649 INFO org.apache.hadoop.yarn.server.resourcemanager.rmapp.attempt.RMAppAttemptImpl: ScheduleTransition.transition(appattempt_1471812677892_0004_000001,EventType: ATTEMPT_ADDED)
2016-08-21 14:54:46,649 INFO org.apache.hadoop.yarn.server.resourcemanager.scheduler.fair.FairScheduler: allocate(appattempt_1471812677892_0004_000001 [{Priority: 0, Capability: <memory:2048, vCores:1>, # Containers: 1, Location: *, Relax Locality: true}] [] null null
2016-08-21 14:54:46,649 INFO org.apache.hadoop.yarn.server.resourcemanager.scheduler.fair.FSAppAttempt: root.interactive1: <memory:0, vCores:0>
2016-08-21 14:54:46,650 INFO org.apache.hadoop.yarn.server.resourcemanager.scheduler.fair.FSAppAttempt: root.interactive2: <memory:0, vCores:0>
2016-08-21 14:54:46,650 INFO org.apache.hadoop.yarn.server.resourcemanager.scheduler.fair.FSAppAttempt: root.batch: <memory:16384, vCores:8>
2016-08-21 14:54:46,650 INFO org.apache.hadoop.yarn.server.resourcemanager.scheduler.fair.FSAppAttempt: appattempt_1471812677892_0004_000001 minReqResource: <memory:16384, vCores:8> flexibleResource: <memory:0, vCores:0>
2016-08-21 14:54:46,650 INFO org.apache.hadoop.yarn.server.resourcemanager.scheduler.fair.FairScheduler: Cannot allocate appattempt_1471812677892_0004_000001 because there is NO flexible resource left
2016-08-21 14:54:46,715 INFO org.apache.hadoop.yarn.server.resourcemanager.scheduler.fair.FairScheduler: allocate(appattempt_1471812677892_0002_000001 [] [] [] []
2016-08-21 14:54:46,715 INFO org.apache.hadoop.yarn.server.resourcemanager.scheduler.fair.FSAppAttempt: root.interactive1: <memory:0, vCores:0>
2016-08-21 14:54:46,715 INFO org.apache.hadoop.yarn.server.resourcemanager.scheduler.fair.FSAppAttempt: root.interactive2: <memory:0, vCores:0>
2016-08-21 14:54:46,715 INFO org.apache.hadoop.yarn.server.resourcemanager.scheduler.fair.FSAppAttempt: root.batch: <memory:16384, vCores:8>
2016-08-21 14:54:46,715 INFO org.apache.hadoop.yarn.server.resourcemanager.scheduler.fair.FSAppAttempt: appattempt_1471812677892_0002_000001 minReqResource: <memory:16384, vCores:8> flexibleResource: <memory:0, vCores:0>
2016-08-21 14:54:46,715 INFO org.apache.hadoop.yarn.server.resourcemanager.scheduler.fair.FairScheduler: allocate resource to application attempt: appattempt_1471812677892_0002_000001 queue:root.batch isRunning=true 
2016-08-21 14:54:46,715 INFO org.apache.hadoop.yarn.server.resourcemanager.scheduler.fair.FairScheduler: iglf: 2.getHeadroom()=<memory:0, vCores:0>
2016-08-21 14:54:47,652 INFO org.apache.hadoop.yarn.server.resourcemanager.rmapp.attempt.RMAppAttemptImpl: ScheduleTransition.transition(appattempt_1471812677892_0004_000001,EventType: ATTEMPT_ADDED)
2016-08-21 14:54:47,652 INFO org.apache.hadoop.yarn.server.resourcemanager.scheduler.fair.FairScheduler: allocate(appattempt_1471812677892_0004_000001 [{Priority: 0, Capability: <memory:2048, vCores:1>, # Containers: 1, Location: *, Relax Locality: true}] [] null null
2016-08-21 14:54:47,652 INFO org.apache.hadoop.yarn.server.resourcemanager.scheduler.fair.FSAppAttempt: root.interactive1: <memory:0, vCores:0>
2016-08-21 14:54:47,652 INFO org.apache.hadoop.yarn.server.resourcemanager.scheduler.fair.FSAppAttempt: root.interactive2: <memory:0, vCores:0>
2016-08-21 14:54:47,652 INFO org.apache.hadoop.yarn.server.resourcemanager.scheduler.fair.FSAppAttempt: root.batch: <memory:16384, vCores:8>
2016-08-21 14:54:47,652 INFO org.apache.hadoop.yarn.server.resourcemanager.scheduler.fair.FSAppAttempt: appattempt_1471812677892_0004_000001 minReqResource: <memory:16384, vCores:8> flexibleResource: <memory:0, vCores:0>
2016-08-21 14:54:47,653 INFO org.apache.hadoop.yarn.server.resourcemanager.scheduler.fair.FairScheduler: Cannot allocate appattempt_1471812677892_0004_000001 because there is NO flexible resource left
2016-08-21 14:54:48,654 INFO org.apache.hadoop.yarn.server.resourcemanager.rmapp.attempt.RMAppAttemptImpl: ScheduleTransition.transition(appattempt_1471812677892_0004_000001,EventType: ATTEMPT_ADDED)
2016-08-21 14:54:48,654 INFO org.apache.hadoop.yarn.server.resourcemanager.scheduler.fair.FairScheduler: allocate(appattempt_1471812677892_0004_000001 [{Priority: 0, Capability: <memory:2048, vCores:1>, # Containers: 1, Location: *, Relax Locality: true}] [] null null
2016-08-21 14:54:48,654 INFO org.apache.hadoop.yarn.server.resourcemanager.scheduler.fair.FSAppAttempt: root.interactive1: <memory:0, vCores:0>
2016-08-21 14:54:48,654 INFO org.apache.hadoop.yarn.server.resourcemanager.scheduler.fair.FSAppAttempt: root.interactive2: <memory:0, vCores:0>
2016-08-21 14:54:48,655 INFO org.apache.hadoop.yarn.server.resourcemanager.scheduler.fair.FSAppAttempt: root.batch: <memory:16384, vCores:8>
2016-08-21 14:54:48,655 INFO org.apache.hadoop.yarn.server.resourcemanager.scheduler.fair.FSAppAttempt: appattempt_1471812677892_0004_000001 minReqResource: <memory:16384, vCores:8> flexibleResource: <memory:0, vCores:0>
2016-08-21 14:54:48,655 INFO org.apache.hadoop.yarn.server.resourcemanager.scheduler.fair.FairScheduler: Cannot allocate appattempt_1471812677892_0004_000001 because there is NO flexible resource left
2016-08-21 14:54:48,701 INFO org.apache.hadoop.yarn.server.resourcemanager.scheduler.fair.FairScheduler: allocate(appattempt_1471812677892_0002_000001 [{Priority: 1, Capability: <memory:1920, vCores:1>, # Containers: 56, Location: *, Relax Locality: true}] [] [] []
2016-08-21 14:54:48,702 INFO org.apache.hadoop.yarn.server.resourcemanager.scheduler.fair.FSAppAttempt: root.interactive1: <memory:0, vCores:0>
2016-08-21 14:54:48,702 INFO org.apache.hadoop.yarn.server.resourcemanager.scheduler.fair.FSAppAttempt: root.interactive2: <memory:0, vCores:0>
2016-08-21 14:54:48,702 INFO org.apache.hadoop.yarn.server.resourcemanager.scheduler.fair.FSAppAttempt: root.batch: <memory:16384, vCores:8>
2016-08-21 14:54:48,702 INFO org.apache.hadoop.yarn.server.resourcemanager.scheduler.fair.FSAppAttempt: appattempt_1471812677892_0002_000001 minReqResource: <memory:16384, vCores:8> flexibleResource: <memory:0, vCores:0>
2016-08-21 14:54:48,702 INFO org.apache.hadoop.yarn.server.resourcemanager.scheduler.fair.FairScheduler: allocate resource to application attempt: appattempt_1471812677892_0002_000001 queue:root.batch isRunning=true 
2016-08-21 14:54:48,702 INFO org.apache.hadoop.yarn.server.resourcemanager.scheduler.fair.FairScheduler: iglf: 2.getHeadroom()=<memory:0, vCores:0>
2016-08-21 14:54:48,906 INFO org.apache.hadoop.yarn.server.resourcemanager.scheduler.fair.FairScheduler: allocate(appattempt_1471812677892_0002_000001 [] [] [] []
2016-08-21 14:54:48,906 INFO org.apache.hadoop.yarn.server.resourcemanager.scheduler.fair.FSAppAttempt: root.interactive1: <memory:0, vCores:0>
2016-08-21 14:54:48,906 INFO org.apache.hadoop.yarn.server.resourcemanager.scheduler.fair.FSAppAttempt: root.interactive2: <memory:0, vCores:0>
2016-08-21 14:54:48,906 INFO org.apache.hadoop.yarn.server.resourcemanager.scheduler.fair.FSAppAttempt: root.batch: <memory:16384, vCores:8>
2016-08-21 14:54:48,906 INFO org.apache.hadoop.yarn.server.resourcemanager.scheduler.fair.FSAppAttempt: appattempt_1471812677892_0002_000001 minReqResource: <memory:16384, vCores:8> flexibleResource: <memory:0, vCores:0>
2016-08-21 14:54:48,906 INFO org.apache.hadoop.yarn.server.resourcemanager.scheduler.fair.FairScheduler: allocate resource to application attempt: appattempt_1471812677892_0002_000001 queue:root.batch isRunning=true 
2016-08-21 14:54:48,906 INFO org.apache.hadoop.yarn.server.resourcemanager.scheduler.fair.FairScheduler: iglf: 2.getHeadroom()=<memory:0, vCores:0>
2016-08-21 14:54:49,309 INFO org.apache.hadoop.yarn.server.resourcemanager.scheduler.fair.FairScheduler: allocate(appattempt_1471812677892_0002_000001 [] [] [] []
2016-08-21 14:54:49,309 INFO org.apache.hadoop.yarn.server.resourcemanager.scheduler.fair.FSAppAttempt: root.interactive1: <memory:0, vCores:0>
2016-08-21 14:54:49,309 INFO org.apache.hadoop.yarn.server.resourcemanager.scheduler.fair.FSAppAttempt: root.interactive2: <memory:0, vCores:0>
2016-08-21 14:54:49,309 INFO org.apache.hadoop.yarn.server.resourcemanager.scheduler.fair.FSAppAttempt: root.batch: <memory:16384, vCores:8>
2016-08-21 14:54:49,309 INFO org.apache.hadoop.yarn.server.resourcemanager.scheduler.fair.FSAppAttempt: appattempt_1471812677892_0002_000001 minReqResource: <memory:16384, vCores:8> flexibleResource: <memory:0, vCores:0>
2016-08-21 14:54:49,309 INFO org.apache.hadoop.yarn.server.resourcemanager.scheduler.fair.FairScheduler: allocate resource to application attempt: appattempt_1471812677892_0002_000001 queue:root.batch isRunning=true 
2016-08-21 14:54:49,310 INFO org.apache.hadoop.yarn.server.resourcemanager.scheduler.fair.FairScheduler: iglf: 2.getHeadroom()=<memory:0, vCores:0>
2016-08-21 14:54:49,656 INFO org.apache.hadoop.yarn.server.resourcemanager.rmapp.attempt.RMAppAttemptImpl: ScheduleTransition.transition(appattempt_1471812677892_0004_000001,EventType: ATTEMPT_ADDED)
2016-08-21 14:54:49,656 INFO org.apache.hadoop.yarn.server.resourcemanager.scheduler.fair.FairScheduler: allocate(appattempt_1471812677892_0004_000001 [{Priority: 0, Capability: <memory:2048, vCores:1>, # Containers: 1, Location: *, Relax Locality: true}] [] null null
2016-08-21 14:54:49,656 INFO org.apache.hadoop.yarn.server.resourcemanager.scheduler.fair.FSAppAttempt: root.interactive1: <memory:0, vCores:0>
2016-08-21 14:54:49,656 INFO org.apache.hadoop.yarn.server.resourcemanager.scheduler.fair.FSAppAttempt: root.interactive2: <memory:0, vCores:0>
2016-08-21 14:54:49,656 INFO org.apache.hadoop.yarn.server.resourcemanager.scheduler.fair.FSAppAttempt: root.batch: <memory:16384, vCores:8>
2016-08-21 14:54:49,656 INFO org.apache.hadoop.yarn.server.resourcemanager.scheduler.fair.FSAppAttempt: appattempt_1471812677892_0004_000001 minReqResource: <memory:16384, vCores:8> flexibleResource: <memory:0, vCores:0>
2016-08-21 14:54:49,656 INFO org.apache.hadoop.yarn.server.resourcemanager.scheduler.fair.FairScheduler: Cannot allocate appattempt_1471812677892_0004_000001 because there is NO flexible resource left
2016-08-21 14:54:50,112 INFO org.apache.hadoop.yarn.server.resourcemanager.scheduler.fair.FairScheduler: allocate(appattempt_1471812677892_0002_000001 [] [] [] []
2016-08-21 14:54:50,113 INFO org.apache.hadoop.yarn.server.resourcemanager.scheduler.fair.FSAppAttempt: root.interactive1: <memory:0, vCores:0>
2016-08-21 14:54:50,113 INFO org.apache.hadoop.yarn.server.resourcemanager.scheduler.fair.FSAppAttempt: root.interactive2: <memory:0, vCores:0>
2016-08-21 14:54:50,113 INFO org.apache.hadoop.yarn.server.resourcemanager.scheduler.fair.FSAppAttempt: root.batch: <memory:16384, vCores:8>
2016-08-21 14:54:50,113 INFO org.apache.hadoop.yarn.server.resourcemanager.scheduler.fair.FSAppAttempt: appattempt_1471812677892_0002_000001 minReqResource: <memory:16384, vCores:8> flexibleResource: <memory:0, vCores:0>
2016-08-21 14:54:50,113 INFO org.apache.hadoop.yarn.server.resourcemanager.scheduler.fair.FairScheduler: allocate resource to application attempt: appattempt_1471812677892_0002_000001 queue:root.batch isRunning=true 
2016-08-21 14:54:50,113 INFO org.apache.hadoop.yarn.server.resourcemanager.scheduler.fair.FairScheduler: iglf: 2.getHeadroom()=<memory:0, vCores:0>
2016-08-21 14:54:50,658 INFO org.apache.hadoop.yarn.server.resourcemanager.rmapp.attempt.RMAppAttemptImpl: ScheduleTransition.transition(appattempt_1471812677892_0004_000001,EventType: ATTEMPT_ADDED)
2016-08-21 14:54:50,658 INFO org.apache.hadoop.yarn.server.resourcemanager.scheduler.fair.FairScheduler: allocate(appattempt_1471812677892_0004_000001 [{Priority: 0, Capability: <memory:2048, vCores:1>, # Containers: 1, Location: *, Relax Locality: true}] [] null null
2016-08-21 14:54:50,658 INFO org.apache.hadoop.yarn.server.resourcemanager.scheduler.fair.FSAppAttempt: root.interactive1: <memory:0, vCores:0>
2016-08-21 14:54:50,658 INFO org.apache.hadoop.yarn.server.resourcemanager.scheduler.fair.FSAppAttempt: root.interactive2: <memory:0, vCores:0>
2016-08-21 14:54:50,658 INFO org.apache.hadoop.yarn.server.resourcemanager.scheduler.fair.FSAppAttempt: root.batch: <memory:16384, vCores:8>
2016-08-21 14:54:50,658 INFO org.apache.hadoop.yarn.server.resourcemanager.scheduler.fair.FSAppAttempt: appattempt_1471812677892_0004_000001 minReqResource: <memory:16384, vCores:8> flexibleResource: <memory:0, vCores:0>
2016-08-21 14:54:50,658 INFO org.apache.hadoop.yarn.server.resourcemanager.scheduler.fair.FairScheduler: Cannot allocate appattempt_1471812677892_0004_000001 because there is NO flexible resource left
2016-08-21 14:54:50,829 INFO org.apache.hadoop.yarn.server.resourcemanager.scheduler.fair.FairScheduler: Should preempt <memory:2048, vCores:1> res for queue root.interactive1: resDueToMinShare = <memory:2048, vCores:1>, resDueToFairShare = <memory:2048, vCores:1>
2016-08-21 14:54:50,829 INFO org.apache.hadoop.yarn.server.resourcemanager.scheduler.fair.FairScheduler: Should preempt <memory:2048, vCores:1> res for queue root.interactive2: resDueToMinShare = <memory:2048, vCores:1>, resDueToFairShare = <memory:2048, vCores:1>
2016-08-21 14:54:50,829 INFO org.apache.hadoop.yarn.server.resourcemanager.scheduler.fair.FairScheduler: Preempting container (prio=1res=<memory:2048, vCores:1>) from queue root.batch
2016-08-21 14:54:50,830 INFO org.apache.hadoop.yarn.server.resourcemanager.scheduler.fair.FairScheduler: Preempting container (prio=1res=<memory:2048, vCores:1>) from queue root.batch
2016-08-21 14:54:51,666 INFO org.apache.hadoop.yarn.server.resourcemanager.rmapp.attempt.RMAppAttemptImpl: ScheduleTransition.transition(appattempt_1471812677892_0004_000001,EventType: ATTEMPT_ADDED)
2016-08-21 14:54:51,666 INFO org.apache.hadoop.yarn.server.resourcemanager.scheduler.fair.FairScheduler: allocate(appattempt_1471812677892_0004_000001 [{Priority: 0, Capability: <memory:2048, vCores:1>, # Containers: 1, Location: *, Relax Locality: true}] [] null null
2016-08-21 14:54:51,666 INFO org.apache.hadoop.yarn.server.resourcemanager.scheduler.fair.FSAppAttempt: root.interactive1: <memory:0, vCores:0>
2016-08-21 14:54:51,666 INFO org.apache.hadoop.yarn.server.resourcemanager.scheduler.fair.FSAppAttempt: root.interactive2: <memory:0, vCores:0>
2016-08-21 14:54:51,666 INFO org.apache.hadoop.yarn.server.resourcemanager.scheduler.fair.FSAppAttempt: root.batch: <memory:16384, vCores:8>
2016-08-21 14:54:51,666 INFO org.apache.hadoop.yarn.server.resourcemanager.scheduler.fair.FSAppAttempt: appattempt_1471812677892_0004_000001 minReqResource: <memory:16384, vCores:8> flexibleResource: <memory:0, vCores:0>
2016-08-21 14:54:51,666 INFO org.apache.hadoop.yarn.server.resourcemanager.scheduler.fair.FairScheduler: Cannot allocate appattempt_1471812677892_0004_000001 because there is NO flexible resource left
2016-08-21 14:54:51,717 INFO org.apache.hadoop.yarn.server.resourcemanager.scheduler.fair.FairScheduler: allocate(appattempt_1471812677892_0002_000001 [] [] [] []
2016-08-21 14:54:51,717 INFO org.apache.hadoop.yarn.server.resourcemanager.scheduler.fair.FSAppAttempt: root.interactive1: <memory:0, vCores:0>
2016-08-21 14:54:51,717 INFO org.apache.hadoop.yarn.server.resourcemanager.scheduler.fair.FSAppAttempt: root.interactive2: <memory:0, vCores:0>
2016-08-21 14:54:51,717 INFO org.apache.hadoop.yarn.server.resourcemanager.scheduler.fair.FSAppAttempt: root.batch: <memory:16384, vCores:8>
2016-08-21 14:54:51,717 INFO org.apache.hadoop.yarn.server.resourcemanager.scheduler.fair.FSAppAttempt: appattempt_1471812677892_0002_000001 minReqResource: <memory:16384, vCores:8> flexibleResource: <memory:0, vCores:0>
2016-08-21 14:54:51,717 INFO org.apache.hadoop.yarn.server.resourcemanager.scheduler.fair.FairScheduler: allocate resource to application attempt: appattempt_1471812677892_0002_000001 queue:root.batch isRunning=true 
2016-08-21 14:54:51,717 INFO org.apache.hadoop.yarn.server.resourcemanager.scheduler.fair.FairScheduler: iglf: 2.getHeadroom()=<memory:0, vCores:0>
2016-08-21 14:54:52,668 INFO org.apache.hadoop.yarn.server.resourcemanager.rmapp.attempt.RMAppAttemptImpl: ScheduleTransition.transition(appattempt_1471812677892_0004_000001,EventType: ATTEMPT_ADDED)
2016-08-21 14:54:52,669 INFO org.apache.hadoop.yarn.server.resourcemanager.scheduler.fair.FairScheduler: allocate(appattempt_1471812677892_0004_000001 [{Priority: 0, Capability: <memory:2048, vCores:1>, # Containers: 1, Location: *, Relax Locality: true}] [] null null
2016-08-21 14:54:52,669 INFO org.apache.hadoop.yarn.server.resourcemanager.scheduler.fair.FSAppAttempt: root.interactive1: <memory:0, vCores:0>
2016-08-21 14:54:52,669 INFO org.apache.hadoop.yarn.server.resourcemanager.scheduler.fair.FSAppAttempt: root.interactive2: <memory:0, vCores:0>
2016-08-21 14:54:52,669 INFO org.apache.hadoop.yarn.server.resourcemanager.scheduler.fair.FSAppAttempt: root.batch: <memory:16384, vCores:8>
2016-08-21 14:54:52,669 INFO org.apache.hadoop.yarn.server.resourcemanager.scheduler.fair.FSAppAttempt: appattempt_1471812677892_0004_000001 minReqResource: <memory:16384, vCores:8> flexibleResource: <memory:0, vCores:0>
2016-08-21 14:54:52,669 INFO org.apache.hadoop.yarn.server.resourcemanager.scheduler.fair.FairScheduler: Cannot allocate appattempt_1471812677892_0004_000001 because there is NO flexible resource left
2016-08-21 14:54:53,670 INFO org.apache.hadoop.yarn.server.resourcemanager.rmapp.attempt.RMAppAttemptImpl: ScheduleTransition.transition(appattempt_1471812677892_0004_000001,EventType: ATTEMPT_ADDED)
2016-08-21 14:54:53,670 INFO org.apache.hadoop.yarn.server.resourcemanager.scheduler.fair.FairScheduler: allocate(appattempt_1471812677892_0004_000001 [{Priority: 0, Capability: <memory:2048, vCores:1>, # Containers: 1, Location: *, Relax Locality: true}] [] null null
2016-08-21 14:54:53,670 INFO org.apache.hadoop.yarn.server.resourcemanager.scheduler.fair.FSAppAttempt: root.interactive1: <memory:0, vCores:0>
2016-08-21 14:54:53,670 INFO org.apache.hadoop.yarn.server.resourcemanager.scheduler.fair.FSAppAttempt: root.interactive2: <memory:0, vCores:0>
2016-08-21 14:54:53,670 INFO org.apache.hadoop.yarn.server.resourcemanager.scheduler.fair.FSAppAttempt: root.batch: <memory:16384, vCores:8>
2016-08-21 14:54:53,670 INFO org.apache.hadoop.yarn.server.resourcemanager.scheduler.fair.FSAppAttempt: appattempt_1471812677892_0004_000001 minReqResource: <memory:16384, vCores:8> flexibleResource: <memory:0, vCores:0>
2016-08-21 14:54:53,670 INFO org.apache.hadoop.yarn.server.resourcemanager.scheduler.fair.FairScheduler: Cannot allocate appattempt_1471812677892_0004_000001 because there is NO flexible resource left
2016-08-21 14:54:53,703 INFO org.apache.hadoop.yarn.server.resourcemanager.scheduler.fair.FairScheduler: allocate(appattempt_1471812677892_0002_000001 [{Priority: 1, Capability: <memory:1920, vCores:1>, # Containers: 120, Location: *, Relax Locality: true}] [] [] []
2016-08-21 14:54:53,703 INFO org.apache.hadoop.yarn.server.resourcemanager.scheduler.fair.FSAppAttempt: root.interactive1: <memory:0, vCores:0>
2016-08-21 14:54:53,703 INFO org.apache.hadoop.yarn.server.resourcemanager.scheduler.fair.FSAppAttempt: root.interactive2: <memory:0, vCores:0>
2016-08-21 14:54:53,703 INFO org.apache.hadoop.yarn.server.resourcemanager.scheduler.fair.FSAppAttempt: root.batch: <memory:16384, vCores:8>
2016-08-21 14:54:53,704 INFO org.apache.hadoop.yarn.server.resourcemanager.scheduler.fair.FSAppAttempt: appattempt_1471812677892_0002_000001 minReqResource: <memory:16384, vCores:8> flexibleResource: <memory:0, vCores:0>
2016-08-21 14:54:53,704 INFO org.apache.hadoop.yarn.server.resourcemanager.scheduler.fair.FairScheduler: allocate resource to application attempt: appattempt_1471812677892_0002_000001 queue:root.batch isRunning=true 
2016-08-21 14:54:53,704 INFO org.apache.hadoop.yarn.server.resourcemanager.scheduler.fair.FairScheduler: iglf: 2.getHeadroom()=<memory:0, vCores:0>
2016-08-21 14:54:53,907 INFO org.apache.hadoop.yarn.server.resourcemanager.scheduler.fair.FairScheduler: allocate(appattempt_1471812677892_0002_000001 [] [] [] []
2016-08-21 14:54:53,907 INFO org.apache.hadoop.yarn.server.resourcemanager.scheduler.fair.FSAppAttempt: root.interactive1: <memory:0, vCores:0>
2016-08-21 14:54:53,907 INFO org.apache.hadoop.yarn.server.resourcemanager.scheduler.fair.FSAppAttempt: root.interactive2: <memory:0, vCores:0>
2016-08-21 14:54:53,908 INFO org.apache.hadoop.yarn.server.resourcemanager.scheduler.fair.FSAppAttempt: root.batch: <memory:16384, vCores:8>
2016-08-21 14:54:53,908 INFO org.apache.hadoop.yarn.server.resourcemanager.scheduler.fair.FSAppAttempt: appattempt_1471812677892_0002_000001 minReqResource: <memory:16384, vCores:8> flexibleResource: <memory:0, vCores:0>
2016-08-21 14:54:53,908 INFO org.apache.hadoop.yarn.server.resourcemanager.scheduler.fair.FairScheduler: allocate resource to application attempt: appattempt_1471812677892_0002_000001 queue:root.batch isRunning=true 
2016-08-21 14:54:53,908 INFO org.apache.hadoop.yarn.server.resourcemanager.scheduler.fair.FairScheduler: iglf: 2.getHeadroom()=<memory:0, vCores:0>
2016-08-21 14:54:54,311 INFO org.apache.hadoop.yarn.server.resourcemanager.scheduler.fair.FairScheduler: allocate(appattempt_1471812677892_0002_000001 [] [] [] []
2016-08-21 14:54:54,311 INFO org.apache.hadoop.yarn.server.resourcemanager.scheduler.fair.FSAppAttempt: root.interactive1: <memory:0, vCores:0>
2016-08-21 14:54:54,311 INFO org.apache.hadoop.yarn.server.resourcemanager.scheduler.fair.FSAppAttempt: root.interactive2: <memory:0, vCores:0>
2016-08-21 14:54:54,311 INFO org.apache.hadoop.yarn.server.resourcemanager.scheduler.fair.FSAppAttempt: root.batch: <memory:16384, vCores:8>
2016-08-21 14:54:54,312 INFO org.apache.hadoop.yarn.server.resourcemanager.scheduler.fair.FSAppAttempt: appattempt_1471812677892_0002_000001 minReqResource: <memory:16384, vCores:8> flexibleResource: <memory:0, vCores:0>
2016-08-21 14:54:54,312 INFO org.apache.hadoop.yarn.server.resourcemanager.scheduler.fair.FairScheduler: allocate resource to application attempt: appattempt_1471812677892_0002_000001 queue:root.batch isRunning=true 
2016-08-21 14:54:54,312 INFO org.apache.hadoop.yarn.server.resourcemanager.scheduler.fair.FairScheduler: iglf: 2.getHeadroom()=<memory:0, vCores:0>
2016-08-21 14:54:54,672 INFO org.apache.hadoop.yarn.server.resourcemanager.rmapp.attempt.RMAppAttemptImpl: ScheduleTransition.transition(appattempt_1471812677892_0004_000001,EventType: ATTEMPT_ADDED)
2016-08-21 14:54:54,672 INFO org.apache.hadoop.yarn.server.resourcemanager.scheduler.fair.FairScheduler: allocate(appattempt_1471812677892_0004_000001 [{Priority: 0, Capability: <memory:2048, vCores:1>, # Containers: 1, Location: *, Relax Locality: true}] [] null null
2016-08-21 14:54:54,672 INFO org.apache.hadoop.yarn.server.resourcemanager.scheduler.fair.FSAppAttempt: root.interactive1: <memory:0, vCores:0>
2016-08-21 14:54:54,672 INFO org.apache.hadoop.yarn.server.resourcemanager.scheduler.fair.FSAppAttempt: root.interactive2: <memory:0, vCores:0>
2016-08-21 14:54:54,673 INFO org.apache.hadoop.yarn.server.resourcemanager.scheduler.fair.FSAppAttempt: root.batch: <memory:16384, vCores:8>
2016-08-21 14:54:54,673 INFO org.apache.hadoop.yarn.server.resourcemanager.scheduler.fair.FSAppAttempt: appattempt_1471812677892_0004_000001 minReqResource: <memory:16384, vCores:8> flexibleResource: <memory:0, vCores:0>
2016-08-21 14:54:54,673 INFO org.apache.hadoop.yarn.server.resourcemanager.scheduler.fair.FairScheduler: Cannot allocate appattempt_1471812677892_0004_000001 because there is NO flexible resource left
2016-08-21 14:54:55,116 INFO org.apache.hadoop.yarn.server.resourcemanager.scheduler.fair.FairScheduler: allocate(appattempt_1471812677892_0002_000001 [] [] [] []
2016-08-21 14:54:55,116 INFO org.apache.hadoop.yarn.server.resourcemanager.scheduler.fair.FSAppAttempt: root.interactive1: <memory:0, vCores:0>
2016-08-21 14:54:55,116 INFO org.apache.hadoop.yarn.server.resourcemanager.scheduler.fair.FSAppAttempt: root.interactive2: <memory:0, vCores:0>
2016-08-21 14:54:55,116 INFO org.apache.hadoop.yarn.server.resourcemanager.scheduler.fair.FSAppAttempt: root.batch: <memory:16384, vCores:8>
2016-08-21 14:54:55,116 INFO org.apache.hadoop.yarn.server.resourcemanager.scheduler.fair.FSAppAttempt: appattempt_1471812677892_0002_000001 minReqResource: <memory:16384, vCores:8> flexibleResource: <memory:0, vCores:0>
2016-08-21 14:54:55,116 INFO org.apache.hadoop.yarn.server.resourcemanager.scheduler.fair.FairScheduler: allocate resource to application attempt: appattempt_1471812677892_0002_000001 queue:root.batch isRunning=true 
2016-08-21 14:54:55,116 INFO org.apache.hadoop.yarn.server.resourcemanager.scheduler.fair.FairScheduler: iglf: 2.getHeadroom()=<memory:0, vCores:0>
2016-08-21 14:54:55,674 INFO org.apache.hadoop.yarn.server.resourcemanager.rmapp.attempt.RMAppAttemptImpl: ScheduleTransition.transition(appattempt_1471812677892_0004_000001,EventType: ATTEMPT_ADDED)
2016-08-21 14:54:55,674 INFO org.apache.hadoop.yarn.server.resourcemanager.scheduler.fair.FairScheduler: allocate(appattempt_1471812677892_0004_000001 [{Priority: 0, Capability: <memory:2048, vCores:1>, # Containers: 1, Location: *, Relax Locality: true}] [] null null
2016-08-21 14:54:55,674 INFO org.apache.hadoop.yarn.server.resourcemanager.scheduler.fair.FSAppAttempt: root.interactive1: <memory:0, vCores:0>
2016-08-21 14:54:55,674 INFO org.apache.hadoop.yarn.server.resourcemanager.scheduler.fair.FSAppAttempt: root.interactive2: <memory:0, vCores:0>
2016-08-21 14:54:55,674 INFO org.apache.hadoop.yarn.server.resourcemanager.scheduler.fair.FSAppAttempt: root.batch: <memory:16384, vCores:8>
2016-08-21 14:54:55,674 INFO org.apache.hadoop.yarn.server.resourcemanager.scheduler.fair.FSAppAttempt: appattempt_1471812677892_0004_000001 minReqResource: <memory:16384, vCores:8> flexibleResource: <memory:0, vCores:0>
2016-08-21 14:54:55,674 INFO org.apache.hadoop.yarn.server.resourcemanager.scheduler.fair.FairScheduler: Cannot allocate appattempt_1471812677892_0004_000001 because there is NO flexible resource left
2016-08-21 14:54:55,838 INFO org.apache.hadoop.yarn.server.resourcemanager.scheduler.fair.FairScheduler: Should preempt <memory:2048, vCores:1> res for queue root.interactive1: resDueToMinShare = <memory:2048, vCores:1>, resDueToFairShare = <memory:2048, vCores:1>
2016-08-21 14:54:55,839 INFO org.apache.hadoop.yarn.server.resourcemanager.scheduler.fair.FairScheduler: Should preempt <memory:2048, vCores:1> res for queue root.interactive2: resDueToMinShare = <memory:2048, vCores:1>, resDueToFairShare = <memory:2048, vCores:1>
2016-08-21 14:54:55,839 INFO org.apache.hadoop.yarn.server.resourcemanager.scheduler.fair.FairScheduler: Preempting container (prio=1res=<memory:2048, vCores:1>) from queue root.batch
2016-08-21 14:54:55,839 INFO org.apache.hadoop.yarn.server.resourcemanager.scheduler.fair.FairScheduler: Preempting container (prio=1res=<memory:2048, vCores:1>) from queue root.batch
2016-08-21 14:54:56,676 INFO org.apache.hadoop.yarn.server.resourcemanager.rmapp.attempt.RMAppAttemptImpl: ScheduleTransition.transition(appattempt_1471812677892_0004_000001,EventType: ATTEMPT_ADDED)
2016-08-21 14:54:56,676 INFO org.apache.hadoop.yarn.server.resourcemanager.scheduler.fair.FairScheduler: allocate(appattempt_1471812677892_0004_000001 [{Priority: 0, Capability: <memory:2048, vCores:1>, # Containers: 1, Location: *, Relax Locality: true}] [] null null
2016-08-21 14:54:56,676 INFO org.apache.hadoop.yarn.server.resourcemanager.scheduler.fair.FSAppAttempt: root.interactive1: <memory:0, vCores:0>
2016-08-21 14:54:56,676 INFO org.apache.hadoop.yarn.server.resourcemanager.scheduler.fair.FSAppAttempt: root.interactive2: <memory:0, vCores:0>
2016-08-21 14:54:56,676 INFO org.apache.hadoop.yarn.server.resourcemanager.scheduler.fair.FSAppAttempt: root.batch: <memory:16384, vCores:8>
2016-08-21 14:54:56,676 INFO org.apache.hadoop.yarn.server.resourcemanager.scheduler.fair.FSAppAttempt: appattempt_1471812677892_0004_000001 minReqResource: <memory:16384, vCores:8> flexibleResource: <memory:0, vCores:0>
2016-08-21 14:54:56,676 INFO org.apache.hadoop.yarn.server.resourcemanager.scheduler.fair.FairScheduler: Cannot allocate appattempt_1471812677892_0004_000001 because there is NO flexible resource left
2016-08-21 14:54:56,720 INFO org.apache.hadoop.yarn.server.resourcemanager.scheduler.fair.FairScheduler: allocate(appattempt_1471812677892_0002_000001 [] [] [] []
2016-08-21 14:54:56,720 INFO org.apache.hadoop.yarn.server.resourcemanager.scheduler.fair.FSAppAttempt: root.interactive1: <memory:0, vCores:0>
2016-08-21 14:54:56,720 INFO org.apache.hadoop.yarn.server.resourcemanager.scheduler.fair.FSAppAttempt: root.interactive2: <memory:0, vCores:0>
2016-08-21 14:54:56,720 INFO org.apache.hadoop.yarn.server.resourcemanager.scheduler.fair.FSAppAttempt: root.batch: <memory:16384, vCores:8>
2016-08-21 14:54:56,720 INFO org.apache.hadoop.yarn.server.resourcemanager.scheduler.fair.FSAppAttempt: appattempt_1471812677892_0002_000001 minReqResource: <memory:16384, vCores:8> flexibleResource: <memory:0, vCores:0>
2016-08-21 14:54:56,720 INFO org.apache.hadoop.yarn.server.resourcemanager.scheduler.fair.FairScheduler: allocate resource to application attempt: appattempt_1471812677892_0002_000001 queue:root.batch isRunning=true 
2016-08-21 14:54:56,721 INFO org.apache.hadoop.yarn.server.resourcemanager.scheduler.fair.FairScheduler: iglf: 2.getHeadroom()=<memory:0, vCores:0>
2016-08-21 14:54:57,678 INFO org.apache.hadoop.yarn.server.resourcemanager.rmapp.attempt.RMAppAttemptImpl: ScheduleTransition.transition(appattempt_1471812677892_0004_000001,EventType: ATTEMPT_ADDED)
2016-08-21 14:54:57,678 INFO org.apache.hadoop.yarn.server.resourcemanager.scheduler.fair.FairScheduler: allocate(appattempt_1471812677892_0004_000001 [{Priority: 0, Capability: <memory:2048, vCores:1>, # Containers: 1, Location: *, Relax Locality: true}] [] null null
2016-08-21 14:54:57,678 INFO org.apache.hadoop.yarn.server.resourcemanager.scheduler.fair.FSAppAttempt: root.interactive1: <memory:0, vCores:0>
2016-08-21 14:54:57,678 INFO org.apache.hadoop.yarn.server.resourcemanager.scheduler.fair.FSAppAttempt: root.interactive2: <memory:0, vCores:0>
2016-08-21 14:54:57,678 INFO org.apache.hadoop.yarn.server.resourcemanager.scheduler.fair.FSAppAttempt: root.batch: <memory:16384, vCores:8>
2016-08-21 14:54:57,678 INFO org.apache.hadoop.yarn.server.resourcemanager.scheduler.fair.FSAppAttempt: appattempt_1471812677892_0004_000001 minReqResource: <memory:16384, vCores:8> flexibleResource: <memory:0, vCores:0>
2016-08-21 14:54:57,678 INFO org.apache.hadoop.yarn.server.resourcemanager.scheduler.fair.FairScheduler: Cannot allocate appattempt_1471812677892_0004_000001 because there is NO flexible resource left
2016-08-21 14:54:58,681 INFO org.apache.hadoop.yarn.server.resourcemanager.rmapp.attempt.RMAppAttemptImpl: ScheduleTransition.transition(appattempt_1471812677892_0004_000001,EventType: ATTEMPT_ADDED)
2016-08-21 14:54:58,681 INFO org.apache.hadoop.yarn.server.resourcemanager.scheduler.fair.FairScheduler: allocate(appattempt_1471812677892_0004_000001 [{Priority: 0, Capability: <memory:2048, vCores:1>, # Containers: 1, Location: *, Relax Locality: true}] [] null null
2016-08-21 14:54:58,681 INFO org.apache.hadoop.yarn.server.resourcemanager.scheduler.fair.FSAppAttempt: root.interactive1: <memory:0, vCores:0>
2016-08-21 14:54:58,681 INFO org.apache.hadoop.yarn.server.resourcemanager.scheduler.fair.FSAppAttempt: root.interactive2: <memory:0, vCores:0>
2016-08-21 14:54:58,681 INFO org.apache.hadoop.yarn.server.resourcemanager.scheduler.fair.FSAppAttempt: root.batch: <memory:16384, vCores:8>
2016-08-21 14:54:58,682 INFO org.apache.hadoop.yarn.server.resourcemanager.scheduler.fair.FSAppAttempt: appattempt_1471812677892_0004_000001 minReqResource: <memory:16384, vCores:8> flexibleResource: <memory:0, vCores:0>
2016-08-21 14:54:58,682 INFO org.apache.hadoop.yarn.server.resourcemanager.scheduler.fair.FairScheduler: Cannot allocate appattempt_1471812677892_0004_000001 because there is NO flexible resource left
2016-08-21 14:54:58,710 INFO org.apache.hadoop.yarn.server.resourcemanager.scheduler.fair.FairScheduler: allocate(appattempt_1471812677892_0002_000001 [{Priority: 1, Capability: <memory:1920, vCores:1>, # Containers: 248, Location: *, Relax Locality: true}] [] [] []
2016-08-21 14:54:58,710 INFO org.apache.hadoop.yarn.server.resourcemanager.scheduler.fair.FSAppAttempt: root.interactive1: <memory:0, vCores:0>
2016-08-21 14:54:58,710 INFO org.apache.hadoop.yarn.server.resourcemanager.scheduler.fair.FSAppAttempt: root.interactive2: <memory:0, vCores:0>
2016-08-21 14:54:58,710 INFO org.apache.hadoop.yarn.server.resourcemanager.scheduler.fair.FSAppAttempt: root.batch: <memory:16384, vCores:8>
2016-08-21 14:54:58,710 INFO org.apache.hadoop.yarn.server.resourcemanager.scheduler.fair.FSAppAttempt: appattempt_1471812677892_0002_000001 minReqResource: <memory:16384, vCores:8> flexibleResource: <memory:0, vCores:0>
2016-08-21 14:54:58,710 INFO org.apache.hadoop.yarn.server.resourcemanager.scheduler.fair.FairScheduler: allocate resource to application attempt: appattempt_1471812677892_0002_000001 queue:root.batch isRunning=true 
2016-08-21 14:54:58,711 INFO org.apache.hadoop.yarn.server.resourcemanager.scheduler.fair.FairScheduler: iglf: 2.getHeadroom()=<memory:0, vCores:0>
2016-08-21 14:54:58,915 INFO org.apache.hadoop.yarn.server.resourcemanager.scheduler.fair.FairScheduler: allocate(appattempt_1471812677892_0002_000001 [] [] [] []
2016-08-21 14:54:58,915 INFO org.apache.hadoop.yarn.server.resourcemanager.scheduler.fair.FSAppAttempt: root.interactive1: <memory:0, vCores:0>
2016-08-21 14:54:58,915 INFO org.apache.hadoop.yarn.server.resourcemanager.scheduler.fair.FSAppAttempt: root.interactive2: <memory:0, vCores:0>
2016-08-21 14:54:58,915 INFO org.apache.hadoop.yarn.server.resourcemanager.scheduler.fair.FSAppAttempt: root.batch: <memory:16384, vCores:8>
2016-08-21 14:54:58,915 INFO org.apache.hadoop.yarn.server.resourcemanager.scheduler.fair.FSAppAttempt: appattempt_1471812677892_0002_000001 minReqResource: <memory:16384, vCores:8> flexibleResource: <memory:0, vCores:0>
2016-08-21 14:54:58,915 INFO org.apache.hadoop.yarn.server.resourcemanager.scheduler.fair.FairScheduler: allocate resource to application attempt: appattempt_1471812677892_0002_000001 queue:root.batch isRunning=true 
2016-08-21 14:54:58,915 INFO org.apache.hadoop.yarn.server.resourcemanager.scheduler.fair.FairScheduler: iglf: 2.getHeadroom()=<memory:0, vCores:0>
2016-08-21 14:54:59,320 INFO org.apache.hadoop.yarn.server.resourcemanager.scheduler.fair.FairScheduler: allocate(appattempt_1471812677892_0002_000001 [] [] [] []
2016-08-21 14:54:59,321 INFO org.apache.hadoop.yarn.server.resourcemanager.scheduler.fair.FSAppAttempt: root.interactive1: <memory:0, vCores:0>
2016-08-21 14:54:59,321 INFO org.apache.hadoop.yarn.server.resourcemanager.scheduler.fair.FSAppAttempt: root.interactive2: <memory:0, vCores:0>
2016-08-21 14:54:59,321 INFO org.apache.hadoop.yarn.server.resourcemanager.scheduler.fair.FSAppAttempt: root.batch: <memory:16384, vCores:8>
2016-08-21 14:54:59,321 INFO org.apache.hadoop.yarn.server.resourcemanager.scheduler.fair.FSAppAttempt: appattempt_1471812677892_0002_000001 minReqResource: <memory:16384, vCores:8> flexibleResource: <memory:0, vCores:0>
2016-08-21 14:54:59,321 INFO org.apache.hadoop.yarn.server.resourcemanager.scheduler.fair.FairScheduler: allocate resource to application attempt: appattempt_1471812677892_0002_000001 queue:root.batch isRunning=true 
2016-08-21 14:54:59,321 INFO org.apache.hadoop.yarn.server.resourcemanager.scheduler.fair.FairScheduler: iglf: 2.getHeadroom()=<memory:0, vCores:0>
2016-08-21 14:54:59,683 INFO org.apache.hadoop.yarn.server.resourcemanager.rmapp.attempt.RMAppAttemptImpl: ScheduleTransition.transition(appattempt_1471812677892_0004_000001,EventType: ATTEMPT_ADDED)
2016-08-21 14:54:59,683 INFO org.apache.hadoop.yarn.server.resourcemanager.scheduler.fair.FairScheduler: allocate(appattempt_1471812677892_0004_000001 [{Priority: 0, Capability: <memory:2048, vCores:1>, # Containers: 1, Location: *, Relax Locality: true}] [] null null
2016-08-21 14:54:59,683 INFO org.apache.hadoop.yarn.server.resourcemanager.scheduler.fair.FSAppAttempt: root.interactive1: <memory:0, vCores:0>
2016-08-21 14:54:59,683 INFO org.apache.hadoop.yarn.server.resourcemanager.scheduler.fair.FSAppAttempt: root.interactive2: <memory:0, vCores:0>
2016-08-21 14:54:59,683 INFO org.apache.hadoop.yarn.server.resourcemanager.scheduler.fair.FSAppAttempt: root.batch: <memory:16384, vCores:8>
2016-08-21 14:54:59,683 INFO org.apache.hadoop.yarn.server.resourcemanager.scheduler.fair.FSAppAttempt: appattempt_1471812677892_0004_000001 minReqResource: <memory:16384, vCores:8> flexibleResource: <memory:0, vCores:0>
2016-08-21 14:54:59,683 INFO org.apache.hadoop.yarn.server.resourcemanager.scheduler.fair.FairScheduler: Cannot allocate appattempt_1471812677892_0004_000001 because there is NO flexible resource left
2016-08-21 14:55:00,125 INFO org.apache.hadoop.yarn.server.resourcemanager.scheduler.fair.FairScheduler: allocate(appattempt_1471812677892_0002_000001 [] [] [] []
2016-08-21 14:55:00,125 INFO org.apache.hadoop.yarn.server.resourcemanager.scheduler.fair.FSAppAttempt: root.interactive1: <memory:0, vCores:0>
2016-08-21 14:55:00,125 INFO org.apache.hadoop.yarn.server.resourcemanager.scheduler.fair.FSAppAttempt: root.interactive2: <memory:0, vCores:0>
2016-08-21 14:55:00,125 INFO org.apache.hadoop.yarn.server.resourcemanager.scheduler.fair.FSAppAttempt: root.batch: <memory:16384, vCores:8>
2016-08-21 14:55:00,126 INFO org.apache.hadoop.yarn.server.resourcemanager.scheduler.fair.FSAppAttempt: appattempt_1471812677892_0002_000001 minReqResource: <memory:16384, vCores:8> flexibleResource: <memory:0, vCores:0>
2016-08-21 14:55:00,126 INFO org.apache.hadoop.yarn.server.resourcemanager.scheduler.fair.FairScheduler: allocate resource to application attempt: appattempt_1471812677892_0002_000001 queue:root.batch isRunning=true 
2016-08-21 14:55:00,126 INFO org.apache.hadoop.yarn.server.resourcemanager.scheduler.fair.FairScheduler: iglf: 2.getHeadroom()=<memory:0, vCores:0>
2016-08-21 14:55:00,401 INFO org.apache.hadoop.yarn.server.resourcemanager.scheduler.fair.FairScheduler: allocate(appattempt_1471812677892_0002_000001 [{Priority: 1, Capability: <memory:1920, vCores:1>, # Containers: 214, Location: *, Relax Locality: true}] [] [] []
2016-08-21 14:55:00,401 INFO org.apache.hadoop.yarn.server.resourcemanager.scheduler.fair.FSAppAttempt: root.interactive1: <memory:0, vCores:0>
2016-08-21 14:55:00,401 INFO org.apache.hadoop.yarn.server.resourcemanager.scheduler.fair.FSAppAttempt: root.interactive2: <memory:0, vCores:0>
2016-08-21 14:55:00,401 INFO org.apache.hadoop.yarn.server.resourcemanager.scheduler.fair.FSAppAttempt: root.batch: <memory:16384, vCores:8>
2016-08-21 14:55:00,401 INFO org.apache.hadoop.yarn.server.resourcemanager.scheduler.fair.FSAppAttempt: appattempt_1471812677892_0002_000001 minReqResource: <memory:16384, vCores:8> flexibleResource: <memory:0, vCores:0>
2016-08-21 14:55:00,401 INFO org.apache.hadoop.yarn.server.resourcemanager.scheduler.fair.FairScheduler: allocate resource to application attempt: appattempt_1471812677892_0002_000001 queue:root.batch isRunning=true 
2016-08-21 14:55:00,401 INFO org.apache.hadoop.yarn.server.resourcemanager.scheduler.fair.FairScheduler: iglf: 2.getHeadroom()=<memory:0, vCores:0>
2016-08-21 14:55:00,498 INFO org.apache.hadoop.yarn.server.resourcemanager.scheduler.fair.FairScheduler: allocate(appattempt_1471812677892_0002_000001 [{Priority: 1, Capability: <memory:1920, vCores:1>, # Containers: 165, Location: *, Relax Locality: true}] [] [] []
2016-08-21 14:55:00,499 INFO org.apache.hadoop.yarn.server.resourcemanager.scheduler.fair.FSAppAttempt: root.interactive1: <memory:0, vCores:0>
2016-08-21 14:55:00,499 INFO org.apache.hadoop.yarn.server.resourcemanager.scheduler.fair.FSAppAttempt: root.interactive2: <memory:0, vCores:0>
2016-08-21 14:55:00,499 INFO org.apache.hadoop.yarn.server.resourcemanager.scheduler.fair.FSAppAttempt: root.batch: <memory:16384, vCores:8>
2016-08-21 14:55:00,499 INFO org.apache.hadoop.yarn.server.resourcemanager.scheduler.fair.FSAppAttempt: appattempt_1471812677892_0002_000001 minReqResource: <memory:16384, vCores:8> flexibleResource: <memory:0, vCores:0>
2016-08-21 14:55:00,499 INFO org.apache.hadoop.yarn.server.resourcemanager.scheduler.fair.FairScheduler: allocate resource to application attempt: appattempt_1471812677892_0002_000001 queue:root.batch isRunning=true 
2016-08-21 14:55:00,499 INFO org.apache.hadoop.yarn.server.resourcemanager.scheduler.fair.FairScheduler: iglf: 2.getHeadroom()=<memory:0, vCores:0>
2016-08-21 14:55:00,598 INFO org.apache.hadoop.yarn.server.resourcemanager.scheduler.fair.FairScheduler: allocate(appattempt_1471812677892_0002_000001 [{Priority: 1, Capability: <memory:1920, vCores:1>, # Containers: 120, Location: *, Relax Locality: true}] [] [] []
2016-08-21 14:55:00,598 INFO org.apache.hadoop.yarn.server.resourcemanager.scheduler.fair.FSAppAttempt: root.interactive1: <memory:0, vCores:0>
2016-08-21 14:55:00,598 INFO org.apache.hadoop.yarn.server.resourcemanager.scheduler.fair.FSAppAttempt: root.interactive2: <memory:0, vCores:0>
2016-08-21 14:55:00,598 INFO org.apache.hadoop.yarn.server.resourcemanager.scheduler.fair.FSAppAttempt: root.batch: <memory:16384, vCores:8>
2016-08-21 14:55:00,599 INFO org.apache.hadoop.yarn.server.resourcemanager.scheduler.fair.FSAppAttempt: appattempt_1471812677892_0002_000001 minReqResource: <memory:16384, vCores:8> flexibleResource: <memory:0, vCores:0>
2016-08-21 14:55:00,599 INFO org.apache.hadoop.yarn.server.resourcemanager.scheduler.fair.FairScheduler: allocate resource to application attempt: appattempt_1471812677892_0002_000001 queue:root.batch isRunning=true 
2016-08-21 14:55:00,599 INFO org.apache.hadoop.yarn.server.resourcemanager.scheduler.fair.FairScheduler: iglf: 2.getHeadroom()=<memory:0, vCores:0>
2016-08-21 14:55:00,684 INFO org.apache.hadoop.yarn.server.resourcemanager.rmapp.attempt.RMAppAttemptImpl: ScheduleTransition.transition(appattempt_1471812677892_0004_000001,EventType: ATTEMPT_ADDED)
2016-08-21 14:55:00,685 INFO org.apache.hadoop.yarn.server.resourcemanager.scheduler.fair.FairScheduler: allocate(appattempt_1471812677892_0004_000001 [{Priority: 0, Capability: <memory:2048, vCores:1>, # Containers: 1, Location: *, Relax Locality: true}] [] null null
2016-08-21 14:55:00,685 INFO org.apache.hadoop.yarn.server.resourcemanager.scheduler.fair.FSAppAttempt: root.interactive1: <memory:0, vCores:0>
2016-08-21 14:55:00,685 INFO org.apache.hadoop.yarn.server.resourcemanager.scheduler.fair.FSAppAttempt: root.interactive2: <memory:0, vCores:0>
2016-08-21 14:55:00,685 INFO org.apache.hadoop.yarn.server.resourcemanager.scheduler.fair.FSAppAttempt: root.batch: <memory:16384, vCores:8>
2016-08-21 14:55:00,685 INFO org.apache.hadoop.yarn.server.resourcemanager.scheduler.fair.FSAppAttempt: appattempt_1471812677892_0004_000001 minReqResource: <memory:16384, vCores:8> flexibleResource: <memory:0, vCores:0>
2016-08-21 14:55:00,685 INFO org.apache.hadoop.yarn.server.resourcemanager.scheduler.fair.FairScheduler: Cannot allocate appattempt_1471812677892_0004_000001 because there is NO flexible resource left
2016-08-21 14:55:00,698 INFO org.apache.hadoop.yarn.server.resourcemanager.scheduler.fair.FairScheduler: allocate(appattempt_1471812677892_0002_000001 [{Priority: 1, Capability: <memory:1920, vCores:1>, # Containers: 69, Location: *, Relax Locality: true}] [] [] []
2016-08-21 14:55:00,698 INFO org.apache.hadoop.yarn.server.resourcemanager.scheduler.fair.FSAppAttempt: root.interactive1: <memory:0, vCores:0>
2016-08-21 14:55:00,698 INFO org.apache.hadoop.yarn.server.resourcemanager.scheduler.fair.FSAppAttempt: root.interactive2: <memory:0, vCores:0>
2016-08-21 14:55:00,698 INFO org.apache.hadoop.yarn.server.resourcemanager.scheduler.fair.FSAppAttempt: root.batch: <memory:16384, vCores:8>
2016-08-21 14:55:00,698 INFO org.apache.hadoop.yarn.server.resourcemanager.scheduler.fair.FSAppAttempt: appattempt_1471812677892_0002_000001 minReqResource: <memory:16384, vCores:8> flexibleResource: <memory:0, vCores:0>
2016-08-21 14:55:00,698 INFO org.apache.hadoop.yarn.server.resourcemanager.scheduler.fair.FairScheduler: allocate resource to application attempt: appattempt_1471812677892_0002_000001 queue:root.batch isRunning=true 
2016-08-21 14:55:00,699 INFO org.apache.hadoop.yarn.server.resourcemanager.scheduler.fair.FairScheduler: iglf: 2.getHeadroom()=<memory:0, vCores:0>
2016-08-21 14:55:00,798 INFO org.apache.hadoop.yarn.server.resourcemanager.scheduler.fair.FairScheduler: allocate(appattempt_1471812677892_0002_000001 [{Priority: 1, Capability: <memory:1920, vCores:1>, # Containers: 25, Location: *, Relax Locality: true}] [] [] []
2016-08-21 14:55:00,799 INFO org.apache.hadoop.yarn.server.resourcemanager.scheduler.fair.FSAppAttempt: root.interactive1: <memory:0, vCores:0>
2016-08-21 14:55:00,799 INFO org.apache.hadoop.yarn.server.resourcemanager.scheduler.fair.FSAppAttempt: root.interactive2: <memory:0, vCores:0>
2016-08-21 14:55:00,799 INFO org.apache.hadoop.yarn.server.resourcemanager.scheduler.fair.FSAppAttempt: root.batch: <memory:16384, vCores:8>
2016-08-21 14:55:00,799 INFO org.apache.hadoop.yarn.server.resourcemanager.scheduler.fair.FSAppAttempt: appattempt_1471812677892_0002_000001 minReqResource: <memory:16384, vCores:8> flexibleResource: <memory:0, vCores:0>
2016-08-21 14:55:00,799 INFO org.apache.hadoop.yarn.server.resourcemanager.scheduler.fair.FairScheduler: allocate resource to application attempt: appattempt_1471812677892_0002_000001 queue:root.batch isRunning=true 
2016-08-21 14:55:00,800 INFO org.apache.hadoop.yarn.server.resourcemanager.scheduler.fair.FairScheduler: iglf: 2.getHeadroom()=<memory:0, vCores:0>
2016-08-21 14:55:00,849 INFO org.apache.hadoop.yarn.server.resourcemanager.scheduler.fair.FairScheduler: Should preempt <memory:2048, vCores:1> res for queue root.interactive1: resDueToMinShare = <memory:2048, vCores:1>, resDueToFairShare = <memory:2048, vCores:1>
2016-08-21 14:55:00,849 INFO org.apache.hadoop.yarn.server.resourcemanager.scheduler.fair.FairScheduler: Should preempt <memory:2048, vCores:1> res for queue root.interactive2: resDueToMinShare = <memory:2048, vCores:1>, resDueToFairShare = <memory:2048, vCores:1>
2016-08-21 14:55:00,849 INFO org.apache.hadoop.yarn.server.resourcemanager.scheduler.fair.FairScheduler: Preempting container (prio=1res=<memory:2048, vCores:1>) from queue root.batch
2016-08-21 14:55:00,849 INFO org.apache.hadoop.yarn.server.resourcemanager.scheduler.fair.FairScheduler: Preempting container (prio=1res=<memory:2048, vCores:1>) from queue root.batch
2016-08-21 14:55:00,897 INFO org.apache.hadoop.yarn.server.resourcemanager.scheduler.fair.FairScheduler: allocate(appattempt_1471812677892_0002_000001 [{Priority: 1, Capability: <memory:1920, vCores:1>, # Containers: 0, Location: *, Relax Locality: true}] [] [] []
2016-08-21 14:55:00,897 INFO org.apache.hadoop.yarn.server.resourcemanager.scheduler.fair.FSAppAttempt: root.interactive1: <memory:0, vCores:0>
2016-08-21 14:55:00,897 INFO org.apache.hadoop.yarn.server.resourcemanager.scheduler.fair.FSAppAttempt: root.interactive2: <memory:0, vCores:0>
2016-08-21 14:55:00,897 INFO org.apache.hadoop.yarn.server.resourcemanager.scheduler.fair.FSAppAttempt: root.batch: <memory:16384, vCores:8>
2016-08-21 14:55:00,897 INFO org.apache.hadoop.yarn.server.resourcemanager.scheduler.fair.FSAppAttempt: appattempt_1471812677892_0002_000001 minReqResource: <memory:16384, vCores:8> flexibleResource: <memory:0, vCores:0>
2016-08-21 14:55:00,898 INFO org.apache.hadoop.yarn.server.resourcemanager.scheduler.fair.FairScheduler: allocate resource to application attempt: appattempt_1471812677892_0002_000001 queue:root.batch isRunning=true 
2016-08-21 14:55:00,898 INFO org.apache.hadoop.yarn.server.resourcemanager.scheduler.AppSchedulingInfo: checking for deactivate of application :application_1471812677892_0002
2016-08-21 14:55:00,898 INFO org.apache.hadoop.yarn.server.resourcemanager.scheduler.fair.FairScheduler: iglf: 2.getHeadroom()=<memory:0, vCores:0>
2016-08-21 14:55:00,949 INFO org.apache.hadoop.yarn.server.resourcemanager.rmapp.attempt.RMAppAttemptImpl: Updating application attempt appattempt_1471812677892_0002_000001 with final state: FINISHING, and exit status: -1000
2016-08-21 14:55:00,949 INFO org.apache.hadoop.yarn.server.resourcemanager.rmapp.attempt.RMAppAttemptImpl: appattempt_1471812677892_0002_000001 State change from RUNNING to FINAL_SAVING
2016-08-21 14:55:00,949 INFO org.apache.hadoop.yarn.server.resourcemanager.rmapp.RMAppImpl: Updating application application_1471812677892_0002 with final state: FINISHING
2016-08-21 14:55:00,950 INFO org.apache.hadoop.yarn.server.resourcemanager.rmapp.attempt.RMAppAttemptImpl: appattempt_1471812677892_0002_000001 State change from FINAL_SAVING to FINISHING
2016-08-21 14:55:00,950 INFO org.apache.hadoop.yarn.server.resourcemanager.recovery.RMStateStore: Updating info for app: application_1471812677892_0002
2016-08-21 14:55:01,053 INFO org.apache.hadoop.yarn.server.resourcemanager.ApplicationMasterService: application_1471812677892_0002 unregistered successfully. 
2016-08-21 14:55:01,448 INFO org.apache.hadoop.yarn.server.resourcemanager.rmcontainer.RMContainerImpl: Processing container_1471812677892_0002_01_000006 of event FINISHED
2016-08-21 14:55:01,449 INFO org.apache.hadoop.yarn.server.resourcemanager.rmcontainer.RMContainerImpl: container_1471812677892_0002_01_000006 Container Transitioned from RUNNING to COMPLETED
2016-08-21 14:55:01,449 INFO org.apache.hadoop.yarn.server.resourcemanager.scheduler.fair.FSAppAttempt: Completed container: container_1471812677892_0002_01_000006 in state: COMPLETED event:FINISHED
2016-08-21 14:55:01,449 INFO org.apache.hadoop.yarn.server.resourcemanager.RMAuditLogger: USER=tanle	OPERATION=AM Released Container	TARGET=SchedulerApp	RESULT=SUCCESS	APPID=application_1471812677892_0002	CONTAINERID=container_1471812677892_0002_01_000006
2016-08-21 14:55:01,449 INFO org.apache.hadoop.yarn.server.resourcemanager.scheduler.SchedulerNode: Released container container_1471812677892_0002_01_000006 of capacity <memory:2048, vCores:1> on host cp-1.yarn-perf.yarnrm-PG0.wisc.cloudlab.us:39022, which currently has 3 containers, <memory:6144, vCores:3> used and <memory:2048, vCores:1> available, release resources=true
2016-08-21 14:55:01,449 INFO org.apache.hadoop.yarn.server.resourcemanager.scheduler.fair.FairScheduler: Application attempt appattempt_1471812677892_0002_000001 released container container_1471812677892_0002_01_000006 on node: host: cp-1.yarn-perf.yarnrm-PG0.wisc.cloudlab.us:39022 #containers=3 available=<memory:2048, vCores:1> used=<memory:6144, vCores:3> with event: FINISHED
2016-08-21 14:55:01,449 INFO org.apache.hadoop.yarn.server.resourcemanager.rmcontainer.RMContainerImpl: Processing container_1471812677892_0002_01_000003 of event FINISHED
2016-08-21 14:55:01,450 INFO org.apache.hadoop.yarn.server.resourcemanager.rmcontainer.RMContainerImpl: container_1471812677892_0002_01_000003 Container Transitioned from RUNNING to COMPLETED
2016-08-21 14:55:01,450 INFO org.apache.hadoop.yarn.server.resourcemanager.scheduler.fair.FSAppAttempt: Completed container: container_1471812677892_0002_01_000003 in state: COMPLETED event:FINISHED
2016-08-21 14:55:01,450 INFO org.apache.hadoop.yarn.server.resourcemanager.RMAuditLogger: USER=tanle	OPERATION=AM Released Container	TARGET=SchedulerApp	RESULT=SUCCESS	APPID=application_1471812677892_0002	CONTAINERID=container_1471812677892_0002_01_000003
2016-08-21 14:55:01,450 INFO org.apache.hadoop.yarn.server.resourcemanager.scheduler.SchedulerNode: Released container container_1471812677892_0002_01_000003 of capacity <memory:2048, vCores:1> on host cp-1.yarn-perf.yarnrm-PG0.wisc.cloudlab.us:39022, which currently has 2 containers, <memory:4096, vCores:2> used and <memory:4096, vCores:2> available, release resources=true
2016-08-21 14:55:01,450 INFO org.apache.hadoop.yarn.server.resourcemanager.scheduler.fair.FairScheduler: Application attempt appattempt_1471812677892_0002_000001 released container container_1471812677892_0002_01_000003 on node: host: cp-1.yarn-perf.yarnrm-PG0.wisc.cloudlab.us:39022 #containers=2 available=<memory:4096, vCores:2> used=<memory:4096, vCores:2> with event: FINISHED
2016-08-21 14:55:01,450 INFO org.apache.hadoop.yarn.server.resourcemanager.rmcontainer.RMContainerImpl: Processing container_1471812677892_0002_01_000004 of event FINISHED
2016-08-21 14:55:01,450 INFO org.apache.hadoop.yarn.server.resourcemanager.rmcontainer.RMContainerImpl: container_1471812677892_0002_01_000004 Container Transitioned from RUNNING to COMPLETED
2016-08-21 14:55:01,450 INFO org.apache.hadoop.yarn.server.resourcemanager.scheduler.fair.FSAppAttempt: Completed container: container_1471812677892_0002_01_000004 in state: COMPLETED event:FINISHED
2016-08-21 14:55:01,450 INFO org.apache.hadoop.yarn.server.resourcemanager.RMAuditLogger: USER=tanle	OPERATION=AM Released Container	TARGET=SchedulerApp	RESULT=SUCCESS	APPID=application_1471812677892_0002	CONTAINERID=container_1471812677892_0002_01_000004
2016-08-21 14:55:01,451 INFO org.apache.hadoop.yarn.server.resourcemanager.scheduler.SchedulerNode: Released container container_1471812677892_0002_01_000004 of capacity <memory:2048, vCores:1> on host cp-1.yarn-perf.yarnrm-PG0.wisc.cloudlab.us:39022, which currently has 1 containers, <memory:2048, vCores:1> used and <memory:6144, vCores:3> available, release resources=true
2016-08-21 14:55:01,451 INFO org.apache.hadoop.yarn.server.resourcemanager.scheduler.fair.FairScheduler: Application attempt appattempt_1471812677892_0002_000001 released container container_1471812677892_0002_01_000004 on node: host: cp-1.yarn-perf.yarnrm-PG0.wisc.cloudlab.us:39022 #containers=1 available=<memory:6144, vCores:3> used=<memory:2048, vCores:1> with event: FINISHED
2016-08-21 14:55:01,451 INFO org.apache.hadoop.yarn.server.resourcemanager.rmcontainer.RMContainerImpl: Processing container_1471812677892_0002_01_000008 of event FINISHED
2016-08-21 14:55:01,451 INFO org.apache.hadoop.yarn.server.resourcemanager.rmcontainer.RMContainerImpl: container_1471812677892_0002_01_000008 Container Transitioned from RUNNING to COMPLETED
2016-08-21 14:55:01,451 INFO org.apache.hadoop.yarn.server.resourcemanager.scheduler.fair.FSAppAttempt: Completed container: container_1471812677892_0002_01_000008 in state: COMPLETED event:FINISHED
2016-08-21 14:55:01,451 INFO org.apache.hadoop.yarn.server.resourcemanager.RMAuditLogger: USER=tanle	OPERATION=AM Released Container	TARGET=SchedulerApp	RESULT=SUCCESS	APPID=application_1471812677892_0002	CONTAINERID=container_1471812677892_0002_01_000008
2016-08-21 14:55:01,451 INFO org.apache.hadoop.yarn.server.resourcemanager.scheduler.SchedulerNode: Released container container_1471812677892_0002_01_000008 of capacity <memory:2048, vCores:1> on host cp-1.yarn-perf.yarnrm-PG0.wisc.cloudlab.us:39022, which currently has 0 containers, <memory:0, vCores:0> used and <memory:8192, vCores:4> available, release resources=true
2016-08-21 14:55:01,452 INFO org.apache.hadoop.yarn.server.resourcemanager.scheduler.fair.FairScheduler: Application attempt appattempt_1471812677892_0002_000001 released container container_1471812677892_0002_01_000008 on node: host: cp-1.yarn-perf.yarnrm-PG0.wisc.cloudlab.us:39022 #containers=0 available=<memory:8192, vCores:4> used=<memory:0, vCores:0> with event: FINISHED
2016-08-21 14:55:01,452 INFO org.apache.hadoop.yarn.server.resourcemanager.scheduler.fair.FairScheduler: Releasing reservation that cannot be satisfied for application appattempt_1471812677892_0002_000001 on node host: cp-1.yarn-perf.yarnrm-PG0.wisc.cloudlab.us:39022 #containers=0 available=<memory:8192, vCores:4> used=<memory:0, vCores:0>
2016-08-21 14:55:01,452 INFO org.apache.hadoop.yarn.server.resourcemanager.scheduler.fair.FSAppAttempt: Application application_1471812677892_0002 unreserved  on node host: cp-1.yarn-perf.yarnrm-PG0.wisc.cloudlab.us:39022 #containers=0 available=<memory:8192, vCores:4> used=<memory:0, vCores:0>, currently has 1 at priority 1; currentReservation <memory:2048, vCores:1>
2016-08-21 14:55:01,452 INFO org.apache.hadoop.yarn.server.resourcemanager.scheduler.fair.FSAppAttempt: assignContainer(FSSchedulerNode node:cp-1.yarn-perf.yarnrm-PG0.wisc.cloudlab.us, boolean reserved=false) for appattempt_1471812677892_0005_000001
2016-08-21 14:55:01,452 INFO org.apache.hadoop.yarn.server.resourcemanager.scheduler.fair.FSAppAttempt: assignContainer(FSSchedulerNode:cp-1.yarn-perf.yarnrm-PG0.wisc.cloudlab.us, ResourceRequest request, NodeType type, boolean reserved=false
2016-08-21 14:55:01,453 INFO org.apache.hadoop.yarn.server.resourcemanager.scheduler.fair.FSAppAttempt: allocate container: container_1471812677892_0005_01_000001 priority 0
2016-08-21 14:55:01,453 INFO org.apache.hadoop.yarn.server.resourcemanager.rmcontainer.RMContainerImpl: Processing container_1471812677892_0005_01_000001 of event START
2016-08-21 14:55:01,453 INFO org.apache.hadoop.yarn.server.resourcemanager.rmcontainer.RMContainerImpl: container_1471812677892_0005_01_000001 Container Transitioned from NEW to ALLOCATED
2016-08-21 14:55:01,453 INFO org.apache.hadoop.yarn.server.resourcemanager.RMAuditLogger: USER=tanle	OPERATION=AM Allocated Container	TARGET=SchedulerApp	RESULT=SUCCESS	APPID=application_1471812677892_0005	CONTAINERID=container_1471812677892_0005_01_000001
2016-08-21 14:55:01,453 INFO org.apache.hadoop.yarn.server.resourcemanager.rmapp.attempt.RMAppAttemptImpl: AMContainerAllocatedTransition.transition(appattempt_1471812677892_0005_000001,EventType: CONTAINER_ALLOCATED)
2016-08-21 14:55:01,453 INFO org.apache.hadoop.yarn.server.resourcemanager.scheduler.SchedulerNode: Assigned container container_1471812677892_0005_01_000001 of capacity <memory:2048, vCores:1> on host cp-1.yarn-perf.yarnrm-PG0.wisc.cloudlab.us:39022, which has 1 containers, <memory:2048, vCores:1> used and <memory:6144, vCores:3> available after allocation
2016-08-21 14:55:01,453 INFO org.apache.hadoop.yarn.server.resourcemanager.scheduler.fair.FairScheduler: allocate(appattempt_1471812677892_0005_000001 [] [] null null
2016-08-21 14:55:01,454 INFO org.apache.hadoop.yarn.server.resourcemanager.scheduler.fair.FSAppAttempt: root.interactive1: <memory:0, vCores:0>
2016-08-21 14:55:01,454 INFO org.apache.hadoop.yarn.server.resourcemanager.scheduler.fair.FSAppAttempt: root.interactive2: <memory:2048, vCores:1>
2016-08-21 14:55:01,454 INFO org.apache.hadoop.yarn.server.resourcemanager.scheduler.fair.FSAppAttempt: root.batch: <memory:8192, vCores:4>
2016-08-21 14:55:01,454 INFO org.apache.hadoop.yarn.server.resourcemanager.scheduler.fair.FSAppAttempt: appattempt_1471812677892_0005_000001 minReqResource: <memory:16384, vCores:8> flexibleResource: <memory:0, vCores:0>
2016-08-21 14:55:01,454 INFO org.apache.hadoop.yarn.server.resourcemanager.scheduler.fair.FairScheduler: allocate resource to application attempt: appattempt_1471812677892_0005_000001 queue:root.interactive2 isRunning=true 
2016-08-21 14:55:01,456 INFO org.apache.hadoop.yarn.server.resourcemanager.security.NMTokenSecretManagerInRM: Sending NMToken for nodeId : cp-1.yarn-perf.yarnrm-PG0.wisc.cloudlab.us:39022 for container : container_1471812677892_0005_01_000001
2016-08-21 14:55:01,457 INFO org.apache.hadoop.yarn.server.resourcemanager.rmcontainer.RMContainerImpl: Processing container_1471812677892_0005_01_000001 of event ACQUIRED
2016-08-21 14:55:01,458 INFO org.apache.hadoop.yarn.server.resourcemanager.rmcontainer.RMContainerImpl: container_1471812677892_0005_01_000001 Container Transitioned from ALLOCATED to ACQUIRED
2016-08-21 14:55:01,458 INFO org.apache.hadoop.yarn.server.resourcemanager.scheduler.fair.FairScheduler: iglf: 5.getHeadroom()=<memory:6144, vCores:3>
2016-08-21 14:55:01,458 INFO org.apache.hadoop.yarn.server.resourcemanager.security.NMTokenSecretManagerInRM: Clear node set for appattempt_1471812677892_0005_000001
2016-08-21 14:55:01,458 INFO org.apache.hadoop.yarn.server.resourcemanager.rmapp.attempt.RMAppAttemptImpl: Storing attempt: AppId: application_1471812677892_0005 AttemptId: appattempt_1471812677892_0005_000001 MasterContainer: Container: [ContainerId: container_1471812677892_0005_01_000001, NodeId: cp-1.yarn-perf.yarnrm-PG0.wisc.cloudlab.us:39022, NodeHttpAddress: cp-1.yarn-perf.yarnrm-PG0.wisc.cloudlab.us:8042, Resource: <memory:2048, vCores:1>, Priority: 0, Token: Token { kind: ContainerToken, service: 128.104.222.17:39022 }, ]
2016-08-21 14:55:01,458 INFO org.apache.hadoop.yarn.server.resourcemanager.rmapp.attempt.RMAppAttemptImpl: appattempt_1471812677892_0005_000001 State change from SCHEDULED to ALLOCATED_SAVING
2016-08-21 14:55:01,459 INFO org.apache.hadoop.yarn.server.resourcemanager.rmapp.attempt.RMAppAttemptImpl: appattempt_1471812677892_0005_000001 State change from ALLOCATED_SAVING to ALLOCATED
2016-08-21 14:55:01,460 INFO org.apache.hadoop.yarn.server.resourcemanager.amlauncher.AMLauncher: Launching masterappattempt_1471812677892_0005_000001
2016-08-21 14:55:01,463 INFO org.apache.hadoop.yarn.server.resourcemanager.amlauncher.AMLauncher: Setting up container Container: [ContainerId: container_1471812677892_0005_01_000001, NodeId: cp-1.yarn-perf.yarnrm-PG0.wisc.cloudlab.us:39022, NodeHttpAddress: cp-1.yarn-perf.yarnrm-PG0.wisc.cloudlab.us:8042, Resource: <memory:2048, vCores:1>, Priority: 0, Token: Token { kind: ContainerToken, service: 128.104.222.17:39022 }, ] for AM appattempt_1471812677892_0005_000001
2016-08-21 14:55:01,463 INFO org.apache.hadoop.yarn.server.resourcemanager.amlauncher.AMLauncher: Command to launch container container_1471812677892_0005_01_000001 : {{JAVA_HOME}}/bin/java,-server,-Xmx1536m,-Djava.io.tmpdir={{PWD}}/tmp,-Dspark.yarn.app.container.log.dir=<LOG_DIR>,-XX:MaxPermSize=256m,org.apache.spark.deploy.yarn.ApplicationMaster,--class,'org.apache.spark.examples.SparkPi',--jar,file:/users/tanle/./spark/examples/jars/spark-examples_2.11-2.0.0-preview.jar,--arg,'10000',--properties-file,{{PWD}}/__spark_conf__/__spark_conf__.properties,1>,<LOG_DIR>/stdout,2>,<LOG_DIR>/stderr
2016-08-21 14:55:01,463 INFO org.apache.hadoop.yarn.server.resourcemanager.security.AMRMTokenSecretManager: Create AMRMToken for ApplicationAttempt: appattempt_1471812677892_0005_000001
2016-08-21 14:55:01,464 INFO org.apache.hadoop.yarn.server.resourcemanager.security.AMRMTokenSecretManager: Creating password for appattempt_1471812677892_0005_000001
2016-08-21 14:55:01,481 INFO org.apache.hadoop.yarn.server.resourcemanager.amlauncher.AMLauncher: Done launching container Container: [ContainerId: container_1471812677892_0005_01_000001, NodeId: cp-1.yarn-perf.yarnrm-PG0.wisc.cloudlab.us:39022, NodeHttpAddress: cp-1.yarn-perf.yarnrm-PG0.wisc.cloudlab.us:8042, Resource: <memory:2048, vCores:1>, Priority: 0, Token: Token { kind: ContainerToken, service: 128.104.222.17:39022 }, ] for AM appattempt_1471812677892_0005_000001
2016-08-21 14:55:01,481 INFO org.apache.hadoop.yarn.server.resourcemanager.rmapp.attempt.RMAppAttemptImpl: appattempt_1471812677892_0005_000001 State change from ALLOCATED to LAUNCHED
2016-08-21 14:55:01,515 INFO org.apache.hadoop.yarn.server.resourcemanager.rmcontainer.RMContainerImpl: Processing container_1471812677892_0002_01_000005 of event FINISHED
2016-08-21 14:55:01,516 INFO org.apache.hadoop.yarn.server.resourcemanager.rmcontainer.RMContainerImpl: container_1471812677892_0002_01_000005 Container Transitioned from RUNNING to COMPLETED
2016-08-21 14:55:01,516 INFO org.apache.hadoop.yarn.server.resourcemanager.scheduler.fair.FSAppAttempt: Completed container: container_1471812677892_0002_01_000005 in state: COMPLETED event:FINISHED
2016-08-21 14:55:01,516 INFO org.apache.hadoop.yarn.server.resourcemanager.RMAuditLogger: USER=tanle	OPERATION=AM Released Container	TARGET=SchedulerApp	RESULT=SUCCESS	APPID=application_1471812677892_0002	CONTAINERID=container_1471812677892_0002_01_000005
2016-08-21 14:55:01,516 INFO org.apache.hadoop.yarn.server.resourcemanager.scheduler.SchedulerNode: Released container container_1471812677892_0002_01_000005 of capacity <memory:2048, vCores:1> on host c220g1-031106.wisc.cloudlab.us:33388, which currently has 3 containers, <memory:6144, vCores:3> used and <memory:2048, vCores:1> available, release resources=true
2016-08-21 14:55:01,516 INFO org.apache.hadoop.yarn.server.resourcemanager.scheduler.fair.FairScheduler: Application attempt appattempt_1471812677892_0002_000001 released container container_1471812677892_0002_01_000005 on node: host: c220g1-031106.wisc.cloudlab.us:33388 #containers=3 available=<memory:2048, vCores:1> used=<memory:6144, vCores:3> with event: FINISHED
2016-08-21 14:55:01,516 INFO org.apache.hadoop.yarn.server.resourcemanager.rmcontainer.RMContainerImpl: Processing container_1471812677892_0002_01_000007 of event FINISHED
2016-08-21 14:55:01,517 INFO org.apache.hadoop.yarn.server.resourcemanager.rmcontainer.RMContainerImpl: container_1471812677892_0002_01_000007 Container Transitioned from RUNNING to COMPLETED
2016-08-21 14:55:01,517 INFO org.apache.hadoop.yarn.server.resourcemanager.scheduler.fair.FSAppAttempt: Completed container: container_1471812677892_0002_01_000007 in state: COMPLETED event:FINISHED
2016-08-21 14:55:01,517 INFO org.apache.hadoop.yarn.server.resourcemanager.RMAuditLogger: USER=tanle	OPERATION=AM Released Container	TARGET=SchedulerApp	RESULT=SUCCESS	APPID=application_1471812677892_0002	CONTAINERID=container_1471812677892_0002_01_000007
2016-08-21 14:55:01,517 INFO org.apache.hadoop.yarn.server.resourcemanager.scheduler.SchedulerNode: Released container container_1471812677892_0002_01_000007 of capacity <memory:2048, vCores:1> on host c220g1-031106.wisc.cloudlab.us:33388, which currently has 2 containers, <memory:4096, vCores:2> used and <memory:4096, vCores:2> available, release resources=true
2016-08-21 14:55:01,517 INFO org.apache.hadoop.yarn.server.resourcemanager.scheduler.fair.FairScheduler: Application attempt appattempt_1471812677892_0002_000001 released container container_1471812677892_0002_01_000007 on node: host: c220g1-031106.wisc.cloudlab.us:33388 #containers=2 available=<memory:4096, vCores:2> used=<memory:4096, vCores:2> with event: FINISHED
2016-08-21 14:55:01,517 INFO org.apache.hadoop.yarn.server.resourcemanager.rmcontainer.RMContainerImpl: Processing container_1471812677892_0002_01_000002 of event FINISHED
2016-08-21 14:55:01,517 INFO org.apache.hadoop.yarn.server.resourcemanager.rmcontainer.RMContainerImpl: container_1471812677892_0002_01_000002 Container Transitioned from RUNNING to COMPLETED
2016-08-21 14:55:01,517 INFO org.apache.hadoop.yarn.server.resourcemanager.scheduler.fair.FSAppAttempt: Completed container: container_1471812677892_0002_01_000002 in state: COMPLETED event:FINISHED
2016-08-21 14:55:01,518 INFO org.apache.hadoop.yarn.server.resourcemanager.RMAuditLogger: USER=tanle	OPERATION=AM Released Container	TARGET=SchedulerApp	RESULT=SUCCESS	APPID=application_1471812677892_0002	CONTAINERID=container_1471812677892_0002_01_000002
2016-08-21 14:55:01,518 INFO org.apache.hadoop.yarn.server.resourcemanager.ApplicationMasterService: Unregistering app attempt : appattempt_1471812677892_0002_000001
2016-08-21 14:55:01,518 INFO org.apache.hadoop.yarn.server.resourcemanager.scheduler.SchedulerNode: Released container container_1471812677892_0002_01_000002 of capacity <memory:2048, vCores:1> on host c220g1-031106.wisc.cloudlab.us:33388, which currently has 1 containers, <memory:2048, vCores:1> used and <memory:6144, vCores:3> available, release resources=true
2016-08-21 14:55:01,518 INFO org.apache.hadoop.yarn.server.resourcemanager.security.AMRMTokenSecretManager: Application finished, removing password for appattempt_1471812677892_0002_000001
2016-08-21 14:55:01,518 INFO org.apache.hadoop.yarn.server.resourcemanager.scheduler.fair.FairScheduler: Application attempt appattempt_1471812677892_0002_000001 released container container_1471812677892_0002_01_000002 on node: host: c220g1-031106.wisc.cloudlab.us:33388 #containers=1 available=<memory:6144, vCores:3> used=<memory:2048, vCores:1> with event: FINISHED
2016-08-21 14:55:01,518 INFO org.apache.hadoop.yarn.server.resourcemanager.rmapp.attempt.RMAppAttemptImpl: appattempt_1471812677892_0002_000001 State change from FINISHING to FINISHED
2016-08-21 14:55:01,518 INFO org.apache.hadoop.yarn.server.resourcemanager.rmcontainer.RMContainerImpl: Processing container_1471812677892_0002_01_000009 of event FINISHED
2016-08-21 14:55:01,518 INFO org.apache.hadoop.yarn.server.resourcemanager.rmcontainer.RMContainerImpl: container_1471812677892_0002_01_000009 Container Transitioned from RUNNING to COMPLETED
2016-08-21 14:55:01,519 INFO org.apache.hadoop.yarn.server.resourcemanager.scheduler.fair.FSAppAttempt: Completed container: container_1471812677892_0002_01_000009 in state: COMPLETED event:FINISHED
2016-08-21 14:55:01,519 INFO org.apache.hadoop.yarn.server.resourcemanager.RMAuditLogger: USER=tanle	OPERATION=AM Released Container	TARGET=SchedulerApp	RESULT=SUCCESS	APPID=application_1471812677892_0002	CONTAINERID=container_1471812677892_0002_01_000009
2016-08-21 14:55:01,519 INFO org.apache.hadoop.yarn.server.resourcemanager.scheduler.SchedulerNode: Released container container_1471812677892_0002_01_000009 of capacity <memory:2048, vCores:1> on host c220g1-031106.wisc.cloudlab.us:33388, which currently has 0 containers, <memory:0, vCores:0> used and <memory:8192, vCores:4> available, release resources=true
2016-08-21 14:55:01,519 INFO org.apache.hadoop.yarn.server.resourcemanager.RMAuditLogger: USER=tanle	OPERATION=Application Finished - Succeeded	TARGET=RMAppManager	RESULT=SUCCESS	APPID=application_1471812677892_0002
2016-08-21 14:55:01,519 INFO org.apache.hadoop.yarn.server.resourcemanager.scheduler.fair.FairScheduler: Application attempt appattempt_1471812677892_0002_000001 released container container_1471812677892_0002_01_000009 on node: host: c220g1-031106.wisc.cloudlab.us:33388 #containers=0 available=<memory:8192, vCores:4> used=<memory:0, vCores:0> with event: FINISHED
2016-08-21 14:55:01,519 INFO org.apache.hadoop.yarn.server.resourcemanager.scheduler.fair.FairScheduler: Releasing reservation that cannot be satisfied for application appattempt_1471812677892_0002_000001 on node host: c220g1-031106.wisc.cloudlab.us:33388 #containers=0 available=<memory:8192, vCores:4> used=<memory:0, vCores:0>
2016-08-21 14:55:01,519 INFO org.apache.hadoop.yarn.server.resourcemanager.scheduler.fair.FSAppAttempt: Application application_1471812677892_0002 unreserved  on node host: c220g1-031106.wisc.cloudlab.us:33388 #containers=0 available=<memory:8192, vCores:4> used=<memory:0, vCores:0>, currently has 0 at priority 1; currentReservation <memory:0, vCores:0>
2016-08-21 14:55:01,519 INFO org.apache.hadoop.yarn.server.resourcemanager.amlauncher.AMLauncher: Cleaning master appattempt_1471812677892_0002_000001
2016-08-21 14:55:01,520 INFO org.apache.hadoop.yarn.server.resourcemanager.RMAppManager$ApplicationSummary: appId=application_1471812677892_0002,name=org.apache.spark.examples.SparkPi,user=tanle,queue=root.batch,state=FINISHED,trackingUrl=http://nm.yarn-perf.yarnrm-pg0.wisc.cloudlab.us:8088/proxy/application_1471812677892_0002/,appMasterHost=128.104.222.16,startTime=1471812817800,finishTime=1471812900949,finalStatus=SUCCEEDED,memorySeconds=544500,vcoreSeconds=265,preemptedAMContainers=0,preemptedNonAMContainers=0,preemptedResources=<memory:0\, vCores:0>,applicationType=SPARK
2016-08-21 14:55:01,520 INFO org.apache.hadoop.yarn.server.resourcemanager.scheduler.fair.FSAppAttempt: assignContainer(FSSchedulerNode node:c220g1-031106.wisc.cloudlab.us, boolean reserved=false) for appattempt_1471812677892_0003_000001
2016-08-21 14:55:01,520 INFO org.apache.hadoop.yarn.server.resourcemanager.scheduler.fair.FSAppAttempt: assignContainer(FSSchedulerNode:c220g1-031106.wisc.cloudlab.us, ResourceRequest request, NodeType type, boolean reserved=false
2016-08-21 14:55:01,520 INFO org.apache.hadoop.yarn.server.resourcemanager.scheduler.fair.FSAppAttempt: allocate container: container_1471812677892_0003_01_000001 priority 0
2016-08-21 14:55:01,521 INFO org.apache.hadoop.yarn.server.resourcemanager.rmcontainer.RMContainerImpl: Processing container_1471812677892_0003_01_000001 of event START
2016-08-21 14:55:01,521 INFO org.apache.hadoop.yarn.server.resourcemanager.rmcontainer.RMContainerImpl: container_1471812677892_0003_01_000001 Container Transitioned from NEW to ALLOCATED
2016-08-21 14:55:01,521 INFO org.apache.hadoop.yarn.server.resourcemanager.RMAuditLogger: USER=tanle	OPERATION=AM Allocated Container	TARGET=SchedulerApp	RESULT=SUCCESS	APPID=application_1471812677892_0003	CONTAINERID=container_1471812677892_0003_01_000001
2016-08-21 14:55:01,521 INFO org.apache.hadoop.yarn.server.resourcemanager.rmapp.attempt.RMAppAttemptImpl: AMContainerAllocatedTransition.transition(appattempt_1471812677892_0003_000001,EventType: CONTAINER_ALLOCATED)
2016-08-21 14:55:01,521 INFO org.apache.hadoop.yarn.server.resourcemanager.scheduler.SchedulerNode: Assigned container container_1471812677892_0003_01_000001 of capacity <memory:2048, vCores:1> on host c220g1-031106.wisc.cloudlab.us:33388, which has 1 containers, <memory:2048, vCores:1> used and <memory:6144, vCores:3> available after allocation
2016-08-21 14:55:01,521 INFO org.apache.hadoop.yarn.server.resourcemanager.scheduler.fair.FairScheduler: allocate(appattempt_1471812677892_0003_000001 [] [] null null
2016-08-21 14:55:01,521 INFO org.apache.hadoop.yarn.server.resourcemanager.scheduler.fair.FairScheduler: Application appattempt_1471812677892_0002_000001 is done. finalState=FINISHED
2016-08-21 14:55:01,521 INFO org.apache.hadoop.yarn.server.resourcemanager.scheduler.fair.FSAppAttempt: root.interactive1: <memory:2048, vCores:1>
2016-08-21 14:55:01,522 INFO org.apache.hadoop.yarn.server.resourcemanager.scheduler.fair.FSAppAttempt: root.interactive2: <memory:2048, vCores:1>
2016-08-21 14:55:01,522 INFO org.apache.hadoop.yarn.server.resourcemanager.scheduler.AppSchedulingInfo: Application application_1471812677892_0002 requests cleared
2016-08-21 14:55:01,522 INFO org.apache.hadoop.yarn.server.resourcemanager.scheduler.fair.FSAppAttempt: root.batch: <memory:0, vCores:0>
2016-08-21 14:55:01,522 INFO org.apache.hadoop.yarn.server.resourcemanager.scheduler.fair.FSLeafQueue: queue: root.batch include 0 active apps: [org.apache.hadoop.yarn.server.resourcemanager.scheduler.fair.FSAppAttempt@221fb9be, org.apache.hadoop.yarn.server.resourcemanager.scheduler.fair.FSAppAttempt@50db7a72]
2016-08-21 14:55:01,522 INFO org.apache.hadoop.yarn.server.resourcemanager.scheduler.fair.FSAppAttempt: appattempt_1471812677892_0003_000001 minReqResource: <memory:16384, vCores:8> flexibleResource: <memory:0, vCores:0>
2016-08-21 14:55:01,522 INFO org.apache.hadoop.yarn.server.resourcemanager.scheduler.fair.FairScheduler: allocate resource to application attempt: appattempt_1471812677892_0003_000001 queue:root.interactive1 isRunning=true 
2016-08-21 14:55:01,522 INFO org.apache.hadoop.yarn.server.resourcemanager.scheduler.fair.FairScheduler: remove application attempt appattempt_1471812677892_0002_000001 in queue: [root.batch, demand=<memory:20480, vCores:10>, running=<memory:0, vCores:0>, share=<memory:0, vCores:0>, w=<memory weight=1.0, cpu weight=1.0>]
2016-08-21 14:55:01,523 INFO org.apache.hadoop.yarn.server.resourcemanager.scheduler.fair.FairScheduler: set queue: [root.batch, demand=<memory:20480, vCores:10>, running=<memory:0, vCores:0>, share=<memory:0, vCores:0>, w=<memory weight=1.0, cpu weight=1.0>] isRunning=false
2016-08-21 14:55:01,524 INFO org.apache.hadoop.yarn.server.resourcemanager.security.NMTokenSecretManagerInRM: Sending NMToken for nodeId : c220g1-031106.wisc.cloudlab.us:33388 for container : container_1471812677892_0003_01_000001
2016-08-21 14:55:01,525 INFO org.apache.hadoop.yarn.server.resourcemanager.rmcontainer.RMContainerImpl: Processing container_1471812677892_0003_01_000001 of event ACQUIRED
2016-08-21 14:55:01,526 INFO org.apache.hadoop.yarn.server.resourcemanager.rmcontainer.RMContainerImpl: container_1471812677892_0003_01_000001 Container Transitioned from ALLOCATED to ACQUIRED
2016-08-21 14:55:01,526 INFO org.apache.hadoop.yarn.server.resourcemanager.scheduler.fair.FairScheduler: iglf: 3.getHeadroom()=<memory:6144, vCores:3>
2016-08-21 14:55:01,526 INFO org.apache.hadoop.yarn.server.resourcemanager.security.NMTokenSecretManagerInRM: Clear node set for appattempt_1471812677892_0003_000001
2016-08-21 14:55:01,526 INFO org.apache.hadoop.yarn.server.resourcemanager.rmapp.attempt.RMAppAttemptImpl: Storing attempt: AppId: application_1471812677892_0003 AttemptId: appattempt_1471812677892_0003_000001 MasterContainer: Container: [ContainerId: container_1471812677892_0003_01_000001, NodeId: c220g1-031106.wisc.cloudlab.us:33388, NodeHttpAddress: c220g1-031106.wisc.cloudlab.us:8042, Resource: <memory:2048, vCores:1>, Priority: 0, Token: Token { kind: ContainerToken, service: 128.104.222.16:33388 }, ]
2016-08-21 14:55:01,526 INFO org.apache.hadoop.yarn.server.resourcemanager.rmapp.attempt.RMAppAttemptImpl: appattempt_1471812677892_0003_000001 State change from SCHEDULED to ALLOCATED_SAVING
2016-08-21 14:55:01,526 INFO org.apache.hadoop.yarn.server.resourcemanager.rmapp.attempt.RMAppAttemptImpl: appattempt_1471812677892_0003_000001 State change from ALLOCATED_SAVING to ALLOCATED
2016-08-21 14:55:01,527 INFO org.apache.hadoop.yarn.server.resourcemanager.amlauncher.AMLauncher: Launching masterappattempt_1471812677892_0003_000001
2016-08-21 14:55:01,530 INFO org.apache.hadoop.yarn.server.resourcemanager.amlauncher.AMLauncher: Setting up container Container: [ContainerId: container_1471812677892_0003_01_000001, NodeId: c220g1-031106.wisc.cloudlab.us:33388, NodeHttpAddress: c220g1-031106.wisc.cloudlab.us:8042, Resource: <memory:2048, vCores:1>, Priority: 0, Token: Token { kind: ContainerToken, service: 128.104.222.16:33388 }, ] for AM appattempt_1471812677892_0003_000001
2016-08-21 14:55:01,530 INFO org.apache.hadoop.yarn.server.resourcemanager.amlauncher.AMLauncher: Command to launch container container_1471812677892_0003_01_000001 : {{JAVA_HOME}}/bin/java,-server,-Xmx1536m,-Djava.io.tmpdir={{PWD}}/tmp,-Dspark.yarn.app.container.log.dir=<LOG_DIR>,-XX:MaxPermSize=256m,org.apache.spark.deploy.yarn.ApplicationMaster,--class,'org.apache.spark.examples.SparkPi',--jar,file:/users/tanle/./spark/examples/jars/spark-examples_2.11-2.0.0-preview.jar,--arg,'10000',--properties-file,{{PWD}}/__spark_conf__/__spark_conf__.properties,1>,<LOG_DIR>/stdout,2>,<LOG_DIR>/stderr
2016-08-21 14:55:01,530 INFO org.apache.hadoop.yarn.server.resourcemanager.security.AMRMTokenSecretManager: Create AMRMToken for ApplicationAttempt: appattempt_1471812677892_0003_000001
2016-08-21 14:55:01,530 INFO org.apache.hadoop.yarn.server.resourcemanager.security.AMRMTokenSecretManager: Creating password for appattempt_1471812677892_0003_000001
2016-08-21 14:55:01,537 INFO org.apache.hadoop.yarn.server.resourcemanager.scheduler.fair.FSAppAttempt: assignContainer(FSSchedulerNode node:c220g1-031106.wisc.cloudlab.us, boolean reserved=false) for appattempt_1471812677892_0004_000001
2016-08-21 14:55:01,539 INFO org.apache.hadoop.yarn.server.resourcemanager.scheduler.fair.FSAppAttempt: assignContainer(FSSchedulerNode node:c220g1-031106.wisc.cloudlab.us, boolean reserved=false) for appattempt_1471812677892_0005_000001
2016-08-21 14:55:01,539 INFO org.apache.hadoop.yarn.server.resourcemanager.scheduler.fair.FSAppAttempt: assignContainer(FSSchedulerNode node:c220g1-031106.wisc.cloudlab.us, boolean reserved=false) for appattempt_1471812677892_0003_000001
2016-08-21 14:55:01,539 INFO org.apache.hadoop.yarn.server.resourcemanager.scheduler.fair.FSAppAttempt: assignContainer(FSSchedulerNode node:c220g1-031106.wisc.cloudlab.us, boolean reserved=false) for appattempt_1471812677892_0006_000001
2016-08-21 14:55:01,539 INFO org.apache.hadoop.yarn.server.resourcemanager.scheduler.fair.FSAppAttempt: assignContainer(FSSchedulerNode node:c220g1-031106.wisc.cloudlab.us, boolean reserved=false) for appattempt_1471812677892_0007_000001
2016-08-21 14:55:01,547 INFO org.apache.hadoop.yarn.server.resourcemanager.amlauncher.AMLauncher: Done launching container Container: [ContainerId: container_1471812677892_0003_01_000001, NodeId: c220g1-031106.wisc.cloudlab.us:33388, NodeHttpAddress: c220g1-031106.wisc.cloudlab.us:8042, Resource: <memory:2048, vCores:1>, Priority: 0, Token: Token { kind: ContainerToken, service: 128.104.222.16:33388 }, ] for AM appattempt_1471812677892_0003_000001
2016-08-21 14:55:01,548 INFO org.apache.hadoop.yarn.server.resourcemanager.rmapp.attempt.RMAppAttemptImpl: appattempt_1471812677892_0003_000001 State change from ALLOCATED to LAUNCHED
2016-08-21 14:55:01,686 INFO org.apache.hadoop.yarn.server.resourcemanager.rmapp.attempt.RMAppAttemptImpl: ScheduleTransition.transition(appattempt_1471812677892_0004_000001,EventType: ATTEMPT_ADDED)
2016-08-21 14:55:01,686 INFO org.apache.hadoop.yarn.server.resourcemanager.scheduler.fair.FairScheduler: allocate(appattempt_1471812677892_0004_000001 [{Priority: 0, Capability: <memory:2048, vCores:1>, # Containers: 1, Location: *, Relax Locality: true}] [] null null
2016-08-21 14:55:01,686 INFO org.apache.hadoop.yarn.server.resourcemanager.scheduler.fair.FSAppAttempt: root.interactive1: <memory:2048, vCores:1>
2016-08-21 14:55:01,686 INFO org.apache.hadoop.yarn.server.resourcemanager.scheduler.fair.FSAppAttempt: root.interactive2: <memory:2048, vCores:1>
2016-08-21 14:55:01,686 INFO org.apache.hadoop.yarn.server.resourcemanager.scheduler.fair.FSAppAttempt: appattempt_1471812677892_0004_000001 minReqResource: <memory:16384, vCores:8> flexibleResource: <memory:0, vCores:0>
2016-08-21 14:55:01,686 INFO org.apache.hadoop.yarn.server.resourcemanager.scheduler.fair.FairScheduler: Cannot allocate appattempt_1471812677892_0004_000001 because there is NO flexible resource left
2016-08-21 14:55:02,452 INFO org.apache.hadoop.yarn.server.resourcemanager.rmcontainer.RMContainerImpl: Processing container_1471812677892_0005_01_000001 of event LAUNCHED
2016-08-21 14:55:02,452 INFO org.apache.hadoop.yarn.server.resourcemanager.rmcontainer.RMContainerImpl: container_1471812677892_0005_01_000001 Container Transitioned from ACQUIRED to RUNNING
2016-08-21 14:55:02,452 INFO org.apache.hadoop.yarn.server.resourcemanager.scheduler.fair.FSAppAttempt: assignContainer(FSSchedulerNode node:cp-1.yarn-perf.yarnrm-PG0.wisc.cloudlab.us, boolean reserved=false) for appattempt_1471812677892_0004_000001
2016-08-21 14:55:02,452 INFO org.apache.hadoop.yarn.server.resourcemanager.scheduler.fair.FSAppAttempt: assignContainer(FSSchedulerNode node:cp-1.yarn-perf.yarnrm-PG0.wisc.cloudlab.us, boolean reserved=false) for appattempt_1471812677892_0005_000001
2016-08-21 14:55:02,453 INFO org.apache.hadoop.yarn.server.resourcemanager.scheduler.fair.FSAppAttempt: assignContainer(FSSchedulerNode node:cp-1.yarn-perf.yarnrm-PG0.wisc.cloudlab.us, boolean reserved=false) for appattempt_1471812677892_0003_000001
2016-08-21 14:55:02,453 INFO org.apache.hadoop.yarn.server.resourcemanager.scheduler.fair.FSAppAttempt: assignContainer(FSSchedulerNode node:cp-1.yarn-perf.yarnrm-PG0.wisc.cloudlab.us, boolean reserved=false) for appattempt_1471812677892_0006_000001
2016-08-21 14:55:02,453 INFO org.apache.hadoop.yarn.server.resourcemanager.scheduler.fair.FSAppAttempt: assignContainer(FSSchedulerNode node:cp-1.yarn-perf.yarnrm-PG0.wisc.cloudlab.us, boolean reserved=false) for appattempt_1471812677892_0007_000001
2016-08-21 14:55:02,543 INFO org.apache.hadoop.yarn.server.resourcemanager.rmcontainer.RMContainerImpl: Processing container_1471812677892_0003_01_000001 of event LAUNCHED
2016-08-21 14:55:02,543 INFO org.apache.hadoop.yarn.server.resourcemanager.rmcontainer.RMContainerImpl: container_1471812677892_0003_01_000001 Container Transitioned from ACQUIRED to RUNNING
2016-08-21 14:55:02,544 INFO org.apache.hadoop.yarn.server.resourcemanager.scheduler.fair.FairScheduler: Null container completed...
2016-08-21 14:55:02,544 INFO org.apache.hadoop.yarn.server.resourcemanager.scheduler.fair.FairScheduler: Null container completed...
2016-08-21 14:55:02,544 INFO org.apache.hadoop.yarn.server.resourcemanager.scheduler.fair.FairScheduler: Null container completed...
2016-08-21 14:55:02,545 INFO org.apache.hadoop.yarn.server.resourcemanager.scheduler.fair.FSAppAttempt: assignContainer(FSSchedulerNode node:c220g1-031106.wisc.cloudlab.us, boolean reserved=false) for appattempt_1471812677892_0004_000001
2016-08-21 14:55:02,545 INFO org.apache.hadoop.yarn.server.resourcemanager.scheduler.fair.FSAppAttempt: assignContainer(FSSchedulerNode node:c220g1-031106.wisc.cloudlab.us, boolean reserved=false) for appattempt_1471812677892_0005_000001
2016-08-21 14:55:02,545 INFO org.apache.hadoop.yarn.server.resourcemanager.scheduler.fair.FSAppAttempt: assignContainer(FSSchedulerNode node:c220g1-031106.wisc.cloudlab.us, boolean reserved=false) for appattempt_1471812677892_0003_000001
2016-08-21 14:55:02,545 INFO org.apache.hadoop.yarn.server.resourcemanager.scheduler.fair.FSAppAttempt: assignContainer(FSSchedulerNode node:c220g1-031106.wisc.cloudlab.us, boolean reserved=false) for appattempt_1471812677892_0006_000001
2016-08-21 14:55:02,545 INFO org.apache.hadoop.yarn.server.resourcemanager.scheduler.fair.FSAppAttempt: assignContainer(FSSchedulerNode node:c220g1-031106.wisc.cloudlab.us, boolean reserved=false) for appattempt_1471812677892_0007_000001
2016-08-21 14:55:02,687 INFO org.apache.hadoop.yarn.server.resourcemanager.rmapp.attempt.RMAppAttemptImpl: ScheduleTransition.transition(appattempt_1471812677892_0004_000001,EventType: ATTEMPT_ADDED)
2016-08-21 14:55:02,687 INFO org.apache.hadoop.yarn.server.resourcemanager.scheduler.fair.FairScheduler: allocate(appattempt_1471812677892_0004_000001 [{Priority: 0, Capability: <memory:2048, vCores:1>, # Containers: 1, Location: *, Relax Locality: true}] [] null null
2016-08-21 14:55:02,688 INFO org.apache.hadoop.yarn.server.resourcemanager.scheduler.fair.FSAppAttempt: root.interactive1: <memory:2048, vCores:1>
2016-08-21 14:55:02,688 INFO org.apache.hadoop.yarn.server.resourcemanager.scheduler.fair.FSAppAttempt: root.interactive2: <memory:2048, vCores:1>
2016-08-21 14:55:02,688 INFO org.apache.hadoop.yarn.server.resourcemanager.scheduler.fair.FSAppAttempt: appattempt_1471812677892_0004_000001 minReqResource: <memory:16384, vCores:8> flexibleResource: <memory:0, vCores:0>
2016-08-21 14:55:02,688 INFO org.apache.hadoop.yarn.server.resourcemanager.scheduler.fair.FairScheduler: Cannot allocate appattempt_1471812677892_0004_000001 because there is NO flexible resource left
2016-08-21 14:55:03,456 INFO org.apache.hadoop.yarn.server.resourcemanager.scheduler.fair.FairScheduler: Null container completed...
2016-08-21 14:55:03,457 INFO org.apache.hadoop.yarn.server.resourcemanager.scheduler.fair.FairScheduler: Null container completed...
2016-08-21 14:55:03,457 INFO org.apache.hadoop.yarn.server.resourcemanager.scheduler.fair.FairScheduler: Null container completed...
2016-08-21 14:55:03,457 INFO org.apache.hadoop.yarn.server.resourcemanager.scheduler.fair.FairScheduler: Null container completed...
2016-08-21 14:55:03,457 INFO org.apache.hadoop.yarn.server.resourcemanager.scheduler.fair.FSAppAttempt: assignContainer(FSSchedulerNode node:cp-1.yarn-perf.yarnrm-PG0.wisc.cloudlab.us, boolean reserved=false) for appattempt_1471812677892_0004_000001
2016-08-21 14:55:03,457 INFO org.apache.hadoop.yarn.server.resourcemanager.scheduler.fair.FSAppAttempt: assignContainer(FSSchedulerNode node:cp-1.yarn-perf.yarnrm-PG0.wisc.cloudlab.us, boolean reserved=false) for appattempt_1471812677892_0005_000001
2016-08-21 14:55:03,457 INFO org.apache.hadoop.yarn.server.resourcemanager.scheduler.fair.FSAppAttempt: assignContainer(FSSchedulerNode node:cp-1.yarn-perf.yarnrm-PG0.wisc.cloudlab.us, boolean reserved=false) for appattempt_1471812677892_0003_000001
2016-08-21 14:55:03,457 INFO org.apache.hadoop.yarn.server.resourcemanager.scheduler.fair.FSAppAttempt: assignContainer(FSSchedulerNode node:cp-1.yarn-perf.yarnrm-PG0.wisc.cloudlab.us, boolean reserved=false) for appattempt_1471812677892_0006_000001
2016-08-21 14:55:03,458 INFO org.apache.hadoop.yarn.server.resourcemanager.scheduler.fair.FSAppAttempt: assignContainer(FSSchedulerNode node:cp-1.yarn-perf.yarnrm-PG0.wisc.cloudlab.us, boolean reserved=false) for appattempt_1471812677892_0007_000001
2016-08-21 14:55:03,546 INFO org.apache.hadoop.yarn.server.resourcemanager.scheduler.fair.FSAppAttempt: assignContainer(FSSchedulerNode node:c220g1-031106.wisc.cloudlab.us, boolean reserved=false) for appattempt_1471812677892_0004_000001
2016-08-21 14:55:03,546 INFO org.apache.hadoop.yarn.server.resourcemanager.scheduler.fair.FSAppAttempt: assignContainer(FSSchedulerNode node:c220g1-031106.wisc.cloudlab.us, boolean reserved=false) for appattempt_1471812677892_0005_000001
2016-08-21 14:55:03,546 INFO org.apache.hadoop.yarn.server.resourcemanager.scheduler.fair.FSAppAttempt: assignContainer(FSSchedulerNode node:c220g1-031106.wisc.cloudlab.us, boolean reserved=false) for appattempt_1471812677892_0003_000001
2016-08-21 14:55:03,546 INFO org.apache.hadoop.yarn.server.resourcemanager.scheduler.fair.FSAppAttempt: assignContainer(FSSchedulerNode node:c220g1-031106.wisc.cloudlab.us, boolean reserved=false) for appattempt_1471812677892_0006_000001
2016-08-21 14:55:03,547 INFO org.apache.hadoop.yarn.server.resourcemanager.scheduler.fair.FSAppAttempt: assignContainer(FSSchedulerNode node:c220g1-031106.wisc.cloudlab.us, boolean reserved=false) for appattempt_1471812677892_0007_000001
2016-08-21 14:55:03,689 INFO org.apache.hadoop.yarn.server.resourcemanager.rmapp.attempt.RMAppAttemptImpl: ScheduleTransition.transition(appattempt_1471812677892_0004_000001,EventType: ATTEMPT_ADDED)
2016-08-21 14:55:03,689 INFO org.apache.hadoop.yarn.server.resourcemanager.scheduler.fair.FairScheduler: allocate(appattempt_1471812677892_0004_000001 [{Priority: 0, Capability: <memory:2048, vCores:1>, # Containers: 1, Location: *, Relax Locality: true}] [] null null
2016-08-21 14:55:03,689 INFO org.apache.hadoop.yarn.server.resourcemanager.scheduler.fair.FSAppAttempt: root.interactive1: <memory:2048, vCores:1>
2016-08-21 14:55:03,689 INFO org.apache.hadoop.yarn.server.resourcemanager.scheduler.fair.FSAppAttempt: root.interactive2: <memory:2048, vCores:1>
2016-08-21 14:55:03,689 INFO org.apache.hadoop.yarn.server.resourcemanager.scheduler.fair.FSAppAttempt: appattempt_1471812677892_0004_000001 minReqResource: <memory:16384, vCores:8> flexibleResource: <memory:0, vCores:0>
2016-08-21 14:55:03,689 INFO org.apache.hadoop.yarn.server.resourcemanager.scheduler.fair.FairScheduler: Cannot allocate appattempt_1471812677892_0004_000001 because there is NO flexible resource left
2016-08-21 14:55:04,457 INFO org.apache.hadoop.yarn.server.resourcemanager.scheduler.fair.FSAppAttempt: assignContainer(FSSchedulerNode node:cp-1.yarn-perf.yarnrm-PG0.wisc.cloudlab.us, boolean reserved=false) for appattempt_1471812677892_0004_000001
2016-08-21 14:55:04,457 INFO org.apache.hadoop.yarn.server.resourcemanager.scheduler.fair.FSAppAttempt: assignContainer(FSSchedulerNode node:cp-1.yarn-perf.yarnrm-PG0.wisc.cloudlab.us, boolean reserved=false) for appattempt_1471812677892_0005_000001
2016-08-21 14:55:04,457 INFO org.apache.hadoop.yarn.server.resourcemanager.scheduler.fair.FSAppAttempt: assignContainer(FSSchedulerNode node:cp-1.yarn-perf.yarnrm-PG0.wisc.cloudlab.us, boolean reserved=false) for appattempt_1471812677892_0003_000001
2016-08-21 14:55:04,458 INFO org.apache.hadoop.yarn.server.resourcemanager.scheduler.fair.FSAppAttempt: assignContainer(FSSchedulerNode node:cp-1.yarn-perf.yarnrm-PG0.wisc.cloudlab.us, boolean reserved=false) for appattempt_1471812677892_0006_000001
2016-08-21 14:55:04,565 INFO org.apache.hadoop.yarn.server.resourcemanager.scheduler.fair.FSAppAttempt: assignContainer(FSSchedulerNode node:cp-1.yarn-perf.yarnrm-PG0.wisc.cloudlab.us, boolean reserved=false) for appattempt_1471812677892_0007_000001
2016-08-21 14:55:04,565 INFO org.apache.hadoop.yarn.server.resourcemanager.scheduler.fair.FSAppAttempt: assignContainer(FSSchedulerNode node:c220g1-031106.wisc.cloudlab.us, boolean reserved=false) for appattempt_1471812677892_0004_000001
2016-08-21 14:55:04,565 INFO org.apache.hadoop.yarn.server.resourcemanager.scheduler.fair.FSAppAttempt: assignContainer(FSSchedulerNode node:c220g1-031106.wisc.cloudlab.us, boolean reserved=false) for appattempt_1471812677892_0005_000001
2016-08-21 14:55:04,565 INFO org.apache.hadoop.yarn.server.resourcemanager.scheduler.fair.FSAppAttempt: assignContainer(FSSchedulerNode node:c220g1-031106.wisc.cloudlab.us, boolean reserved=false) for appattempt_1471812677892_0003_000001
2016-08-21 14:55:04,565 INFO org.apache.hadoop.yarn.server.resourcemanager.scheduler.fair.FSAppAttempt: assignContainer(FSSchedulerNode node:c220g1-031106.wisc.cloudlab.us, boolean reserved=false) for appattempt_1471812677892_0006_000001
2016-08-21 14:55:04,565 INFO org.apache.hadoop.yarn.server.resourcemanager.scheduler.fair.FSAppAttempt: assignContainer(FSSchedulerNode node:c220g1-031106.wisc.cloudlab.us, boolean reserved=false) for appattempt_1471812677892_0007_000001
2016-08-21 14:55:04,690 INFO org.apache.hadoop.yarn.server.resourcemanager.rmapp.attempt.RMAppAttemptImpl: ScheduleTransition.transition(appattempt_1471812677892_0004_000001,EventType: ATTEMPT_ADDED)
2016-08-21 14:55:04,690 INFO org.apache.hadoop.yarn.server.resourcemanager.scheduler.fair.FairScheduler: allocate(appattempt_1471812677892_0004_000001 [{Priority: 0, Capability: <memory:2048, vCores:1>, # Containers: 1, Location: *, Relax Locality: true}] [] null null
2016-08-21 14:55:04,690 INFO org.apache.hadoop.yarn.server.resourcemanager.scheduler.fair.FSAppAttempt: root.interactive1: <memory:2048, vCores:1>
2016-08-21 14:55:04,690 INFO org.apache.hadoop.yarn.server.resourcemanager.scheduler.fair.FSAppAttempt: root.interactive2: <memory:2048, vCores:1>
2016-08-21 14:55:04,691 INFO org.apache.hadoop.yarn.server.resourcemanager.scheduler.fair.FSAppAttempt: appattempt_1471812677892_0004_000001 minReqResource: <memory:16384, vCores:8> flexibleResource: <memory:0, vCores:0>
2016-08-21 14:55:04,691 INFO org.apache.hadoop.yarn.server.resourcemanager.scheduler.fair.FairScheduler: Cannot allocate appattempt_1471812677892_0004_000001 because there is NO flexible resource left
2016-08-21 14:55:05,460 INFO org.apache.hadoop.yarn.server.resourcemanager.scheduler.fair.FSAppAttempt: assignContainer(FSSchedulerNode node:cp-1.yarn-perf.yarnrm-PG0.wisc.cloudlab.us, boolean reserved=false) for appattempt_1471812677892_0004_000001
2016-08-21 14:55:05,460 INFO org.apache.hadoop.yarn.server.resourcemanager.scheduler.fair.FSAppAttempt: assignContainer(FSSchedulerNode node:cp-1.yarn-perf.yarnrm-PG0.wisc.cloudlab.us, boolean reserved=false) for appattempt_1471812677892_0005_000001
2016-08-21 14:55:05,460 INFO org.apache.hadoop.yarn.server.resourcemanager.scheduler.fair.FSAppAttempt: assignContainer(FSSchedulerNode node:cp-1.yarn-perf.yarnrm-PG0.wisc.cloudlab.us, boolean reserved=false) for appattempt_1471812677892_0003_000001
2016-08-21 14:55:05,460 INFO org.apache.hadoop.yarn.server.resourcemanager.scheduler.fair.FSAppAttempt: assignContainer(FSSchedulerNode node:cp-1.yarn-perf.yarnrm-PG0.wisc.cloudlab.us, boolean reserved=false) for appattempt_1471812677892_0006_000001
2016-08-21 14:55:05,460 INFO org.apache.hadoop.yarn.server.resourcemanager.scheduler.fair.FSAppAttempt: assignContainer(FSSchedulerNode node:cp-1.yarn-perf.yarnrm-PG0.wisc.cloudlab.us, boolean reserved=false) for appattempt_1471812677892_0007_000001
2016-08-21 14:55:05,553 INFO org.apache.hadoop.yarn.server.resourcemanager.scheduler.fair.FSAppAttempt: assignContainer(FSSchedulerNode node:c220g1-031106.wisc.cloudlab.us, boolean reserved=false) for appattempt_1471812677892_0004_000001
2016-08-21 14:55:05,553 INFO org.apache.hadoop.yarn.server.resourcemanager.scheduler.fair.FSAppAttempt: assignContainer(FSSchedulerNode node:c220g1-031106.wisc.cloudlab.us, boolean reserved=false) for appattempt_1471812677892_0005_000001
2016-08-21 14:55:05,553 INFO org.apache.hadoop.yarn.server.resourcemanager.scheduler.fair.FSAppAttempt: assignContainer(FSSchedulerNode node:c220g1-031106.wisc.cloudlab.us, boolean reserved=false) for appattempt_1471812677892_0003_000001
2016-08-21 14:55:05,553 INFO org.apache.hadoop.yarn.server.resourcemanager.scheduler.fair.FSAppAttempt: assignContainer(FSSchedulerNode node:c220g1-031106.wisc.cloudlab.us, boolean reserved=false) for appattempt_1471812677892_0006_000001
2016-08-21 14:55:05,553 INFO org.apache.hadoop.yarn.server.resourcemanager.scheduler.fair.FSAppAttempt: assignContainer(FSSchedulerNode node:c220g1-031106.wisc.cloudlab.us, boolean reserved=false) for appattempt_1471812677892_0007_000001
2016-08-21 14:55:05,692 INFO org.apache.hadoop.yarn.server.resourcemanager.rmapp.attempt.RMAppAttemptImpl: ScheduleTransition.transition(appattempt_1471812677892_0004_000001,EventType: ATTEMPT_ADDED)
2016-08-21 14:55:05,692 INFO org.apache.hadoop.yarn.server.resourcemanager.scheduler.fair.FairScheduler: allocate(appattempt_1471812677892_0004_000001 [{Priority: 0, Capability: <memory:2048, vCores:1>, # Containers: 1, Location: *, Relax Locality: true}] [] null null
2016-08-21 14:55:05,692 INFO org.apache.hadoop.yarn.server.resourcemanager.scheduler.fair.FSAppAttempt: root.interactive1: <memory:2048, vCores:1>
2016-08-21 14:55:05,692 INFO org.apache.hadoop.yarn.server.resourcemanager.scheduler.fair.FSAppAttempt: root.interactive2: <memory:2048, vCores:1>
2016-08-21 14:55:05,692 INFO org.apache.hadoop.yarn.server.resourcemanager.scheduler.fair.FSAppAttempt: appattempt_1471812677892_0004_000001 minReqResource: <memory:16384, vCores:8> flexibleResource: <memory:0, vCores:0>
2016-08-21 14:55:05,692 INFO org.apache.hadoop.yarn.server.resourcemanager.scheduler.fair.FairScheduler: Cannot allocate appattempt_1471812677892_0004_000001 because there is NO flexible resource left
2016-08-21 14:55:06,462 INFO org.apache.hadoop.yarn.server.resourcemanager.scheduler.fair.FSAppAttempt: assignContainer(FSSchedulerNode node:cp-1.yarn-perf.yarnrm-PG0.wisc.cloudlab.us, boolean reserved=false) for appattempt_1471812677892_0004_000001
2016-08-21 14:55:06,462 INFO org.apache.hadoop.yarn.server.resourcemanager.scheduler.fair.FSAppAttempt: assignContainer(FSSchedulerNode node:cp-1.yarn-perf.yarnrm-PG0.wisc.cloudlab.us, boolean reserved=false) for appattempt_1471812677892_0005_000001
2016-08-21 14:55:06,463 INFO org.apache.hadoop.yarn.server.resourcemanager.scheduler.fair.FSAppAttempt: assignContainer(FSSchedulerNode node:cp-1.yarn-perf.yarnrm-PG0.wisc.cloudlab.us, boolean reserved=false) for appattempt_1471812677892_0003_000001
2016-08-21 14:55:06,463 INFO org.apache.hadoop.yarn.server.resourcemanager.scheduler.fair.FSAppAttempt: assignContainer(FSSchedulerNode node:cp-1.yarn-perf.yarnrm-PG0.wisc.cloudlab.us, boolean reserved=false) for appattempt_1471812677892_0006_000001
2016-08-21 14:55:06,463 INFO org.apache.hadoop.yarn.server.resourcemanager.scheduler.fair.FSAppAttempt: assignContainer(FSSchedulerNode node:cp-1.yarn-perf.yarnrm-PG0.wisc.cloudlab.us, boolean reserved=false) for appattempt_1471812677892_0007_000001
2016-08-21 14:55:06,555 INFO org.apache.hadoop.yarn.server.resourcemanager.scheduler.fair.FSAppAttempt: assignContainer(FSSchedulerNode node:c220g1-031106.wisc.cloudlab.us, boolean reserved=false) for appattempt_1471812677892_0004_000001
2016-08-21 14:55:06,555 INFO org.apache.hadoop.yarn.server.resourcemanager.scheduler.fair.FSAppAttempt: assignContainer(FSSchedulerNode node:c220g1-031106.wisc.cloudlab.us, boolean reserved=false) for appattempt_1471812677892_0005_000001
2016-08-21 14:55:06,555 INFO org.apache.hadoop.yarn.server.resourcemanager.scheduler.fair.FSAppAttempt: assignContainer(FSSchedulerNode node:c220g1-031106.wisc.cloudlab.us, boolean reserved=false) for appattempt_1471812677892_0003_000001
2016-08-21 14:55:06,555 INFO org.apache.hadoop.yarn.server.resourcemanager.scheduler.fair.FSAppAttempt: assignContainer(FSSchedulerNode node:c220g1-031106.wisc.cloudlab.us, boolean reserved=false) for appattempt_1471812677892_0006_000001
2016-08-21 14:55:06,555 INFO org.apache.hadoop.yarn.server.resourcemanager.scheduler.fair.FSAppAttempt: assignContainer(FSSchedulerNode node:c220g1-031106.wisc.cloudlab.us, boolean reserved=false) for appattempt_1471812677892_0007_000001
2016-08-21 14:55:06,693 INFO org.apache.hadoop.yarn.server.resourcemanager.rmapp.attempt.RMAppAttemptImpl: ScheduleTransition.transition(appattempt_1471812677892_0004_000001,EventType: ATTEMPT_ADDED)
2016-08-21 14:55:06,693 INFO org.apache.hadoop.yarn.server.resourcemanager.scheduler.fair.FairScheduler: allocate(appattempt_1471812677892_0004_000001 [{Priority: 0, Capability: <memory:2048, vCores:1>, # Containers: 1, Location: *, Relax Locality: true}] [] null null
2016-08-21 14:55:06,694 INFO org.apache.hadoop.yarn.server.resourcemanager.scheduler.fair.FSAppAttempt: root.interactive1: <memory:2048, vCores:1>
2016-08-21 14:55:06,694 INFO org.apache.hadoop.yarn.server.resourcemanager.scheduler.fair.FSAppAttempt: root.interactive2: <memory:2048, vCores:1>
2016-08-21 14:55:06,694 INFO org.apache.hadoop.yarn.server.resourcemanager.scheduler.fair.FSAppAttempt: appattempt_1471812677892_0004_000001 minReqResource: <memory:16384, vCores:8> flexibleResource: <memory:0, vCores:0>
2016-08-21 14:55:06,694 INFO org.apache.hadoop.yarn.server.resourcemanager.scheduler.fair.FairScheduler: Cannot allocate appattempt_1471812677892_0004_000001 because there is NO flexible resource left
2016-08-21 14:55:07,466 INFO org.apache.hadoop.yarn.server.resourcemanager.scheduler.fair.FSAppAttempt: assignContainer(FSSchedulerNode node:cp-1.yarn-perf.yarnrm-PG0.wisc.cloudlab.us, boolean reserved=false) for appattempt_1471812677892_0004_000001
2016-08-21 14:55:07,466 INFO org.apache.hadoop.yarn.server.resourcemanager.scheduler.fair.FSAppAttempt: assignContainer(FSSchedulerNode node:cp-1.yarn-perf.yarnrm-PG0.wisc.cloudlab.us, boolean reserved=false) for appattempt_1471812677892_0005_000001
2016-08-21 14:55:07,466 INFO org.apache.hadoop.yarn.server.resourcemanager.scheduler.fair.FSAppAttempt: assignContainer(FSSchedulerNode node:cp-1.yarn-perf.yarnrm-PG0.wisc.cloudlab.us, boolean reserved=false) for appattempt_1471812677892_0003_000001
2016-08-21 14:55:07,466 INFO org.apache.hadoop.yarn.server.resourcemanager.scheduler.fair.FSAppAttempt: assignContainer(FSSchedulerNode node:cp-1.yarn-perf.yarnrm-PG0.wisc.cloudlab.us, boolean reserved=false) for appattempt_1471812677892_0006_000001
2016-08-21 14:55:07,467 INFO org.apache.hadoop.yarn.server.resourcemanager.scheduler.fair.FSAppAttempt: assignContainer(FSSchedulerNode node:cp-1.yarn-perf.yarnrm-PG0.wisc.cloudlab.us, boolean reserved=false) for appattempt_1471812677892_0007_000001
2016-08-21 14:55:07,558 INFO org.apache.hadoop.yarn.server.resourcemanager.scheduler.fair.FSAppAttempt: assignContainer(FSSchedulerNode node:c220g1-031106.wisc.cloudlab.us, boolean reserved=false) for appattempt_1471812677892_0004_000001
2016-08-21 14:55:07,558 INFO org.apache.hadoop.yarn.server.resourcemanager.scheduler.fair.FSAppAttempt: assignContainer(FSSchedulerNode node:c220g1-031106.wisc.cloudlab.us, boolean reserved=false) for appattempt_1471812677892_0005_000001
2016-08-21 14:55:07,558 INFO org.apache.hadoop.yarn.server.resourcemanager.scheduler.fair.FSAppAttempt: assignContainer(FSSchedulerNode node:c220g1-031106.wisc.cloudlab.us, boolean reserved=false) for appattempt_1471812677892_0003_000001
2016-08-21 14:55:07,558 INFO org.apache.hadoop.yarn.server.resourcemanager.scheduler.fair.FSAppAttempt: assignContainer(FSSchedulerNode node:c220g1-031106.wisc.cloudlab.us, boolean reserved=false) for appattempt_1471812677892_0006_000001
2016-08-21 14:55:07,558 INFO org.apache.hadoop.yarn.server.resourcemanager.scheduler.fair.FSAppAttempt: assignContainer(FSSchedulerNode node:c220g1-031106.wisc.cloudlab.us, boolean reserved=false) for appattempt_1471812677892_0007_000001
2016-08-21 14:55:07,695 INFO org.apache.hadoop.yarn.server.resourcemanager.rmapp.attempt.RMAppAttemptImpl: ScheduleTransition.transition(appattempt_1471812677892_0004_000001,EventType: ATTEMPT_ADDED)
2016-08-21 14:55:07,695 INFO org.apache.hadoop.yarn.server.resourcemanager.scheduler.fair.FairScheduler: allocate(appattempt_1471812677892_0004_000001 [{Priority: 0, Capability: <memory:2048, vCores:1>, # Containers: 1, Location: *, Relax Locality: true}] [] null null
2016-08-21 14:55:07,695 INFO org.apache.hadoop.yarn.server.resourcemanager.scheduler.fair.FSAppAttempt: root.interactive1: <memory:2048, vCores:1>
2016-08-21 14:55:07,695 INFO org.apache.hadoop.yarn.server.resourcemanager.scheduler.fair.FSAppAttempt: root.interactive2: <memory:2048, vCores:1>
2016-08-21 14:55:07,695 INFO org.apache.hadoop.yarn.server.resourcemanager.scheduler.fair.FSAppAttempt: appattempt_1471812677892_0004_000001 minReqResource: <memory:16384, vCores:8> flexibleResource: <memory:0, vCores:0>
2016-08-21 14:55:07,695 INFO org.apache.hadoop.yarn.server.resourcemanager.scheduler.fair.FairScheduler: Cannot allocate appattempt_1471812677892_0004_000001 because there is NO flexible resource left
2016-08-21 14:55:08,347 INFO SecurityLogger.org.apache.hadoop.ipc.Server: Auth successful for appattempt_1471812677892_0005_000001 (auth:SIMPLE)
2016-08-21 14:55:08,351 INFO org.apache.hadoop.yarn.server.resourcemanager.ApplicationMasterService: AM registration appattempt_1471812677892_0005_000001
2016-08-21 14:55:08,351 INFO org.apache.hadoop.yarn.server.resourcemanager.RMAuditLogger: USER=tanle	IP=128.104.222.17	OPERATION=Register App Master	TARGET=ApplicationMasterService	RESULT=SUCCESS	APPID=application_1471812677892_0005	APPATTEMPTID=appattempt_1471812677892_0005_000001
2016-08-21 14:55:08,351 INFO org.apache.hadoop.yarn.server.resourcemanager.rmapp.attempt.RMAppAttemptImpl: appattempt_1471812677892_0005_000001 State change from LAUNCHED to RUNNING
2016-08-21 14:55:08,416 INFO org.apache.hadoop.yarn.server.resourcemanager.scheduler.fair.FairScheduler: allocate(appattempt_1471812677892_0005_000001 [] [] [] []
2016-08-21 14:55:08,416 INFO org.apache.hadoop.yarn.server.resourcemanager.scheduler.fair.FSAppAttempt: root.interactive1: <memory:2048, vCores:1>
2016-08-21 14:55:08,416 INFO org.apache.hadoop.yarn.server.resourcemanager.scheduler.fair.FSAppAttempt: root.interactive2: <memory:2048, vCores:1>
2016-08-21 14:55:08,416 INFO org.apache.hadoop.yarn.server.resourcemanager.scheduler.fair.FSAppAttempt: appattempt_1471812677892_0005_000001 minReqResource: <memory:16384, vCores:8> flexibleResource: <memory:0, vCores:0>
2016-08-21 14:55:08,416 INFO org.apache.hadoop.yarn.server.resourcemanager.scheduler.fair.FairScheduler: allocate resource to application attempt: appattempt_1471812677892_0005_000001 queue:root.interactive2 isRunning=true 
2016-08-21 14:55:08,416 INFO org.apache.hadoop.yarn.server.resourcemanager.scheduler.fair.FairScheduler: iglf: 5.getHeadroom()=<memory:6144, vCores:3>
2016-08-21 14:55:08,442 INFO org.apache.hadoop.yarn.server.resourcemanager.scheduler.fair.FairScheduler: allocate(appattempt_1471812677892_0005_000001 [] [] [] []
2016-08-21 14:55:08,443 INFO org.apache.hadoop.yarn.server.resourcemanager.scheduler.fair.FSAppAttempt: root.interactive1: <memory:2048, vCores:1>
2016-08-21 14:55:08,443 INFO org.apache.hadoop.yarn.server.resourcemanager.scheduler.fair.FSAppAttempt: root.interactive2: <memory:2048, vCores:1>
2016-08-21 14:55:08,443 INFO org.apache.hadoop.yarn.server.resourcemanager.scheduler.fair.FSAppAttempt: appattempt_1471812677892_0005_000001 minReqResource: <memory:16384, vCores:8> flexibleResource: <memory:0, vCores:0>
2016-08-21 14:55:08,443 INFO org.apache.hadoop.yarn.server.resourcemanager.scheduler.fair.FairScheduler: allocate resource to application attempt: appattempt_1471812677892_0005_000001 queue:root.interactive2 isRunning=true 
2016-08-21 14:55:08,443 INFO org.apache.hadoop.yarn.server.resourcemanager.scheduler.fair.FairScheduler: iglf: 5.getHeadroom()=<memory:6144, vCores:3>
2016-08-21 14:55:08,469 INFO org.apache.hadoop.yarn.server.resourcemanager.scheduler.fair.FSAppAttempt: assignContainer(FSSchedulerNode node:cp-1.yarn-perf.yarnrm-PG0.wisc.cloudlab.us, boolean reserved=false) for appattempt_1471812677892_0004_000001
2016-08-21 14:55:08,469 INFO org.apache.hadoop.yarn.server.resourcemanager.scheduler.fair.FSAppAttempt: assignContainer(FSSchedulerNode node:cp-1.yarn-perf.yarnrm-PG0.wisc.cloudlab.us, boolean reserved=false) for appattempt_1471812677892_0005_000001
2016-08-21 14:55:08,469 INFO org.apache.hadoop.yarn.server.resourcemanager.scheduler.fair.FSAppAttempt: assignContainer(FSSchedulerNode node:cp-1.yarn-perf.yarnrm-PG0.wisc.cloudlab.us, boolean reserved=false) for appattempt_1471812677892_0003_000001
2016-08-21 14:55:08,469 INFO org.apache.hadoop.yarn.server.resourcemanager.scheduler.fair.FSAppAttempt: assignContainer(FSSchedulerNode node:cp-1.yarn-perf.yarnrm-PG0.wisc.cloudlab.us, boolean reserved=false) for appattempt_1471812677892_0006_000001
2016-08-21 14:55:08,469 INFO org.apache.hadoop.yarn.server.resourcemanager.scheduler.fair.FSAppAttempt: assignContainer(FSSchedulerNode node:cp-1.yarn-perf.yarnrm-PG0.wisc.cloudlab.us, boolean reserved=false) for appattempt_1471812677892_0007_000001
2016-08-21 14:55:08,560 INFO org.apache.hadoop.yarn.server.resourcemanager.scheduler.fair.FSAppAttempt: assignContainer(FSSchedulerNode node:c220g1-031106.wisc.cloudlab.us, boolean reserved=false) for appattempt_1471812677892_0004_000001
2016-08-21 14:55:08,560 INFO org.apache.hadoop.yarn.server.resourcemanager.scheduler.fair.FSAppAttempt: assignContainer(FSSchedulerNode node:c220g1-031106.wisc.cloudlab.us, boolean reserved=false) for appattempt_1471812677892_0005_000001
2016-08-21 14:55:08,560 INFO org.apache.hadoop.yarn.server.resourcemanager.scheduler.fair.FSAppAttempt: assignContainer(FSSchedulerNode node:c220g1-031106.wisc.cloudlab.us, boolean reserved=false) for appattempt_1471812677892_0003_000001
2016-08-21 14:55:08,560 INFO org.apache.hadoop.yarn.server.resourcemanager.scheduler.fair.FSAppAttempt: assignContainer(FSSchedulerNode node:c220g1-031106.wisc.cloudlab.us, boolean reserved=false) for appattempt_1471812677892_0006_000001
2016-08-21 14:55:08,561 INFO org.apache.hadoop.yarn.server.resourcemanager.scheduler.fair.FSAppAttempt: assignContainer(FSSchedulerNode node:c220g1-031106.wisc.cloudlab.us, boolean reserved=false) for appattempt_1471812677892_0007_000001
2016-08-21 14:55:08,696 INFO org.apache.hadoop.yarn.server.resourcemanager.rmapp.attempt.RMAppAttemptImpl: ScheduleTransition.transition(appattempt_1471812677892_0004_000001,EventType: ATTEMPT_ADDED)
2016-08-21 14:55:08,696 INFO org.apache.hadoop.yarn.server.resourcemanager.scheduler.fair.FairScheduler: allocate(appattempt_1471812677892_0004_000001 [{Priority: 0, Capability: <memory:2048, vCores:1>, # Containers: 1, Location: *, Relax Locality: true}] [] null null
2016-08-21 14:55:08,696 INFO org.apache.hadoop.yarn.server.resourcemanager.scheduler.fair.FSAppAttempt: root.interactive1: <memory:2048, vCores:1>
2016-08-21 14:55:08,696 INFO org.apache.hadoop.yarn.server.resourcemanager.scheduler.fair.FSAppAttempt: root.interactive2: <memory:2048, vCores:1>
2016-08-21 14:55:08,696 INFO org.apache.hadoop.yarn.server.resourcemanager.scheduler.fair.FSAppAttempt: appattempt_1471812677892_0004_000001 minReqResource: <memory:16384, vCores:8> flexibleResource: <memory:0, vCores:0>
2016-08-21 14:55:08,696 INFO org.apache.hadoop.yarn.server.resourcemanager.scheduler.fair.FairScheduler: Cannot allocate appattempt_1471812677892_0004_000001 because there is NO flexible resource left
2016-08-21 14:55:09,471 INFO org.apache.hadoop.yarn.server.resourcemanager.scheduler.fair.FSAppAttempt: assignContainer(FSSchedulerNode node:cp-1.yarn-perf.yarnrm-PG0.wisc.cloudlab.us, boolean reserved=false) for appattempt_1471812677892_0004_000001
2016-08-21 14:55:09,472 INFO org.apache.hadoop.yarn.server.resourcemanager.scheduler.fair.FSAppAttempt: assignContainer(FSSchedulerNode node:cp-1.yarn-perf.yarnrm-PG0.wisc.cloudlab.us, boolean reserved=false) for appattempt_1471812677892_0005_000001
2016-08-21 14:55:09,485 INFO org.apache.hadoop.yarn.server.resourcemanager.scheduler.fair.FSAppAttempt: assignContainer(FSSchedulerNode node:cp-1.yarn-perf.yarnrm-PG0.wisc.cloudlab.us, boolean reserved=false) for appattempt_1471812677892_0003_000001
2016-08-21 14:55:09,485 INFO org.apache.hadoop.yarn.server.resourcemanager.scheduler.fair.FSAppAttempt: assignContainer(FSSchedulerNode node:cp-1.yarn-perf.yarnrm-PG0.wisc.cloudlab.us, boolean reserved=false) for appattempt_1471812677892_0006_000001
2016-08-21 14:55:09,485 INFO org.apache.hadoop.yarn.server.resourcemanager.scheduler.fair.FSAppAttempt: assignContainer(FSSchedulerNode node:cp-1.yarn-perf.yarnrm-PG0.wisc.cloudlab.us, boolean reserved=false) for appattempt_1471812677892_0007_000001
2016-08-21 14:55:09,562 INFO org.apache.hadoop.yarn.server.resourcemanager.scheduler.fair.FSAppAttempt: assignContainer(FSSchedulerNode node:c220g1-031106.wisc.cloudlab.us, boolean reserved=false) for appattempt_1471812677892_0004_000001
2016-08-21 14:55:09,563 INFO org.apache.hadoop.yarn.server.resourcemanager.scheduler.fair.FSAppAttempt: assignContainer(FSSchedulerNode node:c220g1-031106.wisc.cloudlab.us, boolean reserved=false) for appattempt_1471812677892_0005_000001
2016-08-21 14:55:09,563 INFO org.apache.hadoop.yarn.server.resourcemanager.scheduler.fair.FSAppAttempt: assignContainer(FSSchedulerNode node:c220g1-031106.wisc.cloudlab.us, boolean reserved=false) for appattempt_1471812677892_0003_000001
2016-08-21 14:55:09,563 INFO org.apache.hadoop.yarn.server.resourcemanager.scheduler.fair.FSAppAttempt: assignContainer(FSSchedulerNode node:c220g1-031106.wisc.cloudlab.us, boolean reserved=false) for appattempt_1471812677892_0006_000001
2016-08-21 14:55:09,563 INFO org.apache.hadoop.yarn.server.resourcemanager.scheduler.fair.FSAppAttempt: assignContainer(FSSchedulerNode node:c220g1-031106.wisc.cloudlab.us, boolean reserved=false) for appattempt_1471812677892_0007_000001
2016-08-21 14:55:09,698 INFO org.apache.hadoop.yarn.server.resourcemanager.rmapp.attempt.RMAppAttemptImpl: ScheduleTransition.transition(appattempt_1471812677892_0004_000001,EventType: ATTEMPT_ADDED)
2016-08-21 14:55:09,698 INFO org.apache.hadoop.yarn.server.resourcemanager.scheduler.fair.FairScheduler: allocate(appattempt_1471812677892_0004_000001 [{Priority: 0, Capability: <memory:2048, vCores:1>, # Containers: 1, Location: *, Relax Locality: true}] [] null null
2016-08-21 14:55:09,698 INFO org.apache.hadoop.yarn.server.resourcemanager.scheduler.fair.FSAppAttempt: root.interactive1: <memory:2048, vCores:1>
2016-08-21 14:55:09,698 INFO org.apache.hadoop.yarn.server.resourcemanager.scheduler.fair.FSAppAttempt: root.interactive2: <memory:2048, vCores:1>
2016-08-21 14:55:09,698 INFO org.apache.hadoop.yarn.server.resourcemanager.scheduler.fair.FSAppAttempt: appattempt_1471812677892_0004_000001 minReqResource: <memory:16384, vCores:8> flexibleResource: <memory:0, vCores:0>
2016-08-21 14:55:09,698 INFO org.apache.hadoop.yarn.server.resourcemanager.scheduler.fair.FairScheduler: Cannot allocate appattempt_1471812677892_0004_000001 because there is NO flexible resource left
2016-08-21 14:55:10,474 INFO org.apache.hadoop.yarn.server.resourcemanager.scheduler.fair.FSAppAttempt: assignContainer(FSSchedulerNode node:cp-1.yarn-perf.yarnrm-PG0.wisc.cloudlab.us, boolean reserved=false) for appattempt_1471812677892_0004_000001
2016-08-21 14:55:10,474 INFO org.apache.hadoop.yarn.server.resourcemanager.scheduler.fair.FSAppAttempt: assignContainer(FSSchedulerNode node:cp-1.yarn-perf.yarnrm-PG0.wisc.cloudlab.us, boolean reserved=false) for appattempt_1471812677892_0005_000001
2016-08-21 14:55:10,474 INFO org.apache.hadoop.yarn.server.resourcemanager.scheduler.fair.FSAppAttempt: assignContainer(FSSchedulerNode node:cp-1.yarn-perf.yarnrm-PG0.wisc.cloudlab.us, boolean reserved=false) for appattempt_1471812677892_0003_000001
2016-08-21 14:55:10,474 INFO org.apache.hadoop.yarn.server.resourcemanager.scheduler.fair.FSAppAttempt: assignContainer(FSSchedulerNode node:cp-1.yarn-perf.yarnrm-PG0.wisc.cloudlab.us, boolean reserved=false) for appattempt_1471812677892_0006_000001
2016-08-21 14:55:10,474 INFO org.apache.hadoop.yarn.server.resourcemanager.scheduler.fair.FSAppAttempt: assignContainer(FSSchedulerNode node:cp-1.yarn-perf.yarnrm-PG0.wisc.cloudlab.us, boolean reserved=false) for appattempt_1471812677892_0007_000001
2016-08-21 14:55:10,565 INFO org.apache.hadoop.yarn.server.resourcemanager.scheduler.fair.FSAppAttempt: assignContainer(FSSchedulerNode node:c220g1-031106.wisc.cloudlab.us, boolean reserved=false) for appattempt_1471812677892_0004_000001
2016-08-21 14:55:10,565 INFO org.apache.hadoop.yarn.server.resourcemanager.scheduler.fair.FSAppAttempt: assignContainer(FSSchedulerNode node:c220g1-031106.wisc.cloudlab.us, boolean reserved=false) for appattempt_1471812677892_0005_000001
2016-08-21 14:55:10,565 INFO org.apache.hadoop.yarn.server.resourcemanager.scheduler.fair.FSAppAttempt: assignContainer(FSSchedulerNode node:c220g1-031106.wisc.cloudlab.us, boolean reserved=false) for appattempt_1471812677892_0003_000001
2016-08-21 14:55:10,565 INFO org.apache.hadoop.yarn.server.resourcemanager.scheduler.fair.FSAppAttempt: assignContainer(FSSchedulerNode node:c220g1-031106.wisc.cloudlab.us, boolean reserved=false) for appattempt_1471812677892_0006_000001
2016-08-21 14:55:10,565 INFO org.apache.hadoop.yarn.server.resourcemanager.scheduler.fair.FSAppAttempt: assignContainer(FSSchedulerNode node:c220g1-031106.wisc.cloudlab.us, boolean reserved=false) for appattempt_1471812677892_0007_000001
2016-08-21 14:55:10,700 INFO org.apache.hadoop.yarn.server.resourcemanager.rmapp.attempt.RMAppAttemptImpl: ScheduleTransition.transition(appattempt_1471812677892_0004_000001,EventType: ATTEMPT_ADDED)
2016-08-21 14:55:10,700 INFO org.apache.hadoop.yarn.server.resourcemanager.scheduler.fair.FairScheduler: allocate(appattempt_1471812677892_0004_000001 [{Priority: 0, Capability: <memory:2048, vCores:1>, # Containers: 1, Location: *, Relax Locality: true}] [] null null
2016-08-21 14:55:10,700 INFO org.apache.hadoop.yarn.server.resourcemanager.scheduler.fair.FSAppAttempt: root.interactive1: <memory:2048, vCores:1>
2016-08-21 14:55:10,700 INFO org.apache.hadoop.yarn.server.resourcemanager.scheduler.fair.FSAppAttempt: root.interactive2: <memory:2048, vCores:1>
2016-08-21 14:55:10,700 INFO org.apache.hadoop.yarn.server.resourcemanager.scheduler.fair.FSAppAttempt: appattempt_1471812677892_0004_000001 minReqResource: <memory:16384, vCores:8> flexibleResource: <memory:0, vCores:0>
2016-08-21 14:55:10,700 INFO org.apache.hadoop.yarn.server.resourcemanager.scheduler.fair.FairScheduler: Cannot allocate appattempt_1471812677892_0004_000001 because there is NO flexible resource left
2016-08-21 14:55:11,447 INFO org.apache.hadoop.yarn.server.resourcemanager.scheduler.fair.FairScheduler: allocate(appattempt_1471812677892_0005_000001 [] [] [] []
2016-08-21 14:55:11,447 INFO org.apache.hadoop.yarn.server.resourcemanager.scheduler.fair.FSAppAttempt: root.interactive1: <memory:2048, vCores:1>
2016-08-21 14:55:11,447 INFO org.apache.hadoop.yarn.server.resourcemanager.scheduler.fair.FSAppAttempt: root.interactive2: <memory:2048, vCores:1>
2016-08-21 14:55:11,447 INFO org.apache.hadoop.yarn.server.resourcemanager.scheduler.fair.FSAppAttempt: appattempt_1471812677892_0005_000001 minReqResource: <memory:16384, vCores:8> flexibleResource: <memory:0, vCores:0>
2016-08-21 14:55:11,447 INFO org.apache.hadoop.yarn.server.resourcemanager.scheduler.fair.FairScheduler: allocate resource to application attempt: appattempt_1471812677892_0005_000001 queue:root.interactive2 isRunning=true 
2016-08-21 14:55:11,447 INFO org.apache.hadoop.yarn.server.resourcemanager.scheduler.fair.FairScheduler: iglf: 5.getHeadroom()=<memory:6144, vCores:3>
2016-08-21 14:55:11,477 INFO org.apache.hadoop.yarn.server.resourcemanager.scheduler.fair.FSAppAttempt: assignContainer(FSSchedulerNode node:cp-1.yarn-perf.yarnrm-PG0.wisc.cloudlab.us, boolean reserved=false) for appattempt_1471812677892_0004_000001
2016-08-21 14:55:11,477 INFO org.apache.hadoop.yarn.server.resourcemanager.scheduler.fair.FSAppAttempt: assignContainer(FSSchedulerNode node:cp-1.yarn-perf.yarnrm-PG0.wisc.cloudlab.us, boolean reserved=false) for appattempt_1471812677892_0005_000001
2016-08-21 14:55:11,477 INFO org.apache.hadoop.yarn.server.resourcemanager.scheduler.fair.FSAppAttempt: assignContainer(FSSchedulerNode node:cp-1.yarn-perf.yarnrm-PG0.wisc.cloudlab.us, boolean reserved=false) for appattempt_1471812677892_0003_000001
2016-08-21 14:55:11,477 INFO org.apache.hadoop.yarn.server.resourcemanager.scheduler.fair.FSAppAttempt: assignContainer(FSSchedulerNode node:cp-1.yarn-perf.yarnrm-PG0.wisc.cloudlab.us, boolean reserved=false) for appattempt_1471812677892_0006_000001
2016-08-21 14:55:11,477 INFO org.apache.hadoop.yarn.server.resourcemanager.scheduler.fair.FSAppAttempt: assignContainer(FSSchedulerNode node:cp-1.yarn-perf.yarnrm-PG0.wisc.cloudlab.us, boolean reserved=false) for appattempt_1471812677892_0007_000001
2016-08-21 14:55:11,567 INFO org.apache.hadoop.yarn.server.resourcemanager.scheduler.fair.FSAppAttempt: assignContainer(FSSchedulerNode node:c220g1-031106.wisc.cloudlab.us, boolean reserved=false) for appattempt_1471812677892_0004_000001
2016-08-21 14:55:11,567 INFO org.apache.hadoop.yarn.server.resourcemanager.scheduler.fair.FSAppAttempt: assignContainer(FSSchedulerNode node:c220g1-031106.wisc.cloudlab.us, boolean reserved=false) for appattempt_1471812677892_0005_000001
2016-08-21 14:55:11,567 INFO org.apache.hadoop.yarn.server.resourcemanager.scheduler.fair.FSAppAttempt: assignContainer(FSSchedulerNode node:c220g1-031106.wisc.cloudlab.us, boolean reserved=false) for appattempt_1471812677892_0003_000001
2016-08-21 14:55:11,567 INFO org.apache.hadoop.yarn.server.resourcemanager.scheduler.fair.FSAppAttempt: assignContainer(FSSchedulerNode node:c220g1-031106.wisc.cloudlab.us, boolean reserved=false) for appattempt_1471812677892_0006_000001
2016-08-21 14:55:11,567 INFO org.apache.hadoop.yarn.server.resourcemanager.scheduler.fair.FSAppAttempt: assignContainer(FSSchedulerNode node:c220g1-031106.wisc.cloudlab.us, boolean reserved=false) for appattempt_1471812677892_0007_000001
2016-08-21 14:55:11,702 INFO org.apache.hadoop.yarn.server.resourcemanager.rmapp.attempt.RMAppAttemptImpl: ScheduleTransition.transition(appattempt_1471812677892_0004_000001,EventType: ATTEMPT_ADDED)
2016-08-21 14:55:11,702 INFO org.apache.hadoop.yarn.server.resourcemanager.scheduler.fair.FairScheduler: allocate(appattempt_1471812677892_0004_000001 [{Priority: 0, Capability: <memory:2048, vCores:1>, # Containers: 1, Location: *, Relax Locality: true}] [] null null
2016-08-21 14:55:11,702 INFO org.apache.hadoop.yarn.server.resourcemanager.scheduler.fair.FSAppAttempt: root.interactive1: <memory:2048, vCores:1>
2016-08-21 14:55:11,702 INFO org.apache.hadoop.yarn.server.resourcemanager.scheduler.fair.FSAppAttempt: root.interactive2: <memory:2048, vCores:1>
2016-08-21 14:55:11,702 INFO org.apache.hadoop.yarn.server.resourcemanager.scheduler.fair.FSAppAttempt: appattempt_1471812677892_0004_000001 minReqResource: <memory:16384, vCores:8> flexibleResource: <memory:0, vCores:0>
2016-08-21 14:55:11,702 INFO org.apache.hadoop.yarn.server.resourcemanager.scheduler.fair.FairScheduler: Cannot allocate appattempt_1471812677892_0004_000001 because there is NO flexible resource left
2016-08-21 14:55:12,480 INFO org.apache.hadoop.yarn.server.resourcemanager.scheduler.fair.FSAppAttempt: assignContainer(FSSchedulerNode node:cp-1.yarn-perf.yarnrm-PG0.wisc.cloudlab.us, boolean reserved=false) for appattempt_1471812677892_0004_000001
2016-08-21 14:55:12,480 INFO org.apache.hadoop.yarn.server.resourcemanager.scheduler.fair.FSAppAttempt: assignContainer(FSSchedulerNode node:cp-1.yarn-perf.yarnrm-PG0.wisc.cloudlab.us, boolean reserved=false) for appattempt_1471812677892_0005_000001
2016-08-21 14:55:12,480 INFO org.apache.hadoop.yarn.server.resourcemanager.scheduler.fair.FSAppAttempt: assignContainer(FSSchedulerNode node:cp-1.yarn-perf.yarnrm-PG0.wisc.cloudlab.us, boolean reserved=false) for appattempt_1471812677892_0003_000001
2016-08-21 14:55:12,480 INFO org.apache.hadoop.yarn.server.resourcemanager.scheduler.fair.FSAppAttempt: assignContainer(FSSchedulerNode node:cp-1.yarn-perf.yarnrm-PG0.wisc.cloudlab.us, boolean reserved=false) for appattempt_1471812677892_0006_000001
2016-08-21 14:55:12,480 INFO org.apache.hadoop.yarn.server.resourcemanager.scheduler.fair.FSAppAttempt: assignContainer(FSSchedulerNode node:cp-1.yarn-perf.yarnrm-PG0.wisc.cloudlab.us, boolean reserved=false) for appattempt_1471812677892_0007_000001
2016-08-21 14:55:12,570 INFO org.apache.hadoop.yarn.server.resourcemanager.scheduler.fair.FSAppAttempt: assignContainer(FSSchedulerNode node:c220g1-031106.wisc.cloudlab.us, boolean reserved=false) for appattempt_1471812677892_0004_000001
2016-08-21 14:55:12,570 INFO org.apache.hadoop.yarn.server.resourcemanager.scheduler.fair.FSAppAttempt: assignContainer(FSSchedulerNode node:c220g1-031106.wisc.cloudlab.us, boolean reserved=false) for appattempt_1471812677892_0005_000001
2016-08-21 14:55:12,570 INFO org.apache.hadoop.yarn.server.resourcemanager.scheduler.fair.FSAppAttempt: assignContainer(FSSchedulerNode node:c220g1-031106.wisc.cloudlab.us, boolean reserved=false) for appattempt_1471812677892_0003_000001
2016-08-21 14:55:12,571 INFO org.apache.hadoop.yarn.server.resourcemanager.scheduler.fair.FSAppAttempt: assignContainer(FSSchedulerNode node:c220g1-031106.wisc.cloudlab.us, boolean reserved=false) for appattempt_1471812677892_0006_000001
2016-08-21 14:55:12,571 INFO org.apache.hadoop.yarn.server.resourcemanager.scheduler.fair.FSAppAttempt: assignContainer(FSSchedulerNode node:c220g1-031106.wisc.cloudlab.us, boolean reserved=false) for appattempt_1471812677892_0007_000001
2016-08-21 14:55:12,703 INFO org.apache.hadoop.yarn.server.resourcemanager.rmapp.attempt.RMAppAttemptImpl: ScheduleTransition.transition(appattempt_1471812677892_0004_000001,EventType: ATTEMPT_ADDED)
2016-08-21 14:55:12,703 INFO org.apache.hadoop.yarn.server.resourcemanager.scheduler.fair.FairScheduler: allocate(appattempt_1471812677892_0004_000001 [{Priority: 0, Capability: <memory:2048, vCores:1>, # Containers: 1, Location: *, Relax Locality: true}] [] null null
2016-08-21 14:55:12,704 INFO org.apache.hadoop.yarn.server.resourcemanager.scheduler.fair.FSAppAttempt: root.interactive1: <memory:2048, vCores:1>
2016-08-21 14:55:12,704 INFO org.apache.hadoop.yarn.server.resourcemanager.scheduler.fair.FSAppAttempt: root.interactive2: <memory:2048, vCores:1>
2016-08-21 14:55:12,704 INFO org.apache.hadoop.yarn.server.resourcemanager.scheduler.fair.FSAppAttempt: appattempt_1471812677892_0004_000001 minReqResource: <memory:16384, vCores:8> flexibleResource: <memory:0, vCores:0>
2016-08-21 14:55:12,704 INFO org.apache.hadoop.yarn.server.resourcemanager.scheduler.fair.FairScheduler: Cannot allocate appattempt_1471812677892_0004_000001 because there is NO flexible resource left
2016-08-21 14:55:13,483 INFO org.apache.hadoop.yarn.server.resourcemanager.scheduler.fair.FSAppAttempt: assignContainer(FSSchedulerNode node:cp-1.yarn-perf.yarnrm-PG0.wisc.cloudlab.us, boolean reserved=false) for appattempt_1471812677892_0004_000001
2016-08-21 14:55:13,484 INFO org.apache.hadoop.yarn.server.resourcemanager.scheduler.fair.FSAppAttempt: assignContainer(FSSchedulerNode node:cp-1.yarn-perf.yarnrm-PG0.wisc.cloudlab.us, boolean reserved=false) for appattempt_1471812677892_0005_000001
2016-08-21 14:55:13,484 INFO org.apache.hadoop.yarn.server.resourcemanager.scheduler.fair.FSAppAttempt: assignContainer(FSSchedulerNode node:cp-1.yarn-perf.yarnrm-PG0.wisc.cloudlab.us, boolean reserved=false) for appattempt_1471812677892_0003_000001
2016-08-21 14:55:13,484 INFO org.apache.hadoop.yarn.server.resourcemanager.scheduler.fair.FSAppAttempt: assignContainer(FSSchedulerNode node:cp-1.yarn-perf.yarnrm-PG0.wisc.cloudlab.us, boolean reserved=false) for appattempt_1471812677892_0006_000001
2016-08-21 14:55:13,484 INFO org.apache.hadoop.yarn.server.resourcemanager.scheduler.fair.FSAppAttempt: assignContainer(FSSchedulerNode node:cp-1.yarn-perf.yarnrm-PG0.wisc.cloudlab.us, boolean reserved=false) for appattempt_1471812677892_0007_000001
2016-08-21 14:55:13,573 INFO org.apache.hadoop.yarn.server.resourcemanager.scheduler.fair.FSAppAttempt: assignContainer(FSSchedulerNode node:c220g1-031106.wisc.cloudlab.us, boolean reserved=false) for appattempt_1471812677892_0004_000001
2016-08-21 14:55:13,573 INFO org.apache.hadoop.yarn.server.resourcemanager.scheduler.fair.FSAppAttempt: assignContainer(FSSchedulerNode node:c220g1-031106.wisc.cloudlab.us, boolean reserved=false) for appattempt_1471812677892_0005_000001
2016-08-21 14:55:13,573 INFO org.apache.hadoop.yarn.server.resourcemanager.scheduler.fair.FSAppAttempt: assignContainer(FSSchedulerNode node:c220g1-031106.wisc.cloudlab.us, boolean reserved=false) for appattempt_1471812677892_0003_000001
2016-08-21 14:55:13,573 INFO org.apache.hadoop.yarn.server.resourcemanager.scheduler.fair.FSAppAttempt: assignContainer(FSSchedulerNode node:c220g1-031106.wisc.cloudlab.us, boolean reserved=false) for appattempt_1471812677892_0006_000001
2016-08-21 14:55:13,573 INFO org.apache.hadoop.yarn.server.resourcemanager.scheduler.fair.FSAppAttempt: assignContainer(FSSchedulerNode node:c220g1-031106.wisc.cloudlab.us, boolean reserved=false) for appattempt_1471812677892_0007_000001
2016-08-21 14:55:13,705 INFO org.apache.hadoop.yarn.server.resourcemanager.rmapp.attempt.RMAppAttemptImpl: ScheduleTransition.transition(appattempt_1471812677892_0004_000001,EventType: ATTEMPT_ADDED)
2016-08-21 14:55:13,705 INFO org.apache.hadoop.yarn.server.resourcemanager.scheduler.fair.FairScheduler: allocate(appattempt_1471812677892_0004_000001 [{Priority: 0, Capability: <memory:2048, vCores:1>, # Containers: 1, Location: *, Relax Locality: true}] [] null null
2016-08-21 14:55:13,706 INFO org.apache.hadoop.yarn.server.resourcemanager.scheduler.fair.FSAppAttempt: root.interactive1: <memory:2048, vCores:1>
2016-08-21 14:55:13,706 INFO org.apache.hadoop.yarn.server.resourcemanager.scheduler.fair.FSAppAttempt: root.interactive2: <memory:2048, vCores:1>
2016-08-21 14:55:13,706 INFO org.apache.hadoop.yarn.server.resourcemanager.scheduler.fair.FSAppAttempt: appattempt_1471812677892_0004_000001 minReqResource: <memory:16384, vCores:8> flexibleResource: <memory:0, vCores:0>
2016-08-21 14:55:13,706 INFO org.apache.hadoop.yarn.server.resourcemanager.scheduler.fair.FairScheduler: Cannot allocate appattempt_1471812677892_0004_000001 because there is NO flexible resource left
2016-08-21 14:55:14,346 INFO org.apache.hadoop.yarn.server.resourcemanager.scheduler.fair.FairScheduler: allocate(appattempt_1471812677892_0005_000001 [{Priority: 1, Capability: <memory:1920, vCores:1>, # Containers: 1, Location: *, Relax Locality: true}] [] [] []
2016-08-21 14:55:14,346 INFO org.apache.hadoop.yarn.server.resourcemanager.scheduler.fair.FSAppAttempt: root.interactive1: <memory:2048, vCores:1>
2016-08-21 14:55:14,347 INFO org.apache.hadoop.yarn.server.resourcemanager.scheduler.fair.FSAppAttempt: root.interactive2: <memory:2048, vCores:1>
2016-08-21 14:55:14,347 INFO org.apache.hadoop.yarn.server.resourcemanager.scheduler.fair.FSAppAttempt: appattempt_1471812677892_0005_000001 minReqResource: <memory:16384, vCores:8> flexibleResource: <memory:0, vCores:0>
2016-08-21 14:55:14,347 INFO org.apache.hadoop.yarn.server.resourcemanager.scheduler.fair.FairScheduler: allocate resource to application attempt: appattempt_1471812677892_0005_000001 queue:root.interactive2 isRunning=true 
2016-08-21 14:55:14,347 INFO org.apache.hadoop.yarn.server.resourcemanager.scheduler.fair.FairScheduler: iglf: 5.getHeadroom()=<memory:6144, vCores:3>
2016-08-21 14:55:14,486 INFO org.apache.hadoop.yarn.server.resourcemanager.scheduler.fair.FSAppAttempt: assignContainer(FSSchedulerNode node:cp-1.yarn-perf.yarnrm-PG0.wisc.cloudlab.us, boolean reserved=false) for appattempt_1471812677892_0004_000001
2016-08-21 14:55:14,491 INFO org.apache.hadoop.yarn.server.resourcemanager.scheduler.fair.FSAppAttempt: assignContainer(FSSchedulerNode node:cp-1.yarn-perf.yarnrm-PG0.wisc.cloudlab.us, boolean reserved=false) for appattempt_1471812677892_0005_000001
2016-08-21 14:55:14,491 INFO org.apache.hadoop.yarn.server.resourcemanager.scheduler.fair.FSAppAttempt: assignContainer(FSSchedulerNode:cp-1.yarn-perf.yarnrm-PG0.wisc.cloudlab.us, ResourceRequest request, NodeType type, boolean reserved=false
2016-08-21 14:55:14,491 INFO org.apache.hadoop.yarn.server.resourcemanager.scheduler.fair.FSAppAttempt: allocate container: container_1471812677892_0005_01_000002 priority 1
2016-08-21 14:55:14,492 INFO org.apache.hadoop.yarn.server.resourcemanager.rmcontainer.RMContainerImpl: Processing container_1471812677892_0005_01_000002 of event START
2016-08-21 14:55:14,492 INFO org.apache.hadoop.yarn.server.resourcemanager.rmcontainer.RMContainerImpl: container_1471812677892_0005_01_000002 Container Transitioned from NEW to ALLOCATED
2016-08-21 14:55:14,492 INFO org.apache.hadoop.yarn.server.resourcemanager.RMAuditLogger: USER=tanle	OPERATION=AM Allocated Container	TARGET=SchedulerApp	RESULT=SUCCESS	APPID=application_1471812677892_0005	CONTAINERID=container_1471812677892_0005_01_000002
2016-08-21 14:55:14,492 INFO org.apache.hadoop.yarn.server.resourcemanager.scheduler.SchedulerNode: Assigned container container_1471812677892_0005_01_000002 of capacity <memory:2048, vCores:1> on host cp-1.yarn-perf.yarnrm-PG0.wisc.cloudlab.us:39022, which has 2 containers, <memory:4096, vCores:2> used and <memory:4096, vCores:2> available after allocation
2016-08-21 14:55:14,551 INFO org.apache.hadoop.yarn.server.resourcemanager.scheduler.fair.FairScheduler: allocate(appattempt_1471812677892_0005_000001 [] [] [] []
2016-08-21 14:55:14,551 INFO org.apache.hadoop.yarn.server.resourcemanager.scheduler.fair.FSAppAttempt: root.interactive1: <memory:2048, vCores:1>
2016-08-21 14:55:14,551 INFO org.apache.hadoop.yarn.server.resourcemanager.scheduler.fair.FSAppAttempt: root.interactive2: <memory:4096, vCores:2>
2016-08-21 14:55:14,551 INFO org.apache.hadoop.yarn.server.resourcemanager.scheduler.fair.FSAppAttempt: appattempt_1471812677892_0005_000001 minReqResource: <memory:16384, vCores:8> flexibleResource: <memory:0, vCores:0>
2016-08-21 14:55:14,551 INFO org.apache.hadoop.yarn.server.resourcemanager.scheduler.fair.FairScheduler: allocate resource to application attempt: appattempt_1471812677892_0005_000001 queue:root.interactive2 isRunning=true 
2016-08-21 14:55:14,554 INFO org.apache.hadoop.yarn.server.resourcemanager.security.NMTokenSecretManagerInRM: Sending NMToken for nodeId : cp-1.yarn-perf.yarnrm-PG0.wisc.cloudlab.us:39022 for container : container_1471812677892_0005_01_000002
2016-08-21 14:55:14,555 INFO org.apache.hadoop.yarn.server.resourcemanager.rmcontainer.RMContainerImpl: Processing container_1471812677892_0005_01_000002 of event ACQUIRED
2016-08-21 14:55:14,556 INFO org.apache.hadoop.yarn.server.resourcemanager.rmcontainer.RMContainerImpl: container_1471812677892_0005_01_000002 Container Transitioned from ALLOCATED to ACQUIRED
2016-08-21 14:55:14,556 INFO org.apache.hadoop.yarn.server.resourcemanager.scheduler.fair.FairScheduler: iglf: 5.getHeadroom()=<memory:4096, vCores:2>
2016-08-21 14:55:14,575 INFO org.apache.hadoop.yarn.server.resourcemanager.scheduler.fair.FSAppAttempt: assignContainer(FSSchedulerNode node:c220g1-031106.wisc.cloudlab.us, boolean reserved=false) for appattempt_1471812677892_0004_000001
2016-08-21 14:55:14,575 INFO org.apache.hadoop.yarn.server.resourcemanager.scheduler.fair.FSAppAttempt: assignContainer(FSSchedulerNode node:c220g1-031106.wisc.cloudlab.us, boolean reserved=false) for appattempt_1471812677892_0003_000001
2016-08-21 14:55:14,575 INFO org.apache.hadoop.yarn.server.resourcemanager.scheduler.fair.FSAppAttempt: assignContainer(FSSchedulerNode node:c220g1-031106.wisc.cloudlab.us, boolean reserved=false) for appattempt_1471812677892_0005_000001
2016-08-21 14:55:14,576 INFO org.apache.hadoop.yarn.server.resourcemanager.scheduler.fair.FSAppAttempt: assignContainer(FSSchedulerNode node:c220g1-031106.wisc.cloudlab.us, boolean reserved=false) for appattempt_1471812677892_0006_000001
2016-08-21 14:55:14,576 INFO org.apache.hadoop.yarn.server.resourcemanager.scheduler.fair.FSAppAttempt: assignContainer(FSSchedulerNode node:c220g1-031106.wisc.cloudlab.us, boolean reserved=false) for appattempt_1471812677892_0007_000001
2016-08-21 14:55:14,707 INFO org.apache.hadoop.yarn.server.resourcemanager.rmapp.attempt.RMAppAttemptImpl: ScheduleTransition.transition(appattempt_1471812677892_0004_000001,EventType: ATTEMPT_ADDED)
2016-08-21 14:55:14,707 INFO org.apache.hadoop.yarn.server.resourcemanager.scheduler.fair.FairScheduler: allocate(appattempt_1471812677892_0004_000001 [{Priority: 0, Capability: <memory:2048, vCores:1>, # Containers: 1, Location: *, Relax Locality: true}] [] null null
2016-08-21 14:55:14,707 INFO org.apache.hadoop.yarn.server.resourcemanager.scheduler.fair.FSAppAttempt: root.interactive1: <memory:2048, vCores:1>
2016-08-21 14:55:14,707 INFO org.apache.hadoop.yarn.server.resourcemanager.scheduler.fair.FSAppAttempt: root.interactive2: <memory:4096, vCores:2>
2016-08-21 14:55:14,707 INFO org.apache.hadoop.yarn.server.resourcemanager.scheduler.fair.FSAppAttempt: appattempt_1471812677892_0004_000001 minReqResource: <memory:16384, vCores:8> flexibleResource: <memory:0, vCores:0>
2016-08-21 14:55:14,707 INFO org.apache.hadoop.yarn.server.resourcemanager.scheduler.fair.FairScheduler: Cannot allocate appattempt_1471812677892_0004_000001 because there is NO flexible resource left
2016-08-21 14:55:15,490 INFO org.apache.hadoop.yarn.server.resourcemanager.rmcontainer.RMContainerImpl: Processing container_1471812677892_0005_01_000002 of event LAUNCHED
2016-08-21 14:55:15,490 INFO org.apache.hadoop.yarn.server.resourcemanager.rmcontainer.RMContainerImpl: container_1471812677892_0005_01_000002 Container Transitioned from ACQUIRED to RUNNING
2016-08-21 14:55:15,490 INFO org.apache.hadoop.yarn.server.resourcemanager.scheduler.fair.FSAppAttempt: assignContainer(FSSchedulerNode node:cp-1.yarn-perf.yarnrm-PG0.wisc.cloudlab.us, boolean reserved=false) for appattempt_1471812677892_0004_000001
2016-08-21 14:55:15,491 INFO org.apache.hadoop.yarn.server.resourcemanager.scheduler.fair.FSAppAttempt: assignContainer(FSSchedulerNode node:cp-1.yarn-perf.yarnrm-PG0.wisc.cloudlab.us, boolean reserved=false) for appattempt_1471812677892_0003_000001
2016-08-21 14:55:15,491 INFO org.apache.hadoop.yarn.server.resourcemanager.scheduler.fair.FSAppAttempt: assignContainer(FSSchedulerNode node:cp-1.yarn-perf.yarnrm-PG0.wisc.cloudlab.us, boolean reserved=false) for appattempt_1471812677892_0005_000001
2016-08-21 14:55:15,491 INFO org.apache.hadoop.yarn.server.resourcemanager.scheduler.fair.FSAppAttempt: assignContainer(FSSchedulerNode node:cp-1.yarn-perf.yarnrm-PG0.wisc.cloudlab.us, boolean reserved=false) for appattempt_1471812677892_0006_000001
2016-08-21 14:55:15,491 INFO org.apache.hadoop.yarn.server.resourcemanager.scheduler.fair.FSAppAttempt: assignContainer(FSSchedulerNode node:cp-1.yarn-perf.yarnrm-PG0.wisc.cloudlab.us, boolean reserved=false) for appattempt_1471812677892_0007_000001
2016-08-21 14:55:15,577 INFO org.apache.hadoop.yarn.server.resourcemanager.scheduler.fair.FSAppAttempt: assignContainer(FSSchedulerNode node:c220g1-031106.wisc.cloudlab.us, boolean reserved=false) for appattempt_1471812677892_0004_000001
2016-08-21 14:55:15,577 INFO org.apache.hadoop.yarn.server.resourcemanager.scheduler.fair.FSAppAttempt: assignContainer(FSSchedulerNode node:c220g1-031106.wisc.cloudlab.us, boolean reserved=false) for appattempt_1471812677892_0003_000001
2016-08-21 14:55:15,578 INFO org.apache.hadoop.yarn.server.resourcemanager.scheduler.fair.FSAppAttempt: assignContainer(FSSchedulerNode node:c220g1-031106.wisc.cloudlab.us, boolean reserved=false) for appattempt_1471812677892_0005_000001
2016-08-21 14:55:15,578 INFO org.apache.hadoop.yarn.server.resourcemanager.scheduler.fair.FSAppAttempt: assignContainer(FSSchedulerNode node:c220g1-031106.wisc.cloudlab.us, boolean reserved=false) for appattempt_1471812677892_0006_000001
2016-08-21 14:55:15,578 INFO org.apache.hadoop.yarn.server.resourcemanager.scheduler.fair.FSAppAttempt: assignContainer(FSSchedulerNode node:c220g1-031106.wisc.cloudlab.us, boolean reserved=false) for appattempt_1471812677892_0007_000001
2016-08-21 14:55:15,708 INFO org.apache.hadoop.yarn.server.resourcemanager.rmapp.attempt.RMAppAttemptImpl: ScheduleTransition.transition(appattempt_1471812677892_0004_000001,EventType: ATTEMPT_ADDED)
2016-08-21 14:55:15,708 INFO org.apache.hadoop.yarn.server.resourcemanager.scheduler.fair.FairScheduler: allocate(appattempt_1471812677892_0004_000001 [{Priority: 0, Capability: <memory:2048, vCores:1>, # Containers: 1, Location: *, Relax Locality: true}] [] null null
2016-08-21 14:55:15,709 INFO org.apache.hadoop.yarn.server.resourcemanager.scheduler.fair.FSAppAttempt: root.interactive1: <memory:2048, vCores:1>
2016-08-21 14:55:15,709 INFO org.apache.hadoop.yarn.server.resourcemanager.scheduler.fair.FSAppAttempt: root.interactive2: <memory:4096, vCores:2>
2016-08-21 14:55:15,709 INFO org.apache.hadoop.yarn.server.resourcemanager.scheduler.fair.FSAppAttempt: appattempt_1471812677892_0004_000001 minReqResource: <memory:16384, vCores:8> flexibleResource: <memory:0, vCores:0>
2016-08-21 14:55:15,709 INFO org.apache.hadoop.yarn.server.resourcemanager.scheduler.fair.FairScheduler: Cannot allocate appattempt_1471812677892_0004_000001 because there is NO flexible resource left
2016-08-21 14:55:16,492 INFO org.apache.hadoop.yarn.server.resourcemanager.scheduler.fair.FSAppAttempt: assignContainer(FSSchedulerNode node:cp-1.yarn-perf.yarnrm-PG0.wisc.cloudlab.us, boolean reserved=false) for appattempt_1471812677892_0004_000001
2016-08-21 14:55:16,493 INFO org.apache.hadoop.yarn.server.resourcemanager.scheduler.fair.FSAppAttempt: assignContainer(FSSchedulerNode node:cp-1.yarn-perf.yarnrm-PG0.wisc.cloudlab.us, boolean reserved=false) for appattempt_1471812677892_0003_000001
2016-08-21 14:55:16,493 INFO org.apache.hadoop.yarn.server.resourcemanager.scheduler.fair.FSAppAttempt: assignContainer(FSSchedulerNode node:cp-1.yarn-perf.yarnrm-PG0.wisc.cloudlab.us, boolean reserved=false) for appattempt_1471812677892_0005_000001
2016-08-21 14:55:16,493 INFO org.apache.hadoop.yarn.server.resourcemanager.scheduler.fair.FSAppAttempt: assignContainer(FSSchedulerNode node:cp-1.yarn-perf.yarnrm-PG0.wisc.cloudlab.us, boolean reserved=false) for appattempt_1471812677892_0006_000001
2016-08-21 14:55:16,493 INFO org.apache.hadoop.yarn.server.resourcemanager.scheduler.fair.FSAppAttempt: assignContainer(FSSchedulerNode node:cp-1.yarn-perf.yarnrm-PG0.wisc.cloudlab.us, boolean reserved=false) for appattempt_1471812677892_0007_000001
2016-08-21 14:55:16,581 INFO org.apache.hadoop.yarn.server.resourcemanager.scheduler.fair.FSAppAttempt: assignContainer(FSSchedulerNode node:c220g1-031106.wisc.cloudlab.us, boolean reserved=false) for appattempt_1471812677892_0004_000001
2016-08-21 14:55:16,581 INFO org.apache.hadoop.yarn.server.resourcemanager.scheduler.fair.FSAppAttempt: assignContainer(FSSchedulerNode node:c220g1-031106.wisc.cloudlab.us, boolean reserved=false) for appattempt_1471812677892_0003_000001
2016-08-21 14:55:16,581 INFO org.apache.hadoop.yarn.server.resourcemanager.scheduler.fair.FSAppAttempt: assignContainer(FSSchedulerNode node:c220g1-031106.wisc.cloudlab.us, boolean reserved=false) for appattempt_1471812677892_0005_000001
2016-08-21 14:55:16,581 INFO org.apache.hadoop.yarn.server.resourcemanager.scheduler.fair.FSAppAttempt: assignContainer(FSSchedulerNode node:c220g1-031106.wisc.cloudlab.us, boolean reserved=false) for appattempt_1471812677892_0006_000001
2016-08-21 14:55:16,581 INFO org.apache.hadoop.yarn.server.resourcemanager.scheduler.fair.FSAppAttempt: assignContainer(FSSchedulerNode node:c220g1-031106.wisc.cloudlab.us, boolean reserved=false) for appattempt_1471812677892_0007_000001
2016-08-21 14:55:16,710 INFO org.apache.hadoop.yarn.server.resourcemanager.rmapp.attempt.RMAppAttemptImpl: ScheduleTransition.transition(appattempt_1471812677892_0004_000001,EventType: ATTEMPT_ADDED)
2016-08-21 14:55:16,710 INFO org.apache.hadoop.yarn.server.resourcemanager.scheduler.fair.FairScheduler: allocate(appattempt_1471812677892_0004_000001 [{Priority: 0, Capability: <memory:2048, vCores:1>, # Containers: 1, Location: *, Relax Locality: true}] [] null null
2016-08-21 14:55:16,710 INFO org.apache.hadoop.yarn.server.resourcemanager.scheduler.fair.FSAppAttempt: root.interactive1: <memory:2048, vCores:1>
2016-08-21 14:55:16,711 INFO org.apache.hadoop.yarn.server.resourcemanager.scheduler.fair.FSAppAttempt: root.interactive2: <memory:4096, vCores:2>
2016-08-21 14:55:16,711 INFO org.apache.hadoop.yarn.server.resourcemanager.scheduler.fair.FSAppAttempt: appattempt_1471812677892_0004_000001 minReqResource: <memory:16384, vCores:8> flexibleResource: <memory:0, vCores:0>
2016-08-21 14:55:16,711 INFO org.apache.hadoop.yarn.server.resourcemanager.scheduler.fair.FairScheduler: Cannot allocate appattempt_1471812677892_0004_000001 because there is NO flexible resource left
2016-08-21 14:55:16,736 INFO SecurityLogger.org.apache.hadoop.ipc.Server: Auth successful for appattempt_1471812677892_0003_000001 (auth:SIMPLE)
2016-08-21 14:55:16,739 INFO org.apache.hadoop.yarn.server.resourcemanager.ApplicationMasterService: AM registration appattempt_1471812677892_0003_000001
2016-08-21 14:55:16,740 INFO org.apache.hadoop.yarn.server.resourcemanager.RMAuditLogger: USER=tanle	IP=128.104.222.16	OPERATION=Register App Master	TARGET=ApplicationMasterService	RESULT=SUCCESS	APPID=application_1471812677892_0003	APPATTEMPTID=appattempt_1471812677892_0003_000001
2016-08-21 14:55:16,740 INFO org.apache.hadoop.yarn.server.resourcemanager.rmapp.attempt.RMAppAttemptImpl: appattempt_1471812677892_0003_000001 State change from LAUNCHED to RUNNING
2016-08-21 14:55:16,804 INFO org.apache.hadoop.yarn.server.resourcemanager.scheduler.fair.FairScheduler: allocate(appattempt_1471812677892_0003_000001 [] [] [] []
2016-08-21 14:55:16,804 INFO org.apache.hadoop.yarn.server.resourcemanager.scheduler.fair.FSAppAttempt: root.interactive1: <memory:2048, vCores:1>
2016-08-21 14:55:16,804 INFO org.apache.hadoop.yarn.server.resourcemanager.scheduler.fair.FSAppAttempt: root.interactive2: <memory:4096, vCores:2>
2016-08-21 14:55:16,804 INFO org.apache.hadoop.yarn.server.resourcemanager.scheduler.fair.FSAppAttempt: appattempt_1471812677892_0003_000001 minReqResource: <memory:16384, vCores:8> flexibleResource: <memory:0, vCores:0>
2016-08-21 14:55:16,804 INFO org.apache.hadoop.yarn.server.resourcemanager.scheduler.fair.FairScheduler: allocate resource to application attempt: appattempt_1471812677892_0003_000001 queue:root.interactive1 isRunning=true 
2016-08-21 14:55:16,804 INFO org.apache.hadoop.yarn.server.resourcemanager.scheduler.fair.FairScheduler: iglf: 3.getHeadroom()=<memory:6144, vCores:3>
2016-08-21 14:55:16,834 INFO org.apache.hadoop.yarn.server.resourcemanager.scheduler.fair.FairScheduler: allocate(appattempt_1471812677892_0003_000001 [] [] [] []
2016-08-21 14:55:16,834 INFO org.apache.hadoop.yarn.server.resourcemanager.scheduler.fair.FSAppAttempt: root.interactive1: <memory:2048, vCores:1>
2016-08-21 14:55:16,834 INFO org.apache.hadoop.yarn.server.resourcemanager.scheduler.fair.FSAppAttempt: root.interactive2: <memory:4096, vCores:2>
2016-08-21 14:55:16,834 INFO org.apache.hadoop.yarn.server.resourcemanager.scheduler.fair.FSAppAttempt: appattempt_1471812677892_0003_000001 minReqResource: <memory:16384, vCores:8> flexibleResource: <memory:0, vCores:0>
2016-08-21 14:55:16,834 INFO org.apache.hadoop.yarn.server.resourcemanager.scheduler.fair.FairScheduler: allocate resource to application attempt: appattempt_1471812677892_0003_000001 queue:root.interactive1 isRunning=true 
2016-08-21 14:55:16,834 INFO org.apache.hadoop.yarn.server.resourcemanager.scheduler.fair.FairScheduler: iglf: 3.getHeadroom()=<memory:6144, vCores:3>
2016-08-21 14:55:17,495 INFO org.apache.hadoop.yarn.server.resourcemanager.scheduler.fair.FSAppAttempt: assignContainer(FSSchedulerNode node:cp-1.yarn-perf.yarnrm-PG0.wisc.cloudlab.us, boolean reserved=false) for appattempt_1471812677892_0004_000001
2016-08-21 14:55:17,495 INFO org.apache.hadoop.yarn.server.resourcemanager.scheduler.fair.FSAppAttempt: assignContainer(FSSchedulerNode node:cp-1.yarn-perf.yarnrm-PG0.wisc.cloudlab.us, boolean reserved=false) for appattempt_1471812677892_0003_000001
2016-08-21 14:55:17,495 INFO org.apache.hadoop.yarn.server.resourcemanager.scheduler.fair.FSAppAttempt: assignContainer(FSSchedulerNode node:cp-1.yarn-perf.yarnrm-PG0.wisc.cloudlab.us, boolean reserved=false) for appattempt_1471812677892_0005_000001
2016-08-21 14:55:17,496 INFO org.apache.hadoop.yarn.server.resourcemanager.scheduler.fair.FSAppAttempt: assignContainer(FSSchedulerNode node:cp-1.yarn-perf.yarnrm-PG0.wisc.cloudlab.us, boolean reserved=false) for appattempt_1471812677892_0006_000001
2016-08-21 14:55:17,496 INFO org.apache.hadoop.yarn.server.resourcemanager.scheduler.fair.FSAppAttempt: assignContainer(FSSchedulerNode node:cp-1.yarn-perf.yarnrm-PG0.wisc.cloudlab.us, boolean reserved=false) for appattempt_1471812677892_0007_000001
2016-08-21 14:55:17,583 INFO org.apache.hadoop.yarn.server.resourcemanager.scheduler.fair.FSAppAttempt: assignContainer(FSSchedulerNode node:c220g1-031106.wisc.cloudlab.us, boolean reserved=false) for appattempt_1471812677892_0004_000001
2016-08-21 14:55:17,583 INFO org.apache.hadoop.yarn.server.resourcemanager.scheduler.fair.FSAppAttempt: assignContainer(FSSchedulerNode node:c220g1-031106.wisc.cloudlab.us, boolean reserved=false) for appattempt_1471812677892_0003_000001
2016-08-21 14:55:17,583 INFO org.apache.hadoop.yarn.server.resourcemanager.scheduler.fair.FSAppAttempt: assignContainer(FSSchedulerNode node:c220g1-031106.wisc.cloudlab.us, boolean reserved=false) for appattempt_1471812677892_0005_000001
2016-08-21 14:55:17,583 INFO org.apache.hadoop.yarn.server.resourcemanager.scheduler.fair.FSAppAttempt: assignContainer(FSSchedulerNode node:c220g1-031106.wisc.cloudlab.us, boolean reserved=false) for appattempt_1471812677892_0006_000001
2016-08-21 14:55:17,583 INFO org.apache.hadoop.yarn.server.resourcemanager.scheduler.fair.FSAppAttempt: assignContainer(FSSchedulerNode node:c220g1-031106.wisc.cloudlab.us, boolean reserved=false) for appattempt_1471812677892_0007_000001
2016-08-21 14:55:17,588 INFO org.apache.hadoop.yarn.server.resourcemanager.scheduler.fair.FairScheduler: allocate(appattempt_1471812677892_0005_000001 [{Priority: 1, Capability: <memory:1920, vCores:1>, # Containers: 0, Location: *, Relax Locality: true}] [] [] []
2016-08-21 14:55:17,588 INFO org.apache.hadoop.yarn.server.resourcemanager.scheduler.fair.FSAppAttempt: root.interactive1: <memory:2048, vCores:1>
2016-08-21 14:55:17,588 INFO org.apache.hadoop.yarn.server.resourcemanager.scheduler.fair.FSAppAttempt: root.interactive2: <memory:4096, vCores:2>
2016-08-21 14:55:17,588 INFO org.apache.hadoop.yarn.server.resourcemanager.scheduler.fair.FSAppAttempt: appattempt_1471812677892_0005_000001 minReqResource: <memory:16384, vCores:8> flexibleResource: <memory:0, vCores:0>
2016-08-21 14:55:17,588 INFO org.apache.hadoop.yarn.server.resourcemanager.scheduler.fair.FairScheduler: allocate resource to application attempt: appattempt_1471812677892_0005_000001 queue:root.interactive2 isRunning=true 
2016-08-21 14:55:17,588 INFO org.apache.hadoop.yarn.server.resourcemanager.scheduler.AppSchedulingInfo: checking for deactivate of application :application_1471812677892_0005
2016-08-21 14:55:17,588 INFO org.apache.hadoop.yarn.server.resourcemanager.scheduler.fair.FairScheduler: iglf: 5.getHeadroom()=<memory:4096, vCores:2>
2016-08-21 14:55:17,712 INFO org.apache.hadoop.yarn.server.resourcemanager.rmapp.attempt.RMAppAttemptImpl: ScheduleTransition.transition(appattempt_1471812677892_0004_000001,EventType: ATTEMPT_ADDED)
2016-08-21 14:55:17,712 INFO org.apache.hadoop.yarn.server.resourcemanager.scheduler.fair.FairScheduler: allocate(appattempt_1471812677892_0004_000001 [{Priority: 0, Capability: <memory:2048, vCores:1>, # Containers: 1, Location: *, Relax Locality: true}] [] null null
2016-08-21 14:55:17,712 INFO org.apache.hadoop.yarn.server.resourcemanager.scheduler.fair.FSAppAttempt: root.interactive1: <memory:2048, vCores:1>
2016-08-21 14:55:17,712 INFO org.apache.hadoop.yarn.server.resourcemanager.scheduler.fair.FSAppAttempt: root.interactive2: <memory:4096, vCores:2>
2016-08-21 14:55:17,712 INFO org.apache.hadoop.yarn.server.resourcemanager.scheduler.fair.FSAppAttempt: appattempt_1471812677892_0004_000001 minReqResource: <memory:16384, vCores:8> flexibleResource: <memory:0, vCores:0>
2016-08-21 14:55:17,712 INFO org.apache.hadoop.yarn.server.resourcemanager.scheduler.fair.FairScheduler: Cannot allocate appattempt_1471812677892_0004_000001 because there is NO flexible resource left
2016-08-21 14:55:18,498 INFO org.apache.hadoop.yarn.server.resourcemanager.scheduler.fair.FSAppAttempt: assignContainer(FSSchedulerNode node:cp-1.yarn-perf.yarnrm-PG0.wisc.cloudlab.us, boolean reserved=false) for appattempt_1471812677892_0004_000001
2016-08-21 14:55:18,498 INFO org.apache.hadoop.yarn.server.resourcemanager.scheduler.fair.FSAppAttempt: assignContainer(FSSchedulerNode node:cp-1.yarn-perf.yarnrm-PG0.wisc.cloudlab.us, boolean reserved=false) for appattempt_1471812677892_0003_000001
2016-08-21 14:55:18,499 INFO org.apache.hadoop.yarn.server.resourcemanager.scheduler.fair.FSAppAttempt: assignContainer(FSSchedulerNode node:cp-1.yarn-perf.yarnrm-PG0.wisc.cloudlab.us, boolean reserved=false) for appattempt_1471812677892_0005_000001
2016-08-21 14:55:18,499 INFO org.apache.hadoop.yarn.server.resourcemanager.scheduler.fair.FSAppAttempt: assignContainer(FSSchedulerNode node:cp-1.yarn-perf.yarnrm-PG0.wisc.cloudlab.us, boolean reserved=false) for appattempt_1471812677892_0006_000001
2016-08-21 14:55:18,499 INFO org.apache.hadoop.yarn.server.resourcemanager.scheduler.fair.FSAppAttempt: assignContainer(FSSchedulerNode node:cp-1.yarn-perf.yarnrm-PG0.wisc.cloudlab.us, boolean reserved=false) for appattempt_1471812677892_0007_000001
2016-08-21 14:55:18,586 INFO org.apache.hadoop.yarn.server.resourcemanager.scheduler.fair.FSAppAttempt: assignContainer(FSSchedulerNode node:c220g1-031106.wisc.cloudlab.us, boolean reserved=false) for appattempt_1471812677892_0004_000001
2016-08-21 14:55:18,587 INFO org.apache.hadoop.yarn.server.resourcemanager.scheduler.fair.FSAppAttempt: assignContainer(FSSchedulerNode node:c220g1-031106.wisc.cloudlab.us, boolean reserved=false) for appattempt_1471812677892_0003_000001
2016-08-21 14:55:18,587 INFO org.apache.hadoop.yarn.server.resourcemanager.scheduler.fair.FSAppAttempt: assignContainer(FSSchedulerNode node:c220g1-031106.wisc.cloudlab.us, boolean reserved=false) for appattempt_1471812677892_0005_000001
2016-08-21 14:55:18,587 INFO org.apache.hadoop.yarn.server.resourcemanager.scheduler.fair.FSAppAttempt: assignContainer(FSSchedulerNode node:c220g1-031106.wisc.cloudlab.us, boolean reserved=false) for appattempt_1471812677892_0006_000001
2016-08-21 14:55:18,587 INFO org.apache.hadoop.yarn.server.resourcemanager.scheduler.fair.FSAppAttempt: assignContainer(FSSchedulerNode node:c220g1-031106.wisc.cloudlab.us, boolean reserved=false) for appattempt_1471812677892_0007_000001
2016-08-21 14:55:18,715 INFO org.apache.hadoop.yarn.server.resourcemanager.rmapp.attempt.RMAppAttemptImpl: ScheduleTransition.transition(appattempt_1471812677892_0004_000001,EventType: ATTEMPT_ADDED)
2016-08-21 14:55:18,715 INFO org.apache.hadoop.yarn.server.resourcemanager.scheduler.fair.FairScheduler: allocate(appattempt_1471812677892_0004_000001 [{Priority: 0, Capability: <memory:2048, vCores:1>, # Containers: 1, Location: *, Relax Locality: true}] [] null null
2016-08-21 14:55:18,715 INFO org.apache.hadoop.yarn.server.resourcemanager.scheduler.fair.FSAppAttempt: root.interactive1: <memory:2048, vCores:1>
2016-08-21 14:55:18,716 INFO org.apache.hadoop.yarn.server.resourcemanager.scheduler.fair.FSAppAttempt: root.interactive2: <memory:4096, vCores:2>
2016-08-21 14:55:18,716 INFO org.apache.hadoop.yarn.server.resourcemanager.scheduler.fair.FSAppAttempt: appattempt_1471812677892_0004_000001 minReqResource: <memory:16384, vCores:8> flexibleResource: <memory:0, vCores:0>
2016-08-21 14:55:18,716 INFO org.apache.hadoop.yarn.server.resourcemanager.scheduler.fair.FairScheduler: Cannot allocate appattempt_1471812677892_0004_000001 because there is NO flexible resource left
2016-08-21 14:55:19,295 INFO org.apache.hadoop.yarn.server.resourcemanager.scheduler.fair.FairScheduler: allocate(appattempt_1471812677892_0005_000001 [{Priority: 1, Capability: <memory:1920, vCores:1>, # Containers: 2, Location: *, Relax Locality: true}] [] [] []
2016-08-21 14:55:19,295 INFO org.apache.hadoop.yarn.server.resourcemanager.scheduler.fair.FSAppAttempt: root.interactive1: <memory:2048, vCores:1>
2016-08-21 14:55:19,295 INFO org.apache.hadoop.yarn.server.resourcemanager.scheduler.fair.FSAppAttempt: root.interactive2: <memory:4096, vCores:2>
2016-08-21 14:55:19,295 INFO org.apache.hadoop.yarn.server.resourcemanager.scheduler.fair.FSAppAttempt: appattempt_1471812677892_0005_000001 minReqResource: <memory:16384, vCores:8> flexibleResource: <memory:0, vCores:0>
2016-08-21 14:55:19,295 INFO org.apache.hadoop.yarn.server.resourcemanager.scheduler.fair.FairScheduler: allocate resource to application attempt: appattempt_1471812677892_0005_000001 queue:root.interactive2 isRunning=true 
2016-08-21 14:55:19,296 INFO org.apache.hadoop.yarn.server.resourcemanager.scheduler.fair.FairScheduler: iglf: 5.getHeadroom()=<memory:4096, vCores:2>
2016-08-21 14:55:19,499 INFO org.apache.hadoop.yarn.server.resourcemanager.scheduler.fair.FairScheduler: allocate(appattempt_1471812677892_0005_000001 [] [] [] []
2016-08-21 14:55:19,499 INFO org.apache.hadoop.yarn.server.resourcemanager.scheduler.fair.FSAppAttempt: root.interactive1: <memory:2048, vCores:1>
2016-08-21 14:55:19,499 INFO org.apache.hadoop.yarn.server.resourcemanager.scheduler.fair.FSAppAttempt: root.interactive2: <memory:4096, vCores:2>
2016-08-21 14:55:19,499 INFO org.apache.hadoop.yarn.server.resourcemanager.scheduler.fair.FSAppAttempt: appattempt_1471812677892_0005_000001 minReqResource: <memory:16384, vCores:8> flexibleResource: <memory:0, vCores:0>
2016-08-21 14:55:19,499 INFO org.apache.hadoop.yarn.server.resourcemanager.scheduler.fair.FairScheduler: allocate resource to application attempt: appattempt_1471812677892_0005_000001 queue:root.interactive2 isRunning=true 
2016-08-21 14:55:19,499 INFO org.apache.hadoop.yarn.server.resourcemanager.scheduler.fair.FairScheduler: iglf: 5.getHeadroom()=<memory:4096, vCores:2>
2016-08-21 14:55:19,501 INFO org.apache.hadoop.yarn.server.resourcemanager.scheduler.fair.FSAppAttempt: assignContainer(FSSchedulerNode node:cp-1.yarn-perf.yarnrm-PG0.wisc.cloudlab.us, boolean reserved=false) for appattempt_1471812677892_0004_000001
2016-08-21 14:55:19,501 INFO org.apache.hadoop.yarn.server.resourcemanager.scheduler.fair.FSAppAttempt: assignContainer(FSSchedulerNode node:cp-1.yarn-perf.yarnrm-PG0.wisc.cloudlab.us, boolean reserved=false) for appattempt_1471812677892_0003_000001
2016-08-21 14:55:19,501 INFO org.apache.hadoop.yarn.server.resourcemanager.scheduler.fair.FSAppAttempt: assignContainer(FSSchedulerNode node:cp-1.yarn-perf.yarnrm-PG0.wisc.cloudlab.us, boolean reserved=false) for appattempt_1471812677892_0005_000001
2016-08-21 14:55:19,502 INFO org.apache.hadoop.yarn.server.resourcemanager.scheduler.fair.FSAppAttempt: assignContainer(FSSchedulerNode:cp-1.yarn-perf.yarnrm-PG0.wisc.cloudlab.us, ResourceRequest request, NodeType type, boolean reserved=false
2016-08-21 14:55:19,502 INFO org.apache.hadoop.yarn.server.resourcemanager.scheduler.fair.FSAppAttempt: allocate container: container_1471812677892_0005_01_000003 priority 1
2016-08-21 14:55:19,502 INFO org.apache.hadoop.yarn.server.resourcemanager.rmcontainer.RMContainerImpl: Processing container_1471812677892_0005_01_000003 of event START
2016-08-21 14:55:19,502 INFO org.apache.hadoop.yarn.server.resourcemanager.rmcontainer.RMContainerImpl: container_1471812677892_0005_01_000003 Container Transitioned from NEW to ALLOCATED
2016-08-21 14:55:19,502 INFO org.apache.hadoop.yarn.server.resourcemanager.RMAuditLogger: USER=tanle	OPERATION=AM Allocated Container	TARGET=SchedulerApp	RESULT=SUCCESS	APPID=application_1471812677892_0005	CONTAINERID=container_1471812677892_0005_01_000003
2016-08-21 14:55:19,502 INFO org.apache.hadoop.yarn.server.resourcemanager.scheduler.SchedulerNode: Assigned container container_1471812677892_0005_01_000003 of capacity <memory:2048, vCores:1> on host cp-1.yarn-perf.yarnrm-PG0.wisc.cloudlab.us:39022, which has 3 containers, <memory:6144, vCores:3> used and <memory:2048, vCores:1> available after allocation
2016-08-21 14:55:19,589 INFO org.apache.hadoop.yarn.server.resourcemanager.scheduler.fair.FSAppAttempt: assignContainer(FSSchedulerNode node:c220g1-031106.wisc.cloudlab.us, boolean reserved=false) for appattempt_1471812677892_0004_000001
2016-08-21 14:55:19,590 INFO org.apache.hadoop.yarn.server.resourcemanager.scheduler.fair.FSAppAttempt: assignContainer(FSSchedulerNode node:c220g1-031106.wisc.cloudlab.us, boolean reserved=false) for appattempt_1471812677892_0003_000001
2016-08-21 14:55:19,590 INFO org.apache.hadoop.yarn.server.resourcemanager.scheduler.fair.FSAppAttempt: assignContainer(FSSchedulerNode node:c220g1-031106.wisc.cloudlab.us, boolean reserved=false) for appattempt_1471812677892_0005_000001
2016-08-21 14:55:19,590 INFO org.apache.hadoop.yarn.server.resourcemanager.scheduler.fair.FSAppAttempt: assignContainer(FSSchedulerNode:c220g1-031106.wisc.cloudlab.us, ResourceRequest request, NodeType type, boolean reserved=false
2016-08-21 14:55:19,590 INFO org.apache.hadoop.yarn.server.resourcemanager.scheduler.fair.FSAppAttempt: allocate container: container_1471812677892_0005_01_000004 priority 1
2016-08-21 14:55:19,590 INFO org.apache.hadoop.yarn.server.resourcemanager.rmcontainer.RMContainerImpl: Processing container_1471812677892_0005_01_000004 of event START
2016-08-21 14:55:19,590 INFO org.apache.hadoop.yarn.server.resourcemanager.rmcontainer.RMContainerImpl: container_1471812677892_0005_01_000004 Container Transitioned from NEW to ALLOCATED
2016-08-21 14:55:19,590 INFO org.apache.hadoop.yarn.server.resourcemanager.RMAuditLogger: USER=tanle	OPERATION=AM Allocated Container	TARGET=SchedulerApp	RESULT=SUCCESS	APPID=application_1471812677892_0005	CONTAINERID=container_1471812677892_0005_01_000004
2016-08-21 14:55:19,590 INFO org.apache.hadoop.yarn.server.resourcemanager.scheduler.SchedulerNode: Assigned container container_1471812677892_0005_01_000004 of capacity <memory:2048, vCores:1> on host c220g1-031106.wisc.cloudlab.us:33388, which has 2 containers, <memory:4096, vCores:2> used and <memory:4096, vCores:2> available after allocation
2016-08-21 14:55:19,716 INFO org.apache.hadoop.yarn.server.resourcemanager.rmapp.attempt.RMAppAttemptImpl: ScheduleTransition.transition(appattempt_1471812677892_0004_000001,EventType: ATTEMPT_ADDED)
2016-08-21 14:55:19,717 INFO org.apache.hadoop.yarn.server.resourcemanager.scheduler.fair.FairScheduler: allocate(appattempt_1471812677892_0004_000001 [{Priority: 0, Capability: <memory:2048, vCores:1>, # Containers: 1, Location: *, Relax Locality: true}] [] null null
2016-08-21 14:55:19,717 INFO org.apache.hadoop.yarn.server.resourcemanager.scheduler.fair.FSAppAttempt: root.interactive1: <memory:2048, vCores:1>
2016-08-21 14:55:19,717 INFO org.apache.hadoop.yarn.server.resourcemanager.scheduler.fair.FSAppAttempt: root.interactive2: <memory:8192, vCores:4>
2016-08-21 14:55:19,717 INFO org.apache.hadoop.yarn.server.resourcemanager.scheduler.fair.FSAppAttempt: appattempt_1471812677892_0004_000001 minReqResource: <memory:16384, vCores:8> flexibleResource: <memory:0, vCores:0>
2016-08-21 14:55:19,717 INFO org.apache.hadoop.yarn.server.resourcemanager.scheduler.fair.FairScheduler: Cannot allocate appattempt_1471812677892_0004_000001 because there is NO flexible resource left
2016-08-21 14:55:19,838 INFO org.apache.hadoop.yarn.server.resourcemanager.scheduler.fair.FairScheduler: allocate(appattempt_1471812677892_0003_000001 [] [] [] []
2016-08-21 14:55:19,838 INFO org.apache.hadoop.yarn.server.resourcemanager.scheduler.fair.FSAppAttempt: root.interactive1: <memory:2048, vCores:1>
2016-08-21 14:55:19,838 INFO org.apache.hadoop.yarn.server.resourcemanager.scheduler.fair.FSAppAttempt: root.interactive2: <memory:8192, vCores:4>
2016-08-21 14:55:19,838 INFO org.apache.hadoop.yarn.server.resourcemanager.scheduler.fair.FSAppAttempt: appattempt_1471812677892_0003_000001 minReqResource: <memory:16384, vCores:8> flexibleResource: <memory:0, vCores:0>
2016-08-21 14:55:19,838 INFO org.apache.hadoop.yarn.server.resourcemanager.scheduler.fair.FairScheduler: allocate resource to application attempt: appattempt_1471812677892_0003_000001 queue:root.interactive1 isRunning=true 
2016-08-21 14:55:19,839 INFO org.apache.hadoop.yarn.server.resourcemanager.scheduler.fair.FairScheduler: iglf: 3.getHeadroom()=<memory:6144, vCores:3>
2016-08-21 14:55:19,902 INFO org.apache.hadoop.yarn.server.resourcemanager.scheduler.fair.FairScheduler: allocate(appattempt_1471812677892_0005_000001 [] [] [] []
2016-08-21 14:55:19,902 INFO org.apache.hadoop.yarn.server.resourcemanager.scheduler.fair.FSAppAttempt: root.interactive1: <memory:2048, vCores:1>
2016-08-21 14:55:19,902 INFO org.apache.hadoop.yarn.server.resourcemanager.scheduler.fair.FSAppAttempt: root.interactive2: <memory:8192, vCores:4>
2016-08-21 14:55:19,903 INFO org.apache.hadoop.yarn.server.resourcemanager.scheduler.fair.FSAppAttempt: appattempt_1471812677892_0005_000001 minReqResource: <memory:16384, vCores:8> flexibleResource: <memory:0, vCores:0>
2016-08-21 14:55:19,903 INFO org.apache.hadoop.yarn.server.resourcemanager.scheduler.fair.FairScheduler: allocate resource to application attempt: appattempt_1471812677892_0005_000001 queue:root.interactive2 isRunning=true 
2016-08-21 14:55:19,905 INFO org.apache.hadoop.yarn.server.resourcemanager.rmcontainer.RMContainerImpl: Processing container_1471812677892_0005_01_000003 of event ACQUIRED
2016-08-21 14:55:19,906 INFO org.apache.hadoop.yarn.server.resourcemanager.rmcontainer.RMContainerImpl: container_1471812677892_0005_01_000003 Container Transitioned from ALLOCATED to ACQUIRED
2016-08-21 14:55:19,908 INFO org.apache.hadoop.yarn.server.resourcemanager.security.NMTokenSecretManagerInRM: Sending NMToken for nodeId : c220g1-031106.wisc.cloudlab.us:33388 for container : container_1471812677892_0005_01_000004
2016-08-21 14:55:19,909 INFO org.apache.hadoop.yarn.server.resourcemanager.rmcontainer.RMContainerImpl: Processing container_1471812677892_0005_01_000004 of event ACQUIRED
2016-08-21 14:55:19,909 INFO org.apache.hadoop.yarn.server.resourcemanager.rmcontainer.RMContainerImpl: container_1471812677892_0005_01_000004 Container Transitioned from ALLOCATED to ACQUIRED
2016-08-21 14:55:19,909 INFO org.apache.hadoop.yarn.server.resourcemanager.scheduler.fair.FairScheduler: iglf: 5.getHeadroom()=<memory:0, vCores:0>
2016-08-21 14:55:20,505 INFO org.apache.hadoop.yarn.server.resourcemanager.rmcontainer.RMContainerImpl: Processing container_1471812677892_0005_01_000003 of event LAUNCHED
2016-08-21 14:55:20,505 INFO org.apache.hadoop.yarn.server.resourcemanager.rmcontainer.RMContainerImpl: container_1471812677892_0005_01_000003 Container Transitioned from ACQUIRED to RUNNING
2016-08-21 14:55:20,505 INFO org.apache.hadoop.yarn.server.resourcemanager.scheduler.fair.FSAppAttempt: assignContainer(FSSchedulerNode node:cp-1.yarn-perf.yarnrm-PG0.wisc.cloudlab.us, boolean reserved=false) for appattempt_1471812677892_0004_000001
2016-08-21 14:55:20,505 INFO org.apache.hadoop.yarn.server.resourcemanager.scheduler.fair.FSAppAttempt: assignContainer(FSSchedulerNode node:cp-1.yarn-perf.yarnrm-PG0.wisc.cloudlab.us, boolean reserved=false) for appattempt_1471812677892_0003_000001
2016-08-21 14:55:20,505 INFO org.apache.hadoop.yarn.server.resourcemanager.scheduler.fair.FSAppAttempt: assignContainer(FSSchedulerNode node:cp-1.yarn-perf.yarnrm-PG0.wisc.cloudlab.us, boolean reserved=false) for appattempt_1471812677892_0006_000001
2016-08-21 14:55:20,506 INFO org.apache.hadoop.yarn.server.resourcemanager.scheduler.fair.FSAppAttempt: assignContainer(FSSchedulerNode node:cp-1.yarn-perf.yarnrm-PG0.wisc.cloudlab.us, boolean reserved=false) for appattempt_1471812677892_0007_000001
2016-08-21 14:55:20,506 INFO org.apache.hadoop.yarn.server.resourcemanager.scheduler.fair.FSAppAttempt: assignContainer(FSSchedulerNode node:cp-1.yarn-perf.yarnrm-PG0.wisc.cloudlab.us, boolean reserved=false) for appattempt_1471812677892_0005_000001
2016-08-21 14:55:20,593 INFO org.apache.hadoop.yarn.server.resourcemanager.rmcontainer.RMContainerImpl: Processing container_1471812677892_0005_01_000004 of event LAUNCHED
2016-08-21 14:55:20,594 INFO org.apache.hadoop.yarn.server.resourcemanager.rmcontainer.RMContainerImpl: container_1471812677892_0005_01_000004 Container Transitioned from ACQUIRED to RUNNING
2016-08-21 14:55:20,594 INFO org.apache.hadoop.yarn.server.resourcemanager.scheduler.fair.FSAppAttempt: assignContainer(FSSchedulerNode node:c220g1-031106.wisc.cloudlab.us, boolean reserved=false) for appattempt_1471812677892_0004_000001
2016-08-21 14:55:20,594 INFO org.apache.hadoop.yarn.server.resourcemanager.scheduler.fair.FSAppAttempt: assignContainer(FSSchedulerNode node:c220g1-031106.wisc.cloudlab.us, boolean reserved=false) for appattempt_1471812677892_0003_000001
2016-08-21 14:55:20,594 INFO org.apache.hadoop.yarn.server.resourcemanager.scheduler.fair.FSAppAttempt: assignContainer(FSSchedulerNode node:c220g1-031106.wisc.cloudlab.us, boolean reserved=false) for appattempt_1471812677892_0006_000001
2016-08-21 14:55:20,594 INFO org.apache.hadoop.yarn.server.resourcemanager.scheduler.fair.FSAppAttempt: assignContainer(FSSchedulerNode node:c220g1-031106.wisc.cloudlab.us, boolean reserved=false) for appattempt_1471812677892_0007_000001
2016-08-21 14:55:20,595 INFO org.apache.hadoop.yarn.server.resourcemanager.scheduler.fair.FSAppAttempt: assignContainer(FSSchedulerNode node:c220g1-031106.wisc.cloudlab.us, boolean reserved=false) for appattempt_1471812677892_0005_000001
2016-08-21 14:55:20,717 INFO org.apache.hadoop.yarn.server.resourcemanager.rmapp.attempt.RMAppAttemptImpl: ScheduleTransition.transition(appattempt_1471812677892_0004_000001,EventType: ATTEMPT_ADDED)
2016-08-21 14:55:20,718 INFO org.apache.hadoop.yarn.server.resourcemanager.scheduler.fair.FairScheduler: allocate(appattempt_1471812677892_0004_000001 [{Priority: 0, Capability: <memory:2048, vCores:1>, # Containers: 1, Location: *, Relax Locality: true}] [] null null
2016-08-21 14:55:20,718 INFO org.apache.hadoop.yarn.server.resourcemanager.scheduler.fair.FSAppAttempt: root.interactive1: <memory:2048, vCores:1>
2016-08-21 14:55:20,718 INFO org.apache.hadoop.yarn.server.resourcemanager.scheduler.fair.FSAppAttempt: root.interactive2: <memory:8192, vCores:4>
2016-08-21 14:55:20,719 INFO org.apache.hadoop.yarn.server.resourcemanager.scheduler.fair.FSAppAttempt: appattempt_1471812677892_0004_000001 minReqResource: <memory:16384, vCores:8> flexibleResource: <memory:0, vCores:0>
2016-08-21 14:55:20,719 INFO org.apache.hadoop.yarn.server.resourcemanager.scheduler.fair.FairScheduler: Cannot allocate appattempt_1471812677892_0004_000001 because there is NO flexible resource left
2016-08-21 14:55:21,506 INFO org.apache.hadoop.yarn.server.resourcemanager.scheduler.fair.FSAppAttempt: assignContainer(FSSchedulerNode node:cp-1.yarn-perf.yarnrm-PG0.wisc.cloudlab.us, boolean reserved=false) for appattempt_1471812677892_0004_000001
2016-08-21 14:55:21,507 INFO org.apache.hadoop.yarn.server.resourcemanager.scheduler.fair.FSAppAttempt: assignContainer(FSSchedulerNode node:cp-1.yarn-perf.yarnrm-PG0.wisc.cloudlab.us, boolean reserved=false) for appattempt_1471812677892_0003_000001
2016-08-21 14:55:21,507 INFO org.apache.hadoop.yarn.server.resourcemanager.scheduler.fair.FSAppAttempt: assignContainer(FSSchedulerNode node:cp-1.yarn-perf.yarnrm-PG0.wisc.cloudlab.us, boolean reserved=false) for appattempt_1471812677892_0006_000001
2016-08-21 14:55:21,507 INFO org.apache.hadoop.yarn.server.resourcemanager.scheduler.fair.FSAppAttempt: assignContainer(FSSchedulerNode node:cp-1.yarn-perf.yarnrm-PG0.wisc.cloudlab.us, boolean reserved=false) for appattempt_1471812677892_0007_000001
2016-08-21 14:55:21,507 INFO org.apache.hadoop.yarn.server.resourcemanager.scheduler.fair.FSAppAttempt: assignContainer(FSSchedulerNode node:cp-1.yarn-perf.yarnrm-PG0.wisc.cloudlab.us, boolean reserved=false) for appattempt_1471812677892_0005_000001
2016-08-21 14:55:21,596 INFO org.apache.hadoop.yarn.server.resourcemanager.scheduler.fair.FSAppAttempt: assignContainer(FSSchedulerNode node:c220g1-031106.wisc.cloudlab.us, boolean reserved=false) for appattempt_1471812677892_0004_000001
2016-08-21 14:55:21,596 INFO org.apache.hadoop.yarn.server.resourcemanager.scheduler.fair.FSAppAttempt: assignContainer(FSSchedulerNode node:c220g1-031106.wisc.cloudlab.us, boolean reserved=false) for appattempt_1471812677892_0003_000001
2016-08-21 14:55:21,596 INFO org.apache.hadoop.yarn.server.resourcemanager.scheduler.fair.FSAppAttempt: assignContainer(FSSchedulerNode node:c220g1-031106.wisc.cloudlab.us, boolean reserved=false) for appattempt_1471812677892_0006_000001
2016-08-21 14:55:21,596 INFO org.apache.hadoop.yarn.server.resourcemanager.scheduler.fair.FSAppAttempt: assignContainer(FSSchedulerNode node:c220g1-031106.wisc.cloudlab.us, boolean reserved=false) for appattempt_1471812677892_0007_000001
2016-08-21 14:55:21,596 INFO org.apache.hadoop.yarn.server.resourcemanager.scheduler.fair.FSAppAttempt: assignContainer(FSSchedulerNode node:c220g1-031106.wisc.cloudlab.us, boolean reserved=false) for appattempt_1471812677892_0005_000001
2016-08-21 14:55:21,720 INFO org.apache.hadoop.yarn.server.resourcemanager.rmapp.attempt.RMAppAttemptImpl: ScheduleTransition.transition(appattempt_1471812677892_0004_000001,EventType: ATTEMPT_ADDED)
2016-08-21 14:55:21,720 INFO org.apache.hadoop.yarn.server.resourcemanager.scheduler.fair.FairScheduler: allocate(appattempt_1471812677892_0004_000001 [{Priority: 0, Capability: <memory:2048, vCores:1>, # Containers: 1, Location: *, Relax Locality: true}] [] null null
2016-08-21 14:55:21,720 INFO org.apache.hadoop.yarn.server.resourcemanager.scheduler.fair.FSAppAttempt: root.interactive1: <memory:2048, vCores:1>
2016-08-21 14:55:21,720 INFO org.apache.hadoop.yarn.server.resourcemanager.scheduler.fair.FSAppAttempt: root.interactive2: <memory:8192, vCores:4>
2016-08-21 14:55:21,720 INFO org.apache.hadoop.yarn.server.resourcemanager.scheduler.fair.FSAppAttempt: appattempt_1471812677892_0004_000001 minReqResource: <memory:16384, vCores:8> flexibleResource: <memory:0, vCores:0>
2016-08-21 14:55:21,720 INFO org.apache.hadoop.yarn.server.resourcemanager.scheduler.fair.FairScheduler: Cannot allocate appattempt_1471812677892_0004_000001 because there is NO flexible resource left
2016-08-21 14:55:22,510 INFO org.apache.hadoop.yarn.server.resourcemanager.scheduler.fair.FSAppAttempt: assignContainer(FSSchedulerNode node:cp-1.yarn-perf.yarnrm-PG0.wisc.cloudlab.us, boolean reserved=false) for appattempt_1471812677892_0004_000001
2016-08-21 14:55:22,510 INFO org.apache.hadoop.yarn.server.resourcemanager.scheduler.fair.FSAppAttempt: assignContainer(FSSchedulerNode node:cp-1.yarn-perf.yarnrm-PG0.wisc.cloudlab.us, boolean reserved=false) for appattempt_1471812677892_0003_000001
2016-08-21 14:55:22,511 INFO org.apache.hadoop.yarn.server.resourcemanager.scheduler.fair.FSAppAttempt: assignContainer(FSSchedulerNode node:cp-1.yarn-perf.yarnrm-PG0.wisc.cloudlab.us, boolean reserved=false) for appattempt_1471812677892_0006_000001
2016-08-21 14:55:22,511 INFO org.apache.hadoop.yarn.server.resourcemanager.scheduler.fair.FSAppAttempt: assignContainer(FSSchedulerNode node:cp-1.yarn-perf.yarnrm-PG0.wisc.cloudlab.us, boolean reserved=false) for appattempt_1471812677892_0007_000001
2016-08-21 14:55:22,511 INFO org.apache.hadoop.yarn.server.resourcemanager.scheduler.fair.FSAppAttempt: assignContainer(FSSchedulerNode node:cp-1.yarn-perf.yarnrm-PG0.wisc.cloudlab.us, boolean reserved=false) for appattempt_1471812677892_0005_000001
2016-08-21 14:55:22,599 INFO org.apache.hadoop.yarn.server.resourcemanager.scheduler.fair.FSAppAttempt: assignContainer(FSSchedulerNode node:c220g1-031106.wisc.cloudlab.us, boolean reserved=false) for appattempt_1471812677892_0004_000001
2016-08-21 14:55:22,599 INFO org.apache.hadoop.yarn.server.resourcemanager.scheduler.fair.FSAppAttempt: assignContainer(FSSchedulerNode node:c220g1-031106.wisc.cloudlab.us, boolean reserved=false) for appattempt_1471812677892_0003_000001
2016-08-21 14:55:22,600 INFO org.apache.hadoop.yarn.server.resourcemanager.scheduler.fair.FSAppAttempt: assignContainer(FSSchedulerNode node:c220g1-031106.wisc.cloudlab.us, boolean reserved=false) for appattempt_1471812677892_0006_000001
2016-08-21 14:55:22,600 INFO org.apache.hadoop.yarn.server.resourcemanager.scheduler.fair.FSAppAttempt: assignContainer(FSSchedulerNode node:c220g1-031106.wisc.cloudlab.us, boolean reserved=false) for appattempt_1471812677892_0007_000001
2016-08-21 14:55:22,600 INFO org.apache.hadoop.yarn.server.resourcemanager.scheduler.fair.FSAppAttempt: assignContainer(FSSchedulerNode node:c220g1-031106.wisc.cloudlab.us, boolean reserved=false) for appattempt_1471812677892_0005_000001
2016-08-21 14:55:22,724 INFO org.apache.hadoop.yarn.server.resourcemanager.rmapp.attempt.RMAppAttemptImpl: ScheduleTransition.transition(appattempt_1471812677892_0004_000001,EventType: ATTEMPT_ADDED)
2016-08-21 14:55:22,725 INFO org.apache.hadoop.yarn.server.resourcemanager.scheduler.fair.FairScheduler: allocate(appattempt_1471812677892_0004_000001 [{Priority: 0, Capability: <memory:2048, vCores:1>, # Containers: 1, Location: *, Relax Locality: true}] [] null null
2016-08-21 14:55:22,725 INFO org.apache.hadoop.yarn.server.resourcemanager.scheduler.fair.FSAppAttempt: root.interactive1: <memory:2048, vCores:1>
2016-08-21 14:55:22,725 INFO org.apache.hadoop.yarn.server.resourcemanager.scheduler.fair.FSAppAttempt: root.interactive2: <memory:8192, vCores:4>
2016-08-21 14:55:22,725 INFO org.apache.hadoop.yarn.server.resourcemanager.scheduler.fair.FSAppAttempt: appattempt_1471812677892_0004_000001 minReqResource: <memory:16384, vCores:8> flexibleResource: <memory:0, vCores:0>
2016-08-21 14:55:22,725 INFO org.apache.hadoop.yarn.server.resourcemanager.scheduler.fair.FairScheduler: Cannot allocate appattempt_1471812677892_0004_000001 because there is NO flexible resource left
2016-08-21 14:55:22,729 INFO org.apache.hadoop.yarn.server.resourcemanager.scheduler.fair.FairScheduler: allocate(appattempt_1471812677892_0003_000001 [{Priority: 1, Capability: <memory:1920, vCores:1>, # Containers: 1, Location: *, Relax Locality: true}] [] [] []
2016-08-21 14:55:22,729 INFO org.apache.hadoop.yarn.server.resourcemanager.scheduler.fair.FSAppAttempt: root.interactive1: <memory:2048, vCores:1>
2016-08-21 14:55:22,730 INFO org.apache.hadoop.yarn.server.resourcemanager.scheduler.fair.FSAppAttempt: root.interactive2: <memory:8192, vCores:4>
2016-08-21 14:55:22,730 INFO org.apache.hadoop.yarn.server.resourcemanager.scheduler.fair.FSAppAttempt: appattempt_1471812677892_0003_000001 minReqResource: <memory:16384, vCores:8> flexibleResource: <memory:0, vCores:0>
2016-08-21 14:55:22,730 INFO org.apache.hadoop.yarn.server.resourcemanager.scheduler.fair.FairScheduler: allocate resource to application attempt: appattempt_1471812677892_0003_000001 queue:root.interactive1 isRunning=true 
2016-08-21 14:55:22,730 INFO org.apache.hadoop.yarn.server.resourcemanager.scheduler.fair.FairScheduler: iglf: 3.getHeadroom()=<memory:6144, vCores:3>
2016-08-21 14:55:22,923 INFO org.apache.hadoop.yarn.server.resourcemanager.scheduler.fair.FairScheduler: allocate(appattempt_1471812677892_0005_000001 [{Priority: 1, Capability: <memory:1920, vCores:1>, # Containers: 0, Location: *, Relax Locality: true}] [] [] []
2016-08-21 14:55:22,923 INFO org.apache.hadoop.yarn.server.resourcemanager.scheduler.fair.FSAppAttempt: root.interactive1: <memory:2048, vCores:1>
2016-08-21 14:55:22,924 INFO org.apache.hadoop.yarn.server.resourcemanager.scheduler.fair.FSAppAttempt: root.interactive2: <memory:8192, vCores:4>
2016-08-21 14:55:22,924 INFO org.apache.hadoop.yarn.server.resourcemanager.scheduler.fair.FSAppAttempt: appattempt_1471812677892_0005_000001 minReqResource: <memory:16384, vCores:8> flexibleResource: <memory:0, vCores:0>
2016-08-21 14:55:22,924 INFO org.apache.hadoop.yarn.server.resourcemanager.scheduler.fair.FairScheduler: allocate resource to application attempt: appattempt_1471812677892_0005_000001 queue:root.interactive2 isRunning=true 
2016-08-21 14:55:22,924 INFO org.apache.hadoop.yarn.server.resourcemanager.scheduler.AppSchedulingInfo: checking for deactivate of application :application_1471812677892_0005
2016-08-21 14:55:22,924 INFO org.apache.hadoop.yarn.server.resourcemanager.scheduler.fair.FairScheduler: iglf: 5.getHeadroom()=<memory:0, vCores:0>
2016-08-21 14:55:22,933 INFO org.apache.hadoop.yarn.server.resourcemanager.scheduler.fair.FairScheduler: allocate(appattempt_1471812677892_0003_000001 [] [] [] []
2016-08-21 14:55:22,933 INFO org.apache.hadoop.yarn.server.resourcemanager.scheduler.fair.FSAppAttempt: root.interactive1: <memory:2048, vCores:1>
2016-08-21 14:55:22,934 INFO org.apache.hadoop.yarn.server.resourcemanager.scheduler.fair.FSAppAttempt: root.interactive2: <memory:8192, vCores:4>
2016-08-21 14:55:22,934 INFO org.apache.hadoop.yarn.server.resourcemanager.scheduler.fair.FSAppAttempt: appattempt_1471812677892_0003_000001 minReqResource: <memory:16384, vCores:8> flexibleResource: <memory:0, vCores:0>
2016-08-21 14:55:22,934 INFO org.apache.hadoop.yarn.server.resourcemanager.scheduler.fair.FairScheduler: allocate resource to application attempt: appattempt_1471812677892_0003_000001 queue:root.interactive1 isRunning=true 
2016-08-21 14:55:22,934 INFO org.apache.hadoop.yarn.server.resourcemanager.scheduler.fair.FairScheduler: iglf: 3.getHeadroom()=<memory:6144, vCores:3>
2016-08-21 14:55:23,337 INFO org.apache.hadoop.yarn.server.resourcemanager.scheduler.fair.FairScheduler: allocate(appattempt_1471812677892_0003_000001 [] [] [] []
2016-08-21 14:55:23,337 INFO org.apache.hadoop.yarn.server.resourcemanager.scheduler.fair.FSAppAttempt: root.interactive1: <memory:2048, vCores:1>
2016-08-21 14:55:23,337 INFO org.apache.hadoop.yarn.server.resourcemanager.scheduler.fair.FSAppAttempt: root.interactive2: <memory:8192, vCores:4>
2016-08-21 14:55:23,337 INFO org.apache.hadoop.yarn.server.resourcemanager.scheduler.fair.FSAppAttempt: appattempt_1471812677892_0003_000001 minReqResource: <memory:16384, vCores:8> flexibleResource: <memory:0, vCores:0>
2016-08-21 14:55:23,337 INFO org.apache.hadoop.yarn.server.resourcemanager.scheduler.fair.FairScheduler: allocate resource to application attempt: appattempt_1471812677892_0003_000001 queue:root.interactive1 isRunning=true 
