2016-10-14 07:49:13,402 INFO org.apache.hadoop.yarn.server.resourcemanager.ResourceManager: STARTUP_MSG: 
/************************************************************
STARTUP_MSG: Starting ResourceManager
STARTUP_MSG:   host = nm.yarn-perf.yarnrm-pg0.wisc.cloudlab.us/128.104.222.53
STARTUP_MSG:   args = []
STARTUP_MSG:   version = 2.7.2
STARTUP_MSG:   build = https://github.com/lenhattan86/ccra -r 1fd9921b287b0f215cb02c37a19d37c6aac70e8d; compiled by 'tanle' on 2016-10-14T13:36Z
STARTUP_MSG:   java = 1.7.0_80
************************************************************/
2016-10-14 07:49:13,418 INFO org.apache.hadoop.yarn.server.resourcemanager.ResourceManager: registered UNIX signal handlers for [TERM, HUP, INT]
2016-10-14 07:49:13,794 INFO org.apache.hadoop.conf.Configuration: found resource core-site.xml at file:/users/tanle/hadoop/etc/hadoop/core-site.xml
2016-10-14 07:49:13,902 WARN org.apache.hadoop.util.NativeCodeLoader: Unable to load native-hadoop library for your platform... using builtin-java classes where applicable
2016-10-14 07:49:13,978 INFO org.apache.hadoop.security.Groups: clearing userToGroupsMap cache
2016-10-14 07:49:14,073 INFO org.apache.hadoop.conf.Configuration: found resource yarn-site.xml at file:/users/tanle/hadoop/etc/hadoop/yarn-site.xml
2016-10-14 07:49:14,283 INFO org.apache.hadoop.yarn.event.AsyncDispatcher: Registering class org.apache.hadoop.yarn.server.resourcemanager.RMFatalEventType for class org.apache.hadoop.yarn.server.resourcemanager.ResourceManager$RMFatalEventDispatcher
2016-10-14 07:49:14,468 INFO org.apache.hadoop.yarn.server.resourcemanager.security.NMTokenSecretManagerInRM: NMTokenKeyRollingInterval: 86400000ms and NMTokenKeyActivationDelay: 900000ms
2016-10-14 07:49:14,472 INFO org.apache.hadoop.yarn.server.resourcemanager.security.RMContainerTokenSecretManager: ContainerTokenKeyRollingInterval: 86400000ms and ContainerTokenKeyActivationDelay: 900000ms
2016-10-14 07:49:14,477 INFO org.apache.hadoop.yarn.server.resourcemanager.security.AMRMTokenSecretManager: AMRMTokenKeyRollingInterval: 86400000ms and AMRMTokenKeyActivationDelay: 900000 ms
2016-10-14 07:49:14,511 INFO org.apache.hadoop.yarn.event.AsyncDispatcher: Registering class org.apache.hadoop.yarn.server.resourcemanager.recovery.RMStateStoreEventType for class org.apache.hadoop.yarn.server.resourcemanager.recovery.RMStateStore$ForwardingEventHandler
2016-10-14 07:49:14,512 INFO org.apache.hadoop.yarn.event.AsyncDispatcher: Registering class org.apache.hadoop.yarn.server.resourcemanager.NodesListManagerEventType for class org.apache.hadoop.yarn.server.resourcemanager.NodesListManager
2016-10-14 07:49:14,513 INFO org.apache.hadoop.yarn.server.resourcemanager.ResourceManager: Using Scheduler: org.apache.hadoop.yarn.server.resourcemanager.scheduler.fair.FairScheduler
2016-10-14 07:49:14,544 INFO org.apache.hadoop.yarn.event.AsyncDispatcher: Registering class org.apache.hadoop.yarn.server.resourcemanager.scheduler.event.SchedulerEventType for class org.apache.hadoop.yarn.server.resourcemanager.ResourceManager$SchedulerEventDispatcher
2016-10-14 07:49:14,545 INFO org.apache.hadoop.yarn.event.AsyncDispatcher: Registering class org.apache.hadoop.yarn.server.resourcemanager.rmapp.RMAppEventType for class org.apache.hadoop.yarn.server.resourcemanager.ResourceManager$ApplicationEventDispatcher
2016-10-14 07:49:14,546 INFO org.apache.hadoop.yarn.event.AsyncDispatcher: Registering class org.apache.hadoop.yarn.server.resourcemanager.rmapp.attempt.RMAppAttemptEventType for class org.apache.hadoop.yarn.server.resourcemanager.ResourceManager$ApplicationAttemptEventDispatcher
2016-10-14 07:49:14,546 INFO org.apache.hadoop.yarn.event.AsyncDispatcher: Registering class org.apache.hadoop.yarn.server.resourcemanager.rmnode.RMNodeEventType for class org.apache.hadoop.yarn.server.resourcemanager.ResourceManager$NodeEventDispatcher
2016-10-14 07:49:14,613 INFO org.apache.hadoop.metrics2.impl.MetricsConfig: loaded properties from hadoop-metrics2.properties
2016-10-14 07:49:14,669 INFO org.apache.hadoop.metrics2.impl.MetricsSystemImpl: Scheduled snapshot period at 10 second(s).
2016-10-14 07:49:14,669 INFO org.apache.hadoop.metrics2.impl.MetricsSystemImpl: ResourceManager metrics system started
2016-10-14 07:49:14,683 INFO org.apache.hadoop.yarn.event.AsyncDispatcher: Registering class org.apache.hadoop.yarn.server.resourcemanager.RMAppManagerEventType for class org.apache.hadoop.yarn.server.resourcemanager.RMAppManager
2016-10-14 07:49:14,691 INFO org.apache.hadoop.yarn.event.AsyncDispatcher: Registering class org.apache.hadoop.yarn.server.resourcemanager.amlauncher.AMLauncherEventType for class org.apache.hadoop.yarn.server.resourcemanager.amlauncher.ApplicationMasterLauncher
2016-10-14 07:49:14,692 INFO org.apache.hadoop.yarn.server.resourcemanager.RMNMInfo: Registered RMNMInfo MBean
2016-10-14 07:49:14,694 INFO org.apache.hadoop.yarn.security.YarnAuthorizationProvider: org.apache.hadoop.yarn.security.ConfiguredYarnAuthorizer is instiantiated.
2016-10-14 07:49:14,695 INFO org.apache.hadoop.util.HostsFileReader: Refreshing hosts (include/exclude) list
2016-10-14 07:49:14,736 INFO org.apache.hadoop.yarn.server.resourcemanager.scheduler.fair.AllocationFileLoaderService: Loading allocation file /users/tanle/hadoop/etc/fair-scheduler.xml
2016-10-14 07:49:14,782 INFO org.apache.hadoop.yarn.server.resourcemanager.metrics.SystemMetricsPublisher: YARN system metrics publishing service is not enabled
2016-10-14 07:49:14,782 INFO org.apache.hadoop.yarn.server.resourcemanager.ResourceManager: Transitioning to active state
2016-10-14 07:49:14,803 INFO org.apache.hadoop.yarn.server.resourcemanager.recovery.RMStateStore: Updating AMRMToken
2016-10-14 07:49:14,803 INFO org.apache.hadoop.yarn.server.resourcemanager.security.RMContainerTokenSecretManager: Rolling master-key for container-tokens
2016-10-14 07:49:14,803 INFO org.apache.hadoop.yarn.server.resourcemanager.security.NMTokenSecretManagerInRM: Rolling master-key for nm-tokens
2016-10-14 07:49:14,804 INFO org.apache.hadoop.security.token.delegation.AbstractDelegationTokenSecretManager: Updating the current master key for generating delegation tokens
2016-10-14 07:49:14,805 INFO org.apache.hadoop.yarn.server.resourcemanager.security.RMDelegationTokenSecretManager: storing master key with keyID 1
2016-10-14 07:49:14,805 INFO org.apache.hadoop.yarn.server.resourcemanager.recovery.RMStateStore: Storing RMDTMasterKey.
2016-10-14 07:49:14,807 INFO org.apache.hadoop.security.token.delegation.AbstractDelegationTokenSecretManager: Starting expired delegation token remover thread, tokenRemoverScanInterval=60 min(s)
2016-10-14 07:49:14,807 INFO org.apache.hadoop.security.token.delegation.AbstractDelegationTokenSecretManager: Updating the current master key for generating delegation tokens
2016-10-14 07:49:14,807 INFO org.apache.hadoop.yarn.server.resourcemanager.security.RMDelegationTokenSecretManager: storing master key with keyID 2
2016-10-14 07:49:14,807 INFO org.apache.hadoop.yarn.server.resourcemanager.recovery.RMStateStore: Storing RMDTMasterKey.
2016-10-14 07:49:14,810 INFO org.apache.hadoop.yarn.event.AsyncDispatcher: Registering class org.apache.hadoop.yarn.nodelabels.event.NodeLabelsStoreEventType for class org.apache.hadoop.yarn.nodelabels.CommonNodeLabelsManager$ForwardingEventHandler
2016-10-14 07:49:14,854 INFO org.apache.hadoop.ipc.CallQueueManager: Using callQueue class java.util.concurrent.LinkedBlockingQueue
2016-10-14 07:49:14,870 INFO org.apache.hadoop.ipc.Server: Starting Socket Reader #1 for port 8031
2016-10-14 07:49:14,890 INFO org.apache.hadoop.yarn.factories.impl.pb.RpcServerFactoryPBImpl: Adding protocol org.apache.hadoop.yarn.server.api.ResourceTrackerPB to the server
2016-10-14 07:49:14,892 INFO org.apache.hadoop.ipc.Server: IPC Server Responder: starting
2016-10-14 07:49:14,892 INFO org.apache.hadoop.ipc.Server: IPC Server listener on 8031: starting
2016-10-14 07:49:14,962 INFO org.apache.hadoop.ipc.CallQueueManager: Using callQueue class java.util.concurrent.LinkedBlockingQueue
2016-10-14 07:49:14,968 INFO org.apache.hadoop.ipc.Server: Starting Socket Reader #1 for port 8030
2016-10-14 07:49:14,976 INFO org.apache.hadoop.yarn.factories.impl.pb.RpcServerFactoryPBImpl: Adding protocol org.apache.hadoop.yarn.api.ApplicationMasterProtocolPB to the server
2016-10-14 07:49:14,977 INFO org.apache.hadoop.ipc.Server: IPC Server Responder: starting
2016-10-14 07:49:14,977 INFO org.apache.hadoop.ipc.Server: IPC Server listener on 8030: starting
2016-10-14 07:49:15,032 INFO org.apache.hadoop.ipc.CallQueueManager: Using callQueue class java.util.concurrent.LinkedBlockingQueue
2016-10-14 07:49:15,033 INFO org.apache.hadoop.ipc.Server: Starting Socket Reader #1 for port 8032
2016-10-14 07:49:15,037 INFO org.apache.hadoop.yarn.factories.impl.pb.RpcServerFactoryPBImpl: Adding protocol org.apache.hadoop.yarn.api.ApplicationClientProtocolPB to the server
2016-10-14 07:49:15,037 INFO org.apache.hadoop.ipc.Server: IPC Server Responder: starting
2016-10-14 07:49:15,037 INFO org.apache.hadoop.ipc.Server: IPC Server listener on 8032: starting
2016-10-14 07:49:15,044 INFO org.apache.hadoop.yarn.server.resourcemanager.ResourceManager: Transitioned to active state
2016-10-14 07:49:15,157 INFO org.mortbay.log: Logging to org.slf4j.impl.Log4jLoggerAdapter(org.mortbay.log) via org.mortbay.log.Slf4jLog
2016-10-14 07:49:15,166 INFO org.apache.hadoop.security.authentication.server.AuthenticationFilter: Unable to initialize FileSignerSecretProvider, falling back to use random secrets.
2016-10-14 07:49:15,172 INFO org.apache.hadoop.http.HttpRequestLog: Http request log for http.requests.resourcemanager is not defined
2016-10-14 07:49:15,179 INFO org.apache.hadoop.http.HttpServer2: Added global filter 'safety' (class=org.apache.hadoop.http.HttpServer2$QuotingInputFilter)
2016-10-14 07:49:15,184 INFO org.apache.hadoop.http.HttpServer2: Added filter RMAuthenticationFilter (class=org.apache.hadoop.yarn.server.security.http.RMAuthenticationFilter) to context cluster
2016-10-14 07:49:15,184 INFO org.apache.hadoop.http.HttpServer2: Added filter RMAuthenticationFilter (class=org.apache.hadoop.yarn.server.security.http.RMAuthenticationFilter) to context logs
2016-10-14 07:49:15,184 INFO org.apache.hadoop.http.HttpServer2: Added filter RMAuthenticationFilter (class=org.apache.hadoop.yarn.server.security.http.RMAuthenticationFilter) to context static
2016-10-14 07:49:15,184 INFO org.apache.hadoop.http.HttpServer2: Added filter static_user_filter (class=org.apache.hadoop.http.lib.StaticUserWebFilter$StaticUserFilter) to context cluster
2016-10-14 07:49:15,185 INFO org.apache.hadoop.http.HttpServer2: Added filter static_user_filter (class=org.apache.hadoop.http.lib.StaticUserWebFilter$StaticUserFilter) to context logs
2016-10-14 07:49:15,185 INFO org.apache.hadoop.http.HttpServer2: Added filter static_user_filter (class=org.apache.hadoop.http.lib.StaticUserWebFilter$StaticUserFilter) to context static
2016-10-14 07:49:15,188 INFO org.apache.hadoop.http.HttpServer2: adding path spec: /cluster/*
2016-10-14 07:49:15,188 INFO org.apache.hadoop.http.HttpServer2: adding path spec: /ws/*
2016-10-14 07:49:15,528 INFO org.apache.hadoop.yarn.webapp.WebApps: Registered webapp guice modules
2016-10-14 07:49:15,529 INFO org.apache.hadoop.http.HttpServer2: Jetty bound to port 8088
2016-10-14 07:49:15,530 INFO org.mortbay.log: jetty-6.1.26
2016-10-14 07:49:15,554 INFO org.mortbay.log: Extract jar:file:/users/tanle/hadoop/share/hadoop/yarn/hadoop-yarn-common-2.7.2.jar!/webapps/cluster to /tmp/Jetty_nm_yarn.perf_yarnrm.pg0_wisc_cloudlab_us_8088_cluster____.pro683/webapp
2016-10-14 07:49:15,761 INFO org.apache.hadoop.security.token.delegation.AbstractDelegationTokenSecretManager: Updating the current master key for generating delegation tokens
2016-10-14 07:49:15,762 INFO org.apache.hadoop.security.token.delegation.AbstractDelegationTokenSecretManager: Starting expired delegation token remover thread, tokenRemoverScanInterval=60 min(s)
2016-10-14 07:49:15,762 INFO org.apache.hadoop.security.token.delegation.AbstractDelegationTokenSecretManager: Updating the current master key for generating delegation tokens
2016-10-14 07:49:16,498 INFO org.mortbay.log: Started HttpServer2$SelectChannelConnectorWithSafeStartup@nm.yarn-perf.yarnrm-pg0.wisc.cloudlab.us:8088
2016-10-14 07:49:16,498 INFO org.apache.hadoop.yarn.webapp.WebApps: Web app cluster started at 8088
2016-10-14 07:49:16,535 INFO org.apache.hadoop.ipc.CallQueueManager: Using callQueue class java.util.concurrent.LinkedBlockingQueue
2016-10-14 07:49:16,536 INFO org.apache.hadoop.ipc.Server: Starting Socket Reader #1 for port 8033
2016-10-14 07:49:16,539 INFO org.apache.hadoop.yarn.factories.impl.pb.RpcServerFactoryPBImpl: Adding protocol org.apache.hadoop.yarn.server.api.ResourceManagerAdministrationProtocolPB to the server
2016-10-14 07:49:16,540 INFO org.apache.hadoop.ipc.Server: IPC Server Responder: starting
2016-10-14 07:49:16,540 INFO org.apache.hadoop.ipc.Server: IPC Server listener on 8033: starting
2016-10-14 07:49:18,137 INFO org.apache.hadoop.yarn.util.RackResolver: Resolved cp-2.yarn-perf.yarnrm-PG0.wisc.cloudlab.us to /default-rack
2016-10-14 07:49:18,141 INFO org.apache.hadoop.yarn.server.resourcemanager.ResourceTrackerService: NodeManager from node cp-2.yarn-perf.yarnrm-PG0.wisc.cloudlab.us(cmPort: 43837 httpPort: 8042) registered with capability: <memory:8192, vCores:4>, assigned nodeId cp-2.yarn-perf.yarnrm-PG0.wisc.cloudlab.us:43837
2016-10-14 07:49:18,144 INFO org.apache.hadoop.yarn.server.resourcemanager.rmnode.RMNodeImpl: cp-2.yarn-perf.yarnrm-PG0.wisc.cloudlab.us:43837 Node Transitioned from NEW to RUNNING
2016-10-14 07:49:18,148 INFO org.apache.hadoop.yarn.server.resourcemanager.scheduler.fair.FairScheduler: Added node cp-2.yarn-perf.yarnrm-PG0.wisc.cloudlab.us:43837 cluster capacity: <memory:8192, vCores:4>
2016-10-14 07:49:18,193 INFO org.apache.hadoop.yarn.util.RackResolver: Resolved c220g1-030617.wisc.cloudlab.us to /default-rack
2016-10-14 07:49:18,194 INFO org.apache.hadoop.yarn.server.resourcemanager.ResourceTrackerService: NodeManager from node c220g1-030617.wisc.cloudlab.us(cmPort: 46119 httpPort: 8042) registered with capability: <memory:8192, vCores:4>, assigned nodeId c220g1-030617.wisc.cloudlab.us:46119
2016-10-14 07:49:18,194 INFO org.apache.hadoop.yarn.server.resourcemanager.rmnode.RMNodeImpl: c220g1-030617.wisc.cloudlab.us:46119 Node Transitioned from NEW to RUNNING
2016-10-14 07:49:18,195 INFO org.apache.hadoop.yarn.server.resourcemanager.scheduler.fair.FairScheduler: Added node c220g1-030617.wisc.cloudlab.us:46119 cluster capacity: <memory:16384, vCores:8>
2016-10-14 07:49:18,292 INFO org.apache.hadoop.yarn.util.RackResolver: Resolved cp-1.yarn-perf.yarnrm-PG0.wisc.cloudlab.us to /default-rack
2016-10-14 07:49:18,293 INFO org.apache.hadoop.yarn.server.resourcemanager.ResourceTrackerService: NodeManager from node cp-1.yarn-perf.yarnrm-PG0.wisc.cloudlab.us(cmPort: 36424 httpPort: 8042) registered with capability: <memory:8192, vCores:4>, assigned nodeId cp-1.yarn-perf.yarnrm-PG0.wisc.cloudlab.us:36424
2016-10-14 07:49:18,293 INFO org.apache.hadoop.yarn.server.resourcemanager.rmnode.RMNodeImpl: cp-1.yarn-perf.yarnrm-PG0.wisc.cloudlab.us:36424 Node Transitioned from NEW to RUNNING
2016-10-14 07:49:18,294 INFO org.apache.hadoop.yarn.server.resourcemanager.scheduler.fair.FairScheduler: Added node cp-1.yarn-perf.yarnrm-PG0.wisc.cloudlab.us:36424 cluster capacity: <memory:24576, vCores:12>
2016-10-14 07:49:18,436 INFO org.apache.hadoop.yarn.util.RackResolver: Resolved cp-3.yarn-perf.yarnrm-PG0.wisc.cloudlab.us to /default-rack
2016-10-14 07:49:18,436 INFO org.apache.hadoop.yarn.server.resourcemanager.ResourceTrackerService: NodeManager from node cp-3.yarn-perf.yarnrm-PG0.wisc.cloudlab.us(cmPort: 44309 httpPort: 8042) registered with capability: <memory:8192, vCores:4>, assigned nodeId cp-3.yarn-perf.yarnrm-PG0.wisc.cloudlab.us:44309
2016-10-14 07:49:18,436 INFO org.apache.hadoop.yarn.server.resourcemanager.rmnode.RMNodeImpl: cp-3.yarn-perf.yarnrm-PG0.wisc.cloudlab.us:44309 Node Transitioned from NEW to RUNNING
2016-10-14 07:49:18,437 INFO org.apache.hadoop.yarn.server.resourcemanager.scheduler.fair.FairScheduler: Added node cp-3.yarn-perf.yarnrm-PG0.wisc.cloudlab.us:44309 cluster capacity: <memory:32768, vCores:16>
2016-10-14 07:51:14,286 INFO org.apache.hadoop.yarn.server.resourcemanager.ClientRMService: Allocated new applicationId: 1
2016-10-14 07:51:14,392 INFO org.apache.hadoop.yarn.server.resourcemanager.ClientRMService: Allocated new applicationId: 2
2016-10-14 07:51:27,242 WARN org.apache.hadoop.yarn.server.resourcemanager.rmapp.RMAppImpl: The specific max attempts: 0 for application: 2 is invalid, because it is out of the range [1, 2]. Use the global max attempts instead.
2016-10-14 07:51:27,243 INFO org.apache.hadoop.yarn.server.resourcemanager.ClientRMService: Application with id 2 submitted by user tanle
2016-10-14 07:51:27,244 INFO org.apache.hadoop.yarn.server.resourcemanager.rmapp.RMAppImpl: Storing application with id application_1476452954783_0002
2016-10-14 07:51:27,245 INFO org.apache.hadoop.yarn.server.resourcemanager.RMAuditLogger: USER=tanle	IP=128.104.222.53	OPERATION=Submit Application Request	TARGET=ClientRMService	RESULT=SUCCESS	APPID=application_1476452954783_0002
2016-10-14 07:51:27,256 INFO org.apache.hadoop.yarn.server.resourcemanager.recovery.RMStateStore: Storing info for app: application_1476452954783_0002
2016-10-14 07:51:27,267 INFO org.apache.hadoop.yarn.server.resourcemanager.scheduler.fair.FairScheduler: Accepted application application_1476452954783_0002 from user: tanle, in queue: batch0, currently num of applications: 1
2016-10-14 07:51:27,334 INFO org.apache.hadoop.yarn.server.resourcemanager.ApplicationMasterService: Registering app attempt : appattempt_1476452954783_0002_000001
2016-10-14 07:51:27,335 INFO org.apache.hadoop.yarn.server.resourcemanager.rmapp.attempt.RMAppAttemptImpl: appattempt_1476452954783_0002_000001 State change from NEW to SUBMITTED
2016-10-14 07:51:27,359 INFO org.apache.hadoop.yarn.server.resourcemanager.scheduler.fair.FairScheduler: Added Application Attempt appattempt_1476452954783_0002_000001 to scheduler from user: tanle
2016-10-14 07:51:27,359 INFO org.apache.hadoop.yarn.server.resourcemanager.rmapp.attempt.RMAppAttemptImpl: ScheduleTransition.transition(appattempt_1476452954783_0002_000001,EventType: ATTEMPT_ADDED)
2016-10-14 07:51:27,360 INFO org.apache.hadoop.yarn.server.resourcemanager.scheduler.fair.FairScheduler: allocate(appattempt_1476452954783_0002_000001 [{Priority: 0, Capability: <memory:2048, vCores:1>, # Containers: 1, Location: *, Relax Locality: true}] [] null null
2016-10-14 07:51:27,360 INFO org.apache.hadoop.yarn.server.resourcemanager.scheduler.fair.FSAppAttempt: appattempt_1476452954783_0002_000001 minReqResource: <memory:0, vCores:0> flexibleResource: <memory:32768, vCores:16>
2016-10-14 07:51:27,360 INFO org.apache.hadoop.yarn.server.resourcemanager.scheduler.fair.FairScheduler: [admission control] getFlexibleResource <memory:32768, vCores:16>
2016-10-14 07:51:27,362 INFO org.apache.hadoop.yarn.server.resourcemanager.rmapp.attempt.RMAppAttemptImpl: appattempt_1476452954783_0002_000001 State change from SUBMITTED to SCHEDULED
2016-10-14 07:51:27,389 WARN org.apache.hadoop.yarn.server.resourcemanager.rmapp.RMAppImpl: The specific max attempts: 0 for application: 1 is invalid, because it is out of the range [1, 2]. Use the global max attempts instead.
2016-10-14 07:51:27,390 INFO org.apache.hadoop.yarn.server.resourcemanager.ClientRMService: Application with id 1 submitted by user tanle
2016-10-14 07:51:27,390 INFO org.apache.hadoop.yarn.server.resourcemanager.rmapp.RMAppImpl: Storing application with id application_1476452954783_0001
2016-10-14 07:51:27,390 INFO org.apache.hadoop.yarn.server.resourcemanager.RMAuditLogger: USER=tanle	IP=128.104.222.53	OPERATION=Submit Application Request	TARGET=ClientRMService	RESULT=SUCCESS	APPID=application_1476452954783_0001
2016-10-14 07:51:27,390 INFO org.apache.hadoop.yarn.server.resourcemanager.recovery.RMStateStore: Storing info for app: application_1476452954783_0001
2016-10-14 07:51:27,395 INFO org.apache.hadoop.yarn.server.resourcemanager.scheduler.fair.FairScheduler: Accepted application application_1476452954783_0001 from user: tanle, in queue: interactive0, currently num of applications: 2
2016-10-14 07:51:27,396 INFO org.apache.hadoop.yarn.server.resourcemanager.ApplicationMasterService: Registering app attempt : appattempt_1476452954783_0001_000001
2016-10-14 07:51:27,397 INFO org.apache.hadoop.yarn.server.resourcemanager.rmapp.attempt.RMAppAttemptImpl: appattempt_1476452954783_0001_000001 State change from NEW to SUBMITTED
2016-10-14 07:51:27,397 INFO org.apache.hadoop.yarn.server.resourcemanager.scheduler.fair.FairScheduler: Added Application Attempt appattempt_1476452954783_0001_000001 to scheduler from user: tanle
2016-10-14 07:51:27,398 INFO org.apache.hadoop.yarn.server.resourcemanager.rmapp.attempt.RMAppAttemptImpl: ScheduleTransition.transition(appattempt_1476452954783_0001_000001,EventType: ATTEMPT_ADDED)
2016-10-14 07:51:27,398 INFO org.apache.hadoop.yarn.server.resourcemanager.scheduler.fair.FairScheduler: allocate(appattempt_1476452954783_0001_000001 [{Priority: 0, Capability: <memory:2048, vCores:1>, # Containers: 1, Location: *, Relax Locality: true}] [] null null
2016-10-14 07:51:27,398 INFO org.apache.hadoop.yarn.server.resourcemanager.scheduler.fair.FSAppAttempt: root.batch0 getMinReq:<memory:0, vCores:0> demand: <memory:0, vCores:0> usage: <memory:0, vCores:0>running true active: true isLeafQueue():true
2016-10-14 07:51:27,398 INFO org.apache.hadoop.yarn.server.resourcemanager.scheduler.fair.FSAppAttempt: appattempt_1476452954783_0001_000001 minReqResource: <memory:0, vCores:0> flexibleResource: <memory:32768, vCores:16>
2016-10-14 07:51:27,398 INFO org.apache.hadoop.yarn.server.resourcemanager.scheduler.fair.FairScheduler: [admission control] getFlexibleResource <memory:32768, vCores:16>
2016-10-14 07:51:27,399 INFO org.apache.hadoop.yarn.server.resourcemanager.rmapp.attempt.RMAppAttemptImpl: appattempt_1476452954783_0001_000001 State change from SUBMITTED to SCHEDULED
2016-10-14 07:51:27,654 INFO org.apache.hadoop.yarn.server.resourcemanager.scheduler.fair.FSAppAttempt: assignContainer(FSSchedulerNode node:cp-2.yarn-perf.yarnrm-PG0.wisc.cloudlab.us, boolean reserved=false) for appattempt_1476452954783_0001_000001
2016-10-14 07:51:27,671 INFO org.apache.hadoop.yarn.server.resourcemanager.scheduler.fair.FSAppAttempt: allocate container: container_1476452954783_0001_01_000001 priority 0
2016-10-14 07:51:27,685 INFO org.apache.hadoop.yarn.server.resourcemanager.rmcontainer.RMContainerImpl: Processing container_1476452954783_0001_01_000001 of event START
2016-10-14 07:51:27,686 INFO org.apache.hadoop.yarn.server.resourcemanager.rmcontainer.RMContainerImpl: container_1476452954783_0001_01_000001 Container Transitioned from NEW to ALLOCATED
2016-10-14 07:51:27,686 INFO org.apache.hadoop.yarn.server.resourcemanager.RMAuditLogger: USER=tanle	OPERATION=AM Allocated Container	TARGET=SchedulerApp	RESULT=SUCCESS	APPID=application_1476452954783_0001	CONTAINERID=container_1476452954783_0001_01_000001
2016-10-14 07:51:27,686 INFO org.apache.hadoop.yarn.server.resourcemanager.rmapp.attempt.RMAppAttemptImpl: AMContainerAllocatedTransition.transition(appattempt_1476452954783_0001_000001,EventType: CONTAINER_ALLOCATED)
2016-10-14 07:51:27,686 INFO org.apache.hadoop.yarn.server.resourcemanager.scheduler.SchedulerNode: Assigned container container_1476452954783_0001_01_000001 of capacity <memory:2048, vCores:1> on host cp-2.yarn-perf.yarnrm-PG0.wisc.cloudlab.us:43837, which has 1 containers, <memory:2048, vCores:1> used and <memory:6144, vCores:3> available after allocation
2016-10-14 07:51:27,686 INFO org.apache.hadoop.yarn.server.resourcemanager.scheduler.fair.FairScheduler: allocate(appattempt_1476452954783_0001_000001 [] [] null null
2016-10-14 07:51:27,686 INFO org.apache.hadoop.yarn.server.resourcemanager.scheduler.fair.FSAppAttempt: root.interactive0 getMinReq:<memory:24576, vCores:12> demand: <memory:2048, vCores:1> usage: <memory:2048, vCores:1>running true active: true isLeafQueue():true
2016-10-14 07:51:27,686 INFO org.apache.hadoop.yarn.server.resourcemanager.scheduler.fair.FSAppAttempt: root.batch0 getMinReq:<memory:0, vCores:0> demand: <memory:2048, vCores:1> usage: <memory:0, vCores:0>running true active: true isLeafQueue():true
2016-10-14 07:51:27,686 INFO org.apache.hadoop.yarn.server.resourcemanager.scheduler.fair.FSAppAttempt: appattempt_1476452954783_0001_000001 minReqResource: <memory:24576, vCores:12> flexibleResource: <memory:8192, vCores:4>
2016-10-14 07:51:27,687 INFO org.apache.hadoop.yarn.server.resourcemanager.scheduler.fair.FairScheduler: [admission control] getFlexibleResource <memory:8192, vCores:4>
2016-10-14 07:51:27,687 INFO org.apache.hadoop.yarn.server.resourcemanager.scheduler.fair.FairScheduler: app appattempt_1476452954783_0001_000001 in queue root.interactive0 isRunning: true
2016-10-14 07:51:27,688 INFO org.apache.hadoop.yarn.server.resourcemanager.scheduler.fair.FSAppAttempt: assignContainer(FSSchedulerNode node:c220g1-030617.wisc.cloudlab.us, boolean reserved=false) for appattempt_1476452954783_0001_000001
2016-10-14 07:51:27,715 INFO org.apache.hadoop.yarn.server.resourcemanager.security.NMTokenSecretManagerInRM: Sending NMToken for nodeId : cp-2.yarn-perf.yarnrm-PG0.wisc.cloudlab.us:43837 for container : container_1476452954783_0001_01_000001
2016-10-14 07:51:27,728 INFO org.apache.hadoop.yarn.server.resourcemanager.rmcontainer.RMContainerImpl: Processing container_1476452954783_0001_01_000001 of event ACQUIRED
2016-10-14 07:51:27,729 INFO org.apache.hadoop.yarn.server.resourcemanager.rmcontainer.RMContainerImpl: container_1476452954783_0001_01_000001 Container Transitioned from ALLOCATED to ACQUIRED
2016-10-14 07:51:27,729 INFO org.apache.hadoop.yarn.server.resourcemanager.security.NMTokenSecretManagerInRM: Clear node set for appattempt_1476452954783_0001_000001
2016-10-14 07:51:27,729 INFO org.apache.hadoop.yarn.server.resourcemanager.scheduler.fair.FSAppAttempt: assignContainer(FSSchedulerNode node:c220g1-030617.wisc.cloudlab.us, boolean reserved=false) for appattempt_1476452954783_0002_000001
2016-10-14 07:51:27,730 INFO org.apache.hadoop.yarn.server.resourcemanager.scheduler.fair.FSAppAttempt: allocate container: container_1476452954783_0002_01_000001 priority 0
2016-10-14 07:51:27,730 INFO org.apache.hadoop.yarn.server.resourcemanager.rmcontainer.RMContainerImpl: Processing container_1476452954783_0002_01_000001 of event START
2016-10-14 07:51:27,730 INFO org.apache.hadoop.yarn.server.resourcemanager.rmcontainer.RMContainerImpl: container_1476452954783_0002_01_000001 Container Transitioned from NEW to ALLOCATED
2016-10-14 07:51:27,730 INFO org.apache.hadoop.yarn.server.resourcemanager.RMAuditLogger: USER=tanle	OPERATION=AM Allocated Container	TARGET=SchedulerApp	RESULT=SUCCESS	APPID=application_1476452954783_0002	CONTAINERID=container_1476452954783_0002_01_000001
2016-10-14 07:51:27,731 INFO org.apache.hadoop.yarn.server.resourcemanager.scheduler.SchedulerNode: Assigned container container_1476452954783_0002_01_000001 of capacity <memory:2048, vCores:1> on host c220g1-030617.wisc.cloudlab.us:46119, which has 1 containers, <memory:2048, vCores:1> used and <memory:6144, vCores:3> available after allocation
2016-10-14 07:51:27,734 INFO org.apache.hadoop.yarn.server.resourcemanager.rmapp.attempt.RMAppAttemptImpl: Storing attempt: AppId: application_1476452954783_0001 AttemptId: appattempt_1476452954783_0001_000001 MasterContainer: Container: [ContainerId: container_1476452954783_0001_01_000001, NodeId: cp-2.yarn-perf.yarnrm-PG0.wisc.cloudlab.us:43837, NodeHttpAddress: cp-2.yarn-perf.yarnrm-PG0.wisc.cloudlab.us:8042, Resource: <memory:2048, vCores:1>, Priority: 0, Token: Token { kind: ContainerToken, service: 128.104.222.60:43837 }, ]
2016-10-14 07:51:27,750 INFO org.apache.hadoop.yarn.server.resourcemanager.rmapp.attempt.RMAppAttemptImpl: appattempt_1476452954783_0001_000001 State change from SCHEDULED to ALLOCATED_SAVING
2016-10-14 07:51:27,750 INFO org.apache.hadoop.yarn.server.resourcemanager.rmapp.attempt.RMAppAttemptImpl: AMContainerAllocatedTransition.transition(appattempt_1476452954783_0002_000001,EventType: CONTAINER_ALLOCATED)
2016-10-14 07:51:27,750 INFO org.apache.hadoop.yarn.server.resourcemanager.scheduler.fair.FairScheduler: allocate(appattempt_1476452954783_0002_000001 [] [] null null
2016-10-14 07:51:27,750 INFO org.apache.hadoop.yarn.server.resourcemanager.scheduler.fair.FSAppAttempt: root.interactive0 getMinReq:<memory:24576, vCores:12> demand: <memory:2048, vCores:1> usage: <memory:2048, vCores:1>running true active: true isLeafQueue():true
2016-10-14 07:51:27,750 INFO org.apache.hadoop.yarn.server.resourcemanager.scheduler.fair.FSAppAttempt: root.batch0 getMinReq:<memory:0, vCores:0> demand: <memory:2048, vCores:1> usage: <memory:2048, vCores:1>running true active: true isLeafQueue():true
2016-10-14 07:51:27,750 INFO org.apache.hadoop.yarn.server.resourcemanager.scheduler.fair.FSAppAttempt: appattempt_1476452954783_0002_000001 minReqResource: <memory:24576, vCores:12> flexibleResource: <memory:8192, vCores:4>
2016-10-14 07:51:27,750 INFO org.apache.hadoop.yarn.server.resourcemanager.scheduler.fair.FairScheduler: [admission control] getFlexibleResource <memory:8192, vCores:4>
2016-10-14 07:51:27,752 INFO org.apache.hadoop.yarn.server.resourcemanager.security.NMTokenSecretManagerInRM: Sending NMToken for nodeId : c220g1-030617.wisc.cloudlab.us:46119 for container : container_1476452954783_0002_01_000001
2016-10-14 07:51:27,753 INFO org.apache.hadoop.yarn.server.resourcemanager.rmcontainer.RMContainerImpl: Processing container_1476452954783_0002_01_000001 of event ACQUIRED
2016-10-14 07:51:27,753 INFO org.apache.hadoop.yarn.server.resourcemanager.rmcontainer.RMContainerImpl: container_1476452954783_0002_01_000001 Container Transitioned from ALLOCATED to ACQUIRED
2016-10-14 07:51:27,753 INFO org.apache.hadoop.yarn.server.resourcemanager.security.NMTokenSecretManagerInRM: Clear node set for appattempt_1476452954783_0002_000001
2016-10-14 07:51:27,754 INFO org.apache.hadoop.yarn.server.resourcemanager.rmapp.attempt.RMAppAttemptImpl: Storing attempt: AppId: application_1476452954783_0002 AttemptId: appattempt_1476452954783_0002_000001 MasterContainer: Container: [ContainerId: container_1476452954783_0002_01_000001, NodeId: c220g1-030617.wisc.cloudlab.us:46119, NodeHttpAddress: c220g1-030617.wisc.cloudlab.us:8042, Resource: <memory:2048, vCores:1>, Priority: 0, Token: Token { kind: ContainerToken, service: 128.104.222.67:46119 }, ]
2016-10-14 07:51:27,754 INFO org.apache.hadoop.yarn.server.resourcemanager.rmapp.attempt.RMAppAttemptImpl: appattempt_1476452954783_0002_000001 State change from SCHEDULED to ALLOCATED_SAVING
2016-10-14 07:51:27,755 INFO org.apache.hadoop.yarn.server.resourcemanager.rmapp.attempt.RMAppAttemptImpl: appattempt_1476452954783_0001_000001 State change from ALLOCATED_SAVING to ALLOCATED
2016-10-14 07:51:27,755 INFO org.apache.hadoop.yarn.server.resourcemanager.rmapp.attempt.RMAppAttemptImpl: appattempt_1476452954783_0002_000001 State change from ALLOCATED_SAVING to ALLOCATED
2016-10-14 07:51:27,759 INFO org.apache.hadoop.yarn.server.resourcemanager.amlauncher.AMLauncher: Launching masterappattempt_1476452954783_0001_000001
2016-10-14 07:51:27,759 INFO org.apache.hadoop.yarn.server.resourcemanager.amlauncher.AMLauncher: Launching masterappattempt_1476452954783_0002_000001
2016-10-14 07:51:27,786 INFO org.apache.hadoop.yarn.server.resourcemanager.scheduler.fair.FSAppAttempt: assignContainer(FSSchedulerNode node:cp-1.yarn-perf.yarnrm-PG0.wisc.cloudlab.us, boolean reserved=false) for appattempt_1476452954783_0001_000001
2016-10-14 07:51:27,787 INFO org.apache.hadoop.yarn.server.resourcemanager.scheduler.fair.FSAppAttempt: assignContainer(FSSchedulerNode node:cp-1.yarn-perf.yarnrm-PG0.wisc.cloudlab.us, boolean reserved=false) for appattempt_1476452954783_0002_000001
2016-10-14 07:51:27,817 INFO org.apache.hadoop.yarn.server.resourcemanager.amlauncher.AMLauncher: Setting up container Container: [ContainerId: container_1476452954783_0002_01_000001, NodeId: c220g1-030617.wisc.cloudlab.us:46119, NodeHttpAddress: c220g1-030617.wisc.cloudlab.us:8042, Resource: <memory:2048, vCores:1>, Priority: 0, Token: Token { kind: ContainerToken, service: 128.104.222.67:46119 }, ] for AM appattempt_1476452954783_0002_000001
2016-10-14 07:51:27,817 INFO org.apache.hadoop.yarn.server.resourcemanager.amlauncher.AMLauncher: Setting up container Container: [ContainerId: container_1476452954783_0001_01_000001, NodeId: cp-2.yarn-perf.yarnrm-PG0.wisc.cloudlab.us:43837, NodeHttpAddress: cp-2.yarn-perf.yarnrm-PG0.wisc.cloudlab.us:8042, Resource: <memory:2048, vCores:1>, Priority: 0, Token: Token { kind: ContainerToken, service: 128.104.222.60:43837 }, ] for AM appattempt_1476452954783_0001_000001
2016-10-14 07:51:27,818 INFO org.apache.hadoop.yarn.server.resourcemanager.amlauncher.AMLauncher: Command to launch container container_1476452954783_0002_01_000001 : {{JAVA_HOME}}/bin/java,-server,-Xmx1536m,-Djava.io.tmpdir={{PWD}}/tmp,-Dspark.yarn.app.container.log.dir=<LOG_DIR>,-XX:MaxPermSize=256m,org.apache.spark.deploy.yarn.ApplicationMaster,--class,'org.apache.spark.examples.SparkPi',--jar,file:/users/tanle/spark-test-cases/../spark/examples/jars/spark-examples_2.11-2.0.0-preview.jar,--arg,'10000',--properties-file,{{PWD}}/__spark_conf__/__spark_conf__.properties,1>,<LOG_DIR>/stdout,2>,<LOG_DIR>/stderr
2016-10-14 07:51:27,818 INFO org.apache.hadoop.yarn.server.resourcemanager.amlauncher.AMLauncher: Command to launch container container_1476452954783_0001_01_000001 : {{JAVA_HOME}}/bin/java,-server,-Xmx1536m,-Djava.io.tmpdir={{PWD}}/tmp,-Dspark.yarn.app.container.log.dir=<LOG_DIR>,-XX:MaxPermSize=256m,org.apache.spark.deploy.yarn.ApplicationMaster,--class,'org.apache.spark.examples.SparkPi',--jar,file:/users/tanle/spark-test-cases/../spark/examples/jars/spark-examples_2.11-2.0.0-preview.jar,--arg,'10000',--properties-file,{{PWD}}/__spark_conf__/__spark_conf__.properties,1>,<LOG_DIR>/stdout,2>,<LOG_DIR>/stderr
2016-10-14 07:51:27,820 INFO org.apache.hadoop.yarn.server.resourcemanager.security.AMRMTokenSecretManager: Create AMRMToken for ApplicationAttempt: appattempt_1476452954783_0002_000001
2016-10-14 07:51:27,825 INFO org.apache.hadoop.yarn.server.resourcemanager.security.AMRMTokenSecretManager: Creating password for appattempt_1476452954783_0002_000001
2016-10-14 07:51:27,825 INFO org.apache.hadoop.yarn.server.resourcemanager.security.AMRMTokenSecretManager: Create AMRMToken for ApplicationAttempt: appattempt_1476452954783_0001_000001
2016-10-14 07:51:27,826 INFO org.apache.hadoop.yarn.server.resourcemanager.security.AMRMTokenSecretManager: Creating password for appattempt_1476452954783_0001_000001
2016-10-14 07:51:27,846 INFO org.apache.hadoop.yarn.server.resourcemanager.scheduler.fair.FSAppAttempt: assignContainer(FSSchedulerNode node:cp-3.yarn-perf.yarnrm-PG0.wisc.cloudlab.us, boolean reserved=false) for appattempt_1476452954783_0001_000001
2016-10-14 07:51:27,846 INFO org.apache.hadoop.yarn.server.resourcemanager.scheduler.fair.FSAppAttempt: assignContainer(FSSchedulerNode node:cp-3.yarn-perf.yarnrm-PG0.wisc.cloudlab.us, boolean reserved=false) for appattempt_1476452954783_0002_000001
2016-10-14 07:51:28,223 INFO org.apache.hadoop.yarn.server.resourcemanager.amlauncher.AMLauncher: Done launching container Container: [ContainerId: container_1476452954783_0002_01_000001, NodeId: c220g1-030617.wisc.cloudlab.us:46119, NodeHttpAddress: c220g1-030617.wisc.cloudlab.us:8042, Resource: <memory:2048, vCores:1>, Priority: 0, Token: Token { kind: ContainerToken, service: 128.104.222.67:46119 }, ] for AM appattempt_1476452954783_0002_000001
2016-10-14 07:51:28,223 INFO org.apache.hadoop.yarn.server.resourcemanager.amlauncher.AMLauncher: Done launching container Container: [ContainerId: container_1476452954783_0001_01_000001, NodeId: cp-2.yarn-perf.yarnrm-PG0.wisc.cloudlab.us:43837, NodeHttpAddress: cp-2.yarn-perf.yarnrm-PG0.wisc.cloudlab.us:8042, Resource: <memory:2048, vCores:1>, Priority: 0, Token: Token { kind: ContainerToken, service: 128.104.222.60:43837 }, ] for AM appattempt_1476452954783_0001_000001
2016-10-14 07:51:28,224 INFO org.apache.hadoop.yarn.server.resourcemanager.rmapp.attempt.RMAppAttemptImpl: appattempt_1476452954783_0002_000001 State change from ALLOCATED to LAUNCHED
2016-10-14 07:51:28,224 INFO org.apache.hadoop.yarn.server.resourcemanager.rmapp.attempt.RMAppAttemptImpl: appattempt_1476452954783_0001_000001 State change from ALLOCATED to LAUNCHED
2016-10-14 07:51:28,671 INFO org.apache.hadoop.yarn.server.resourcemanager.rmcontainer.RMContainerImpl: Processing container_1476452954783_0002_01_000001 of event LAUNCHED
2016-10-14 07:51:28,672 INFO org.apache.hadoop.yarn.server.resourcemanager.rmcontainer.RMContainerImpl: container_1476452954783_0002_01_000001 Container Transitioned from ACQUIRED to RUNNING
2016-10-14 07:51:28,673 INFO org.apache.hadoop.yarn.server.resourcemanager.scheduler.fair.FSAppAttempt: assignContainer(FSSchedulerNode node:c220g1-030617.wisc.cloudlab.us, boolean reserved=false) for appattempt_1476452954783_0001_000001
2016-10-14 07:51:28,673 INFO org.apache.hadoop.yarn.server.resourcemanager.scheduler.fair.FSAppAttempt: assignContainer(FSSchedulerNode node:c220g1-030617.wisc.cloudlab.us, boolean reserved=false) for appattempt_1476452954783_0002_000001
2016-10-14 07:51:28,674 INFO org.apache.hadoop.yarn.server.resourcemanager.rmcontainer.RMContainerImpl: Processing container_1476452954783_0001_01_000001 of event LAUNCHED
2016-10-14 07:51:28,674 INFO org.apache.hadoop.yarn.server.resourcemanager.rmcontainer.RMContainerImpl: container_1476452954783_0001_01_000001 Container Transitioned from ACQUIRED to RUNNING
2016-10-14 07:51:28,675 INFO org.apache.hadoop.yarn.server.resourcemanager.scheduler.fair.FSAppAttempt: assignContainer(FSSchedulerNode node:cp-2.yarn-perf.yarnrm-PG0.wisc.cloudlab.us, boolean reserved=false) for appattempt_1476452954783_0001_000001
2016-10-14 07:51:28,675 INFO org.apache.hadoop.yarn.server.resourcemanager.scheduler.fair.FSAppAttempt: assignContainer(FSSchedulerNode node:cp-2.yarn-perf.yarnrm-PG0.wisc.cloudlab.us, boolean reserved=false) for appattempt_1476452954783_0002_000001
2016-10-14 07:51:28,788 INFO org.apache.hadoop.yarn.server.resourcemanager.scheduler.fair.FSAppAttempt: assignContainer(FSSchedulerNode node:cp-1.yarn-perf.yarnrm-PG0.wisc.cloudlab.us, boolean reserved=false) for appattempt_1476452954783_0001_000001
2016-10-14 07:51:28,788 INFO org.apache.hadoop.yarn.server.resourcemanager.scheduler.fair.FSAppAttempt: assignContainer(FSSchedulerNode node:cp-1.yarn-perf.yarnrm-PG0.wisc.cloudlab.us, boolean reserved=false) for appattempt_1476452954783_0002_000001
2016-10-14 07:51:28,849 INFO org.apache.hadoop.yarn.server.resourcemanager.scheduler.fair.FSAppAttempt: assignContainer(FSSchedulerNode node:cp-3.yarn-perf.yarnrm-PG0.wisc.cloudlab.us, boolean reserved=false) for appattempt_1476452954783_0001_000001
2016-10-14 07:51:28,849 INFO org.apache.hadoop.yarn.server.resourcemanager.scheduler.fair.FSAppAttempt: assignContainer(FSSchedulerNode node:cp-3.yarn-perf.yarnrm-PG0.wisc.cloudlab.us, boolean reserved=false) for appattempt_1476452954783_0002_000001
2016-10-14 07:51:29,673 INFO org.apache.hadoop.yarn.server.resourcemanager.scheduler.fair.FSAppAttempt: assignContainer(FSSchedulerNode node:cp-2.yarn-perf.yarnrm-PG0.wisc.cloudlab.us, boolean reserved=false) for appattempt_1476452954783_0001_000001
2016-10-14 07:51:29,673 INFO org.apache.hadoop.yarn.server.resourcemanager.scheduler.fair.FSAppAttempt: assignContainer(FSSchedulerNode node:cp-2.yarn-perf.yarnrm-PG0.wisc.cloudlab.us, boolean reserved=false) for appattempt_1476452954783_0002_000001
2016-10-14 07:51:29,675 INFO org.apache.hadoop.yarn.server.resourcemanager.scheduler.fair.FSAppAttempt: assignContainer(FSSchedulerNode node:c220g1-030617.wisc.cloudlab.us, boolean reserved=false) for appattempt_1476452954783_0001_000001
2016-10-14 07:51:29,675 INFO org.apache.hadoop.yarn.server.resourcemanager.scheduler.fair.FSAppAttempt: assignContainer(FSSchedulerNode node:c220g1-030617.wisc.cloudlab.us, boolean reserved=false) for appattempt_1476452954783_0002_000001
2016-10-14 07:51:29,790 INFO org.apache.hadoop.yarn.server.resourcemanager.scheduler.fair.FSAppAttempt: assignContainer(FSSchedulerNode node:cp-1.yarn-perf.yarnrm-PG0.wisc.cloudlab.us, boolean reserved=false) for appattempt_1476452954783_0001_000001
2016-10-14 07:51:29,790 INFO org.apache.hadoop.yarn.server.resourcemanager.scheduler.fair.FSAppAttempt: assignContainer(FSSchedulerNode node:cp-1.yarn-perf.yarnrm-PG0.wisc.cloudlab.us, boolean reserved=false) for appattempt_1476452954783_0002_000001
2016-10-14 07:51:29,851 INFO org.apache.hadoop.yarn.server.resourcemanager.scheduler.fair.FSAppAttempt: assignContainer(FSSchedulerNode node:cp-3.yarn-perf.yarnrm-PG0.wisc.cloudlab.us, boolean reserved=false) for appattempt_1476452954783_0001_000001
2016-10-14 07:51:29,851 INFO org.apache.hadoop.yarn.server.resourcemanager.scheduler.fair.FSAppAttempt: assignContainer(FSSchedulerNode node:cp-3.yarn-perf.yarnrm-PG0.wisc.cloudlab.us, boolean reserved=false) for appattempt_1476452954783_0002_000001
2016-10-14 07:51:30,675 INFO org.apache.hadoop.yarn.server.resourcemanager.scheduler.fair.FSAppAttempt: assignContainer(FSSchedulerNode node:cp-2.yarn-perf.yarnrm-PG0.wisc.cloudlab.us, boolean reserved=false) for appattempt_1476452954783_0001_000001
2016-10-14 07:51:30,676 INFO org.apache.hadoop.yarn.server.resourcemanager.scheduler.fair.FSAppAttempt: assignContainer(FSSchedulerNode node:cp-2.yarn-perf.yarnrm-PG0.wisc.cloudlab.us, boolean reserved=false) for appattempt_1476452954783_0002_000001
2016-10-14 07:51:30,677 INFO org.apache.hadoop.yarn.server.resourcemanager.scheduler.fair.FSAppAttempt: assignContainer(FSSchedulerNode node:c220g1-030617.wisc.cloudlab.us, boolean reserved=false) for appattempt_1476452954783_0001_000001
2016-10-14 07:51:30,677 INFO org.apache.hadoop.yarn.server.resourcemanager.scheduler.fair.FSAppAttempt: assignContainer(FSSchedulerNode node:c220g1-030617.wisc.cloudlab.us, boolean reserved=false) for appattempt_1476452954783_0002_000001
2016-10-14 07:51:30,793 INFO org.apache.hadoop.yarn.server.resourcemanager.scheduler.fair.FSAppAttempt: assignContainer(FSSchedulerNode node:cp-1.yarn-perf.yarnrm-PG0.wisc.cloudlab.us, boolean reserved=false) for appattempt_1476452954783_0001_000001
2016-10-14 07:51:30,793 INFO org.apache.hadoop.yarn.server.resourcemanager.scheduler.fair.FSAppAttempt: assignContainer(FSSchedulerNode node:cp-1.yarn-perf.yarnrm-PG0.wisc.cloudlab.us, boolean reserved=false) for appattempt_1476452954783_0002_000001
2016-10-14 07:51:30,853 INFO org.apache.hadoop.yarn.server.resourcemanager.scheduler.fair.FSAppAttempt: assignContainer(FSSchedulerNode node:cp-3.yarn-perf.yarnrm-PG0.wisc.cloudlab.us, boolean reserved=false) for appattempt_1476452954783_0001_000001
2016-10-14 07:51:30,853 INFO org.apache.hadoop.yarn.server.resourcemanager.scheduler.fair.FSAppAttempt: assignContainer(FSSchedulerNode node:cp-3.yarn-perf.yarnrm-PG0.wisc.cloudlab.us, boolean reserved=false) for appattempt_1476452954783_0002_000001
2016-10-14 07:51:31,678 INFO org.apache.hadoop.yarn.server.resourcemanager.scheduler.fair.FSAppAttempt: assignContainer(FSSchedulerNode node:c220g1-030617.wisc.cloudlab.us, boolean reserved=false) for appattempt_1476452954783_0001_000001
2016-10-14 07:51:31,679 INFO org.apache.hadoop.yarn.server.resourcemanager.scheduler.fair.FSAppAttempt: assignContainer(FSSchedulerNode node:c220g1-030617.wisc.cloudlab.us, boolean reserved=false) for appattempt_1476452954783_0002_000001
2016-10-14 07:51:31,680 INFO org.apache.hadoop.yarn.server.resourcemanager.scheduler.fair.FSAppAttempt: assignContainer(FSSchedulerNode node:cp-2.yarn-perf.yarnrm-PG0.wisc.cloudlab.us, boolean reserved=false) for appattempt_1476452954783_0001_000001
2016-10-14 07:51:31,680 INFO org.apache.hadoop.yarn.server.resourcemanager.scheduler.fair.FSAppAttempt: assignContainer(FSSchedulerNode node:cp-2.yarn-perf.yarnrm-PG0.wisc.cloudlab.us, boolean reserved=false) for appattempt_1476452954783_0002_000001
2016-10-14 07:51:31,795 INFO org.apache.hadoop.yarn.server.resourcemanager.scheduler.fair.FSAppAttempt: assignContainer(FSSchedulerNode node:cp-1.yarn-perf.yarnrm-PG0.wisc.cloudlab.us, boolean reserved=false) for appattempt_1476452954783_0001_000001
2016-10-14 07:51:31,795 INFO org.apache.hadoop.yarn.server.resourcemanager.scheduler.fair.FSAppAttempt: assignContainer(FSSchedulerNode node:cp-1.yarn-perf.yarnrm-PG0.wisc.cloudlab.us, boolean reserved=false) for appattempt_1476452954783_0002_000001
2016-10-14 07:51:31,855 INFO org.apache.hadoop.yarn.server.resourcemanager.scheduler.fair.FSAppAttempt: assignContainer(FSSchedulerNode node:cp-3.yarn-perf.yarnrm-PG0.wisc.cloudlab.us, boolean reserved=false) for appattempt_1476452954783_0001_000001
2016-10-14 07:51:31,856 INFO org.apache.hadoop.yarn.server.resourcemanager.scheduler.fair.FSAppAttempt: assignContainer(FSSchedulerNode node:cp-3.yarn-perf.yarnrm-PG0.wisc.cloudlab.us, boolean reserved=false) for appattempt_1476452954783_0002_000001
2016-10-14 07:51:32,681 INFO org.apache.hadoop.yarn.server.resourcemanager.scheduler.fair.FSAppAttempt: assignContainer(FSSchedulerNode node:cp-2.yarn-perf.yarnrm-PG0.wisc.cloudlab.us, boolean reserved=false) for appattempt_1476452954783_0001_000001
2016-10-14 07:51:32,681 INFO org.apache.hadoop.yarn.server.resourcemanager.scheduler.fair.FSAppAttempt: assignContainer(FSSchedulerNode node:cp-2.yarn-perf.yarnrm-PG0.wisc.cloudlab.us, boolean reserved=false) for appattempt_1476452954783_0002_000001
2016-10-14 07:51:32,683 INFO org.apache.hadoop.yarn.server.resourcemanager.scheduler.fair.FSAppAttempt: assignContainer(FSSchedulerNode node:c220g1-030617.wisc.cloudlab.us, boolean reserved=false) for appattempt_1476452954783_0001_000001
2016-10-14 07:51:32,683 INFO org.apache.hadoop.yarn.server.resourcemanager.scheduler.fair.FSAppAttempt: assignContainer(FSSchedulerNode node:c220g1-030617.wisc.cloudlab.us, boolean reserved=false) for appattempt_1476452954783_0002_000001
2016-10-14 07:51:32,798 INFO org.apache.hadoop.yarn.server.resourcemanager.scheduler.fair.FSAppAttempt: assignContainer(FSSchedulerNode node:cp-1.yarn-perf.yarnrm-PG0.wisc.cloudlab.us, boolean reserved=false) for appattempt_1476452954783_0001_000001
2016-10-14 07:51:32,798 INFO org.apache.hadoop.yarn.server.resourcemanager.scheduler.fair.FSAppAttempt: assignContainer(FSSchedulerNode node:cp-1.yarn-perf.yarnrm-PG0.wisc.cloudlab.us, boolean reserved=false) for appattempt_1476452954783_0002_000001
2016-10-14 07:51:32,858 INFO org.apache.hadoop.yarn.server.resourcemanager.scheduler.fair.FSAppAttempt: assignContainer(FSSchedulerNode node:cp-3.yarn-perf.yarnrm-PG0.wisc.cloudlab.us, boolean reserved=false) for appattempt_1476452954783_0001_000001
2016-10-14 07:51:32,859 INFO org.apache.hadoop.yarn.server.resourcemanager.scheduler.fair.FSAppAttempt: assignContainer(FSSchedulerNode node:cp-3.yarn-perf.yarnrm-PG0.wisc.cloudlab.us, boolean reserved=false) for appattempt_1476452954783_0002_000001
2016-10-14 07:51:33,685 INFO org.apache.hadoop.yarn.server.resourcemanager.scheduler.fair.FSAppAttempt: assignContainer(FSSchedulerNode node:c220g1-030617.wisc.cloudlab.us, boolean reserved=false) for appattempt_1476452954783_0001_000001
2016-10-14 07:51:33,685 INFO org.apache.hadoop.yarn.server.resourcemanager.scheduler.fair.FSAppAttempt: assignContainer(FSSchedulerNode node:c220g1-030617.wisc.cloudlab.us, boolean reserved=false) for appattempt_1476452954783_0002_000001
2016-10-14 07:51:33,686 INFO org.apache.hadoop.yarn.server.resourcemanager.scheduler.fair.FSAppAttempt: assignContainer(FSSchedulerNode node:cp-2.yarn-perf.yarnrm-PG0.wisc.cloudlab.us, boolean reserved=false) for appattempt_1476452954783_0001_000001
2016-10-14 07:51:33,687 INFO org.apache.hadoop.yarn.server.resourcemanager.scheduler.fair.FSAppAttempt: assignContainer(FSSchedulerNode node:cp-2.yarn-perf.yarnrm-PG0.wisc.cloudlab.us, boolean reserved=false) for appattempt_1476452954783_0002_000001
2016-10-14 07:51:33,800 INFO org.apache.hadoop.yarn.server.resourcemanager.scheduler.fair.FSAppAttempt: assignContainer(FSSchedulerNode node:cp-1.yarn-perf.yarnrm-PG0.wisc.cloudlab.us, boolean reserved=false) for appattempt_1476452954783_0001_000001
2016-10-14 07:51:33,801 INFO org.apache.hadoop.yarn.server.resourcemanager.scheduler.fair.FSAppAttempt: assignContainer(FSSchedulerNode node:cp-1.yarn-perf.yarnrm-PG0.wisc.cloudlab.us, boolean reserved=false) for appattempt_1476452954783_0002_000001
2016-10-14 07:51:33,861 INFO org.apache.hadoop.yarn.server.resourcemanager.scheduler.fair.FSAppAttempt: assignContainer(FSSchedulerNode node:cp-3.yarn-perf.yarnrm-PG0.wisc.cloudlab.us, boolean reserved=false) for appattempt_1476452954783_0001_000001
2016-10-14 07:51:33,861 INFO org.apache.hadoop.yarn.server.resourcemanager.scheduler.fair.FSAppAttempt: assignContainer(FSSchedulerNode node:cp-3.yarn-perf.yarnrm-PG0.wisc.cloudlab.us, boolean reserved=false) for appattempt_1476452954783_0002_000001
2016-10-14 07:51:34,183 INFO org.apache.hadoop.yarn.server.resourcemanager.ClientRMService: Allocated new applicationId: 3
2016-10-14 07:51:34,795 INFO org.apache.hadoop.yarn.server.resourcemanager.scheduler.fair.FSAppAttempt: assignContainer(FSSchedulerNode node:c220g1-030617.wisc.cloudlab.us, boolean reserved=false) for appattempt_1476452954783_0001_000001
2016-10-14 07:51:34,796 INFO org.apache.hadoop.yarn.server.resourcemanager.scheduler.fair.FSAppAttempt: assignContainer(FSSchedulerNode node:c220g1-030617.wisc.cloudlab.us, boolean reserved=false) for appattempt_1476452954783_0002_000001
2016-10-14 07:51:34,797 INFO org.apache.hadoop.yarn.server.resourcemanager.scheduler.fair.FSAppAttempt: assignContainer(FSSchedulerNode node:cp-2.yarn-perf.yarnrm-PG0.wisc.cloudlab.us, boolean reserved=false) for appattempt_1476452954783_0001_000001
2016-10-14 07:51:34,797 INFO org.apache.hadoop.yarn.server.resourcemanager.scheduler.fair.FSAppAttempt: assignContainer(FSSchedulerNode node:cp-2.yarn-perf.yarnrm-PG0.wisc.cloudlab.us, boolean reserved=false) for appattempt_1476452954783_0002_000001
2016-10-14 07:51:34,803 INFO org.apache.hadoop.yarn.server.resourcemanager.scheduler.fair.FSAppAttempt: assignContainer(FSSchedulerNode node:cp-1.yarn-perf.yarnrm-PG0.wisc.cloudlab.us, boolean reserved=false) for appattempt_1476452954783_0001_000001
2016-10-14 07:51:34,803 INFO org.apache.hadoop.yarn.server.resourcemanager.scheduler.fair.FSAppAttempt: assignContainer(FSSchedulerNode node:cp-1.yarn-perf.yarnrm-PG0.wisc.cloudlab.us, boolean reserved=false) for appattempt_1476452954783_0002_000001
2016-10-14 07:51:34,864 INFO org.apache.hadoop.yarn.server.resourcemanager.scheduler.fair.FSAppAttempt: assignContainer(FSSchedulerNode node:cp-3.yarn-perf.yarnrm-PG0.wisc.cloudlab.us, boolean reserved=false) for appattempt_1476452954783_0001_000001
2016-10-14 07:51:34,864 INFO org.apache.hadoop.yarn.server.resourcemanager.scheduler.fair.FSAppAttempt: assignContainer(FSSchedulerNode node:cp-3.yarn-perf.yarnrm-PG0.wisc.cloudlab.us, boolean reserved=false) for appattempt_1476452954783_0002_000001
2016-10-14 07:51:35,690 INFO org.apache.hadoop.yarn.server.resourcemanager.scheduler.fair.FSAppAttempt: assignContainer(FSSchedulerNode node:c220g1-030617.wisc.cloudlab.us, boolean reserved=false) for appattempt_1476452954783_0001_000001
2016-10-14 07:51:35,690 INFO org.apache.hadoop.yarn.server.resourcemanager.scheduler.fair.FSAppAttempt: assignContainer(FSSchedulerNode node:c220g1-030617.wisc.cloudlab.us, boolean reserved=false) for appattempt_1476452954783_0002_000001
2016-10-14 07:51:35,692 INFO org.apache.hadoop.yarn.server.resourcemanager.scheduler.fair.FSAppAttempt: assignContainer(FSSchedulerNode node:cp-2.yarn-perf.yarnrm-PG0.wisc.cloudlab.us, boolean reserved=false) for appattempt_1476452954783_0001_000001
2016-10-14 07:51:35,692 INFO org.apache.hadoop.yarn.server.resourcemanager.scheduler.fair.FSAppAttempt: assignContainer(FSSchedulerNode node:cp-2.yarn-perf.yarnrm-PG0.wisc.cloudlab.us, boolean reserved=false) for appattempt_1476452954783_0002_000001
2016-10-14 07:51:35,805 INFO org.apache.hadoop.yarn.server.resourcemanager.scheduler.fair.FSAppAttempt: assignContainer(FSSchedulerNode node:cp-1.yarn-perf.yarnrm-PG0.wisc.cloudlab.us, boolean reserved=false) for appattempt_1476452954783_0001_000001
2016-10-14 07:51:35,806 INFO org.apache.hadoop.yarn.server.resourcemanager.scheduler.fair.FSAppAttempt: assignContainer(FSSchedulerNode node:cp-1.yarn-perf.yarnrm-PG0.wisc.cloudlab.us, boolean reserved=false) for appattempt_1476452954783_0002_000001
2016-10-14 07:51:35,866 INFO org.apache.hadoop.yarn.server.resourcemanager.scheduler.fair.FSAppAttempt: assignContainer(FSSchedulerNode node:cp-3.yarn-perf.yarnrm-PG0.wisc.cloudlab.us, boolean reserved=false) for appattempt_1476452954783_0001_000001
2016-10-14 07:51:35,867 INFO org.apache.hadoop.yarn.server.resourcemanager.scheduler.fair.FSAppAttempt: assignContainer(FSSchedulerNode node:cp-3.yarn-perf.yarnrm-PG0.wisc.cloudlab.us, boolean reserved=false) for appattempt_1476452954783_0002_000001
2016-10-14 07:51:36,693 INFO org.apache.hadoop.yarn.server.resourcemanager.scheduler.fair.FSAppAttempt: assignContainer(FSSchedulerNode node:c220g1-030617.wisc.cloudlab.us, boolean reserved=false) for appattempt_1476452954783_0001_000001
2016-10-14 07:51:36,693 INFO org.apache.hadoop.yarn.server.resourcemanager.scheduler.fair.FSAppAttempt: assignContainer(FSSchedulerNode node:c220g1-030617.wisc.cloudlab.us, boolean reserved=false) for appattempt_1476452954783_0002_000001
2016-10-14 07:51:36,694 INFO org.apache.hadoop.yarn.server.resourcemanager.scheduler.fair.FSAppAttempt: assignContainer(FSSchedulerNode node:cp-2.yarn-perf.yarnrm-PG0.wisc.cloudlab.us, boolean reserved=false) for appattempt_1476452954783_0001_000001
2016-10-14 07:51:36,695 INFO org.apache.hadoop.yarn.server.resourcemanager.scheduler.fair.FSAppAttempt: assignContainer(FSSchedulerNode node:cp-2.yarn-perf.yarnrm-PG0.wisc.cloudlab.us, boolean reserved=false) for appattempt_1476452954783_0002_000001
2016-10-14 07:51:36,808 INFO org.apache.hadoop.yarn.server.resourcemanager.scheduler.fair.FSAppAttempt: assignContainer(FSSchedulerNode node:cp-1.yarn-perf.yarnrm-PG0.wisc.cloudlab.us, boolean reserved=false) for appattempt_1476452954783_0001_000001
2016-10-14 07:51:36,808 INFO org.apache.hadoop.yarn.server.resourcemanager.scheduler.fair.FSAppAttempt: assignContainer(FSSchedulerNode node:cp-1.yarn-perf.yarnrm-PG0.wisc.cloudlab.us, boolean reserved=false) for appattempt_1476452954783_0002_000001
2016-10-14 07:51:36,869 INFO org.apache.hadoop.yarn.server.resourcemanager.scheduler.fair.FSAppAttempt: assignContainer(FSSchedulerNode node:cp-3.yarn-perf.yarnrm-PG0.wisc.cloudlab.us, boolean reserved=false) for appattempt_1476452954783_0001_000001
2016-10-14 07:51:36,869 INFO org.apache.hadoop.yarn.server.resourcemanager.scheduler.fair.FSAppAttempt: assignContainer(FSSchedulerNode node:cp-3.yarn-perf.yarnrm-PG0.wisc.cloudlab.us, boolean reserved=false) for appattempt_1476452954783_0002_000001
2016-10-14 07:51:37,695 INFO org.apache.hadoop.yarn.server.resourcemanager.scheduler.fair.FSAppAttempt: assignContainer(FSSchedulerNode node:c220g1-030617.wisc.cloudlab.us, boolean reserved=false) for appattempt_1476452954783_0001_000001
2016-10-14 07:51:37,696 INFO org.apache.hadoop.yarn.server.resourcemanager.scheduler.fair.FSAppAttempt: assignContainer(FSSchedulerNode node:c220g1-030617.wisc.cloudlab.us, boolean reserved=false) for appattempt_1476452954783_0002_000001
2016-10-14 07:51:37,697 INFO org.apache.hadoop.yarn.server.resourcemanager.scheduler.fair.FSAppAttempt: assignContainer(FSSchedulerNode node:cp-2.yarn-perf.yarnrm-PG0.wisc.cloudlab.us, boolean reserved=false) for appattempt_1476452954783_0001_000001
2016-10-14 07:51:37,697 INFO org.apache.hadoop.yarn.server.resourcemanager.scheduler.fair.FSAppAttempt: assignContainer(FSSchedulerNode node:cp-2.yarn-perf.yarnrm-PG0.wisc.cloudlab.us, boolean reserved=false) for appattempt_1476452954783_0002_000001
2016-10-14 07:51:37,810 INFO org.apache.hadoop.yarn.server.resourcemanager.scheduler.fair.FSAppAttempt: assignContainer(FSSchedulerNode node:cp-1.yarn-perf.yarnrm-PG0.wisc.cloudlab.us, boolean reserved=false) for appattempt_1476452954783_0001_000001
2016-10-14 07:51:37,811 INFO org.apache.hadoop.yarn.server.resourcemanager.scheduler.fair.FSAppAttempt: assignContainer(FSSchedulerNode node:cp-1.yarn-perf.yarnrm-PG0.wisc.cloudlab.us, boolean reserved=false) for appattempt_1476452954783_0002_000001
2016-10-14 07:51:37,872 INFO org.apache.hadoop.yarn.server.resourcemanager.scheduler.fair.FSAppAttempt: assignContainer(FSSchedulerNode node:cp-3.yarn-perf.yarnrm-PG0.wisc.cloudlab.us, boolean reserved=false) for appattempt_1476452954783_0001_000001
2016-10-14 07:51:37,872 INFO org.apache.hadoop.yarn.server.resourcemanager.scheduler.fair.FSAppAttempt: assignContainer(FSSchedulerNode node:cp-3.yarn-perf.yarnrm-PG0.wisc.cloudlab.us, boolean reserved=false) for appattempt_1476452954783_0002_000001
2016-10-14 07:51:38,698 INFO org.apache.hadoop.yarn.server.resourcemanager.scheduler.fair.FSAppAttempt: assignContainer(FSSchedulerNode node:c220g1-030617.wisc.cloudlab.us, boolean reserved=false) for appattempt_1476452954783_0001_000001
2016-10-14 07:51:38,698 INFO org.apache.hadoop.yarn.server.resourcemanager.scheduler.fair.FSAppAttempt: assignContainer(FSSchedulerNode node:c220g1-030617.wisc.cloudlab.us, boolean reserved=false) for appattempt_1476452954783_0002_000001
2016-10-14 07:51:38,700 INFO org.apache.hadoop.yarn.server.resourcemanager.scheduler.fair.FSAppAttempt: assignContainer(FSSchedulerNode node:cp-2.yarn-perf.yarnrm-PG0.wisc.cloudlab.us, boolean reserved=false) for appattempt_1476452954783_0001_000001
2016-10-14 07:51:38,700 INFO org.apache.hadoop.yarn.server.resourcemanager.scheduler.fair.FSAppAttempt: assignContainer(FSSchedulerNode node:cp-2.yarn-perf.yarnrm-PG0.wisc.cloudlab.us, boolean reserved=false) for appattempt_1476452954783_0002_000001
2016-10-14 07:51:38,813 INFO org.apache.hadoop.yarn.server.resourcemanager.scheduler.fair.FSAppAttempt: assignContainer(FSSchedulerNode node:cp-1.yarn-perf.yarnrm-PG0.wisc.cloudlab.us, boolean reserved=false) for appattempt_1476452954783_0001_000001
2016-10-14 07:51:38,813 INFO org.apache.hadoop.yarn.server.resourcemanager.scheduler.fair.FSAppAttempt: assignContainer(FSSchedulerNode node:cp-1.yarn-perf.yarnrm-PG0.wisc.cloudlab.us, boolean reserved=false) for appattempt_1476452954783_0002_000001
2016-10-14 07:51:38,874 INFO org.apache.hadoop.yarn.server.resourcemanager.scheduler.fair.FSAppAttempt: assignContainer(FSSchedulerNode node:cp-3.yarn-perf.yarnrm-PG0.wisc.cloudlab.us, boolean reserved=false) for appattempt_1476452954783_0001_000001
2016-10-14 07:51:38,874 INFO org.apache.hadoop.yarn.server.resourcemanager.scheduler.fair.FSAppAttempt: assignContainer(FSSchedulerNode node:cp-3.yarn-perf.yarnrm-PG0.wisc.cloudlab.us, boolean reserved=false) for appattempt_1476452954783_0002_000001
2016-10-14 07:51:39,700 INFO org.apache.hadoop.yarn.server.resourcemanager.scheduler.fair.FSAppAttempt: assignContainer(FSSchedulerNode node:cp-2.yarn-perf.yarnrm-PG0.wisc.cloudlab.us, boolean reserved=false) for appattempt_1476452954783_0001_000001
2016-10-14 07:51:39,700 INFO org.apache.hadoop.yarn.server.resourcemanager.scheduler.fair.FSAppAttempt: assignContainer(FSSchedulerNode node:cp-2.yarn-perf.yarnrm-PG0.wisc.cloudlab.us, boolean reserved=false) for appattempt_1476452954783_0002_000001
2016-10-14 07:51:39,701 INFO org.apache.hadoop.yarn.server.resourcemanager.scheduler.fair.FSAppAttempt: assignContainer(FSSchedulerNode node:c220g1-030617.wisc.cloudlab.us, boolean reserved=false) for appattempt_1476452954783_0001_000001
2016-10-14 07:51:39,701 INFO org.apache.hadoop.yarn.server.resourcemanager.scheduler.fair.FSAppAttempt: assignContainer(FSSchedulerNode node:c220g1-030617.wisc.cloudlab.us, boolean reserved=false) for appattempt_1476452954783_0002_000001
2016-10-14 07:51:39,815 INFO org.apache.hadoop.yarn.server.resourcemanager.scheduler.fair.FSAppAttempt: assignContainer(FSSchedulerNode node:cp-1.yarn-perf.yarnrm-PG0.wisc.cloudlab.us, boolean reserved=false) for appattempt_1476452954783_0001_000001
2016-10-14 07:51:39,815 INFO org.apache.hadoop.yarn.server.resourcemanager.scheduler.fair.FSAppAttempt: assignContainer(FSSchedulerNode node:cp-1.yarn-perf.yarnrm-PG0.wisc.cloudlab.us, boolean reserved=false) for appattempt_1476452954783_0002_000001
2016-10-14 07:51:39,877 INFO org.apache.hadoop.yarn.server.resourcemanager.scheduler.fair.FSAppAttempt: assignContainer(FSSchedulerNode node:cp-3.yarn-perf.yarnrm-PG0.wisc.cloudlab.us, boolean reserved=false) for appattempt_1476452954783_0001_000001
2016-10-14 07:51:39,877 INFO org.apache.hadoop.yarn.server.resourcemanager.scheduler.fair.FSAppAttempt: assignContainer(FSSchedulerNode node:cp-3.yarn-perf.yarnrm-PG0.wisc.cloudlab.us, boolean reserved=false) for appattempt_1476452954783_0002_000001
2016-10-14 07:51:40,703 INFO org.apache.hadoop.yarn.server.resourcemanager.scheduler.fair.FSAppAttempt: assignContainer(FSSchedulerNode node:cp-2.yarn-perf.yarnrm-PG0.wisc.cloudlab.us, boolean reserved=false) for appattempt_1476452954783_0001_000001
2016-10-14 07:51:40,703 INFO org.apache.hadoop.yarn.server.resourcemanager.scheduler.fair.FSAppAttempt: assignContainer(FSSchedulerNode node:cp-2.yarn-perf.yarnrm-PG0.wisc.cloudlab.us, boolean reserved=false) for appattempt_1476452954783_0002_000001
2016-10-14 07:51:40,705 INFO org.apache.hadoop.yarn.server.resourcemanager.scheduler.fair.FSAppAttempt: assignContainer(FSSchedulerNode node:c220g1-030617.wisc.cloudlab.us, boolean reserved=false) for appattempt_1476452954783_0001_000001
2016-10-14 07:51:40,705 INFO org.apache.hadoop.yarn.server.resourcemanager.scheduler.fair.FSAppAttempt: assignContainer(FSSchedulerNode node:c220g1-030617.wisc.cloudlab.us, boolean reserved=false) for appattempt_1476452954783_0002_000001
2016-10-14 07:51:40,817 INFO org.apache.hadoop.yarn.server.resourcemanager.scheduler.fair.FSAppAttempt: assignContainer(FSSchedulerNode node:cp-1.yarn-perf.yarnrm-PG0.wisc.cloudlab.us, boolean reserved=false) for appattempt_1476452954783_0001_000001
2016-10-14 07:51:40,818 INFO org.apache.hadoop.yarn.server.resourcemanager.scheduler.fair.FSAppAttempt: assignContainer(FSSchedulerNode node:cp-1.yarn-perf.yarnrm-PG0.wisc.cloudlab.us, boolean reserved=false) for appattempt_1476452954783_0002_000001
2016-10-14 07:51:40,879 INFO org.apache.hadoop.yarn.server.resourcemanager.scheduler.fair.FSAppAttempt: assignContainer(FSSchedulerNode node:cp-3.yarn-perf.yarnrm-PG0.wisc.cloudlab.us, boolean reserved=false) for appattempt_1476452954783_0001_000001
2016-10-14 07:51:40,879 INFO org.apache.hadoop.yarn.server.resourcemanager.scheduler.fair.FSAppAttempt: assignContainer(FSSchedulerNode node:cp-3.yarn-perf.yarnrm-PG0.wisc.cloudlab.us, boolean reserved=false) for appattempt_1476452954783_0002_000001
2016-10-14 07:51:41,706 INFO org.apache.hadoop.yarn.server.resourcemanager.scheduler.fair.FSAppAttempt: assignContainer(FSSchedulerNode node:cp-2.yarn-perf.yarnrm-PG0.wisc.cloudlab.us, boolean reserved=false) for appattempt_1476452954783_0001_000001
2016-10-14 07:51:41,706 INFO org.apache.hadoop.yarn.server.resourcemanager.scheduler.fair.FSAppAttempt: assignContainer(FSSchedulerNode node:cp-2.yarn-perf.yarnrm-PG0.wisc.cloudlab.us, boolean reserved=false) for appattempt_1476452954783_0002_000001
2016-10-14 07:51:41,708 INFO org.apache.hadoop.yarn.server.resourcemanager.scheduler.fair.FSAppAttempt: assignContainer(FSSchedulerNode node:c220g1-030617.wisc.cloudlab.us, boolean reserved=false) for appattempt_1476452954783_0001_000001
2016-10-14 07:51:41,708 INFO org.apache.hadoop.yarn.server.resourcemanager.scheduler.fair.FSAppAttempt: assignContainer(FSSchedulerNode node:c220g1-030617.wisc.cloudlab.us, boolean reserved=false) for appattempt_1476452954783_0002_000001
2016-10-14 07:51:41,819 INFO org.apache.hadoop.yarn.server.resourcemanager.scheduler.fair.FSAppAttempt: assignContainer(FSSchedulerNode node:cp-1.yarn-perf.yarnrm-PG0.wisc.cloudlab.us, boolean reserved=false) for appattempt_1476452954783_0001_000001
2016-10-14 07:51:41,820 INFO org.apache.hadoop.yarn.server.resourcemanager.scheduler.fair.FSAppAttempt: assignContainer(FSSchedulerNode node:cp-1.yarn-perf.yarnrm-PG0.wisc.cloudlab.us, boolean reserved=false) for appattempt_1476452954783_0002_000001
2016-10-14 07:51:41,882 INFO org.apache.hadoop.yarn.server.resourcemanager.scheduler.fair.FSAppAttempt: assignContainer(FSSchedulerNode node:cp-3.yarn-perf.yarnrm-PG0.wisc.cloudlab.us, boolean reserved=false) for appattempt_1476452954783_0001_000001
2016-10-14 07:51:41,882 INFO org.apache.hadoop.yarn.server.resourcemanager.scheduler.fair.FSAppAttempt: assignContainer(FSSchedulerNode node:cp-3.yarn-perf.yarnrm-PG0.wisc.cloudlab.us, boolean reserved=false) for appattempt_1476452954783_0002_000001
2016-10-14 07:51:42,708 INFO org.apache.hadoop.yarn.server.resourcemanager.scheduler.fair.FSAppAttempt: assignContainer(FSSchedulerNode node:cp-2.yarn-perf.yarnrm-PG0.wisc.cloudlab.us, boolean reserved=false) for appattempt_1476452954783_0001_000001
2016-10-14 07:51:42,708 INFO org.apache.hadoop.yarn.server.resourcemanager.scheduler.fair.FSAppAttempt: assignContainer(FSSchedulerNode node:cp-2.yarn-perf.yarnrm-PG0.wisc.cloudlab.us, boolean reserved=false) for appattempt_1476452954783_0002_000001
2016-10-14 07:51:42,710 INFO org.apache.hadoop.yarn.server.resourcemanager.scheduler.fair.FSAppAttempt: assignContainer(FSSchedulerNode node:c220g1-030617.wisc.cloudlab.us, boolean reserved=false) for appattempt_1476452954783_0001_000001
2016-10-14 07:51:42,710 INFO org.apache.hadoop.yarn.server.resourcemanager.scheduler.fair.FSAppAttempt: assignContainer(FSSchedulerNode node:c220g1-030617.wisc.cloudlab.us, boolean reserved=false) for appattempt_1476452954783_0002_000001
2016-10-14 07:51:42,822 INFO org.apache.hadoop.yarn.server.resourcemanager.scheduler.fair.FSAppAttempt: assignContainer(FSSchedulerNode node:cp-1.yarn-perf.yarnrm-PG0.wisc.cloudlab.us, boolean reserved=false) for appattempt_1476452954783_0001_000001
2016-10-14 07:51:42,822 INFO org.apache.hadoop.yarn.server.resourcemanager.scheduler.fair.FSAppAttempt: assignContainer(FSSchedulerNode node:cp-1.yarn-perf.yarnrm-PG0.wisc.cloudlab.us, boolean reserved=false) for appattempt_1476452954783_0002_000001
2016-10-14 07:51:42,884 INFO org.apache.hadoop.yarn.server.resourcemanager.scheduler.fair.FSAppAttempt: assignContainer(FSSchedulerNode node:cp-3.yarn-perf.yarnrm-PG0.wisc.cloudlab.us, boolean reserved=false) for appattempt_1476452954783_0001_000001
2016-10-14 07:51:42,885 INFO org.apache.hadoop.yarn.server.resourcemanager.scheduler.fair.FSAppAttempt: assignContainer(FSSchedulerNode node:cp-3.yarn-perf.yarnrm-PG0.wisc.cloudlab.us, boolean reserved=false) for appattempt_1476452954783_0002_000001
2016-10-14 07:51:43,711 INFO org.apache.hadoop.yarn.server.resourcemanager.scheduler.fair.FSAppAttempt: assignContainer(FSSchedulerNode node:cp-2.yarn-perf.yarnrm-PG0.wisc.cloudlab.us, boolean reserved=false) for appattempt_1476452954783_0001_000001
2016-10-14 07:51:43,711 INFO org.apache.hadoop.yarn.server.resourcemanager.scheduler.fair.FSAppAttempt: assignContainer(FSSchedulerNode node:cp-2.yarn-perf.yarnrm-PG0.wisc.cloudlab.us, boolean reserved=false) for appattempt_1476452954783_0002_000001
2016-10-14 07:51:43,712 INFO org.apache.hadoop.yarn.server.resourcemanager.scheduler.fair.FSAppAttempt: assignContainer(FSSchedulerNode node:c220g1-030617.wisc.cloudlab.us, boolean reserved=false) for appattempt_1476452954783_0001_000001
2016-10-14 07:51:43,712 INFO org.apache.hadoop.yarn.server.resourcemanager.scheduler.fair.FSAppAttempt: assignContainer(FSSchedulerNode node:c220g1-030617.wisc.cloudlab.us, boolean reserved=false) for appattempt_1476452954783_0002_000001
2016-10-14 07:51:43,824 INFO org.apache.hadoop.yarn.server.resourcemanager.scheduler.fair.FSAppAttempt: assignContainer(FSSchedulerNode node:cp-1.yarn-perf.yarnrm-PG0.wisc.cloudlab.us, boolean reserved=false) for appattempt_1476452954783_0001_000001
2016-10-14 07:51:43,824 INFO org.apache.hadoop.yarn.server.resourcemanager.scheduler.fair.FSAppAttempt: assignContainer(FSSchedulerNode node:cp-1.yarn-perf.yarnrm-PG0.wisc.cloudlab.us, boolean reserved=false) for appattempt_1476452954783_0002_000001
2016-10-14 07:51:43,887 INFO org.apache.hadoop.yarn.server.resourcemanager.scheduler.fair.FSAppAttempt: assignContainer(FSSchedulerNode node:cp-3.yarn-perf.yarnrm-PG0.wisc.cloudlab.us, boolean reserved=false) for appattempt_1476452954783_0001_000001
2016-10-14 07:51:43,887 INFO org.apache.hadoop.yarn.server.resourcemanager.scheduler.fair.FSAppAttempt: assignContainer(FSSchedulerNode node:cp-3.yarn-perf.yarnrm-PG0.wisc.cloudlab.us, boolean reserved=false) for appattempt_1476452954783_0002_000001
2016-10-14 07:51:44,714 INFO org.apache.hadoop.yarn.server.resourcemanager.scheduler.fair.FSAppAttempt: assignContainer(FSSchedulerNode node:cp-2.yarn-perf.yarnrm-PG0.wisc.cloudlab.us, boolean reserved=false) for appattempt_1476452954783_0001_000001
2016-10-14 07:51:44,714 INFO org.apache.hadoop.yarn.server.resourcemanager.scheduler.fair.FSAppAttempt: assignContainer(FSSchedulerNode node:cp-2.yarn-perf.yarnrm-PG0.wisc.cloudlab.us, boolean reserved=false) for appattempt_1476452954783_0002_000001
2016-10-14 07:51:44,715 INFO org.apache.hadoop.yarn.server.resourcemanager.scheduler.fair.FSAppAttempt: assignContainer(FSSchedulerNode node:c220g1-030617.wisc.cloudlab.us, boolean reserved=false) for appattempt_1476452954783_0001_000001
2016-10-14 07:51:44,716 INFO org.apache.hadoop.yarn.server.resourcemanager.scheduler.fair.FSAppAttempt: assignContainer(FSSchedulerNode node:c220g1-030617.wisc.cloudlab.us, boolean reserved=false) for appattempt_1476452954783_0002_000001
2016-10-14 07:51:44,827 INFO org.apache.hadoop.yarn.server.resourcemanager.scheduler.fair.FSAppAttempt: assignContainer(FSSchedulerNode node:cp-1.yarn-perf.yarnrm-PG0.wisc.cloudlab.us, boolean reserved=false) for appattempt_1476452954783_0001_000001
2016-10-14 07:51:44,827 INFO org.apache.hadoop.yarn.server.resourcemanager.scheduler.fair.FSAppAttempt: assignContainer(FSSchedulerNode node:cp-1.yarn-perf.yarnrm-PG0.wisc.cloudlab.us, boolean reserved=false) for appattempt_1476452954783_0002_000001
2016-10-14 07:51:44,889 INFO org.apache.hadoop.yarn.server.resourcemanager.scheduler.fair.FSAppAttempt: assignContainer(FSSchedulerNode node:cp-3.yarn-perf.yarnrm-PG0.wisc.cloudlab.us, boolean reserved=false) for appattempt_1476452954783_0001_000001
2016-10-14 07:51:44,890 INFO org.apache.hadoop.yarn.server.resourcemanager.scheduler.fair.FSAppAttempt: assignContainer(FSSchedulerNode node:cp-3.yarn-perf.yarnrm-PG0.wisc.cloudlab.us, boolean reserved=false) for appattempt_1476452954783_0002_000001
2016-10-14 07:51:45,717 INFO org.apache.hadoop.yarn.server.resourcemanager.scheduler.fair.FSAppAttempt: assignContainer(FSSchedulerNode node:c220g1-030617.wisc.cloudlab.us, boolean reserved=false) for appattempt_1476452954783_0001_000001
2016-10-14 07:51:45,717 INFO org.apache.hadoop.yarn.server.resourcemanager.scheduler.fair.FSAppAttempt: assignContainer(FSSchedulerNode node:c220g1-030617.wisc.cloudlab.us, boolean reserved=false) for appattempt_1476452954783_0002_000001
2016-10-14 07:51:45,718 INFO org.apache.hadoop.yarn.server.resourcemanager.scheduler.fair.FSAppAttempt: assignContainer(FSSchedulerNode node:cp-2.yarn-perf.yarnrm-PG0.wisc.cloudlab.us, boolean reserved=false) for appattempt_1476452954783_0001_000001
2016-10-14 07:51:45,718 INFO org.apache.hadoop.yarn.server.resourcemanager.scheduler.fair.FSAppAttempt: assignContainer(FSSchedulerNode node:cp-2.yarn-perf.yarnrm-PG0.wisc.cloudlab.us, boolean reserved=false) for appattempt_1476452954783_0002_000001
2016-10-14 07:51:45,829 INFO org.apache.hadoop.yarn.server.resourcemanager.scheduler.fair.FSAppAttempt: assignContainer(FSSchedulerNode node:cp-1.yarn-perf.yarnrm-PG0.wisc.cloudlab.us, boolean reserved=false) for appattempt_1476452954783_0001_000001
2016-10-14 07:51:45,829 INFO org.apache.hadoop.yarn.server.resourcemanager.scheduler.fair.FSAppAttempt: assignContainer(FSSchedulerNode node:cp-1.yarn-perf.yarnrm-PG0.wisc.cloudlab.us, boolean reserved=false) for appattempt_1476452954783_0002_000001
2016-10-14 07:51:45,892 INFO org.apache.hadoop.yarn.server.resourcemanager.scheduler.fair.FSAppAttempt: assignContainer(FSSchedulerNode node:cp-3.yarn-perf.yarnrm-PG0.wisc.cloudlab.us, boolean reserved=false) for appattempt_1476452954783_0001_000001
2016-10-14 07:51:45,892 INFO org.apache.hadoop.yarn.server.resourcemanager.scheduler.fair.FSAppAttempt: assignContainer(FSSchedulerNode node:cp-3.yarn-perf.yarnrm-PG0.wisc.cloudlab.us, boolean reserved=false) for appattempt_1476452954783_0002_000001
2016-10-14 07:51:46,720 INFO org.apache.hadoop.yarn.server.resourcemanager.scheduler.fair.FSAppAttempt: assignContainer(FSSchedulerNode node:c220g1-030617.wisc.cloudlab.us, boolean reserved=false) for appattempt_1476452954783_0001_000001
2016-10-14 07:51:46,720 INFO org.apache.hadoop.yarn.server.resourcemanager.scheduler.fair.FSAppAttempt: assignContainer(FSSchedulerNode node:c220g1-030617.wisc.cloudlab.us, boolean reserved=false) for appattempt_1476452954783_0002_000001
2016-10-14 07:51:46,721 INFO org.apache.hadoop.yarn.server.resourcemanager.scheduler.fair.FSAppAttempt: assignContainer(FSSchedulerNode node:cp-2.yarn-perf.yarnrm-PG0.wisc.cloudlab.us, boolean reserved=false) for appattempt_1476452954783_0001_000001
2016-10-14 07:51:46,721 INFO org.apache.hadoop.yarn.server.resourcemanager.scheduler.fair.FSAppAttempt: assignContainer(FSSchedulerNode node:cp-2.yarn-perf.yarnrm-PG0.wisc.cloudlab.us, boolean reserved=false) for appattempt_1476452954783_0002_000001
2016-10-14 07:51:46,831 INFO org.apache.hadoop.yarn.server.resourcemanager.scheduler.fair.FSAppAttempt: assignContainer(FSSchedulerNode node:cp-1.yarn-perf.yarnrm-PG0.wisc.cloudlab.us, boolean reserved=false) for appattempt_1476452954783_0001_000001
2016-10-14 07:51:46,832 INFO org.apache.hadoop.yarn.server.resourcemanager.scheduler.fair.FSAppAttempt: assignContainer(FSSchedulerNode node:cp-1.yarn-perf.yarnrm-PG0.wisc.cloudlab.us, boolean reserved=false) for appattempt_1476452954783_0002_000001
2016-10-14 07:51:46,894 INFO org.apache.hadoop.yarn.server.resourcemanager.scheduler.fair.FSAppAttempt: assignContainer(FSSchedulerNode node:cp-3.yarn-perf.yarnrm-PG0.wisc.cloudlab.us, boolean reserved=false) for appattempt_1476452954783_0001_000001
2016-10-14 07:51:46,894 INFO org.apache.hadoop.yarn.server.resourcemanager.scheduler.fair.FSAppAttempt: assignContainer(FSSchedulerNode node:cp-3.yarn-perf.yarnrm-PG0.wisc.cloudlab.us, boolean reserved=false) for appattempt_1476452954783_0002_000001
2016-10-14 07:51:47,722 INFO org.apache.hadoop.yarn.server.resourcemanager.scheduler.fair.FSAppAttempt: assignContainer(FSSchedulerNode node:c220g1-030617.wisc.cloudlab.us, boolean reserved=false) for appattempt_1476452954783_0001_000001
2016-10-14 07:51:47,722 INFO org.apache.hadoop.yarn.server.resourcemanager.scheduler.fair.FSAppAttempt: assignContainer(FSSchedulerNode node:c220g1-030617.wisc.cloudlab.us, boolean reserved=false) for appattempt_1476452954783_0002_000001
2016-10-14 07:51:47,724 INFO org.apache.hadoop.yarn.server.resourcemanager.scheduler.fair.FSAppAttempt: assignContainer(FSSchedulerNode node:cp-2.yarn-perf.yarnrm-PG0.wisc.cloudlab.us, boolean reserved=false) for appattempt_1476452954783_0001_000001
2016-10-14 07:51:47,724 INFO org.apache.hadoop.yarn.server.resourcemanager.scheduler.fair.FSAppAttempt: assignContainer(FSSchedulerNode node:cp-2.yarn-perf.yarnrm-PG0.wisc.cloudlab.us, boolean reserved=false) for appattempt_1476452954783_0002_000001
2016-10-14 07:51:47,834 INFO org.apache.hadoop.yarn.server.resourcemanager.scheduler.fair.FSAppAttempt: assignContainer(FSSchedulerNode node:cp-1.yarn-perf.yarnrm-PG0.wisc.cloudlab.us, boolean reserved=false) for appattempt_1476452954783_0001_000001
2016-10-14 07:51:47,834 INFO org.apache.hadoop.yarn.server.resourcemanager.scheduler.fair.FSAppAttempt: assignContainer(FSSchedulerNode node:cp-1.yarn-perf.yarnrm-PG0.wisc.cloudlab.us, boolean reserved=false) for appattempt_1476452954783_0002_000001
2016-10-14 07:51:47,897 INFO org.apache.hadoop.yarn.server.resourcemanager.scheduler.fair.FSAppAttempt: assignContainer(FSSchedulerNode node:cp-3.yarn-perf.yarnrm-PG0.wisc.cloudlab.us, boolean reserved=false) for appattempt_1476452954783_0001_000001
2016-10-14 07:51:47,897 INFO org.apache.hadoop.yarn.server.resourcemanager.scheduler.fair.FSAppAttempt: assignContainer(FSSchedulerNode node:cp-3.yarn-perf.yarnrm-PG0.wisc.cloudlab.us, boolean reserved=false) for appattempt_1476452954783_0002_000001
2016-10-14 07:51:48,726 INFO org.apache.hadoop.yarn.server.resourcemanager.scheduler.fair.FSAppAttempt: assignContainer(FSSchedulerNode node:cp-2.yarn-perf.yarnrm-PG0.wisc.cloudlab.us, boolean reserved=false) for appattempt_1476452954783_0001_000001
2016-10-14 07:51:48,726 INFO org.apache.hadoop.yarn.server.resourcemanager.scheduler.fair.FSAppAttempt: assignContainer(FSSchedulerNode node:cp-2.yarn-perf.yarnrm-PG0.wisc.cloudlab.us, boolean reserved=false) for appattempt_1476452954783_0002_000001
2016-10-14 07:51:48,727 INFO org.apache.hadoop.yarn.server.resourcemanager.scheduler.fair.FSAppAttempt: assignContainer(FSSchedulerNode node:c220g1-030617.wisc.cloudlab.us, boolean reserved=false) for appattempt_1476452954783_0001_000001
2016-10-14 07:51:48,727 INFO org.apache.hadoop.yarn.server.resourcemanager.scheduler.fair.FSAppAttempt: assignContainer(FSSchedulerNode node:c220g1-030617.wisc.cloudlab.us, boolean reserved=false) for appattempt_1476452954783_0002_000001
2016-10-14 07:51:48,837 INFO org.apache.hadoop.yarn.server.resourcemanager.scheduler.fair.FSAppAttempt: assignContainer(FSSchedulerNode node:cp-1.yarn-perf.yarnrm-PG0.wisc.cloudlab.us, boolean reserved=false) for appattempt_1476452954783_0001_000001
2016-10-14 07:51:48,837 INFO org.apache.hadoop.yarn.server.resourcemanager.scheduler.fair.FSAppAttempt: assignContainer(FSSchedulerNode node:cp-1.yarn-perf.yarnrm-PG0.wisc.cloudlab.us, boolean reserved=false) for appattempt_1476452954783_0002_000001
2016-10-14 07:51:48,900 INFO org.apache.hadoop.yarn.server.resourcemanager.scheduler.fair.FSAppAttempt: assignContainer(FSSchedulerNode node:cp-3.yarn-perf.yarnrm-PG0.wisc.cloudlab.us, boolean reserved=false) for appattempt_1476452954783_0001_000001
2016-10-14 07:51:48,900 INFO org.apache.hadoop.yarn.server.resourcemanager.scheduler.fair.FSAppAttempt: assignContainer(FSSchedulerNode node:cp-3.yarn-perf.yarnrm-PG0.wisc.cloudlab.us, boolean reserved=false) for appattempt_1476452954783_0002_000001
2016-10-14 07:51:49,720 INFO SecurityLogger.org.apache.hadoop.ipc.Server: Auth successful for appattempt_1476452954783_0002_000001 (auth:SIMPLE)
2016-10-14 07:51:49,734 INFO org.apache.hadoop.yarn.server.resourcemanager.ApplicationMasterService: AM registration appattempt_1476452954783_0002_000001
2016-10-14 07:51:49,751 INFO org.apache.hadoop.yarn.server.resourcemanager.scheduler.fair.FSAppAttempt: assignContainer(FSSchedulerNode node:c220g1-030617.wisc.cloudlab.us, boolean reserved=false) for appattempt_1476452954783_0001_000001
2016-10-14 07:51:49,752 INFO org.apache.hadoop.yarn.server.resourcemanager.RMAuditLogger: USER=tanle	IP=128.104.222.67	OPERATION=Register App Master	TARGET=ApplicationMasterService	RESULT=SUCCESS	APPID=application_1476452954783_0002	APPATTEMPTID=appattempt_1476452954783_0002_000001
2016-10-14 07:51:49,752 INFO org.apache.hadoop.yarn.server.resourcemanager.scheduler.fair.FSAppAttempt: assignContainer(FSSchedulerNode node:c220g1-030617.wisc.cloudlab.us, boolean reserved=false) for appattempt_1476452954783_0002_000001
2016-10-14 07:51:49,752 INFO org.apache.hadoop.yarn.server.resourcemanager.rmapp.attempt.RMAppAttemptImpl: appattempt_1476452954783_0002_000001 State change from LAUNCHED to RUNNING
2016-10-14 07:51:49,753 INFO org.apache.hadoop.yarn.server.resourcemanager.scheduler.fair.FSAppAttempt: assignContainer(FSSchedulerNode node:cp-2.yarn-perf.yarnrm-PG0.wisc.cloudlab.us, boolean reserved=false) for appattempt_1476452954783_0001_000001
2016-10-14 07:51:49,753 INFO org.apache.hadoop.yarn.server.resourcemanager.scheduler.fair.FSAppAttempt: assignContainer(FSSchedulerNode node:cp-2.yarn-perf.yarnrm-PG0.wisc.cloudlab.us, boolean reserved=false) for appattempt_1476452954783_0002_000001
2016-10-14 07:51:49,839 INFO org.apache.hadoop.yarn.server.resourcemanager.scheduler.fair.FSAppAttempt: assignContainer(FSSchedulerNode node:cp-1.yarn-perf.yarnrm-PG0.wisc.cloudlab.us, boolean reserved=false) for appattempt_1476452954783_0001_000001
2016-10-14 07:51:49,839 INFO org.apache.hadoop.yarn.server.resourcemanager.scheduler.fair.FSAppAttempt: assignContainer(FSSchedulerNode node:cp-1.yarn-perf.yarnrm-PG0.wisc.cloudlab.us, boolean reserved=false) for appattempt_1476452954783_0002_000001
2016-10-14 07:51:49,851 INFO org.apache.hadoop.yarn.server.resourcemanager.scheduler.fair.FairScheduler: allocate(appattempt_1476452954783_0002_000001 [] [] [] []
2016-10-14 07:51:49,851 INFO org.apache.hadoop.yarn.server.resourcemanager.scheduler.fair.FSAppAttempt: root.interactive0 getMinReq:<memory:24576, vCores:12> demand: <memory:2048, vCores:1> usage: <memory:2048, vCores:1>running true active: true isLeafQueue():true
2016-10-14 07:51:49,852 INFO org.apache.hadoop.yarn.server.resourcemanager.scheduler.fair.FSAppAttempt: root.batch0 getMinReq:<memory:0, vCores:0> demand: <memory:2048, vCores:1> usage: <memory:2048, vCores:1>running true active: true isLeafQueue():true
2016-10-14 07:51:49,852 INFO org.apache.hadoop.yarn.server.resourcemanager.scheduler.fair.FSAppAttempt: appattempt_1476452954783_0002_000001 minReqResource: <memory:24576, vCores:12> flexibleResource: <memory:8192, vCores:4>
2016-10-14 07:51:49,852 INFO org.apache.hadoop.yarn.server.resourcemanager.scheduler.fair.FairScheduler: [admission control] getFlexibleResource <memory:8192, vCores:4>
2016-10-14 07:51:49,898 INFO org.apache.hadoop.yarn.server.resourcemanager.scheduler.fair.FairScheduler: allocate(appattempt_1476452954783_0002_000001 [] [] [] []
2016-10-14 07:51:49,898 INFO org.apache.hadoop.yarn.server.resourcemanager.scheduler.fair.FSAppAttempt: root.interactive0 getMinReq:<memory:24576, vCores:12> demand: <memory:2048, vCores:1> usage: <memory:2048, vCores:1>running true active: true isLeafQueue():true
2016-10-14 07:51:49,898 INFO org.apache.hadoop.yarn.server.resourcemanager.scheduler.fair.FSAppAttempt: root.batch0 getMinReq:<memory:0, vCores:0> demand: <memory:2048, vCores:1> usage: <memory:2048, vCores:1>running true active: true isLeafQueue():true
2016-10-14 07:51:49,898 INFO org.apache.hadoop.yarn.server.resourcemanager.scheduler.fair.FSAppAttempt: appattempt_1476452954783_0002_000001 minReqResource: <memory:24576, vCores:12> flexibleResource: <memory:8192, vCores:4>
2016-10-14 07:51:49,898 INFO org.apache.hadoop.yarn.server.resourcemanager.scheduler.fair.FairScheduler: [admission control] getFlexibleResource <memory:8192, vCores:4>
2016-10-14 07:51:49,902 INFO org.apache.hadoop.yarn.server.resourcemanager.scheduler.fair.FSAppAttempt: assignContainer(FSSchedulerNode node:cp-3.yarn-perf.yarnrm-PG0.wisc.cloudlab.us, boolean reserved=false) for appattempt_1476452954783_0001_000001
2016-10-14 07:51:49,903 INFO org.apache.hadoop.yarn.server.resourcemanager.scheduler.fair.FSAppAttempt: assignContainer(FSSchedulerNode node:cp-3.yarn-perf.yarnrm-PG0.wisc.cloudlab.us, boolean reserved=false) for appattempt_1476452954783_0002_000001
2016-10-14 07:51:50,733 INFO org.apache.hadoop.yarn.server.resourcemanager.scheduler.fair.FSAppAttempt: assignContainer(FSSchedulerNode node:cp-2.yarn-perf.yarnrm-PG0.wisc.cloudlab.us, boolean reserved=false) for appattempt_1476452954783_0001_000001
2016-10-14 07:51:50,733 INFO org.apache.hadoop.yarn.server.resourcemanager.scheduler.fair.FSAppAttempt: assignContainer(FSSchedulerNode node:cp-2.yarn-perf.yarnrm-PG0.wisc.cloudlab.us, boolean reserved=false) for appattempt_1476452954783_0002_000001
2016-10-14 07:51:50,734 INFO org.apache.hadoop.yarn.server.resourcemanager.scheduler.fair.FSAppAttempt: assignContainer(FSSchedulerNode node:c220g1-030617.wisc.cloudlab.us, boolean reserved=false) for appattempt_1476452954783_0001_000001
2016-10-14 07:51:50,734 INFO org.apache.hadoop.yarn.server.resourcemanager.scheduler.fair.FSAppAttempt: assignContainer(FSSchedulerNode node:c220g1-030617.wisc.cloudlab.us, boolean reserved=false) for appattempt_1476452954783_0002_000001
2016-10-14 07:51:50,755 INFO SecurityLogger.org.apache.hadoop.ipc.Server: Auth successful for appattempt_1476452954783_0001_000001 (auth:SIMPLE)
2016-10-14 07:51:50,759 INFO org.apache.hadoop.yarn.server.resourcemanager.ApplicationMasterService: AM registration appattempt_1476452954783_0001_000001
2016-10-14 07:51:50,759 INFO org.apache.hadoop.yarn.server.resourcemanager.RMAuditLogger: USER=tanle	IP=128.104.222.60	OPERATION=Register App Master	TARGET=ApplicationMasterService	RESULT=SUCCESS	APPID=application_1476452954783_0001	APPATTEMPTID=appattempt_1476452954783_0001_000001
2016-10-14 07:51:50,759 INFO org.apache.hadoop.yarn.server.resourcemanager.rmapp.attempt.RMAppAttemptImpl: appattempt_1476452954783_0001_000001 State change from LAUNCHED to RUNNING
2016-10-14 07:51:50,799 INFO org.apache.hadoop.yarn.server.resourcemanager.scheduler.fair.FairScheduler: allocate(appattempt_1476452954783_0001_000001 [] [] [] []
2016-10-14 07:51:50,799 INFO org.apache.hadoop.yarn.server.resourcemanager.scheduler.fair.FSAppAttempt: root.interactive0 getMinReq:<memory:24576, vCores:12> demand: <memory:2048, vCores:1> usage: <memory:2048, vCores:1>running true active: true isLeafQueue():true
2016-10-14 07:51:50,799 INFO org.apache.hadoop.yarn.server.resourcemanager.scheduler.fair.FSAppAttempt: root.batch0 getMinReq:<memory:0, vCores:0> demand: <memory:2048, vCores:1> usage: <memory:2048, vCores:1>running true active: true isLeafQueue():true
2016-10-14 07:51:50,799 INFO org.apache.hadoop.yarn.server.resourcemanager.scheduler.fair.FSAppAttempt: appattempt_1476452954783_0001_000001 minReqResource: <memory:24576, vCores:12> flexibleResource: <memory:8192, vCores:4>
2016-10-14 07:51:50,799 INFO org.apache.hadoop.yarn.server.resourcemanager.scheduler.fair.FairScheduler: [admission control] getFlexibleResource <memory:8192, vCores:4>
2016-10-14 07:51:50,799 INFO org.apache.hadoop.yarn.server.resourcemanager.scheduler.fair.FairScheduler: app appattempt_1476452954783_0001_000001 in queue root.interactive0 isRunning: true
2016-10-14 07:51:50,818 INFO org.apache.hadoop.yarn.server.resourcemanager.scheduler.fair.FairScheduler: allocate(appattempt_1476452954783_0001_000001 [] [] [] []
2016-10-14 07:51:50,818 INFO org.apache.hadoop.yarn.server.resourcemanager.scheduler.fair.FSAppAttempt: root.interactive0 getMinReq:<memory:24576, vCores:12> demand: <memory:2048, vCores:1> usage: <memory:2048, vCores:1>running true active: true isLeafQueue():true
2016-10-14 07:51:50,818 INFO org.apache.hadoop.yarn.server.resourcemanager.scheduler.fair.FSAppAttempt: root.batch0 getMinReq:<memory:0, vCores:0> demand: <memory:2048, vCores:1> usage: <memory:2048, vCores:1>running true active: true isLeafQueue():true
2016-10-14 07:51:50,818 INFO org.apache.hadoop.yarn.server.resourcemanager.scheduler.fair.FSAppAttempt: appattempt_1476452954783_0001_000001 minReqResource: <memory:24576, vCores:12> flexibleResource: <memory:8192, vCores:4>
2016-10-14 07:51:50,818 INFO org.apache.hadoop.yarn.server.resourcemanager.scheduler.fair.FairScheduler: [admission control] getFlexibleResource <memory:8192, vCores:4>
2016-10-14 07:51:50,819 INFO org.apache.hadoop.yarn.server.resourcemanager.scheduler.fair.FairScheduler: app appattempt_1476452954783_0001_000001 in queue root.interactive0 isRunning: true
2016-10-14 07:51:50,842 INFO org.apache.hadoop.yarn.server.resourcemanager.scheduler.fair.FSAppAttempt: assignContainer(FSSchedulerNode node:cp-1.yarn-perf.yarnrm-PG0.wisc.cloudlab.us, boolean reserved=false) for appattempt_1476452954783_0001_000001
2016-10-14 07:51:50,842 INFO org.apache.hadoop.yarn.server.resourcemanager.scheduler.fair.FSAppAttempt: assignContainer(FSSchedulerNode node:cp-1.yarn-perf.yarnrm-PG0.wisc.cloudlab.us, boolean reserved=false) for appattempt_1476452954783_0002_000001
2016-10-14 07:51:50,905 INFO org.apache.hadoop.yarn.server.resourcemanager.scheduler.fair.FSAppAttempt: assignContainer(FSSchedulerNode node:cp-3.yarn-perf.yarnrm-PG0.wisc.cloudlab.us, boolean reserved=false) for appattempt_1476452954783_0001_000001
2016-10-14 07:51:50,905 INFO org.apache.hadoop.yarn.server.resourcemanager.scheduler.fair.FSAppAttempt: assignContainer(FSSchedulerNode node:cp-3.yarn-perf.yarnrm-PG0.wisc.cloudlab.us, boolean reserved=false) for appattempt_1476452954783_0002_000001
2016-10-14 07:51:51,719 WARN org.apache.hadoop.yarn.server.resourcemanager.rmapp.RMAppImpl: The specific max attempts: 0 for application: 3 is invalid, because it is out of the range [1, 2]. Use the global max attempts instead.
2016-10-14 07:51:51,719 INFO org.apache.hadoop.yarn.server.resourcemanager.ClientRMService: Application with id 3 submitted by user tanle
2016-10-14 07:51:51,719 INFO org.apache.hadoop.yarn.server.resourcemanager.rmapp.RMAppImpl: Storing application with id application_1476452954783_0003
2016-10-14 07:51:51,719 INFO org.apache.hadoop.yarn.server.resourcemanager.RMAuditLogger: USER=tanle	IP=128.104.222.53	OPERATION=Submit Application Request	TARGET=ClientRMService	RESULT=SUCCESS	APPID=application_1476452954783_0003
2016-10-14 07:51:51,720 INFO org.apache.hadoop.yarn.server.resourcemanager.recovery.RMStateStore: Storing info for app: application_1476452954783_0003
2016-10-14 07:51:51,720 INFO org.apache.hadoop.yarn.server.resourcemanager.scheduler.fair.FairScheduler: Accepted application application_1476452954783_0003 from user: tanle, in queue: batch0, currently num of applications: 3
2016-10-14 07:51:51,721 INFO org.apache.hadoop.yarn.server.resourcemanager.ApplicationMasterService: Registering app attempt : appattempt_1476452954783_0003_000001
2016-10-14 07:51:51,721 INFO org.apache.hadoop.yarn.server.resourcemanager.rmapp.attempt.RMAppAttemptImpl: appattempt_1476452954783_0003_000001 State change from NEW to SUBMITTED
2016-10-14 07:51:51,722 INFO org.apache.hadoop.yarn.server.resourcemanager.scheduler.fair.FairScheduler: Added Application Attempt appattempt_1476452954783_0003_000001 to scheduler from user: tanle
2016-10-14 07:51:51,722 INFO org.apache.hadoop.yarn.server.resourcemanager.rmapp.attempt.RMAppAttemptImpl: ScheduleTransition.transition(appattempt_1476452954783_0003_000001,EventType: ATTEMPT_ADDED)
2016-10-14 07:51:51,722 INFO org.apache.hadoop.yarn.server.resourcemanager.scheduler.fair.FairScheduler: allocate(appattempt_1476452954783_0003_000001 [{Priority: 0, Capability: <memory:2048, vCores:1>, # Containers: 1, Location: *, Relax Locality: true}] [] null null
2016-10-14 07:51:51,722 INFO org.apache.hadoop.yarn.server.resourcemanager.scheduler.fair.FSAppAttempt: root.interactive0 getMinReq:<memory:24576, vCores:12> demand: <memory:2048, vCores:1> usage: <memory:2048, vCores:1>running true active: true isLeafQueue():true
2016-10-14 07:51:51,722 INFO org.apache.hadoop.yarn.server.resourcemanager.scheduler.fair.FSAppAttempt: root.batch0 getMinReq:<memory:0, vCores:0> demand: <memory:2048, vCores:1> usage: <memory:2048, vCores:1>running true active: true isLeafQueue():true
2016-10-14 07:51:51,723 INFO org.apache.hadoop.yarn.server.resourcemanager.scheduler.fair.FSAppAttempt: appattempt_1476452954783_0003_000001 minReqResource: <memory:24576, vCores:12> flexibleResource: <memory:8192, vCores:4>
2016-10-14 07:51:51,723 INFO org.apache.hadoop.yarn.server.resourcemanager.scheduler.fair.FairScheduler: [admission control] getFlexibleResource <memory:8192, vCores:4>
2016-10-14 07:51:51,723 INFO org.apache.hadoop.yarn.server.resourcemanager.rmapp.attempt.RMAppAttemptImpl: appattempt_1476452954783_0003_000001 State change from SUBMITTED to SCHEDULED
2016-10-14 07:51:51,735 INFO org.apache.hadoop.yarn.server.resourcemanager.scheduler.fair.FSAppAttempt: assignContainer(FSSchedulerNode node:cp-2.yarn-perf.yarnrm-PG0.wisc.cloudlab.us, boolean reserved=false) for appattempt_1476452954783_0001_000001
2016-10-14 07:51:51,735 INFO org.apache.hadoop.yarn.server.resourcemanager.scheduler.fair.FSAppAttempt: assignContainer(FSSchedulerNode node:cp-2.yarn-perf.yarnrm-PG0.wisc.cloudlab.us, boolean reserved=false) for appattempt_1476452954783_0002_000001
2016-10-14 07:51:51,735 INFO org.apache.hadoop.yarn.server.resourcemanager.scheduler.fair.FSAppAttempt: assignContainer(FSSchedulerNode node:cp-2.yarn-perf.yarnrm-PG0.wisc.cloudlab.us, boolean reserved=false) for appattempt_1476452954783_0003_000001
2016-10-14 07:51:51,737 INFO org.apache.hadoop.yarn.server.resourcemanager.scheduler.fair.FSAppAttempt: assignContainer(FSSchedulerNode node:c220g1-030617.wisc.cloudlab.us, boolean reserved=false) for appattempt_1476452954783_0001_000001
2016-10-14 07:51:51,737 INFO org.apache.hadoop.yarn.server.resourcemanager.scheduler.fair.FSAppAttempt: assignContainer(FSSchedulerNode node:c220g1-030617.wisc.cloudlab.us, boolean reserved=false) for appattempt_1476452954783_0002_000001
2016-10-14 07:51:51,737 INFO org.apache.hadoop.yarn.server.resourcemanager.scheduler.fair.FSAppAttempt: assignContainer(FSSchedulerNode node:c220g1-030617.wisc.cloudlab.us, boolean reserved=false) for appattempt_1476452954783_0003_000001
2016-10-14 07:51:51,844 INFO org.apache.hadoop.yarn.server.resourcemanager.scheduler.fair.FSAppAttempt: assignContainer(FSSchedulerNode node:cp-1.yarn-perf.yarnrm-PG0.wisc.cloudlab.us, boolean reserved=false) for appattempt_1476452954783_0001_000001
2016-10-14 07:51:51,844 INFO org.apache.hadoop.yarn.server.resourcemanager.scheduler.fair.FSAppAttempt: assignContainer(FSSchedulerNode node:cp-1.yarn-perf.yarnrm-PG0.wisc.cloudlab.us, boolean reserved=false) for appattempt_1476452954783_0002_000001
2016-10-14 07:51:51,844 INFO org.apache.hadoop.yarn.server.resourcemanager.scheduler.fair.FSAppAttempt: assignContainer(FSSchedulerNode node:cp-1.yarn-perf.yarnrm-PG0.wisc.cloudlab.us, boolean reserved=false) for appattempt_1476452954783_0003_000001
2016-10-14 07:51:51,907 INFO org.apache.hadoop.yarn.server.resourcemanager.scheduler.fair.FSAppAttempt: assignContainer(FSSchedulerNode node:cp-3.yarn-perf.yarnrm-PG0.wisc.cloudlab.us, boolean reserved=false) for appattempt_1476452954783_0001_000001
2016-10-14 07:51:51,908 INFO org.apache.hadoop.yarn.server.resourcemanager.scheduler.fair.FSAppAttempt: assignContainer(FSSchedulerNode node:cp-3.yarn-perf.yarnrm-PG0.wisc.cloudlab.us, boolean reserved=false) for appattempt_1476452954783_0002_000001
2016-10-14 07:51:51,908 INFO org.apache.hadoop.yarn.server.resourcemanager.scheduler.fair.FSAppAttempt: assignContainer(FSSchedulerNode node:cp-3.yarn-perf.yarnrm-PG0.wisc.cloudlab.us, boolean reserved=false) for appattempt_1476452954783_0003_000001
2016-10-14 07:51:52,739 INFO org.apache.hadoop.yarn.server.resourcemanager.scheduler.fair.FSAppAttempt: assignContainer(FSSchedulerNode node:cp-2.yarn-perf.yarnrm-PG0.wisc.cloudlab.us, boolean reserved=false) for appattempt_1476452954783_0001_000001
2016-10-14 07:51:52,739 INFO org.apache.hadoop.yarn.server.resourcemanager.scheduler.fair.FSAppAttempt: assignContainer(FSSchedulerNode node:cp-2.yarn-perf.yarnrm-PG0.wisc.cloudlab.us, boolean reserved=false) for appattempt_1476452954783_0002_000001
2016-10-14 07:51:52,739 INFO org.apache.hadoop.yarn.server.resourcemanager.scheduler.fair.FSAppAttempt: assignContainer(FSSchedulerNode node:cp-2.yarn-perf.yarnrm-PG0.wisc.cloudlab.us, boolean reserved=false) for appattempt_1476452954783_0003_000001
2016-10-14 07:51:52,740 INFO org.apache.hadoop.yarn.server.resourcemanager.scheduler.fair.FSAppAttempt: assignContainer(FSSchedulerNode node:c220g1-030617.wisc.cloudlab.us, boolean reserved=false) for appattempt_1476452954783_0001_000001
2016-10-14 07:51:52,740 INFO org.apache.hadoop.yarn.server.resourcemanager.scheduler.fair.FSAppAttempt: assignContainer(FSSchedulerNode node:c220g1-030617.wisc.cloudlab.us, boolean reserved=false) for appattempt_1476452954783_0002_000001
2016-10-14 07:51:52,741 INFO org.apache.hadoop.yarn.server.resourcemanager.scheduler.fair.FSAppAttempt: assignContainer(FSSchedulerNode node:c220g1-030617.wisc.cloudlab.us, boolean reserved=false) for appattempt_1476452954783_0003_000001
2016-10-14 07:51:52,847 INFO org.apache.hadoop.yarn.server.resourcemanager.scheduler.fair.FSAppAttempt: assignContainer(FSSchedulerNode node:cp-1.yarn-perf.yarnrm-PG0.wisc.cloudlab.us, boolean reserved=false) for appattempt_1476452954783_0001_000001
2016-10-14 07:51:52,847 INFO org.apache.hadoop.yarn.server.resourcemanager.scheduler.fair.FSAppAttempt: assignContainer(FSSchedulerNode node:cp-1.yarn-perf.yarnrm-PG0.wisc.cloudlab.us, boolean reserved=false) for appattempt_1476452954783_0002_000001
2016-10-14 07:51:52,847 INFO org.apache.hadoop.yarn.server.resourcemanager.scheduler.fair.FSAppAttempt: assignContainer(FSSchedulerNode node:cp-1.yarn-perf.yarnrm-PG0.wisc.cloudlab.us, boolean reserved=false) for appattempt_1476452954783_0003_000001
2016-10-14 07:51:52,903 INFO org.apache.hadoop.yarn.server.resourcemanager.scheduler.fair.FairScheduler: allocate(appattempt_1476452954783_0002_000001 [] [] [] []
2016-10-14 07:51:52,903 INFO org.apache.hadoop.yarn.server.resourcemanager.scheduler.fair.FSAppAttempt: root.interactive0 getMinReq:<memory:24576, vCores:12> demand: <memory:2048, vCores:1> usage: <memory:2048, vCores:1>running true active: true isLeafQueue():true
2016-10-14 07:51:52,903 INFO org.apache.hadoop.yarn.server.resourcemanager.scheduler.fair.FSAppAttempt: root.batch0 getMinReq:<memory:0, vCores:0> demand: <memory:4096, vCores:2> usage: <memory:2048, vCores:1>running true active: true isLeafQueue():true
2016-10-14 07:51:52,903 INFO org.apache.hadoop.yarn.server.resourcemanager.scheduler.fair.FSAppAttempt: appattempt_1476452954783_0002_000001 minReqResource: <memory:24576, vCores:12> flexibleResource: <memory:8192, vCores:4>
2016-10-14 07:51:52,903 INFO org.apache.hadoop.yarn.server.resourcemanager.scheduler.fair.FairScheduler: [admission control] getFlexibleResource <memory:8192, vCores:4>
2016-10-14 07:51:52,910 INFO org.apache.hadoop.yarn.server.resourcemanager.scheduler.fair.FSAppAttempt: assignContainer(FSSchedulerNode node:cp-3.yarn-perf.yarnrm-PG0.wisc.cloudlab.us, boolean reserved=false) for appattempt_1476452954783_0001_000001
2016-10-14 07:51:52,910 INFO org.apache.hadoop.yarn.server.resourcemanager.scheduler.fair.FSAppAttempt: assignContainer(FSSchedulerNode node:cp-3.yarn-perf.yarnrm-PG0.wisc.cloudlab.us, boolean reserved=false) for appattempt_1476452954783_0002_000001
2016-10-14 07:51:52,910 INFO org.apache.hadoop.yarn.server.resourcemanager.scheduler.fair.FSAppAttempt: assignContainer(FSSchedulerNode node:cp-3.yarn-perf.yarnrm-PG0.wisc.cloudlab.us, boolean reserved=false) for appattempt_1476452954783_0003_000001
2016-10-14 07:51:53,741 INFO org.apache.hadoop.yarn.server.resourcemanager.scheduler.fair.FSAppAttempt: assignContainer(FSSchedulerNode node:c220g1-030617.wisc.cloudlab.us, boolean reserved=false) for appattempt_1476452954783_0001_000001
2016-10-14 07:51:53,742 INFO org.apache.hadoop.yarn.server.resourcemanager.scheduler.fair.FSAppAttempt: assignContainer(FSSchedulerNode node:c220g1-030617.wisc.cloudlab.us, boolean reserved=false) for appattempt_1476452954783_0002_000001
2016-10-14 07:51:53,742 INFO org.apache.hadoop.yarn.server.resourcemanager.scheduler.fair.FSAppAttempt: assignContainer(FSSchedulerNode node:c220g1-030617.wisc.cloudlab.us, boolean reserved=false) for appattempt_1476452954783_0003_000001
2016-10-14 07:51:53,743 INFO org.apache.hadoop.yarn.server.resourcemanager.scheduler.fair.FSAppAttempt: assignContainer(FSSchedulerNode node:cp-2.yarn-perf.yarnrm-PG0.wisc.cloudlab.us, boolean reserved=false) for appattempt_1476452954783_0001_000001
2016-10-14 07:51:53,743 INFO org.apache.hadoop.yarn.server.resourcemanager.scheduler.fair.FSAppAttempt: assignContainer(FSSchedulerNode node:cp-2.yarn-perf.yarnrm-PG0.wisc.cloudlab.us, boolean reserved=false) for appattempt_1476452954783_0002_000001
2016-10-14 07:51:53,743 INFO org.apache.hadoop.yarn.server.resourcemanager.scheduler.fair.FSAppAttempt: assignContainer(FSSchedulerNode node:cp-2.yarn-perf.yarnrm-PG0.wisc.cloudlab.us, boolean reserved=false) for appattempt_1476452954783_0003_000001
2016-10-14 07:51:53,824 INFO org.apache.hadoop.yarn.server.resourcemanager.scheduler.fair.FairScheduler: allocate(appattempt_1476452954783_0001_000001 [] [] [] []
2016-10-14 07:51:53,824 INFO org.apache.hadoop.yarn.server.resourcemanager.scheduler.fair.FSAppAttempt: root.interactive0 getMinReq:<memory:24576, vCores:12> demand: <memory:2048, vCores:1> usage: <memory:2048, vCores:1>running true active: true isLeafQueue():true
2016-10-14 07:51:53,824 INFO org.apache.hadoop.yarn.server.resourcemanager.scheduler.fair.FSAppAttempt: root.batch0 getMinReq:<memory:0, vCores:0> demand: <memory:4096, vCores:2> usage: <memory:2048, vCores:1>running true active: true isLeafQueue():true
2016-10-14 07:51:53,824 INFO org.apache.hadoop.yarn.server.resourcemanager.scheduler.fair.FSAppAttempt: appattempt_1476452954783_0001_000001 minReqResource: <memory:24576, vCores:12> flexibleResource: <memory:8192, vCores:4>
2016-10-14 07:51:53,824 INFO org.apache.hadoop.yarn.server.resourcemanager.scheduler.fair.FairScheduler: [admission control] getFlexibleResource <memory:8192, vCores:4>
2016-10-14 07:51:53,824 INFO org.apache.hadoop.yarn.server.resourcemanager.scheduler.fair.FairScheduler: app appattempt_1476452954783_0001_000001 in queue root.interactive0 isRunning: true
2016-10-14 07:51:53,849 INFO org.apache.hadoop.yarn.server.resourcemanager.scheduler.fair.FSAppAttempt: assignContainer(FSSchedulerNode node:cp-1.yarn-perf.yarnrm-PG0.wisc.cloudlab.us, boolean reserved=false) for appattempt_1476452954783_0001_000001
2016-10-14 07:51:53,850 INFO org.apache.hadoop.yarn.server.resourcemanager.scheduler.fair.FSAppAttempt: assignContainer(FSSchedulerNode node:cp-1.yarn-perf.yarnrm-PG0.wisc.cloudlab.us, boolean reserved=false) for appattempt_1476452954783_0002_000001
2016-10-14 07:51:53,850 INFO org.apache.hadoop.yarn.server.resourcemanager.scheduler.fair.FSAppAttempt: assignContainer(FSSchedulerNode node:cp-1.yarn-perf.yarnrm-PG0.wisc.cloudlab.us, boolean reserved=false) for appattempt_1476452954783_0003_000001
2016-10-14 07:51:53,913 INFO org.apache.hadoop.yarn.server.resourcemanager.scheduler.fair.FSAppAttempt: assignContainer(FSSchedulerNode node:cp-3.yarn-perf.yarnrm-PG0.wisc.cloudlab.us, boolean reserved=false) for appattempt_1476452954783_0001_000001
2016-10-14 07:51:53,913 INFO org.apache.hadoop.yarn.server.resourcemanager.scheduler.fair.FSAppAttempt: assignContainer(FSSchedulerNode node:cp-3.yarn-perf.yarnrm-PG0.wisc.cloudlab.us, boolean reserved=false) for appattempt_1476452954783_0002_000001
2016-10-14 07:51:53,913 INFO org.apache.hadoop.yarn.server.resourcemanager.scheduler.fair.FSAppAttempt: assignContainer(FSSchedulerNode node:cp-3.yarn-perf.yarnrm-PG0.wisc.cloudlab.us, boolean reserved=false) for appattempt_1476452954783_0003_000001
2016-10-14 07:51:54,194 INFO org.apache.hadoop.yarn.server.resourcemanager.ClientRMService: Allocated new applicationId: 4
2016-10-14 07:51:54,744 INFO org.apache.hadoop.yarn.server.resourcemanager.scheduler.fair.FSAppAttempt: assignContainer(FSSchedulerNode node:c220g1-030617.wisc.cloudlab.us, boolean reserved=false) for appattempt_1476452954783_0001_000001
2016-10-14 07:51:54,744 INFO org.apache.hadoop.yarn.server.resourcemanager.scheduler.fair.FSAppAttempt: assignContainer(FSSchedulerNode node:c220g1-030617.wisc.cloudlab.us, boolean reserved=false) for appattempt_1476452954783_0002_000001
2016-10-14 07:51:54,744 INFO org.apache.hadoop.yarn.server.resourcemanager.scheduler.fair.FSAppAttempt: assignContainer(FSSchedulerNode node:c220g1-030617.wisc.cloudlab.us, boolean reserved=false) for appattempt_1476452954783_0003_000001
2016-10-14 07:51:54,745 INFO org.apache.hadoop.yarn.server.resourcemanager.scheduler.fair.FSAppAttempt: assignContainer(FSSchedulerNode node:cp-2.yarn-perf.yarnrm-PG0.wisc.cloudlab.us, boolean reserved=false) for appattempt_1476452954783_0001_000001
2016-10-14 07:51:54,745 INFO org.apache.hadoop.yarn.server.resourcemanager.scheduler.fair.FSAppAttempt: assignContainer(FSSchedulerNode node:cp-2.yarn-perf.yarnrm-PG0.wisc.cloudlab.us, boolean reserved=false) for appattempt_1476452954783_0002_000001
2016-10-14 07:51:54,746 INFO org.apache.hadoop.yarn.server.resourcemanager.scheduler.fair.FSAppAttempt: assignContainer(FSSchedulerNode node:cp-2.yarn-perf.yarnrm-PG0.wisc.cloudlab.us, boolean reserved=false) for appattempt_1476452954783_0003_000001
2016-10-14 07:51:54,852 INFO org.apache.hadoop.yarn.server.resourcemanager.scheduler.fair.FSAppAttempt: assignContainer(FSSchedulerNode node:cp-1.yarn-perf.yarnrm-PG0.wisc.cloudlab.us, boolean reserved=false) for appattempt_1476452954783_0001_000001
2016-10-14 07:51:54,852 INFO org.apache.hadoop.yarn.server.resourcemanager.scheduler.fair.FSAppAttempt: assignContainer(FSSchedulerNode node:cp-1.yarn-perf.yarnrm-PG0.wisc.cloudlab.us, boolean reserved=false) for appattempt_1476452954783_0002_000001
2016-10-14 07:51:54,852 INFO org.apache.hadoop.yarn.server.resourcemanager.scheduler.fair.FSAppAttempt: assignContainer(FSSchedulerNode node:cp-1.yarn-perf.yarnrm-PG0.wisc.cloudlab.us, boolean reserved=false) for appattempt_1476452954783_0003_000001
2016-10-14 07:51:54,915 INFO org.apache.hadoop.yarn.server.resourcemanager.scheduler.fair.FSAppAttempt: assignContainer(FSSchedulerNode node:cp-3.yarn-perf.yarnrm-PG0.wisc.cloudlab.us, boolean reserved=false) for appattempt_1476452954783_0001_000001
2016-10-14 07:51:54,915 INFO org.apache.hadoop.yarn.server.resourcemanager.scheduler.fair.FSAppAttempt: assignContainer(FSSchedulerNode node:cp-3.yarn-perf.yarnrm-PG0.wisc.cloudlab.us, boolean reserved=false) for appattempt_1476452954783_0002_000001
2016-10-14 07:51:54,915 INFO org.apache.hadoop.yarn.server.resourcemanager.scheduler.fair.FSAppAttempt: assignContainer(FSSchedulerNode node:cp-3.yarn-perf.yarnrm-PG0.wisc.cloudlab.us, boolean reserved=false) for appattempt_1476452954783_0003_000001
2016-10-14 07:51:55,736 INFO org.apache.hadoop.yarn.server.resourcemanager.scheduler.fair.FairScheduler: allocate(appattempt_1476452954783_0002_000001 [{Priority: 1, Capability: <memory:1920, vCores:1>, # Containers: 1, Location: *, Relax Locality: true}] [] [] []
2016-10-14 07:51:55,736 INFO org.apache.hadoop.yarn.server.resourcemanager.scheduler.fair.FSAppAttempt: root.interactive0 getMinReq:<memory:24576, vCores:12> demand: <memory:2048, vCores:1> usage: <memory:2048, vCores:1>running true active: true isLeafQueue():true
2016-10-14 07:51:55,736 INFO org.apache.hadoop.yarn.server.resourcemanager.scheduler.fair.FSAppAttempt: root.batch0 getMinReq:<memory:0, vCores:0> demand: <memory:4096, vCores:2> usage: <memory:2048, vCores:1>running true active: true isLeafQueue():true
2016-10-14 07:51:55,736 INFO org.apache.hadoop.yarn.server.resourcemanager.scheduler.fair.FSAppAttempt: appattempt_1476452954783_0002_000001 minReqResource: <memory:24576, vCores:12> flexibleResource: <memory:8192, vCores:4>
2016-10-14 07:51:55,736 INFO org.apache.hadoop.yarn.server.resourcemanager.scheduler.fair.FairScheduler: [admission control] getFlexibleResource <memory:8192, vCores:4>
2016-10-14 07:51:55,747 INFO org.apache.hadoop.yarn.server.resourcemanager.scheduler.fair.FSAppAttempt: assignContainer(FSSchedulerNode node:c220g1-030617.wisc.cloudlab.us, boolean reserved=false) for appattempt_1476452954783_0001_000001
2016-10-14 07:51:55,747 INFO org.apache.hadoop.yarn.server.resourcemanager.scheduler.fair.FSAppAttempt: assignContainer(FSSchedulerNode node:c220g1-030617.wisc.cloudlab.us, boolean reserved=false) for appattempt_1476452954783_0002_000001
2016-10-14 07:51:55,747 INFO org.apache.hadoop.yarn.server.resourcemanager.scheduler.fair.FSAppAttempt: allocate container: container_1476452954783_0002_01_000002 priority 1
2016-10-14 07:51:55,748 INFO org.apache.hadoop.yarn.server.resourcemanager.rmcontainer.RMContainerImpl: Processing container_1476452954783_0002_01_000002 of event START
2016-10-14 07:51:55,748 INFO org.apache.hadoop.yarn.server.resourcemanager.rmcontainer.RMContainerImpl: container_1476452954783_0002_01_000002 Container Transitioned from NEW to ALLOCATED
2016-10-14 07:51:55,748 INFO org.apache.hadoop.yarn.server.resourcemanager.RMAuditLogger: USER=tanle	OPERATION=AM Allocated Container	TARGET=SchedulerApp	RESULT=SUCCESS	APPID=application_1476452954783_0002	CONTAINERID=container_1476452954783_0002_01_000002
2016-10-14 07:51:55,748 INFO org.apache.hadoop.yarn.server.resourcemanager.scheduler.SchedulerNode: Assigned container container_1476452954783_0002_01_000002 of capacity <memory:2048, vCores:1> on host c220g1-030617.wisc.cloudlab.us:46119, which has 2 containers, <memory:4096, vCores:2> used and <memory:4096, vCores:2> available after allocation
2016-10-14 07:51:55,749 INFO org.apache.hadoop.yarn.server.resourcemanager.scheduler.fair.FSAppAttempt: assignContainer(FSSchedulerNode node:cp-2.yarn-perf.yarnrm-PG0.wisc.cloudlab.us, boolean reserved=false) for appattempt_1476452954783_0001_000001
2016-10-14 07:51:55,749 INFO org.apache.hadoop.yarn.server.resourcemanager.scheduler.fair.FSAppAttempt: assignContainer(FSSchedulerNode node:cp-2.yarn-perf.yarnrm-PG0.wisc.cloudlab.us, boolean reserved=false) for appattempt_1476452954783_0002_000001
2016-10-14 07:51:55,749 INFO org.apache.hadoop.yarn.server.resourcemanager.scheduler.fair.FSAppAttempt: assignContainer(FSSchedulerNode node:cp-2.yarn-perf.yarnrm-PG0.wisc.cloudlab.us, boolean reserved=false) for appattempt_1476452954783_0003_000001
2016-10-14 07:51:55,854 INFO org.apache.hadoop.yarn.server.resourcemanager.scheduler.fair.FSAppAttempt: assignContainer(FSSchedulerNode node:cp-1.yarn-perf.yarnrm-PG0.wisc.cloudlab.us, boolean reserved=false) for appattempt_1476452954783_0001_000001
2016-10-14 07:51:55,855 INFO org.apache.hadoop.yarn.server.resourcemanager.scheduler.fair.FSAppAttempt: assignContainer(FSSchedulerNode node:cp-1.yarn-perf.yarnrm-PG0.wisc.cloudlab.us, boolean reserved=false) for appattempt_1476452954783_0002_000001
2016-10-14 07:51:55,855 INFO org.apache.hadoop.yarn.server.resourcemanager.scheduler.fair.FSAppAttempt: assignContainer(FSSchedulerNode node:cp-1.yarn-perf.yarnrm-PG0.wisc.cloudlab.us, boolean reserved=false) for appattempt_1476452954783_0003_000001
2016-10-14 07:51:55,918 INFO org.apache.hadoop.yarn.server.resourcemanager.scheduler.fair.FSAppAttempt: assignContainer(FSSchedulerNode node:cp-3.yarn-perf.yarnrm-PG0.wisc.cloudlab.us, boolean reserved=false) for appattempt_1476452954783_0001_000001
2016-10-14 07:51:55,918 INFO org.apache.hadoop.yarn.server.resourcemanager.scheduler.fair.FSAppAttempt: assignContainer(FSSchedulerNode node:cp-3.yarn-perf.yarnrm-PG0.wisc.cloudlab.us, boolean reserved=false) for appattempt_1476452954783_0002_000001
2016-10-14 07:51:55,918 INFO org.apache.hadoop.yarn.server.resourcemanager.scheduler.fair.FSAppAttempt: assignContainer(FSSchedulerNode node:cp-3.yarn-perf.yarnrm-PG0.wisc.cloudlab.us, boolean reserved=false) for appattempt_1476452954783_0003_000001
2016-10-14 07:51:55,940 INFO org.apache.hadoop.yarn.server.resourcemanager.scheduler.fair.FairScheduler: allocate(appattempt_1476452954783_0002_000001 [] [] [] []
2016-10-14 07:51:55,940 INFO org.apache.hadoop.yarn.server.resourcemanager.scheduler.fair.FSAppAttempt: root.interactive0 getMinReq:<memory:24576, vCores:12> demand: <memory:2048, vCores:1> usage: <memory:2048, vCores:1>running true active: true isLeafQueue():true
2016-10-14 07:51:55,940 INFO org.apache.hadoop.yarn.server.resourcemanager.scheduler.fair.FSAppAttempt: root.batch0 getMinReq:<memory:0, vCores:0> demand: <memory:4096, vCores:2> usage: <memory:4096, vCores:2>running true active: true isLeafQueue():true
2016-10-14 07:51:55,940 INFO org.apache.hadoop.yarn.server.resourcemanager.scheduler.fair.FSAppAttempt: appattempt_1476452954783_0002_000001 minReqResource: <memory:24576, vCores:12> flexibleResource: <memory:8192, vCores:4>
2016-10-14 07:51:55,940 INFO org.apache.hadoop.yarn.server.resourcemanager.scheduler.fair.FairScheduler: [admission control] getFlexibleResource <memory:8192, vCores:4>
2016-10-14 07:51:55,943 INFO org.apache.hadoop.yarn.server.resourcemanager.security.NMTokenSecretManagerInRM: Sending NMToken for nodeId : c220g1-030617.wisc.cloudlab.us:46119 for container : container_1476452954783_0002_01_000002
2016-10-14 07:51:55,948 INFO org.apache.hadoop.yarn.server.resourcemanager.rmcontainer.RMContainerImpl: Processing container_1476452954783_0002_01_000002 of event ACQUIRED
2016-10-14 07:51:55,948 INFO org.apache.hadoop.yarn.server.resourcemanager.rmcontainer.RMContainerImpl: container_1476452954783_0002_01_000002 Container Transitioned from ALLOCATED to ACQUIRED
2016-10-14 07:51:56,730 INFO org.apache.hadoop.yarn.server.resourcemanager.scheduler.fair.FairScheduler: allocate(appattempt_1476452954783_0001_000001 [{Priority: 1, Capability: <memory:1920, vCores:1>, # Containers: 1, Location: *, Relax Locality: true}] [] [] []
2016-10-14 07:51:56,730 INFO org.apache.hadoop.yarn.server.resourcemanager.scheduler.fair.FSAppAttempt: root.interactive0 getMinReq:<memory:24576, vCores:12> demand: <memory:2048, vCores:1> usage: <memory:2048, vCores:1>running true active: true isLeafQueue():true
2016-10-14 07:51:56,730 INFO org.apache.hadoop.yarn.server.resourcemanager.scheduler.fair.FSAppAttempt: root.batch0 getMinReq:<memory:0, vCores:0> demand: <memory:6144, vCores:3> usage: <memory:4096, vCores:2>running true active: true isLeafQueue():true
2016-10-14 07:51:56,730 INFO org.apache.hadoop.yarn.server.resourcemanager.scheduler.fair.FSAppAttempt: appattempt_1476452954783_0001_000001 minReqResource: <memory:24576, vCores:12> flexibleResource: <memory:8192, vCores:4>
2016-10-14 07:51:56,730 INFO org.apache.hadoop.yarn.server.resourcemanager.scheduler.fair.FairScheduler: [admission control] getFlexibleResource <memory:8192, vCores:4>
2016-10-14 07:51:56,730 INFO org.apache.hadoop.yarn.server.resourcemanager.scheduler.fair.FairScheduler: app appattempt_1476452954783_0001_000001 in queue root.interactive0 isRunning: true
2016-10-14 07:51:56,749 INFO org.apache.hadoop.yarn.server.resourcemanager.rmcontainer.RMContainerImpl: Processing container_1476452954783_0002_01_000002 of event LAUNCHED
2016-10-14 07:51:56,749 INFO org.apache.hadoop.yarn.server.resourcemanager.rmcontainer.RMContainerImpl: container_1476452954783_0002_01_000002 Container Transitioned from ACQUIRED to RUNNING
2016-10-14 07:51:56,750 INFO org.apache.hadoop.yarn.server.resourcemanager.scheduler.fair.FSAppAttempt: assignContainer(FSSchedulerNode node:c220g1-030617.wisc.cloudlab.us, boolean reserved=false) for appattempt_1476452954783_0001_000001
2016-10-14 07:51:56,750 INFO org.apache.hadoop.yarn.server.resourcemanager.scheduler.fair.FSAppAttempt: allocate container: container_1476452954783_0001_01_000002 priority 1
2016-10-14 07:51:56,751 INFO org.apache.hadoop.yarn.server.resourcemanager.rmcontainer.RMContainerImpl: Processing container_1476452954783_0001_01_000002 of event START
2016-10-14 07:51:56,751 INFO org.apache.hadoop.yarn.server.resourcemanager.rmcontainer.RMContainerImpl: container_1476452954783_0001_01_000002 Container Transitioned from NEW to ALLOCATED
2016-10-14 07:51:56,751 INFO org.apache.hadoop.yarn.server.resourcemanager.RMAuditLogger: USER=tanle	OPERATION=AM Allocated Container	TARGET=SchedulerApp	RESULT=SUCCESS	APPID=application_1476452954783_0001	CONTAINERID=container_1476452954783_0001_01_000002
2016-10-14 07:51:56,751 INFO org.apache.hadoop.yarn.server.resourcemanager.scheduler.SchedulerNode: Assigned container container_1476452954783_0001_01_000002 of capacity <memory:2048, vCores:1> on host c220g1-030617.wisc.cloudlab.us:46119, which has 3 containers, <memory:6144, vCores:3> used and <memory:2048, vCores:1> available after allocation
2016-10-14 07:51:56,752 INFO org.apache.hadoop.yarn.server.resourcemanager.scheduler.fair.FSAppAttempt: assignContainer(FSSchedulerNode node:cp-2.yarn-perf.yarnrm-PG0.wisc.cloudlab.us, boolean reserved=false) for appattempt_1476452954783_0001_000001
2016-10-14 07:51:56,752 INFO org.apache.hadoop.yarn.server.resourcemanager.scheduler.fair.FSAppAttempt: assignContainer(FSSchedulerNode node:cp-2.yarn-perf.yarnrm-PG0.wisc.cloudlab.us, boolean reserved=false) for appattempt_1476452954783_0002_000001
2016-10-14 07:51:56,752 INFO org.apache.hadoop.yarn.server.resourcemanager.scheduler.fair.FSAppAttempt: assignContainer(FSSchedulerNode node:cp-2.yarn-perf.yarnrm-PG0.wisc.cloudlab.us, boolean reserved=false) for appattempt_1476452954783_0003_000001
2016-10-14 07:51:56,857 INFO org.apache.hadoop.yarn.server.resourcemanager.scheduler.fair.FSAppAttempt: assignContainer(FSSchedulerNode node:cp-1.yarn-perf.yarnrm-PG0.wisc.cloudlab.us, boolean reserved=false) for appattempt_1476452954783_0001_000001
2016-10-14 07:51:56,857 INFO org.apache.hadoop.yarn.server.resourcemanager.scheduler.fair.FSAppAttempt: assignContainer(FSSchedulerNode node:cp-1.yarn-perf.yarnrm-PG0.wisc.cloudlab.us, boolean reserved=false) for appattempt_1476452954783_0002_000001
2016-10-14 07:51:56,857 INFO org.apache.hadoop.yarn.server.resourcemanager.scheduler.fair.FSAppAttempt: assignContainer(FSSchedulerNode node:cp-1.yarn-perf.yarnrm-PG0.wisc.cloudlab.us, boolean reserved=false) for appattempt_1476452954783_0003_000001
2016-10-14 07:51:56,920 INFO org.apache.hadoop.yarn.server.resourcemanager.scheduler.fair.FSAppAttempt: assignContainer(FSSchedulerNode node:cp-3.yarn-perf.yarnrm-PG0.wisc.cloudlab.us, boolean reserved=false) for appattempt_1476452954783_0001_000001
2016-10-14 07:51:56,920 INFO org.apache.hadoop.yarn.server.resourcemanager.scheduler.fair.FSAppAttempt: assignContainer(FSSchedulerNode node:cp-3.yarn-perf.yarnrm-PG0.wisc.cloudlab.us, boolean reserved=false) for appattempt_1476452954783_0002_000001
2016-10-14 07:51:56,920 INFO org.apache.hadoop.yarn.server.resourcemanager.scheduler.fair.FSAppAttempt: assignContainer(FSSchedulerNode node:cp-3.yarn-perf.yarnrm-PG0.wisc.cloudlab.us, boolean reserved=false) for appattempt_1476452954783_0003_000001
2016-10-14 07:51:56,934 INFO org.apache.hadoop.yarn.server.resourcemanager.scheduler.fair.FairScheduler: allocate(appattempt_1476452954783_0001_000001 [] [] [] []
2016-10-14 07:51:56,934 INFO org.apache.hadoop.yarn.server.resourcemanager.scheduler.fair.FSAppAttempt: root.interactive0 getMinReq:<memory:24576, vCores:12> demand: <memory:2048, vCores:1> usage: <memory:4096, vCores:2>running true active: true isLeafQueue():true
2016-10-14 07:51:56,934 INFO org.apache.hadoop.yarn.server.resourcemanager.scheduler.fair.FSAppAttempt: root.batch0 getMinReq:<memory:0, vCores:0> demand: <memory:6144, vCores:3> usage: <memory:4096, vCores:2>running true active: true isLeafQueue():true
2016-10-14 07:51:56,934 INFO org.apache.hadoop.yarn.server.resourcemanager.scheduler.fair.FSAppAttempt: appattempt_1476452954783_0001_000001 minReqResource: <memory:24576, vCores:12> flexibleResource: <memory:8192, vCores:4>
2016-10-14 07:51:56,934 INFO org.apache.hadoop.yarn.server.resourcemanager.scheduler.fair.FairScheduler: [admission control] getFlexibleResource <memory:8192, vCores:4>
2016-10-14 07:51:56,934 INFO org.apache.hadoop.yarn.server.resourcemanager.scheduler.fair.FairScheduler: app appattempt_1476452954783_0001_000001 in queue root.interactive0 isRunning: true
2016-10-14 07:51:56,936 INFO org.apache.hadoop.yarn.server.resourcemanager.security.NMTokenSecretManagerInRM: Sending NMToken for nodeId : c220g1-030617.wisc.cloudlab.us:46119 for container : container_1476452954783_0001_01_000002
2016-10-14 07:51:56,938 INFO org.apache.hadoop.yarn.server.resourcemanager.rmcontainer.RMContainerImpl: Processing container_1476452954783_0001_01_000002 of event ACQUIRED
2016-10-14 07:51:56,938 INFO org.apache.hadoop.yarn.server.resourcemanager.rmcontainer.RMContainerImpl: container_1476452954783_0001_01_000002 Container Transitioned from ALLOCATED to ACQUIRED
2016-10-14 07:51:57,753 INFO org.apache.hadoop.yarn.server.resourcemanager.rmcontainer.RMContainerImpl: Processing container_1476452954783_0001_01_000002 of event LAUNCHED
2016-10-14 07:51:57,753 INFO org.apache.hadoop.yarn.server.resourcemanager.rmcontainer.RMContainerImpl: container_1476452954783_0001_01_000002 Container Transitioned from ACQUIRED to RUNNING
2016-10-14 07:51:57,755 INFO org.apache.hadoop.yarn.server.resourcemanager.scheduler.fair.FSAppAttempt: assignContainer(FSSchedulerNode node:c220g1-030617.wisc.cloudlab.us, boolean reserved=false) for appattempt_1476452954783_0001_000001
2016-10-14 07:51:57,755 INFO org.apache.hadoop.yarn.server.resourcemanager.scheduler.fair.FSAppAttempt: assignContainer(FSSchedulerNode node:c220g1-030617.wisc.cloudlab.us, boolean reserved=false) for appattempt_1476452954783_0002_000001
2016-10-14 07:51:57,755 INFO org.apache.hadoop.yarn.server.resourcemanager.scheduler.fair.FSAppAttempt: assignContainer(FSSchedulerNode node:c220g1-030617.wisc.cloudlab.us, boolean reserved=false) for appattempt_1476452954783_0003_000001
2016-10-14 07:51:57,756 INFO org.apache.hadoop.yarn.server.resourcemanager.scheduler.fair.FSAppAttempt: assignContainer(FSSchedulerNode node:cp-2.yarn-perf.yarnrm-PG0.wisc.cloudlab.us, boolean reserved=false) for appattempt_1476452954783_0001_000001
2016-10-14 07:51:57,756 INFO org.apache.hadoop.yarn.server.resourcemanager.scheduler.fair.FSAppAttempt: assignContainer(FSSchedulerNode node:cp-2.yarn-perf.yarnrm-PG0.wisc.cloudlab.us, boolean reserved=false) for appattempt_1476452954783_0002_000001
2016-10-14 07:51:57,757 INFO org.apache.hadoop.yarn.server.resourcemanager.scheduler.fair.FSAppAttempt: assignContainer(FSSchedulerNode node:cp-2.yarn-perf.yarnrm-PG0.wisc.cloudlab.us, boolean reserved=false) for appattempt_1476452954783_0003_000001
2016-10-14 07:51:57,859 INFO org.apache.hadoop.yarn.server.resourcemanager.scheduler.fair.FSAppAttempt: assignContainer(FSSchedulerNode node:cp-1.yarn-perf.yarnrm-PG0.wisc.cloudlab.us, boolean reserved=false) for appattempt_1476452954783_0001_000001
2016-10-14 07:51:57,859 INFO org.apache.hadoop.yarn.server.resourcemanager.scheduler.fair.FSAppAttempt: assignContainer(FSSchedulerNode node:cp-1.yarn-perf.yarnrm-PG0.wisc.cloudlab.us, boolean reserved=false) for appattempt_1476452954783_0002_000001
2016-10-14 07:51:57,859 INFO org.apache.hadoop.yarn.server.resourcemanager.scheduler.fair.FSAppAttempt: assignContainer(FSSchedulerNode node:cp-1.yarn-perf.yarnrm-PG0.wisc.cloudlab.us, boolean reserved=false) for appattempt_1476452954783_0003_000001
2016-10-14 07:51:57,922 INFO org.apache.hadoop.yarn.server.resourcemanager.scheduler.fair.FSAppAttempt: assignContainer(FSSchedulerNode node:cp-3.yarn-perf.yarnrm-PG0.wisc.cloudlab.us, boolean reserved=false) for appattempt_1476452954783_0001_000001
2016-10-14 07:51:57,923 INFO org.apache.hadoop.yarn.server.resourcemanager.scheduler.fair.FSAppAttempt: assignContainer(FSSchedulerNode node:cp-3.yarn-perf.yarnrm-PG0.wisc.cloudlab.us, boolean reserved=false) for appattempt_1476452954783_0002_000001
2016-10-14 07:51:57,923 INFO org.apache.hadoop.yarn.server.resourcemanager.scheduler.fair.FSAppAttempt: assignContainer(FSSchedulerNode node:cp-3.yarn-perf.yarnrm-PG0.wisc.cloudlab.us, boolean reserved=false) for appattempt_1476452954783_0003_000001
2016-10-14 07:51:58,756 INFO org.apache.hadoop.yarn.server.resourcemanager.scheduler.fair.FSAppAttempt: assignContainer(FSSchedulerNode node:c220g1-030617.wisc.cloudlab.us, boolean reserved=false) for appattempt_1476452954783_0001_000001
2016-10-14 07:51:58,756 INFO org.apache.hadoop.yarn.server.resourcemanager.scheduler.fair.FSAppAttempt: assignContainer(FSSchedulerNode node:c220g1-030617.wisc.cloudlab.us, boolean reserved=false) for appattempt_1476452954783_0002_000001
2016-10-14 07:51:58,756 INFO org.apache.hadoop.yarn.server.resourcemanager.scheduler.fair.FSAppAttempt: assignContainer(FSSchedulerNode node:c220g1-030617.wisc.cloudlab.us, boolean reserved=false) for appattempt_1476452954783_0003_000001
2016-10-14 07:51:58,757 INFO org.apache.hadoop.yarn.server.resourcemanager.scheduler.fair.FSAppAttempt: assignContainer(FSSchedulerNode node:cp-2.yarn-perf.yarnrm-PG0.wisc.cloudlab.us, boolean reserved=false) for appattempt_1476452954783_0001_000001
2016-10-14 07:51:58,757 INFO org.apache.hadoop.yarn.server.resourcemanager.scheduler.fair.FSAppAttempt: assignContainer(FSSchedulerNode node:cp-2.yarn-perf.yarnrm-PG0.wisc.cloudlab.us, boolean reserved=false) for appattempt_1476452954783_0002_000001
2016-10-14 07:51:58,758 INFO org.apache.hadoop.yarn.server.resourcemanager.scheduler.fair.FSAppAttempt: assignContainer(FSSchedulerNode node:cp-2.yarn-perf.yarnrm-PG0.wisc.cloudlab.us, boolean reserved=false) for appattempt_1476452954783_0003_000001
2016-10-14 07:51:58,861 INFO org.apache.hadoop.yarn.server.resourcemanager.scheduler.fair.FSAppAttempt: assignContainer(FSSchedulerNode node:cp-1.yarn-perf.yarnrm-PG0.wisc.cloudlab.us, boolean reserved=false) for appattempt_1476452954783_0001_000001
2016-10-14 07:51:58,861 INFO org.apache.hadoop.yarn.server.resourcemanager.scheduler.fair.FSAppAttempt: assignContainer(FSSchedulerNode node:cp-1.yarn-perf.yarnrm-PG0.wisc.cloudlab.us, boolean reserved=false) for appattempt_1476452954783_0002_000001
2016-10-14 07:51:58,861 INFO org.apache.hadoop.yarn.server.resourcemanager.scheduler.fair.FSAppAttempt: assignContainer(FSSchedulerNode node:cp-1.yarn-perf.yarnrm-PG0.wisc.cloudlab.us, boolean reserved=false) for appattempt_1476452954783_0003_000001
2016-10-14 07:51:58,925 INFO org.apache.hadoop.yarn.server.resourcemanager.scheduler.fair.FSAppAttempt: assignContainer(FSSchedulerNode node:cp-3.yarn-perf.yarnrm-PG0.wisc.cloudlab.us, boolean reserved=false) for appattempt_1476452954783_0001_000001
2016-10-14 07:51:58,925 INFO org.apache.hadoop.yarn.server.resourcemanager.scheduler.fair.FSAppAttempt: assignContainer(FSSchedulerNode node:cp-3.yarn-perf.yarnrm-PG0.wisc.cloudlab.us, boolean reserved=false) for appattempt_1476452954783_0002_000001
2016-10-14 07:51:58,925 INFO org.apache.hadoop.yarn.server.resourcemanager.scheduler.fair.FSAppAttempt: assignContainer(FSSchedulerNode node:cp-3.yarn-perf.yarnrm-PG0.wisc.cloudlab.us, boolean reserved=false) for appattempt_1476452954783_0003_000001
2016-10-14 07:51:58,984 INFO org.apache.hadoop.yarn.server.resourcemanager.scheduler.fair.FairScheduler: allocate(appattempt_1476452954783_0002_000001 [{Priority: 1, Capability: <memory:1920, vCores:1>, # Containers: 0, Location: *, Relax Locality: true}] [] [] []
2016-10-14 07:51:58,984 INFO org.apache.hadoop.yarn.server.resourcemanager.scheduler.fair.FSAppAttempt: root.interactive0 getMinReq:<memory:24576, vCores:12> demand: <memory:4096, vCores:2> usage: <memory:4096, vCores:2>running true active: true isLeafQueue():true
2016-10-14 07:51:58,984 INFO org.apache.hadoop.yarn.server.resourcemanager.scheduler.fair.FSAppAttempt: root.batch0 getMinReq:<memory:0, vCores:0> demand: <memory:6144, vCores:3> usage: <memory:4096, vCores:2>running true active: true isLeafQueue():true
2016-10-14 07:51:58,985 INFO org.apache.hadoop.yarn.server.resourcemanager.scheduler.fair.FSAppAttempt: appattempt_1476452954783_0002_000001 minReqResource: <memory:24576, vCores:12> flexibleResource: <memory:8192, vCores:4>
2016-10-14 07:51:58,985 INFO org.apache.hadoop.yarn.server.resourcemanager.scheduler.fair.FairScheduler: [admission control] getFlexibleResource <memory:8192, vCores:4>
2016-10-14 07:51:58,985 INFO org.apache.hadoop.yarn.server.resourcemanager.scheduler.AppSchedulingInfo: checking for deactivate of application :application_1476452954783_0002
2016-10-14 07:51:59,759 INFO org.apache.hadoop.yarn.server.resourcemanager.scheduler.fair.FSAppAttempt: assignContainer(FSSchedulerNode node:c220g1-030617.wisc.cloudlab.us, boolean reserved=false) for appattempt_1476452954783_0001_000001
2016-10-14 07:51:59,759 INFO org.apache.hadoop.yarn.server.resourcemanager.scheduler.fair.FSAppAttempt: assignContainer(FSSchedulerNode node:c220g1-030617.wisc.cloudlab.us, boolean reserved=false) for appattempt_1476452954783_0002_000001
2016-10-14 07:51:59,759 INFO org.apache.hadoop.yarn.server.resourcemanager.scheduler.fair.FSAppAttempt: assignContainer(FSSchedulerNode node:c220g1-030617.wisc.cloudlab.us, boolean reserved=false) for appattempt_1476452954783_0003_000001
2016-10-14 07:51:59,760 INFO org.apache.hadoop.yarn.server.resourcemanager.scheduler.fair.FSAppAttempt: assignContainer(FSSchedulerNode node:cp-2.yarn-perf.yarnrm-PG0.wisc.cloudlab.us, boolean reserved=false) for appattempt_1476452954783_0001_000001
2016-10-14 07:51:59,760 INFO org.apache.hadoop.yarn.server.resourcemanager.scheduler.fair.FSAppAttempt: assignContainer(FSSchedulerNode node:cp-2.yarn-perf.yarnrm-PG0.wisc.cloudlab.us, boolean reserved=false) for appattempt_1476452954783_0002_000001
2016-10-14 07:51:59,760 INFO org.apache.hadoop.yarn.server.resourcemanager.scheduler.fair.FSAppAttempt: assignContainer(FSSchedulerNode node:cp-2.yarn-perf.yarnrm-PG0.wisc.cloudlab.us, boolean reserved=false) for appattempt_1476452954783_0003_000001
2016-10-14 07:51:59,863 INFO org.apache.hadoop.yarn.server.resourcemanager.scheduler.fair.FSAppAttempt: assignContainer(FSSchedulerNode node:cp-1.yarn-perf.yarnrm-PG0.wisc.cloudlab.us, boolean reserved=false) for appattempt_1476452954783_0001_000001
2016-10-14 07:51:59,864 INFO org.apache.hadoop.yarn.server.resourcemanager.scheduler.fair.FSAppAttempt: assignContainer(FSSchedulerNode node:cp-1.yarn-perf.yarnrm-PG0.wisc.cloudlab.us, boolean reserved=false) for appattempt_1476452954783_0002_000001
2016-10-14 07:51:59,864 INFO org.apache.hadoop.yarn.server.resourcemanager.scheduler.fair.FSAppAttempt: assignContainer(FSSchedulerNode node:cp-1.yarn-perf.yarnrm-PG0.wisc.cloudlab.us, boolean reserved=false) for appattempt_1476452954783_0003_000001
2016-10-14 07:51:59,927 INFO org.apache.hadoop.yarn.server.resourcemanager.scheduler.fair.FSAppAttempt: assignContainer(FSSchedulerNode node:cp-3.yarn-perf.yarnrm-PG0.wisc.cloudlab.us, boolean reserved=false) for appattempt_1476452954783_0001_000001
2016-10-14 07:51:59,928 INFO org.apache.hadoop.yarn.server.resourcemanager.scheduler.fair.FSAppAttempt: assignContainer(FSSchedulerNode node:cp-3.yarn-perf.yarnrm-PG0.wisc.cloudlab.us, boolean reserved=false) for appattempt_1476452954783_0002_000001
2016-10-14 07:51:59,928 INFO org.apache.hadoop.yarn.server.resourcemanager.scheduler.fair.FSAppAttempt: assignContainer(FSSchedulerNode node:cp-3.yarn-perf.yarnrm-PG0.wisc.cloudlab.us, boolean reserved=false) for appattempt_1476452954783_0003_000001
2016-10-14 07:51:59,971 INFO org.apache.hadoop.yarn.server.resourcemanager.scheduler.fair.FairScheduler: allocate(appattempt_1476452954783_0001_000001 [{Priority: 1, Capability: <memory:1920, vCores:1>, # Containers: 0, Location: *, Relax Locality: true}] [] [] []
2016-10-14 07:51:59,971 INFO org.apache.hadoop.yarn.server.resourcemanager.scheduler.fair.FSAppAttempt: root.interactive0 getMinReq:<memory:24576, vCores:12> demand: <memory:4096, vCores:2> usage: <memory:4096, vCores:2>running true active: true isLeafQueue():true
2016-10-14 07:51:59,971 INFO org.apache.hadoop.yarn.server.resourcemanager.scheduler.fair.FSAppAttempt: root.batch0 getMinReq:<memory:0, vCores:0> demand: <memory:6144, vCores:3> usage: <memory:4096, vCores:2>running true active: true isLeafQueue():true
2016-10-14 07:51:59,972 INFO org.apache.hadoop.yarn.server.resourcemanager.scheduler.fair.FSAppAttempt: appattempt_1476452954783_0001_000001 minReqResource: <memory:24576, vCores:12> flexibleResource: <memory:8192, vCores:4>
2016-10-14 07:51:59,972 INFO org.apache.hadoop.yarn.server.resourcemanager.scheduler.fair.FairScheduler: [admission control] getFlexibleResource <memory:8192, vCores:4>
2016-10-14 07:51:59,972 INFO org.apache.hadoop.yarn.server.resourcemanager.scheduler.fair.FairScheduler: app appattempt_1476452954783_0001_000001 in queue root.interactive0 isRunning: true
2016-10-14 07:51:59,972 INFO org.apache.hadoop.yarn.server.resourcemanager.scheduler.AppSchedulingInfo: checking for deactivate of application :application_1476452954783_0001
2016-10-14 07:52:00,653 INFO org.apache.hadoop.yarn.server.resourcemanager.scheduler.fair.FairScheduler: allocate(appattempt_1476452954783_0002_000001 [{Priority: 1, Capability: <memory:1920, vCores:1>, # Containers: 2, Location: *, Relax Locality: true}] [] [] []
2016-10-14 07:52:00,653 INFO org.apache.hadoop.yarn.server.resourcemanager.scheduler.fair.FSAppAttempt: root.interactive0 getMinReq:<memory:24576, vCores:12> demand: <memory:4096, vCores:2> usage: <memory:4096, vCores:2>running true active: true isLeafQueue():true
2016-10-14 07:52:00,653 INFO org.apache.hadoop.yarn.server.resourcemanager.scheduler.fair.FSAppAttempt: root.batch0 getMinReq:<memory:0, vCores:0> demand: <memory:6144, vCores:3> usage: <memory:4096, vCores:2>running true active: true isLeafQueue():true
2016-10-14 07:52:00,653 INFO org.apache.hadoop.yarn.server.resourcemanager.scheduler.fair.FSAppAttempt: appattempt_1476452954783_0002_000001 minReqResource: <memory:24576, vCores:12> flexibleResource: <memory:8192, vCores:4>
2016-10-14 07:52:00,653 INFO org.apache.hadoop.yarn.server.resourcemanager.scheduler.fair.FairScheduler: [admission control] getFlexibleResource <memory:8192, vCores:4>
2016-10-14 07:52:00,761 INFO org.apache.hadoop.yarn.server.resourcemanager.scheduler.fair.FSAppAttempt: assignContainer(FSSchedulerNode node:c220g1-030617.wisc.cloudlab.us, boolean reserved=false) for appattempt_1476452954783_0001_000001
2016-10-14 07:52:00,762 INFO org.apache.hadoop.yarn.server.resourcemanager.scheduler.fair.FSAppAttempt: assignContainer(FSSchedulerNode node:c220g1-030617.wisc.cloudlab.us, boolean reserved=false) for appattempt_1476452954783_0002_000001
2016-10-14 07:52:00,762 INFO org.apache.hadoop.yarn.server.resourcemanager.scheduler.fair.FSAppAttempt: allocate container: container_1476452954783_0002_01_000003 priority 1
2016-10-14 07:52:00,762 INFO org.apache.hadoop.yarn.server.resourcemanager.rmcontainer.RMContainerImpl: Processing container_1476452954783_0002_01_000003 of event START
2016-10-14 07:52:00,763 INFO org.apache.hadoop.yarn.server.resourcemanager.rmcontainer.RMContainerImpl: container_1476452954783_0002_01_000003 Container Transitioned from NEW to ALLOCATED
2016-10-14 07:52:00,763 INFO org.apache.hadoop.yarn.server.resourcemanager.RMAuditLogger: USER=tanle	OPERATION=AM Allocated Container	TARGET=SchedulerApp	RESULT=SUCCESS	APPID=application_1476452954783_0002	CONTAINERID=container_1476452954783_0002_01_000003
2016-10-14 07:52:00,763 INFO org.apache.hadoop.yarn.server.resourcemanager.scheduler.SchedulerNode: Assigned container container_1476452954783_0002_01_000003 of capacity <memory:2048, vCores:1> on host c220g1-030617.wisc.cloudlab.us:46119, which has 4 containers, <memory:8192, vCores:4> used and <memory:0, vCores:0> available after allocation
2016-10-14 07:52:00,764 INFO org.apache.hadoop.yarn.server.resourcemanager.scheduler.fair.FSAppAttempt: assignContainer(FSSchedulerNode node:cp-2.yarn-perf.yarnrm-PG0.wisc.cloudlab.us, boolean reserved=false) for appattempt_1476452954783_0001_000001
2016-10-14 07:52:00,764 INFO org.apache.hadoop.yarn.server.resourcemanager.scheduler.fair.FSAppAttempt: assignContainer(FSSchedulerNode node:cp-2.yarn-perf.yarnrm-PG0.wisc.cloudlab.us, boolean reserved=false) for appattempt_1476452954783_0002_000001
2016-10-14 07:52:00,764 INFO org.apache.hadoop.yarn.server.resourcemanager.scheduler.fair.FSAppAttempt: allocate container: container_1476452954783_0002_01_000004 priority 1
2016-10-14 07:52:00,765 INFO org.apache.hadoop.yarn.server.resourcemanager.rmcontainer.RMContainerImpl: Processing container_1476452954783_0002_01_000004 of event START
2016-10-14 07:52:00,765 INFO org.apache.hadoop.yarn.server.resourcemanager.rmcontainer.RMContainerImpl: container_1476452954783_0002_01_000004 Container Transitioned from NEW to ALLOCATED
2016-10-14 07:52:00,765 INFO org.apache.hadoop.yarn.server.resourcemanager.RMAuditLogger: USER=tanle	OPERATION=AM Allocated Container	TARGET=SchedulerApp	RESULT=SUCCESS	APPID=application_1476452954783_0002	CONTAINERID=container_1476452954783_0002_01_000004
2016-10-14 07:52:00,765 INFO org.apache.hadoop.yarn.server.resourcemanager.scheduler.SchedulerNode: Assigned container container_1476452954783_0002_01_000004 of capacity <memory:2048, vCores:1> on host cp-2.yarn-perf.yarnrm-PG0.wisc.cloudlab.us:43837, which has 2 containers, <memory:4096, vCores:2> used and <memory:4096, vCores:2> available after allocation
2016-10-14 07:52:00,856 INFO org.apache.hadoop.yarn.server.resourcemanager.scheduler.fair.FairScheduler: allocate(appattempt_1476452954783_0002_000001 [] [] [] []
2016-10-14 07:52:00,857 INFO org.apache.hadoop.yarn.server.resourcemanager.scheduler.fair.FSAppAttempt: root.interactive0 getMinReq:<memory:24576, vCores:12> demand: <memory:4096, vCores:2> usage: <memory:4096, vCores:2>running true active: true isLeafQueue():true
2016-10-14 07:52:00,857 INFO org.apache.hadoop.yarn.server.resourcemanager.scheduler.fair.FSAppAttempt: root.batch0 getMinReq:<memory:0, vCores:0> demand: <memory:6144, vCores:3> usage: <memory:8192, vCores:4>running true active: true isLeafQueue():true
2016-10-14 07:52:00,857 INFO org.apache.hadoop.yarn.server.resourcemanager.scheduler.fair.FSAppAttempt: appattempt_1476452954783_0002_000001 minReqResource: <memory:24576, vCores:12> flexibleResource: <memory:8192, vCores:4>
2016-10-14 07:52:00,857 INFO org.apache.hadoop.yarn.server.resourcemanager.scheduler.fair.FairScheduler: [admission control] getFlexibleResource <memory:8192, vCores:4>
2016-10-14 07:52:00,859 INFO org.apache.hadoop.yarn.server.resourcemanager.rmcontainer.RMContainerImpl: Processing container_1476452954783_0002_01_000003 of event ACQUIRED
2016-10-14 07:52:00,860 INFO org.apache.hadoop.yarn.server.resourcemanager.rmcontainer.RMContainerImpl: container_1476452954783_0002_01_000003 Container Transitioned from ALLOCATED to ACQUIRED
2016-10-14 07:52:00,861 INFO org.apache.hadoop.yarn.server.resourcemanager.security.NMTokenSecretManagerInRM: Sending NMToken for nodeId : cp-2.yarn-perf.yarnrm-PG0.wisc.cloudlab.us:43837 for container : container_1476452954783_0002_01_000004
2016-10-14 07:52:00,863 INFO org.apache.hadoop.yarn.server.resourcemanager.rmcontainer.RMContainerImpl: Processing container_1476452954783_0002_01_000004 of event ACQUIRED
2016-10-14 07:52:00,863 INFO org.apache.hadoop.yarn.server.resourcemanager.rmcontainer.RMContainerImpl: container_1476452954783_0002_01_000004 Container Transitioned from ALLOCATED to ACQUIRED
2016-10-14 07:52:00,866 INFO org.apache.hadoop.yarn.server.resourcemanager.scheduler.fair.FSAppAttempt: assignContainer(FSSchedulerNode node:cp-1.yarn-perf.yarnrm-PG0.wisc.cloudlab.us, boolean reserved=false) for appattempt_1476452954783_0001_000001
2016-10-14 07:52:00,866 INFO org.apache.hadoop.yarn.server.resourcemanager.scheduler.fair.FSAppAttempt: assignContainer(FSSchedulerNode node:cp-1.yarn-perf.yarnrm-PG0.wisc.cloudlab.us, boolean reserved=false) for appattempt_1476452954783_0002_000001
2016-10-14 07:52:00,866 INFO org.apache.hadoop.yarn.server.resourcemanager.scheduler.fair.FSAppAttempt: assignContainer(FSSchedulerNode node:cp-1.yarn-perf.yarnrm-PG0.wisc.cloudlab.us, boolean reserved=false) for appattempt_1476452954783_0003_000001
2016-10-14 07:52:00,930 INFO org.apache.hadoop.yarn.server.resourcemanager.scheduler.fair.FSAppAttempt: assignContainer(FSSchedulerNode node:cp-3.yarn-perf.yarnrm-PG0.wisc.cloudlab.us, boolean reserved=false) for appattempt_1476452954783_0001_000001
2016-10-14 07:52:00,930 INFO org.apache.hadoop.yarn.server.resourcemanager.scheduler.fair.FSAppAttempt: assignContainer(FSSchedulerNode node:cp-3.yarn-perf.yarnrm-PG0.wisc.cloudlab.us, boolean reserved=false) for appattempt_1476452954783_0002_000001
2016-10-14 07:52:00,930 INFO org.apache.hadoop.yarn.server.resourcemanager.scheduler.fair.FSAppAttempt: assignContainer(FSSchedulerNode node:cp-3.yarn-perf.yarnrm-PG0.wisc.cloudlab.us, boolean reserved=false) for appattempt_1476452954783_0003_000001
2016-10-14 07:52:01,647 INFO org.apache.hadoop.yarn.server.resourcemanager.scheduler.fair.FairScheduler: allocate(appattempt_1476452954783_0001_000001 [{Priority: 1, Capability: <memory:1920, vCores:1>, # Containers: 2, Location: *, Relax Locality: true}] [] [] []
2016-10-14 07:52:01,647 INFO org.apache.hadoop.yarn.server.resourcemanager.scheduler.fair.FSAppAttempt: root.interactive0 getMinReq:<memory:24576, vCores:12> demand: <memory:4096, vCores:2> usage: <memory:4096, vCores:2>running true active: true isLeafQueue():true
2016-10-14 07:52:01,647 INFO org.apache.hadoop.yarn.server.resourcemanager.scheduler.fair.FSAppAttempt: root.batch0 getMinReq:<memory:0, vCores:0> demand: <memory:10240, vCores:5> usage: <memory:8192, vCores:4>running true active: true isLeafQueue():true
2016-10-14 07:52:01,647 INFO org.apache.hadoop.yarn.server.resourcemanager.scheduler.fair.FSAppAttempt: appattempt_1476452954783_0001_000001 minReqResource: <memory:24576, vCores:12> flexibleResource: <memory:8192, vCores:4>
2016-10-14 07:52:01,647 INFO org.apache.hadoop.yarn.server.resourcemanager.scheduler.fair.FairScheduler: [admission control] getFlexibleResource <memory:8192, vCores:4>
2016-10-14 07:52:01,647 INFO org.apache.hadoop.yarn.server.resourcemanager.scheduler.fair.FairScheduler: app appattempt_1476452954783_0001_000001 in queue root.interactive0 isRunning: true
2016-10-14 07:52:01,763 INFO org.apache.hadoop.yarn.server.resourcemanager.rmcontainer.RMContainerImpl: Processing container_1476452954783_0002_01_000003 of event LAUNCHED
2016-10-14 07:52:01,763 INFO org.apache.hadoop.yarn.server.resourcemanager.rmcontainer.RMContainerImpl: container_1476452954783_0002_01_000003 Container Transitioned from ACQUIRED to RUNNING
2016-10-14 07:52:01,764 INFO org.apache.hadoop.yarn.server.resourcemanager.scheduler.fair.FSAppAttempt: assignContainer(FSSchedulerNode node:c220g1-030617.wisc.cloudlab.us, boolean reserved=false) for appattempt_1476452954783_0001_000001
2016-10-14 07:52:01,765 INFO org.apache.hadoop.yarn.server.resourcemanager.scheduler.fair.FSAppAttempt: Making reservation: node=c220g1-030617.wisc.cloudlab.us app_id=application_1476452954783_0001
2016-10-14 07:52:01,766 INFO org.apache.hadoop.yarn.server.resourcemanager.rmcontainer.RMContainerImpl: Processing container_1476452954783_0001_01_000003 of event RESERVED
2016-10-14 07:52:01,766 INFO org.apache.hadoop.yarn.server.resourcemanager.rmcontainer.RMContainerImpl: container_1476452954783_0001_01_000003 Container Transitioned from NEW to RESERVED
2016-10-14 07:52:01,766 INFO org.apache.hadoop.yarn.server.resourcemanager.scheduler.fair.FSSchedulerNode: Reserved container container_1476452954783_0001_01_000003 on node host: c220g1-030617.wisc.cloudlab.us:46119 #containers=4 available=<memory:0, vCores:0> used=<memory:8192, vCores:4> for application org.apache.hadoop.yarn.server.resourcemanager.scheduler.fair.FSAppAttempt@13f22e88
2016-10-14 07:52:01,767 INFO org.apache.hadoop.yarn.server.resourcemanager.rmcontainer.RMContainerImpl: Processing container_1476452954783_0002_01_000004 of event LAUNCHED
2016-10-14 07:52:01,767 INFO org.apache.hadoop.yarn.server.resourcemanager.rmcontainer.RMContainerImpl: container_1476452954783_0002_01_000004 Container Transitioned from ACQUIRED to RUNNING
2016-10-14 07:52:01,768 INFO org.apache.hadoop.yarn.server.resourcemanager.scheduler.fair.FSAppAttempt: assignContainer(FSSchedulerNode node:cp-2.yarn-perf.yarnrm-PG0.wisc.cloudlab.us, boolean reserved=false) for appattempt_1476452954783_0001_000001
2016-10-14 07:52:01,768 INFO org.apache.hadoop.yarn.server.resourcemanager.scheduler.fair.FSAppAttempt: allocate container: container_1476452954783_0001_01_000004 priority 1
2016-10-14 07:52:01,768 INFO org.apache.hadoop.yarn.server.resourcemanager.rmcontainer.RMContainerImpl: Processing container_1476452954783_0001_01_000004 of event START
2016-10-14 07:52:01,768 INFO org.apache.hadoop.yarn.server.resourcemanager.rmcontainer.RMContainerImpl: container_1476452954783_0001_01_000004 Container Transitioned from NEW to ALLOCATED
2016-10-14 07:52:01,769 INFO org.apache.hadoop.yarn.server.resourcemanager.RMAuditLogger: USER=tanle	OPERATION=AM Allocated Container	TARGET=SchedulerApp	RESULT=SUCCESS	APPID=application_1476452954783_0001	CONTAINERID=container_1476452954783_0001_01_000004
2016-10-14 07:52:01,769 INFO org.apache.hadoop.yarn.server.resourcemanager.scheduler.SchedulerNode: Assigned container container_1476452954783_0001_01_000004 of capacity <memory:2048, vCores:1> on host cp-2.yarn-perf.yarnrm-PG0.wisc.cloudlab.us:43837, which has 3 containers, <memory:6144, vCores:3> used and <memory:2048, vCores:1> available after allocation
2016-10-14 07:52:01,850 INFO org.apache.hadoop.yarn.server.resourcemanager.scheduler.fair.FairScheduler: allocate(appattempt_1476452954783_0001_000001 [] [] [] []
2016-10-14 07:52:01,850 INFO org.apache.hadoop.yarn.server.resourcemanager.scheduler.fair.FSAppAttempt: root.interactive0 getMinReq:<memory:24576, vCores:12> demand: <memory:4096, vCores:2> usage: <memory:6144, vCores:3>running true active: true isLeafQueue():true
2016-10-14 07:52:01,850 INFO org.apache.hadoop.yarn.server.resourcemanager.scheduler.fair.FSAppAttempt: root.batch0 getMinReq:<memory:0, vCores:0> demand: <memory:10240, vCores:5> usage: <memory:8192, vCores:4>running true active: true isLeafQueue():true
2016-10-14 07:52:01,851 INFO org.apache.hadoop.yarn.server.resourcemanager.scheduler.fair.FSAppAttempt: appattempt_1476452954783_0001_000001 minReqResource: <memory:24576, vCores:12> flexibleResource: <memory:8192, vCores:4>
2016-10-14 07:52:01,851 INFO org.apache.hadoop.yarn.server.resourcemanager.scheduler.fair.FairScheduler: [admission control] getFlexibleResource <memory:8192, vCores:4>
2016-10-14 07:52:01,851 INFO org.apache.hadoop.yarn.server.resourcemanager.scheduler.fair.FairScheduler: app appattempt_1476452954783_0001_000001 in queue root.interactive0 isRunning: true
2016-10-14 07:52:01,853 INFO org.apache.hadoop.yarn.server.resourcemanager.security.NMTokenSecretManagerInRM: Sending NMToken for nodeId : cp-2.yarn-perf.yarnrm-PG0.wisc.cloudlab.us:43837 for container : container_1476452954783_0001_01_000004
2016-10-14 07:52:01,858 INFO org.apache.hadoop.yarn.server.resourcemanager.rmcontainer.RMContainerImpl: Processing container_1476452954783_0001_01_000004 of event ACQUIRED
2016-10-14 07:52:01,858 INFO org.apache.hadoop.yarn.server.resourcemanager.rmcontainer.RMContainerImpl: container_1476452954783_0001_01_000004 Container Transitioned from ALLOCATED to ACQUIRED
2016-10-14 07:52:01,868 INFO org.apache.hadoop.yarn.server.resourcemanager.scheduler.fair.FSAppAttempt: assignContainer(FSSchedulerNode node:cp-1.yarn-perf.yarnrm-PG0.wisc.cloudlab.us, boolean reserved=false) for appattempt_1476452954783_0001_000001
2016-10-14 07:52:01,868 INFO org.apache.hadoop.yarn.server.resourcemanager.scheduler.fair.FSAppAttempt: allocate container: container_1476452954783_0001_01_000005 priority 1
2016-10-14 07:52:01,868 INFO org.apache.hadoop.yarn.server.resourcemanager.rmcontainer.RMContainerImpl: Processing container_1476452954783_0001_01_000005 of event START
2016-10-14 07:52:01,869 INFO org.apache.hadoop.yarn.server.resourcemanager.rmcontainer.RMContainerImpl: container_1476452954783_0001_01_000005 Container Transitioned from NEW to ALLOCATED
2016-10-14 07:52:01,869 INFO org.apache.hadoop.yarn.server.resourcemanager.RMAuditLogger: USER=tanle	OPERATION=AM Allocated Container	TARGET=SchedulerApp	RESULT=SUCCESS	APPID=application_1476452954783_0001	CONTAINERID=container_1476452954783_0001_01_000005
2016-10-14 07:52:01,869 INFO org.apache.hadoop.yarn.server.resourcemanager.scheduler.SchedulerNode: Assigned container container_1476452954783_0001_01_000005 of capacity <memory:2048, vCores:1> on host cp-1.yarn-perf.yarnrm-PG0.wisc.cloudlab.us:36424, which has 1 containers, <memory:2048, vCores:1> used and <memory:6144, vCores:3> available after allocation
2016-10-14 07:52:01,932 INFO org.apache.hadoop.yarn.server.resourcemanager.scheduler.fair.FSAppAttempt: assignContainer(FSSchedulerNode node:cp-3.yarn-perf.yarnrm-PG0.wisc.cloudlab.us, boolean reserved=false) for appattempt_1476452954783_0001_000001
2016-10-14 07:52:01,932 INFO org.apache.hadoop.yarn.server.resourcemanager.scheduler.fair.FSAppAttempt: assignContainer(FSSchedulerNode node:cp-3.yarn-perf.yarnrm-PG0.wisc.cloudlab.us, boolean reserved=false) for appattempt_1476452954783_0002_000001
2016-10-14 07:52:01,933 INFO org.apache.hadoop.yarn.server.resourcemanager.scheduler.fair.FSAppAttempt: assignContainer(FSSchedulerNode node:cp-3.yarn-perf.yarnrm-PG0.wisc.cloudlab.us, boolean reserved=false) for appattempt_1476452954783_0003_000001
2016-10-14 07:52:02,266 INFO org.apache.hadoop.yarn.server.resourcemanager.scheduler.fair.FairScheduler: allocate(appattempt_1476452954783_0001_000001 [{Priority: 1, Capability: <memory:1920, vCores:1>, # Containers: 1, Location: *, Relax Locality: true}] [] [] []
2016-10-14 07:52:02,267 INFO org.apache.hadoop.yarn.server.resourcemanager.scheduler.fair.FSAppAttempt: root.interactive0 getMinReq:<memory:24576, vCores:12> demand: <memory:8192, vCores:4> usage: <memory:8192, vCores:4>running true active: true isLeafQueue():true
2016-10-14 07:52:02,267 INFO org.apache.hadoop.yarn.server.resourcemanager.scheduler.fair.FSAppAttempt: root.batch0 getMinReq:<memory:0, vCores:0> demand: <memory:10240, vCores:5> usage: <memory:8192, vCores:4>running true active: true isLeafQueue():true
2016-10-14 07:52:02,267 INFO org.apache.hadoop.yarn.server.resourcemanager.scheduler.fair.FSAppAttempt: appattempt_1476452954783_0001_000001 minReqResource: <memory:24576, vCores:12> flexibleResource: <memory:8192, vCores:4>
2016-10-14 07:52:02,267 INFO org.apache.hadoop.yarn.server.resourcemanager.scheduler.fair.FairScheduler: [admission control] getFlexibleResource <memory:8192, vCores:4>
2016-10-14 07:52:02,267 INFO org.apache.hadoop.yarn.server.resourcemanager.scheduler.fair.FairScheduler: app appattempt_1476452954783_0001_000001 in queue root.interactive0 isRunning: true
2016-10-14 07:52:02,281 INFO org.apache.hadoop.yarn.server.resourcemanager.security.NMTokenSecretManagerInRM: Sending NMToken for nodeId : cp-1.yarn-perf.yarnrm-PG0.wisc.cloudlab.us:36424 for container : container_1476452954783_0001_01_000005
2016-10-14 07:52:02,283 INFO org.apache.hadoop.yarn.server.resourcemanager.rmcontainer.RMContainerImpl: Processing container_1476452954783_0001_01_000005 of event ACQUIRED
2016-10-14 07:52:02,284 INFO org.apache.hadoop.yarn.server.resourcemanager.rmcontainer.RMContainerImpl: container_1476452954783_0001_01_000005 Container Transitioned from ALLOCATED to ACQUIRED
2016-10-14 07:52:02,768 INFO org.apache.hadoop.yarn.server.resourcemanager.rmcontainer.RMContainerImpl: Processing container_1476452954783_0001_01_000004 of event LAUNCHED
2016-10-14 07:52:02,768 INFO org.apache.hadoop.yarn.server.resourcemanager.rmcontainer.RMContainerImpl: container_1476452954783_0001_01_000004 Container Transitioned from ACQUIRED to RUNNING
2016-10-14 07:52:02,769 INFO org.apache.hadoop.yarn.server.resourcemanager.scheduler.fair.FSAppAttempt: assignContainer(FSSchedulerNode node:cp-2.yarn-perf.yarnrm-PG0.wisc.cloudlab.us, boolean reserved=false) for appattempt_1476452954783_0001_000001
2016-10-14 07:52:02,770 INFO org.apache.hadoop.yarn.server.resourcemanager.scheduler.fair.FSAppAttempt: allocate container: container_1476452954783_0001_01_000006 priority 1
2016-10-14 07:52:02,770 INFO org.apache.hadoop.yarn.server.resourcemanager.rmcontainer.RMContainerImpl: Processing container_1476452954783_0001_01_000006 of event START
2016-10-14 07:52:02,770 INFO org.apache.hadoop.yarn.server.resourcemanager.rmcontainer.RMContainerImpl: container_1476452954783_0001_01_000006 Container Transitioned from NEW to ALLOCATED
2016-10-14 07:52:02,770 INFO org.apache.hadoop.yarn.server.resourcemanager.RMAuditLogger: USER=tanle	OPERATION=AM Allocated Container	TARGET=SchedulerApp	RESULT=SUCCESS	APPID=application_1476452954783_0001	CONTAINERID=container_1476452954783_0001_01_000006
2016-10-14 07:52:02,770 INFO org.apache.hadoop.yarn.server.resourcemanager.scheduler.SchedulerNode: Assigned container container_1476452954783_0001_01_000006 of capacity <memory:2048, vCores:1> on host cp-2.yarn-perf.yarnrm-PG0.wisc.cloudlab.us:43837, which has 4 containers, <memory:8192, vCores:4> used and <memory:0, vCores:0> available after allocation
2016-10-14 07:52:02,877 INFO org.apache.hadoop.yarn.server.resourcemanager.rmcontainer.RMContainerImpl: Processing container_1476452954783_0001_01_000005 of event LAUNCHED
2016-10-14 07:52:02,877 INFO org.apache.hadoop.yarn.server.resourcemanager.rmcontainer.RMContainerImpl: container_1476452954783_0001_01_000005 Container Transitioned from ACQUIRED to RUNNING
2016-10-14 07:52:02,878 INFO org.apache.hadoop.yarn.server.resourcemanager.scheduler.fair.FSAppAttempt: assignContainer(FSSchedulerNode node:cp-1.yarn-perf.yarnrm-PG0.wisc.cloudlab.us, boolean reserved=false) for appattempt_1476452954783_0001_000001
2016-10-14 07:52:02,878 INFO org.apache.hadoop.yarn.server.resourcemanager.scheduler.fair.FSAppAttempt: assignContainer(FSSchedulerNode node:cp-1.yarn-perf.yarnrm-PG0.wisc.cloudlab.us, boolean reserved=false) for appattempt_1476452954783_0002_000001
2016-10-14 07:52:02,878 INFO org.apache.hadoop.yarn.server.resourcemanager.scheduler.fair.FSAppAttempt: assignContainer(FSSchedulerNode node:cp-1.yarn-perf.yarnrm-PG0.wisc.cloudlab.us, boolean reserved=false) for appattempt_1476452954783_0003_000001
2016-10-14 07:52:02,935 INFO org.apache.hadoop.yarn.server.resourcemanager.scheduler.fair.FSAppAttempt: assignContainer(FSSchedulerNode node:cp-3.yarn-perf.yarnrm-PG0.wisc.cloudlab.us, boolean reserved=false) for appattempt_1476452954783_0001_000001
2016-10-14 07:52:02,935 INFO org.apache.hadoop.yarn.server.resourcemanager.scheduler.fair.FSAppAttempt: assignContainer(FSSchedulerNode node:cp-3.yarn-perf.yarnrm-PG0.wisc.cloudlab.us, boolean reserved=false) for appattempt_1476452954783_0002_000001
2016-10-14 07:52:02,935 INFO org.apache.hadoop.yarn.server.resourcemanager.scheduler.fair.FSAppAttempt: assignContainer(FSSchedulerNode node:cp-3.yarn-perf.yarnrm-PG0.wisc.cloudlab.us, boolean reserved=false) for appattempt_1476452954783_0003_000001
2016-10-14 07:52:03,768 INFO org.apache.hadoop.yarn.server.resourcemanager.scheduler.fair.FairScheduler: Releasing reservation that cannot be satisfied for application appattempt_1476452954783_0001_000001 on node host: c220g1-030617.wisc.cloudlab.us:46119 #containers=4 available=<memory:0, vCores:0> used=<memory:8192, vCores:4>
2016-10-14 07:52:03,769 INFO org.apache.hadoop.yarn.server.resourcemanager.scheduler.fair.FSAppAttempt: Application application_1476452954783_0001 unreserved  on node host: c220g1-030617.wisc.cloudlab.us:46119 #containers=4 available=<memory:0, vCores:0> used=<memory:8192, vCores:4>, currently has 0 at priority 1; currentReservation <memory:0, vCores:0>
2016-10-14 07:52:03,770 INFO org.apache.hadoop.yarn.server.resourcemanager.scheduler.fair.FSAppAttempt: assignContainer(FSSchedulerNode node:c220g1-030617.wisc.cloudlab.us, boolean reserved=false) for appattempt_1476452954783_0001_000001
2016-10-14 07:52:03,770 INFO org.apache.hadoop.yarn.server.resourcemanager.scheduler.fair.FSAppAttempt: assignContainer(FSSchedulerNode node:c220g1-030617.wisc.cloudlab.us, boolean reserved=false) for appattempt_1476452954783_0002_000001
2016-10-14 07:52:03,770 INFO org.apache.hadoop.yarn.server.resourcemanager.scheduler.fair.FSAppAttempt: assignContainer(FSSchedulerNode node:c220g1-030617.wisc.cloudlab.us, boolean reserved=false) for appattempt_1476452954783_0003_000001
2016-10-14 07:52:03,771 INFO org.apache.hadoop.yarn.server.resourcemanager.scheduler.fair.FSAppAttempt: assignContainer(FSSchedulerNode node:cp-2.yarn-perf.yarnrm-PG0.wisc.cloudlab.us, boolean reserved=false) for appattempt_1476452954783_0001_000001
2016-10-14 07:52:03,771 INFO org.apache.hadoop.yarn.server.resourcemanager.scheduler.fair.FSAppAttempt: assignContainer(FSSchedulerNode node:cp-2.yarn-perf.yarnrm-PG0.wisc.cloudlab.us, boolean reserved=false) for appattempt_1476452954783_0002_000001
2016-10-14 07:52:03,771 INFO org.apache.hadoop.yarn.server.resourcemanager.scheduler.fair.FSAppAttempt: assignContainer(FSSchedulerNode node:cp-2.yarn-perf.yarnrm-PG0.wisc.cloudlab.us, boolean reserved=false) for appattempt_1476452954783_0003_000001
2016-10-14 07:52:03,877 INFO org.apache.hadoop.yarn.server.resourcemanager.scheduler.fair.FairScheduler: allocate(appattempt_1476452954783_0002_000001 [{Priority: 1, Capability: <memory:1920, vCores:1>, # Containers: 0, Location: *, Relax Locality: true}] [] [] []
2016-10-14 07:52:03,877 INFO org.apache.hadoop.yarn.server.resourcemanager.scheduler.fair.FSAppAttempt: root.interactive0 getMinReq:<memory:24576, vCores:12> demand: <memory:10240, vCores:5> usage: <memory:10240, vCores:5>running true active: true isLeafQueue():true
2016-10-14 07:52:03,877 INFO org.apache.hadoop.yarn.server.resourcemanager.scheduler.fair.FSAppAttempt: root.batch0 getMinReq:<memory:0, vCores:0> demand: <memory:10240, vCores:5> usage: <memory:8192, vCores:4>running true active: true isLeafQueue():true
2016-10-14 07:52:03,877 INFO org.apache.hadoop.yarn.server.resourcemanager.scheduler.fair.FSAppAttempt: appattempt_1476452954783_0002_000001 minReqResource: <memory:24576, vCores:12> flexibleResource: <memory:8192, vCores:4>
2016-10-14 07:52:03,877 INFO org.apache.hadoop.yarn.server.resourcemanager.scheduler.fair.FairScheduler: [admission control] getFlexibleResource <memory:8192, vCores:4>
2016-10-14 07:52:03,877 INFO org.apache.hadoop.yarn.server.resourcemanager.scheduler.AppSchedulingInfo: checking for deactivate of application :application_1476452954783_0002
2016-10-14 07:52:03,880 INFO org.apache.hadoop.yarn.server.resourcemanager.scheduler.fair.FSAppAttempt: assignContainer(FSSchedulerNode node:cp-1.yarn-perf.yarnrm-PG0.wisc.cloudlab.us, boolean reserved=false) for appattempt_1476452954783_0001_000001
2016-10-14 07:52:03,880 INFO org.apache.hadoop.yarn.server.resourcemanager.scheduler.fair.FSAppAttempt: assignContainer(FSSchedulerNode node:cp-1.yarn-perf.yarnrm-PG0.wisc.cloudlab.us, boolean reserved=false) for appattempt_1476452954783_0002_000001
2016-10-14 07:52:03,880 INFO org.apache.hadoop.yarn.server.resourcemanager.scheduler.fair.FSAppAttempt: assignContainer(FSSchedulerNode node:cp-1.yarn-perf.yarnrm-PG0.wisc.cloudlab.us, boolean reserved=false) for appattempt_1476452954783_0003_000001
2016-10-14 07:52:03,937 INFO org.apache.hadoop.yarn.server.resourcemanager.scheduler.fair.FSAppAttempt: assignContainer(FSSchedulerNode node:cp-3.yarn-perf.yarnrm-PG0.wisc.cloudlab.us, boolean reserved=false) for appattempt_1476452954783_0001_000001
2016-10-14 07:52:03,937 INFO org.apache.hadoop.yarn.server.resourcemanager.scheduler.fair.FSAppAttempt: assignContainer(FSSchedulerNode node:cp-3.yarn-perf.yarnrm-PG0.wisc.cloudlab.us, boolean reserved=false) for appattempt_1476452954783_0002_000001
2016-10-14 07:52:03,937 INFO org.apache.hadoop.yarn.server.resourcemanager.scheduler.fair.FSAppAttempt: assignContainer(FSSchedulerNode node:cp-3.yarn-perf.yarnrm-PG0.wisc.cloudlab.us, boolean reserved=false) for appattempt_1476452954783_0003_000001
2016-10-14 07:52:04,782 INFO org.apache.hadoop.yarn.server.resourcemanager.scheduler.fair.FSAppAttempt: assignContainer(FSSchedulerNode node:c220g1-030617.wisc.cloudlab.us, boolean reserved=false) for appattempt_1476452954783_0001_000001
2016-10-14 07:52:04,782 INFO org.apache.hadoop.yarn.server.resourcemanager.scheduler.fair.FSAppAttempt: assignContainer(FSSchedulerNode node:c220g1-030617.wisc.cloudlab.us, boolean reserved=false) for appattempt_1476452954783_0002_000001
2016-10-14 07:52:04,782 INFO org.apache.hadoop.yarn.server.resourcemanager.scheduler.fair.FSAppAttempt: assignContainer(FSSchedulerNode node:c220g1-030617.wisc.cloudlab.us, boolean reserved=false) for appattempt_1476452954783_0003_000001
2016-10-14 07:52:04,783 INFO org.apache.hadoop.yarn.server.resourcemanager.scheduler.fair.FSAppAttempt: assignContainer(FSSchedulerNode node:cp-2.yarn-perf.yarnrm-PG0.wisc.cloudlab.us, boolean reserved=false) for appattempt_1476452954783_0001_000001
2016-10-14 07:52:04,783 INFO org.apache.hadoop.yarn.server.resourcemanager.scheduler.fair.FSAppAttempt: assignContainer(FSSchedulerNode node:cp-2.yarn-perf.yarnrm-PG0.wisc.cloudlab.us, boolean reserved=false) for appattempt_1476452954783_0002_000001
2016-10-14 07:52:04,783 INFO org.apache.hadoop.yarn.server.resourcemanager.scheduler.fair.FSAppAttempt: assignContainer(FSSchedulerNode node:cp-2.yarn-perf.yarnrm-PG0.wisc.cloudlab.us, boolean reserved=false) for appattempt_1476452954783_0003_000001
2016-10-14 07:52:04,883 INFO org.apache.hadoop.yarn.server.resourcemanager.scheduler.fair.FSAppAttempt: assignContainer(FSSchedulerNode node:cp-1.yarn-perf.yarnrm-PG0.wisc.cloudlab.us, boolean reserved=false) for appattempt_1476452954783_0001_000001
2016-10-14 07:52:04,883 INFO org.apache.hadoop.yarn.server.resourcemanager.scheduler.fair.FSAppAttempt: assignContainer(FSSchedulerNode node:cp-1.yarn-perf.yarnrm-PG0.wisc.cloudlab.us, boolean reserved=false) for appattempt_1476452954783_0002_000001
2016-10-14 07:52:04,883 INFO org.apache.hadoop.yarn.server.resourcemanager.scheduler.fair.FSAppAttempt: assignContainer(FSSchedulerNode node:cp-1.yarn-perf.yarnrm-PG0.wisc.cloudlab.us, boolean reserved=false) for appattempt_1476452954783_0003_000001
2016-10-14 07:52:04,940 INFO org.apache.hadoop.yarn.server.resourcemanager.scheduler.fair.FSAppAttempt: assignContainer(FSSchedulerNode node:cp-3.yarn-perf.yarnrm-PG0.wisc.cloudlab.us, boolean reserved=false) for appattempt_1476452954783_0001_000001
2016-10-14 07:52:04,940 INFO org.apache.hadoop.yarn.server.resourcemanager.scheduler.fair.FSAppAttempt: assignContainer(FSSchedulerNode node:cp-3.yarn-perf.yarnrm-PG0.wisc.cloudlab.us, boolean reserved=false) for appattempt_1476452954783_0002_000001
2016-10-14 07:52:04,940 INFO org.apache.hadoop.yarn.server.resourcemanager.scheduler.fair.FSAppAttempt: assignContainer(FSSchedulerNode node:cp-3.yarn-perf.yarnrm-PG0.wisc.cloudlab.us, boolean reserved=false) for appattempt_1476452954783_0003_000001
2016-10-14 07:52:05,292 INFO org.apache.hadoop.yarn.server.resourcemanager.scheduler.fair.FairScheduler: allocate(appattempt_1476452954783_0001_000001 [{Priority: 1, Capability: <memory:1920, vCores:1>, # Containers: 0, Location: *, Relax Locality: true}] [] [] []
2016-10-14 07:52:05,292 INFO org.apache.hadoop.yarn.server.resourcemanager.scheduler.fair.FSAppAttempt: root.interactive0 getMinReq:<memory:24576, vCores:12> demand: <memory:10240, vCores:5> usage: <memory:10240, vCores:5>running true active: true isLeafQueue():true
2016-10-14 07:52:05,292 INFO org.apache.hadoop.yarn.server.resourcemanager.scheduler.fair.FSAppAttempt: root.batch0 getMinReq:<memory:0, vCores:0> demand: <memory:10240, vCores:5> usage: <memory:8192, vCores:4>running true active: true isLeafQueue():true
2016-10-14 07:52:05,292 INFO org.apache.hadoop.yarn.server.resourcemanager.scheduler.fair.FSAppAttempt: appattempt_1476452954783_0001_000001 minReqResource: <memory:24576, vCores:12> flexibleResource: <memory:8192, vCores:4>
2016-10-14 07:52:05,292 INFO org.apache.hadoop.yarn.server.resourcemanager.scheduler.fair.FairScheduler: [admission control] getFlexibleResource <memory:8192, vCores:4>
2016-10-14 07:52:05,292 INFO org.apache.hadoop.yarn.server.resourcemanager.scheduler.fair.FairScheduler: app appattempt_1476452954783_0001_000001 in queue root.interactive0 isRunning: true
2016-10-14 07:52:05,293 INFO org.apache.hadoop.yarn.server.resourcemanager.scheduler.AppSchedulingInfo: checking for deactivate of application :application_1476452954783_0001
2016-10-14 07:52:05,295 INFO org.apache.hadoop.yarn.server.resourcemanager.rmcontainer.RMContainerImpl: Processing container_1476452954783_0001_01_000006 of event ACQUIRED
2016-10-14 07:52:05,296 INFO org.apache.hadoop.yarn.server.resourcemanager.rmcontainer.RMContainerImpl: container_1476452954783_0001_01_000006 Container Transitioned from ALLOCATED to ACQUIRED
2016-10-14 07:52:05,655 INFO org.apache.hadoop.yarn.server.resourcemanager.scheduler.fair.FairScheduler: allocate(appattempt_1476452954783_0002_000001 [{Priority: 1, Capability: <memory:1920, vCores:1>, # Containers: 4, Location: *, Relax Locality: true}] [] [] []
2016-10-14 07:52:05,655 INFO org.apache.hadoop.yarn.server.resourcemanager.scheduler.fair.FSAppAttempt: root.interactive0 getMinReq:<memory:24576, vCores:12> demand: <memory:10240, vCores:5> usage: <memory:10240, vCores:5>running true active: true isLeafQueue():true
2016-10-14 07:52:05,655 INFO org.apache.hadoop.yarn.server.resourcemanager.scheduler.fair.FSAppAttempt: root.batch0 getMinReq:<memory:0, vCores:0> demand: <memory:10240, vCores:5> usage: <memory:8192, vCores:4>running true active: true isLeafQueue():true
2016-10-14 07:52:05,655 INFO org.apache.hadoop.yarn.server.resourcemanager.scheduler.fair.FSAppAttempt: appattempt_1476452954783_0002_000001 minReqResource: <memory:24576, vCores:12> flexibleResource: <memory:8192, vCores:4>
2016-10-14 07:52:05,655 INFO org.apache.hadoop.yarn.server.resourcemanager.scheduler.fair.FairScheduler: [admission control] getFlexibleResource <memory:8192, vCores:4>
2016-10-14 07:52:05,774 INFO org.apache.hadoop.yarn.server.resourcemanager.scheduler.fair.FSAppAttempt: assignContainer(FSSchedulerNode node:c220g1-030617.wisc.cloudlab.us, boolean reserved=false) for appattempt_1476452954783_0001_000001
2016-10-14 07:52:05,775 INFO org.apache.hadoop.yarn.server.resourcemanager.scheduler.fair.FSAppAttempt: assignContainer(FSSchedulerNode node:c220g1-030617.wisc.cloudlab.us, boolean reserved=false) for appattempt_1476452954783_0002_000001
2016-10-14 07:52:05,775 INFO org.apache.hadoop.yarn.server.resourcemanager.scheduler.fair.FSAppAttempt: Making reservation: node=c220g1-030617.wisc.cloudlab.us app_id=application_1476452954783_0002
2016-10-14 07:52:05,775 INFO org.apache.hadoop.yarn.server.resourcemanager.rmcontainer.RMContainerImpl: Processing container_1476452954783_0002_01_000005 of event RESERVED
2016-10-14 07:52:05,775 INFO org.apache.hadoop.yarn.server.resourcemanager.rmcontainer.RMContainerImpl: container_1476452954783_0002_01_000005 Container Transitioned from NEW to RESERVED
2016-10-14 07:52:05,775 INFO org.apache.hadoop.yarn.server.resourcemanager.scheduler.fair.FSSchedulerNode: Reserved container container_1476452954783_0002_01_000005 on node host: c220g1-030617.wisc.cloudlab.us:46119 #containers=4 available=<memory:0, vCores:0> used=<memory:8192, vCores:4> for application org.apache.hadoop.yarn.server.resourcemanager.scheduler.fair.FSAppAttempt@695330d
2016-10-14 07:52:05,777 INFO org.apache.hadoop.yarn.server.resourcemanager.scheduler.fair.FSAppAttempt: assignContainer(FSSchedulerNode node:cp-2.yarn-perf.yarnrm-PG0.wisc.cloudlab.us, boolean reserved=false) for appattempt_1476452954783_0001_000001
2016-10-14 07:52:05,777 INFO org.apache.hadoop.yarn.server.resourcemanager.scheduler.fair.FSAppAttempt: assignContainer(FSSchedulerNode node:cp-2.yarn-perf.yarnrm-PG0.wisc.cloudlab.us, boolean reserved=false) for appattempt_1476452954783_0002_000001
2016-10-14 07:52:05,777 INFO org.apache.hadoop.yarn.server.resourcemanager.scheduler.fair.FSAppAttempt: Making reservation: node=cp-2.yarn-perf.yarnrm-PG0.wisc.cloudlab.us app_id=application_1476452954783_0002
2016-10-14 07:52:05,778 INFO org.apache.hadoop.yarn.server.resourcemanager.rmcontainer.RMContainerImpl: Processing container_1476452954783_0002_01_000006 of event RESERVED
2016-10-14 07:52:05,778 INFO org.apache.hadoop.yarn.server.resourcemanager.rmcontainer.RMContainerImpl: container_1476452954783_0002_01_000006 Container Transitioned from NEW to RESERVED
2016-10-14 07:52:05,778 INFO org.apache.hadoop.yarn.server.resourcemanager.scheduler.fair.FSSchedulerNode: Reserved container container_1476452954783_0002_01_000006 on node host: cp-2.yarn-perf.yarnrm-PG0.wisc.cloudlab.us:43837 #containers=4 available=<memory:0, vCores:0> used=<memory:8192, vCores:4> for application org.apache.hadoop.yarn.server.resourcemanager.scheduler.fair.FSAppAttempt@695330d
2016-10-14 07:52:05,858 INFO org.apache.hadoop.yarn.server.resourcemanager.scheduler.fair.FairScheduler: allocate(appattempt_1476452954783_0002_000001 [] [] [] []
2016-10-14 07:52:05,859 INFO org.apache.hadoop.yarn.server.resourcemanager.scheduler.fair.FSAppAttempt: root.interactive0 getMinReq:<memory:24576, vCores:12> demand: <memory:10240, vCores:5> usage: <memory:10240, vCores:5>running true active: true isLeafQueue():true
2016-10-14 07:52:05,859 INFO org.apache.hadoop.yarn.server.resourcemanager.scheduler.fair.FSAppAttempt: root.batch0 getMinReq:<memory:0, vCores:0> demand: <memory:10240, vCores:5> usage: <memory:8192, vCores:4>running true active: true isLeafQueue():true
2016-10-14 07:52:05,859 INFO org.apache.hadoop.yarn.server.resourcemanager.scheduler.fair.FSAppAttempt: appattempt_1476452954783_0002_000001 minReqResource: <memory:24576, vCores:12> flexibleResource: <memory:8192, vCores:4>
2016-10-14 07:52:05,859 INFO org.apache.hadoop.yarn.server.resourcemanager.scheduler.fair.FairScheduler: [admission control] getFlexibleResource <memory:8192, vCores:4>
2016-10-14 07:52:05,885 INFO org.apache.hadoop.yarn.server.resourcemanager.scheduler.fair.FSAppAttempt: assignContainer(FSSchedulerNode node:cp-1.yarn-perf.yarnrm-PG0.wisc.cloudlab.us, boolean reserved=false) for appattempt_1476452954783_0001_000001
2016-10-14 07:52:05,885 INFO org.apache.hadoop.yarn.server.resourcemanager.scheduler.fair.FSAppAttempt: assignContainer(FSSchedulerNode node:cp-1.yarn-perf.yarnrm-PG0.wisc.cloudlab.us, boolean reserved=false) for appattempt_1476452954783_0002_000001
2016-10-14 07:52:05,886 INFO org.apache.hadoop.yarn.server.resourcemanager.scheduler.fair.FSAppAttempt: allocate container: container_1476452954783_0002_01_000007 priority 1
2016-10-14 07:52:05,886 INFO org.apache.hadoop.yarn.server.resourcemanager.rmcontainer.RMContainerImpl: Processing container_1476452954783_0002_01_000007 of event START
2016-10-14 07:52:05,886 INFO org.apache.hadoop.yarn.server.resourcemanager.rmcontainer.RMContainerImpl: container_1476452954783_0002_01_000007 Container Transitioned from NEW to ALLOCATED
2016-10-14 07:52:05,886 INFO org.apache.hadoop.yarn.server.resourcemanager.RMAuditLogger: USER=tanle	OPERATION=AM Allocated Container	TARGET=SchedulerApp	RESULT=SUCCESS	APPID=application_1476452954783_0002	CONTAINERID=container_1476452954783_0002_01_000007
2016-10-14 07:52:05,886 INFO org.apache.hadoop.yarn.server.resourcemanager.scheduler.SchedulerNode: Assigned container container_1476452954783_0002_01_000007 of capacity <memory:2048, vCores:1> on host cp-1.yarn-perf.yarnrm-PG0.wisc.cloudlab.us:36424, which has 2 containers, <memory:4096, vCores:2> used and <memory:4096, vCores:2> available after allocation
2016-10-14 07:52:05,942 INFO org.apache.hadoop.yarn.server.resourcemanager.scheduler.fair.FSAppAttempt: assignContainer(FSSchedulerNode node:cp-3.yarn-perf.yarnrm-PG0.wisc.cloudlab.us, boolean reserved=false) for appattempt_1476452954783_0001_000001
2016-10-14 07:52:05,942 INFO org.apache.hadoop.yarn.server.resourcemanager.scheduler.fair.FSAppAttempt: assignContainer(FSSchedulerNode node:cp-3.yarn-perf.yarnrm-PG0.wisc.cloudlab.us, boolean reserved=false) for appattempt_1476452954783_0002_000001
2016-10-14 07:52:05,942 INFO org.apache.hadoop.yarn.server.resourcemanager.scheduler.fair.FSAppAttempt: allocate container: container_1476452954783_0002_01_000008 priority 1
2016-10-14 07:52:05,943 INFO org.apache.hadoop.yarn.server.resourcemanager.rmcontainer.RMContainerImpl: Processing container_1476452954783_0002_01_000008 of event START
2016-10-14 07:52:05,943 INFO org.apache.hadoop.yarn.server.resourcemanager.rmcontainer.RMContainerImpl: container_1476452954783_0002_01_000008 Container Transitioned from NEW to ALLOCATED
2016-10-14 07:52:05,943 INFO org.apache.hadoop.yarn.server.resourcemanager.RMAuditLogger: USER=tanle	OPERATION=AM Allocated Container	TARGET=SchedulerApp	RESULT=SUCCESS	APPID=application_1476452954783_0002	CONTAINERID=container_1476452954783_0002_01_000008
2016-10-14 07:52:05,943 INFO org.apache.hadoop.yarn.server.resourcemanager.scheduler.SchedulerNode: Assigned container container_1476452954783_0002_01_000008 of capacity <memory:2048, vCores:1> on host cp-3.yarn-perf.yarnrm-PG0.wisc.cloudlab.us:44309, which has 1 containers, <memory:2048, vCores:1> used and <memory:6144, vCores:3> available after allocation
2016-10-14 07:52:06,262 INFO org.apache.hadoop.yarn.server.resourcemanager.scheduler.fair.FairScheduler: allocate(appattempt_1476452954783_0002_000001 [] [] [] []
2016-10-14 07:52:06,263 INFO org.apache.hadoop.yarn.server.resourcemanager.scheduler.fair.FSAppAttempt: root.interactive0 getMinReq:<memory:24576, vCores:12> demand: <memory:10240, vCores:5> usage: <memory:10240, vCores:5>running true active: true isLeafQueue():true
2016-10-14 07:52:06,263 INFO org.apache.hadoop.yarn.server.resourcemanager.scheduler.fair.FSAppAttempt: root.batch0 getMinReq:<memory:0, vCores:0> demand: <memory:18432, vCores:9> usage: <memory:12288, vCores:6>running true active: true isLeafQueue():true
2016-10-14 07:52:06,263 INFO org.apache.hadoop.yarn.server.resourcemanager.scheduler.fair.FSAppAttempt: appattempt_1476452954783_0002_000001 minReqResource: <memory:24576, vCores:12> flexibleResource: <memory:8192, vCores:4>
2016-10-14 07:52:06,263 INFO org.apache.hadoop.yarn.server.resourcemanager.scheduler.fair.FairScheduler: [admission control] getFlexibleResource <memory:8192, vCores:4>
2016-10-14 07:52:06,265 INFO org.apache.hadoop.yarn.server.resourcemanager.security.NMTokenSecretManagerInRM: Sending NMToken for nodeId : cp-1.yarn-perf.yarnrm-PG0.wisc.cloudlab.us:36424 for container : container_1476452954783_0002_01_000007
2016-10-14 07:52:06,266 INFO org.apache.hadoop.yarn.server.resourcemanager.rmcontainer.RMContainerImpl: Processing container_1476452954783_0002_01_000007 of event ACQUIRED
2016-10-14 07:52:06,266 INFO org.apache.hadoop.yarn.server.resourcemanager.rmcontainer.RMContainerImpl: container_1476452954783_0002_01_000007 Container Transitioned from ALLOCATED to ACQUIRED
2016-10-14 07:52:06,268 INFO org.apache.hadoop.yarn.server.resourcemanager.security.NMTokenSecretManagerInRM: Sending NMToken for nodeId : cp-3.yarn-perf.yarnrm-PG0.wisc.cloudlab.us:44309 for container : container_1476452954783_0002_01_000008
2016-10-14 07:52:06,269 INFO org.apache.hadoop.yarn.server.resourcemanager.rmcontainer.RMContainerImpl: Processing container_1476452954783_0002_01_000008 of event ACQUIRED
2016-10-14 07:52:06,269 INFO org.apache.hadoop.yarn.server.resourcemanager.rmcontainer.RMContainerImpl: container_1476452954783_0002_01_000008 Container Transitioned from ALLOCATED to ACQUIRED
2016-10-14 07:52:06,646 INFO org.apache.hadoop.yarn.server.resourcemanager.scheduler.fair.FairScheduler: allocate(appattempt_1476452954783_0001_000001 [{Priority: 1, Capability: <memory:1920, vCores:1>, # Containers: 4, Location: *, Relax Locality: true}] [container_1476452954783_0001_01_000006] [] []
2016-10-14 07:52:06,646 INFO org.apache.hadoop.yarn.server.resourcemanager.scheduler.fair.FSAppAttempt: root.interactive0 getMinReq:<memory:24576, vCores:12> demand: <memory:10240, vCores:5> usage: <memory:10240, vCores:5>running true active: true isLeafQueue():true
2016-10-14 07:52:06,647 INFO org.apache.hadoop.yarn.server.resourcemanager.scheduler.fair.FSAppAttempt: root.batch0 getMinReq:<memory:0, vCores:0> demand: <memory:18432, vCores:9> usage: <memory:12288, vCores:6>running true active: true isLeafQueue():true
2016-10-14 07:52:06,647 INFO org.apache.hadoop.yarn.server.resourcemanager.scheduler.fair.FSAppAttempt: appattempt_1476452954783_0001_000001 minReqResource: <memory:24576, vCores:12> flexibleResource: <memory:8192, vCores:4>
2016-10-14 07:52:06,647 INFO org.apache.hadoop.yarn.server.resourcemanager.scheduler.fair.FairScheduler: [admission control] getFlexibleResource <memory:8192, vCores:4>
2016-10-14 07:52:06,647 INFO org.apache.hadoop.yarn.server.resourcemanager.scheduler.fair.FairScheduler: app appattempt_1476452954783_0001_000001 in queue root.interactive0 isRunning: true
2016-10-14 07:52:06,652 INFO org.apache.hadoop.yarn.server.resourcemanager.rmcontainer.RMContainerImpl: Processing container_1476452954783_0001_01_000006 of event RELEASED
2016-10-14 07:52:06,653 INFO org.apache.hadoop.yarn.server.resourcemanager.rmcontainer.RMContainerImpl: container_1476452954783_0001_01_000006 Container Transitioned from ACQUIRED to RELEASED
2016-10-14 07:52:06,654 INFO org.apache.hadoop.yarn.server.resourcemanager.scheduler.fair.FSAppAttempt: Completed container: container_1476452954783_0001_01_000006 in state: RELEASED event:RELEASED
2016-10-14 07:52:06,654 INFO org.apache.hadoop.yarn.server.resourcemanager.RMAuditLogger: USER=tanle	IP=128.104.222.60	OPERATION=AM Released Container	TARGET=SchedulerApp	RESULT=SUCCESS	APPID=application_1476452954783_0001	CONTAINERID=container_1476452954783_0001_01_000006
2016-10-14 07:52:06,655 INFO org.apache.hadoop.yarn.server.resourcemanager.scheduler.SchedulerNode: Released container container_1476452954783_0001_01_000006 of capacity <memory:2048, vCores:1> on host cp-2.yarn-perf.yarnrm-PG0.wisc.cloudlab.us:43837, which currently has 3 containers, <memory:6144, vCores:3> used and <memory:2048, vCores:1> available, release resources=true
2016-10-14 07:52:06,655 INFO org.apache.hadoop.yarn.server.resourcemanager.scheduler.fair.FairScheduler: Application attempt appattempt_1476452954783_0001_000001 released container container_1476452954783_0001_01_000006 on node: host: cp-2.yarn-perf.yarnrm-PG0.wisc.cloudlab.us:43837 #containers=3 available=<memory:2048, vCores:1> used=<memory:6144, vCores:3> with event: RELEASED
2016-10-14 07:52:06,779 INFO org.apache.hadoop.yarn.server.resourcemanager.scheduler.fair.FSAppAttempt: assignContainer(FSSchedulerNode node:cp-2.yarn-perf.yarnrm-PG0.wisc.cloudlab.us, boolean reserved=true) for appattempt_1476452954783_0002_000001
2016-10-14 07:52:06,779 INFO org.apache.hadoop.yarn.server.resourcemanager.scheduler.fair.FSAppAttempt: allocate container: container_1476452954783_0002_01_000006 priority 1
2016-10-14 07:52:06,780 INFO org.apache.hadoop.yarn.server.resourcemanager.rmcontainer.RMContainerImpl: Processing container_1476452954783_0002_01_000006 of event START
2016-10-14 07:52:06,780 INFO org.apache.hadoop.yarn.server.resourcemanager.rmcontainer.RMContainerImpl: container_1476452954783_0002_01_000006 Container Transitioned from NEW to ALLOCATED
2016-10-14 07:52:06,780 INFO org.apache.hadoop.yarn.server.resourcemanager.RMAuditLogger: USER=tanle	OPERATION=AM Allocated Container	TARGET=SchedulerApp	RESULT=SUCCESS	APPID=application_1476452954783_0002	CONTAINERID=container_1476452954783_0002_01_000006
2016-10-14 07:52:06,780 INFO org.apache.hadoop.yarn.server.resourcemanager.scheduler.fair.FSAppAttempt: Application application_1476452954783_0002 unreserved  on node host: cp-2.yarn-perf.yarnrm-PG0.wisc.cloudlab.us:43837 #containers=3 available=<memory:2048, vCores:1> used=<memory:6144, vCores:3>, currently has 1 at priority 1; currentReservation <memory:2048, vCores:1>
2016-10-14 07:52:06,780 INFO org.apache.hadoop.yarn.server.resourcemanager.scheduler.SchedulerNode: Assigned container container_1476452954783_0002_01_000006 of capacity <memory:2048, vCores:1> on host cp-2.yarn-perf.yarnrm-PG0.wisc.cloudlab.us:43837, which has 4 containers, <memory:8192, vCores:4> used and <memory:0, vCores:0> available after allocation
2016-10-14 07:52:06,887 INFO org.apache.hadoop.yarn.server.resourcemanager.scheduler.fair.FairScheduler: allocate(appattempt_1476452954783_0001_000001 [] [] [] []
2016-10-14 07:52:06,887 INFO org.apache.hadoop.yarn.server.resourcemanager.scheduler.fair.FSAppAttempt: root.interactive0 getMinReq:<memory:24576, vCores:12> demand: <memory:10240, vCores:5> usage: <memory:8192, vCores:4>running true active: true isLeafQueue():true
2016-10-14 07:52:06,887 INFO org.apache.hadoop.yarn.server.resourcemanager.scheduler.fair.FSAppAttempt: root.batch0 getMinReq:<memory:0, vCores:0> demand: <memory:18432, vCores:9> usage: <memory:14336, vCores:7>running true active: true isLeafQueue():true
2016-10-14 07:52:06,887 INFO org.apache.hadoop.yarn.server.resourcemanager.scheduler.fair.FSAppAttempt: appattempt_1476452954783_0001_000001 minReqResource: <memory:24576, vCores:12> flexibleResource: <memory:8192, vCores:4>
2016-10-14 07:52:06,887 INFO org.apache.hadoop.yarn.server.resourcemanager.scheduler.fair.FairScheduler: [admission control] getFlexibleResource <memory:8192, vCores:4>
2016-10-14 07:52:06,887 INFO org.apache.hadoop.yarn.server.resourcemanager.scheduler.fair.FairScheduler: app appattempt_1476452954783_0001_000001 in queue root.interactive0 isRunning: true
2016-10-14 07:52:06,888 INFO org.apache.hadoop.yarn.server.resourcemanager.rmcontainer.RMContainerImpl: Processing container_1476452954783_0002_01_000007 of event LAUNCHED
2016-10-14 07:52:06,888 INFO org.apache.hadoop.yarn.server.resourcemanager.rmcontainer.RMContainerImpl: container_1476452954783_0002_01_000007 Container Transitioned from ACQUIRED to RUNNING
2016-10-14 07:52:06,889 INFO org.apache.hadoop.yarn.server.resourcemanager.scheduler.fair.FSAppAttempt: assignContainer(FSSchedulerNode node:cp-1.yarn-perf.yarnrm-PG0.wisc.cloudlab.us, boolean reserved=false) for appattempt_1476452954783_0001_000001
2016-10-14 07:52:06,889 INFO org.apache.hadoop.yarn.server.resourcemanager.scheduler.fair.FSAppAttempt: allocate container: container_1476452954783_0001_01_000007 priority 1
2016-10-14 07:52:06,890 INFO org.apache.hadoop.yarn.server.resourcemanager.rmcontainer.RMContainerImpl: Processing container_1476452954783_0001_01_000007 of event START
2016-10-14 07:52:06,890 INFO org.apache.hadoop.yarn.server.resourcemanager.rmcontainer.RMContainerImpl: container_1476452954783_0001_01_000007 Container Transitioned from NEW to ALLOCATED
2016-10-14 07:52:06,891 INFO org.apache.hadoop.yarn.server.resourcemanager.RMAuditLogger: USER=tanle	OPERATION=AM Allocated Container	TARGET=SchedulerApp	RESULT=SUCCESS	APPID=application_1476452954783_0001	CONTAINERID=container_1476452954783_0001_01_000007
2016-10-14 07:52:06,891 INFO org.apache.hadoop.yarn.server.resourcemanager.scheduler.SchedulerNode: Assigned container container_1476452954783_0001_01_000007 of capacity <memory:2048, vCores:1> on host cp-1.yarn-perf.yarnrm-PG0.wisc.cloudlab.us:36424, which has 3 containers, <memory:6144, vCores:3> used and <memory:2048, vCores:1> available after allocation
2016-10-14 07:52:06,954 INFO org.apache.hadoop.yarn.server.resourcemanager.rmcontainer.RMContainerImpl: Processing container_1476452954783_0002_01_000008 of event LAUNCHED
2016-10-14 07:52:06,954 INFO org.apache.hadoop.yarn.server.resourcemanager.rmcontainer.RMContainerImpl: container_1476452954783_0002_01_000008 Container Transitioned from ACQUIRED to RUNNING
2016-10-14 07:52:06,955 INFO org.apache.hadoop.yarn.server.resourcemanager.scheduler.fair.FSAppAttempt: assignContainer(FSSchedulerNode node:cp-3.yarn-perf.yarnrm-PG0.wisc.cloudlab.us, boolean reserved=false) for appattempt_1476452954783_0001_000001
2016-10-14 07:52:06,956 INFO org.apache.hadoop.yarn.server.resourcemanager.scheduler.fair.FSAppAttempt: allocate container: container_1476452954783_0001_01_000008 priority 1
2016-10-14 07:52:06,956 INFO org.apache.hadoop.yarn.server.resourcemanager.rmcontainer.RMContainerImpl: Processing container_1476452954783_0001_01_000008 of event START
2016-10-14 07:52:06,957 INFO org.apache.hadoop.yarn.server.resourcemanager.rmcontainer.RMContainerImpl: container_1476452954783_0001_01_000008 Container Transitioned from NEW to ALLOCATED
2016-10-14 07:52:06,957 INFO org.apache.hadoop.yarn.server.resourcemanager.RMAuditLogger: USER=tanle	OPERATION=AM Allocated Container	TARGET=SchedulerApp	RESULT=SUCCESS	APPID=application_1476452954783_0001	CONTAINERID=container_1476452954783_0001_01_000008
2016-10-14 07:52:06,957 INFO org.apache.hadoop.yarn.server.resourcemanager.scheduler.SchedulerNode: Assigned container container_1476452954783_0001_01_000008 of capacity <memory:2048, vCores:1> on host cp-3.yarn-perf.yarnrm-PG0.wisc.cloudlab.us:44309, which has 2 containers, <memory:4096, vCores:2> used and <memory:4096, vCores:2> available after allocation
2016-10-14 07:52:07,080 INFO org.apache.hadoop.yarn.server.resourcemanager.scheduler.fair.FairScheduler: allocate(appattempt_1476452954783_0002_000001 [{Priority: 1, Capability: <memory:1920, vCores:1>, # Containers: 2, Location: *, Relax Locality: true}] [] [] []
2016-10-14 07:52:07,081 INFO org.apache.hadoop.yarn.server.resourcemanager.scheduler.fair.FSAppAttempt: root.interactive0 getMinReq:<memory:24576, vCores:12> demand: <memory:16384, vCores:8> usage: <memory:12288, vCores:6>running true active: true isLeafQueue():true
2016-10-14 07:52:07,081 INFO org.apache.hadoop.yarn.server.resourcemanager.scheduler.fair.FSAppAttempt: root.batch0 getMinReq:<memory:0, vCores:0> demand: <memory:18432, vCores:9> usage: <memory:14336, vCores:7>running true active: true isLeafQueue():true
2016-10-14 07:52:07,081 INFO org.apache.hadoop.yarn.server.resourcemanager.scheduler.fair.FSAppAttempt: appattempt_1476452954783_0002_000001 minReqResource: <memory:24576, vCores:12> flexibleResource: <memory:8192, vCores:4>
2016-10-14 07:52:07,081 INFO org.apache.hadoop.yarn.server.resourcemanager.scheduler.fair.FairScheduler: [admission control] getFlexibleResource <memory:8192, vCores:4>
2016-10-14 07:52:07,083 INFO org.apache.hadoop.yarn.server.resourcemanager.rmcontainer.RMContainerImpl: Processing container_1476452954783_0002_01_000006 of event ACQUIRED
2016-10-14 07:52:07,083 INFO org.apache.hadoop.yarn.server.resourcemanager.rmcontainer.RMContainerImpl: container_1476452954783_0002_01_000006 Container Transitioned from ALLOCATED to ACQUIRED
2016-10-14 07:52:07,292 INFO org.apache.hadoop.yarn.server.resourcemanager.scheduler.fair.FairScheduler: allocate(appattempt_1476452954783_0001_000001 [] [] [] []
2016-10-14 07:52:07,292 INFO org.apache.hadoop.yarn.server.resourcemanager.scheduler.fair.FSAppAttempt: root.interactive0 getMinReq:<memory:24576, vCores:12> demand: <memory:16384, vCores:8> usage: <memory:12288, vCores:6>running true active: true isLeafQueue():true
2016-10-14 07:52:07,292 INFO org.apache.hadoop.yarn.server.resourcemanager.scheduler.fair.FSAppAttempt: root.batch0 getMinReq:<memory:0, vCores:0> demand: <memory:18432, vCores:9> usage: <memory:14336, vCores:7>running true active: true isLeafQueue():true
2016-10-14 07:52:07,292 INFO org.apache.hadoop.yarn.server.resourcemanager.scheduler.fair.FSAppAttempt: appattempt_1476452954783_0001_000001 minReqResource: <memory:24576, vCores:12> flexibleResource: <memory:8192, vCores:4>
2016-10-14 07:52:07,293 INFO org.apache.hadoop.yarn.server.resourcemanager.scheduler.fair.FairScheduler: [admission control] getFlexibleResource <memory:8192, vCores:4>
2016-10-14 07:52:07,293 INFO org.apache.hadoop.yarn.server.resourcemanager.scheduler.fair.FairScheduler: app appattempt_1476452954783_0001_000001 in queue root.interactive0 isRunning: true
2016-10-14 07:52:07,295 INFO org.apache.hadoop.yarn.server.resourcemanager.rmcontainer.RMContainerImpl: Processing container_1476452954783_0001_01_000007 of event ACQUIRED
2016-10-14 07:52:07,295 INFO org.apache.hadoop.yarn.server.resourcemanager.rmcontainer.RMContainerImpl: container_1476452954783_0001_01_000007 Container Transitioned from ALLOCATED to ACQUIRED
2016-10-14 07:52:07,297 INFO org.apache.hadoop.yarn.server.resourcemanager.security.NMTokenSecretManagerInRM: Sending NMToken for nodeId : cp-3.yarn-perf.yarnrm-PG0.wisc.cloudlab.us:44309 for container : container_1476452954783_0001_01_000008
2016-10-14 07:52:07,298 INFO org.apache.hadoop.yarn.server.resourcemanager.rmcontainer.RMContainerImpl: Processing container_1476452954783_0001_01_000008 of event ACQUIRED
2016-10-14 07:52:07,300 INFO org.apache.hadoop.yarn.server.resourcemanager.rmcontainer.RMContainerImpl: container_1476452954783_0001_01_000008 Container Transitioned from ALLOCATED to ACQUIRED
2016-10-14 07:52:07,784 INFO org.apache.hadoop.yarn.server.resourcemanager.rmcontainer.RMContainerImpl: Processing container_1476452954783_0002_01_000006 of event LAUNCHED
2016-10-14 07:52:07,784 INFO org.apache.hadoop.yarn.server.resourcemanager.rmcontainer.RMContainerImpl: container_1476452954783_0002_01_000006 Container Transitioned from ACQUIRED to RUNNING
2016-10-14 07:52:07,785 INFO org.apache.hadoop.yarn.server.resourcemanager.scheduler.fair.FSAppAttempt: assignContainer(FSSchedulerNode node:cp-2.yarn-perf.yarnrm-PG0.wisc.cloudlab.us, boolean reserved=false) for appattempt_1476452954783_0001_000001
2016-10-14 07:52:07,786 INFO org.apache.hadoop.yarn.server.resourcemanager.scheduler.fair.FSAppAttempt: Making reservation: node=cp-2.yarn-perf.yarnrm-PG0.wisc.cloudlab.us app_id=application_1476452954783_0001
2016-10-14 07:52:07,786 INFO org.apache.hadoop.yarn.server.resourcemanager.rmcontainer.RMContainerImpl: Processing container_1476452954783_0001_01_000009 of event RESERVED
2016-10-14 07:52:07,786 INFO org.apache.hadoop.yarn.server.resourcemanager.rmcontainer.RMContainerImpl: container_1476452954783_0001_01_000009 Container Transitioned from NEW to RESERVED
2016-10-14 07:52:07,786 INFO org.apache.hadoop.yarn.server.resourcemanager.scheduler.fair.FSSchedulerNode: Reserved container container_1476452954783_0001_01_000009 on node host: cp-2.yarn-perf.yarnrm-PG0.wisc.cloudlab.us:43837 #containers=4 available=<memory:0, vCores:0> used=<memory:8192, vCores:4> for application org.apache.hadoop.yarn.server.resourcemanager.scheduler.fair.FSAppAttempt@13f22e88
2016-10-14 07:52:07,891 INFO org.apache.hadoop.yarn.server.resourcemanager.rmcontainer.RMContainerImpl: Processing container_1476452954783_0001_01_000007 of event LAUNCHED
2016-10-14 07:52:07,891 INFO org.apache.hadoop.yarn.server.resourcemanager.rmcontainer.RMContainerImpl: container_1476452954783_0001_01_000007 Container Transitioned from ACQUIRED to RUNNING
2016-10-14 07:52:07,892 INFO org.apache.hadoop.yarn.server.resourcemanager.scheduler.fair.FSAppAttempt: assignContainer(FSSchedulerNode node:cp-1.yarn-perf.yarnrm-PG0.wisc.cloudlab.us, boolean reserved=false) for appattempt_1476452954783_0001_000001
2016-10-14 07:52:07,893 INFO org.apache.hadoop.yarn.server.resourcemanager.scheduler.fair.FSAppAttempt: allocate container: container_1476452954783_0001_01_000010 priority 1
2016-10-14 07:52:07,893 INFO org.apache.hadoop.yarn.server.resourcemanager.rmcontainer.RMContainerImpl: Processing container_1476452954783_0001_01_000010 of event START
2016-10-14 07:52:07,893 INFO org.apache.hadoop.yarn.server.resourcemanager.rmcontainer.RMContainerImpl: container_1476452954783_0001_01_000010 Container Transitioned from NEW to ALLOCATED
2016-10-14 07:52:07,893 INFO org.apache.hadoop.yarn.server.resourcemanager.RMAuditLogger: USER=tanle	OPERATION=AM Allocated Container	TARGET=SchedulerApp	RESULT=SUCCESS	APPID=application_1476452954783_0001	CONTAINERID=container_1476452954783_0001_01_000010
2016-10-14 07:52:07,893 INFO org.apache.hadoop.yarn.server.resourcemanager.scheduler.SchedulerNode: Assigned container container_1476452954783_0001_01_000010 of capacity <memory:2048, vCores:1> on host cp-1.yarn-perf.yarnrm-PG0.wisc.cloudlab.us:36424, which has 4 containers, <memory:8192, vCores:4> used and <memory:0, vCores:0> available after allocation
2016-10-14 07:52:07,958 INFO org.apache.hadoop.yarn.server.resourcemanager.rmcontainer.RMContainerImpl: Processing container_1476452954783_0001_01_000008 of event LAUNCHED
2016-10-14 07:52:07,958 INFO org.apache.hadoop.yarn.server.resourcemanager.rmcontainer.RMContainerImpl: container_1476452954783_0001_01_000008 Container Transitioned from ACQUIRED to RUNNING
2016-10-14 07:52:07,959 INFO org.apache.hadoop.yarn.server.resourcemanager.scheduler.fair.FSAppAttempt: assignContainer(FSSchedulerNode node:cp-3.yarn-perf.yarnrm-PG0.wisc.cloudlab.us, boolean reserved=false) for appattempt_1476452954783_0001_000001
2016-10-14 07:52:07,959 INFO org.apache.hadoop.yarn.server.resourcemanager.scheduler.fair.FSAppAttempt: allocate container: container_1476452954783_0001_01_000011 priority 1
2016-10-14 07:52:07,959 INFO org.apache.hadoop.yarn.server.resourcemanager.rmcontainer.RMContainerImpl: Processing container_1476452954783_0001_01_000011 of event START
2016-10-14 07:52:07,960 INFO org.apache.hadoop.yarn.server.resourcemanager.rmcontainer.RMContainerImpl: container_1476452954783_0001_01_000011 Container Transitioned from NEW to ALLOCATED
2016-10-14 07:52:07,960 INFO org.apache.hadoop.yarn.server.resourcemanager.RMAuditLogger: USER=tanle	OPERATION=AM Allocated Container	TARGET=SchedulerApp	RESULT=SUCCESS	APPID=application_1476452954783_0001	CONTAINERID=container_1476452954783_0001_01_000011
2016-10-14 07:52:07,960 INFO org.apache.hadoop.yarn.server.resourcemanager.scheduler.SchedulerNode: Assigned container container_1476452954783_0001_01_000011 of capacity <memory:2048, vCores:1> on host cp-3.yarn-perf.yarnrm-PG0.wisc.cloudlab.us:44309, which has 3 containers, <memory:6144, vCores:3> used and <memory:2048, vCores:1> available after allocation
2016-10-14 07:52:08,114 INFO org.apache.hadoop.yarn.server.resourcemanager.scheduler.fair.FairScheduler: allocate(appattempt_1476452954783_0001_000001 [{Priority: 1, Capability: <memory:1920, vCores:1>, # Containers: 2, Location: *, Relax Locality: true}] [] [] []
2016-10-14 07:52:08,115 INFO org.apache.hadoop.yarn.server.resourcemanager.scheduler.fair.FSAppAttempt: root.interactive0 getMinReq:<memory:24576, vCores:12> demand: <memory:16384, vCores:8> usage: <memory:16384, vCores:8>running true active: true isLeafQueue():true
2016-10-14 07:52:08,115 INFO org.apache.hadoop.yarn.server.resourcemanager.scheduler.fair.FSAppAttempt: root.batch0 getMinReq:<memory:0, vCores:0> demand: <memory:20480, vCores:10> usage: <memory:14336, vCores:7>running true active: true isLeafQueue():true
2016-10-14 07:52:08,115 INFO org.apache.hadoop.yarn.server.resourcemanager.scheduler.fair.FSAppAttempt: appattempt_1476452954783_0001_000001 minReqResource: <memory:24576, vCores:12> flexibleResource: <memory:8192, vCores:4>
2016-10-14 07:52:08,115 INFO org.apache.hadoop.yarn.server.resourcemanager.scheduler.fair.FairScheduler: [admission control] getFlexibleResource <memory:8192, vCores:4>
2016-10-14 07:52:08,115 INFO org.apache.hadoop.yarn.server.resourcemanager.scheduler.fair.FairScheduler: app appattempt_1476452954783_0001_000001 in queue root.interactive0 isRunning: true
2016-10-14 07:52:08,117 INFO org.apache.hadoop.yarn.server.resourcemanager.rmcontainer.RMContainerImpl: Processing container_1476452954783_0001_01_000010 of event ACQUIRED
2016-10-14 07:52:08,117 INFO org.apache.hadoop.yarn.server.resourcemanager.rmcontainer.RMContainerImpl: container_1476452954783_0001_01_000010 Container Transitioned from ALLOCATED to ACQUIRED
2016-10-14 07:52:08,119 INFO org.apache.hadoop.yarn.server.resourcemanager.rmcontainer.RMContainerImpl: Processing container_1476452954783_0001_01_000011 of event ACQUIRED
2016-10-14 07:52:08,119 INFO org.apache.hadoop.yarn.server.resourcemanager.rmcontainer.RMContainerImpl: container_1476452954783_0001_01_000011 Container Transitioned from ALLOCATED to ACQUIRED
2016-10-14 07:52:08,690 INFO org.apache.hadoop.yarn.server.resourcemanager.scheduler.fair.FairScheduler: allocate(appattempt_1476452954783_0002_000001 [{Priority: 1, Capability: <memory:1920, vCores:1>, # Containers: 1, Location: *, Relax Locality: true}] [] [] []
2016-10-14 07:52:08,690 INFO org.apache.hadoop.yarn.server.resourcemanager.scheduler.fair.FSAppAttempt: root.interactive0 getMinReq:<memory:24576, vCores:12> demand: <memory:20480, vCores:10> usage: <memory:16384, vCores:8>running true active: true isLeafQueue():true
2016-10-14 07:52:08,690 INFO org.apache.hadoop.yarn.server.resourcemanager.scheduler.fair.FSAppAttempt: root.batch0 getMinReq:<memory:0, vCores:0> demand: <memory:20480, vCores:10> usage: <memory:14336, vCores:7>running true active: true isLeafQueue():true
2016-10-14 07:52:08,690 INFO org.apache.hadoop.yarn.server.resourcemanager.scheduler.fair.FSAppAttempt: appattempt_1476452954783_0002_000001 minReqResource: <memory:24576, vCores:12> flexibleResource: <memory:8192, vCores:4>
2016-10-14 07:52:08,690 INFO org.apache.hadoop.yarn.server.resourcemanager.scheduler.fair.FairScheduler: [admission control] getFlexibleResource <memory:8192, vCores:4>
2016-10-14 07:52:08,894 INFO org.apache.hadoop.yarn.server.resourcemanager.rmcontainer.RMContainerImpl: Processing container_1476452954783_0001_01_000010 of event LAUNCHED
2016-10-14 07:52:08,894 INFO org.apache.hadoop.yarn.server.resourcemanager.rmcontainer.RMContainerImpl: container_1476452954783_0001_01_000010 Container Transitioned from ACQUIRED to RUNNING
2016-10-14 07:52:08,895 INFO org.apache.hadoop.yarn.server.resourcemanager.scheduler.fair.FSAppAttempt: assignContainer(FSSchedulerNode node:cp-1.yarn-perf.yarnrm-PG0.wisc.cloudlab.us, boolean reserved=false) for appattempt_1476452954783_0001_000001
2016-10-14 07:52:08,895 INFO org.apache.hadoop.yarn.server.resourcemanager.scheduler.fair.FSAppAttempt: Making reservation: node=cp-1.yarn-perf.yarnrm-PG0.wisc.cloudlab.us app_id=application_1476452954783_0001
2016-10-14 07:52:08,896 INFO org.apache.hadoop.yarn.server.resourcemanager.rmcontainer.RMContainerImpl: Processing container_1476452954783_0001_01_000012 of event RESERVED
2016-10-14 07:52:08,896 INFO org.apache.hadoop.yarn.server.resourcemanager.rmcontainer.RMContainerImpl: container_1476452954783_0001_01_000012 Container Transitioned from NEW to RESERVED
2016-10-14 07:52:08,896 INFO org.apache.hadoop.yarn.server.resourcemanager.scheduler.fair.FSSchedulerNode: Reserved container container_1476452954783_0001_01_000012 on node host: cp-1.yarn-perf.yarnrm-PG0.wisc.cloudlab.us:36424 #containers=4 available=<memory:0, vCores:0> used=<memory:8192, vCores:4> for application org.apache.hadoop.yarn.server.resourcemanager.scheduler.fair.FSAppAttempt@13f22e88
2016-10-14 07:52:08,961 INFO org.apache.hadoop.yarn.server.resourcemanager.rmcontainer.RMContainerImpl: Processing container_1476452954783_0001_01_000011 of event LAUNCHED
2016-10-14 07:52:08,961 INFO org.apache.hadoop.yarn.server.resourcemanager.rmcontainer.RMContainerImpl: container_1476452954783_0001_01_000011 Container Transitioned from ACQUIRED to RUNNING
2016-10-14 07:52:08,962 INFO org.apache.hadoop.yarn.server.resourcemanager.scheduler.fair.FSAppAttempt: assignContainer(FSSchedulerNode node:cp-3.yarn-perf.yarnrm-PG0.wisc.cloudlab.us, boolean reserved=false) for appattempt_1476452954783_0001_000001
2016-10-14 07:52:08,962 INFO org.apache.hadoop.yarn.server.resourcemanager.scheduler.fair.FSAppAttempt: allocate container: container_1476452954783_0001_01_000013 priority 1
2016-10-14 07:52:08,962 INFO org.apache.hadoop.yarn.server.resourcemanager.rmcontainer.RMContainerImpl: Processing container_1476452954783_0001_01_000013 of event START
2016-10-14 07:52:08,962 INFO org.apache.hadoop.yarn.server.resourcemanager.rmcontainer.RMContainerImpl: container_1476452954783_0001_01_000013 Container Transitioned from NEW to ALLOCATED
2016-10-14 07:52:08,963 INFO org.apache.hadoop.yarn.server.resourcemanager.RMAuditLogger: USER=tanle	OPERATION=AM Allocated Container	TARGET=SchedulerApp	RESULT=SUCCESS	APPID=application_1476452954783_0001	CONTAINERID=container_1476452954783_0001_01_000013
2016-10-14 07:52:08,963 INFO org.apache.hadoop.yarn.server.resourcemanager.scheduler.SchedulerNode: Assigned container container_1476452954783_0001_01_000013 of capacity <memory:2048, vCores:1> on host cp-3.yarn-perf.yarnrm-PG0.wisc.cloudlab.us:44309, which has 4 containers, <memory:8192, vCores:4> used and <memory:0, vCores:0> available after allocation
2016-10-14 07:52:09,965 INFO org.apache.hadoop.yarn.server.resourcemanager.scheduler.fair.FSAppAttempt: assignContainer(FSSchedulerNode node:cp-3.yarn-perf.yarnrm-PG0.wisc.cloudlab.us, boolean reserved=false) for appattempt_1476452954783_0001_000001
2016-10-14 07:52:09,965 INFO org.apache.hadoop.yarn.server.resourcemanager.scheduler.fair.FSAppAttempt: Making reservation: node=cp-3.yarn-perf.yarnrm-PG0.wisc.cloudlab.us app_id=application_1476452954783_0001
2016-10-14 07:52:09,966 INFO org.apache.hadoop.yarn.server.resourcemanager.rmcontainer.RMContainerImpl: Processing container_1476452954783_0001_01_000014 of event RESERVED
2016-10-14 07:52:09,966 INFO org.apache.hadoop.yarn.server.resourcemanager.rmcontainer.RMContainerImpl: container_1476452954783_0001_01_000014 Container Transitioned from NEW to RESERVED
2016-10-14 07:52:09,966 INFO org.apache.hadoop.yarn.server.resourcemanager.scheduler.fair.FSSchedulerNode: Reserved container container_1476452954783_0001_01_000014 on node host: cp-3.yarn-perf.yarnrm-PG0.wisc.cloudlab.us:44309 #containers=4 available=<memory:0, vCores:0> used=<memory:8192, vCores:4> for application org.apache.hadoop.yarn.server.resourcemanager.scheduler.fair.FSAppAttempt@13f22e88
2016-10-14 07:52:10,653 INFO org.apache.hadoop.yarn.server.resourcemanager.scheduler.fair.FairScheduler: allocate(appattempt_1476452954783_0002_000001 [{Priority: 1, Capability: <memory:1920, vCores:1>, # Containers: 9, Location: *, Relax Locality: true}] [] [] []
2016-10-14 07:52:10,653 INFO org.apache.hadoop.yarn.server.resourcemanager.scheduler.fair.FSAppAttempt: root.interactive0 getMinReq:<memory:24576, vCores:12> demand: <memory:20480, vCores:10> usage: <memory:18432, vCores:9>running true active: true isLeafQueue():true
2016-10-14 07:52:10,653 INFO org.apache.hadoop.yarn.server.resourcemanager.scheduler.fair.FSAppAttempt: root.batch0 getMinReq:<memory:0, vCores:0> demand: <memory:18432, vCores:9> usage: <memory:14336, vCores:7>running true active: true isLeafQueue():true
2016-10-14 07:52:10,653 INFO org.apache.hadoop.yarn.server.resourcemanager.scheduler.fair.FSAppAttempt: appattempt_1476452954783_0002_000001 minReqResource: <memory:24576, vCores:12> flexibleResource: <memory:8192, vCores:4>
2016-10-14 07:52:10,653 INFO org.apache.hadoop.yarn.server.resourcemanager.scheduler.fair.FairScheduler: [admission control] getFlexibleResource <memory:8192, vCores:4>
2016-10-14 07:52:10,858 INFO org.apache.hadoop.yarn.server.resourcemanager.scheduler.fair.FairScheduler: allocate(appattempt_1476452954783_0002_000001 [] [] [] []
2016-10-14 07:52:10,858 INFO org.apache.hadoop.yarn.server.resourcemanager.scheduler.fair.FSAppAttempt: root.interactive0 getMinReq:<memory:24576, vCores:12> demand: <memory:20480, vCores:10> usage: <memory:18432, vCores:9>running true active: true isLeafQueue():true
2016-10-14 07:52:10,858 INFO org.apache.hadoop.yarn.server.resourcemanager.scheduler.fair.FSAppAttempt: root.batch0 getMinReq:<memory:0, vCores:0> demand: <memory:18432, vCores:9> usage: <memory:14336, vCores:7>running true active: true isLeafQueue():true
2016-10-14 07:52:10,858 INFO org.apache.hadoop.yarn.server.resourcemanager.scheduler.fair.FSAppAttempt: appattempt_1476452954783_0002_000001 minReqResource: <memory:24576, vCores:12> flexibleResource: <memory:8192, vCores:4>
2016-10-14 07:52:10,859 INFO org.apache.hadoop.yarn.server.resourcemanager.scheduler.fair.FairScheduler: [admission control] getFlexibleResource <memory:8192, vCores:4>
2016-10-14 07:52:11,125 INFO org.apache.hadoop.yarn.server.resourcemanager.scheduler.fair.FairScheduler: allocate(appattempt_1476452954783_0001_000001 [{Priority: 1, Capability: <memory:1920, vCores:1>, # Containers: 0, Location: *, Relax Locality: true}] [] [] []
2016-10-14 07:52:11,126 INFO org.apache.hadoop.yarn.server.resourcemanager.scheduler.fair.FSAppAttempt: root.interactive0 getMinReq:<memory:24576, vCores:12> demand: <memory:20480, vCores:10> usage: <memory:18432, vCores:9>running true active: true isLeafQueue():true
2016-10-14 07:52:11,126 INFO org.apache.hadoop.yarn.server.resourcemanager.scheduler.fair.FSAppAttempt: root.batch0 getMinReq:<memory:0, vCores:0> demand: <memory:34816, vCores:17> usage: <memory:14336, vCores:7>running true active: true isLeafQueue():true
2016-10-14 07:52:11,126 INFO org.apache.hadoop.yarn.server.resourcemanager.scheduler.fair.FSAppAttempt: appattempt_1476452954783_0001_000001 minReqResource: <memory:24576, vCores:12> flexibleResource: <memory:8192, vCores:4>
2016-10-14 07:52:11,126 INFO org.apache.hadoop.yarn.server.resourcemanager.scheduler.fair.FairScheduler: [admission control] getFlexibleResource <memory:8192, vCores:4>
2016-10-14 07:52:11,126 INFO org.apache.hadoop.yarn.server.resourcemanager.scheduler.fair.FairScheduler: app appattempt_1476452954783_0001_000001 in queue root.interactive0 isRunning: true
2016-10-14 07:52:11,126 INFO org.apache.hadoop.yarn.server.resourcemanager.scheduler.AppSchedulingInfo: checking for deactivate of application :application_1476452954783_0001
2016-10-14 07:52:11,128 INFO org.apache.hadoop.yarn.server.resourcemanager.rmcontainer.RMContainerImpl: Processing container_1476452954783_0001_01_000013 of event ACQUIRED
2016-10-14 07:52:11,128 INFO org.apache.hadoop.yarn.server.resourcemanager.rmcontainer.RMContainerImpl: container_1476452954783_0001_01_000013 Container Transitioned from ALLOCATED to ACQUIRED
2016-10-14 07:52:11,262 INFO org.apache.hadoop.yarn.server.resourcemanager.scheduler.fair.FairScheduler: allocate(appattempt_1476452954783_0002_000001 [] [] [] []
2016-10-14 07:52:11,262 INFO org.apache.hadoop.yarn.server.resourcemanager.scheduler.fair.FSAppAttempt: root.interactive0 getMinReq:<memory:24576, vCores:12> demand: <memory:20480, vCores:10> usage: <memory:18432, vCores:9>running true active: true isLeafQueue():true
2016-10-14 07:52:11,262 INFO org.apache.hadoop.yarn.server.resourcemanager.scheduler.fair.FSAppAttempt: root.batch0 getMinReq:<memory:0, vCores:0> demand: <memory:34816, vCores:17> usage: <memory:14336, vCores:7>running true active: true isLeafQueue():true
2016-10-14 07:52:11,263 INFO org.apache.hadoop.yarn.server.resourcemanager.scheduler.fair.FSAppAttempt: appattempt_1476452954783_0002_000001 minReqResource: <memory:24576, vCores:12> flexibleResource: <memory:8192, vCores:4>
2016-10-14 07:52:11,263 INFO org.apache.hadoop.yarn.server.resourcemanager.scheduler.fair.FairScheduler: [admission control] getFlexibleResource <memory:8192, vCores:4>
2016-10-14 07:52:11,648 INFO org.apache.hadoop.yarn.server.resourcemanager.scheduler.fair.FairScheduler: allocate(appattempt_1476452954783_0001_000001 [{Priority: 1, Capability: <memory:1920, vCores:1>, # Containers: 8, Location: *, Relax Locality: true}] [container_1476452954783_0001_01_000013] [] []
2016-10-14 07:52:11,648 INFO org.apache.hadoop.yarn.server.resourcemanager.scheduler.fair.FSAppAttempt: root.interactive0 getMinReq:<memory:24576, vCores:12> demand: <memory:18432, vCores:9> usage: <memory:18432, vCores:9>running true active: true isLeafQueue():true
2016-10-14 07:52:11,648 INFO org.apache.hadoop.yarn.server.resourcemanager.scheduler.fair.FSAppAttempt: root.batch0 getMinReq:<memory:0, vCores:0> demand: <memory:34816, vCores:17> usage: <memory:14336, vCores:7>running true active: true isLeafQueue():true
2016-10-14 07:52:11,648 INFO org.apache.hadoop.yarn.server.resourcemanager.scheduler.fair.FSAppAttempt: appattempt_1476452954783_0001_000001 minReqResource: <memory:24576, vCores:12> flexibleResource: <memory:8192, vCores:4>
2016-10-14 07:52:11,648 INFO org.apache.hadoop.yarn.server.resourcemanager.scheduler.fair.FairScheduler: [admission control] getFlexibleResource <memory:8192, vCores:4>
2016-10-14 07:52:11,648 INFO org.apache.hadoop.yarn.server.resourcemanager.scheduler.fair.FairScheduler: app appattempt_1476452954783_0001_000001 in queue root.interactive0 isRunning: true
2016-10-14 07:52:11,648 INFO org.apache.hadoop.yarn.server.resourcemanager.rmcontainer.RMContainerImpl: Processing container_1476452954783_0001_01_000013 of event RELEASED
2016-10-14 07:52:11,649 INFO org.apache.hadoop.yarn.server.resourcemanager.rmcontainer.RMContainerImpl: container_1476452954783_0001_01_000013 Container Transitioned from ACQUIRED to RELEASED
2016-10-14 07:52:11,649 INFO org.apache.hadoop.yarn.server.resourcemanager.scheduler.fair.FSAppAttempt: Completed container: container_1476452954783_0001_01_000013 in state: RELEASED event:RELEASED
2016-10-14 07:52:11,649 INFO org.apache.hadoop.yarn.server.resourcemanager.RMAuditLogger: USER=tanle	IP=128.104.222.60	OPERATION=AM Released Container	TARGET=SchedulerApp	RESULT=SUCCESS	APPID=application_1476452954783_0001	CONTAINERID=container_1476452954783_0001_01_000013
2016-10-14 07:52:11,649 INFO org.apache.hadoop.yarn.server.resourcemanager.scheduler.SchedulerNode: Released container container_1476452954783_0001_01_000013 of capacity <memory:2048, vCores:1> on host cp-3.yarn-perf.yarnrm-PG0.wisc.cloudlab.us:44309, which currently has 3 containers, <memory:6144, vCores:3> used and <memory:2048, vCores:1> available, release resources=true
2016-10-14 07:52:11,649 INFO org.apache.hadoop.yarn.server.resourcemanager.scheduler.fair.FairScheduler: Application attempt appattempt_1476452954783_0001_000001 released container container_1476452954783_0001_01_000013 on node: host: cp-3.yarn-perf.yarnrm-PG0.wisc.cloudlab.us:44309 #containers=3 available=<memory:2048, vCores:1> used=<memory:6144, vCores:3> with event: RELEASED
2016-10-14 07:52:11,853 INFO org.apache.hadoop.yarn.server.resourcemanager.scheduler.fair.FairScheduler: allocate(appattempt_1476452954783_0001_000001 [] [] [] []
2016-10-14 07:52:11,853 INFO org.apache.hadoop.yarn.server.resourcemanager.scheduler.fair.FSAppAttempt: root.interactive0 getMinReq:<memory:24576, vCores:12> demand: <memory:18432, vCores:9> usage: <memory:16384, vCores:8>running true active: true isLeafQueue():true
2016-10-14 07:52:11,853 INFO org.apache.hadoop.yarn.server.resourcemanager.scheduler.fair.FSAppAttempt: root.batch0 getMinReq:<memory:0, vCores:0> demand: <memory:34816, vCores:17> usage: <memory:14336, vCores:7>running true active: true isLeafQueue():true
2016-10-14 07:52:11,853 INFO org.apache.hadoop.yarn.server.resourcemanager.scheduler.fair.FSAppAttempt: appattempt_1476452954783_0001_000001 minReqResource: <memory:24576, vCores:12> flexibleResource: <memory:8192, vCores:4>
2016-10-14 07:52:11,854 INFO org.apache.hadoop.yarn.server.resourcemanager.scheduler.fair.FairScheduler: [admission control] getFlexibleResource <memory:8192, vCores:4>
2016-10-14 07:52:11,854 INFO org.apache.hadoop.yarn.server.resourcemanager.scheduler.fair.FairScheduler: app appattempt_1476452954783_0001_000001 in queue root.interactive0 isRunning: true
2016-10-14 07:52:11,970 INFO org.apache.hadoop.yarn.server.resourcemanager.scheduler.fair.FSAppAttempt: assignContainer(FSSchedulerNode node:cp-3.yarn-perf.yarnrm-PG0.wisc.cloudlab.us, boolean reserved=true) for appattempt_1476452954783_0001_000001
2016-10-14 07:52:11,970 INFO org.apache.hadoop.yarn.server.resourcemanager.scheduler.fair.FSAppAttempt: allocate container: container_1476452954783_0001_01_000014 priority 1
2016-10-14 07:52:11,970 INFO org.apache.hadoop.yarn.server.resourcemanager.rmcontainer.RMContainerImpl: Processing container_1476452954783_0001_01_000014 of event START
2016-10-14 07:52:11,970 INFO org.apache.hadoop.yarn.server.resourcemanager.rmcontainer.RMContainerImpl: container_1476452954783_0001_01_000014 Container Transitioned from NEW to ALLOCATED
2016-10-14 07:52:11,971 INFO org.apache.hadoop.yarn.server.resourcemanager.RMAuditLogger: USER=tanle	OPERATION=AM Allocated Container	TARGET=SchedulerApp	RESULT=SUCCESS	APPID=application_1476452954783_0001	CONTAINERID=container_1476452954783_0001_01_000014
2016-10-14 07:52:11,971 INFO org.apache.hadoop.yarn.server.resourcemanager.scheduler.fair.FSAppAttempt: Application application_1476452954783_0001 unreserved  on node host: cp-3.yarn-perf.yarnrm-PG0.wisc.cloudlab.us:44309 #containers=3 available=<memory:2048, vCores:1> used=<memory:6144, vCores:3>, currently has 2 at priority 1; currentReservation <memory:4096, vCores:2>
2016-10-14 07:52:11,971 INFO org.apache.hadoop.yarn.server.resourcemanager.scheduler.SchedulerNode: Assigned container container_1476452954783_0001_01_000014 of capacity <memory:2048, vCores:1> on host cp-3.yarn-perf.yarnrm-PG0.wisc.cloudlab.us:44309, which has 4 containers, <memory:8192, vCores:4> used and <memory:0, vCores:0> available after allocation
2016-10-14 07:52:12,065 INFO org.apache.hadoop.yarn.server.resourcemanager.scheduler.fair.FairScheduler: allocate(appattempt_1476452954783_0002_000001 [] [] [] []
2016-10-14 07:52:12,065 INFO org.apache.hadoop.yarn.server.resourcemanager.scheduler.fair.FSAppAttempt: root.interactive0 getMinReq:<memory:24576, vCores:12> demand: <memory:32768, vCores:16> usage: <memory:18432, vCores:9>running true active: true isLeafQueue():true
2016-10-14 07:52:12,065 INFO org.apache.hadoop.yarn.server.resourcemanager.scheduler.fair.FSAppAttempt: root.batch0 getMinReq:<memory:0, vCores:0> demand: <memory:34816, vCores:17> usage: <memory:14336, vCores:7>running true active: true isLeafQueue():true
2016-10-14 07:52:12,066 INFO org.apache.hadoop.yarn.server.resourcemanager.scheduler.fair.FSAppAttempt: appattempt_1476452954783_0002_000001 minReqResource: <memory:24576, vCores:12> flexibleResource: <memory:8192, vCores:4>
2016-10-14 07:52:12,066 INFO org.apache.hadoop.yarn.server.resourcemanager.scheduler.fair.FairScheduler: [admission control] getFlexibleResource <memory:8192, vCores:4>
2016-10-14 07:52:12,257 INFO org.apache.hadoop.yarn.server.resourcemanager.scheduler.fair.FairScheduler: allocate(appattempt_1476452954783_0001_000001 [] [] [] []
2016-10-14 07:52:12,257 INFO org.apache.hadoop.yarn.server.resourcemanager.scheduler.fair.FSAppAttempt: root.interactive0 getMinReq:<memory:24576, vCores:12> demand: <memory:32768, vCores:16> usage: <memory:18432, vCores:9>running true active: true isLeafQueue():true
2016-10-14 07:52:12,257 INFO org.apache.hadoop.yarn.server.resourcemanager.scheduler.fair.FSAppAttempt: root.batch0 getMinReq:<memory:0, vCores:0> demand: <memory:34816, vCores:17> usage: <memory:14336, vCores:7>running true active: true isLeafQueue():true
2016-10-14 07:52:12,257 INFO org.apache.hadoop.yarn.server.resourcemanager.scheduler.fair.FSAppAttempt: appattempt_1476452954783_0001_000001 minReqResource: <memory:24576, vCores:12> flexibleResource: <memory:8192, vCores:4>
2016-10-14 07:52:12,257 INFO org.apache.hadoop.yarn.server.resourcemanager.scheduler.fair.FairScheduler: [admission control] getFlexibleResource <memory:8192, vCores:4>
2016-10-14 07:52:12,257 INFO org.apache.hadoop.yarn.server.resourcemanager.scheduler.fair.FairScheduler: app appattempt_1476452954783_0001_000001 in queue root.interactive0 isRunning: true
2016-10-14 07:52:12,259 INFO org.apache.hadoop.yarn.server.resourcemanager.rmcontainer.RMContainerImpl: Processing container_1476452954783_0001_01_000014 of event ACQUIRED
2016-10-14 07:52:12,259 INFO org.apache.hadoop.yarn.server.resourcemanager.rmcontainer.RMContainerImpl: container_1476452954783_0001_01_000014 Container Transitioned from ALLOCATED to ACQUIRED
2016-10-14 07:52:12,975 INFO org.apache.hadoop.yarn.server.resourcemanager.rmcontainer.RMContainerImpl: Processing container_1476452954783_0001_01_000014 of event LAUNCHED
2016-10-14 07:52:12,975 INFO org.apache.hadoop.yarn.server.resourcemanager.rmcontainer.RMContainerImpl: container_1476452954783_0001_01_000014 Container Transitioned from ACQUIRED to RUNNING
2016-10-14 07:52:12,976 INFO org.apache.hadoop.yarn.server.resourcemanager.scheduler.fair.FSAppAttempt: assignContainer(FSSchedulerNode node:cp-3.yarn-perf.yarnrm-PG0.wisc.cloudlab.us, boolean reserved=false) for appattempt_1476452954783_0001_000001
2016-10-14 07:52:12,977 INFO org.apache.hadoop.yarn.server.resourcemanager.scheduler.fair.FSAppAttempt: Making reservation: node=cp-3.yarn-perf.yarnrm-PG0.wisc.cloudlab.us app_id=application_1476452954783_0001
2016-10-14 07:52:12,977 INFO org.apache.hadoop.yarn.server.resourcemanager.rmcontainer.RMContainerImpl: Processing container_1476452954783_0001_01_000015 of event RESERVED
2016-10-14 07:52:12,977 INFO org.apache.hadoop.yarn.server.resourcemanager.rmcontainer.RMContainerImpl: container_1476452954783_0001_01_000015 Container Transitioned from NEW to RESERVED
2016-10-14 07:52:12,977 INFO org.apache.hadoop.yarn.server.resourcemanager.scheduler.fair.FSSchedulerNode: Reserved container container_1476452954783_0001_01_000015 on node host: cp-3.yarn-perf.yarnrm-PG0.wisc.cloudlab.us:44309 #containers=4 available=<memory:0, vCores:0> used=<memory:8192, vCores:4> for application org.apache.hadoop.yarn.server.resourcemanager.scheduler.fair.FSAppAttempt@13f22e88
2016-10-14 07:52:13,068 INFO org.apache.hadoop.yarn.server.resourcemanager.scheduler.fair.FairScheduler: allocate(appattempt_1476452954783_0001_000001 [{Priority: 1, Capability: <memory:1920, vCores:1>, # Containers: 7, Location: *, Relax Locality: true}] [] [] []
2016-10-14 07:52:13,068 INFO org.apache.hadoop.yarn.server.resourcemanager.scheduler.fair.FSAppAttempt: root.interactive0 getMinReq:<memory:24576, vCores:12> demand: <memory:32768, vCores:16> usage: <memory:18432, vCores:9>running true active: true isLeafQueue():true
2016-10-14 07:52:13,068 INFO org.apache.hadoop.yarn.server.resourcemanager.scheduler.fair.FSAppAttempt: root.batch0 getMinReq:<memory:0, vCores:0> demand: <memory:34816, vCores:17> usage: <memory:14336, vCores:7>running true active: true isLeafQueue():true
2016-10-14 07:52:13,068 INFO org.apache.hadoop.yarn.server.resourcemanager.scheduler.fair.FSAppAttempt: appattempt_1476452954783_0001_000001 minReqResource: <memory:24576, vCores:12> flexibleResource: <memory:8192, vCores:4>
2016-10-14 07:52:13,068 INFO org.apache.hadoop.yarn.server.resourcemanager.scheduler.fair.FairScheduler: [admission control] getFlexibleResource <memory:8192, vCores:4>
2016-10-14 07:52:13,068 INFO org.apache.hadoop.yarn.server.resourcemanager.scheduler.fair.FairScheduler: app appattempt_1476452954783_0001_000001 in queue root.interactive0 isRunning: true
2016-10-14 07:52:13,669 INFO org.apache.hadoop.yarn.server.resourcemanager.scheduler.fair.FairScheduler: allocate(appattempt_1476452954783_0002_000001 [] [] [] []
2016-10-14 07:52:13,669 INFO org.apache.hadoop.yarn.server.resourcemanager.scheduler.fair.FSAppAttempt: root.interactive0 getMinReq:<memory:24576, vCores:12> demand: <memory:32768, vCores:16> usage: <memory:18432, vCores:9>running true active: true isLeafQueue():true
2016-10-14 07:52:13,669 INFO org.apache.hadoop.yarn.server.resourcemanager.scheduler.fair.FSAppAttempt: root.batch0 getMinReq:<memory:0, vCores:0> demand: <memory:34816, vCores:17> usage: <memory:14336, vCores:7>running true active: true isLeafQueue():true
2016-10-14 07:52:13,669 INFO org.apache.hadoop.yarn.server.resourcemanager.scheduler.fair.FSAppAttempt: appattempt_1476452954783_0002_000001 minReqResource: <memory:24576, vCores:12> flexibleResource: <memory:8192, vCores:4>
2016-10-14 07:52:13,669 INFO org.apache.hadoop.yarn.server.resourcemanager.scheduler.fair.FairScheduler: [admission control] getFlexibleResource <memory:8192, vCores:4>
2016-10-14 07:52:14,672 INFO org.apache.hadoop.yarn.server.resourcemanager.scheduler.fair.FairScheduler: allocate(appattempt_1476452954783_0001_000001 [] [] [] []
2016-10-14 07:52:14,672 INFO org.apache.hadoop.yarn.server.resourcemanager.scheduler.fair.FSAppAttempt: root.interactive0 getMinReq:<memory:24576, vCores:12> demand: <memory:32768, vCores:16> usage: <memory:18432, vCores:9>running true active: true isLeafQueue():true
2016-10-14 07:52:14,672 INFO org.apache.hadoop.yarn.server.resourcemanager.scheduler.fair.FSAppAttempt: root.batch0 getMinReq:<memory:0, vCores:0> demand: <memory:34816, vCores:17> usage: <memory:14336, vCores:7>running true active: true isLeafQueue():true
2016-10-14 07:52:14,672 INFO org.apache.hadoop.yarn.server.resourcemanager.scheduler.fair.FSAppAttempt: appattempt_1476452954783_0001_000001 minReqResource: <memory:24576, vCores:12> flexibleResource: <memory:8192, vCores:4>
2016-10-14 07:52:14,672 INFO org.apache.hadoop.yarn.server.resourcemanager.scheduler.fair.FairScheduler: [admission control] getFlexibleResource <memory:8192, vCores:4>
2016-10-14 07:52:14,672 INFO org.apache.hadoop.yarn.server.resourcemanager.scheduler.fair.FairScheduler: app appattempt_1476452954783_0001_000001 in queue root.interactive0 isRunning: true
2016-10-14 07:52:15,640 INFO org.apache.hadoop.yarn.server.resourcemanager.scheduler.fair.FairScheduler: allocate(appattempt_1476452954783_0001_000001 [] [] [] []
2016-10-14 07:52:15,640 INFO org.apache.hadoop.yarn.server.resourcemanager.scheduler.fair.FSAppAttempt: root.interactive0 getMinReq:<memory:24576, vCores:12> demand: <memory:32768, vCores:16> usage: <memory:18432, vCores:9>running true active: true isLeafQueue():true
2016-10-14 07:52:15,640 INFO org.apache.hadoop.yarn.server.resourcemanager.scheduler.fair.FSAppAttempt: root.batch0 getMinReq:<memory:0, vCores:0> demand: <memory:34816, vCores:17> usage: <memory:14336, vCores:7>running true active: true isLeafQueue():true
2016-10-14 07:52:15,640 INFO org.apache.hadoop.yarn.server.resourcemanager.scheduler.fair.FSAppAttempt: appattempt_1476452954783_0001_000001 minReqResource: <memory:24576, vCores:12> flexibleResource: <memory:8192, vCores:4>
2016-10-14 07:52:15,640 INFO org.apache.hadoop.yarn.server.resourcemanager.scheduler.fair.FairScheduler: [admission control] getFlexibleResource <memory:8192, vCores:4>
2016-10-14 07:52:15,640 INFO org.apache.hadoop.yarn.server.resourcemanager.scheduler.fair.FairScheduler: app appattempt_1476452954783_0001_000001 in queue root.interactive0 isRunning: true
2016-10-14 07:52:15,654 INFO org.apache.hadoop.yarn.server.resourcemanager.scheduler.fair.FairScheduler: allocate(appattempt_1476452954783_0002_000001 [{Priority: 1, Capability: <memory:1920, vCores:1>, # Containers: 25, Location: *, Relax Locality: true}] [] [] []
2016-10-14 07:52:15,654 INFO org.apache.hadoop.yarn.server.resourcemanager.scheduler.fair.FSAppAttempt: root.interactive0 getMinReq:<memory:24576, vCores:12> demand: <memory:32768, vCores:16> usage: <memory:18432, vCores:9>running true active: true isLeafQueue():true
2016-10-14 07:52:15,654 INFO org.apache.hadoop.yarn.server.resourcemanager.scheduler.fair.FSAppAttempt: root.batch0 getMinReq:<memory:0, vCores:0> demand: <memory:34816, vCores:17> usage: <memory:14336, vCores:7>running true active: true isLeafQueue():true
2016-10-14 07:52:15,654 INFO org.apache.hadoop.yarn.server.resourcemanager.scheduler.fair.FSAppAttempt: appattempt_1476452954783_0002_000001 minReqResource: <memory:24576, vCores:12> flexibleResource: <memory:8192, vCores:4>
2016-10-14 07:52:15,654 INFO org.apache.hadoop.yarn.server.resourcemanager.scheduler.fair.FairScheduler: [admission control] getFlexibleResource <memory:8192, vCores:4>
2016-10-14 07:52:15,808 INFO org.apache.hadoop.yarn.server.resourcemanager.rmcontainer.RMContainerImpl: Processing container_1476452954783_0001_01_000004 of event FINISHED
2016-10-14 07:52:15,809 INFO org.apache.hadoop.yarn.server.resourcemanager.rmcontainer.RMContainerImpl: container_1476452954783_0001_01_000004 Container Transitioned from RUNNING to COMPLETED
2016-10-14 07:52:15,809 INFO org.apache.hadoop.yarn.server.resourcemanager.scheduler.fair.FSAppAttempt: Completed container: container_1476452954783_0001_01_000004 in state: COMPLETED event:FINISHED
2016-10-14 07:52:15,809 INFO org.apache.hadoop.yarn.server.resourcemanager.RMAuditLogger: USER=tanle	OPERATION=AM Released Container	TARGET=SchedulerApp	RESULT=SUCCESS	APPID=application_1476452954783_0001	CONTAINERID=container_1476452954783_0001_01_000004
2016-10-14 07:52:15,809 INFO org.apache.hadoop.yarn.server.resourcemanager.scheduler.SchedulerNode: Released container container_1476452954783_0001_01_000004 of capacity <memory:2048, vCores:1> on host cp-2.yarn-perf.yarnrm-PG0.wisc.cloudlab.us:43837, which currently has 3 containers, <memory:6144, vCores:3> used and <memory:2048, vCores:1> available, release resources=true
2016-10-14 07:52:15,809 INFO org.apache.hadoop.yarn.server.resourcemanager.scheduler.fair.FairScheduler: Application attempt appattempt_1476452954783_0001_000001 released container container_1476452954783_0001_01_000004 on node: host: cp-2.yarn-perf.yarnrm-PG0.wisc.cloudlab.us:43837 #containers=3 available=<memory:2048, vCores:1> used=<memory:6144, vCores:3> with event: FINISHED
2016-10-14 07:52:15,809 INFO org.apache.hadoop.yarn.server.resourcemanager.scheduler.fair.FSAppAttempt: assignContainer(FSSchedulerNode node:cp-2.yarn-perf.yarnrm-PG0.wisc.cloudlab.us, boolean reserved=true) for appattempt_1476452954783_0001_000001
2016-10-14 07:52:15,809 INFO org.apache.hadoop.yarn.server.resourcemanager.scheduler.fair.FSAppAttempt: allocate container: container_1476452954783_0001_01_000009 priority 1
2016-10-14 07:52:15,810 INFO org.apache.hadoop.yarn.server.resourcemanager.rmcontainer.RMContainerImpl: Processing container_1476452954783_0001_01_000009 of event START
2016-10-14 07:52:15,810 INFO org.apache.hadoop.yarn.server.resourcemanager.rmcontainer.RMContainerImpl: container_1476452954783_0001_01_000009 Container Transitioned from NEW to ALLOCATED
2016-10-14 07:52:15,810 INFO org.apache.hadoop.yarn.server.resourcemanager.RMAuditLogger: USER=tanle	OPERATION=AM Allocated Container	TARGET=SchedulerApp	RESULT=SUCCESS	APPID=application_1476452954783_0001	CONTAINERID=container_1476452954783_0001_01_000009
2016-10-14 07:52:15,810 INFO org.apache.hadoop.yarn.server.resourcemanager.scheduler.fair.FSAppAttempt: Application application_1476452954783_0001 unreserved  on node host: cp-2.yarn-perf.yarnrm-PG0.wisc.cloudlab.us:43837 #containers=3 available=<memory:2048, vCores:1> used=<memory:6144, vCores:3>, currently has 2 at priority 1; currentReservation <memory:4096, vCores:2>
2016-10-14 07:52:15,810 INFO org.apache.hadoop.yarn.server.resourcemanager.scheduler.SchedulerNode: Assigned container container_1476452954783_0001_01_000009 of capacity <memory:2048, vCores:1> on host cp-2.yarn-perf.yarnrm-PG0.wisc.cloudlab.us:43837, which has 4 containers, <memory:8192, vCores:4> used and <memory:0, vCores:0> available after allocation
2016-10-14 07:52:15,844 INFO org.apache.hadoop.yarn.server.resourcemanager.scheduler.fair.FairScheduler: allocate(appattempt_1476452954783_0001_000001 [] [] [] []
2016-10-14 07:52:15,844 INFO org.apache.hadoop.yarn.server.resourcemanager.scheduler.fair.FSAppAttempt: root.interactive0 getMinReq:<memory:24576, vCores:12> demand: <memory:32768, vCores:16> usage: <memory:18432, vCores:9>running true active: true isLeafQueue():true
2016-10-14 07:52:15,844 INFO org.apache.hadoop.yarn.server.resourcemanager.scheduler.fair.FSAppAttempt: root.batch0 getMinReq:<memory:0, vCores:0> demand: <memory:34816, vCores:17> usage: <memory:14336, vCores:7>running true active: true isLeafQueue():true
2016-10-14 07:52:15,844 INFO org.apache.hadoop.yarn.server.resourcemanager.scheduler.fair.FSAppAttempt: appattempt_1476452954783_0001_000001 minReqResource: <memory:24576, vCores:12> flexibleResource: <memory:8192, vCores:4>
2016-10-14 07:52:15,844 INFO org.apache.hadoop.yarn.server.resourcemanager.scheduler.fair.FairScheduler: [admission control] getFlexibleResource <memory:8192, vCores:4>
2016-10-14 07:52:15,844 INFO org.apache.hadoop.yarn.server.resourcemanager.scheduler.fair.FairScheduler: app appattempt_1476452954783_0001_000001 in queue root.interactive0 isRunning: true
2016-10-14 07:52:15,846 INFO org.apache.hadoop.yarn.server.resourcemanager.rmcontainer.RMContainerImpl: Processing container_1476452954783_0001_01_000009 of event ACQUIRED
2016-10-14 07:52:15,847 INFO org.apache.hadoop.yarn.server.resourcemanager.rmcontainer.RMContainerImpl: container_1476452954783_0001_01_000009 Container Transitioned from ALLOCATED to ACQUIRED
2016-10-14 07:52:15,858 INFO org.apache.hadoop.yarn.server.resourcemanager.scheduler.fair.FairScheduler: allocate(appattempt_1476452954783_0002_000001 [] [] [] []
2016-10-14 07:52:15,858 INFO org.apache.hadoop.yarn.server.resourcemanager.scheduler.fair.FSAppAttempt: root.interactive0 getMinReq:<memory:24576, vCores:12> demand: <memory:32768, vCores:16> usage: <memory:18432, vCores:9>running true active: true isLeafQueue():true
2016-10-14 07:52:15,858 INFO org.apache.hadoop.yarn.server.resourcemanager.scheduler.fair.FSAppAttempt: root.batch0 getMinReq:<memory:0, vCores:0> demand: <memory:34816, vCores:17> usage: <memory:14336, vCores:7>running true active: true isLeafQueue():true
2016-10-14 07:52:15,858 INFO org.apache.hadoop.yarn.server.resourcemanager.scheduler.fair.FSAppAttempt: appattempt_1476452954783_0002_000001 minReqResource: <memory:24576, vCores:12> flexibleResource: <memory:8192, vCores:4>
2016-10-14 07:52:15,858 INFO org.apache.hadoop.yarn.server.resourcemanager.scheduler.fair.FairScheduler: [admission control] getFlexibleResource <memory:8192, vCores:4>
2016-10-14 07:52:16,263 INFO org.apache.hadoop.yarn.server.resourcemanager.scheduler.fair.FairScheduler: allocate(appattempt_1476452954783_0002_000001 [] [] [] []
2016-10-14 07:52:16,263 INFO org.apache.hadoop.yarn.server.resourcemanager.scheduler.fair.FSAppAttempt: root.interactive0 getMinReq:<memory:24576, vCores:12> demand: <memory:30720, vCores:15> usage: <memory:18432, vCores:9>running true active: true isLeafQueue():true
2016-10-14 07:52:16,263 INFO org.apache.hadoop.yarn.server.resourcemanager.scheduler.fair.FSAppAttempt: root.batch0 getMinReq:<memory:0, vCores:0> demand: <memory:67584, vCores:33> usage: <memory:14336, vCores:7>running true active: true isLeafQueue():true
2016-10-14 07:52:16,263 INFO org.apache.hadoop.yarn.server.resourcemanager.scheduler.fair.FSAppAttempt: appattempt_1476452954783_0002_000001 minReqResource: <memory:24576, vCores:12> flexibleResource: <memory:8192, vCores:4>
2016-10-14 07:52:16,263 INFO org.apache.hadoop.yarn.server.resourcemanager.scheduler.fair.FairScheduler: [admission control] getFlexibleResource <memory:8192, vCores:4>
2016-10-14 07:52:16,263 INFO org.apache.hadoop.yarn.server.resourcemanager.scheduler.fair.FairScheduler: allocate(appattempt_1476452954783_0001_000001 [{Priority: 1, Capability: <memory:1920, vCores:1>, # Containers: 7, Location: *, Relax Locality: true}] [] [] []
2016-10-14 07:52:16,263 INFO org.apache.hadoop.yarn.server.resourcemanager.scheduler.fair.FSAppAttempt: root.interactive0 getMinReq:<memory:24576, vCores:12> demand: <memory:30720, vCores:15> usage: <memory:18432, vCores:9>running true active: true isLeafQueue():true
2016-10-14 07:52:16,263 INFO org.apache.hadoop.yarn.server.resourcemanager.scheduler.fair.FSAppAttempt: root.batch0 getMinReq:<memory:0, vCores:0> demand: <memory:67584, vCores:33> usage: <memory:14336, vCores:7>running true active: true isLeafQueue():true
2016-10-14 07:52:16,264 INFO org.apache.hadoop.yarn.server.resourcemanager.scheduler.fair.FSAppAttempt: appattempt_1476452954783_0001_000001 minReqResource: <memory:24576, vCores:12> flexibleResource: <memory:8192, vCores:4>
2016-10-14 07:52:16,264 INFO org.apache.hadoop.yarn.server.resourcemanager.scheduler.fair.FairScheduler: [admission control] getFlexibleResource <memory:8192, vCores:4>
2016-10-14 07:52:16,264 INFO org.apache.hadoop.yarn.server.resourcemanager.scheduler.fair.FairScheduler: app appattempt_1476452954783_0001_000001 in queue root.interactive0 isRunning: true
2016-10-14 07:52:16,648 INFO org.apache.hadoop.yarn.server.resourcemanager.scheduler.fair.FairScheduler: allocate(appattempt_1476452954783_0001_000001 [{Priority: 1, Capability: <memory:1920, vCores:1>, # Containers: 23, Location: *, Relax Locality: true}] [] [] []
2016-10-14 07:52:16,648 INFO org.apache.hadoop.yarn.server.resourcemanager.scheduler.fair.FSAppAttempt: root.interactive0 getMinReq:<memory:24576, vCores:12> demand: <memory:32768, vCores:16> usage: <memory:18432, vCores:9>running true active: true isLeafQueue():true
2016-10-14 07:52:16,648 INFO org.apache.hadoop.yarn.server.resourcemanager.scheduler.fair.FSAppAttempt: root.batch0 getMinReq:<memory:0, vCores:0> demand: <memory:67584, vCores:33> usage: <memory:14336, vCores:7>running true active: true isLeafQueue():true
2016-10-14 07:52:16,648 INFO org.apache.hadoop.yarn.server.resourcemanager.scheduler.fair.FSAppAttempt: appattempt_1476452954783_0001_000001 minReqResource: <memory:24576, vCores:12> flexibleResource: <memory:8192, vCores:4>
2016-10-14 07:52:16,648 INFO org.apache.hadoop.yarn.server.resourcemanager.scheduler.fair.FairScheduler: [admission control] getFlexibleResource <memory:8192, vCores:4>
2016-10-14 07:52:16,648 INFO org.apache.hadoop.yarn.server.resourcemanager.scheduler.fair.FairScheduler: app appattempt_1476452954783_0001_000001 in queue root.interactive0 isRunning: true
2016-10-14 07:52:16,813 INFO org.apache.hadoop.yarn.server.resourcemanager.rmcontainer.RMContainerImpl: Processing container_1476452954783_0001_01_000009 of event LAUNCHED
2016-10-14 07:52:16,813 INFO org.apache.hadoop.yarn.server.resourcemanager.rmcontainer.RMContainerImpl: container_1476452954783_0001_01_000009 Container Transitioned from ACQUIRED to RUNNING
2016-10-14 07:52:16,814 INFO org.apache.hadoop.yarn.server.resourcemanager.scheduler.fair.FSAppAttempt: assignContainer(FSSchedulerNode node:cp-2.yarn-perf.yarnrm-PG0.wisc.cloudlab.us, boolean reserved=false) for appattempt_1476452954783_0001_000001
2016-10-14 07:52:16,814 INFO org.apache.hadoop.yarn.server.resourcemanager.scheduler.fair.FSAppAttempt: Making reservation: node=cp-2.yarn-perf.yarnrm-PG0.wisc.cloudlab.us app_id=application_1476452954783_0001
2016-10-14 07:52:16,815 INFO org.apache.hadoop.yarn.server.resourcemanager.rmcontainer.RMContainerImpl: Processing container_1476452954783_0001_01_000016 of event RESERVED
2016-10-14 07:52:16,815 INFO org.apache.hadoop.yarn.server.resourcemanager.rmcontainer.RMContainerImpl: container_1476452954783_0001_01_000016 Container Transitioned from NEW to RESERVED
2016-10-14 07:52:16,815 INFO org.apache.hadoop.yarn.server.resourcemanager.scheduler.fair.FSSchedulerNode: Reserved container container_1476452954783_0001_01_000016 on node host: cp-2.yarn-perf.yarnrm-PG0.wisc.cloudlab.us:43837 #containers=4 available=<memory:0, vCores:0> used=<memory:8192, vCores:4> for application org.apache.hadoop.yarn.server.resourcemanager.scheduler.fair.FSAppAttempt@13f22e88
2016-10-14 07:52:16,851 INFO org.apache.hadoop.yarn.server.resourcemanager.scheduler.fair.FairScheduler: allocate(appattempt_1476452954783_0001_000001 [] [] [] []
2016-10-14 07:52:16,851 INFO org.apache.hadoop.yarn.server.resourcemanager.scheduler.fair.FSAppAttempt: root.interactive0 getMinReq:<memory:24576, vCores:12> demand: <memory:32768, vCores:16> usage: <memory:18432, vCores:9>running true active: true isLeafQueue():true
2016-10-14 07:52:16,851 INFO org.apache.hadoop.yarn.server.resourcemanager.scheduler.fair.FSAppAttempt: root.batch0 getMinReq:<memory:0, vCores:0> demand: <memory:67584, vCores:33> usage: <memory:14336, vCores:7>running true active: true isLeafQueue():true
2016-10-14 07:52:16,851 INFO org.apache.hadoop.yarn.server.resourcemanager.scheduler.fair.FSAppAttempt: appattempt_1476452954783_0001_000001 minReqResource: <memory:24576, vCores:12> flexibleResource: <memory:8192, vCores:4>
2016-10-14 07:52:16,851 INFO org.apache.hadoop.yarn.server.resourcemanager.scheduler.fair.FairScheduler: [admission control] getFlexibleResource <memory:8192, vCores:4>
2016-10-14 07:52:16,851 INFO org.apache.hadoop.yarn.server.resourcemanager.scheduler.fair.FairScheduler: app appattempt_1476452954783_0001_000001 in queue root.interactive0 isRunning: true
2016-10-14 07:52:16,972 INFO org.apache.hadoop.yarn.server.resourcemanager.scheduler.fair.FairScheduler: allocate(appattempt_1476452954783_0002_000001 [] [] [] []
2016-10-14 07:52:16,972 INFO org.apache.hadoop.yarn.server.resourcemanager.scheduler.fair.FSAppAttempt: root.interactive0 getMinReq:<memory:24576, vCores:12> demand: <memory:32768, vCores:16> usage: <memory:18432, vCores:9>running true active: true isLeafQueue():true
2016-10-14 07:52:16,973 INFO org.apache.hadoop.yarn.server.resourcemanager.scheduler.fair.FSAppAttempt: root.batch0 getMinReq:<memory:0, vCores:0> demand: <memory:67584, vCores:33> usage: <memory:14336, vCores:7>running true active: true isLeafQueue():true
2016-10-14 07:52:16,973 INFO org.apache.hadoop.yarn.server.resourcemanager.scheduler.fair.FSAppAttempt: appattempt_1476452954783_0002_000001 minReqResource: <memory:24576, vCores:12> flexibleResource: <memory:8192, vCores:4>
2016-10-14 07:52:16,973 INFO org.apache.hadoop.yarn.server.resourcemanager.scheduler.fair.FairScheduler: [admission control] getFlexibleResource <memory:8192, vCores:4>
2016-10-14 07:52:17,176 INFO org.apache.hadoop.yarn.server.resourcemanager.scheduler.fair.FairScheduler: allocate(appattempt_1476452954783_0002_000001 [] [] [] []
2016-10-14 07:52:17,176 INFO org.apache.hadoop.yarn.server.resourcemanager.scheduler.fair.FSAppAttempt: root.interactive0 getMinReq:<memory:24576, vCores:12> demand: <memory:65536, vCores:32> usage: <memory:18432, vCores:9>running true active: true isLeafQueue():true
2016-10-14 07:52:17,176 INFO org.apache.hadoop.yarn.server.resourcemanager.scheduler.fair.FSAppAttempt: root.batch0 getMinReq:<memory:0, vCores:0> demand: <memory:67584, vCores:33> usage: <memory:14336, vCores:7>running true active: true isLeafQueue():true
2016-10-14 07:52:17,176 INFO org.apache.hadoop.yarn.server.resourcemanager.scheduler.fair.FSAppAttempt: appattempt_1476452954783_0002_000001 minReqResource: <memory:24576, vCores:12> flexibleResource: <memory:8192, vCores:4>
2016-10-14 07:52:17,176 INFO org.apache.hadoop.yarn.server.resourcemanager.scheduler.fair.FairScheduler: [admission control] getFlexibleResource <memory:8192, vCores:4>
2016-10-14 07:52:17,254 INFO org.apache.hadoop.yarn.server.resourcemanager.scheduler.fair.FairScheduler: allocate(appattempt_1476452954783_0001_000001 [] [] [] []
2016-10-14 07:52:17,254 INFO org.apache.hadoop.yarn.server.resourcemanager.scheduler.fair.FSAppAttempt: root.interactive0 getMinReq:<memory:24576, vCores:12> demand: <memory:65536, vCores:32> usage: <memory:18432, vCores:9>running true active: true isLeafQueue():true
2016-10-14 07:52:17,254 INFO org.apache.hadoop.yarn.server.resourcemanager.scheduler.fair.FSAppAttempt: root.batch0 getMinReq:<memory:0, vCores:0> demand: <memory:67584, vCores:33> usage: <memory:14336, vCores:7>running true active: true isLeafQueue():true
2016-10-14 07:52:17,254 INFO org.apache.hadoop.yarn.server.resourcemanager.scheduler.fair.FSAppAttempt: appattempt_1476452954783_0001_000001 minReqResource: <memory:24576, vCores:12> flexibleResource: <memory:8192, vCores:4>
2016-10-14 07:52:17,255 INFO org.apache.hadoop.yarn.server.resourcemanager.scheduler.fair.FairScheduler: [admission control] getFlexibleResource <memory:8192, vCores:4>
2016-10-14 07:52:17,255 INFO org.apache.hadoop.yarn.server.resourcemanager.scheduler.fair.FairScheduler: app appattempt_1476452954783_0001_000001 in queue root.interactive0 isRunning: true
2016-10-14 07:52:17,579 INFO org.apache.hadoop.yarn.server.resourcemanager.scheduler.fair.FairScheduler: allocate(appattempt_1476452954783_0002_000001 [] [] [] []
2016-10-14 07:52:17,579 INFO org.apache.hadoop.yarn.server.resourcemanager.scheduler.fair.FSAppAttempt: root.interactive0 getMinReq:<memory:24576, vCores:12> demand: <memory:65536, vCores:32> usage: <memory:18432, vCores:9>running true active: true isLeafQueue():true
2016-10-14 07:52:17,579 INFO org.apache.hadoop.yarn.server.resourcemanager.scheduler.fair.FSAppAttempt: root.batch0 getMinReq:<memory:0, vCores:0> demand: <memory:67584, vCores:33> usage: <memory:14336, vCores:7>running true active: true isLeafQueue():true
2016-10-14 07:52:17,579 INFO org.apache.hadoop.yarn.server.resourcemanager.scheduler.fair.FSAppAttempt: appattempt_1476452954783_0002_000001 minReqResource: <memory:24576, vCores:12> flexibleResource: <memory:8192, vCores:4>
2016-10-14 07:52:17,579 INFO org.apache.hadoop.yarn.server.resourcemanager.scheduler.fair.FairScheduler: [admission control] getFlexibleResource <memory:8192, vCores:4>
2016-10-14 07:52:17,816 INFO org.apache.hadoop.yarn.server.resourcemanager.rmcontainer.RMContainerImpl: Processing container_1476452954783_0002_01_000004 of event FINISHED
2016-10-14 07:52:17,816 INFO org.apache.hadoop.yarn.server.resourcemanager.rmcontainer.RMContainerImpl: container_1476452954783_0002_01_000004 Container Transitioned from RUNNING to COMPLETED
2016-10-14 07:52:17,816 INFO org.apache.hadoop.yarn.server.resourcemanager.scheduler.fair.FSAppAttempt: Completed container: container_1476452954783_0002_01_000004 in state: COMPLETED event:FINISHED
2016-10-14 07:52:17,816 INFO org.apache.hadoop.yarn.server.resourcemanager.RMAuditLogger: USER=tanle	OPERATION=AM Released Container	TARGET=SchedulerApp	RESULT=SUCCESS	APPID=application_1476452954783_0002	CONTAINERID=container_1476452954783_0002_01_000004
2016-10-14 07:52:17,817 INFO org.apache.hadoop.yarn.server.resourcemanager.scheduler.SchedulerNode: Released container container_1476452954783_0002_01_000004 of capacity <memory:2048, vCores:1> on host cp-2.yarn-perf.yarnrm-PG0.wisc.cloudlab.us:43837, which currently has 3 containers, <memory:6144, vCores:3> used and <memory:2048, vCores:1> available, release resources=true
2016-10-14 07:52:17,817 INFO org.apache.hadoop.yarn.server.resourcemanager.scheduler.fair.FairScheduler: Application attempt appattempt_1476452954783_0002_000001 released container container_1476452954783_0002_01_000004 on node: host: cp-2.yarn-perf.yarnrm-PG0.wisc.cloudlab.us:43837 #containers=3 available=<memory:2048, vCores:1> used=<memory:6144, vCores:3> with event: FINISHED
2016-10-14 07:52:17,817 INFO org.apache.hadoop.yarn.server.resourcemanager.scheduler.fair.FSAppAttempt: assignContainer(FSSchedulerNode node:cp-2.yarn-perf.yarnrm-PG0.wisc.cloudlab.us, boolean reserved=true) for appattempt_1476452954783_0001_000001
2016-10-14 07:52:17,817 INFO org.apache.hadoop.yarn.server.resourcemanager.scheduler.fair.FSAppAttempt: allocate container: container_1476452954783_0001_01_000016 priority 1
2016-10-14 07:52:17,817 INFO org.apache.hadoop.yarn.server.resourcemanager.rmcontainer.RMContainerImpl: Processing container_1476452954783_0001_01_000016 of event START
2016-10-14 07:52:17,817 INFO org.apache.hadoop.yarn.server.resourcemanager.rmcontainer.RMContainerImpl: container_1476452954783_0001_01_000016 Container Transitioned from NEW to ALLOCATED
2016-10-14 07:52:17,817 INFO org.apache.hadoop.yarn.server.resourcemanager.RMAuditLogger: USER=tanle	OPERATION=AM Allocated Container	TARGET=SchedulerApp	RESULT=SUCCESS	APPID=application_1476452954783_0001	CONTAINERID=container_1476452954783_0001_01_000016
2016-10-14 07:52:17,817 INFO org.apache.hadoop.yarn.server.resourcemanager.scheduler.fair.FSAppAttempt: Application application_1476452954783_0001 unreserved  on node host: cp-2.yarn-perf.yarnrm-PG0.wisc.cloudlab.us:43837 #containers=3 available=<memory:2048, vCores:1> used=<memory:6144, vCores:3>, currently has 2 at priority 1; currentReservation <memory:4096, vCores:2>
2016-10-14 07:52:17,817 INFO org.apache.hadoop.yarn.server.resourcemanager.scheduler.SchedulerNode: Assigned container container_1476452954783_0001_01_000016 of capacity <memory:2048, vCores:1> on host cp-2.yarn-perf.yarnrm-PG0.wisc.cloudlab.us:43837, which has 4 containers, <memory:8192, vCores:4> used and <memory:0, vCores:0> available after allocation
2016-10-14 07:52:18,057 INFO org.apache.hadoop.yarn.server.resourcemanager.scheduler.fair.FairScheduler: allocate(appattempt_1476452954783_0001_000001 [] [] [] []
2016-10-14 07:52:18,057 INFO org.apache.hadoop.yarn.server.resourcemanager.scheduler.fair.FSAppAttempt: root.interactive0 getMinReq:<memory:24576, vCores:12> demand: <memory:65536, vCores:32> usage: <memory:20480, vCores:10>running true active: true isLeafQueue():true
2016-10-14 07:52:18,057 INFO org.apache.hadoop.yarn.server.resourcemanager.scheduler.fair.FSAppAttempt: root.batch0 getMinReq:<memory:0, vCores:0> demand: <memory:65536, vCores:32> usage: <memory:12288, vCores:6>running true active: true isLeafQueue():true
2016-10-14 07:52:18,058 INFO org.apache.hadoop.yarn.server.resourcemanager.scheduler.fair.FSAppAttempt: appattempt_1476452954783_0001_000001 minReqResource: <memory:24576, vCores:12> flexibleResource: <memory:8192, vCores:4>
2016-10-14 07:52:18,058 INFO org.apache.hadoop.yarn.server.resourcemanager.scheduler.fair.FairScheduler: [admission control] getFlexibleResource <memory:8192, vCores:4>
2016-10-14 07:52:18,058 INFO org.apache.hadoop.yarn.server.resourcemanager.scheduler.fair.FairScheduler: app appattempt_1476452954783_0001_000001 in queue root.interactive0 isRunning: true
2016-10-14 07:52:18,060 INFO org.apache.hadoop.yarn.server.resourcemanager.rmcontainer.RMContainerImpl: Processing container_1476452954783_0001_01_000016 of event ACQUIRED
2016-10-14 07:52:18,060 INFO org.apache.hadoop.yarn.server.resourcemanager.rmcontainer.RMContainerImpl: container_1476452954783_0001_01_000016 Container Transitioned from ALLOCATED to ACQUIRED
2016-10-14 07:52:18,382 INFO org.apache.hadoop.yarn.server.resourcemanager.scheduler.fair.FairScheduler: allocate(appattempt_1476452954783_0002_000001 [] [] [] []
2016-10-14 07:52:18,382 INFO org.apache.hadoop.yarn.server.resourcemanager.scheduler.fair.FSAppAttempt: root.interactive0 getMinReq:<memory:24576, vCores:12> demand: <memory:65536, vCores:32> usage: <memory:20480, vCores:10>running true active: true isLeafQueue():true
2016-10-14 07:52:18,383 INFO org.apache.hadoop.yarn.server.resourcemanager.scheduler.fair.FSAppAttempt: root.batch0 getMinReq:<memory:0, vCores:0> demand: <memory:65536, vCores:32> usage: <memory:12288, vCores:6>running true active: true isLeafQueue():true
2016-10-14 07:52:18,383 INFO org.apache.hadoop.yarn.server.resourcemanager.scheduler.fair.FSAppAttempt: appattempt_1476452954783_0002_000001 minReqResource: <memory:24576, vCores:12> flexibleResource: <memory:8192, vCores:4>
2016-10-14 07:52:18,383 INFO org.apache.hadoop.yarn.server.resourcemanager.scheduler.fair.FairScheduler: [admission control] getFlexibleResource <memory:8192, vCores:4>
2016-10-14 07:52:18,820 INFO org.apache.hadoop.yarn.server.resourcemanager.rmcontainer.RMContainerImpl: Processing container_1476452954783_0001_01_000016 of event LAUNCHED
2016-10-14 07:52:18,820 INFO org.apache.hadoop.yarn.server.resourcemanager.rmcontainer.RMContainerImpl: container_1476452954783_0001_01_000016 Container Transitioned from ACQUIRED to RUNNING
2016-10-14 07:52:18,821 INFO org.apache.hadoop.yarn.server.resourcemanager.scheduler.fair.FSAppAttempt: assignContainer(FSSchedulerNode node:cp-2.yarn-perf.yarnrm-PG0.wisc.cloudlab.us, boolean reserved=false) for appattempt_1476452954783_0001_000001
2016-10-14 07:52:18,821 INFO org.apache.hadoop.yarn.server.resourcemanager.scheduler.fair.FSAppAttempt: Making reservation: node=cp-2.yarn-perf.yarnrm-PG0.wisc.cloudlab.us app_id=application_1476452954783_0001
2016-10-14 07:52:18,821 INFO org.apache.hadoop.yarn.server.resourcemanager.rmcontainer.RMContainerImpl: Processing container_1476452954783_0001_01_000017 of event RESERVED
2016-10-14 07:52:18,821 INFO org.apache.hadoop.yarn.server.resourcemanager.rmcontainer.RMContainerImpl: container_1476452954783_0001_01_000017 Container Transitioned from NEW to RESERVED
2016-10-14 07:52:18,821 INFO org.apache.hadoop.yarn.server.resourcemanager.scheduler.fair.FSSchedulerNode: Reserved container container_1476452954783_0001_01_000017 on node host: cp-2.yarn-perf.yarnrm-PG0.wisc.cloudlab.us:43837 #containers=4 available=<memory:0, vCores:0> used=<memory:8192, vCores:4> for application org.apache.hadoop.yarn.server.resourcemanager.scheduler.fair.FSAppAttempt@13f22e88
2016-10-14 07:52:19,666 INFO org.apache.hadoop.yarn.server.resourcemanager.scheduler.fair.FairScheduler: allocate(appattempt_1476452954783_0001_000001 [{Priority: 1, Capability: <memory:1920, vCores:1>, # Containers: 22, Location: *, Relax Locality: true}] [] [] []
2016-10-14 07:52:19,667 INFO org.apache.hadoop.yarn.server.resourcemanager.scheduler.fair.FSAppAttempt: root.interactive0 getMinReq:<memory:24576, vCores:12> demand: <memory:65536, vCores:32> usage: <memory:20480, vCores:10>running true active: true isLeafQueue():true
2016-10-14 07:52:19,667 INFO org.apache.hadoop.yarn.server.resourcemanager.scheduler.fair.FSAppAttempt: root.batch0 getMinReq:<memory:0, vCores:0> demand: <memory:65536, vCores:32> usage: <memory:12288, vCores:6>running true active: true isLeafQueue():true
2016-10-14 07:52:19,667 INFO org.apache.hadoop.yarn.server.resourcemanager.scheduler.fair.FSAppAttempt: appattempt_1476452954783_0001_000001 minReqResource: <memory:24576, vCores:12> flexibleResource: <memory:8192, vCores:4>
2016-10-14 07:52:19,667 INFO org.apache.hadoop.yarn.server.resourcemanager.scheduler.fair.FairScheduler: [admission control] getFlexibleResource <memory:8192, vCores:4>
2016-10-14 07:52:19,667 INFO org.apache.hadoop.yarn.server.resourcemanager.scheduler.fair.FairScheduler: app appattempt_1476452954783_0001_000001 in queue root.interactive0 isRunning: true
2016-10-14 07:52:20,007 INFO org.apache.hadoop.yarn.server.resourcemanager.scheduler.fair.FairScheduler: allocate(appattempt_1476452954783_0002_000001 [{Priority: 1, Capability: <memory:1920, vCores:1>, # Containers: 26, Location: *, Relax Locality: true}] [] [] []
2016-10-14 07:52:20,007 INFO org.apache.hadoop.yarn.server.resourcemanager.scheduler.fair.FSAppAttempt: root.interactive0 getMinReq:<memory:24576, vCores:12> demand: <memory:65536, vCores:32> usage: <memory:20480, vCores:10>running true active: true isLeafQueue():true
2016-10-14 07:52:20,007 INFO org.apache.hadoop.yarn.server.resourcemanager.scheduler.fair.FSAppAttempt: root.batch0 getMinReq:<memory:0, vCores:0> demand: <memory:65536, vCores:32> usage: <memory:12288, vCores:6>running true active: true isLeafQueue():true
2016-10-14 07:52:20,007 INFO org.apache.hadoop.yarn.server.resourcemanager.scheduler.fair.FSAppAttempt: appattempt_1476452954783_0002_000001 minReqResource: <memory:24576, vCores:12> flexibleResource: <memory:8192, vCores:4>
2016-10-14 07:52:20,007 INFO org.apache.hadoop.yarn.server.resourcemanager.scheduler.fair.FairScheduler: [admission control] getFlexibleResource <memory:8192, vCores:4>
2016-10-14 07:52:20,256 INFO org.apache.hadoop.yarn.server.resourcemanager.scheduler.fair.FairScheduler: allocate(appattempt_1476452954783_0002_000001 [] [] [] []
2016-10-14 07:52:20,256 INFO org.apache.hadoop.yarn.server.resourcemanager.scheduler.fair.FSAppAttempt: root.interactive0 getMinReq:<memory:24576, vCores:12> demand: <memory:65536, vCores:32> usage: <memory:20480, vCores:10>running true active: true isLeafQueue():true
2016-10-14 07:52:20,256 INFO org.apache.hadoop.yarn.server.resourcemanager.scheduler.fair.FSAppAttempt: root.batch0 getMinReq:<memory:0, vCores:0> demand: <memory:67584, vCores:33> usage: <memory:12288, vCores:6>running true active: true isLeafQueue():true
2016-10-14 07:52:20,256 INFO org.apache.hadoop.yarn.server.resourcemanager.scheduler.fair.FSAppAttempt: appattempt_1476452954783_0002_000001 minReqResource: <memory:24576, vCores:12> flexibleResource: <memory:8192, vCores:4>
2016-10-14 07:52:20,256 INFO org.apache.hadoop.yarn.server.resourcemanager.scheduler.fair.FairScheduler: [admission control] getFlexibleResource <memory:8192, vCores:4>
2016-10-14 07:52:20,459 INFO org.apache.hadoop.yarn.server.resourcemanager.scheduler.fair.FairScheduler: allocate(appattempt_1476452954783_0002_000001 [] [] [] []
2016-10-14 07:52:20,459 INFO org.apache.hadoop.yarn.server.resourcemanager.scheduler.fair.FSAppAttempt: root.interactive0 getMinReq:<memory:24576, vCores:12> demand: <memory:65536, vCores:32> usage: <memory:20480, vCores:10>running true active: true isLeafQueue():true
2016-10-14 07:52:20,459 INFO org.apache.hadoop.yarn.server.resourcemanager.scheduler.fair.FSAppAttempt: root.batch0 getMinReq:<memory:0, vCores:0> demand: <memory:67584, vCores:33> usage: <memory:12288, vCores:6>running true active: true isLeafQueue():true
2016-10-14 07:52:20,459 INFO org.apache.hadoop.yarn.server.resourcemanager.scheduler.fair.FSAppAttempt: appattempt_1476452954783_0002_000001 minReqResource: <memory:24576, vCores:12> flexibleResource: <memory:8192, vCores:4>
2016-10-14 07:52:20,459 INFO org.apache.hadoop.yarn.server.resourcemanager.scheduler.fair.FairScheduler: [admission control] getFlexibleResource <memory:8192, vCores:4>
2016-10-14 07:52:20,655 INFO org.apache.hadoop.yarn.server.resourcemanager.scheduler.fair.FairScheduler: allocate(appattempt_1476452954783_0002_000001 [{Priority: 1, Capability: <memory:1920, vCores:1>, # Containers: 58, Location: *, Relax Locality: true}] [] [] []
2016-10-14 07:52:20,656 INFO org.apache.hadoop.yarn.server.resourcemanager.scheduler.fair.FSAppAttempt: root.interactive0 getMinReq:<memory:24576, vCores:12> demand: <memory:65536, vCores:32> usage: <memory:20480, vCores:10>running true active: true isLeafQueue():true
2016-10-14 07:52:20,656 INFO org.apache.hadoop.yarn.server.resourcemanager.scheduler.fair.FSAppAttempt: root.batch0 getMinReq:<memory:0, vCores:0> demand: <memory:67584, vCores:33> usage: <memory:12288, vCores:6>running true active: true isLeafQueue():true
2016-10-14 07:52:20,656 INFO org.apache.hadoop.yarn.server.resourcemanager.scheduler.fair.FSAppAttempt: appattempt_1476452954783_0002_000001 minReqResource: <memory:24576, vCores:12> flexibleResource: <memory:8192, vCores:4>
2016-10-14 07:52:20,656 INFO org.apache.hadoop.yarn.server.resourcemanager.scheduler.fair.FairScheduler: [admission control] getFlexibleResource <memory:8192, vCores:4>
2016-10-14 07:52:20,826 INFO org.apache.hadoop.yarn.server.resourcemanager.rmcontainer.RMContainerImpl: Processing container_1476452954783_0002_01_000006 of event FINISHED
2016-10-14 07:52:20,826 INFO org.apache.hadoop.yarn.server.resourcemanager.rmcontainer.RMContainerImpl: container_1476452954783_0002_01_000006 Container Transitioned from RUNNING to COMPLETED
2016-10-14 07:52:20,826 INFO org.apache.hadoop.yarn.server.resourcemanager.scheduler.fair.FSAppAttempt: Completed container: container_1476452954783_0002_01_000006 in state: COMPLETED event:FINISHED
2016-10-14 07:52:20,826 INFO org.apache.hadoop.yarn.server.resourcemanager.RMAuditLogger: USER=tanle	OPERATION=AM Released Container	TARGET=SchedulerApp	RESULT=SUCCESS	APPID=application_1476452954783_0002	CONTAINERID=container_1476452954783_0002_01_000006
2016-10-14 07:52:20,826 INFO org.apache.hadoop.yarn.server.resourcemanager.scheduler.SchedulerNode: Released container container_1476452954783_0002_01_000006 of capacity <memory:2048, vCores:1> on host cp-2.yarn-perf.yarnrm-PG0.wisc.cloudlab.us:43837, which currently has 3 containers, <memory:6144, vCores:3> used and <memory:2048, vCores:1> available, release resources=true
2016-10-14 07:52:20,826 INFO org.apache.hadoop.yarn.server.resourcemanager.scheduler.fair.FairScheduler: Application attempt appattempt_1476452954783_0002_000001 released container container_1476452954783_0002_01_000006 on node: host: cp-2.yarn-perf.yarnrm-PG0.wisc.cloudlab.us:43837 #containers=3 available=<memory:2048, vCores:1> used=<memory:6144, vCores:3> with event: FINISHED
2016-10-14 07:52:20,827 INFO org.apache.hadoop.yarn.server.resourcemanager.scheduler.fair.FSAppAttempt: assignContainer(FSSchedulerNode node:cp-2.yarn-perf.yarnrm-PG0.wisc.cloudlab.us, boolean reserved=true) for appattempt_1476452954783_0001_000001
2016-10-14 07:52:20,827 INFO org.apache.hadoop.yarn.server.resourcemanager.scheduler.fair.FSAppAttempt: allocate container: container_1476452954783_0001_01_000017 priority 1
2016-10-14 07:52:20,827 INFO org.apache.hadoop.yarn.server.resourcemanager.rmcontainer.RMContainerImpl: Processing container_1476452954783_0001_01_000017 of event START
2016-10-14 07:52:20,827 INFO org.apache.hadoop.yarn.server.resourcemanager.rmcontainer.RMContainerImpl: container_1476452954783_0001_01_000017 Container Transitioned from NEW to ALLOCATED
2016-10-14 07:52:20,827 INFO org.apache.hadoop.yarn.server.resourcemanager.RMAuditLogger: USER=tanle	OPERATION=AM Allocated Container	TARGET=SchedulerApp	RESULT=SUCCESS	APPID=application_1476452954783_0001	CONTAINERID=container_1476452954783_0001_01_000017
2016-10-14 07:52:20,827 INFO org.apache.hadoop.yarn.server.resourcemanager.scheduler.fair.FSAppAttempt: Application application_1476452954783_0001 unreserved  on node host: cp-2.yarn-perf.yarnrm-PG0.wisc.cloudlab.us:43837 #containers=3 available=<memory:2048, vCores:1> used=<memory:6144, vCores:3>, currently has 2 at priority 1; currentReservation <memory:4096, vCores:2>
2016-10-14 07:52:20,827 INFO org.apache.hadoop.yarn.server.resourcemanager.scheduler.SchedulerNode: Assigned container container_1476452954783_0001_01_000017 of capacity <memory:2048, vCores:1> on host cp-2.yarn-perf.yarnrm-PG0.wisc.cloudlab.us:43837, which has 4 containers, <memory:8192, vCores:4> used and <memory:0, vCores:0> available after allocation
2016-10-14 07:52:20,859 INFO org.apache.hadoop.yarn.server.resourcemanager.scheduler.fair.FairScheduler: allocate(appattempt_1476452954783_0002_000001 [] [] [] []
2016-10-14 07:52:20,859 INFO org.apache.hadoop.yarn.server.resourcemanager.scheduler.fair.FSAppAttempt: root.interactive0 getMinReq:<memory:24576, vCores:12> demand: <memory:65536, vCores:32> usage: <memory:22528, vCores:11>running true active: true isLeafQueue():true
2016-10-14 07:52:20,859 INFO org.apache.hadoop.yarn.server.resourcemanager.scheduler.fair.FSAppAttempt: root.batch0 getMinReq:<memory:0, vCores:0> demand: <memory:67584, vCores:33> usage: <memory:10240, vCores:5>running true active: true isLeafQueue():true
2016-10-14 07:52:20,859 INFO org.apache.hadoop.yarn.server.resourcemanager.scheduler.fair.FSAppAttempt: appattempt_1476452954783_0002_000001 minReqResource: <memory:24576, vCores:12> flexibleResource: <memory:8192, vCores:4>
2016-10-14 07:52:20,859 INFO org.apache.hadoop.yarn.server.resourcemanager.scheduler.fair.FairScheduler: [admission control] getFlexibleResource <memory:8192, vCores:4>
2016-10-14 07:52:21,264 INFO org.apache.hadoop.yarn.server.resourcemanager.scheduler.fair.FairScheduler: allocate(appattempt_1476452954783_0002_000001 [{Priority: 1, Capability: <memory:1920, vCores:1>, # Containers: 59, Location: *, Relax Locality: true}] [] [] []
2016-10-14 07:52:21,264 INFO org.apache.hadoop.yarn.server.resourcemanager.scheduler.fair.FSAppAttempt: root.interactive0 getMinReq:<memory:24576, vCores:12> demand: <memory:65536, vCores:32> usage: <memory:22528, vCores:11>running true active: true isLeafQueue():true
2016-10-14 07:52:21,264 INFO org.apache.hadoop.yarn.server.resourcemanager.scheduler.fair.FSAppAttempt: root.batch0 getMinReq:<memory:0, vCores:0> demand: <memory:131072, vCores:64> usage: <memory:10240, vCores:5>running true active: true isLeafQueue():true
2016-10-14 07:52:21,264 INFO org.apache.hadoop.yarn.server.resourcemanager.scheduler.fair.FSAppAttempt: appattempt_1476452954783_0002_000001 minReqResource: <memory:24576, vCores:12> flexibleResource: <memory:8192, vCores:4>
2016-10-14 07:52:21,264 INFO org.apache.hadoop.yarn.server.resourcemanager.scheduler.fair.FairScheduler: [admission control] getFlexibleResource <memory:8192, vCores:4>
2016-10-14 07:52:21,650 INFO org.apache.hadoop.yarn.server.resourcemanager.scheduler.fair.FairScheduler: allocate(appattempt_1476452954783_0001_000001 [{Priority: 1, Capability: <memory:1920, vCores:1>, # Containers: 54, Location: *, Relax Locality: true}] [] [] []
2016-10-14 07:52:21,650 INFO org.apache.hadoop.yarn.server.resourcemanager.scheduler.fair.FSAppAttempt: root.interactive0 getMinReq:<memory:24576, vCores:12> demand: <memory:65536, vCores:32> usage: <memory:22528, vCores:11>running true active: true isLeafQueue():true
2016-10-14 07:52:21,650 INFO org.apache.hadoop.yarn.server.resourcemanager.scheduler.fair.FSAppAttempt: root.batch0 getMinReq:<memory:0, vCores:0> demand: <memory:133120, vCores:65> usage: <memory:10240, vCores:5>running true active: true isLeafQueue():true
2016-10-14 07:52:21,650 INFO org.apache.hadoop.yarn.server.resourcemanager.scheduler.fair.FSAppAttempt: appattempt_1476452954783_0001_000001 minReqResource: <memory:24576, vCores:12> flexibleResource: <memory:8192, vCores:4>
2016-10-14 07:52:21,651 INFO org.apache.hadoop.yarn.server.resourcemanager.scheduler.fair.FairScheduler: [admission control] getFlexibleResource <memory:8192, vCores:4>
2016-10-14 07:52:21,651 INFO org.apache.hadoop.yarn.server.resourcemanager.scheduler.fair.FairScheduler: app appattempt_1476452954783_0001_000001 in queue root.interactive0 isRunning: true
2016-10-14 07:52:21,652 INFO org.apache.hadoop.yarn.server.resourcemanager.rmcontainer.RMContainerImpl: Processing container_1476452954783_0001_01_000017 of event ACQUIRED
2016-10-14 07:52:21,653 INFO org.apache.hadoop.yarn.server.resourcemanager.rmcontainer.RMContainerImpl: container_1476452954783_0001_01_000017 Container Transitioned from ALLOCATED to ACQUIRED
2016-10-14 07:52:21,829 INFO org.apache.hadoop.yarn.server.resourcemanager.rmcontainer.RMContainerImpl: Processing container_1476452954783_0001_01_000017 of event LAUNCHED
2016-10-14 07:52:21,829 INFO org.apache.hadoop.yarn.server.resourcemanager.rmcontainer.RMContainerImpl: container_1476452954783_0001_01_000017 Container Transitioned from ACQUIRED to RUNNING
2016-10-14 07:52:21,830 INFO org.apache.hadoop.yarn.server.resourcemanager.scheduler.fair.FSAppAttempt: assignContainer(FSSchedulerNode node:cp-2.yarn-perf.yarnrm-PG0.wisc.cloudlab.us, boolean reserved=false) for appattempt_1476452954783_0001_000001
2016-10-14 07:52:21,831 INFO org.apache.hadoop.yarn.server.resourcemanager.scheduler.fair.FSAppAttempt: Making reservation: node=cp-2.yarn-perf.yarnrm-PG0.wisc.cloudlab.us app_id=application_1476452954783_0001
2016-10-14 07:52:21,831 INFO org.apache.hadoop.yarn.server.resourcemanager.rmcontainer.RMContainerImpl: Processing container_1476452954783_0001_01_000018 of event RESERVED
2016-10-14 07:52:21,831 INFO org.apache.hadoop.yarn.server.resourcemanager.rmcontainer.RMContainerImpl: container_1476452954783_0001_01_000018 Container Transitioned from NEW to RESERVED
2016-10-14 07:52:21,831 INFO org.apache.hadoop.yarn.server.resourcemanager.scheduler.fair.FSSchedulerNode: Reserved container container_1476452954783_0001_01_000018 on node host: cp-2.yarn-perf.yarnrm-PG0.wisc.cloudlab.us:43837 #containers=4 available=<memory:0, vCores:0> used=<memory:8192, vCores:4> for application org.apache.hadoop.yarn.server.resourcemanager.scheduler.fair.FSAppAttempt@13f22e88
2016-10-14 07:52:21,860 INFO org.apache.hadoop.yarn.server.resourcemanager.scheduler.fair.FairScheduler: allocate(appattempt_1476452954783_0001_000001 [{Priority: 1, Capability: <memory:1920, vCores:1>, # Containers: 53, Location: *, Relax Locality: true}] [] [] []
2016-10-14 07:52:21,860 INFO org.apache.hadoop.yarn.server.resourcemanager.scheduler.fair.FSAppAttempt: root.interactive0 getMinReq:<memory:24576, vCores:12> demand: <memory:65536, vCores:32> usage: <memory:22528, vCores:11>running true active: true isLeafQueue():true
2016-10-14 07:52:21,860 INFO org.apache.hadoop.yarn.server.resourcemanager.scheduler.fair.FSAppAttempt: root.batch0 getMinReq:<memory:0, vCores:0> demand: <memory:133120, vCores:65> usage: <memory:10240, vCores:5>running true active: true isLeafQueue():true
2016-10-14 07:52:21,860 INFO org.apache.hadoop.yarn.server.resourcemanager.scheduler.fair.FSAppAttempt: appattempt_1476452954783_0001_000001 minReqResource: <memory:24576, vCores:12> flexibleResource: <memory:8192, vCores:4>
2016-10-14 07:52:21,860 INFO org.apache.hadoop.yarn.server.resourcemanager.scheduler.fair.FairScheduler: [admission control] getFlexibleResource <memory:8192, vCores:4>
2016-10-14 07:52:21,860 INFO org.apache.hadoop.yarn.server.resourcemanager.scheduler.fair.FairScheduler: app appattempt_1476452954783_0001_000001 in queue root.interactive0 isRunning: true
2016-10-14 07:52:22,068 INFO org.apache.hadoop.yarn.server.resourcemanager.scheduler.fair.FairScheduler: allocate(appattempt_1476452954783_0002_000001 [] [] [] []
2016-10-14 07:52:22,068 INFO org.apache.hadoop.yarn.server.resourcemanager.scheduler.fair.FSAppAttempt: root.interactive0 getMinReq:<memory:24576, vCores:12> demand: <memory:131072, vCores:64> usage: <memory:22528, vCores:11>running true active: true isLeafQueue():true
2016-10-14 07:52:22,068 INFO org.apache.hadoop.yarn.server.resourcemanager.scheduler.fair.FSAppAttempt: root.batch0 getMinReq:<memory:0, vCores:0> demand: <memory:133120, vCores:65> usage: <memory:10240, vCores:5>running true active: true isLeafQueue():true
2016-10-14 07:52:22,068 INFO org.apache.hadoop.yarn.server.resourcemanager.scheduler.fair.FSAppAttempt: appattempt_1476452954783_0002_000001 minReqResource: <memory:24576, vCores:12> flexibleResource: <memory:8192, vCores:4>
2016-10-14 07:52:22,068 INFO org.apache.hadoop.yarn.server.resourcemanager.scheduler.fair.FairScheduler: [admission control] getFlexibleResource <memory:8192, vCores:4>
2016-10-14 07:52:22,263 INFO org.apache.hadoop.yarn.server.resourcemanager.scheduler.fair.FairScheduler: allocate(appattempt_1476452954783_0001_000001 [] [] [] []
2016-10-14 07:52:22,263 INFO org.apache.hadoop.yarn.server.resourcemanager.scheduler.fair.FSAppAttempt: root.interactive0 getMinReq:<memory:24576, vCores:12> demand: <memory:131072, vCores:64> usage: <memory:22528, vCores:11>running true active: true isLeafQueue():true
2016-10-14 07:52:22,263 INFO org.apache.hadoop.yarn.server.resourcemanager.scheduler.fair.FSAppAttempt: root.batch0 getMinReq:<memory:0, vCores:0> demand: <memory:133120, vCores:65> usage: <memory:10240, vCores:5>running true active: true isLeafQueue():true
2016-10-14 07:52:22,263 INFO org.apache.hadoop.yarn.server.resourcemanager.scheduler.fair.FSAppAttempt: appattempt_1476452954783_0001_000001 minReqResource: <memory:24576, vCores:12> flexibleResource: <memory:8192, vCores:4>
2016-10-14 07:52:22,263 INFO org.apache.hadoop.yarn.server.resourcemanager.scheduler.fair.FairScheduler: [admission control] getFlexibleResource <memory:8192, vCores:4>
2016-10-14 07:52:22,264 INFO org.apache.hadoop.yarn.server.resourcemanager.scheduler.fair.FairScheduler: app appattempt_1476452954783_0001_000001 in queue root.interactive0 isRunning: true
2016-10-14 07:52:23,067 INFO org.apache.hadoop.yarn.server.resourcemanager.scheduler.fair.FairScheduler: allocate(appattempt_1476452954783_0001_000001 [] [] [] []
2016-10-14 07:52:23,067 INFO org.apache.hadoop.yarn.server.resourcemanager.scheduler.fair.FSAppAttempt: root.interactive0 getMinReq:<memory:24576, vCores:12> demand: <memory:131072, vCores:64> usage: <memory:22528, vCores:11>running true active: true isLeafQueue():true
2016-10-14 07:52:23,067 INFO org.apache.hadoop.yarn.server.resourcemanager.scheduler.fair.FSAppAttempt: root.batch0 getMinReq:<memory:0, vCores:0> demand: <memory:133120, vCores:65> usage: <memory:10240, vCores:5>running true active: true isLeafQueue():true
2016-10-14 07:52:23,067 INFO org.apache.hadoop.yarn.server.resourcemanager.scheduler.fair.FSAppAttempt: appattempt_1476452954783_0001_000001 minReqResource: <memory:24576, vCores:12> flexibleResource: <memory:8192, vCores:4>
2016-10-14 07:52:23,067 INFO org.apache.hadoop.yarn.server.resourcemanager.scheduler.fair.FairScheduler: [admission control] getFlexibleResource <memory:8192, vCores:4>
2016-10-14 07:52:23,067 INFO org.apache.hadoop.yarn.server.resourcemanager.scheduler.fair.FairScheduler: app appattempt_1476452954783_0001_000001 in queue root.interactive0 isRunning: true
2016-10-14 07:52:23,671 INFO org.apache.hadoop.yarn.server.resourcemanager.scheduler.fair.FairScheduler: allocate(appattempt_1476452954783_0002_000001 [] [] [] []
2016-10-14 07:52:23,671 INFO org.apache.hadoop.yarn.server.resourcemanager.scheduler.fair.FSAppAttempt: root.interactive0 getMinReq:<memory:24576, vCores:12> demand: <memory:131072, vCores:64> usage: <memory:22528, vCores:11>running true active: true isLeafQueue():true
2016-10-14 07:52:23,671 INFO org.apache.hadoop.yarn.server.resourcemanager.scheduler.fair.FSAppAttempt: root.batch0 getMinReq:<memory:0, vCores:0> demand: <memory:133120, vCores:65> usage: <memory:10240, vCores:5>running true active: true isLeafQueue():true
2016-10-14 07:52:23,672 INFO org.apache.hadoop.yarn.server.resourcemanager.scheduler.fair.FSAppAttempt: appattempt_1476452954783_0002_000001 minReqResource: <memory:24576, vCores:12> flexibleResource: <memory:8192, vCores:4>
2016-10-14 07:52:23,672 INFO org.apache.hadoop.yarn.server.resourcemanager.scheduler.fair.FairScheduler: [admission control] getFlexibleResource <memory:8192, vCores:4>
2016-10-14 07:52:24,671 INFO org.apache.hadoop.yarn.server.resourcemanager.scheduler.fair.FairScheduler: allocate(appattempt_1476452954783_0001_000001 [] [] [] []
2016-10-14 07:52:24,671 INFO org.apache.hadoop.yarn.server.resourcemanager.scheduler.fair.FSAppAttempt: root.interactive0 getMinReq:<memory:24576, vCores:12> demand: <memory:131072, vCores:64> usage: <memory:22528, vCores:11>running true active: true isLeafQueue():true
2016-10-14 07:52:24,671 INFO org.apache.hadoop.yarn.server.resourcemanager.scheduler.fair.FSAppAttempt: root.batch0 getMinReq:<memory:0, vCores:0> demand: <memory:133120, vCores:65> usage: <memory:10240, vCores:5>running true active: true isLeafQueue():true
2016-10-14 07:52:24,671 INFO org.apache.hadoop.yarn.server.resourcemanager.scheduler.fair.FSAppAttempt: appattempt_1476452954783_0001_000001 minReqResource: <memory:24576, vCores:12> flexibleResource: <memory:8192, vCores:4>
2016-10-14 07:52:24,671 INFO org.apache.hadoop.yarn.server.resourcemanager.scheduler.fair.FairScheduler: [admission control] getFlexibleResource <memory:8192, vCores:4>
2016-10-14 07:52:24,671 INFO org.apache.hadoop.yarn.server.resourcemanager.scheduler.fair.FairScheduler: app appattempt_1476452954783_0001_000001 in queue root.interactive0 isRunning: true
2016-10-14 07:52:25,661 INFO org.apache.hadoop.yarn.server.resourcemanager.scheduler.fair.FairScheduler: allocate(appattempt_1476452954783_0002_000001 [{Priority: 1, Capability: <memory:1920, vCores:1>, # Containers: 123, Location: *, Relax Locality: true}] [] [] []
2016-10-14 07:52:25,661 INFO org.apache.hadoop.yarn.server.resourcemanager.scheduler.fair.FSAppAttempt: root.interactive0 getMinReq:<memory:24576, vCores:12> demand: <memory:131072, vCores:64> usage: <memory:22528, vCores:11>running true active: true isLeafQueue():true
2016-10-14 07:52:25,661 INFO org.apache.hadoop.yarn.server.resourcemanager.scheduler.fair.FSAppAttempt: root.batch0 getMinReq:<memory:0, vCores:0> demand: <memory:133120, vCores:65> usage: <memory:10240, vCores:5>running true active: true isLeafQueue():true
2016-10-14 07:52:25,661 INFO org.apache.hadoop.yarn.server.resourcemanager.scheduler.fair.FSAppAttempt: appattempt_1476452954783_0002_000001 minReqResource: <memory:24576, vCores:12> flexibleResource: <memory:8192, vCores:4>
2016-10-14 07:52:25,661 INFO org.apache.hadoop.yarn.server.resourcemanager.scheduler.fair.FairScheduler: [admission control] getFlexibleResource <memory:8192, vCores:4>
2016-10-14 07:52:25,865 INFO org.apache.hadoop.yarn.server.resourcemanager.scheduler.fair.FairScheduler: allocate(appattempt_1476452954783_0002_000001 [] [] [] []
2016-10-14 07:52:25,865 INFO org.apache.hadoop.yarn.server.resourcemanager.scheduler.fair.FSAppAttempt: root.interactive0 getMinReq:<memory:24576, vCores:12> demand: <memory:131072, vCores:64> usage: <memory:22528, vCores:11>running true active: true isLeafQueue():true
2016-10-14 07:52:25,865 INFO org.apache.hadoop.yarn.server.resourcemanager.scheduler.fair.FSAppAttempt: root.batch0 getMinReq:<memory:0, vCores:0> demand: <memory:133120, vCores:65> usage: <memory:10240, vCores:5>running true active: true isLeafQueue():true
2016-10-14 07:52:25,865 INFO org.apache.hadoop.yarn.server.resourcemanager.scheduler.fair.FSAppAttempt: appattempt_1476452954783_0002_000001 minReqResource: <memory:24576, vCores:12> flexibleResource: <memory:8192, vCores:4>
2016-10-14 07:52:25,865 INFO org.apache.hadoop.yarn.server.resourcemanager.scheduler.fair.FairScheduler: [admission control] getFlexibleResource <memory:8192, vCores:4>
2016-10-14 07:52:26,269 INFO org.apache.hadoop.yarn.server.resourcemanager.scheduler.fair.FairScheduler: allocate(appattempt_1476452954783_0002_000001 [] [] [] []
2016-10-14 07:52:26,269 INFO org.apache.hadoop.yarn.server.resourcemanager.scheduler.fair.FSAppAttempt: root.interactive0 getMinReq:<memory:24576, vCores:12> demand: <memory:131072, vCores:64> usage: <memory:22528, vCores:11>running true active: true isLeafQueue():true
2016-10-14 07:52:26,269 INFO org.apache.hadoop.yarn.server.resourcemanager.scheduler.fair.FSAppAttempt: root.batch0 getMinReq:<memory:0, vCores:0> demand: <memory:264192, vCores:129> usage: <memory:10240, vCores:5>running true active: true isLeafQueue():true
2016-10-14 07:52:26,269 INFO org.apache.hadoop.yarn.server.resourcemanager.scheduler.fair.FSAppAttempt: appattempt_1476452954783_0002_000001 minReqResource: <memory:24576, vCores:12> flexibleResource: <memory:8192, vCores:4>
2016-10-14 07:52:26,269 INFO org.apache.hadoop.yarn.server.resourcemanager.scheduler.fair.FairScheduler: [admission control] getFlexibleResource <memory:8192, vCores:4>
2016-10-14 07:52:26,653 INFO org.apache.hadoop.yarn.server.resourcemanager.scheduler.fair.FairScheduler: allocate(appattempt_1476452954783_0001_000001 [{Priority: 1, Capability: <memory:1920, vCores:1>, # Containers: 117, Location: *, Relax Locality: true}] [] [] []
2016-10-14 07:52:26,653 INFO org.apache.hadoop.yarn.server.resourcemanager.scheduler.fair.FSAppAttempt: root.interactive0 getMinReq:<memory:24576, vCores:12> demand: <memory:131072, vCores:64> usage: <memory:22528, vCores:11>running true active: true isLeafQueue():true
2016-10-14 07:52:26,654 INFO org.apache.hadoop.yarn.server.resourcemanager.scheduler.fair.FSAppAttempt: root.batch0 getMinReq:<memory:0, vCores:0> demand: <memory:264192, vCores:129> usage: <memory:10240, vCores:5>running true active: true isLeafQueue():true
2016-10-14 07:52:26,654 INFO org.apache.hadoop.yarn.server.resourcemanager.scheduler.fair.FSAppAttempt: appattempt_1476452954783_0001_000001 minReqResource: <memory:24576, vCores:12> flexibleResource: <memory:8192, vCores:4>
2016-10-14 07:52:26,654 INFO org.apache.hadoop.yarn.server.resourcemanager.scheduler.fair.FairScheduler: [admission control] getFlexibleResource <memory:8192, vCores:4>
2016-10-14 07:52:26,654 INFO org.apache.hadoop.yarn.server.resourcemanager.scheduler.fair.FairScheduler: app appattempt_1476452954783_0001_000001 in queue root.interactive0 isRunning: true
2016-10-14 07:52:26,857 INFO org.apache.hadoop.yarn.server.resourcemanager.scheduler.fair.FairScheduler: allocate(appattempt_1476452954783_0001_000001 [] [] [] []
2016-10-14 07:52:26,857 INFO org.apache.hadoop.yarn.server.resourcemanager.scheduler.fair.FSAppAttempt: root.interactive0 getMinReq:<memory:24576, vCores:12> demand: <memory:131072, vCores:64> usage: <memory:22528, vCores:11>running true active: true isLeafQueue():true
2016-10-14 07:52:26,857 INFO org.apache.hadoop.yarn.server.resourcemanager.scheduler.fair.FSAppAttempt: root.batch0 getMinReq:<memory:0, vCores:0> demand: <memory:264192, vCores:129> usage: <memory:10240, vCores:5>running true active: true isLeafQueue():true
2016-10-14 07:52:26,857 INFO org.apache.hadoop.yarn.server.resourcemanager.scheduler.fair.FSAppAttempt: appattempt_1476452954783_0001_000001 minReqResource: <memory:24576, vCores:12> flexibleResource: <memory:8192, vCores:4>
2016-10-14 07:52:26,858 INFO org.apache.hadoop.yarn.server.resourcemanager.scheduler.fair.FairScheduler: [admission control] getFlexibleResource <memory:8192, vCores:4>
2016-10-14 07:52:26,858 INFO org.apache.hadoop.yarn.server.resourcemanager.scheduler.fair.FairScheduler: app appattempt_1476452954783_0001_000001 in queue root.interactive0 isRunning: true
2016-10-14 07:52:27,072 INFO org.apache.hadoop.yarn.server.resourcemanager.scheduler.fair.FairScheduler: allocate(appattempt_1476452954783_0002_000001 [] [] [] []
2016-10-14 07:52:27,073 INFO org.apache.hadoop.yarn.server.resourcemanager.scheduler.fair.FSAppAttempt: root.interactive0 getMinReq:<memory:24576, vCores:12> demand: <memory:262144, vCores:128> usage: <memory:22528, vCores:11>running true active: true isLeafQueue():true
2016-10-14 07:52:27,073 INFO org.apache.hadoop.yarn.server.resourcemanager.scheduler.fair.FSAppAttempt: root.batch0 getMinReq:<memory:0, vCores:0> demand: <memory:264192, vCores:129> usage: <memory:10240, vCores:5>running true active: true isLeafQueue():true
2016-10-14 07:52:27,073 INFO org.apache.hadoop.yarn.server.resourcemanager.scheduler.fair.FSAppAttempt: appattempt_1476452954783_0002_000001 minReqResource: <memory:24576, vCores:12> flexibleResource: <memory:8192, vCores:4>
2016-10-14 07:52:27,073 INFO org.apache.hadoop.yarn.server.resourcemanager.scheduler.fair.FairScheduler: [admission control] getFlexibleResource <memory:8192, vCores:4>
2016-10-14 07:52:27,261 INFO org.apache.hadoop.yarn.server.resourcemanager.scheduler.fair.FairScheduler: allocate(appattempt_1476452954783_0001_000001 [] [] [] []
2016-10-14 07:52:27,262 INFO org.apache.hadoop.yarn.server.resourcemanager.scheduler.fair.FSAppAttempt: root.interactive0 getMinReq:<memory:24576, vCores:12> demand: <memory:262144, vCores:128> usage: <memory:22528, vCores:11>running true active: true isLeafQueue():true
2016-10-14 07:52:27,262 INFO org.apache.hadoop.yarn.server.resourcemanager.scheduler.fair.FSAppAttempt: root.batch0 getMinReq:<memory:0, vCores:0> demand: <memory:264192, vCores:129> usage: <memory:10240, vCores:5>running true active: true isLeafQueue():true
2016-10-14 07:52:27,262 INFO org.apache.hadoop.yarn.server.resourcemanager.scheduler.fair.FSAppAttempt: appattempt_1476452954783_0001_000001 minReqResource: <memory:24576, vCores:12> flexibleResource: <memory:8192, vCores:4>
2016-10-14 07:52:27,262 INFO org.apache.hadoop.yarn.server.resourcemanager.scheduler.fair.FairScheduler: [admission control] getFlexibleResource <memory:8192, vCores:4>
2016-10-14 07:52:27,262 INFO org.apache.hadoop.yarn.server.resourcemanager.scheduler.fair.FairScheduler: app appattempt_1476452954783_0001_000001 in queue root.interactive0 isRunning: true
2016-10-14 07:52:28,065 INFO org.apache.hadoop.yarn.server.resourcemanager.scheduler.fair.FairScheduler: allocate(appattempt_1476452954783_0001_000001 [] [] [] []
2016-10-14 07:52:28,066 INFO org.apache.hadoop.yarn.server.resourcemanager.scheduler.fair.FSAppAttempt: root.interactive0 getMinReq:<memory:24576, vCores:12> demand: <memory:262144, vCores:128> usage: <memory:22528, vCores:11>running true active: true isLeafQueue():true
2016-10-14 07:52:28,066 INFO org.apache.hadoop.yarn.server.resourcemanager.scheduler.fair.FSAppAttempt: root.batch0 getMinReq:<memory:0, vCores:0> demand: <memory:264192, vCores:129> usage: <memory:10240, vCores:5>running true active: true isLeafQueue():true
2016-10-14 07:52:28,066 INFO org.apache.hadoop.yarn.server.resourcemanager.scheduler.fair.FSAppAttempt: appattempt_1476452954783_0001_000001 minReqResource: <memory:24576, vCores:12> flexibleResource: <memory:8192, vCores:4>
2016-10-14 07:52:28,066 INFO org.apache.hadoop.yarn.server.resourcemanager.scheduler.fair.FairScheduler: [admission control] getFlexibleResource <memory:8192, vCores:4>
2016-10-14 07:52:28,066 INFO org.apache.hadoop.yarn.server.resourcemanager.scheduler.fair.FairScheduler: app appattempt_1476452954783_0001_000001 in queue root.interactive0 isRunning: true
2016-10-14 07:52:28,676 INFO org.apache.hadoop.yarn.server.resourcemanager.scheduler.fair.FairScheduler: allocate(appattempt_1476452954783_0002_000001 [] [] [] []
2016-10-14 07:52:28,676 INFO org.apache.hadoop.yarn.server.resourcemanager.scheduler.fair.FSAppAttempt: root.interactive0 getMinReq:<memory:24576, vCores:12> demand: <memory:262144, vCores:128> usage: <memory:22528, vCores:11>running true active: true isLeafQueue():true
2016-10-14 07:52:28,676 INFO org.apache.hadoop.yarn.server.resourcemanager.scheduler.fair.FSAppAttempt: root.batch0 getMinReq:<memory:0, vCores:0> demand: <memory:264192, vCores:129> usage: <memory:10240, vCores:5>running true active: true isLeafQueue():true
2016-10-14 07:52:28,676 INFO org.apache.hadoop.yarn.server.resourcemanager.scheduler.fair.FSAppAttempt: appattempt_1476452954783_0002_000001 minReqResource: <memory:24576, vCores:12> flexibleResource: <memory:8192, vCores:4>
2016-10-14 07:52:28,677 INFO org.apache.hadoop.yarn.server.resourcemanager.scheduler.fair.FairScheduler: [admission control] getFlexibleResource <memory:8192, vCores:4>
2016-10-14 07:52:29,182 INFO org.apache.hadoop.yarn.server.resourcemanager.scheduler.fair.FairScheduler: allocate(appattempt_1476452954783_0001_000001 [] [] [] []
2016-10-14 07:52:29,182 INFO org.apache.hadoop.yarn.server.resourcemanager.scheduler.fair.FSAppAttempt: root.interactive0 getMinReq:<memory:24576, vCores:12> demand: <memory:262144, vCores:128> usage: <memory:22528, vCores:11>running true active: true isLeafQueue():true
2016-10-14 07:52:29,182 INFO org.apache.hadoop.yarn.server.resourcemanager.scheduler.fair.FSAppAttempt: root.batch0 getMinReq:<memory:0, vCores:0> demand: <memory:264192, vCores:129> usage: <memory:10240, vCores:5>running true active: true isLeafQueue():true
2016-10-14 07:52:29,183 INFO org.apache.hadoop.yarn.server.resourcemanager.scheduler.fair.FSAppAttempt: appattempt_1476452954783_0001_000001 minReqResource: <memory:24576, vCores:12> flexibleResource: <memory:8192, vCores:4>
2016-10-14 07:52:29,183 INFO org.apache.hadoop.yarn.server.resourcemanager.scheduler.fair.FairScheduler: [admission control] getFlexibleResource <memory:8192, vCores:4>
2016-10-14 07:52:29,183 INFO org.apache.hadoop.yarn.server.resourcemanager.scheduler.fair.FairScheduler: app appattempt_1476452954783_0001_000001 in queue root.interactive0 isRunning: true
2016-10-14 07:52:29,386 INFO org.apache.hadoop.yarn.server.resourcemanager.scheduler.fair.FairScheduler: allocate(appattempt_1476452954783_0001_000001 [] [] [] []
2016-10-14 07:52:29,387 INFO org.apache.hadoop.yarn.server.resourcemanager.scheduler.fair.FSAppAttempt: root.interactive0 getMinReq:<memory:24576, vCores:12> demand: <memory:262144, vCores:128> usage: <memory:22528, vCores:11>running true active: true isLeafQueue():true
2016-10-14 07:52:29,387 INFO org.apache.hadoop.yarn.server.resourcemanager.scheduler.fair.FSAppAttempt: root.batch0 getMinReq:<memory:0, vCores:0> demand: <memory:264192, vCores:129> usage: <memory:10240, vCores:5>running true active: true isLeafQueue():true
2016-10-14 07:52:29,387 INFO org.apache.hadoop.yarn.server.resourcemanager.scheduler.fair.FSAppAttempt: appattempt_1476452954783_0001_000001 minReqResource: <memory:24576, vCores:12> flexibleResource: <memory:8192, vCores:4>
2016-10-14 07:52:29,387 INFO org.apache.hadoop.yarn.server.resourcemanager.scheduler.fair.FairScheduler: [admission control] getFlexibleResource <memory:8192, vCores:4>
2016-10-14 07:52:29,387 INFO org.apache.hadoop.yarn.server.resourcemanager.scheduler.fair.FairScheduler: app appattempt_1476452954783_0001_000001 in queue root.interactive0 isRunning: true
2016-10-14 07:52:29,658 WARN org.apache.hadoop.yarn.server.resourcemanager.rmapp.RMAppImpl: The specific max attempts: 0 for application: 4 is invalid, because it is out of the range [1, 2]. Use the global max attempts instead.
2016-10-14 07:52:29,659 INFO org.apache.hadoop.yarn.server.resourcemanager.ClientRMService: Application with id 4 submitted by user tanle
2016-10-14 07:52:29,659 INFO org.apache.hadoop.yarn.server.resourcemanager.RMAuditLogger: USER=tanle	IP=128.104.222.53	OPERATION=Submit Application Request	TARGET=ClientRMService	RESULT=SUCCESS	APPID=application_1476452954783_0004
2016-10-14 07:52:29,659 INFO org.apache.hadoop.yarn.server.resourcemanager.rmapp.RMAppImpl: Storing application with id application_1476452954783_0004
2016-10-14 07:52:29,660 INFO org.apache.hadoop.yarn.server.resourcemanager.recovery.RMStateStore: Storing info for app: application_1476452954783_0004
2016-10-14 07:52:29,665 INFO org.apache.hadoop.yarn.server.resourcemanager.scheduler.fair.FairScheduler: Accepted application application_1476452954783_0004 from user: tanle, in queue: interactive1, currently num of applications: 4
2016-10-14 07:52:29,665 INFO org.apache.hadoop.yarn.server.resourcemanager.ApplicationMasterService: Registering app attempt : appattempt_1476452954783_0004_000001
2016-10-14 07:52:29,666 INFO org.apache.hadoop.yarn.server.resourcemanager.rmapp.attempt.RMAppAttemptImpl: appattempt_1476452954783_0004_000001 State change from NEW to SUBMITTED
2016-10-14 07:52:29,666 INFO org.apache.hadoop.yarn.server.resourcemanager.scheduler.fair.FairScheduler: Added Application Attempt appattempt_1476452954783_0004_000001 to scheduler from user: tanle
2016-10-14 07:52:29,666 INFO org.apache.hadoop.yarn.server.resourcemanager.rmapp.attempt.RMAppAttemptImpl: ScheduleTransition.transition(appattempt_1476452954783_0004_000001,EventType: ATTEMPT_ADDED)
2016-10-14 07:52:29,666 INFO org.apache.hadoop.yarn.server.resourcemanager.scheduler.fair.FairScheduler: allocate(appattempt_1476452954783_0004_000001 [{Priority: 0, Capability: <memory:2048, vCores:1>, # Containers: 1, Location: *, Relax Locality: true}] [] null null
2016-10-14 07:52:29,667 INFO org.apache.hadoop.yarn.server.resourcemanager.scheduler.fair.FSAppAttempt: root.interactive0 getMinReq:<memory:24576, vCores:12> demand: <memory:262144, vCores:128> usage: <memory:22528, vCores:11>running true active: true isLeafQueue():true
2016-10-14 07:52:29,667 INFO org.apache.hadoop.yarn.server.resourcemanager.scheduler.fair.FSAppAttempt: root.batch0 getMinReq:<memory:0, vCores:0> demand: <memory:264192, vCores:129> usage: <memory:10240, vCores:5>running true active: true isLeafQueue():true
2016-10-14 07:52:29,667 INFO org.apache.hadoop.yarn.server.resourcemanager.scheduler.fair.FSAppAttempt: appattempt_1476452954783_0004_000001 minReqResource: <memory:24576, vCores:12> flexibleResource: <memory:8192, vCores:4>
2016-10-14 07:52:29,667 INFO org.apache.hadoop.yarn.server.resourcemanager.scheduler.fair.FairScheduler: [admission control] getFlexibleResource <memory:8192, vCores:4>
2016-10-14 07:52:29,667 INFO org.apache.hadoop.yarn.server.resourcemanager.scheduler.fair.FairScheduler: app appattempt_1476452954783_0004_000001 in queue root.interactive1 isRunning: false
2016-10-14 07:52:29,667 INFO org.apache.hadoop.yarn.server.resourcemanager.scheduler.fair.FairScheduler: [admission control] Cannot allocate appattempt_1476452954783_0004_000001 because there is NO flexible resource left
2016-10-14 07:52:29,790 INFO org.apache.hadoop.yarn.server.resourcemanager.scheduler.fair.FairScheduler: allocate(appattempt_1476452954783_0001_000001 [] [] [] []
2016-10-14 07:52:29,791 INFO org.apache.hadoop.yarn.server.resourcemanager.scheduler.fair.FSAppAttempt: root.interactive0 getMinReq:<memory:24576, vCores:12> demand: <memory:262144, vCores:128> usage: <memory:22528, vCores:11>running true active: true isLeafQueue():true
2016-10-14 07:52:29,791 INFO org.apache.hadoop.yarn.server.resourcemanager.scheduler.fair.FSAppAttempt: root.batch0 getMinReq:<memory:0, vCores:0> demand: <memory:264192, vCores:129> usage: <memory:10240, vCores:5>running true active: true isLeafQueue():true
2016-10-14 07:52:29,791 INFO org.apache.hadoop.yarn.server.resourcemanager.scheduler.fair.FSAppAttempt: appattempt_1476452954783_0001_000001 minReqResource: <memory:24576, vCores:12> flexibleResource: <memory:8192, vCores:4>
2016-10-14 07:52:29,791 INFO org.apache.hadoop.yarn.server.resourcemanager.scheduler.fair.FairScheduler: [admission control] getFlexibleResource <memory:8192, vCores:4>
2016-10-14 07:52:29,791 INFO org.apache.hadoop.yarn.server.resourcemanager.scheduler.fair.FairScheduler: app appattempt_1476452954783_0001_000001 in queue root.interactive0 isRunning: true
2016-10-14 07:52:29,853 INFO org.apache.hadoop.yarn.server.resourcemanager.rmcontainer.RMContainerImpl: Processing container_1476452954783_0001_01_000009 of event FINISHED
2016-10-14 07:52:29,853 INFO org.apache.hadoop.yarn.server.resourcemanager.rmcontainer.RMContainerImpl: container_1476452954783_0001_01_000009 Container Transitioned from RUNNING to COMPLETED
2016-10-14 07:52:29,853 INFO org.apache.hadoop.yarn.server.resourcemanager.scheduler.fair.FSAppAttempt: Completed container: container_1476452954783_0001_01_000009 in state: COMPLETED event:FINISHED
2016-10-14 07:52:29,854 INFO org.apache.hadoop.yarn.server.resourcemanager.RMAuditLogger: USER=tanle	OPERATION=AM Released Container	TARGET=SchedulerApp	RESULT=SUCCESS	APPID=application_1476452954783_0001	CONTAINERID=container_1476452954783_0001_01_000009
2016-10-14 07:52:29,854 INFO org.apache.hadoop.yarn.server.resourcemanager.scheduler.SchedulerNode: Released container container_1476452954783_0001_01_000009 of capacity <memory:2048, vCores:1> on host cp-2.yarn-perf.yarnrm-PG0.wisc.cloudlab.us:43837, which currently has 3 containers, <memory:6144, vCores:3> used and <memory:2048, vCores:1> available, release resources=true
2016-10-14 07:52:29,854 INFO org.apache.hadoop.yarn.server.resourcemanager.scheduler.fair.FairScheduler: Application attempt appattempt_1476452954783_0001_000001 released container container_1476452954783_0001_01_000009 on node: host: cp-2.yarn-perf.yarnrm-PG0.wisc.cloudlab.us:43837 #containers=3 available=<memory:2048, vCores:1> used=<memory:6144, vCores:3> with event: FINISHED
2016-10-14 07:52:29,854 INFO org.apache.hadoop.yarn.server.resourcemanager.scheduler.fair.FSAppAttempt: assignContainer(FSSchedulerNode node:cp-2.yarn-perf.yarnrm-PG0.wisc.cloudlab.us, boolean reserved=true) for appattempt_1476452954783_0001_000001
2016-10-14 07:52:29,854 INFO org.apache.hadoop.yarn.server.resourcemanager.scheduler.fair.FSAppAttempt: allocate container: container_1476452954783_0001_01_000018 priority 1
2016-10-14 07:52:29,854 INFO org.apache.hadoop.yarn.server.resourcemanager.rmcontainer.RMContainerImpl: Processing container_1476452954783_0001_01_000018 of event START
2016-10-14 07:52:29,855 INFO org.apache.hadoop.yarn.server.resourcemanager.rmcontainer.RMContainerImpl: container_1476452954783_0001_01_000018 Container Transitioned from NEW to ALLOCATED
2016-10-14 07:52:29,855 INFO org.apache.hadoop.yarn.server.resourcemanager.RMAuditLogger: USER=tanle	OPERATION=AM Allocated Container	TARGET=SchedulerApp	RESULT=SUCCESS	APPID=application_1476452954783_0001	CONTAINERID=container_1476452954783_0001_01_000018
2016-10-14 07:52:29,855 INFO org.apache.hadoop.yarn.server.resourcemanager.scheduler.fair.FSAppAttempt: Application application_1476452954783_0001 unreserved  on node host: cp-2.yarn-perf.yarnrm-PG0.wisc.cloudlab.us:43837 #containers=3 available=<memory:2048, vCores:1> used=<memory:6144, vCores:3>, currently has 2 at priority 1; currentReservation <memory:4096, vCores:2>
2016-10-14 07:52:29,855 INFO org.apache.hadoop.yarn.server.resourcemanager.scheduler.SchedulerNode: Assigned container container_1476452954783_0001_01_000018 of capacity <memory:2048, vCores:1> on host cp-2.yarn-perf.yarnrm-PG0.wisc.cloudlab.us:43837, which has 4 containers, <memory:8192, vCores:4> used and <memory:0, vCores:0> available after allocation
2016-10-14 07:52:30,594 INFO org.apache.hadoop.yarn.server.resourcemanager.scheduler.fair.FairScheduler: allocate(appattempt_1476452954783_0001_000001 [] [] [] []
2016-10-14 07:52:30,595 INFO org.apache.hadoop.yarn.server.resourcemanager.scheduler.fair.FSAppAttempt: root.interactive0 getMinReq:<memory:24576, vCores:12> demand: <memory:260096, vCores:127> usage: <memory:22528, vCores:11>running true active: true isLeafQueue():true
2016-10-14 07:52:30,595 INFO org.apache.hadoop.yarn.server.resourcemanager.scheduler.fair.FSAppAttempt: root.batch0 getMinReq:<memory:0, vCores:0> demand: <memory:264192, vCores:129> usage: <memory:10240, vCores:5>running true active: true isLeafQueue():true
2016-10-14 07:52:30,595 INFO org.apache.hadoop.yarn.server.resourcemanager.scheduler.fair.FSAppAttempt: appattempt_1476452954783_0001_000001 minReqResource: <memory:24576, vCores:12> flexibleResource: <memory:8192, vCores:4>
2016-10-14 07:52:30,595 INFO org.apache.hadoop.yarn.server.resourcemanager.scheduler.fair.FairScheduler: [admission control] getFlexibleResource <memory:8192, vCores:4>
2016-10-14 07:52:30,595 INFO org.apache.hadoop.yarn.server.resourcemanager.scheduler.fair.FairScheduler: app appattempt_1476452954783_0001_000001 in queue root.interactive0 isRunning: true
2016-10-14 07:52:30,597 INFO org.apache.hadoop.yarn.server.resourcemanager.rmcontainer.RMContainerImpl: Processing container_1476452954783_0001_01_000018 of event ACQUIRED
2016-10-14 07:52:30,598 INFO org.apache.hadoop.yarn.server.resourcemanager.rmcontainer.RMContainerImpl: container_1476452954783_0001_01_000018 Container Transitioned from ALLOCATED to ACQUIRED
2016-10-14 07:52:30,661 INFO org.apache.hadoop.yarn.server.resourcemanager.scheduler.fair.FairScheduler: allocate(appattempt_1476452954783_0002_000001 [{Priority: 1, Capability: <memory:1920, vCores:1>, # Containers: 251, Location: *, Relax Locality: true}] [] [] []
2016-10-14 07:52:30,661 INFO org.apache.hadoop.yarn.server.resourcemanager.scheduler.fair.FSAppAttempt: root.interactive0 getMinReq:<memory:24576, vCores:12> demand: <memory:260096, vCores:127> usage: <memory:22528, vCores:11>running true active: true isLeafQueue():true
2016-10-14 07:52:30,661 INFO org.apache.hadoop.yarn.server.resourcemanager.scheduler.fair.FSAppAttempt: root.batch0 getMinReq:<memory:0, vCores:0> demand: <memory:264192, vCores:129> usage: <memory:10240, vCores:5>running true active: true isLeafQueue():true
2016-10-14 07:52:30,662 INFO org.apache.hadoop.yarn.server.resourcemanager.scheduler.fair.FSAppAttempt: appattempt_1476452954783_0002_000001 minReqResource: <memory:24576, vCores:12> flexibleResource: <memory:8192, vCores:4>
2016-10-14 07:52:30,662 INFO org.apache.hadoop.yarn.server.resourcemanager.scheduler.fair.FairScheduler: [admission control] getFlexibleResource <memory:8192, vCores:4>
2016-10-14 07:52:30,669 INFO org.apache.hadoop.yarn.server.resourcemanager.rmapp.attempt.RMAppAttemptImpl: ScheduleTransition.transition(appattempt_1476452954783_0004_000001,EventType: ATTEMPT_ADDED)
2016-10-14 07:52:30,669 INFO org.apache.hadoop.yarn.server.resourcemanager.scheduler.fair.FairScheduler: allocate(appattempt_1476452954783_0004_000001 [{Priority: 0, Capability: <memory:2048, vCores:1>, # Containers: 1, Location: *, Relax Locality: true}] [] null null
2016-10-14 07:52:30,670 INFO org.apache.hadoop.yarn.server.resourcemanager.scheduler.fair.FSAppAttempt: root.interactive0 getMinReq:<memory:24576, vCores:12> demand: <memory:260096, vCores:127> usage: <memory:22528, vCores:11>running true active: true isLeafQueue():true
2016-10-14 07:52:30,670 INFO org.apache.hadoop.yarn.server.resourcemanager.scheduler.fair.FSAppAttempt: root.batch0 getMinReq:<memory:0, vCores:0> demand: <memory:264192, vCores:129> usage: <memory:10240, vCores:5>running true active: true isLeafQueue():true
2016-10-14 07:52:30,670 INFO org.apache.hadoop.yarn.server.resourcemanager.scheduler.fair.FSAppAttempt: appattempt_1476452954783_0004_000001 minReqResource: <memory:24576, vCores:12> flexibleResource: <memory:8192, vCores:4>
2016-10-14 07:52:30,670 INFO org.apache.hadoop.yarn.server.resourcemanager.scheduler.fair.FairScheduler: [admission control] getFlexibleResource <memory:8192, vCores:4>
2016-10-14 07:52:30,670 INFO org.apache.hadoop.yarn.server.resourcemanager.scheduler.fair.FairScheduler: app appattempt_1476452954783_0004_000001 in queue root.interactive1 isRunning: false
2016-10-14 07:52:30,670 INFO org.apache.hadoop.yarn.server.resourcemanager.scheduler.fair.FairScheduler: [admission control] Cannot allocate appattempt_1476452954783_0004_000001 because there is NO flexible resource left
2016-10-14 07:52:30,856 INFO org.apache.hadoop.yarn.server.resourcemanager.rmcontainer.RMContainerImpl: Processing container_1476452954783_0001_01_000018 of event LAUNCHED
2016-10-14 07:52:30,856 INFO org.apache.hadoop.yarn.server.resourcemanager.rmcontainer.RMContainerImpl: container_1476452954783_0001_01_000018 Container Transitioned from ACQUIRED to RUNNING
2016-10-14 07:52:30,857 INFO org.apache.hadoop.yarn.server.resourcemanager.scheduler.fair.FSAppAttempt: assignContainer(FSSchedulerNode node:cp-2.yarn-perf.yarnrm-PG0.wisc.cloudlab.us, boolean reserved=false) for appattempt_1476452954783_0004_000001
2016-10-14 07:52:30,857 INFO org.apache.hadoop.yarn.server.resourcemanager.scheduler.fair.FSAppAttempt: assignContainer(FSSchedulerNode node:cp-2.yarn-perf.yarnrm-PG0.wisc.cloudlab.us, boolean reserved=false) for appattempt_1476452954783_0001_000001
2016-10-14 07:52:30,858 INFO org.apache.hadoop.yarn.server.resourcemanager.scheduler.fair.FSAppAttempt: Making reservation: node=cp-2.yarn-perf.yarnrm-PG0.wisc.cloudlab.us app_id=application_1476452954783_0001
2016-10-14 07:52:30,858 INFO org.apache.hadoop.yarn.server.resourcemanager.rmcontainer.RMContainerImpl: Processing container_1476452954783_0001_01_000019 of event RESERVED
2016-10-14 07:52:30,858 INFO org.apache.hadoop.yarn.server.resourcemanager.rmcontainer.RMContainerImpl: container_1476452954783_0001_01_000019 Container Transitioned from NEW to RESERVED
2016-10-14 07:52:30,858 INFO org.apache.hadoop.yarn.server.resourcemanager.scheduler.fair.FSSchedulerNode: Reserved container container_1476452954783_0001_01_000019 on node host: cp-2.yarn-perf.yarnrm-PG0.wisc.cloudlab.us:43837 #containers=4 available=<memory:0, vCores:0> used=<memory:8192, vCores:4> for application org.apache.hadoop.yarn.server.resourcemanager.scheduler.fair.FSAppAttempt@13f22e88
2016-10-14 07:52:30,865 INFO org.apache.hadoop.yarn.server.resourcemanager.scheduler.fair.FairScheduler: allocate(appattempt_1476452954783_0002_000001 [] [] [] []
2016-10-14 07:52:30,865 INFO org.apache.hadoop.yarn.server.resourcemanager.scheduler.fair.FSAppAttempt: root.interactive0 getMinReq:<memory:24576, vCores:12> demand: <memory:260096, vCores:127> usage: <memory:22528, vCores:11>running true active: true isLeafQueue():true
2016-10-14 07:52:30,865 INFO org.apache.hadoop.yarn.server.resourcemanager.scheduler.fair.FSAppAttempt: root.batch0 getMinReq:<memory:0, vCores:0> demand: <memory:264192, vCores:129> usage: <memory:10240, vCores:5>running true active: true isLeafQueue():true
2016-10-14 07:52:30,866 INFO org.apache.hadoop.yarn.server.resourcemanager.scheduler.fair.FSAppAttempt: appattempt_1476452954783_0002_000001 minReqResource: <memory:24576, vCores:12> flexibleResource: <memory:8192, vCores:4>
2016-10-14 07:52:30,866 INFO org.apache.hadoop.yarn.server.resourcemanager.scheduler.fair.FairScheduler: [admission control] getFlexibleResource <memory:8192, vCores:4>
2016-10-14 07:52:31,165 INFO org.apache.hadoop.yarn.server.resourcemanager.scheduler.fair.FairScheduler: allocate(appattempt_1476452954783_0001_000001 [{Priority: 1, Capability: <memory:1920, vCores:1>, # Containers: 117, Location: *, Relax Locality: true}] [] [] []
2016-10-14 07:52:31,165 INFO org.apache.hadoop.yarn.server.resourcemanager.scheduler.fair.FSAppAttempt: root.interactive0 getMinReq:<memory:24576, vCores:12> demand: <memory:260096, vCores:127> usage: <memory:22528, vCores:11>running true active: true isLeafQueue():true
2016-10-14 07:52:31,165 INFO org.apache.hadoop.yarn.server.resourcemanager.scheduler.fair.FSAppAttempt: root.batch0 getMinReq:<memory:0, vCores:0> demand: <memory:526336, vCores:257> usage: <memory:10240, vCores:5>running true active: true isLeafQueue():true
2016-10-14 07:52:31,165 INFO org.apache.hadoop.yarn.server.resourcemanager.scheduler.fair.FSAppAttempt: appattempt_1476452954783_0001_000001 minReqResource: <memory:24576, vCores:12> flexibleResource: <memory:8192, vCores:4>
2016-10-14 07:52:31,165 INFO org.apache.hadoop.yarn.server.resourcemanager.scheduler.fair.FairScheduler: [admission control] getFlexibleResource <memory:8192, vCores:4>
2016-10-14 07:52:31,165 INFO org.apache.hadoop.yarn.server.resourcemanager.scheduler.fair.FairScheduler: app appattempt_1476452954783_0001_000001 in queue root.interactive0 isRunning: true
2016-10-14 07:52:31,269 INFO org.apache.hadoop.yarn.server.resourcemanager.scheduler.fair.FairScheduler: allocate(appattempt_1476452954783_0002_000001 [] [] [] []
2016-10-14 07:52:31,270 INFO org.apache.hadoop.yarn.server.resourcemanager.scheduler.fair.FSAppAttempt: root.interactive0 getMinReq:<memory:24576, vCores:12> demand: <memory:260096, vCores:127> usage: <memory:22528, vCores:11>running true active: true isLeafQueue():true
2016-10-14 07:52:31,270 INFO org.apache.hadoop.yarn.server.resourcemanager.scheduler.fair.FSAppAttempt: root.batch0 getMinReq:<memory:0, vCores:0> demand: <memory:526336, vCores:257> usage: <memory:10240, vCores:5>running true active: true isLeafQueue():true
2016-10-14 07:52:31,270 INFO org.apache.hadoop.yarn.server.resourcemanager.scheduler.fair.FSAppAttempt: appattempt_1476452954783_0002_000001 minReqResource: <memory:24576, vCores:12> flexibleResource: <memory:8192, vCores:4>
2016-10-14 07:52:31,270 INFO org.apache.hadoop.yarn.server.resourcemanager.scheduler.fair.FairScheduler: [admission control] getFlexibleResource <memory:8192, vCores:4>
2016-10-14 07:52:31,369 INFO org.apache.hadoop.yarn.server.resourcemanager.scheduler.fair.FairScheduler: allocate(appattempt_1476452954783_0001_000001 [] [] [] []
2016-10-14 07:52:31,369 INFO org.apache.hadoop.yarn.server.resourcemanager.scheduler.fair.FSAppAttempt: root.interactive0 getMinReq:<memory:24576, vCores:12> demand: <memory:260096, vCores:127> usage: <memory:22528, vCores:11>running true active: true isLeafQueue():true
2016-10-14 07:52:31,369 INFO org.apache.hadoop.yarn.server.resourcemanager.scheduler.fair.FSAppAttempt: root.batch0 getMinReq:<memory:0, vCores:0> demand: <memory:526336, vCores:257> usage: <memory:10240, vCores:5>running true active: true isLeafQueue():true
2016-10-14 07:52:31,369 INFO org.apache.hadoop.yarn.server.resourcemanager.scheduler.fair.FSAppAttempt: appattempt_1476452954783_0001_000001 minReqResource: <memory:24576, vCores:12> flexibleResource: <memory:8192, vCores:4>
2016-10-14 07:52:31,369 INFO org.apache.hadoop.yarn.server.resourcemanager.scheduler.fair.FairScheduler: [admission control] getFlexibleResource <memory:8192, vCores:4>
2016-10-14 07:52:31,369 INFO org.apache.hadoop.yarn.server.resourcemanager.scheduler.fair.FairScheduler: app appattempt_1476452954783_0001_000001 in queue root.interactive0 isRunning: true
2016-10-14 07:52:31,656 INFO org.apache.hadoop.yarn.server.resourcemanager.scheduler.fair.FairScheduler: allocate(appattempt_1476452954783_0001_000001 [{Priority: 1, Capability: <memory:1920, vCores:1>, # Containers: 245, Location: *, Relax Locality: true}] [] [] []
2016-10-14 07:52:31,656 INFO org.apache.hadoop.yarn.server.resourcemanager.scheduler.fair.FSAppAttempt: root.interactive0 getMinReq:<memory:24576, vCores:12> demand: <memory:262144, vCores:128> usage: <memory:22528, vCores:11>running true active: true isLeafQueue():true
2016-10-14 07:52:31,656 INFO org.apache.hadoop.yarn.server.resourcemanager.scheduler.fair.FSAppAttempt: root.batch0 getMinReq:<memory:0, vCores:0> demand: <memory:526336, vCores:257> usage: <memory:10240, vCores:5>running true active: true isLeafQueue():true
2016-10-14 07:52:31,656 INFO org.apache.hadoop.yarn.server.resourcemanager.scheduler.fair.FSAppAttempt: appattempt_1476452954783_0001_000001 minReqResource: <memory:24576, vCores:12> flexibleResource: <memory:8192, vCores:4>
2016-10-14 07:52:31,656 INFO org.apache.hadoop.yarn.server.resourcemanager.scheduler.fair.FairScheduler: [admission control] getFlexibleResource <memory:8192, vCores:4>
2016-10-14 07:52:31,656 INFO org.apache.hadoop.yarn.server.resourcemanager.scheduler.fair.FairScheduler: app appattempt_1476452954783_0001_000001 in queue root.interactive0 isRunning: true
2016-10-14 07:52:31,671 INFO org.apache.hadoop.yarn.server.resourcemanager.rmapp.attempt.RMAppAttemptImpl: ScheduleTransition.transition(appattempt_1476452954783_0004_000001,EventType: ATTEMPT_ADDED)
2016-10-14 07:52:31,671 INFO org.apache.hadoop.yarn.server.resourcemanager.scheduler.fair.FairScheduler: allocate(appattempt_1476452954783_0004_000001 [{Priority: 0, Capability: <memory:2048, vCores:1>, # Containers: 1, Location: *, Relax Locality: true}] [] null null
2016-10-14 07:52:31,671 INFO org.apache.hadoop.yarn.server.resourcemanager.scheduler.fair.FSAppAttempt: root.interactive0 getMinReq:<memory:24576, vCores:12> demand: <memory:262144, vCores:128> usage: <memory:22528, vCores:11>running true active: true isLeafQueue():true
2016-10-14 07:52:31,671 INFO org.apache.hadoop.yarn.server.resourcemanager.scheduler.fair.FSAppAttempt: root.batch0 getMinReq:<memory:0, vCores:0> demand: <memory:526336, vCores:257> usage: <memory:10240, vCores:5>running true active: true isLeafQueue():true
2016-10-14 07:52:31,671 INFO org.apache.hadoop.yarn.server.resourcemanager.scheduler.fair.FSAppAttempt: appattempt_1476452954783_0004_000001 minReqResource: <memory:24576, vCores:12> flexibleResource: <memory:8192, vCores:4>
2016-10-14 07:52:31,671 INFO org.apache.hadoop.yarn.server.resourcemanager.scheduler.fair.FairScheduler: [admission control] getFlexibleResource <memory:8192, vCores:4>
2016-10-14 07:52:31,671 INFO org.apache.hadoop.yarn.server.resourcemanager.scheduler.fair.FairScheduler: app appattempt_1476452954783_0004_000001 in queue root.interactive1 isRunning: false
2016-10-14 07:52:31,671 INFO org.apache.hadoop.yarn.server.resourcemanager.scheduler.fair.FairScheduler: [admission control] Cannot allocate appattempt_1476452954783_0004_000001 because there is NO flexible resource left
2016-10-14 07:52:31,859 INFO org.apache.hadoop.yarn.server.resourcemanager.rmcontainer.RMContainerImpl: Processing container_1476452954783_0001_01_000016 of event FINISHED
2016-10-14 07:52:31,860 INFO org.apache.hadoop.yarn.server.resourcemanager.rmcontainer.RMContainerImpl: container_1476452954783_0001_01_000016 Container Transitioned from RUNNING to COMPLETED
2016-10-14 07:52:31,860 INFO org.apache.hadoop.yarn.server.resourcemanager.scheduler.fair.FSAppAttempt: Completed container: container_1476452954783_0001_01_000016 in state: COMPLETED event:FINISHED
2016-10-14 07:52:31,860 INFO org.apache.hadoop.yarn.server.resourcemanager.RMAuditLogger: USER=tanle	OPERATION=AM Released Container	TARGET=SchedulerApp	RESULT=SUCCESS	APPID=application_1476452954783_0001	CONTAINERID=container_1476452954783_0001_01_000016
2016-10-14 07:52:31,860 INFO org.apache.hadoop.yarn.server.resourcemanager.scheduler.fair.FairScheduler: allocate(appattempt_1476452954783_0001_000001 [] [] [] []
2016-10-14 07:52:31,860 INFO org.apache.hadoop.yarn.server.resourcemanager.scheduler.SchedulerNode: Released container container_1476452954783_0001_01_000016 of capacity <memory:2048, vCores:1> on host cp-2.yarn-perf.yarnrm-PG0.wisc.cloudlab.us:43837, which currently has 3 containers, <memory:6144, vCores:3> used and <memory:2048, vCores:1> available, release resources=true
2016-10-14 07:52:31,860 INFO org.apache.hadoop.yarn.server.resourcemanager.scheduler.fair.FSAppAttempt: root.interactive0 getMinReq:<memory:24576, vCores:12> demand: <memory:262144, vCores:128> usage: <memory:20480, vCores:10>running true active: true isLeafQueue():true
2016-10-14 07:52:31,860 INFO org.apache.hadoop.yarn.server.resourcemanager.scheduler.fair.FSAppAttempt: root.batch0 getMinReq:<memory:0, vCores:0> demand: <memory:526336, vCores:257> usage: <memory:10240, vCores:5>running true active: true isLeafQueue():true
2016-10-14 07:52:31,860 INFO org.apache.hadoop.yarn.server.resourcemanager.scheduler.fair.FairScheduler: Application attempt appattempt_1476452954783_0001_000001 released container container_1476452954783_0001_01_000016 on node: host: cp-2.yarn-perf.yarnrm-PG0.wisc.cloudlab.us:43837 #containers=3 available=<memory:2048, vCores:1> used=<memory:6144, vCores:3> with event: FINISHED
2016-10-14 07:52:31,860 INFO org.apache.hadoop.yarn.server.resourcemanager.scheduler.fair.FSAppAttempt: appattempt_1476452954783_0001_000001 minReqResource: <memory:24576, vCores:12> flexibleResource: <memory:8192, vCores:4>
2016-10-14 07:52:31,860 INFO org.apache.hadoop.yarn.server.resourcemanager.scheduler.fair.FairScheduler: [admission control] getFlexibleResource <memory:8192, vCores:4>
2016-10-14 07:52:31,861 INFO org.apache.hadoop.yarn.server.resourcemanager.scheduler.fair.FairScheduler: app appattempt_1476452954783_0001_000001 in queue root.interactive0 isRunning: true
2016-10-14 07:52:31,861 INFO org.apache.hadoop.yarn.server.resourcemanager.scheduler.fair.FSAppAttempt: assignContainer(FSSchedulerNode node:cp-2.yarn-perf.yarnrm-PG0.wisc.cloudlab.us, boolean reserved=true) for appattempt_1476452954783_0001_000001
2016-10-14 07:52:31,861 INFO org.apache.hadoop.yarn.server.resourcemanager.scheduler.fair.FSAppAttempt: allocate container: container_1476452954783_0001_01_000019 priority 1
2016-10-14 07:52:31,861 INFO org.apache.hadoop.yarn.server.resourcemanager.rmcontainer.RMContainerImpl: Processing container_1476452954783_0001_01_000019 of event START
2016-10-14 07:52:31,861 INFO org.apache.hadoop.yarn.server.resourcemanager.rmcontainer.RMContainerImpl: container_1476452954783_0001_01_000019 Container Transitioned from NEW to ALLOCATED
2016-10-14 07:52:31,861 INFO org.apache.hadoop.yarn.server.resourcemanager.RMAuditLogger: USER=tanle	OPERATION=AM Allocated Container	TARGET=SchedulerApp	RESULT=SUCCESS	APPID=application_1476452954783_0001	CONTAINERID=container_1476452954783_0001_01_000019
2016-10-14 07:52:31,861 INFO org.apache.hadoop.yarn.server.resourcemanager.scheduler.fair.FSAppAttempt: Application application_1476452954783_0001 unreserved  on node host: cp-2.yarn-perf.yarnrm-PG0.wisc.cloudlab.us:43837 #containers=3 available=<memory:2048, vCores:1> used=<memory:6144, vCores:3>, currently has 2 at priority 1; currentReservation <memory:4096, vCores:2>
2016-10-14 07:52:31,862 INFO org.apache.hadoop.yarn.server.resourcemanager.scheduler.SchedulerNode: Assigned container container_1476452954783_0001_01_000019 of capacity <memory:2048, vCores:1> on host cp-2.yarn-perf.yarnrm-PG0.wisc.cloudlab.us:43837, which has 4 containers, <memory:8192, vCores:4> used and <memory:0, vCores:0> available after allocation
2016-10-14 07:52:32,073 INFO org.apache.hadoop.yarn.server.resourcemanager.scheduler.fair.FairScheduler: allocate(appattempt_1476452954783_0002_000001 [] [] [] []
2016-10-14 07:52:32,074 INFO org.apache.hadoop.yarn.server.resourcemanager.scheduler.fair.FSAppAttempt: root.interactive0 getMinReq:<memory:24576, vCores:12> demand: <memory:522240, vCores:255> usage: <memory:22528, vCores:11>running true active: true isLeafQueue():true
2016-10-14 07:52:32,074 INFO org.apache.hadoop.yarn.server.resourcemanager.scheduler.fair.FSAppAttempt: root.batch0 getMinReq:<memory:0, vCores:0> demand: <memory:526336, vCores:257> usage: <memory:10240, vCores:5>running true active: true isLeafQueue():true
2016-10-14 07:52:32,074 INFO org.apache.hadoop.yarn.server.resourcemanager.scheduler.fair.FSAppAttempt: appattempt_1476452954783_0002_000001 minReqResource: <memory:24576, vCores:12> flexibleResource: <memory:8192, vCores:4>
2016-10-14 07:52:32,074 INFO org.apache.hadoop.yarn.server.resourcemanager.scheduler.fair.FairScheduler: [admission control] getFlexibleResource <memory:8192, vCores:4>
2016-10-14 07:52:32,266 INFO org.apache.hadoop.yarn.server.resourcemanager.scheduler.fair.FairScheduler: allocate(appattempt_1476452954783_0001_000001 [{Priority: 1, Capability: <memory:1920, vCores:1>, # Containers: 246, Location: *, Relax Locality: true}] [] [] []
2016-10-14 07:52:32,266 INFO org.apache.hadoop.yarn.server.resourcemanager.scheduler.fair.FSAppAttempt: root.interactive0 getMinReq:<memory:24576, vCores:12> demand: <memory:522240, vCores:255> usage: <memory:22528, vCores:11>running true active: true isLeafQueue():true
2016-10-14 07:52:32,266 INFO org.apache.hadoop.yarn.server.resourcemanager.scheduler.fair.FSAppAttempt: root.batch0 getMinReq:<memory:0, vCores:0> demand: <memory:526336, vCores:257> usage: <memory:10240, vCores:5>running true active: true isLeafQueue():true
2016-10-14 07:52:32,267 INFO org.apache.hadoop.yarn.server.resourcemanager.scheduler.fair.FSAppAttempt: appattempt_1476452954783_0001_000001 minReqResource: <memory:24576, vCores:12> flexibleResource: <memory:8192, vCores:4>
2016-10-14 07:52:32,267 INFO org.apache.hadoop.yarn.server.resourcemanager.scheduler.fair.FairScheduler: [admission control] getFlexibleResource <memory:8192, vCores:4>
2016-10-14 07:52:32,267 INFO org.apache.hadoop.yarn.server.resourcemanager.scheduler.fair.FairScheduler: app appattempt_1476452954783_0001_000001 in queue root.interactive0 isRunning: true
2016-10-14 07:52:32,269 INFO org.apache.hadoop.yarn.server.resourcemanager.rmcontainer.RMContainerImpl: Processing container_1476452954783_0001_01_000019 of event ACQUIRED
2016-10-14 07:52:32,270 INFO org.apache.hadoop.yarn.server.resourcemanager.rmcontainer.RMContainerImpl: container_1476452954783_0001_01_000019 Container Transitioned from ALLOCATED to ACQUIRED
2016-10-14 07:52:32,672 INFO org.apache.hadoop.yarn.server.resourcemanager.rmapp.attempt.RMAppAttemptImpl: ScheduleTransition.transition(appattempt_1476452954783_0004_000001,EventType: ATTEMPT_ADDED)
2016-10-14 07:52:32,673 INFO org.apache.hadoop.yarn.server.resourcemanager.scheduler.fair.FairScheduler: allocate(appattempt_1476452954783_0004_000001 [{Priority: 0, Capability: <memory:2048, vCores:1>, # Containers: 1, Location: *, Relax Locality: true}] [] null null
2016-10-14 07:52:32,673 INFO org.apache.hadoop.yarn.server.resourcemanager.scheduler.fair.FSAppAttempt: root.interactive0 getMinReq:<memory:24576, vCores:12> demand: <memory:526336, vCores:257> usage: <memory:22528, vCores:11>running true active: true isLeafQueue():true
2016-10-14 07:52:32,673 INFO org.apache.hadoop.yarn.server.resourcemanager.scheduler.fair.FSAppAttempt: root.batch0 getMinReq:<memory:0, vCores:0> demand: <memory:526336, vCores:257> usage: <memory:10240, vCores:5>running true active: true isLeafQueue():true
2016-10-14 07:52:32,673 INFO org.apache.hadoop.yarn.server.resourcemanager.scheduler.fair.FSAppAttempt: appattempt_1476452954783_0004_000001 minReqResource: <memory:24576, vCores:12> flexibleResource: <memory:8192, vCores:4>
2016-10-14 07:52:32,673 INFO org.apache.hadoop.yarn.server.resourcemanager.scheduler.fair.FairScheduler: [admission control] getFlexibleResource <memory:8192, vCores:4>
2016-10-14 07:52:32,673 INFO org.apache.hadoop.yarn.server.resourcemanager.scheduler.fair.FairScheduler: app appattempt_1476452954783_0004_000001 in queue root.interactive1 isRunning: false
2016-10-14 07:52:32,673 INFO org.apache.hadoop.yarn.server.resourcemanager.scheduler.fair.FairScheduler: [admission control] Cannot allocate appattempt_1476452954783_0004_000001 because there is NO flexible resource left
2016-10-14 07:52:32,863 INFO org.apache.hadoop.yarn.server.resourcemanager.rmcontainer.RMContainerImpl: Processing container_1476452954783_0001_01_000019 of event LAUNCHED
2016-10-14 07:52:32,863 INFO org.apache.hadoop.yarn.server.resourcemanager.rmcontainer.RMContainerImpl: container_1476452954783_0001_01_000019 Container Transitioned from ACQUIRED to RUNNING
2016-10-14 07:52:32,864 INFO org.apache.hadoop.yarn.server.resourcemanager.scheduler.fair.FSAppAttempt: assignContainer(FSSchedulerNode node:cp-2.yarn-perf.yarnrm-PG0.wisc.cloudlab.us, boolean reserved=false) for appattempt_1476452954783_0004_000001
2016-10-14 07:52:32,864 INFO org.apache.hadoop.yarn.server.resourcemanager.scheduler.fair.FSAppAttempt: assignContainer(FSSchedulerNode node:cp-2.yarn-perf.yarnrm-PG0.wisc.cloudlab.us, boolean reserved=false) for appattempt_1476452954783_0001_000001
2016-10-14 07:52:32,865 INFO org.apache.hadoop.yarn.server.resourcemanager.scheduler.fair.FSAppAttempt: Making reservation: node=cp-2.yarn-perf.yarnrm-PG0.wisc.cloudlab.us app_id=application_1476452954783_0001
2016-10-14 07:52:32,865 INFO org.apache.hadoop.yarn.server.resourcemanager.rmcontainer.RMContainerImpl: Processing container_1476452954783_0001_01_000020 of event RESERVED
2016-10-14 07:52:32,865 INFO org.apache.hadoop.yarn.server.resourcemanager.rmcontainer.RMContainerImpl: container_1476452954783_0001_01_000020 Container Transitioned from NEW to RESERVED
2016-10-14 07:52:32,865 INFO org.apache.hadoop.yarn.server.resourcemanager.scheduler.fair.FSSchedulerNode: Reserved container container_1476452954783_0001_01_000020 on node host: cp-2.yarn-perf.yarnrm-PG0.wisc.cloudlab.us:43837 #containers=4 available=<memory:0, vCores:0> used=<memory:8192, vCores:4> for application org.apache.hadoop.yarn.server.resourcemanager.scheduler.fair.FSAppAttempt@13f22e88
2016-10-14 07:52:33,075 INFO org.apache.hadoop.yarn.server.resourcemanager.scheduler.fair.FairScheduler: allocate(appattempt_1476452954783_0001_000001 [{Priority: 1, Capability: <memory:1920, vCores:1>, # Containers: 245, Location: *, Relax Locality: true}] [] [] []
2016-10-14 07:52:33,075 INFO org.apache.hadoop.yarn.server.resourcemanager.scheduler.fair.FSAppAttempt: root.interactive0 getMinReq:<memory:24576, vCores:12> demand: <memory:526336, vCores:257> usage: <memory:22528, vCores:11>running true active: true isLeafQueue():true
2016-10-14 07:52:33,075 INFO org.apache.hadoop.yarn.server.resourcemanager.scheduler.fair.FSAppAttempt: root.batch0 getMinReq:<memory:0, vCores:0> demand: <memory:526336, vCores:257> usage: <memory:10240, vCores:5>running true active: true isLeafQueue():true
2016-10-14 07:52:33,075 INFO org.apache.hadoop.yarn.server.resourcemanager.scheduler.fair.FSAppAttempt: appattempt_1476452954783_0001_000001 minReqResource: <memory:24576, vCores:12> flexibleResource: <memory:8192, vCores:4>
2016-10-14 07:52:33,075 INFO org.apache.hadoop.yarn.server.resourcemanager.scheduler.fair.FairScheduler: [admission control] getFlexibleResource <memory:8192, vCores:4>
2016-10-14 07:52:33,076 INFO org.apache.hadoop.yarn.server.resourcemanager.scheduler.fair.FairScheduler: app appattempt_1476452954783_0001_000001 in queue root.interactive0 isRunning: true
2016-10-14 07:52:33,674 INFO org.apache.hadoop.yarn.server.resourcemanager.rmapp.attempt.RMAppAttemptImpl: ScheduleTransition.transition(appattempt_1476452954783_0004_000001,EventType: ATTEMPT_ADDED)
2016-10-14 07:52:33,674 INFO org.apache.hadoop.yarn.server.resourcemanager.scheduler.fair.FairScheduler: allocate(appattempt_1476452954783_0004_000001 [{Priority: 0, Capability: <memory:2048, vCores:1>, # Containers: 1, Location: *, Relax Locality: true}] [] null null
2016-10-14 07:52:33,674 INFO org.apache.hadoop.yarn.server.resourcemanager.scheduler.fair.FSAppAttempt: root.interactive0 getMinReq:<memory:24576, vCores:12> demand: <memory:524288, vCores:256> usage: <memory:22528, vCores:11>running true active: true isLeafQueue():true
2016-10-14 07:52:33,675 INFO org.apache.hadoop.yarn.server.resourcemanager.scheduler.fair.FSAppAttempt: root.batch0 getMinReq:<memory:0, vCores:0> demand: <memory:526336, vCores:257> usage: <memory:10240, vCores:5>running true active: true isLeafQueue():true
2016-10-14 07:52:33,675 INFO org.apache.hadoop.yarn.server.resourcemanager.scheduler.fair.FSAppAttempt: appattempt_1476452954783_0004_000001 minReqResource: <memory:24576, vCores:12> flexibleResource: <memory:8192, vCores:4>
2016-10-14 07:52:33,675 INFO org.apache.hadoop.yarn.server.resourcemanager.scheduler.fair.FairScheduler: [admission control] getFlexibleResource <memory:8192, vCores:4>
2016-10-14 07:52:33,675 INFO org.apache.hadoop.yarn.server.resourcemanager.scheduler.fair.FairScheduler: app appattempt_1476452954783_0004_000001 in queue root.interactive1 isRunning: false
2016-10-14 07:52:33,675 INFO org.apache.hadoop.yarn.server.resourcemanager.scheduler.fair.FairScheduler: [admission control] Cannot allocate appattempt_1476452954783_0004_000001 because there is NO flexible resource left
2016-10-14 07:52:33,678 INFO org.apache.hadoop.yarn.server.resourcemanager.scheduler.fair.FairScheduler: allocate(appattempt_1476452954783_0002_000001 [] [] [] []
2016-10-14 07:52:33,678 INFO org.apache.hadoop.yarn.server.resourcemanager.scheduler.fair.FSAppAttempt: root.interactive0 getMinReq:<memory:24576, vCores:12> demand: <memory:524288, vCores:256> usage: <memory:22528, vCores:11>running true active: true isLeafQueue():true
2016-10-14 07:52:33,678 INFO org.apache.hadoop.yarn.server.resourcemanager.scheduler.fair.FSAppAttempt: root.batch0 getMinReq:<memory:0, vCores:0> demand: <memory:526336, vCores:257> usage: <memory:10240, vCores:5>running true active: true isLeafQueue():true
2016-10-14 07:52:33,678 INFO org.apache.hadoop.yarn.server.resourcemanager.scheduler.fair.FSAppAttempt: appattempt_1476452954783_0002_000001 minReqResource: <memory:24576, vCores:12> flexibleResource: <memory:8192, vCores:4>
2016-10-14 07:52:33,678 INFO org.apache.hadoop.yarn.server.resourcemanager.scheduler.fair.FairScheduler: [admission control] getFlexibleResource <memory:8192, vCores:4>
2016-10-14 07:52:34,676 INFO org.apache.hadoop.yarn.server.resourcemanager.rmapp.attempt.RMAppAttemptImpl: ScheduleTransition.transition(appattempt_1476452954783_0004_000001,EventType: ATTEMPT_ADDED)
2016-10-14 07:52:34,676 INFO org.apache.hadoop.yarn.server.resourcemanager.scheduler.fair.FairScheduler: allocate(appattempt_1476452954783_0004_000001 [{Priority: 0, Capability: <memory:2048, vCores:1>, # Containers: 1, Location: *, Relax Locality: true}] [] null null
2016-10-14 07:52:34,676 INFO org.apache.hadoop.yarn.server.resourcemanager.scheduler.fair.FSAppAttempt: root.interactive0 getMinReq:<memory:24576, vCores:12> demand: <memory:524288, vCores:256> usage: <memory:22528, vCores:11>running true active: true isLeafQueue():true
2016-10-14 07:52:34,676 INFO org.apache.hadoop.yarn.server.resourcemanager.scheduler.fair.FSAppAttempt: root.batch0 getMinReq:<memory:0, vCores:0> demand: <memory:526336, vCores:257> usage: <memory:10240, vCores:5>running true active: true isLeafQueue():true
2016-10-14 07:52:34,676 INFO org.apache.hadoop.yarn.server.resourcemanager.scheduler.fair.FSAppAttempt: appattempt_1476452954783_0004_000001 minReqResource: <memory:24576, vCores:12> flexibleResource: <memory:8192, vCores:4>
2016-10-14 07:52:34,676 INFO org.apache.hadoop.yarn.server.resourcemanager.scheduler.fair.FairScheduler: [admission control] getFlexibleResource <memory:8192, vCores:4>
2016-10-14 07:52:34,677 INFO org.apache.hadoop.yarn.server.resourcemanager.scheduler.fair.FairScheduler: app appattempt_1476452954783_0004_000001 in queue root.interactive1 isRunning: false
2016-10-14 07:52:34,677 INFO org.apache.hadoop.yarn.server.resourcemanager.scheduler.fair.FairScheduler: [admission control] Cannot allocate appattempt_1476452954783_0004_000001 because there is NO flexible resource left
2016-10-14 07:52:34,679 INFO org.apache.hadoop.yarn.server.resourcemanager.scheduler.fair.FairScheduler: allocate(appattempt_1476452954783_0001_000001 [] [] [] []
2016-10-14 07:52:34,679 INFO org.apache.hadoop.yarn.server.resourcemanager.scheduler.fair.FSAppAttempt: root.interactive0 getMinReq:<memory:24576, vCores:12> demand: <memory:524288, vCores:256> usage: <memory:22528, vCores:11>running true active: true isLeafQueue():true
2016-10-14 07:52:34,679 INFO org.apache.hadoop.yarn.server.resourcemanager.scheduler.fair.FSAppAttempt: root.batch0 getMinReq:<memory:0, vCores:0> demand: <memory:526336, vCores:257> usage: <memory:10240, vCores:5>running true active: true isLeafQueue():true
2016-10-14 07:52:34,679 INFO org.apache.hadoop.yarn.server.resourcemanager.scheduler.fair.FSAppAttempt: appattempt_1476452954783_0001_000001 minReqResource: <memory:24576, vCores:12> flexibleResource: <memory:8192, vCores:4>
2016-10-14 07:52:34,680 INFO org.apache.hadoop.yarn.server.resourcemanager.scheduler.fair.FairScheduler: [admission control] getFlexibleResource <memory:8192, vCores:4>
2016-10-14 07:52:34,680 INFO org.apache.hadoop.yarn.server.resourcemanager.scheduler.fair.FairScheduler: app appattempt_1476452954783_0001_000001 in queue root.interactive0 isRunning: true
2016-10-14 07:52:34,899 INFO org.apache.hadoop.yarn.server.resourcemanager.scheduler.fair.FairScheduler: allocate(appattempt_1476452954783_0001_000001 [] [] [] []
2016-10-14 07:52:34,899 INFO org.apache.hadoop.yarn.server.resourcemanager.scheduler.fair.FSAppAttempt: root.interactive0 getMinReq:<memory:24576, vCores:12> demand: <memory:524288, vCores:256> usage: <memory:22528, vCores:11>running true active: true isLeafQueue():true
2016-10-14 07:52:34,899 INFO org.apache.hadoop.yarn.server.resourcemanager.scheduler.fair.FSAppAttempt: root.batch0 getMinReq:<memory:0, vCores:0> demand: <memory:526336, vCores:257> usage: <memory:10240, vCores:5>running true active: true isLeafQueue():true
2016-10-14 07:52:34,899 INFO org.apache.hadoop.yarn.server.resourcemanager.scheduler.fair.FSAppAttempt: appattempt_1476452954783_0001_000001 minReqResource: <memory:24576, vCores:12> flexibleResource: <memory:8192, vCores:4>
2016-10-14 07:52:34,899 INFO org.apache.hadoop.yarn.server.resourcemanager.scheduler.fair.FairScheduler: [admission control] getFlexibleResource <memory:8192, vCores:4>
2016-10-14 07:52:34,900 INFO org.apache.hadoop.yarn.server.resourcemanager.scheduler.fair.FairScheduler: app appattempt_1476452954783_0001_000001 in queue root.interactive0 isRunning: true
2016-10-14 07:52:35,104 INFO org.apache.hadoop.yarn.server.resourcemanager.scheduler.fair.FairScheduler: allocate(appattempt_1476452954783_0001_000001 [] [] [] []
2016-10-14 07:52:35,104 INFO org.apache.hadoop.yarn.server.resourcemanager.scheduler.fair.FSAppAttempt: root.interactive0 getMinReq:<memory:24576, vCores:12> demand: <memory:524288, vCores:256> usage: <memory:22528, vCores:11>running true active: true isLeafQueue():true
2016-10-14 07:52:35,104 INFO org.apache.hadoop.yarn.server.resourcemanager.scheduler.fair.FSAppAttempt: root.batch0 getMinReq:<memory:0, vCores:0> demand: <memory:526336, vCores:257> usage: <memory:10240, vCores:5>running true active: true isLeafQueue():true
2016-10-14 07:52:35,104 INFO org.apache.hadoop.yarn.server.resourcemanager.scheduler.fair.FSAppAttempt: appattempt_1476452954783_0001_000001 minReqResource: <memory:24576, vCores:12> flexibleResource: <memory:8192, vCores:4>
2016-10-14 07:52:35,104 INFO org.apache.hadoop.yarn.server.resourcemanager.scheduler.fair.FairScheduler: [admission control] getFlexibleResource <memory:8192, vCores:4>
2016-10-14 07:52:35,104 INFO org.apache.hadoop.yarn.server.resourcemanager.scheduler.fair.FairScheduler: app appattempt_1476452954783_0001_000001 in queue root.interactive0 isRunning: true
2016-10-14 07:52:35,508 INFO org.apache.hadoop.yarn.server.resourcemanager.scheduler.fair.FairScheduler: allocate(appattempt_1476452954783_0001_000001 [] [] [] []
2016-10-14 07:52:35,508 INFO org.apache.hadoop.yarn.server.resourcemanager.scheduler.fair.FSAppAttempt: root.interactive0 getMinReq:<memory:24576, vCores:12> demand: <memory:524288, vCores:256> usage: <memory:22528, vCores:11>running true active: true isLeafQueue():true
2016-10-14 07:52:35,508 INFO org.apache.hadoop.yarn.server.resourcemanager.scheduler.fair.FSAppAttempt: root.batch0 getMinReq:<memory:0, vCores:0> demand: <memory:526336, vCores:257> usage: <memory:10240, vCores:5>running true active: true isLeafQueue():true
2016-10-14 07:52:35,508 INFO org.apache.hadoop.yarn.server.resourcemanager.scheduler.fair.FSAppAttempt: appattempt_1476452954783_0001_000001 minReqResource: <memory:24576, vCores:12> flexibleResource: <memory:8192, vCores:4>
2016-10-14 07:52:35,508 INFO org.apache.hadoop.yarn.server.resourcemanager.scheduler.fair.FairScheduler: [admission control] getFlexibleResource <memory:8192, vCores:4>
2016-10-14 07:52:35,509 INFO org.apache.hadoop.yarn.server.resourcemanager.scheduler.fair.FairScheduler: app appattempt_1476452954783_0001_000001 in queue root.interactive0 isRunning: true
2016-10-14 07:52:35,673 INFO org.apache.hadoop.yarn.server.resourcemanager.scheduler.fair.FairScheduler: allocate(appattempt_1476452954783_0002_000001 [{Priority: 1, Capability: <memory:1920, vCores:1>, # Containers: 507, Location: *, Relax Locality: true}] [] [] []
2016-10-14 07:52:35,678 INFO org.apache.hadoop.yarn.server.resourcemanager.rmapp.attempt.RMAppAttemptImpl: ScheduleTransition.transition(appattempt_1476452954783_0004_000001,EventType: ATTEMPT_ADDED)
2016-10-14 07:52:35,680 INFO org.apache.hadoop.yarn.server.resourcemanager.scheduler.fair.FSAppAttempt: root.interactive0 getMinReq:<memory:24576, vCores:12> demand: <memory:524288, vCores:256> usage: <memory:22528, vCores:11>running true active: true isLeafQueue():true
2016-10-14 07:52:35,680 INFO org.apache.hadoop.yarn.server.resourcemanager.scheduler.fair.FairScheduler: allocate(appattempt_1476452954783_0004_000001 [{Priority: 0, Capability: <memory:2048, vCores:1>, # Containers: 1, Location: *, Relax Locality: true}] [] null null
2016-10-14 07:52:35,680 INFO org.apache.hadoop.yarn.server.resourcemanager.scheduler.fair.FSAppAttempt: root.batch0 getMinReq:<memory:0, vCores:0> demand: <memory:526336, vCores:257> usage: <memory:10240, vCores:5>running true active: true isLeafQueue():true
2016-10-14 07:52:35,680 INFO org.apache.hadoop.yarn.server.resourcemanager.scheduler.fair.FSAppAttempt: root.interactive0 getMinReq:<memory:24576, vCores:12> demand: <memory:524288, vCores:256> usage: <memory:22528, vCores:11>running true active: true isLeafQueue():true
2016-10-14 07:52:35,680 INFO org.apache.hadoop.yarn.server.resourcemanager.scheduler.fair.FSAppAttempt: appattempt_1476452954783_0002_000001 minReqResource: <memory:24576, vCores:12> flexibleResource: <memory:8192, vCores:4>
2016-10-14 07:52:35,680 INFO org.apache.hadoop.yarn.server.resourcemanager.scheduler.fair.FSAppAttempt: root.batch0 getMinReq:<memory:0, vCores:0> demand: <memory:526336, vCores:257> usage: <memory:10240, vCores:5>running true active: true isLeafQueue():true
2016-10-14 07:52:35,680 INFO org.apache.hadoop.yarn.server.resourcemanager.scheduler.fair.FairScheduler: [admission control] getFlexibleResource <memory:8192, vCores:4>
2016-10-14 07:52:35,680 INFO org.apache.hadoop.yarn.server.resourcemanager.scheduler.fair.FSAppAttempt: appattempt_1476452954783_0004_000001 minReqResource: <memory:24576, vCores:12> flexibleResource: <memory:8192, vCores:4>
2016-10-14 07:52:35,680 INFO org.apache.hadoop.yarn.server.resourcemanager.scheduler.fair.FairScheduler: [admission control] getFlexibleResource <memory:8192, vCores:4>
2016-10-14 07:52:35,680 INFO org.apache.hadoop.yarn.server.resourcemanager.scheduler.fair.FairScheduler: app appattempt_1476452954783_0004_000001 in queue root.interactive1 isRunning: false
2016-10-14 07:52:35,680 INFO org.apache.hadoop.yarn.server.resourcemanager.scheduler.fair.FairScheduler: [admission control] Cannot allocate appattempt_1476452954783_0004_000001 because there is NO flexible resource left
2016-10-14 07:52:35,872 INFO org.apache.hadoop.yarn.server.resourcemanager.rmcontainer.RMContainerImpl: Processing container_1476452954783_0001_01_000017 of event FINISHED
2016-10-14 07:52:35,872 INFO org.apache.hadoop.yarn.server.resourcemanager.rmcontainer.RMContainerImpl: container_1476452954783_0001_01_000017 Container Transitioned from RUNNING to COMPLETED
2016-10-14 07:52:35,872 INFO org.apache.hadoop.yarn.server.resourcemanager.scheduler.fair.FSAppAttempt: Completed container: container_1476452954783_0001_01_000017 in state: COMPLETED event:FINISHED
2016-10-14 07:52:35,872 INFO org.apache.hadoop.yarn.server.resourcemanager.RMAuditLogger: USER=tanle	OPERATION=AM Released Container	TARGET=SchedulerApp	RESULT=SUCCESS	APPID=application_1476452954783_0001	CONTAINERID=container_1476452954783_0001_01_000017
2016-10-14 07:52:35,872 INFO org.apache.hadoop.yarn.server.resourcemanager.scheduler.SchedulerNode: Released container container_1476452954783_0001_01_000017 of capacity <memory:2048, vCores:1> on host cp-2.yarn-perf.yarnrm-PG0.wisc.cloudlab.us:43837, which currently has 3 containers, <memory:6144, vCores:3> used and <memory:2048, vCores:1> available, release resources=true
2016-10-14 07:52:35,873 INFO org.apache.hadoop.yarn.server.resourcemanager.scheduler.fair.FairScheduler: Application attempt appattempt_1476452954783_0001_000001 released container container_1476452954783_0001_01_000017 on node: host: cp-2.yarn-perf.yarnrm-PG0.wisc.cloudlab.us:43837 #containers=3 available=<memory:2048, vCores:1> used=<memory:6144, vCores:3> with event: FINISHED
2016-10-14 07:52:35,873 INFO org.apache.hadoop.yarn.server.resourcemanager.scheduler.fair.FSAppAttempt: assignContainer(FSSchedulerNode node:cp-2.yarn-perf.yarnrm-PG0.wisc.cloudlab.us, boolean reserved=true) for appattempt_1476452954783_0001_000001
2016-10-14 07:52:35,873 INFO org.apache.hadoop.yarn.server.resourcemanager.scheduler.fair.FSAppAttempt: allocate container: container_1476452954783_0001_01_000020 priority 1
2016-10-14 07:52:35,873 INFO org.apache.hadoop.yarn.server.resourcemanager.rmcontainer.RMContainerImpl: Processing container_1476452954783_0001_01_000020 of event START
2016-10-14 07:52:35,873 INFO org.apache.hadoop.yarn.server.resourcemanager.rmcontainer.RMContainerImpl: container_1476452954783_0001_01_000020 Container Transitioned from NEW to ALLOCATED
2016-10-14 07:52:35,873 INFO org.apache.hadoop.yarn.server.resourcemanager.RMAuditLogger: USER=tanle	OPERATION=AM Allocated Container	TARGET=SchedulerApp	RESULT=SUCCESS	APPID=application_1476452954783_0001	CONTAINERID=container_1476452954783_0001_01_000020
2016-10-14 07:52:35,873 INFO org.apache.hadoop.yarn.server.resourcemanager.scheduler.fair.FSAppAttempt: Application application_1476452954783_0001 unreserved  on node host: cp-2.yarn-perf.yarnrm-PG0.wisc.cloudlab.us:43837 #containers=3 available=<memory:2048, vCores:1> used=<memory:6144, vCores:3>, currently has 2 at priority 1; currentReservation <memory:4096, vCores:2>
2016-10-14 07:52:35,874 INFO org.apache.hadoop.yarn.server.resourcemanager.scheduler.SchedulerNode: Assigned container container_1476452954783_0001_01_000020 of capacity <memory:2048, vCores:1> on host cp-2.yarn-perf.yarnrm-PG0.wisc.cloudlab.us:43837, which has 4 containers, <memory:8192, vCores:4> used and <memory:0, vCores:0> available after allocation
2016-10-14 07:52:35,884 INFO org.apache.hadoop.yarn.server.resourcemanager.scheduler.fair.FairScheduler: allocate(appattempt_1476452954783_0002_000001 [] [] [] []
2016-10-14 07:52:35,884 INFO org.apache.hadoop.yarn.server.resourcemanager.scheduler.fair.FSAppAttempt: root.interactive0 getMinReq:<memory:24576, vCores:12> demand: <memory:524288, vCores:256> usage: <memory:22528, vCores:11>running true active: true isLeafQueue():true
2016-10-14 07:52:35,884 INFO org.apache.hadoop.yarn.server.resourcemanager.scheduler.fair.FSAppAttempt: root.batch0 getMinReq:<memory:0, vCores:0> demand: <memory:526336, vCores:257> usage: <memory:10240, vCores:5>running true active: true isLeafQueue():true
2016-10-14 07:52:35,884 INFO org.apache.hadoop.yarn.server.resourcemanager.scheduler.fair.FSAppAttempt: appattempt_1476452954783_0002_000001 minReqResource: <memory:24576, vCores:12> flexibleResource: <memory:8192, vCores:4>
2016-10-14 07:52:35,884 INFO org.apache.hadoop.yarn.server.resourcemanager.scheduler.fair.FairScheduler: [admission control] getFlexibleResource <memory:8192, vCores:4>
2016-10-14 07:52:36,228 INFO org.apache.hadoop.yarn.server.resourcemanager.scheduler.fair.FairScheduler: allocate(appattempt_1476452954783_0001_000001 [] [] [] []
2016-10-14 07:52:36,229 INFO org.apache.hadoop.yarn.server.resourcemanager.scheduler.fair.FSAppAttempt: root.interactive0 getMinReq:<memory:24576, vCores:12> demand: <memory:522240, vCores:255> usage: <memory:22528, vCores:11>running true active: true isLeafQueue():true
2016-10-14 07:52:36,229 INFO org.apache.hadoop.yarn.server.resourcemanager.scheduler.fair.FSAppAttempt: root.batch0 getMinReq:<memory:0, vCores:0> demand: <memory:1050624, vCores:513> usage: <memory:10240, vCores:5>running true active: true isLeafQueue():true
2016-10-14 07:52:36,229 INFO org.apache.hadoop.yarn.server.resourcemanager.scheduler.fair.FSAppAttempt: appattempt_1476452954783_0001_000001 minReqResource: <memory:24576, vCores:12> flexibleResource: <memory:8192, vCores:4>
2016-10-14 07:52:36,229 INFO org.apache.hadoop.yarn.server.resourcemanager.scheduler.fair.FairScheduler: [admission control] getFlexibleResource <memory:8192, vCores:4>
2016-10-14 07:52:36,229 INFO org.apache.hadoop.yarn.server.resourcemanager.scheduler.fair.FairScheduler: app appattempt_1476452954783_0001_000001 in queue root.interactive0 isRunning: true
2016-10-14 07:52:36,231 INFO org.apache.hadoop.yarn.server.resourcemanager.rmcontainer.RMContainerImpl: Processing container_1476452954783_0001_01_000020 of event ACQUIRED
2016-10-14 07:52:36,232 INFO org.apache.hadoop.yarn.server.resourcemanager.rmcontainer.RMContainerImpl: container_1476452954783_0001_01_000020 Container Transitioned from ALLOCATED to ACQUIRED
2016-10-14 07:52:36,288 INFO org.apache.hadoop.yarn.server.resourcemanager.scheduler.fair.FairScheduler: allocate(appattempt_1476452954783_0002_000001 [] [] [] []
2016-10-14 07:52:36,288 INFO org.apache.hadoop.yarn.server.resourcemanager.scheduler.fair.FSAppAttempt: root.interactive0 getMinReq:<memory:24576, vCores:12> demand: <memory:522240, vCores:255> usage: <memory:22528, vCores:11>running true active: true isLeafQueue():true
2016-10-14 07:52:36,288 INFO org.apache.hadoop.yarn.server.resourcemanager.scheduler.fair.FSAppAttempt: root.batch0 getMinReq:<memory:0, vCores:0> demand: <memory:1050624, vCores:513> usage: <memory:10240, vCores:5>running true active: true isLeafQueue():true
2016-10-14 07:52:36,288 INFO org.apache.hadoop.yarn.server.resourcemanager.scheduler.fair.FSAppAttempt: appattempt_1476452954783_0002_000001 minReqResource: <memory:24576, vCores:12> flexibleResource: <memory:8192, vCores:4>
2016-10-14 07:52:36,288 INFO org.apache.hadoop.yarn.server.resourcemanager.scheduler.fair.FairScheduler: [admission control] getFlexibleResource <memory:8192, vCores:4>
2016-10-14 07:52:36,402 INFO org.apache.hadoop.yarn.server.resourcemanager.scheduler.fair.FairScheduler: allocate(appattempt_1476452954783_0001_000001 [{Priority: 1, Capability: <memory:1920, vCores:1>, # Containers: 245, Location: *, Relax Locality: true}] [] [] []
2016-10-14 07:52:36,402 INFO org.apache.hadoop.yarn.server.resourcemanager.scheduler.fair.FSAppAttempt: root.interactive0 getMinReq:<memory:24576, vCores:12> demand: <memory:522240, vCores:255> usage: <memory:22528, vCores:11>running true active: true isLeafQueue():true
2016-10-14 07:52:36,402 INFO org.apache.hadoop.yarn.server.resourcemanager.scheduler.fair.FSAppAttempt: root.batch0 getMinReq:<memory:0, vCores:0> demand: <memory:1050624, vCores:513> usage: <memory:10240, vCores:5>running true active: true isLeafQueue():true
2016-10-14 07:52:36,403 INFO org.apache.hadoop.yarn.server.resourcemanager.scheduler.fair.FSAppAttempt: appattempt_1476452954783_0001_000001 minReqResource: <memory:24576, vCores:12> flexibleResource: <memory:8192, vCores:4>
2016-10-14 07:52:36,403 INFO org.apache.hadoop.yarn.server.resourcemanager.scheduler.fair.FairScheduler: [admission control] getFlexibleResource <memory:8192, vCores:4>
2016-10-14 07:52:36,403 INFO org.apache.hadoop.yarn.server.resourcemanager.scheduler.fair.FairScheduler: app appattempt_1476452954783_0001_000001 in queue root.interactive0 isRunning: true
2016-10-14 07:52:36,606 INFO org.apache.hadoop.yarn.server.resourcemanager.scheduler.fair.FairScheduler: allocate(appattempt_1476452954783_0001_000001 [] [] [] []
2016-10-14 07:52:36,606 INFO org.apache.hadoop.yarn.server.resourcemanager.scheduler.fair.FSAppAttempt: root.interactive0 getMinReq:<memory:24576, vCores:12> demand: <memory:524288, vCores:256> usage: <memory:22528, vCores:11>running true active: true isLeafQueue():true
2016-10-14 07:52:36,606 INFO org.apache.hadoop.yarn.server.resourcemanager.scheduler.fair.FSAppAttempt: root.batch0 getMinReq:<memory:0, vCores:0> demand: <memory:1050624, vCores:513> usage: <memory:10240, vCores:5>running true active: true isLeafQueue():true
2016-10-14 07:52:36,606 INFO org.apache.hadoop.yarn.server.resourcemanager.scheduler.fair.FSAppAttempt: appattempt_1476452954783_0001_000001 minReqResource: <memory:24576, vCores:12> flexibleResource: <memory:8192, vCores:4>
2016-10-14 07:52:36,606 INFO org.apache.hadoop.yarn.server.resourcemanager.scheduler.fair.FairScheduler: [admission control] getFlexibleResource <memory:8192, vCores:4>
2016-10-14 07:52:36,606 INFO org.apache.hadoop.yarn.server.resourcemanager.scheduler.fair.FairScheduler: app appattempt_1476452954783_0001_000001 in queue root.interactive0 isRunning: true
2016-10-14 07:52:36,668 INFO org.apache.hadoop.yarn.server.resourcemanager.scheduler.fair.FairScheduler: allocate(appattempt_1476452954783_0001_000001 [{Priority: 1, Capability: <memory:1920, vCores:1>, # Containers: 501, Location: *, Relax Locality: true}] [] [] []
2016-10-14 07:52:36,668 INFO org.apache.hadoop.yarn.server.resourcemanager.scheduler.fair.FSAppAttempt: root.interactive0 getMinReq:<memory:24576, vCores:12> demand: <memory:524288, vCores:256> usage: <memory:22528, vCores:11>running true active: true isLeafQueue():true
2016-10-14 07:52:36,668 INFO org.apache.hadoop.yarn.server.resourcemanager.scheduler.fair.FSAppAttempt: root.batch0 getMinReq:<memory:0, vCores:0> demand: <memory:1050624, vCores:513> usage: <memory:10240, vCores:5>running true active: true isLeafQueue():true
2016-10-14 07:52:36,668 INFO org.apache.hadoop.yarn.server.resourcemanager.scheduler.fair.FSAppAttempt: appattempt_1476452954783_0001_000001 minReqResource: <memory:24576, vCores:12> flexibleResource: <memory:8192, vCores:4>
2016-10-14 07:52:36,668 INFO org.apache.hadoop.yarn.server.resourcemanager.scheduler.fair.FairScheduler: [admission control] getFlexibleResource <memory:8192, vCores:4>
2016-10-14 07:52:36,668 INFO org.apache.hadoop.yarn.server.resourcemanager.scheduler.fair.FairScheduler: app appattempt_1476452954783_0001_000001 in queue root.interactive0 isRunning: true
2016-10-14 07:52:36,681 INFO org.apache.hadoop.yarn.server.resourcemanager.rmapp.attempt.RMAppAttemptImpl: ScheduleTransition.transition(appattempt_1476452954783_0004_000001,EventType: ATTEMPT_ADDED)
2016-10-14 07:52:36,681 INFO org.apache.hadoop.yarn.server.resourcemanager.scheduler.fair.FairScheduler: allocate(appattempt_1476452954783_0004_000001 [{Priority: 0, Capability: <memory:2048, vCores:1>, # Containers: 1, Location: *, Relax Locality: true}] [] null null
2016-10-14 07:52:36,681 INFO org.apache.hadoop.yarn.server.resourcemanager.scheduler.fair.FSAppAttempt: root.interactive0 getMinReq:<memory:24576, vCores:12> demand: <memory:524288, vCores:256> usage: <memory:22528, vCores:11>running true active: true isLeafQueue():true
2016-10-14 07:52:36,682 INFO org.apache.hadoop.yarn.server.resourcemanager.scheduler.fair.FSAppAttempt: root.batch0 getMinReq:<memory:0, vCores:0> demand: <memory:1050624, vCores:513> usage: <memory:10240, vCores:5>running true active: true isLeafQueue():true
2016-10-14 07:52:36,682 INFO org.apache.hadoop.yarn.server.resourcemanager.scheduler.fair.FSAppAttempt: appattempt_1476452954783_0004_000001 minReqResource: <memory:24576, vCores:12> flexibleResource: <memory:8192, vCores:4>
2016-10-14 07:52:36,682 INFO org.apache.hadoop.yarn.server.resourcemanager.scheduler.fair.FairScheduler: [admission control] getFlexibleResource <memory:8192, vCores:4>
2016-10-14 07:52:36,682 INFO org.apache.hadoop.yarn.server.resourcemanager.scheduler.fair.FairScheduler: app appattempt_1476452954783_0004_000001 in queue root.interactive1 isRunning: false
2016-10-14 07:52:36,682 INFO org.apache.hadoop.yarn.server.resourcemanager.scheduler.fair.FairScheduler: [admission control] Cannot allocate appattempt_1476452954783_0004_000001 because there is NO flexible resource left
2016-10-14 07:52:36,871 INFO org.apache.hadoop.yarn.server.resourcemanager.scheduler.fair.FairScheduler: allocate(appattempt_1476452954783_0001_000001 [] [] [] []
2016-10-14 07:52:36,872 INFO org.apache.hadoop.yarn.server.resourcemanager.scheduler.fair.FSAppAttempt: root.interactive0 getMinReq:<memory:24576, vCores:12> demand: <memory:524288, vCores:256> usage: <memory:22528, vCores:11>running true active: true isLeafQueue():true
2016-10-14 07:52:36,872 INFO org.apache.hadoop.yarn.server.resourcemanager.scheduler.fair.FSAppAttempt: root.batch0 getMinReq:<memory:0, vCores:0> demand: <memory:1050624, vCores:513> usage: <memory:10240, vCores:5>running true active: true isLeafQueue():true
2016-10-14 07:52:36,872 INFO org.apache.hadoop.yarn.server.resourcemanager.scheduler.fair.FSAppAttempt: appattempt_1476452954783_0001_000001 minReqResource: <memory:24576, vCores:12> flexibleResource: <memory:8192, vCores:4>
2016-10-14 07:52:36,872 INFO org.apache.hadoop.yarn.server.resourcemanager.scheduler.fair.FairScheduler: [admission control] getFlexibleResource <memory:8192, vCores:4>
2016-10-14 07:52:36,872 INFO org.apache.hadoop.yarn.server.resourcemanager.scheduler.fair.FairScheduler: app appattempt_1476452954783_0001_000001 in queue root.interactive0 isRunning: true
2016-10-14 07:52:36,875 INFO org.apache.hadoop.yarn.server.resourcemanager.rmcontainer.RMContainerImpl: Processing container_1476452954783_0001_01_000020 of event LAUNCHED
2016-10-14 07:52:36,875 INFO org.apache.hadoop.yarn.server.resourcemanager.rmcontainer.RMContainerImpl: container_1476452954783_0001_01_000020 Container Transitioned from ACQUIRED to RUNNING
2016-10-14 07:52:36,876 INFO org.apache.hadoop.yarn.server.resourcemanager.scheduler.fair.FSAppAttempt: assignContainer(FSSchedulerNode node:cp-2.yarn-perf.yarnrm-PG0.wisc.cloudlab.us, boolean reserved=false) for appattempt_1476452954783_0004_000001
2016-10-14 07:52:36,876 INFO org.apache.hadoop.yarn.server.resourcemanager.scheduler.fair.FSAppAttempt: assignContainer(FSSchedulerNode node:cp-2.yarn-perf.yarnrm-PG0.wisc.cloudlab.us, boolean reserved=false) for appattempt_1476452954783_0001_000001
2016-10-14 07:52:36,877 INFO org.apache.hadoop.yarn.server.resourcemanager.scheduler.fair.FSAppAttempt: Making reservation: node=cp-2.yarn-perf.yarnrm-PG0.wisc.cloudlab.us app_id=application_1476452954783_0001
2016-10-14 07:52:36,877 INFO org.apache.hadoop.yarn.server.resourcemanager.rmcontainer.RMContainerImpl: Processing container_1476452954783_0001_01_000021 of event RESERVED
2016-10-14 07:52:36,877 INFO org.apache.hadoop.yarn.server.resourcemanager.rmcontainer.RMContainerImpl: container_1476452954783_0001_01_000021 Container Transitioned from NEW to RESERVED
2016-10-14 07:52:36,877 INFO org.apache.hadoop.yarn.server.resourcemanager.scheduler.fair.FSSchedulerNode: Reserved container container_1476452954783_0001_01_000021 on node host: cp-2.yarn-perf.yarnrm-PG0.wisc.cloudlab.us:43837 #containers=4 available=<memory:0, vCores:0> used=<memory:8192, vCores:4> for application org.apache.hadoop.yarn.server.resourcemanager.scheduler.fair.FSAppAttempt@13f22e88
2016-10-14 07:52:36,980 INFO org.apache.hadoop.yarn.server.resourcemanager.rmcontainer.RMContainerImpl: Processing container_1476452954783_0001_01_000005 of event FINISHED
2016-10-14 07:52:36,980 INFO org.apache.hadoop.yarn.server.resourcemanager.rmcontainer.RMContainerImpl: container_1476452954783_0001_01_000005 Container Transitioned from RUNNING to COMPLETED
2016-10-14 07:52:36,981 INFO org.apache.hadoop.yarn.server.resourcemanager.scheduler.fair.FSAppAttempt: Completed container: container_1476452954783_0001_01_000005 in state: COMPLETED event:FINISHED
2016-10-14 07:52:36,981 INFO org.apache.hadoop.yarn.server.resourcemanager.RMAuditLogger: USER=tanle	OPERATION=AM Released Container	TARGET=SchedulerApp	RESULT=SUCCESS	APPID=application_1476452954783_0001	CONTAINERID=container_1476452954783_0001_01_000005
2016-10-14 07:52:36,981 INFO org.apache.hadoop.yarn.server.resourcemanager.scheduler.SchedulerNode: Released container container_1476452954783_0001_01_000005 of capacity <memory:2048, vCores:1> on host cp-1.yarn-perf.yarnrm-PG0.wisc.cloudlab.us:36424, which currently has 3 containers, <memory:6144, vCores:3> used and <memory:2048, vCores:1> available, release resources=true
2016-10-14 07:52:36,981 INFO org.apache.hadoop.yarn.server.resourcemanager.scheduler.fair.FairScheduler: Application attempt appattempt_1476452954783_0001_000001 released container container_1476452954783_0001_01_000005 on node: host: cp-1.yarn-perf.yarnrm-PG0.wisc.cloudlab.us:36424 #containers=3 available=<memory:2048, vCores:1> used=<memory:6144, vCores:3> with event: FINISHED
2016-10-14 07:52:36,981 INFO org.apache.hadoop.yarn.server.resourcemanager.rmcontainer.RMContainerImpl: Processing container_1476452954783_0001_01_000007 of event FINISHED
2016-10-14 07:52:36,981 INFO org.apache.hadoop.yarn.server.resourcemanager.rmcontainer.RMContainerImpl: container_1476452954783_0001_01_000007 Container Transitioned from RUNNING to COMPLETED
2016-10-14 07:52:36,981 INFO org.apache.hadoop.yarn.server.resourcemanager.scheduler.fair.FSAppAttempt: Completed container: container_1476452954783_0001_01_000007 in state: COMPLETED event:FINISHED
2016-10-14 07:52:36,982 INFO org.apache.hadoop.yarn.server.resourcemanager.RMAuditLogger: USER=tanle	OPERATION=AM Released Container	TARGET=SchedulerApp	RESULT=SUCCESS	APPID=application_1476452954783_0001	CONTAINERID=container_1476452954783_0001_01_000007
2016-10-14 07:52:36,982 INFO org.apache.hadoop.yarn.server.resourcemanager.scheduler.SchedulerNode: Released container container_1476452954783_0001_01_000007 of capacity <memory:2048, vCores:1> on host cp-1.yarn-perf.yarnrm-PG0.wisc.cloudlab.us:36424, which currently has 2 containers, <memory:4096, vCores:2> used and <memory:4096, vCores:2> available, release resources=true
2016-10-14 07:52:36,982 INFO org.apache.hadoop.yarn.server.resourcemanager.scheduler.fair.FairScheduler: Application attempt appattempt_1476452954783_0001_000001 released container container_1476452954783_0001_01_000007 on node: host: cp-1.yarn-perf.yarnrm-PG0.wisc.cloudlab.us:36424 #containers=2 available=<memory:4096, vCores:2> used=<memory:4096, vCores:2> with event: FINISHED
2016-10-14 07:52:36,982 INFO org.apache.hadoop.yarn.server.resourcemanager.rmcontainer.RMContainerImpl: Processing container_1476452954783_0001_01_000010 of event FINISHED
2016-10-14 07:52:36,982 INFO org.apache.hadoop.yarn.server.resourcemanager.rmcontainer.RMContainerImpl: container_1476452954783_0001_01_000010 Container Transitioned from RUNNING to COMPLETED
2016-10-14 07:52:36,982 INFO org.apache.hadoop.yarn.server.resourcemanager.scheduler.fair.FSAppAttempt: Completed container: container_1476452954783_0001_01_000010 in state: COMPLETED event:FINISHED
2016-10-14 07:52:36,982 INFO org.apache.hadoop.yarn.server.resourcemanager.RMAuditLogger: USER=tanle	OPERATION=AM Released Container	TARGET=SchedulerApp	RESULT=SUCCESS	APPID=application_1476452954783_0001	CONTAINERID=container_1476452954783_0001_01_000010
2016-10-14 07:52:36,982 INFO org.apache.hadoop.yarn.server.resourcemanager.scheduler.SchedulerNode: Released container container_1476452954783_0001_01_000010 of capacity <memory:2048, vCores:1> on host cp-1.yarn-perf.yarnrm-PG0.wisc.cloudlab.us:36424, which currently has 1 containers, <memory:2048, vCores:1> used and <memory:6144, vCores:3> available, release resources=true
2016-10-14 07:52:36,983 INFO org.apache.hadoop.yarn.server.resourcemanager.scheduler.fair.FairScheduler: Application attempt appattempt_1476452954783_0001_000001 released container container_1476452954783_0001_01_000010 on node: host: cp-1.yarn-perf.yarnrm-PG0.wisc.cloudlab.us:36424 #containers=1 available=<memory:6144, vCores:3> used=<memory:2048, vCores:1> with event: FINISHED
2016-10-14 07:52:36,983 INFO org.apache.hadoop.yarn.server.resourcemanager.scheduler.fair.FSAppAttempt: assignContainer(FSSchedulerNode node:cp-1.yarn-perf.yarnrm-PG0.wisc.cloudlab.us, boolean reserved=true) for appattempt_1476452954783_0001_000001
2016-10-14 07:52:36,983 INFO org.apache.hadoop.yarn.server.resourcemanager.scheduler.fair.FSAppAttempt: allocate container: container_1476452954783_0001_01_000012 priority 1
2016-10-14 07:52:36,983 INFO org.apache.hadoop.yarn.server.resourcemanager.rmcontainer.RMContainerImpl: Processing container_1476452954783_0001_01_000012 of event START
2016-10-14 07:52:36,983 INFO org.apache.hadoop.yarn.server.resourcemanager.rmcontainer.RMContainerImpl: container_1476452954783_0001_01_000012 Container Transitioned from NEW to ALLOCATED
2016-10-14 07:52:36,983 INFO org.apache.hadoop.yarn.server.resourcemanager.RMAuditLogger: USER=tanle	OPERATION=AM Allocated Container	TARGET=SchedulerApp	RESULT=SUCCESS	APPID=application_1476452954783_0001	CONTAINERID=container_1476452954783_0001_01_000012
2016-10-14 07:52:36,983 INFO org.apache.hadoop.yarn.server.resourcemanager.scheduler.fair.FSAppAttempt: Application application_1476452954783_0001 unreserved  on node host: cp-1.yarn-perf.yarnrm-PG0.wisc.cloudlab.us:36424 #containers=1 available=<memory:6144, vCores:3> used=<memory:2048, vCores:1>, currently has 2 at priority 1; currentReservation <memory:4096, vCores:2>
2016-10-14 07:52:36,984 INFO org.apache.hadoop.yarn.server.resourcemanager.scheduler.SchedulerNode: Assigned container container_1476452954783_0001_01_000012 of capacity <memory:2048, vCores:1> on host cp-1.yarn-perf.yarnrm-PG0.wisc.cloudlab.us:36424, which has 2 containers, <memory:4096, vCores:2> used and <memory:4096, vCores:2> available after allocation
2016-10-14 07:52:37,092 INFO org.apache.hadoop.yarn.server.resourcemanager.scheduler.fair.FairScheduler: allocate(appattempt_1476452954783_0002_000001 [] [] [] []
2016-10-14 07:52:37,092 INFO org.apache.hadoop.yarn.server.resourcemanager.scheduler.fair.FSAppAttempt: root.interactive0 getMinReq:<memory:24576, vCores:12> demand: <memory:1042432, vCores:509> usage: <memory:18432, vCores:9>running true active: true isLeafQueue():true
2016-10-14 07:52:37,092 INFO org.apache.hadoop.yarn.server.resourcemanager.scheduler.fair.FSAppAttempt: root.batch0 getMinReq:<memory:0, vCores:0> demand: <memory:1050624, vCores:513> usage: <memory:10240, vCores:5>running true active: true isLeafQueue():true
2016-10-14 07:52:37,092 INFO org.apache.hadoop.yarn.server.resourcemanager.scheduler.fair.FSAppAttempt: appattempt_1476452954783_0002_000001 minReqResource: <memory:24576, vCores:12> flexibleResource: <memory:8192, vCores:4>
2016-10-14 07:52:37,092 INFO org.apache.hadoop.yarn.server.resourcemanager.scheduler.fair.FairScheduler: [admission control] getFlexibleResource <memory:8192, vCores:4>
2016-10-14 07:52:37,275 INFO org.apache.hadoop.yarn.server.resourcemanager.scheduler.fair.FairScheduler: allocate(appattempt_1476452954783_0001_000001 [] [] [] []
2016-10-14 07:52:37,275 INFO org.apache.hadoop.yarn.server.resourcemanager.scheduler.fair.FSAppAttempt: root.interactive0 getMinReq:<memory:24576, vCores:12> demand: <memory:1042432, vCores:509> usage: <memory:18432, vCores:9>running true active: true isLeafQueue():true
2016-10-14 07:52:37,275 INFO org.apache.hadoop.yarn.server.resourcemanager.scheduler.fair.FSAppAttempt: root.batch0 getMinReq:<memory:0, vCores:0> demand: <memory:1050624, vCores:513> usage: <memory:10240, vCores:5>running true active: true isLeafQueue():true
2016-10-14 07:52:37,276 INFO org.apache.hadoop.yarn.server.resourcemanager.scheduler.fair.FSAppAttempt: appattempt_1476452954783_0001_000001 minReqResource: <memory:24576, vCores:12> flexibleResource: <memory:8192, vCores:4>
2016-10-14 07:52:37,276 INFO org.apache.hadoop.yarn.server.resourcemanager.scheduler.fair.FairScheduler: [admission control] getFlexibleResource <memory:8192, vCores:4>
2016-10-14 07:52:37,276 INFO org.apache.hadoop.yarn.server.resourcemanager.scheduler.fair.FairScheduler: app appattempt_1476452954783_0001_000001 in queue root.interactive0 isRunning: true
2016-10-14 07:52:37,278 INFO org.apache.hadoop.yarn.server.resourcemanager.rmcontainer.RMContainerImpl: Processing container_1476452954783_0001_01_000012 of event ACQUIRED
2016-10-14 07:52:37,278 INFO org.apache.hadoop.yarn.server.resourcemanager.rmcontainer.RMContainerImpl: container_1476452954783_0001_01_000012 Container Transitioned from ALLOCATED to ACQUIRED
2016-10-14 07:52:37,684 INFO org.apache.hadoop.yarn.server.resourcemanager.rmapp.attempt.RMAppAttemptImpl: ScheduleTransition.transition(appattempt_1476452954783_0004_000001,EventType: ATTEMPT_ADDED)
2016-10-14 07:52:37,684 INFO org.apache.hadoop.yarn.server.resourcemanager.scheduler.fair.FairScheduler: allocate(appattempt_1476452954783_0004_000001 [{Priority: 0, Capability: <memory:2048, vCores:1>, # Containers: 1, Location: *, Relax Locality: true}] [] null null
2016-10-14 07:52:37,684 INFO org.apache.hadoop.yarn.server.resourcemanager.scheduler.fair.FSAppAttempt: root.interactive0 getMinReq:<memory:24576, vCores:12> demand: <memory:1042432, vCores:509> usage: <memory:18432, vCores:9>running true active: true isLeafQueue():true
2016-10-14 07:52:37,684 INFO org.apache.hadoop.yarn.server.resourcemanager.scheduler.fair.FSAppAttempt: root.batch0 getMinReq:<memory:0, vCores:0> demand: <memory:1050624, vCores:513> usage: <memory:10240, vCores:5>running true active: true isLeafQueue():true
2016-10-14 07:52:37,684 INFO org.apache.hadoop.yarn.server.resourcemanager.scheduler.fair.FSAppAttempt: appattempt_1476452954783_0004_000001 minReqResource: <memory:24576, vCores:12> flexibleResource: <memory:8192, vCores:4>
2016-10-14 07:52:37,684 INFO org.apache.hadoop.yarn.server.resourcemanager.scheduler.fair.FairScheduler: [admission control] getFlexibleResource <memory:8192, vCores:4>
2016-10-14 07:52:37,684 INFO org.apache.hadoop.yarn.server.resourcemanager.scheduler.fair.FairScheduler: app appattempt_1476452954783_0004_000001 in queue root.interactive1 isRunning: false
2016-10-14 07:52:37,684 INFO org.apache.hadoop.yarn.server.resourcemanager.scheduler.fair.FairScheduler: [admission control] Cannot allocate appattempt_1476452954783_0004_000001 because there is NO flexible resource left
2016-10-14 07:52:37,983 INFO org.apache.hadoop.yarn.server.resourcemanager.rmcontainer.RMContainerImpl: Processing container_1476452954783_0001_01_000012 of event LAUNCHED
2016-10-14 07:52:37,983 INFO org.apache.hadoop.yarn.server.resourcemanager.rmcontainer.RMContainerImpl: container_1476452954783_0001_01_000012 Container Transitioned from ACQUIRED to RUNNING
2016-10-14 07:52:37,984 INFO org.apache.hadoop.yarn.server.resourcemanager.scheduler.fair.FSAppAttempt: assignContainer(FSSchedulerNode node:cp-1.yarn-perf.yarnrm-PG0.wisc.cloudlab.us, boolean reserved=false) for appattempt_1476452954783_0004_000001
2016-10-14 07:52:37,984 INFO org.apache.hadoop.yarn.server.resourcemanager.scheduler.fair.FSAppAttempt: assignContainer(FSSchedulerNode node:cp-1.yarn-perf.yarnrm-PG0.wisc.cloudlab.us, boolean reserved=false) for appattempt_1476452954783_0001_000001
2016-10-14 07:52:37,984 INFO org.apache.hadoop.yarn.server.resourcemanager.scheduler.fair.FSAppAttempt: allocate container: container_1476452954783_0001_01_000022 priority 1
2016-10-14 07:52:37,985 INFO org.apache.hadoop.yarn.server.resourcemanager.rmcontainer.RMContainerImpl: Processing container_1476452954783_0001_01_000022 of event START
2016-10-14 07:52:37,985 INFO org.apache.hadoop.yarn.server.resourcemanager.rmcontainer.RMContainerImpl: container_1476452954783_0001_01_000022 Container Transitioned from NEW to ALLOCATED
2016-10-14 07:52:37,985 INFO org.apache.hadoop.yarn.server.resourcemanager.RMAuditLogger: USER=tanle	OPERATION=AM Allocated Container	TARGET=SchedulerApp	RESULT=SUCCESS	APPID=application_1476452954783_0001	CONTAINERID=container_1476452954783_0001_01_000022
2016-10-14 07:52:37,985 INFO org.apache.hadoop.yarn.server.resourcemanager.scheduler.SchedulerNode: Assigned container container_1476452954783_0001_01_000022 of capacity <memory:2048, vCores:1> on host cp-1.yarn-perf.yarnrm-PG0.wisc.cloudlab.us:36424, which has 3 containers, <memory:6144, vCores:3> used and <memory:2048, vCores:1> available after allocation
2016-10-14 07:52:38,090 INFO org.apache.hadoop.yarn.server.resourcemanager.scheduler.fair.FairScheduler: allocate(appattempt_1476452954783_0001_000001 [{Priority: 1, Capability: <memory:1920, vCores:1>, # Containers: 503, Location: *, Relax Locality: true}] [] [] []
2016-10-14 07:52:38,091 INFO org.apache.hadoop.yarn.server.resourcemanager.scheduler.fair.FSAppAttempt: root.interactive0 getMinReq:<memory:24576, vCores:12> demand: <memory:1042432, vCores:509> usage: <memory:20480, vCores:10>running true active: true isLeafQueue():true
2016-10-14 07:52:38,091 INFO org.apache.hadoop.yarn.server.resourcemanager.scheduler.fair.FSAppAttempt: root.batch0 getMinReq:<memory:0, vCores:0> demand: <memory:1050624, vCores:513> usage: <memory:10240, vCores:5>running true active: true isLeafQueue():true
2016-10-14 07:52:38,091 INFO org.apache.hadoop.yarn.server.resourcemanager.scheduler.fair.FSAppAttempt: appattempt_1476452954783_0001_000001 minReqResource: <memory:24576, vCores:12> flexibleResource: <memory:8192, vCores:4>
2016-10-14 07:52:38,091 INFO org.apache.hadoop.yarn.server.resourcemanager.scheduler.fair.FairScheduler: [admission control] getFlexibleResource <memory:8192, vCores:4>
2016-10-14 07:52:38,091 INFO org.apache.hadoop.yarn.server.resourcemanager.scheduler.fair.FairScheduler: app appattempt_1476452954783_0001_000001 in queue root.interactive0 isRunning: true
2016-10-14 07:52:38,093 INFO org.apache.hadoop.yarn.server.resourcemanager.rmcontainer.RMContainerImpl: Processing container_1476452954783_0001_01_000022 of event ACQUIRED
2016-10-14 07:52:38,093 INFO org.apache.hadoop.yarn.server.resourcemanager.rmcontainer.RMContainerImpl: container_1476452954783_0001_01_000022 Container Transitioned from ALLOCATED to ACQUIRED
2016-10-14 07:52:38,686 INFO org.apache.hadoop.yarn.server.resourcemanager.rmapp.attempt.RMAppAttemptImpl: ScheduleTransition.transition(appattempt_1476452954783_0004_000001,EventType: ATTEMPT_ADDED)
2016-10-14 07:52:38,686 INFO org.apache.hadoop.yarn.server.resourcemanager.scheduler.fair.FairScheduler: allocate(appattempt_1476452954783_0004_000001 [{Priority: 0, Capability: <memory:2048, vCores:1>, # Containers: 1, Location: *, Relax Locality: true}] [] null null
2016-10-14 07:52:38,686 INFO org.apache.hadoop.yarn.server.resourcemanager.scheduler.fair.FSAppAttempt: root.interactive0 getMinReq:<memory:24576, vCores:12> demand: <memory:1050624, vCores:513> usage: <memory:20480, vCores:10>running true active: true isLeafQueue():true
2016-10-14 07:52:38,686 INFO org.apache.hadoop.yarn.server.resourcemanager.scheduler.fair.FSAppAttempt: root.batch0 getMinReq:<memory:0, vCores:0> demand: <memory:1050624, vCores:513> usage: <memory:10240, vCores:5>running true active: true isLeafQueue():true
2016-10-14 07:52:38,686 INFO org.apache.hadoop.yarn.server.resourcemanager.scheduler.fair.FSAppAttempt: appattempt_1476452954783_0004_000001 minReqResource: <memory:24576, vCores:12> flexibleResource: <memory:8192, vCores:4>
2016-10-14 07:52:38,686 INFO org.apache.hadoop.yarn.server.resourcemanager.scheduler.fair.FairScheduler: [admission control] getFlexibleResource <memory:8192, vCores:4>
2016-10-14 07:52:38,686 INFO org.apache.hadoop.yarn.server.resourcemanager.scheduler.fair.FairScheduler: app appattempt_1476452954783_0004_000001 in queue root.interactive1 isRunning: false
2016-10-14 07:52:38,686 INFO org.apache.hadoop.yarn.server.resourcemanager.scheduler.fair.FairScheduler: [admission control] Cannot allocate appattempt_1476452954783_0004_000001 because there is NO flexible resource left
2016-10-14 07:52:38,696 INFO org.apache.hadoop.yarn.server.resourcemanager.scheduler.fair.FairScheduler: allocate(appattempt_1476452954783_0002_000001 [] [] [] []
2016-10-14 07:52:38,696 INFO org.apache.hadoop.yarn.server.resourcemanager.scheduler.fair.FSAppAttempt: root.interactive0 getMinReq:<memory:24576, vCores:12> demand: <memory:1050624, vCores:513> usage: <memory:20480, vCores:10>running true active: true isLeafQueue():true
2016-10-14 07:52:38,696 INFO org.apache.hadoop.yarn.server.resourcemanager.scheduler.fair.FSAppAttempt: root.batch0 getMinReq:<memory:0, vCores:0> demand: <memory:1050624, vCores:513> usage: <memory:10240, vCores:5>running true active: true isLeafQueue():true
2016-10-14 07:52:38,696 INFO org.apache.hadoop.yarn.server.resourcemanager.scheduler.fair.FSAppAttempt: appattempt_1476452954783_0002_000001 minReqResource: <memory:24576, vCores:12> flexibleResource: <memory:8192, vCores:4>
2016-10-14 07:52:38,696 INFO org.apache.hadoop.yarn.server.resourcemanager.scheduler.fair.FairScheduler: [admission control] getFlexibleResource <memory:8192, vCores:4>
2016-10-14 07:52:38,986 INFO org.apache.hadoop.yarn.server.resourcemanager.rmcontainer.RMContainerImpl: Processing container_1476452954783_0001_01_000022 of event LAUNCHED
2016-10-14 07:52:38,987 INFO org.apache.hadoop.yarn.server.resourcemanager.rmcontainer.RMContainerImpl: container_1476452954783_0001_01_000022 Container Transitioned from ACQUIRED to RUNNING
2016-10-14 07:52:38,988 INFO org.apache.hadoop.yarn.server.resourcemanager.scheduler.fair.FSAppAttempt: assignContainer(FSSchedulerNode node:cp-1.yarn-perf.yarnrm-PG0.wisc.cloudlab.us, boolean reserved=false) for appattempt_1476452954783_0004_000001
2016-10-14 07:52:38,988 INFO org.apache.hadoop.yarn.server.resourcemanager.scheduler.fair.FSAppAttempt: assignContainer(FSSchedulerNode node:cp-1.yarn-perf.yarnrm-PG0.wisc.cloudlab.us, boolean reserved=false) for appattempt_1476452954783_0001_000001
2016-10-14 07:52:38,988 INFO org.apache.hadoop.yarn.server.resourcemanager.scheduler.fair.FSAppAttempt: allocate container: container_1476452954783_0001_01_000023 priority 1
2016-10-14 07:52:38,988 INFO org.apache.hadoop.yarn.server.resourcemanager.rmcontainer.RMContainerImpl: Processing container_1476452954783_0001_01_000023 of event START
2016-10-14 07:52:38,988 INFO org.apache.hadoop.yarn.server.resourcemanager.rmcontainer.RMContainerImpl: container_1476452954783_0001_01_000023 Container Transitioned from NEW to ALLOCATED
2016-10-14 07:52:38,988 INFO org.apache.hadoop.yarn.server.resourcemanager.RMAuditLogger: USER=tanle	OPERATION=AM Allocated Container	TARGET=SchedulerApp	RESULT=SUCCESS	APPID=application_1476452954783_0001	CONTAINERID=container_1476452954783_0001_01_000023
2016-10-14 07:52:38,988 INFO org.apache.hadoop.yarn.server.resourcemanager.scheduler.SchedulerNode: Assigned container container_1476452954783_0001_01_000023 of capacity <memory:2048, vCores:1> on host cp-1.yarn-perf.yarnrm-PG0.wisc.cloudlab.us:36424, which has 4 containers, <memory:8192, vCores:4> used and <memory:0, vCores:0> available after allocation
2016-10-14 07:52:39,397 INFO org.apache.hadoop.yarn.server.resourcemanager.scheduler.fair.FairScheduler: allocate(appattempt_1476452954783_0002_000001 [] [] [] []
2016-10-14 07:52:39,397 INFO org.apache.hadoop.yarn.server.resourcemanager.scheduler.fair.FSAppAttempt: root.interactive0 getMinReq:<memory:24576, vCores:12> demand: <memory:1050624, vCores:513> usage: <memory:22528, vCores:11>running true active: true isLeafQueue():true
2016-10-14 07:52:39,397 INFO org.apache.hadoop.yarn.server.resourcemanager.scheduler.fair.FSAppAttempt: root.batch0 getMinReq:<memory:0, vCores:0> demand: <memory:1050624, vCores:513> usage: <memory:10240, vCores:5>running true active: true isLeafQueue():true
2016-10-14 07:52:39,397 INFO org.apache.hadoop.yarn.server.resourcemanager.scheduler.fair.FSAppAttempt: appattempt_1476452954783_0002_000001 minReqResource: <memory:24576, vCores:12> flexibleResource: <memory:8192, vCores:4>
2016-10-14 07:52:39,397 INFO org.apache.hadoop.yarn.server.resourcemanager.scheduler.fair.FairScheduler: [admission control] getFlexibleResource <memory:8192, vCores:4>
2016-10-14 07:52:39,601 INFO org.apache.hadoop.yarn.server.resourcemanager.scheduler.fair.FairScheduler: allocate(appattempt_1476452954783_0002_000001 [] [] [] []
2016-10-14 07:52:39,601 INFO org.apache.hadoop.yarn.server.resourcemanager.scheduler.fair.FSAppAttempt: root.interactive0 getMinReq:<memory:24576, vCores:12> demand: <memory:1050624, vCores:513> usage: <memory:22528, vCores:11>running true active: true isLeafQueue():true
2016-10-14 07:52:39,601 INFO org.apache.hadoop.yarn.server.resourcemanager.scheduler.fair.FSAppAttempt: root.batch0 getMinReq:<memory:0, vCores:0> demand: <memory:1050624, vCores:513> usage: <memory:10240, vCores:5>running true active: true isLeafQueue():true
2016-10-14 07:52:39,601 INFO org.apache.hadoop.yarn.server.resourcemanager.scheduler.fair.FSAppAttempt: appattempt_1476452954783_0002_000001 minReqResource: <memory:24576, vCores:12> flexibleResource: <memory:8192, vCores:4>
2016-10-14 07:52:39,601 INFO org.apache.hadoop.yarn.server.resourcemanager.scheduler.fair.FairScheduler: [admission control] getFlexibleResource <memory:8192, vCores:4>
2016-10-14 07:52:39,687 INFO org.apache.hadoop.yarn.server.resourcemanager.rmapp.attempt.RMAppAttemptImpl: ScheduleTransition.transition(appattempt_1476452954783_0004_000001,EventType: ATTEMPT_ADDED)
2016-10-14 07:52:39,688 INFO org.apache.hadoop.yarn.server.resourcemanager.scheduler.fair.FairScheduler: allocate(appattempt_1476452954783_0004_000001 [{Priority: 0, Capability: <memory:2048, vCores:1>, # Containers: 1, Location: *, Relax Locality: true}] [] null null
2016-10-14 07:52:39,688 INFO org.apache.hadoop.yarn.server.resourcemanager.scheduler.fair.FSAppAttempt: root.interactive0 getMinReq:<memory:24576, vCores:12> demand: <memory:1050624, vCores:513> usage: <memory:22528, vCores:11>running true active: true isLeafQueue():true
2016-10-14 07:52:39,688 INFO org.apache.hadoop.yarn.server.resourcemanager.scheduler.fair.FSAppAttempt: root.batch0 getMinReq:<memory:0, vCores:0> demand: <memory:1050624, vCores:513> usage: <memory:10240, vCores:5>running true active: true isLeafQueue():true
2016-10-14 07:52:39,688 INFO org.apache.hadoop.yarn.server.resourcemanager.scheduler.fair.FSAppAttempt: appattempt_1476452954783_0004_000001 minReqResource: <memory:24576, vCores:12> flexibleResource: <memory:8192, vCores:4>
2016-10-14 07:52:39,688 INFO org.apache.hadoop.yarn.server.resourcemanager.scheduler.fair.FairScheduler: [admission control] getFlexibleResource <memory:8192, vCores:4>
2016-10-14 07:52:39,688 INFO org.apache.hadoop.yarn.server.resourcemanager.scheduler.fair.FairScheduler: app appattempt_1476452954783_0004_000001 in queue root.interactive1 isRunning: false
2016-10-14 07:52:39,688 INFO org.apache.hadoop.yarn.server.resourcemanager.scheduler.fair.FairScheduler: [admission control] Cannot allocate appattempt_1476452954783_0004_000001 because there is NO flexible resource left
2016-10-14 07:52:39,698 INFO org.apache.hadoop.yarn.server.resourcemanager.scheduler.fair.FairScheduler: allocate(appattempt_1476452954783_0001_000001 [{Priority: 1, Capability: <memory:1920, vCores:1>, # Containers: 502, Location: *, Relax Locality: true}] [] [] []
2016-10-14 07:52:39,699 INFO org.apache.hadoop.yarn.server.resourcemanager.scheduler.fair.FSAppAttempt: root.interactive0 getMinReq:<memory:24576, vCores:12> demand: <memory:1050624, vCores:513> usage: <memory:22528, vCores:11>running true active: true isLeafQueue():true
2016-10-14 07:52:39,699 INFO org.apache.hadoop.yarn.server.resourcemanager.scheduler.fair.FSAppAttempt: root.batch0 getMinReq:<memory:0, vCores:0> demand: <memory:1050624, vCores:513> usage: <memory:10240, vCores:5>running true active: true isLeafQueue():true
2016-10-14 07:52:39,699 INFO org.apache.hadoop.yarn.server.resourcemanager.scheduler.fair.FSAppAttempt: appattempt_1476452954783_0001_000001 minReqResource: <memory:24576, vCores:12> flexibleResource: <memory:8192, vCores:4>
2016-10-14 07:52:39,699 INFO org.apache.hadoop.yarn.server.resourcemanager.scheduler.fair.FairScheduler: [admission control] getFlexibleResource <memory:8192, vCores:4>
2016-10-14 07:52:39,699 INFO org.apache.hadoop.yarn.server.resourcemanager.scheduler.fair.FairScheduler: app appattempt_1476452954783_0001_000001 in queue root.interactive0 isRunning: true
2016-10-14 07:52:39,701 INFO org.apache.hadoop.yarn.server.resourcemanager.rmcontainer.RMContainerImpl: Processing container_1476452954783_0001_01_000023 of event ACQUIRED
2016-10-14 07:52:39,701 INFO org.apache.hadoop.yarn.server.resourcemanager.rmcontainer.RMContainerImpl: container_1476452954783_0001_01_000023 Container Transitioned from ALLOCATED to ACQUIRED
2016-10-14 07:52:39,991 INFO org.apache.hadoop.yarn.server.resourcemanager.rmcontainer.RMContainerImpl: Processing container_1476452954783_0001_01_000023 of event LAUNCHED
2016-10-14 07:52:39,991 INFO org.apache.hadoop.yarn.server.resourcemanager.rmcontainer.RMContainerImpl: container_1476452954783_0001_01_000023 Container Transitioned from ACQUIRED to RUNNING
2016-10-14 07:52:39,991 INFO org.apache.hadoop.yarn.server.resourcemanager.rmcontainer.RMContainerImpl: Processing container_1476452954783_0002_01_000007 of event FINISHED
2016-10-14 07:52:39,991 INFO org.apache.hadoop.yarn.server.resourcemanager.rmcontainer.RMContainerImpl: container_1476452954783_0002_01_000007 Container Transitioned from RUNNING to COMPLETED
2016-10-14 07:52:39,991 INFO org.apache.hadoop.yarn.server.resourcemanager.scheduler.fair.FSAppAttempt: Completed container: container_1476452954783_0002_01_000007 in state: COMPLETED event:FINISHED
2016-10-14 07:52:39,991 INFO org.apache.hadoop.yarn.server.resourcemanager.RMAuditLogger: USER=tanle	OPERATION=AM Released Container	TARGET=SchedulerApp	RESULT=SUCCESS	APPID=application_1476452954783_0002	CONTAINERID=container_1476452954783_0002_01_000007
2016-10-14 07:52:39,991 INFO org.apache.hadoop.yarn.server.resourcemanager.scheduler.SchedulerNode: Released container container_1476452954783_0002_01_000007 of capacity <memory:2048, vCores:1> on host cp-1.yarn-perf.yarnrm-PG0.wisc.cloudlab.us:36424, which currently has 3 containers, <memory:6144, vCores:3> used and <memory:2048, vCores:1> available, release resources=true
2016-10-14 07:52:39,992 INFO org.apache.hadoop.yarn.server.resourcemanager.scheduler.fair.FairScheduler: Application attempt appattempt_1476452954783_0002_000001 released container container_1476452954783_0002_01_000007 on node: host: cp-1.yarn-perf.yarnrm-PG0.wisc.cloudlab.us:36424 #containers=3 available=<memory:2048, vCores:1> used=<memory:6144, vCores:3> with event: FINISHED
2016-10-14 07:52:39,992 INFO org.apache.hadoop.yarn.server.resourcemanager.scheduler.fair.FSAppAttempt: assignContainer(FSSchedulerNode node:cp-1.yarn-perf.yarnrm-PG0.wisc.cloudlab.us, boolean reserved=false) for appattempt_1476452954783_0004_000001
2016-10-14 07:52:39,993 INFO org.apache.hadoop.yarn.server.resourcemanager.scheduler.fair.FSAppAttempt: assignContainer(FSSchedulerNode node:cp-1.yarn-perf.yarnrm-PG0.wisc.cloudlab.us, boolean reserved=false) for appattempt_1476452954783_0001_000001
2016-10-14 07:52:39,993 INFO org.apache.hadoop.yarn.server.resourcemanager.scheduler.fair.FSAppAttempt: allocate container: container_1476452954783_0001_01_000024 priority 1
2016-10-14 07:52:39,993 INFO org.apache.hadoop.yarn.server.resourcemanager.rmcontainer.RMContainerImpl: Processing container_1476452954783_0001_01_000024 of event START
2016-10-14 07:52:39,993 INFO org.apache.hadoop.yarn.server.resourcemanager.rmcontainer.RMContainerImpl: container_1476452954783_0001_01_000024 Container Transitioned from NEW to ALLOCATED
2016-10-14 07:52:39,993 INFO org.apache.hadoop.yarn.server.resourcemanager.RMAuditLogger: USER=tanle	OPERATION=AM Allocated Container	TARGET=SchedulerApp	RESULT=SUCCESS	APPID=application_1476452954783_0001	CONTAINERID=container_1476452954783_0001_01_000024
2016-10-14 07:52:39,993 INFO org.apache.hadoop.yarn.server.resourcemanager.scheduler.SchedulerNode: Assigned container container_1476452954783_0001_01_000024 of capacity <memory:2048, vCores:1> on host cp-1.yarn-perf.yarnrm-PG0.wisc.cloudlab.us:36424, which has 4 containers, <memory:8192, vCores:4> used and <memory:0, vCores:0> available after allocation
2016-10-14 07:52:40,005 INFO org.apache.hadoop.yarn.server.resourcemanager.scheduler.fair.FairScheduler: allocate(appattempt_1476452954783_0002_000001 [] [] [] []
2016-10-14 07:52:40,005 INFO org.apache.hadoop.yarn.server.resourcemanager.scheduler.fair.FSAppAttempt: root.interactive0 getMinReq:<memory:24576, vCores:12> demand: <memory:1050624, vCores:513> usage: <memory:24576, vCores:12>running true active: true isLeafQueue():true
2016-10-14 07:52:40,005 INFO org.apache.hadoop.yarn.server.resourcemanager.scheduler.fair.FSAppAttempt: root.batch0 getMinReq:<memory:0, vCores:0> demand: <memory:1050624, vCores:513> usage: <memory:8192, vCores:4>running true active: true isLeafQueue():true
2016-10-14 07:52:40,005 INFO org.apache.hadoop.yarn.server.resourcemanager.scheduler.fair.FSAppAttempt: appattempt_1476452954783_0002_000001 minReqResource: <memory:24576, vCores:12> flexibleResource: <memory:8192, vCores:4>
2016-10-14 07:52:40,005 INFO org.apache.hadoop.yarn.server.resourcemanager.scheduler.fair.FairScheduler: [admission control] getFlexibleResource <memory:8192, vCores:4>
2016-10-14 07:52:40,689 INFO org.apache.hadoop.yarn.server.resourcemanager.rmapp.attempt.RMAppAttemptImpl: ScheduleTransition.transition(appattempt_1476452954783_0004_000001,EventType: ATTEMPT_ADDED)
2016-10-14 07:52:40,689 INFO org.apache.hadoop.yarn.server.resourcemanager.scheduler.fair.FairScheduler: allocate(appattempt_1476452954783_0004_000001 [{Priority: 0, Capability: <memory:2048, vCores:1>, # Containers: 1, Location: *, Relax Locality: true}] [] null null
2016-10-14 07:52:40,689 INFO org.apache.hadoop.yarn.server.resourcemanager.scheduler.fair.FSAppAttempt: root.interactive0 getMinReq:<memory:24576, vCores:12> demand: <memory:1050624, vCores:513> usage: <memory:24576, vCores:12>running true active: true isLeafQueue():true
2016-10-14 07:52:40,690 INFO org.apache.hadoop.yarn.server.resourcemanager.scheduler.fair.FSAppAttempt: root.batch0 getMinReq:<memory:0, vCores:0> demand: <memory:1048576, vCores:512> usage: <memory:8192, vCores:4>running true active: true isLeafQueue():true
2016-10-14 07:52:40,690 INFO org.apache.hadoop.yarn.server.resourcemanager.scheduler.fair.FSAppAttempt: appattempt_1476452954783_0004_000001 minReqResource: <memory:24576, vCores:12> flexibleResource: <memory:8192, vCores:4>
2016-10-14 07:52:40,690 INFO org.apache.hadoop.yarn.server.resourcemanager.scheduler.fair.FairScheduler: [admission control] getFlexibleResource <memory:8192, vCores:4>
2016-10-14 07:52:40,690 INFO org.apache.hadoop.yarn.server.resourcemanager.scheduler.fair.FairScheduler: app appattempt_1476452954783_0004_000001 in queue root.interactive1 isRunning: false
2016-10-14 07:52:40,690 INFO org.apache.hadoop.yarn.server.resourcemanager.scheduler.fair.FairScheduler: [admission control] Cannot allocate appattempt_1476452954783_0004_000001 because there is NO flexible resource left
2016-10-14 07:52:40,691 INFO org.apache.hadoop.yarn.server.resourcemanager.scheduler.fair.FairScheduler: allocate(appattempt_1476452954783_0002_000001 [{Priority: 1, Capability: <memory:1920, vCores:1>, # Containers: 1020, Location: *, Relax Locality: true}] [] [] []
2016-10-14 07:52:40,691 INFO org.apache.hadoop.yarn.server.resourcemanager.scheduler.fair.FSAppAttempt: root.interactive0 getMinReq:<memory:24576, vCores:12> demand: <memory:1050624, vCores:513> usage: <memory:24576, vCores:12>running true active: true isLeafQueue():true
2016-10-14 07:52:40,691 INFO org.apache.hadoop.yarn.server.resourcemanager.scheduler.fair.FSAppAttempt: root.batch0 getMinReq:<memory:0, vCores:0> demand: <memory:1048576, vCores:512> usage: <memory:8192, vCores:4>running true active: true isLeafQueue():true
2016-10-14 07:52:40,691 INFO org.apache.hadoop.yarn.server.resourcemanager.scheduler.fair.FSAppAttempt: appattempt_1476452954783_0002_000001 minReqResource: <memory:24576, vCores:12> flexibleResource: <memory:8192, vCores:4>
2016-10-14 07:52:40,691 INFO org.apache.hadoop.yarn.server.resourcemanager.scheduler.fair.FairScheduler: [admission control] getFlexibleResource <memory:8192, vCores:4>
2016-10-14 07:52:40,895 INFO org.apache.hadoop.yarn.server.resourcemanager.scheduler.fair.FairScheduler: allocate(appattempt_1476452954783_0002_000001 [] [] [] []
2016-10-14 07:52:40,895 INFO org.apache.hadoop.yarn.server.resourcemanager.scheduler.fair.FSAppAttempt: root.interactive0 getMinReq:<memory:24576, vCores:12> demand: <memory:1050624, vCores:513> usage: <memory:24576, vCores:12>running true active: true isLeafQueue():true
2016-10-14 07:52:40,895 INFO org.apache.hadoop.yarn.server.resourcemanager.scheduler.fair.FSAppAttempt: root.batch0 getMinReq:<memory:0, vCores:0> demand: <memory:1048576, vCores:512> usage: <memory:8192, vCores:4>running true active: true isLeafQueue():true
2016-10-14 07:52:40,895 INFO org.apache.hadoop.yarn.server.resourcemanager.scheduler.fair.FSAppAttempt: appattempt_1476452954783_0002_000001 minReqResource: <memory:24576, vCores:12> flexibleResource: <memory:8192, vCores:4>
2016-10-14 07:52:40,895 INFO org.apache.hadoop.yarn.server.resourcemanager.scheduler.fair.FairScheduler: [admission control] getFlexibleResource <memory:8192, vCores:4>
2016-10-14 07:52:40,994 INFO org.apache.hadoop.yarn.server.resourcemanager.scheduler.fair.FSAppAttempt: assignContainer(FSSchedulerNode node:cp-1.yarn-perf.yarnrm-PG0.wisc.cloudlab.us, boolean reserved=false) for appattempt_1476452954783_0004_000001
2016-10-14 07:52:40,995 INFO org.apache.hadoop.yarn.server.resourcemanager.scheduler.fair.FSAppAttempt: assignContainer(FSSchedulerNode node:cp-1.yarn-perf.yarnrm-PG0.wisc.cloudlab.us, boolean reserved=false) for appattempt_1476452954783_0001_000001
2016-10-14 07:52:40,995 INFO org.apache.hadoop.yarn.server.resourcemanager.scheduler.fair.FSAppAttempt: Making reservation: node=cp-1.yarn-perf.yarnrm-PG0.wisc.cloudlab.us app_id=application_1476452954783_0001
2016-10-14 07:52:40,995 INFO org.apache.hadoop.yarn.server.resourcemanager.rmcontainer.RMContainerImpl: Processing container_1476452954783_0001_01_000025 of event RESERVED
2016-10-14 07:52:40,995 INFO org.apache.hadoop.yarn.server.resourcemanager.rmcontainer.RMContainerImpl: container_1476452954783_0001_01_000025 Container Transitioned from NEW to RESERVED
2016-10-14 07:52:40,995 INFO org.apache.hadoop.yarn.server.resourcemanager.scheduler.fair.FSSchedulerNode: Reserved container container_1476452954783_0001_01_000025 on node host: cp-1.yarn-perf.yarnrm-PG0.wisc.cloudlab.us:36424 #containers=4 available=<memory:0, vCores:0> used=<memory:8192, vCores:4> for application org.apache.hadoop.yarn.server.resourcemanager.scheduler.fair.FSAppAttempt@13f22e88
2016-10-14 07:52:41,299 INFO org.apache.hadoop.yarn.server.resourcemanager.scheduler.fair.FairScheduler: allocate(appattempt_1476452954783_0002_000001 [] [] [] []
2016-10-14 07:52:41,299 INFO org.apache.hadoop.yarn.server.resourcemanager.scheduler.fair.FSAppAttempt: root.interactive0 getMinReq:<memory:24576, vCores:12> demand: <memory:1050624, vCores:513> usage: <memory:24576, vCores:12>running true active: true isLeafQueue():true
2016-10-14 07:52:41,299 INFO org.apache.hadoop.yarn.server.resourcemanager.scheduler.fair.FSAppAttempt: root.batch0 getMinReq:<memory:0, vCores:0> demand: <memory:2099200, vCores:1025> usage: <memory:8192, vCores:4>running true active: true isLeafQueue():true
2016-10-14 07:52:41,299 INFO org.apache.hadoop.yarn.server.resourcemanager.scheduler.fair.FSAppAttempt: appattempt_1476452954783_0002_000001 minReqResource: <memory:24576, vCores:12> flexibleResource: <memory:8192, vCores:4>
2016-10-14 07:52:41,299 INFO org.apache.hadoop.yarn.server.resourcemanager.scheduler.fair.FairScheduler: [admission control] getFlexibleResource <memory:8192, vCores:4>
2016-10-14 07:52:41,690 INFO org.apache.hadoop.yarn.server.resourcemanager.scheduler.fair.FairScheduler: allocate(appattempt_1476452954783_0001_000001 [{Priority: 1, Capability: <memory:1920, vCores:1>, # Containers: 1013, Location: *, Relax Locality: true}] [] [] []
2016-10-14 07:52:41,690 INFO org.apache.hadoop.yarn.server.resourcemanager.scheduler.fair.FSAppAttempt: root.interactive0 getMinReq:<memory:24576, vCores:12> demand: <memory:1050624, vCores:513> usage: <memory:24576, vCores:12>running true active: true isLeafQueue():true
2016-10-14 07:52:41,690 INFO org.apache.hadoop.yarn.server.resourcemanager.scheduler.fair.FSAppAttempt: root.batch0 getMinReq:<memory:0, vCores:0> demand: <memory:2099200, vCores:1025> usage: <memory:8192, vCores:4>running true active: true isLeafQueue():true
2016-10-14 07:52:41,690 INFO org.apache.hadoop.yarn.server.resourcemanager.scheduler.fair.FSAppAttempt: appattempt_1476452954783_0001_000001 minReqResource: <memory:24576, vCores:12> flexibleResource: <memory:8192, vCores:4>
2016-10-14 07:52:41,690 INFO org.apache.hadoop.yarn.server.resourcemanager.scheduler.fair.FairScheduler: [admission control] getFlexibleResource <memory:8192, vCores:4>
2016-10-14 07:52:41,690 INFO org.apache.hadoop.yarn.server.resourcemanager.scheduler.fair.FairScheduler: app appattempt_1476452954783_0001_000001 in queue root.interactive0 isRunning: true
2016-10-14 07:52:41,691 INFO org.apache.hadoop.yarn.server.resourcemanager.rmapp.attempt.RMAppAttemptImpl: ScheduleTransition.transition(appattempt_1476452954783_0004_000001,EventType: ATTEMPT_ADDED)
2016-10-14 07:52:41,691 INFO org.apache.hadoop.yarn.server.resourcemanager.scheduler.fair.FairScheduler: allocate(appattempt_1476452954783_0004_000001 [{Priority: 0, Capability: <memory:2048, vCores:1>, # Containers: 1, Location: *, Relax Locality: true}] [] null null
2016-10-14 07:52:41,691 INFO org.apache.hadoop.yarn.server.resourcemanager.scheduler.fair.FSAppAttempt: root.interactive0 getMinReq:<memory:24576, vCores:12> demand: <memory:1050624, vCores:513> usage: <memory:24576, vCores:12>running true active: true isLeafQueue():true
2016-10-14 07:52:41,691 INFO org.apache.hadoop.yarn.server.resourcemanager.scheduler.fair.FSAppAttempt: root.batch0 getMinReq:<memory:0, vCores:0> demand: <memory:2099200, vCores:1025> usage: <memory:8192, vCores:4>running true active: true isLeafQueue():true
2016-10-14 07:52:41,691 INFO org.apache.hadoop.yarn.server.resourcemanager.scheduler.fair.FSAppAttempt: appattempt_1476452954783_0004_000001 minReqResource: <memory:24576, vCores:12> flexibleResource: <memory:8192, vCores:4>
2016-10-14 07:52:41,691 INFO org.apache.hadoop.yarn.server.resourcemanager.scheduler.fair.FairScheduler: [admission control] getFlexibleResource <memory:8192, vCores:4>
2016-10-14 07:52:41,691 INFO org.apache.hadoop.yarn.server.resourcemanager.scheduler.fair.FairScheduler: app appattempt_1476452954783_0004_000001 in queue root.interactive1 isRunning: false
2016-10-14 07:52:41,691 INFO org.apache.hadoop.yarn.server.resourcemanager.scheduler.fair.FairScheduler: [admission control] Cannot allocate appattempt_1476452954783_0004_000001 because there is NO flexible resource left
2016-10-14 07:52:41,693 INFO org.apache.hadoop.yarn.server.resourcemanager.rmcontainer.RMContainerImpl: Processing container_1476452954783_0001_01_000024 of event ACQUIRED
2016-10-14 07:52:41,693 INFO org.apache.hadoop.yarn.server.resourcemanager.rmcontainer.RMContainerImpl: container_1476452954783_0001_01_000024 Container Transitioned from ALLOCATED to ACQUIRED
2016-10-14 07:52:41,899 INFO org.apache.hadoop.yarn.server.resourcemanager.scheduler.fair.FairScheduler: allocate(appattempt_1476452954783_0001_000001 [{Priority: 1, Capability: <memory:1920, vCores:1>, # Containers: 1012, Location: *, Relax Locality: true}] [] [] []
2016-10-14 07:52:41,899 INFO org.apache.hadoop.yarn.server.resourcemanager.scheduler.fair.FSAppAttempt: root.interactive0 getMinReq:<memory:24576, vCores:12> demand: <memory:1050624, vCores:513> usage: <memory:24576, vCores:12>running true active: true isLeafQueue():true
2016-10-14 07:52:41,899 INFO org.apache.hadoop.yarn.server.resourcemanager.scheduler.fair.FSAppAttempt: root.batch0 getMinReq:<memory:0, vCores:0> demand: <memory:2099200, vCores:1025> usage: <memory:8192, vCores:4>running true active: true isLeafQueue():true
2016-10-14 07:52:41,899 INFO org.apache.hadoop.yarn.server.resourcemanager.scheduler.fair.FSAppAttempt: appattempt_1476452954783_0001_000001 minReqResource: <memory:24576, vCores:12> flexibleResource: <memory:8192, vCores:4>
2016-10-14 07:52:41,899 INFO org.apache.hadoop.yarn.server.resourcemanager.scheduler.fair.FairScheduler: [admission control] getFlexibleResource <memory:8192, vCores:4>
2016-10-14 07:52:41,899 INFO org.apache.hadoop.yarn.server.resourcemanager.scheduler.fair.FairScheduler: app appattempt_1476452954783_0001_000001 in queue root.interactive0 isRunning: true
2016-10-14 07:52:41,997 INFO org.apache.hadoop.yarn.server.resourcemanager.rmcontainer.RMContainerImpl: Processing container_1476452954783_0001_01_000024 of event LAUNCHED
2016-10-14 07:52:41,998 INFO org.apache.hadoop.yarn.server.resourcemanager.rmcontainer.RMContainerImpl: container_1476452954783_0001_01_000024 Container Transitioned from ACQUIRED to RUNNING
2016-10-14 07:52:42,102 INFO org.apache.hadoop.yarn.server.resourcemanager.scheduler.fair.FairScheduler: allocate(appattempt_1476452954783_0002_000001 [] [] [] []
2016-10-14 07:52:42,102 INFO org.apache.hadoop.yarn.server.resourcemanager.scheduler.fair.FSAppAttempt: root.interactive0 getMinReq:<memory:24576, vCores:12> demand: <memory:2097152, vCores:1024> usage: <memory:24576, vCores:12>running true active: true isLeafQueue():true
2016-10-14 07:52:42,103 INFO org.apache.hadoop.yarn.server.resourcemanager.scheduler.fair.FSAppAttempt: root.batch0 getMinReq:<memory:0, vCores:0> demand: <memory:2099200, vCores:1025> usage: <memory:8192, vCores:4>running true active: true isLeafQueue():true
2016-10-14 07:52:42,103 INFO org.apache.hadoop.yarn.server.resourcemanager.scheduler.fair.FSAppAttempt: appattempt_1476452954783_0002_000001 minReqResource: <memory:24576, vCores:12> flexibleResource: <memory:8192, vCores:4>
2016-10-14 07:52:42,103 INFO org.apache.hadoop.yarn.server.resourcemanager.scheduler.fair.FairScheduler: [admission control] getFlexibleResource <memory:8192, vCores:4>
2016-10-14 07:52:42,302 INFO org.apache.hadoop.yarn.server.resourcemanager.scheduler.fair.FairScheduler: allocate(appattempt_1476452954783_0001_000001 [] [] [] []
2016-10-14 07:52:42,302 INFO org.apache.hadoop.yarn.server.resourcemanager.scheduler.fair.FSAppAttempt: root.interactive0 getMinReq:<memory:24576, vCores:12> demand: <memory:2097152, vCores:1024> usage: <memory:24576, vCores:12>running true active: true isLeafQueue():true
2016-10-14 07:52:42,303 INFO org.apache.hadoop.yarn.server.resourcemanager.scheduler.fair.FSAppAttempt: root.batch0 getMinReq:<memory:0, vCores:0> demand: <memory:2099200, vCores:1025> usage: <memory:8192, vCores:4>running true active: true isLeafQueue():true
2016-10-14 07:52:42,303 INFO org.apache.hadoop.yarn.server.resourcemanager.scheduler.fair.FSAppAttempt: appattempt_1476452954783_0001_000001 minReqResource: <memory:24576, vCores:12> flexibleResource: <memory:8192, vCores:4>
2016-10-14 07:52:42,303 INFO org.apache.hadoop.yarn.server.resourcemanager.scheduler.fair.FairScheduler: [admission control] getFlexibleResource <memory:8192, vCores:4>
2016-10-14 07:52:42,303 INFO org.apache.hadoop.yarn.server.resourcemanager.scheduler.fair.FairScheduler: app appattempt_1476452954783_0001_000001 in queue root.interactive0 isRunning: true
2016-10-14 07:52:42,692 INFO org.apache.hadoop.yarn.server.resourcemanager.rmapp.attempt.RMAppAttemptImpl: ScheduleTransition.transition(appattempt_1476452954783_0004_000001,EventType: ATTEMPT_ADDED)
2016-10-14 07:52:42,693 INFO org.apache.hadoop.yarn.server.resourcemanager.scheduler.fair.FairScheduler: allocate(appattempt_1476452954783_0004_000001 [{Priority: 0, Capability: <memory:2048, vCores:1>, # Containers: 1, Location: *, Relax Locality: true}] [] null null
2016-10-14 07:52:42,693 INFO org.apache.hadoop.yarn.server.resourcemanager.scheduler.fair.FSAppAttempt: root.interactive0 getMinReq:<memory:24576, vCores:12> demand: <memory:2097152, vCores:1024> usage: <memory:24576, vCores:12>running true active: true isLeafQueue():true
2016-10-14 07:52:42,693 INFO org.apache.hadoop.yarn.server.resourcemanager.scheduler.fair.FSAppAttempt: root.batch0 getMinReq:<memory:0, vCores:0> demand: <memory:2099200, vCores:1025> usage: <memory:8192, vCores:4>running true active: true isLeafQueue():true
2016-10-14 07:52:42,693 INFO org.apache.hadoop.yarn.server.resourcemanager.scheduler.fair.FSAppAttempt: appattempt_1476452954783_0004_000001 minReqResource: <memory:24576, vCores:12> flexibleResource: <memory:8192, vCores:4>
2016-10-14 07:52:42,693 INFO org.apache.hadoop.yarn.server.resourcemanager.scheduler.fair.FairScheduler: [admission control] getFlexibleResource <memory:8192, vCores:4>
2016-10-14 07:52:42,693 INFO org.apache.hadoop.yarn.server.resourcemanager.scheduler.fair.FairScheduler: app appattempt_1476452954783_0004_000001 in queue root.interactive1 isRunning: false
2016-10-14 07:52:42,693 INFO org.apache.hadoop.yarn.server.resourcemanager.scheduler.fair.FairScheduler: [admission control] Cannot allocate appattempt_1476452954783_0004_000001 because there is NO flexible resource left
2016-10-14 07:52:43,106 INFO org.apache.hadoop.yarn.server.resourcemanager.scheduler.fair.FairScheduler: allocate(appattempt_1476452954783_0001_000001 [] [] [] []
2016-10-14 07:52:43,107 INFO org.apache.hadoop.yarn.server.resourcemanager.scheduler.fair.FSAppAttempt: root.interactive0 getMinReq:<memory:24576, vCores:12> demand: <memory:2097152, vCores:1024> usage: <memory:24576, vCores:12>running true active: true isLeafQueue():true
2016-10-14 07:52:43,107 INFO org.apache.hadoop.yarn.server.resourcemanager.scheduler.fair.FSAppAttempt: root.batch0 getMinReq:<memory:0, vCores:0> demand: <memory:2099200, vCores:1025> usage: <memory:8192, vCores:4>running true active: true isLeafQueue():true
2016-10-14 07:52:43,107 INFO org.apache.hadoop.yarn.server.resourcemanager.scheduler.fair.FSAppAttempt: appattempt_1476452954783_0001_000001 minReqResource: <memory:24576, vCores:12> flexibleResource: <memory:8192, vCores:4>
2016-10-14 07:52:43,107 INFO org.apache.hadoop.yarn.server.resourcemanager.scheduler.fair.FairScheduler: [admission control] getFlexibleResource <memory:8192, vCores:4>
2016-10-14 07:52:43,107 INFO org.apache.hadoop.yarn.server.resourcemanager.scheduler.fair.FairScheduler: app appattempt_1476452954783_0001_000001 in queue root.interactive0 isRunning: true
2016-10-14 07:52:43,695 INFO org.apache.hadoop.yarn.server.resourcemanager.rmapp.attempt.RMAppAttemptImpl: ScheduleTransition.transition(appattempt_1476452954783_0004_000001,EventType: ATTEMPT_ADDED)
2016-10-14 07:52:43,695 INFO org.apache.hadoop.yarn.server.resourcemanager.scheduler.fair.FairScheduler: allocate(appattempt_1476452954783_0004_000001 [{Priority: 0, Capability: <memory:2048, vCores:1>, # Containers: 1, Location: *, Relax Locality: true}] [] null null
2016-10-14 07:52:43,695 INFO org.apache.hadoop.yarn.server.resourcemanager.scheduler.fair.FSAppAttempt: root.interactive0 getMinReq:<memory:24576, vCores:12> demand: <memory:2097152, vCores:1024> usage: <memory:24576, vCores:12>running true active: true isLeafQueue():true
2016-10-14 07:52:43,695 INFO org.apache.hadoop.yarn.server.resourcemanager.scheduler.fair.FSAppAttempt: root.batch0 getMinReq:<memory:0, vCores:0> demand: <memory:2099200, vCores:1025> usage: <memory:8192, vCores:4>running true active: true isLeafQueue():true
2016-10-14 07:52:43,695 INFO org.apache.hadoop.yarn.server.resourcemanager.scheduler.fair.FSAppAttempt: appattempt_1476452954783_0004_000001 minReqResource: <memory:24576, vCores:12> flexibleResource: <memory:8192, vCores:4>
2016-10-14 07:52:43,695 INFO org.apache.hadoop.yarn.server.resourcemanager.scheduler.fair.FairScheduler: [admission control] getFlexibleResource <memory:8192, vCores:4>
2016-10-14 07:52:43,695 INFO org.apache.hadoop.yarn.server.resourcemanager.scheduler.fair.FairScheduler: app appattempt_1476452954783_0004_000001 in queue root.interactive1 isRunning: false
2016-10-14 07:52:43,695 INFO org.apache.hadoop.yarn.server.resourcemanager.scheduler.fair.FairScheduler: [admission control] Cannot allocate appattempt_1476452954783_0004_000001 because there is NO flexible resource left
2016-10-14 07:52:43,706 INFO org.apache.hadoop.yarn.server.resourcemanager.scheduler.fair.FairScheduler: allocate(appattempt_1476452954783_0002_000001 [] [] [] []
2016-10-14 07:52:43,706 INFO org.apache.hadoop.yarn.server.resourcemanager.scheduler.fair.FSAppAttempt: root.interactive0 getMinReq:<memory:24576, vCores:12> demand: <memory:2097152, vCores:1024> usage: <memory:24576, vCores:12>running true active: true isLeafQueue():true
2016-10-14 07:52:43,706 INFO org.apache.hadoop.yarn.server.resourcemanager.scheduler.fair.FSAppAttempt: root.batch0 getMinReq:<memory:0, vCores:0> demand: <memory:2099200, vCores:1025> usage: <memory:8192, vCores:4>running true active: true isLeafQueue():true
2016-10-14 07:52:43,706 INFO org.apache.hadoop.yarn.server.resourcemanager.scheduler.fair.FSAppAttempt: appattempt_1476452954783_0002_000001 minReqResource: <memory:24576, vCores:12> flexibleResource: <memory:8192, vCores:4>
2016-10-14 07:52:43,706 INFO org.apache.hadoop.yarn.server.resourcemanager.scheduler.fair.FairScheduler: [admission control] getFlexibleResource <memory:8192, vCores:4>
2016-10-14 07:52:43,758 INFO org.apache.hadoop.yarn.server.resourcemanager.scheduler.fair.FairScheduler: allocate(appattempt_1476452954783_0001_000001 [] [] [] []
2016-10-14 07:52:43,758 INFO org.apache.hadoop.yarn.server.resourcemanager.scheduler.fair.FSAppAttempt: root.interactive0 getMinReq:<memory:24576, vCores:12> demand: <memory:2097152, vCores:1024> usage: <memory:24576, vCores:12>running true active: true isLeafQueue():true
2016-10-14 07:52:43,758 INFO org.apache.hadoop.yarn.server.resourcemanager.scheduler.fair.FSAppAttempt: root.batch0 getMinReq:<memory:0, vCores:0> demand: <memory:2099200, vCores:1025> usage: <memory:8192, vCores:4>running true active: true isLeafQueue():true
2016-10-14 07:52:43,758 INFO org.apache.hadoop.yarn.server.resourcemanager.scheduler.fair.FSAppAttempt: appattempt_1476452954783_0001_000001 minReqResource: <memory:24576, vCores:12> flexibleResource: <memory:8192, vCores:4>
2016-10-14 07:52:43,758 INFO org.apache.hadoop.yarn.server.resourcemanager.scheduler.fair.FairScheduler: [admission control] getFlexibleResource <memory:8192, vCores:4>
