2016-08-19 14:41:08,005 INFO org.apache.hadoop.yarn.server.resourcemanager.ResourceManager: STARTUP_MSG: 
/************************************************************
STARTUP_MSG: Starting ResourceManager
STARTUP_MSG:   host = nm.yarn-perf.yarnrm-pg0.wisc.cloudlab.us/128.104.222.71
STARTUP_MSG:   args = []
STARTUP_MSG:   version = 2.7.2
STARTUP_MSG:   build = https://github.com/lenhattan86/ccra.git -r 07a4902a55d9653a05078c9fe2a351f93e192903; compiled by 'tanle' on 2016-08-19T20:31Z
STARTUP_MSG:   java = 1.7.0_80
************************************************************/
2016-08-19 14:41:08,018 INFO org.apache.hadoop.yarn.server.resourcemanager.ResourceManager: registered UNIX signal handlers for [TERM, HUP, INT]
2016-08-19 14:41:08,388 INFO org.apache.hadoop.conf.Configuration: found resource core-site.xml at file:/users/tanle/hadoop/etc/hadoop/core-site.xml
2016-08-19 14:41:08,523 WARN org.apache.hadoop.util.NativeCodeLoader: Unable to load native-hadoop library for your platform... using builtin-java classes where applicable
2016-08-19 14:41:08,562 INFO org.apache.hadoop.security.Groups: clearing userToGroupsMap cache
2016-08-19 14:41:08,641 INFO org.apache.hadoop.conf.Configuration: found resource yarn-site.xml at file:/users/tanle/hadoop/etc/hadoop/yarn-site.xml
2016-08-19 14:41:08,852 INFO org.apache.hadoop.yarn.event.AsyncDispatcher: Registering class org.apache.hadoop.yarn.server.resourcemanager.RMFatalEventType for class org.apache.hadoop.yarn.server.resourcemanager.ResourceManager$RMFatalEventDispatcher
2016-08-19 14:41:09,024 INFO org.apache.hadoop.yarn.server.resourcemanager.security.NMTokenSecretManagerInRM: NMTokenKeyRollingInterval: 86400000ms and NMTokenKeyActivationDelay: 900000ms
2016-08-19 14:41:09,028 INFO org.apache.hadoop.yarn.server.resourcemanager.security.RMContainerTokenSecretManager: ContainerTokenKeyRollingInterval: 86400000ms and ContainerTokenKeyActivationDelay: 900000ms
2016-08-19 14:41:09,037 INFO org.apache.hadoop.yarn.server.resourcemanager.security.AMRMTokenSecretManager: AMRMTokenKeyRollingInterval: 86400000ms and AMRMTokenKeyActivationDelay: 900000 ms
2016-08-19 14:41:09,088 INFO org.apache.hadoop.yarn.event.AsyncDispatcher: Registering class org.apache.hadoop.yarn.server.resourcemanager.recovery.RMStateStoreEventType for class org.apache.hadoop.yarn.server.resourcemanager.recovery.RMStateStore$ForwardingEventHandler
2016-08-19 14:41:09,090 INFO org.apache.hadoop.yarn.event.AsyncDispatcher: Registering class org.apache.hadoop.yarn.server.resourcemanager.NodesListManagerEventType for class org.apache.hadoop.yarn.server.resourcemanager.NodesListManager
2016-08-19 14:41:09,090 INFO org.apache.hadoop.yarn.server.resourcemanager.ResourceManager: Using Scheduler: org.apache.hadoop.yarn.server.resourcemanager.scheduler.fair.FairScheduler
2016-08-19 14:41:09,131 INFO org.apache.hadoop.yarn.event.AsyncDispatcher: Registering class org.apache.hadoop.yarn.server.resourcemanager.scheduler.event.SchedulerEventType for class org.apache.hadoop.yarn.server.resourcemanager.ResourceManager$SchedulerEventDispatcher
2016-08-19 14:41:09,132 INFO org.apache.hadoop.yarn.event.AsyncDispatcher: Registering class org.apache.hadoop.yarn.server.resourcemanager.rmapp.RMAppEventType for class org.apache.hadoop.yarn.server.resourcemanager.ResourceManager$ApplicationEventDispatcher
2016-08-19 14:41:09,134 INFO org.apache.hadoop.yarn.event.AsyncDispatcher: Registering class org.apache.hadoop.yarn.server.resourcemanager.rmapp.attempt.RMAppAttemptEventType for class org.apache.hadoop.yarn.server.resourcemanager.ResourceManager$ApplicationAttemptEventDispatcher
2016-08-19 14:41:09,135 INFO org.apache.hadoop.yarn.event.AsyncDispatcher: Registering class org.apache.hadoop.yarn.server.resourcemanager.rmnode.RMNodeEventType for class org.apache.hadoop.yarn.server.resourcemanager.ResourceManager$NodeEventDispatcher
2016-08-19 14:41:09,205 INFO org.apache.hadoop.metrics2.impl.MetricsConfig: loaded properties from hadoop-metrics2.properties
2016-08-19 14:41:09,295 INFO org.apache.hadoop.metrics2.impl.MetricsSystemImpl: Scheduled snapshot period at 10 second(s).
2016-08-19 14:41:09,296 INFO org.apache.hadoop.metrics2.impl.MetricsSystemImpl: ResourceManager metrics system started
2016-08-19 14:41:09,316 INFO org.apache.hadoop.yarn.event.AsyncDispatcher: Registering class org.apache.hadoop.yarn.server.resourcemanager.RMAppManagerEventType for class org.apache.hadoop.yarn.server.resourcemanager.RMAppManager
2016-08-19 14:41:09,325 INFO org.apache.hadoop.yarn.event.AsyncDispatcher: Registering class org.apache.hadoop.yarn.server.resourcemanager.amlauncher.AMLauncherEventType for class org.apache.hadoop.yarn.server.resourcemanager.amlauncher.ApplicationMasterLauncher
2016-08-19 14:41:09,328 INFO org.apache.hadoop.yarn.server.resourcemanager.RMNMInfo: Registered RMNMInfo MBean
2016-08-19 14:41:09,330 INFO org.apache.hadoop.yarn.security.YarnAuthorizationProvider: org.apache.hadoop.yarn.security.ConfiguredYarnAuthorizer is instiantiated.
2016-08-19 14:41:09,331 INFO org.apache.hadoop.util.HostsFileReader: Refreshing hosts (include/exclude) list
2016-08-19 14:41:09,375 INFO org.apache.hadoop.yarn.server.resourcemanager.scheduler.fair.AllocationFileLoaderService: Loading allocation file /users/tanle/hadoop/etc/fair-scheduler.xml
2016-08-19 14:41:09,422 INFO org.apache.hadoop.yarn.server.resourcemanager.metrics.SystemMetricsPublisher: YARN system metrics publishing service is not enabled
2016-08-19 14:41:09,422 INFO org.apache.hadoop.yarn.server.resourcemanager.ResourceManager: Transitioning to active state
2016-08-19 14:41:09,436 INFO org.apache.hadoop.yarn.server.resourcemanager.recovery.RMStateStore: Updating AMRMToken
2016-08-19 14:41:09,436 INFO org.apache.hadoop.yarn.server.resourcemanager.security.RMContainerTokenSecretManager: Rolling master-key for container-tokens
2016-08-19 14:41:09,436 INFO org.apache.hadoop.yarn.server.resourcemanager.security.NMTokenSecretManagerInRM: Rolling master-key for nm-tokens
2016-08-19 14:41:09,436 INFO org.apache.hadoop.security.token.delegation.AbstractDelegationTokenSecretManager: Updating the current master key for generating delegation tokens
2016-08-19 14:41:09,437 INFO org.apache.hadoop.yarn.server.resourcemanager.security.RMDelegationTokenSecretManager: storing master key with keyID 1
2016-08-19 14:41:09,437 INFO org.apache.hadoop.yarn.server.resourcemanager.recovery.RMStateStore: Storing RMDTMasterKey.
2016-08-19 14:41:09,438 INFO org.apache.hadoop.security.token.delegation.AbstractDelegationTokenSecretManager: Starting expired delegation token remover thread, tokenRemoverScanInterval=60 min(s)
2016-08-19 14:41:09,438 INFO org.apache.hadoop.security.token.delegation.AbstractDelegationTokenSecretManager: Updating the current master key for generating delegation tokens
2016-08-19 14:41:09,439 INFO org.apache.hadoop.yarn.server.resourcemanager.security.RMDelegationTokenSecretManager: storing master key with keyID 2
2016-08-19 14:41:09,439 INFO org.apache.hadoop.yarn.server.resourcemanager.recovery.RMStateStore: Storing RMDTMasterKey.
2016-08-19 14:41:09,440 INFO org.apache.hadoop.yarn.event.AsyncDispatcher: Registering class org.apache.hadoop.yarn.nodelabels.event.NodeLabelsStoreEventType for class org.apache.hadoop.yarn.nodelabels.CommonNodeLabelsManager$ForwardingEventHandler
2016-08-19 14:41:09,469 INFO org.apache.hadoop.ipc.CallQueueManager: Using callQueue class java.util.concurrent.LinkedBlockingQueue
2016-08-19 14:41:09,482 INFO org.apache.hadoop.ipc.Server: Starting Socket Reader #1 for port 8031
2016-08-19 14:41:09,498 INFO org.apache.hadoop.yarn.factories.impl.pb.RpcServerFactoryPBImpl: Adding protocol org.apache.hadoop.yarn.server.api.ResourceTrackerPB to the server
2016-08-19 14:41:09,499 INFO org.apache.hadoop.ipc.Server: IPC Server Responder: starting
2016-08-19 14:41:09,499 INFO org.apache.hadoop.ipc.Server: IPC Server listener on 8031: starting
2016-08-19 14:41:09,564 INFO org.apache.hadoop.ipc.CallQueueManager: Using callQueue class java.util.concurrent.LinkedBlockingQueue
2016-08-19 14:41:09,570 INFO org.apache.hadoop.ipc.Server: Starting Socket Reader #1 for port 8030
2016-08-19 14:41:09,577 INFO org.apache.hadoop.yarn.factories.impl.pb.RpcServerFactoryPBImpl: Adding protocol org.apache.hadoop.yarn.api.ApplicationMasterProtocolPB to the server
2016-08-19 14:41:09,577 INFO org.apache.hadoop.ipc.Server: IPC Server Responder: starting
2016-08-19 14:41:09,577 INFO org.apache.hadoop.ipc.Server: IPC Server listener on 8030: starting
2016-08-19 14:41:09,630 INFO org.apache.hadoop.ipc.CallQueueManager: Using callQueue class java.util.concurrent.LinkedBlockingQueue
2016-08-19 14:41:09,630 INFO org.apache.hadoop.ipc.Server: Starting Socket Reader #1 for port 8032
2016-08-19 14:41:09,634 INFO org.apache.hadoop.yarn.factories.impl.pb.RpcServerFactoryPBImpl: Adding protocol org.apache.hadoop.yarn.api.ApplicationClientProtocolPB to the server
2016-08-19 14:41:09,634 INFO org.apache.hadoop.ipc.Server: IPC Server Responder: starting
2016-08-19 14:41:09,635 INFO org.apache.hadoop.ipc.Server: IPC Server listener on 8032: starting
2016-08-19 14:41:09,641 INFO org.apache.hadoop.yarn.server.resourcemanager.ResourceManager: Transitioned to active state
2016-08-19 14:41:09,719 INFO org.mortbay.log: Logging to org.slf4j.impl.Log4jLoggerAdapter(org.mortbay.log) via org.mortbay.log.Slf4jLog
2016-08-19 14:41:09,727 INFO org.apache.hadoop.security.authentication.server.AuthenticationFilter: Unable to initialize FileSignerSecretProvider, falling back to use random secrets.
2016-08-19 14:41:09,732 INFO org.apache.hadoop.http.HttpRequestLog: Http request log for http.requests.resourcemanager is not defined
2016-08-19 14:41:09,739 INFO org.apache.hadoop.http.HttpServer2: Added global filter 'safety' (class=org.apache.hadoop.http.HttpServer2$QuotingInputFilter)
2016-08-19 14:41:09,743 INFO org.apache.hadoop.http.HttpServer2: Added filter RMAuthenticationFilter (class=org.apache.hadoop.yarn.server.security.http.RMAuthenticationFilter) to context cluster
2016-08-19 14:41:09,743 INFO org.apache.hadoop.http.HttpServer2: Added filter RMAuthenticationFilter (class=org.apache.hadoop.yarn.server.security.http.RMAuthenticationFilter) to context logs
2016-08-19 14:41:09,743 INFO org.apache.hadoop.http.HttpServer2: Added filter RMAuthenticationFilter (class=org.apache.hadoop.yarn.server.security.http.RMAuthenticationFilter) to context static
2016-08-19 14:41:09,743 INFO org.apache.hadoop.http.HttpServer2: Added filter static_user_filter (class=org.apache.hadoop.http.lib.StaticUserWebFilter$StaticUserFilter) to context cluster
2016-08-19 14:41:09,744 INFO org.apache.hadoop.http.HttpServer2: Added filter static_user_filter (class=org.apache.hadoop.http.lib.StaticUserWebFilter$StaticUserFilter) to context logs
2016-08-19 14:41:09,744 INFO org.apache.hadoop.http.HttpServer2: Added filter static_user_filter (class=org.apache.hadoop.http.lib.StaticUserWebFilter$StaticUserFilter) to context static
2016-08-19 14:41:09,747 INFO org.apache.hadoop.http.HttpServer2: adding path spec: /cluster/*
2016-08-19 14:41:09,747 INFO org.apache.hadoop.http.HttpServer2: adding path spec: /ws/*
2016-08-19 14:41:10,090 INFO org.apache.hadoop.yarn.webapp.WebApps: Registered webapp guice modules
2016-08-19 14:41:10,092 INFO org.apache.hadoop.http.HttpServer2: Jetty bound to port 8088
2016-08-19 14:41:10,092 INFO org.mortbay.log: jetty-6.1.26
2016-08-19 14:41:10,112 INFO org.mortbay.log: Extract jar:file:/users/tanle/hadoop/share/hadoop/yarn/hadoop-yarn-common-2.7.2.jar!/webapps/cluster to /tmp/Jetty_nm_yarn.perf_yarnrm.pg0_wisc_cloudlab_us_8088_cluster____.pro683/webapp
2016-08-19 14:41:10,280 INFO org.apache.hadoop.security.token.delegation.AbstractDelegationTokenSecretManager: Updating the current master key for generating delegation tokens
2016-08-19 14:41:10,280 INFO org.apache.hadoop.security.token.delegation.AbstractDelegationTokenSecretManager: Starting expired delegation token remover thread, tokenRemoverScanInterval=60 min(s)
2016-08-19 14:41:10,280 INFO org.apache.hadoop.security.token.delegation.AbstractDelegationTokenSecretManager: Updating the current master key for generating delegation tokens
2016-08-19 14:41:10,807 INFO org.apache.hadoop.ipc.Server: IPC Server handler 0 on 8032, call org.apache.hadoop.yarn.api.ApplicationClientProtocolPB.getApplicationReport from 128.104.222.71:51538 Call#1017 Retry#0
org.apache.hadoop.yarn.exceptions.ApplicationNotFoundException: Application with id 'application_1471638045398_0006' doesn't exist in RM.
	at org.apache.hadoop.yarn.server.resourcemanager.ClientRMService.getApplicationReport(ClientRMService.java:327)
	at org.apache.hadoop.yarn.api.impl.pb.service.ApplicationClientProtocolPBServiceImpl.getApplicationReport(ApplicationClientProtocolPBServiceImpl.java:175)
	at org.apache.hadoop.yarn.proto.ApplicationClientProtocol$ApplicationClientProtocolService$2.callBlockingMethod(ApplicationClientProtocol.java:417)
	at org.apache.hadoop.ipc.ProtobufRpcEngine$Server$ProtoBufRpcInvoker.call(ProtobufRpcEngine.java:616)
	at org.apache.hadoop.ipc.RPC$Server.call(RPC.java:969)
	at org.apache.hadoop.ipc.Server$Handler$1.run(Server.java:2049)
	at org.apache.hadoop.ipc.Server$Handler$1.run(Server.java:2045)
	at java.security.AccessController.doPrivileged(Native Method)
	at javax.security.auth.Subject.doAs(Subject.java:415)
	at org.apache.hadoop.security.UserGroupInformation.doAs(UserGroupInformation.java:1657)
	at org.apache.hadoop.ipc.Server$Handler.run(Server.java:2045)
2016-08-19 14:41:11,332 INFO org.mortbay.log: Started HttpServer2$SelectChannelConnectorWithSafeStartup@nm.yarn-perf.yarnrm-pg0.wisc.cloudlab.us:8088
2016-08-19 14:41:11,333 INFO org.apache.hadoop.yarn.webapp.WebApps: Web app cluster started at 8088
2016-08-19 14:41:11,371 INFO org.apache.hadoop.ipc.CallQueueManager: Using callQueue class java.util.concurrent.LinkedBlockingQueue
2016-08-19 14:41:11,372 INFO org.apache.hadoop.ipc.Server: Starting Socket Reader #1 for port 8033
2016-08-19 14:41:11,376 INFO org.apache.hadoop.yarn.factories.impl.pb.RpcServerFactoryPBImpl: Adding protocol org.apache.hadoop.yarn.server.api.ResourceManagerAdministrationProtocolPB to the server
2016-08-19 14:41:11,376 INFO org.apache.hadoop.ipc.Server: IPC Server Responder: starting
2016-08-19 14:41:11,376 INFO org.apache.hadoop.ipc.Server: IPC Server listener on 8033: starting
2016-08-19 14:41:12,870 INFO org.apache.hadoop.yarn.util.RackResolver: Resolved cp-1.yarn-perf.yarnrm-PG0.wisc.cloudlab.us to /default-rack
2016-08-19 14:41:12,873 INFO org.apache.hadoop.yarn.server.resourcemanager.ResourceTrackerService: NodeManager from node cp-1.yarn-perf.yarnrm-PG0.wisc.cloudlab.us(cmPort: 33756 httpPort: 8042) registered with capability: <memory:8192, vCores:4>, assigned nodeId cp-1.yarn-perf.yarnrm-PG0.wisc.cloudlab.us:33756
2016-08-19 14:41:12,876 INFO org.apache.hadoop.yarn.server.resourcemanager.rmnode.RMNodeImpl: cp-1.yarn-perf.yarnrm-PG0.wisc.cloudlab.us:33756 Node Transitioned from NEW to RUNNING
2016-08-19 14:41:12,880 INFO org.apache.hadoop.yarn.server.resourcemanager.scheduler.fair.FairScheduler: Added node cp-1.yarn-perf.yarnrm-PG0.wisc.cloudlab.us:33756 cluster capacity: <memory:8192, vCores:4>
2016-08-19 14:41:13,018 INFO org.apache.hadoop.yarn.util.RackResolver: Resolved c220g1-031106.wisc.cloudlab.us to /default-rack
2016-08-19 14:41:13,018 INFO org.apache.hadoop.yarn.server.resourcemanager.ResourceTrackerService: NodeManager from node c220g1-031106.wisc.cloudlab.us(cmPort: 43516 httpPort: 8042) registered with capability: <memory:8192, vCores:4>, assigned nodeId c220g1-031106.wisc.cloudlab.us:43516
2016-08-19 14:41:13,018 INFO org.apache.hadoop.yarn.server.resourcemanager.rmnode.RMNodeImpl: c220g1-031106.wisc.cloudlab.us:43516 Node Transitioned from NEW to RUNNING
2016-08-19 14:41:13,021 INFO org.apache.hadoop.yarn.server.resourcemanager.scheduler.fair.FairScheduler: Added node c220g1-031106.wisc.cloudlab.us:43516 cluster capacity: <memory:16384, vCores:8>
2016-08-19 14:45:48,391 INFO org.apache.hadoop.yarn.server.resourcemanager.ClientRMService: Allocated new applicationId: 1
2016-08-19 14:45:58,178 WARN org.apache.hadoop.yarn.server.resourcemanager.rmapp.RMAppImpl: The specific max attempts: 0 for application: 1 is invalid, because it is out of the range [1, 2]. Use the global max attempts instead.
2016-08-19 14:45:58,180 INFO org.apache.hadoop.yarn.server.resourcemanager.ClientRMService: Application with id 1 submitted by user tanle
2016-08-19 14:45:58,180 INFO org.apache.hadoop.yarn.server.resourcemanager.rmapp.RMAppImpl: Storing application with id application_1471639269423_0001
2016-08-19 14:45:58,182 INFO org.apache.hadoop.yarn.server.resourcemanager.RMAuditLogger: USER=tanle	IP=128.104.222.71	OPERATION=Submit Application Request	TARGET=ClientRMService	RESULT=SUCCESS	APPID=application_1471639269423_0001
2016-08-19 14:45:58,192 INFO org.apache.hadoop.yarn.server.resourcemanager.rmapp.RMAppImpl: application_1471639269423_0001 State change from NEW to NEW_SAVING
2016-08-19 14:45:58,192 INFO org.apache.hadoop.yarn.server.resourcemanager.recovery.RMStateStore: Storing info for app: application_1471639269423_0001
2016-08-19 14:45:58,193 INFO org.apache.hadoop.yarn.server.resourcemanager.rmapp.RMAppImpl: application_1471639269423_0001 State change from NEW_SAVING to SUBMITTED
2016-08-19 14:45:58,205 INFO org.apache.hadoop.yarn.server.resourcemanager.scheduler.fair.FairScheduler: Accepted application application_1471639269423_0001 from user: tanle, in queue: batch, currently num of applications: 1
2016-08-19 14:45:58,234 INFO org.apache.hadoop.yarn.server.resourcemanager.rmapp.RMAppImpl: application_1471639269423_0001 State change from SUBMITTED to ACCEPTED
2016-08-19 14:45:58,274 INFO org.apache.hadoop.yarn.server.resourcemanager.ApplicationMasterService: Registering app attempt : appattempt_1471639269423_0001_000001
2016-08-19 14:45:58,275 INFO org.apache.hadoop.yarn.server.resourcemanager.rmapp.attempt.RMAppAttemptImpl: appattempt_1471639269423_0001_000001 State change from NEW to SUBMITTED
2016-08-19 14:45:58,297 INFO org.apache.hadoop.yarn.server.resourcemanager.scheduler.fair.FairScheduler: Added Application Attempt appattempt_1471639269423_0001_000001 to scheduler from user: tanle
2016-08-19 14:45:58,297 INFO org.apache.hadoop.yarn.server.resourcemanager.rmapp.attempt.RMAppAttemptImpl: ScheduleTransition.transition(appattempt_1471639269423_0001_000001,EventType: ATTEMPT_ADDED)
2016-08-19 14:45:58,298 INFO org.apache.hadoop.yarn.server.resourcemanager.scheduler.fair.FairScheduler: allocate(appattempt_1471639269423_0001_000001 [{Priority: 0, Capability: <memory:2048, vCores:1>, # Containers: 1, Location: *, Relax Locality: true}] [] null null
2016-08-19 14:45:58,298 INFO org.apache.hadoop.yarn.server.resourcemanager.scheduler.fair.FSAppAttempt: appattempt_1471639269423_0001_000001 minReqResource: <memory:0, vCores:0> flexibleResource: <memory:16384, vCores:8>
2016-08-19 14:45:58,300 INFO org.apache.hadoop.yarn.server.resourcemanager.scheduler.fair.FairScheduler: iglf: 1.getHeadroom()=<memory:0, vCores:0>
2016-08-19 14:45:58,300 INFO org.apache.hadoop.yarn.server.resourcemanager.rmapp.attempt.RMAppAttemptImpl: appattempt_1471639269423_0001_000001 State change from SUBMITTED to SCHEDULED
2016-08-19 14:45:58,902 INFO org.apache.hadoop.yarn.server.resourcemanager.scheduler.fair.FSAppAttempt: assignContainer(FSSchedulerNode node:cp-1.yarn-perf.yarnrm-PG0.wisc.cloudlab.us, boolean reserved=false) for appattempt_1471639269423_0001_000001
2016-08-19 14:45:58,903 INFO org.apache.hadoop.yarn.server.resourcemanager.scheduler.fair.FSAppAttempt: assignContainer(FSSchedulerNode:cp-1.yarn-perf.yarnrm-PG0.wisc.cloudlab.us, ResourceRequest request, NodeType type, boolean reserved=false
2016-08-19 14:45:58,917 INFO org.apache.hadoop.yarn.server.resourcemanager.scheduler.fair.FSAppAttempt: allocate container: container_1471639269423_0001_01_000001 priority 0
2016-08-19 14:45:58,930 INFO org.apache.hadoop.yarn.server.resourcemanager.rmcontainer.RMContainerImpl: Processing container_1471639269423_0001_01_000001 of event START
2016-08-19 14:45:58,931 INFO org.apache.hadoop.yarn.server.resourcemanager.rmcontainer.RMContainerImpl: container_1471639269423_0001_01_000001 Container Transitioned from NEW to ALLOCATED
2016-08-19 14:45:58,931 INFO org.apache.hadoop.yarn.server.resourcemanager.RMAuditLogger: USER=tanle	OPERATION=AM Allocated Container	TARGET=SchedulerApp	RESULT=SUCCESS	APPID=application_1471639269423_0001	CONTAINERID=container_1471639269423_0001_01_000001
2016-08-19 14:45:58,931 INFO org.apache.hadoop.yarn.server.resourcemanager.rmapp.attempt.RMAppAttemptImpl: AMContainerAllocatedTransition.transition(appattempt_1471639269423_0001_000001,EventType: CONTAINER_ALLOCATED)
2016-08-19 14:45:58,931 INFO org.apache.hadoop.yarn.server.resourcemanager.scheduler.fair.FairScheduler: allocate(appattempt_1471639269423_0001_000001 [] [] null null
2016-08-19 14:45:58,931 INFO org.apache.hadoop.yarn.server.resourcemanager.scheduler.SchedulerNode: Assigned container container_1471639269423_0001_01_000001 of capacity <memory:2048, vCores:1> on host cp-1.yarn-perf.yarnrm-PG0.wisc.cloudlab.us:33756, which has 1 containers, <memory:2048, vCores:1> used and <memory:6144, vCores:3> available after allocation
2016-08-19 14:45:58,932 INFO org.apache.hadoop.yarn.server.resourcemanager.scheduler.fair.FSAppAttempt: appattempt_1471639269423_0001_000001 minReqResource: <memory:0, vCores:0> flexibleResource: <memory:16384, vCores:8>
2016-08-19 14:45:58,960 INFO org.apache.hadoop.yarn.server.resourcemanager.security.NMTokenSecretManagerInRM: Sending NMToken for nodeId : cp-1.yarn-perf.yarnrm-PG0.wisc.cloudlab.us:33756 for container : container_1471639269423_0001_01_000001
2016-08-19 14:45:58,972 INFO org.apache.hadoop.yarn.server.resourcemanager.rmcontainer.RMContainerImpl: Processing container_1471639269423_0001_01_000001 of event ACQUIRED
2016-08-19 14:45:58,973 INFO org.apache.hadoop.yarn.server.resourcemanager.rmcontainer.RMContainerImpl: container_1471639269423_0001_01_000001 Container Transitioned from ALLOCATED to ACQUIRED
2016-08-19 14:45:58,974 INFO org.apache.hadoop.yarn.server.resourcemanager.scheduler.fair.FairScheduler: iglf: 1.getHeadroom()=<memory:14336, vCores:7>
2016-08-19 14:45:58,974 INFO org.apache.hadoop.yarn.server.resourcemanager.security.NMTokenSecretManagerInRM: Clear node set for appattempt_1471639269423_0001_000001
2016-08-19 14:45:58,978 INFO org.apache.hadoop.yarn.server.resourcemanager.rmapp.attempt.RMAppAttemptImpl: Storing attempt: AppId: application_1471639269423_0001 AttemptId: appattempt_1471639269423_0001_000001 MasterContainer: Container: [ContainerId: container_1471639269423_0001_01_000001, NodeId: cp-1.yarn-perf.yarnrm-PG0.wisc.cloudlab.us:33756, NodeHttpAddress: cp-1.yarn-perf.yarnrm-PG0.wisc.cloudlab.us:8042, Resource: <memory:2048, vCores:1>, Priority: 0, Token: Token { kind: ContainerToken, service: 128.104.222.17:33756 }, ]
2016-08-19 14:45:58,994 INFO org.apache.hadoop.yarn.server.resourcemanager.rmapp.attempt.RMAppAttemptImpl: appattempt_1471639269423_0001_000001 State change from SCHEDULED to ALLOCATED_SAVING
2016-08-19 14:45:58,995 INFO org.apache.hadoop.yarn.server.resourcemanager.rmapp.attempt.RMAppAttemptImpl: appattempt_1471639269423_0001_000001 State change from ALLOCATED_SAVING to ALLOCATED
2016-08-19 14:45:58,996 INFO org.apache.hadoop.yarn.server.resourcemanager.scheduler.fair.FSAppAttempt: assignContainer(FSSchedulerNode node:c220g1-031106.wisc.cloudlab.us, boolean reserved=false) for appattempt_1471639269423_0001_000001
2016-08-19 14:45:58,999 INFO org.apache.hadoop.yarn.server.resourcemanager.amlauncher.AMLauncher: Launching masterappattempt_1471639269423_0001_000001
2016-08-19 14:45:59,053 INFO org.apache.hadoop.yarn.server.resourcemanager.amlauncher.AMLauncher: Setting up container Container: [ContainerId: container_1471639269423_0001_01_000001, NodeId: cp-1.yarn-perf.yarnrm-PG0.wisc.cloudlab.us:33756, NodeHttpAddress: cp-1.yarn-perf.yarnrm-PG0.wisc.cloudlab.us:8042, Resource: <memory:2048, vCores:1>, Priority: 0, Token: Token { kind: ContainerToken, service: 128.104.222.17:33756 }, ] for AM appattempt_1471639269423_0001_000001
2016-08-19 14:45:59,053 INFO org.apache.hadoop.yarn.server.resourcemanager.amlauncher.AMLauncher: Command to launch container container_1471639269423_0001_01_000001 : {{JAVA_HOME}}/bin/java,-server,-Xmx1536m,-Djava.io.tmpdir={{PWD}}/tmp,-Dspark.yarn.app.container.log.dir=<LOG_DIR>,-XX:MaxPermSize=256m,org.apache.spark.deploy.yarn.ApplicationMaster,--class,'org.apache.spark.examples.SparkPi',--jar,file:/users/tanle/./spark/examples/jars/spark-examples_2.11-2.0.0-preview.jar,--arg,'10000',--properties-file,{{PWD}}/__spark_conf__/__spark_conf__.properties,1>,<LOG_DIR>/stdout,2>,<LOG_DIR>/stderr
2016-08-19 14:45:59,055 INFO org.apache.hadoop.yarn.server.resourcemanager.security.AMRMTokenSecretManager: Create AMRMToken for ApplicationAttempt: appattempt_1471639269423_0001_000001
2016-08-19 14:45:59,060 INFO org.apache.hadoop.yarn.server.resourcemanager.security.AMRMTokenSecretManager: Creating password for appattempt_1471639269423_0001_000001
2016-08-19 14:45:59,458 INFO org.apache.hadoop.yarn.server.resourcemanager.amlauncher.AMLauncher: Done launching container Container: [ContainerId: container_1471639269423_0001_01_000001, NodeId: cp-1.yarn-perf.yarnrm-PG0.wisc.cloudlab.us:33756, NodeHttpAddress: cp-1.yarn-perf.yarnrm-PG0.wisc.cloudlab.us:8042, Resource: <memory:2048, vCores:1>, Priority: 0, Token: Token { kind: ContainerToken, service: 128.104.222.17:33756 }, ] for AM appattempt_1471639269423_0001_000001
2016-08-19 14:45:59,458 INFO org.apache.hadoop.yarn.server.resourcemanager.rmapp.attempt.RMAppAttemptImpl: appattempt_1471639269423_0001_000001 State change from ALLOCATED to LAUNCHED
2016-08-19 14:45:59,923 INFO org.apache.hadoop.yarn.server.resourcemanager.rmcontainer.RMContainerImpl: Processing container_1471639269423_0001_01_000001 of event LAUNCHED
2016-08-19 14:45:59,923 INFO org.apache.hadoop.yarn.server.resourcemanager.rmcontainer.RMContainerImpl: container_1471639269423_0001_01_000001 Container Transitioned from ACQUIRED to RUNNING
2016-08-19 14:45:59,924 INFO org.apache.hadoop.yarn.server.resourcemanager.scheduler.fair.FSAppAttempt: assignContainer(FSSchedulerNode node:cp-1.yarn-perf.yarnrm-PG0.wisc.cloudlab.us, boolean reserved=false) for appattempt_1471639269423_0001_000001
2016-08-19 14:45:59,939 INFO org.apache.hadoop.yarn.server.resourcemanager.scheduler.fair.FSAppAttempt: assignContainer(FSSchedulerNode node:c220g1-031106.wisc.cloudlab.us, boolean reserved=false) for appattempt_1471639269423_0001_000001
2016-08-19 14:46:00,924 INFO org.apache.hadoop.yarn.server.resourcemanager.scheduler.fair.FSAppAttempt: assignContainer(FSSchedulerNode node:cp-1.yarn-perf.yarnrm-PG0.wisc.cloudlab.us, boolean reserved=false) for appattempt_1471639269423_0001_000001
2016-08-19 14:46:00,942 INFO org.apache.hadoop.yarn.server.resourcemanager.scheduler.fair.FSAppAttempt: assignContainer(FSSchedulerNode node:c220g1-031106.wisc.cloudlab.us, boolean reserved=false) for appattempt_1471639269423_0001_000001
2016-08-19 14:46:01,926 INFO org.apache.hadoop.yarn.server.resourcemanager.scheduler.fair.FSAppAttempt: assignContainer(FSSchedulerNode node:cp-1.yarn-perf.yarnrm-PG0.wisc.cloudlab.us, boolean reserved=false) for appattempt_1471639269423_0001_000001
2016-08-19 14:46:01,945 INFO org.apache.hadoop.yarn.server.resourcemanager.scheduler.fair.FSAppAttempt: assignContainer(FSSchedulerNode node:c220g1-031106.wisc.cloudlab.us, boolean reserved=false) for appattempt_1471639269423_0001_000001
2016-08-19 14:46:02,929 INFO org.apache.hadoop.yarn.server.resourcemanager.scheduler.fair.FSAppAttempt: assignContainer(FSSchedulerNode node:cp-1.yarn-perf.yarnrm-PG0.wisc.cloudlab.us, boolean reserved=false) for appattempt_1471639269423_0001_000001
2016-08-19 14:46:02,949 INFO org.apache.hadoop.yarn.server.resourcemanager.scheduler.fair.FSAppAttempt: assignContainer(FSSchedulerNode node:c220g1-031106.wisc.cloudlab.us, boolean reserved=false) for appattempt_1471639269423_0001_000001
2016-08-19 14:46:03,932 INFO org.apache.hadoop.yarn.server.resourcemanager.scheduler.fair.FSAppAttempt: assignContainer(FSSchedulerNode node:cp-1.yarn-perf.yarnrm-PG0.wisc.cloudlab.us, boolean reserved=false) for appattempt_1471639269423_0001_000001
2016-08-19 14:46:03,951 INFO org.apache.hadoop.yarn.server.resourcemanager.scheduler.fair.FSAppAttempt: assignContainer(FSSchedulerNode node:c220g1-031106.wisc.cloudlab.us, boolean reserved=false) for appattempt_1471639269423_0001_000001
2016-08-19 14:46:04,935 INFO org.apache.hadoop.yarn.server.resourcemanager.scheduler.fair.FSAppAttempt: assignContainer(FSSchedulerNode node:cp-1.yarn-perf.yarnrm-PG0.wisc.cloudlab.us, boolean reserved=false) for appattempt_1471639269423_0001_000001
2016-08-19 14:46:04,954 INFO org.apache.hadoop.yarn.server.resourcemanager.scheduler.fair.FSAppAttempt: assignContainer(FSSchedulerNode node:c220g1-031106.wisc.cloudlab.us, boolean reserved=false) for appattempt_1471639269423_0001_000001
2016-08-19 14:46:05,938 INFO org.apache.hadoop.yarn.server.resourcemanager.scheduler.fair.FSAppAttempt: assignContainer(FSSchedulerNode node:cp-1.yarn-perf.yarnrm-PG0.wisc.cloudlab.us, boolean reserved=false) for appattempt_1471639269423_0001_000001
2016-08-19 14:46:05,956 INFO org.apache.hadoop.yarn.server.resourcemanager.scheduler.fair.FSAppAttempt: assignContainer(FSSchedulerNode node:c220g1-031106.wisc.cloudlab.us, boolean reserved=false) for appattempt_1471639269423_0001_000001
2016-08-19 14:46:06,941 INFO org.apache.hadoop.yarn.server.resourcemanager.scheduler.fair.FSAppAttempt: assignContainer(FSSchedulerNode node:cp-1.yarn-perf.yarnrm-PG0.wisc.cloudlab.us, boolean reserved=false) for appattempt_1471639269423_0001_000001
2016-08-19 14:46:06,959 INFO org.apache.hadoop.yarn.server.resourcemanager.scheduler.fair.FSAppAttempt: assignContainer(FSSchedulerNode node:c220g1-031106.wisc.cloudlab.us, boolean reserved=false) for appattempt_1471639269423_0001_000001
2016-08-19 14:46:07,944 INFO org.apache.hadoop.yarn.server.resourcemanager.scheduler.fair.FSAppAttempt: assignContainer(FSSchedulerNode node:cp-1.yarn-perf.yarnrm-PG0.wisc.cloudlab.us, boolean reserved=false) for appattempt_1471639269423_0001_000001
2016-08-19 14:46:07,961 INFO org.apache.hadoop.yarn.server.resourcemanager.scheduler.fair.FSAppAttempt: assignContainer(FSSchedulerNode node:c220g1-031106.wisc.cloudlab.us, boolean reserved=false) for appattempt_1471639269423_0001_000001
2016-08-19 14:46:08,365 INFO org.apache.hadoop.yarn.server.resourcemanager.ClientRMService: Allocated new applicationId: 2
2016-08-19 14:46:08,947 INFO org.apache.hadoop.yarn.server.resourcemanager.scheduler.fair.FSAppAttempt: assignContainer(FSSchedulerNode node:cp-1.yarn-perf.yarnrm-PG0.wisc.cloudlab.us, boolean reserved=false) for appattempt_1471639269423_0001_000001
2016-08-19 14:46:08,964 INFO org.apache.hadoop.yarn.server.resourcemanager.scheduler.fair.FSAppAttempt: assignContainer(FSSchedulerNode node:c220g1-031106.wisc.cloudlab.us, boolean reserved=false) for appattempt_1471639269423_0001_000001
2016-08-19 14:46:09,950 INFO org.apache.hadoop.yarn.server.resourcemanager.scheduler.fair.FSAppAttempt: assignContainer(FSSchedulerNode node:cp-1.yarn-perf.yarnrm-PG0.wisc.cloudlab.us, boolean reserved=false) for appattempt_1471639269423_0001_000001
2016-08-19 14:46:09,966 INFO org.apache.hadoop.yarn.server.resourcemanager.scheduler.fair.FSAppAttempt: assignContainer(FSSchedulerNode node:c220g1-031106.wisc.cloudlab.us, boolean reserved=false) for appattempt_1471639269423_0001_000001
2016-08-19 14:46:10,953 INFO org.apache.hadoop.yarn.server.resourcemanager.scheduler.fair.FSAppAttempt: assignContainer(FSSchedulerNode node:cp-1.yarn-perf.yarnrm-PG0.wisc.cloudlab.us, boolean reserved=false) for appattempt_1471639269423_0001_000001
2016-08-19 14:46:10,969 INFO org.apache.hadoop.yarn.server.resourcemanager.scheduler.fair.FSAppAttempt: assignContainer(FSSchedulerNode node:c220g1-031106.wisc.cloudlab.us, boolean reserved=false) for appattempt_1471639269423_0001_000001
2016-08-19 14:46:11,957 INFO org.apache.hadoop.yarn.server.resourcemanager.scheduler.fair.FSAppAttempt: assignContainer(FSSchedulerNode node:cp-1.yarn-perf.yarnrm-PG0.wisc.cloudlab.us, boolean reserved=false) for appattempt_1471639269423_0001_000001
2016-08-19 14:46:11,972 INFO org.apache.hadoop.yarn.server.resourcemanager.scheduler.fair.FSAppAttempt: assignContainer(FSSchedulerNode node:c220g1-031106.wisc.cloudlab.us, boolean reserved=false) for appattempt_1471639269423_0001_000001
2016-08-19 14:46:12,960 INFO org.apache.hadoop.yarn.server.resourcemanager.scheduler.fair.FSAppAttempt: assignContainer(FSSchedulerNode node:cp-1.yarn-perf.yarnrm-PG0.wisc.cloudlab.us, boolean reserved=false) for appattempt_1471639269423_0001_000001
2016-08-19 14:46:12,974 INFO org.apache.hadoop.yarn.server.resourcemanager.scheduler.fair.FSAppAttempt: assignContainer(FSSchedulerNode node:c220g1-031106.wisc.cloudlab.us, boolean reserved=false) for appattempt_1471639269423_0001_000001
2016-08-19 14:46:13,964 INFO org.apache.hadoop.yarn.server.resourcemanager.scheduler.fair.FSAppAttempt: assignContainer(FSSchedulerNode node:cp-1.yarn-perf.yarnrm-PG0.wisc.cloudlab.us, boolean reserved=false) for appattempt_1471639269423_0001_000001
2016-08-19 14:46:13,977 INFO org.apache.hadoop.yarn.server.resourcemanager.scheduler.fair.FSAppAttempt: assignContainer(FSSchedulerNode node:c220g1-031106.wisc.cloudlab.us, boolean reserved=false) for appattempt_1471639269423_0001_000001
2016-08-19 14:46:14,968 INFO org.apache.hadoop.yarn.server.resourcemanager.scheduler.fair.FSAppAttempt: assignContainer(FSSchedulerNode node:cp-1.yarn-perf.yarnrm-PG0.wisc.cloudlab.us, boolean reserved=false) for appattempt_1471639269423_0001_000001
2016-08-19 14:46:14,980 INFO org.apache.hadoop.yarn.server.resourcemanager.scheduler.fair.FSAppAttempt: assignContainer(FSSchedulerNode node:c220g1-031106.wisc.cloudlab.us, boolean reserved=false) for appattempt_1471639269423_0001_000001
2016-08-19 14:46:15,384 INFO SecurityLogger.org.apache.hadoop.ipc.Server: Auth successful for appattempt_1471639269423_0001_000001 (auth:SIMPLE)
2016-08-19 14:46:15,395 INFO org.apache.hadoop.yarn.server.resourcemanager.ApplicationMasterService: AM registration appattempt_1471639269423_0001_000001
2016-08-19 14:46:15,396 INFO org.apache.hadoop.yarn.server.resourcemanager.RMAuditLogger: USER=tanle	IP=128.104.222.17	OPERATION=Register App Master	TARGET=ApplicationMasterService	RESULT=SUCCESS	APPID=application_1471639269423_0001	APPATTEMPTID=appattempt_1471639269423_0001_000001
2016-08-19 14:46:15,397 INFO org.apache.hadoop.yarn.server.resourcemanager.rmapp.attempt.RMAppAttemptImpl: appattempt_1471639269423_0001_000001 State change from LAUNCHED to RUNNING
2016-08-19 14:46:15,397 INFO org.apache.hadoop.yarn.server.resourcemanager.rmapp.RMAppImpl: application_1471639269423_0001 State change from ACCEPTED to RUNNING
2016-08-19 14:46:15,484 INFO org.apache.hadoop.yarn.server.resourcemanager.scheduler.fair.FairScheduler: allocate(appattempt_1471639269423_0001_000001 [] [] [] []
2016-08-19 14:46:15,484 INFO org.apache.hadoop.yarn.server.resourcemanager.scheduler.fair.FSAppAttempt: appattempt_1471639269423_0001_000001 minReqResource: <memory:0, vCores:0> flexibleResource: <memory:16384, vCores:8>
2016-08-19 14:46:15,484 INFO org.apache.hadoop.yarn.server.resourcemanager.scheduler.fair.FairScheduler: iglf: 1.getHeadroom()=<memory:14336, vCores:7>
2016-08-19 14:46:15,530 INFO org.apache.hadoop.yarn.server.resourcemanager.scheduler.fair.FairScheduler: allocate(appattempt_1471639269423_0001_000001 [] [] [] []
2016-08-19 14:46:15,530 INFO org.apache.hadoop.yarn.server.resourcemanager.scheduler.fair.FSAppAttempt: appattempt_1471639269423_0001_000001 minReqResource: <memory:0, vCores:0> flexibleResource: <memory:16384, vCores:8>
2016-08-19 14:46:15,530 INFO org.apache.hadoop.yarn.server.resourcemanager.scheduler.fair.FairScheduler: iglf: 1.getHeadroom()=<memory:14336, vCores:7>
2016-08-19 14:46:15,970 INFO org.apache.hadoop.yarn.server.resourcemanager.scheduler.fair.FSAppAttempt: assignContainer(FSSchedulerNode node:cp-1.yarn-perf.yarnrm-PG0.wisc.cloudlab.us, boolean reserved=false) for appattempt_1471639269423_0001_000001
2016-08-19 14:46:15,982 INFO org.apache.hadoop.yarn.server.resourcemanager.scheduler.fair.FSAppAttempt: assignContainer(FSSchedulerNode node:c220g1-031106.wisc.cloudlab.us, boolean reserved=false) for appattempt_1471639269423_0001_000001
2016-08-19 14:46:16,973 INFO org.apache.hadoop.yarn.server.resourcemanager.scheduler.fair.FSAppAttempt: assignContainer(FSSchedulerNode node:cp-1.yarn-perf.yarnrm-PG0.wisc.cloudlab.us, boolean reserved=false) for appattempt_1471639269423_0001_000001
2016-08-19 14:46:16,985 INFO org.apache.hadoop.yarn.server.resourcemanager.scheduler.fair.FSAppAttempt: assignContainer(FSSchedulerNode node:c220g1-031106.wisc.cloudlab.us, boolean reserved=false) for appattempt_1471639269423_0001_000001
2016-08-19 14:46:17,143 WARN org.apache.hadoop.yarn.server.resourcemanager.rmapp.RMAppImpl: The specific max attempts: 0 for application: 2 is invalid, because it is out of the range [1, 2]. Use the global max attempts instead.
2016-08-19 14:46:17,144 INFO org.apache.hadoop.yarn.server.resourcemanager.ClientRMService: Application with id 2 submitted by user tanle
2016-08-19 14:46:17,144 INFO org.apache.hadoop.yarn.server.resourcemanager.rmapp.RMAppImpl: Storing application with id application_1471639269423_0002
2016-08-19 14:46:17,144 INFO org.apache.hadoop.yarn.server.resourcemanager.RMAuditLogger: USER=tanle	IP=128.104.222.71	OPERATION=Submit Application Request	TARGET=ClientRMService	RESULT=SUCCESS	APPID=application_1471639269423_0002
2016-08-19 14:46:17,144 INFO org.apache.hadoop.yarn.server.resourcemanager.rmapp.RMAppImpl: application_1471639269423_0002 State change from NEW to NEW_SAVING
2016-08-19 14:46:17,145 INFO org.apache.hadoop.yarn.server.resourcemanager.recovery.RMStateStore: Storing info for app: application_1471639269423_0002
2016-08-19 14:46:17,145 INFO org.apache.hadoop.yarn.server.resourcemanager.rmapp.RMAppImpl: application_1471639269423_0002 State change from NEW_SAVING to SUBMITTED
2016-08-19 14:46:17,145 INFO org.apache.hadoop.yarn.server.resourcemanager.scheduler.fair.FairScheduler: Accepted application application_1471639269423_0002 from user: tanle, in queue: batch, currently num of applications: 2
2016-08-19 14:46:17,146 INFO org.apache.hadoop.yarn.server.resourcemanager.rmapp.RMAppImpl: application_1471639269423_0002 State change from SUBMITTED to ACCEPTED
2016-08-19 14:46:17,146 INFO org.apache.hadoop.yarn.server.resourcemanager.ApplicationMasterService: Registering app attempt : appattempt_1471639269423_0002_000001
2016-08-19 14:46:17,147 INFO org.apache.hadoop.yarn.server.resourcemanager.rmapp.attempt.RMAppAttemptImpl: appattempt_1471639269423_0002_000001 State change from NEW to SUBMITTED
2016-08-19 14:46:17,147 INFO org.apache.hadoop.yarn.server.resourcemanager.scheduler.fair.FairScheduler: Added Application Attempt appattempt_1471639269423_0002_000001 to scheduler from user: tanle
2016-08-19 14:46:17,147 INFO org.apache.hadoop.yarn.server.resourcemanager.rmapp.attempt.RMAppAttemptImpl: ScheduleTransition.transition(appattempt_1471639269423_0002_000001,EventType: ATTEMPT_ADDED)
2016-08-19 14:46:17,148 INFO org.apache.hadoop.yarn.server.resourcemanager.scheduler.fair.FairScheduler: allocate(appattempt_1471639269423_0002_000001 [{Priority: 0, Capability: <memory:2048, vCores:1>, # Containers: 1, Location: *, Relax Locality: true}] [] null null
2016-08-19 14:46:17,148 INFO org.apache.hadoop.yarn.server.resourcemanager.scheduler.fair.FSAppAttempt: appattempt_1471639269423_0002_000001 minReqResource: <memory:0, vCores:0> flexibleResource: <memory:16384, vCores:8>
2016-08-19 14:46:17,148 INFO org.apache.hadoop.yarn.server.resourcemanager.scheduler.fair.FairScheduler: iglf: 2.getHeadroom()=<memory:14336, vCores:7>
2016-08-19 14:46:17,148 INFO org.apache.hadoop.yarn.server.resourcemanager.rmapp.attempt.RMAppAttemptImpl: appattempt_1471639269423_0002_000001 State change from SUBMITTED to SCHEDULED
2016-08-19 14:46:17,977 INFO org.apache.hadoop.yarn.server.resourcemanager.scheduler.fair.FSAppAttempt: assignContainer(FSSchedulerNode node:cp-1.yarn-perf.yarnrm-PG0.wisc.cloudlab.us, boolean reserved=false) for appattempt_1471639269423_0002_000001
2016-08-19 14:46:17,977 INFO org.apache.hadoop.yarn.server.resourcemanager.scheduler.fair.FSAppAttempt: assignContainer(FSSchedulerNode:cp-1.yarn-perf.yarnrm-PG0.wisc.cloudlab.us, ResourceRequest request, NodeType type, boolean reserved=false
2016-08-19 14:46:17,977 INFO org.apache.hadoop.yarn.server.resourcemanager.scheduler.fair.FSAppAttempt: allocate container: container_1471639269423_0002_01_000001 priority 0
2016-08-19 14:46:17,978 INFO org.apache.hadoop.yarn.server.resourcemanager.rmcontainer.RMContainerImpl: Processing container_1471639269423_0002_01_000001 of event START
2016-08-19 14:46:17,978 INFO org.apache.hadoop.yarn.server.resourcemanager.rmcontainer.RMContainerImpl: container_1471639269423_0002_01_000001 Container Transitioned from NEW to ALLOCATED
2016-08-19 14:46:17,978 INFO org.apache.hadoop.yarn.server.resourcemanager.RMAuditLogger: USER=tanle	OPERATION=AM Allocated Container	TARGET=SchedulerApp	RESULT=SUCCESS	APPID=application_1471639269423_0002	CONTAINERID=container_1471639269423_0002_01_000001
2016-08-19 14:46:17,978 INFO org.apache.hadoop.yarn.server.resourcemanager.rmapp.attempt.RMAppAttemptImpl: AMContainerAllocatedTransition.transition(appattempt_1471639269423_0002_000001,EventType: CONTAINER_ALLOCATED)
2016-08-19 14:46:18,006 INFO org.apache.hadoop.yarn.server.resourcemanager.scheduler.SchedulerNode: Assigned container container_1471639269423_0002_01_000001 of capacity <memory:2048, vCores:1> on host cp-1.yarn-perf.yarnrm-PG0.wisc.cloudlab.us:33756, which has 2 containers, <memory:4096, vCores:2> used and <memory:4096, vCores:2> available after allocation
2016-08-19 14:46:18,006 INFO org.apache.hadoop.yarn.server.resourcemanager.scheduler.fair.FairScheduler: allocate(appattempt_1471639269423_0002_000001 [] [] null null
2016-08-19 14:46:18,006 INFO org.apache.hadoop.yarn.server.resourcemanager.scheduler.fair.FSAppAttempt: appattempt_1471639269423_0002_000001 minReqResource: <memory:0, vCores:0> flexibleResource: <memory:16384, vCores:8>
2016-08-19 14:46:18,008 INFO org.apache.hadoop.yarn.server.resourcemanager.security.NMTokenSecretManagerInRM: Sending NMToken for nodeId : cp-1.yarn-perf.yarnrm-PG0.wisc.cloudlab.us:33756 for container : container_1471639269423_0002_01_000001
2016-08-19 14:46:18,010 INFO org.apache.hadoop.yarn.server.resourcemanager.rmcontainer.RMContainerImpl: Processing container_1471639269423_0002_01_000001 of event ACQUIRED
2016-08-19 14:46:18,010 INFO org.apache.hadoop.yarn.server.resourcemanager.rmcontainer.RMContainerImpl: container_1471639269423_0002_01_000001 Container Transitioned from ALLOCATED to ACQUIRED
2016-08-19 14:46:18,010 INFO org.apache.hadoop.yarn.server.resourcemanager.scheduler.fair.FairScheduler: iglf: 2.getHeadroom()=<memory:12288, vCores:6>
2016-08-19 14:46:18,010 INFO org.apache.hadoop.yarn.server.resourcemanager.security.NMTokenSecretManagerInRM: Clear node set for appattempt_1471639269423_0002_000001
2016-08-19 14:46:18,011 INFO org.apache.hadoop.yarn.server.resourcemanager.rmapp.attempt.RMAppAttemptImpl: Storing attempt: AppId: application_1471639269423_0002 AttemptId: appattempt_1471639269423_0002_000001 MasterContainer: Container: [ContainerId: container_1471639269423_0002_01_000001, NodeId: cp-1.yarn-perf.yarnrm-PG0.wisc.cloudlab.us:33756, NodeHttpAddress: cp-1.yarn-perf.yarnrm-PG0.wisc.cloudlab.us:8042, Resource: <memory:2048, vCores:1>, Priority: 0, Token: Token { kind: ContainerToken, service: 128.104.222.17:33756 }, ]
2016-08-19 14:46:18,011 INFO org.apache.hadoop.yarn.server.resourcemanager.rmapp.attempt.RMAppAttemptImpl: appattempt_1471639269423_0002_000001 State change from SCHEDULED to ALLOCATED_SAVING
2016-08-19 14:46:18,011 INFO org.apache.hadoop.yarn.server.resourcemanager.rmapp.attempt.RMAppAttemptImpl: appattempt_1471639269423_0002_000001 State change from ALLOCATED_SAVING to ALLOCATED
2016-08-19 14:46:18,012 INFO org.apache.hadoop.yarn.server.resourcemanager.scheduler.fair.FSAppAttempt: assignContainer(FSSchedulerNode node:c220g1-031106.wisc.cloudlab.us, boolean reserved=false) for appattempt_1471639269423_0001_000001
2016-08-19 14:46:18,012 INFO org.apache.hadoop.yarn.server.resourcemanager.scheduler.fair.FSAppAttempt: assignContainer(FSSchedulerNode node:c220g1-031106.wisc.cloudlab.us, boolean reserved=false) for appattempt_1471639269423_0002_000001
2016-08-19 14:46:18,012 INFO org.apache.hadoop.yarn.server.resourcemanager.amlauncher.AMLauncher: Launching masterappattempt_1471639269423_0002_000001
2016-08-19 14:46:18,016 INFO org.apache.hadoop.yarn.server.resourcemanager.amlauncher.AMLauncher: Setting up container Container: [ContainerId: container_1471639269423_0002_01_000001, NodeId: cp-1.yarn-perf.yarnrm-PG0.wisc.cloudlab.us:33756, NodeHttpAddress: cp-1.yarn-perf.yarnrm-PG0.wisc.cloudlab.us:8042, Resource: <memory:2048, vCores:1>, Priority: 0, Token: Token { kind: ContainerToken, service: 128.104.222.17:33756 }, ] for AM appattempt_1471639269423_0002_000001
2016-08-19 14:46:18,016 INFO org.apache.hadoop.yarn.server.resourcemanager.amlauncher.AMLauncher: Command to launch container container_1471639269423_0002_01_000001 : {{JAVA_HOME}}/bin/java,-server,-Xmx1536m,-Djava.io.tmpdir={{PWD}}/tmp,-Dspark.yarn.app.container.log.dir=<LOG_DIR>,-XX:MaxPermSize=256m,org.apache.spark.deploy.yarn.ApplicationMaster,--class,'org.apache.spark.examples.SparkPi',--jar,file:/users/tanle/./spark/examples/jars/spark-examples_2.11-2.0.0-preview.jar,--arg,'10000',--properties-file,{{PWD}}/__spark_conf__/__spark_conf__.properties,1>,<LOG_DIR>/stdout,2>,<LOG_DIR>/stderr
2016-08-19 14:46:18,016 INFO org.apache.hadoop.yarn.server.resourcemanager.security.AMRMTokenSecretManager: Create AMRMToken for ApplicationAttempt: appattempt_1471639269423_0002_000001
2016-08-19 14:46:18,017 INFO org.apache.hadoop.yarn.server.resourcemanager.security.AMRMTokenSecretManager: Creating password for appattempt_1471639269423_0002_000001
2016-08-19 14:46:18,035 INFO org.apache.hadoop.yarn.server.resourcemanager.amlauncher.AMLauncher: Done launching container Container: [ContainerId: container_1471639269423_0002_01_000001, NodeId: cp-1.yarn-perf.yarnrm-PG0.wisc.cloudlab.us:33756, NodeHttpAddress: cp-1.yarn-perf.yarnrm-PG0.wisc.cloudlab.us:8042, Resource: <memory:2048, vCores:1>, Priority: 0, Token: Token { kind: ContainerToken, service: 128.104.222.17:33756 }, ] for AM appattempt_1471639269423_0002_000001
2016-08-19 14:46:18,035 INFO org.apache.hadoop.yarn.server.resourcemanager.rmapp.attempt.RMAppAttemptImpl: appattempt_1471639269423_0002_000001 State change from ALLOCATED to LAUNCHED
2016-08-19 14:46:18,535 INFO org.apache.hadoop.yarn.server.resourcemanager.scheduler.fair.FairScheduler: allocate(appattempt_1471639269423_0001_000001 [] [] [] []
2016-08-19 14:46:18,535 INFO org.apache.hadoop.yarn.server.resourcemanager.scheduler.fair.FSAppAttempt: appattempt_1471639269423_0001_000001 minReqResource: <memory:0, vCores:0> flexibleResource: <memory:16384, vCores:8>
2016-08-19 14:46:18,535 INFO org.apache.hadoop.yarn.server.resourcemanager.scheduler.fair.FairScheduler: iglf: 1.getHeadroom()=<memory:12288, vCores:6>
2016-08-19 14:46:18,980 INFO org.apache.hadoop.yarn.server.resourcemanager.rmcontainer.RMContainerImpl: Processing container_1471639269423_0002_01_000001 of event LAUNCHED
2016-08-19 14:46:18,980 INFO org.apache.hadoop.yarn.server.resourcemanager.rmcontainer.RMContainerImpl: container_1471639269423_0002_01_000001 Container Transitioned from ACQUIRED to RUNNING
2016-08-19 14:46:18,981 INFO org.apache.hadoop.yarn.server.resourcemanager.scheduler.fair.FSAppAttempt: assignContainer(FSSchedulerNode node:cp-1.yarn-perf.yarnrm-PG0.wisc.cloudlab.us, boolean reserved=false) for appattempt_1471639269423_0001_000001
2016-08-19 14:46:18,981 INFO org.apache.hadoop.yarn.server.resourcemanager.scheduler.fair.FSAppAttempt: assignContainer(FSSchedulerNode node:cp-1.yarn-perf.yarnrm-PG0.wisc.cloudlab.us, boolean reserved=false) for appattempt_1471639269423_0002_000001
2016-08-19 14:46:18,990 INFO org.apache.hadoop.yarn.server.resourcemanager.scheduler.fair.FSAppAttempt: assignContainer(FSSchedulerNode node:c220g1-031106.wisc.cloudlab.us, boolean reserved=false) for appattempt_1471639269423_0001_000001
2016-08-19 14:46:18,991 INFO org.apache.hadoop.yarn.server.resourcemanager.scheduler.fair.FSAppAttempt: assignContainer(FSSchedulerNode node:c220g1-031106.wisc.cloudlab.us, boolean reserved=false) for appattempt_1471639269423_0002_000001
2016-08-19 14:46:19,983 INFO org.apache.hadoop.yarn.server.resourcemanager.scheduler.fair.FSAppAttempt: assignContainer(FSSchedulerNode node:cp-1.yarn-perf.yarnrm-PG0.wisc.cloudlab.us, boolean reserved=false) for appattempt_1471639269423_0001_000001
2016-08-19 14:46:19,983 INFO org.apache.hadoop.yarn.server.resourcemanager.scheduler.fair.FSAppAttempt: assignContainer(FSSchedulerNode node:cp-1.yarn-perf.yarnrm-PG0.wisc.cloudlab.us, boolean reserved=false) for appattempt_1471639269423_0002_000001
2016-08-19 14:46:19,993 INFO org.apache.hadoop.yarn.server.resourcemanager.scheduler.fair.FSAppAttempt: assignContainer(FSSchedulerNode node:c220g1-031106.wisc.cloudlab.us, boolean reserved=false) for appattempt_1471639269423_0001_000001
2016-08-19 14:46:19,993 INFO org.apache.hadoop.yarn.server.resourcemanager.scheduler.fair.FSAppAttempt: assignContainer(FSSchedulerNode node:c220g1-031106.wisc.cloudlab.us, boolean reserved=false) for appattempt_1471639269423_0002_000001
2016-08-19 14:46:20,985 INFO org.apache.hadoop.yarn.server.resourcemanager.scheduler.fair.FSAppAttempt: assignContainer(FSSchedulerNode node:cp-1.yarn-perf.yarnrm-PG0.wisc.cloudlab.us, boolean reserved=false) for appattempt_1471639269423_0001_000001
2016-08-19 14:46:20,986 INFO org.apache.hadoop.yarn.server.resourcemanager.scheduler.fair.FSAppAttempt: assignContainer(FSSchedulerNode node:cp-1.yarn-perf.yarnrm-PG0.wisc.cloudlab.us, boolean reserved=false) for appattempt_1471639269423_0002_000001
2016-08-19 14:46:20,996 INFO org.apache.hadoop.yarn.server.resourcemanager.scheduler.fair.FSAppAttempt: assignContainer(FSSchedulerNode node:c220g1-031106.wisc.cloudlab.us, boolean reserved=false) for appattempt_1471639269423_0001_000001
2016-08-19 14:46:20,996 INFO org.apache.hadoop.yarn.server.resourcemanager.scheduler.fair.FSAppAttempt: assignContainer(FSSchedulerNode node:c220g1-031106.wisc.cloudlab.us, boolean reserved=false) for appattempt_1471639269423_0002_000001
2016-08-19 14:46:21,369 INFO org.apache.hadoop.yarn.server.resourcemanager.scheduler.fair.FairScheduler: allocate(appattempt_1471639269423_0001_000001 [{Priority: 1, Capability: <memory:1920, vCores:1>, # Containers: 1, Location: *, Relax Locality: true}] [] [] []
2016-08-19 14:46:21,369 INFO org.apache.hadoop.yarn.server.resourcemanager.scheduler.fair.FSAppAttempt: appattempt_1471639269423_0001_000001 minReqResource: <memory:0, vCores:0> flexibleResource: <memory:16384, vCores:8>
2016-08-19 14:46:21,370 INFO org.apache.hadoop.yarn.server.resourcemanager.scheduler.fair.FairScheduler: iglf: 1.getHeadroom()=<memory:12288, vCores:6>
2016-08-19 14:46:21,574 INFO org.apache.hadoop.yarn.server.resourcemanager.scheduler.fair.FairScheduler: allocate(appattempt_1471639269423_0001_000001 [] [] [] []
2016-08-19 14:46:21,574 INFO org.apache.hadoop.yarn.server.resourcemanager.scheduler.fair.FSAppAttempt: appattempt_1471639269423_0001_000001 minReqResource: <memory:0, vCores:0> flexibleResource: <memory:16384, vCores:8>
2016-08-19 14:46:21,574 INFO org.apache.hadoop.yarn.server.resourcemanager.scheduler.fair.FairScheduler: iglf: 1.getHeadroom()=<memory:12288, vCores:6>
2016-08-19 14:46:21,977 INFO org.apache.hadoop.yarn.server.resourcemanager.scheduler.fair.FairScheduler: allocate(appattempt_1471639269423_0001_000001 [] [] [] []
2016-08-19 14:46:21,977 INFO org.apache.hadoop.yarn.server.resourcemanager.scheduler.fair.FSAppAttempt: appattempt_1471639269423_0001_000001 minReqResource: <memory:0, vCores:0> flexibleResource: <memory:16384, vCores:8>
2016-08-19 14:46:21,977 INFO org.apache.hadoop.yarn.server.resourcemanager.scheduler.fair.FairScheduler: iglf: 1.getHeadroom()=<memory:12288, vCores:6>
2016-08-19 14:46:21,988 INFO org.apache.hadoop.yarn.server.resourcemanager.scheduler.fair.FSAppAttempt: assignContainer(FSSchedulerNode node:cp-1.yarn-perf.yarnrm-PG0.wisc.cloudlab.us, boolean reserved=false) for appattempt_1471639269423_0001_000001
2016-08-19 14:46:21,988 INFO org.apache.hadoop.yarn.server.resourcemanager.scheduler.fair.FSAppAttempt: assignContainer(FSSchedulerNode:cp-1.yarn-perf.yarnrm-PG0.wisc.cloudlab.us, ResourceRequest request, NodeType type, boolean reserved=false
2016-08-19 14:46:21,988 INFO org.apache.hadoop.yarn.server.resourcemanager.scheduler.fair.FSAppAttempt: allocate container: container_1471639269423_0001_01_000002 priority 1
2016-08-19 14:46:21,989 INFO org.apache.hadoop.yarn.server.resourcemanager.rmcontainer.RMContainerImpl: Processing container_1471639269423_0001_01_000002 of event START
2016-08-19 14:46:21,989 INFO org.apache.hadoop.yarn.server.resourcemanager.rmcontainer.RMContainerImpl: container_1471639269423_0001_01_000002 Container Transitioned from NEW to ALLOCATED
2016-08-19 14:46:21,989 INFO org.apache.hadoop.yarn.server.resourcemanager.RMAuditLogger: USER=tanle	OPERATION=AM Allocated Container	TARGET=SchedulerApp	RESULT=SUCCESS	APPID=application_1471639269423_0001	CONTAINERID=container_1471639269423_0001_01_000002
2016-08-19 14:46:21,989 INFO org.apache.hadoop.yarn.server.resourcemanager.scheduler.SchedulerNode: Assigned container container_1471639269423_0001_01_000002 of capacity <memory:2048, vCores:1> on host cp-1.yarn-perf.yarnrm-PG0.wisc.cloudlab.us:33756, which has 3 containers, <memory:6144, vCores:3> used and <memory:2048, vCores:1> available after allocation
2016-08-19 14:46:21,998 INFO org.apache.hadoop.yarn.server.resourcemanager.scheduler.fair.FSAppAttempt: assignContainer(FSSchedulerNode node:c220g1-031106.wisc.cloudlab.us, boolean reserved=false) for appattempt_1471639269423_0002_000001
2016-08-19 14:46:21,998 INFO org.apache.hadoop.yarn.server.resourcemanager.scheduler.fair.FSAppAttempt: assignContainer(FSSchedulerNode node:c220g1-031106.wisc.cloudlab.us, boolean reserved=false) for appattempt_1471639269423_0001_000001
2016-08-19 14:46:22,780 INFO org.apache.hadoop.yarn.server.resourcemanager.scheduler.fair.FairScheduler: allocate(appattempt_1471639269423_0001_000001 [] [] [] []
2016-08-19 14:46:22,780 INFO org.apache.hadoop.yarn.server.resourcemanager.scheduler.fair.FSAppAttempt: appattempt_1471639269423_0001_000001 minReqResource: <memory:0, vCores:0> flexibleResource: <memory:16384, vCores:8>
2016-08-19 14:46:22,783 INFO org.apache.hadoop.yarn.server.resourcemanager.security.NMTokenSecretManagerInRM: Sending NMToken for nodeId : cp-1.yarn-perf.yarnrm-PG0.wisc.cloudlab.us:33756 for container : container_1471639269423_0001_01_000002
2016-08-19 14:46:22,788 INFO org.apache.hadoop.yarn.server.resourcemanager.rmcontainer.RMContainerImpl: Processing container_1471639269423_0001_01_000002 of event ACQUIRED
2016-08-19 14:46:22,789 INFO org.apache.hadoop.yarn.server.resourcemanager.rmcontainer.RMContainerImpl: container_1471639269423_0001_01_000002 Container Transitioned from ALLOCATED to ACQUIRED
2016-08-19 14:46:22,789 INFO org.apache.hadoop.yarn.server.resourcemanager.scheduler.fair.FairScheduler: iglf: 1.getHeadroom()=<memory:10240, vCores:5>
2016-08-19 14:46:22,992 INFO org.apache.hadoop.yarn.server.resourcemanager.rmcontainer.RMContainerImpl: Processing container_1471639269423_0001_01_000002 of event LAUNCHED
2016-08-19 14:46:22,992 INFO org.apache.hadoop.yarn.server.resourcemanager.rmcontainer.RMContainerImpl: container_1471639269423_0001_01_000002 Container Transitioned from ACQUIRED to RUNNING
2016-08-19 14:46:23,012 INFO org.apache.hadoop.yarn.server.resourcemanager.scheduler.fair.FSAppAttempt: assignContainer(FSSchedulerNode node:cp-1.yarn-perf.yarnrm-PG0.wisc.cloudlab.us, boolean reserved=false) for appattempt_1471639269423_0002_000001
2016-08-19 14:46:23,012 INFO org.apache.hadoop.yarn.server.resourcemanager.scheduler.fair.FSAppAttempt: assignContainer(FSSchedulerNode node:cp-1.yarn-perf.yarnrm-PG0.wisc.cloudlab.us, boolean reserved=false) for appattempt_1471639269423_0001_000001
2016-08-19 14:46:23,013 INFO org.apache.hadoop.yarn.server.resourcemanager.scheduler.fair.FSAppAttempt: assignContainer(FSSchedulerNode node:c220g1-031106.wisc.cloudlab.us, boolean reserved=false) for appattempt_1471639269423_0002_000001
2016-08-19 14:46:23,013 INFO org.apache.hadoop.yarn.server.resourcemanager.scheduler.fair.FSAppAttempt: assignContainer(FSSchedulerNode node:c220g1-031106.wisc.cloudlab.us, boolean reserved=false) for appattempt_1471639269423_0001_000001
2016-08-19 14:46:23,995 INFO org.apache.hadoop.yarn.server.resourcemanager.scheduler.fair.FSAppAttempt: assignContainer(FSSchedulerNode node:cp-1.yarn-perf.yarnrm-PG0.wisc.cloudlab.us, boolean reserved=false) for appattempt_1471639269423_0002_000001
2016-08-19 14:46:23,995 INFO org.apache.hadoop.yarn.server.resourcemanager.scheduler.fair.FSAppAttempt: assignContainer(FSSchedulerNode node:cp-1.yarn-perf.yarnrm-PG0.wisc.cloudlab.us, boolean reserved=false) for appattempt_1471639269423_0001_000001
2016-08-19 14:46:24,003 INFO org.apache.hadoop.yarn.server.resourcemanager.scheduler.fair.FSAppAttempt: assignContainer(FSSchedulerNode node:c220g1-031106.wisc.cloudlab.us, boolean reserved=false) for appattempt_1471639269423_0002_000001
2016-08-19 14:46:24,003 INFO org.apache.hadoop.yarn.server.resourcemanager.scheduler.fair.FSAppAttempt: assignContainer(FSSchedulerNode node:c220g1-031106.wisc.cloudlab.us, boolean reserved=false) for appattempt_1471639269423_0001_000001
2016-08-19 14:46:24,998 INFO org.apache.hadoop.yarn.server.resourcemanager.scheduler.fair.FSAppAttempt: assignContainer(FSSchedulerNode node:cp-1.yarn-perf.yarnrm-PG0.wisc.cloudlab.us, boolean reserved=false) for appattempt_1471639269423_0002_000001
2016-08-19 14:46:24,998 INFO org.apache.hadoop.yarn.server.resourcemanager.scheduler.fair.FSAppAttempt: assignContainer(FSSchedulerNode node:cp-1.yarn-perf.yarnrm-PG0.wisc.cloudlab.us, boolean reserved=false) for appattempt_1471639269423_0001_000001
2016-08-19 14:46:25,006 INFO org.apache.hadoop.yarn.server.resourcemanager.scheduler.fair.FSAppAttempt: assignContainer(FSSchedulerNode node:c220g1-031106.wisc.cloudlab.us, boolean reserved=false) for appattempt_1471639269423_0002_000001
2016-08-19 14:46:25,006 INFO org.apache.hadoop.yarn.server.resourcemanager.scheduler.fair.FSAppAttempt: assignContainer(FSSchedulerNode node:c220g1-031106.wisc.cloudlab.us, boolean reserved=false) for appattempt_1471639269423_0001_000001
2016-08-19 14:46:25,825 INFO org.apache.hadoop.yarn.server.resourcemanager.scheduler.fair.FairScheduler: allocate(appattempt_1471639269423_0001_000001 [{Priority: 1, Capability: <memory:1920, vCores:1>, # Containers: 0, Location: *, Relax Locality: true}] [] [] []
2016-08-19 14:46:25,825 INFO org.apache.hadoop.yarn.server.resourcemanager.scheduler.fair.FSAppAttempt: appattempt_1471639269423_0001_000001 minReqResource: <memory:0, vCores:0> flexibleResource: <memory:16384, vCores:8>
2016-08-19 14:46:25,825 INFO org.apache.hadoop.yarn.server.resourcemanager.scheduler.AppSchedulingInfo: checking for deactivate of application :application_1471639269423_0001
2016-08-19 14:46:25,826 INFO org.apache.hadoop.yarn.server.resourcemanager.scheduler.fair.FairScheduler: iglf: 1.getHeadroom()=<memory:10240, vCores:5>
2016-08-19 14:46:26,000 INFO org.apache.hadoop.yarn.server.resourcemanager.scheduler.fair.FSAppAttempt: assignContainer(FSSchedulerNode node:cp-1.yarn-perf.yarnrm-PG0.wisc.cloudlab.us, boolean reserved=false) for appattempt_1471639269423_0002_000001
2016-08-19 14:46:26,001 INFO org.apache.hadoop.yarn.server.resourcemanager.scheduler.fair.FSAppAttempt: assignContainer(FSSchedulerNode node:cp-1.yarn-perf.yarnrm-PG0.wisc.cloudlab.us, boolean reserved=false) for appattempt_1471639269423_0001_000001
2016-08-19 14:46:26,008 INFO org.apache.hadoop.yarn.server.resourcemanager.scheduler.fair.FSAppAttempt: assignContainer(FSSchedulerNode node:c220g1-031106.wisc.cloudlab.us, boolean reserved=false) for appattempt_1471639269423_0002_000001
2016-08-19 14:46:26,008 INFO org.apache.hadoop.yarn.server.resourcemanager.scheduler.fair.FSAppAttempt: assignContainer(FSSchedulerNode node:c220g1-031106.wisc.cloudlab.us, boolean reserved=false) for appattempt_1471639269423_0001_000001
2016-08-19 14:46:26,338 INFO org.apache.hadoop.yarn.server.resourcemanager.scheduler.fair.FairScheduler: allocate(appattempt_1471639269423_0001_000001 [{Priority: 1, Capability: <memory:1920, vCores:1>, # Containers: 2, Location: *, Relax Locality: true}] [] [] []
2016-08-19 14:46:26,338 INFO org.apache.hadoop.yarn.server.resourcemanager.scheduler.fair.FSAppAttempt: appattempt_1471639269423_0001_000001 minReqResource: <memory:0, vCores:0> flexibleResource: <memory:16384, vCores:8>
2016-08-19 14:46:26,338 INFO org.apache.hadoop.yarn.server.resourcemanager.scheduler.fair.FairScheduler: iglf: 1.getHeadroom()=<memory:10240, vCores:5>
2016-08-19 14:46:26,542 INFO org.apache.hadoop.yarn.server.resourcemanager.scheduler.fair.FairScheduler: allocate(appattempt_1471639269423_0001_000001 [] [] [] []
2016-08-19 14:46:26,542 INFO org.apache.hadoop.yarn.server.resourcemanager.scheduler.fair.FSAppAttempt: appattempt_1471639269423_0001_000001 minReqResource: <memory:0, vCores:0> flexibleResource: <memory:16384, vCores:8>
2016-08-19 14:46:26,542 INFO org.apache.hadoop.yarn.server.resourcemanager.scheduler.fair.FairScheduler: iglf: 1.getHeadroom()=<memory:10240, vCores:5>
2016-08-19 14:46:26,945 INFO org.apache.hadoop.yarn.server.resourcemanager.scheduler.fair.FairScheduler: allocate(appattempt_1471639269423_0001_000001 [] [] [] []
2016-08-19 14:46:26,945 INFO org.apache.hadoop.yarn.server.resourcemanager.scheduler.fair.FSAppAttempt: appattempt_1471639269423_0001_000001 minReqResource: <memory:0, vCores:0> flexibleResource: <memory:16384, vCores:8>
2016-08-19 14:46:26,945 INFO org.apache.hadoop.yarn.server.resourcemanager.scheduler.fair.FairScheduler: iglf: 1.getHeadroom()=<memory:10240, vCores:5>
2016-08-19 14:46:27,004 INFO org.apache.hadoop.yarn.server.resourcemanager.scheduler.fair.FSAppAttempt: assignContainer(FSSchedulerNode node:cp-1.yarn-perf.yarnrm-PG0.wisc.cloudlab.us, boolean reserved=false) for appattempt_1471639269423_0002_000001
2016-08-19 14:46:27,005 INFO org.apache.hadoop.yarn.server.resourcemanager.scheduler.fair.FSAppAttempt: assignContainer(FSSchedulerNode node:cp-1.yarn-perf.yarnrm-PG0.wisc.cloudlab.us, boolean reserved=false) for appattempt_1471639269423_0001_000001
2016-08-19 14:46:27,005 INFO org.apache.hadoop.yarn.server.resourcemanager.scheduler.fair.FSAppAttempt: assignContainer(FSSchedulerNode:cp-1.yarn-perf.yarnrm-PG0.wisc.cloudlab.us, ResourceRequest request, NodeType type, boolean reserved=false
2016-08-19 14:46:27,005 INFO org.apache.hadoop.yarn.server.resourcemanager.scheduler.fair.FSAppAttempt: allocate container: container_1471639269423_0001_01_000003 priority 1
2016-08-19 14:46:27,005 INFO org.apache.hadoop.yarn.server.resourcemanager.rmcontainer.RMContainerImpl: Processing container_1471639269423_0001_01_000003 of event START
2016-08-19 14:46:27,005 INFO org.apache.hadoop.yarn.server.resourcemanager.rmcontainer.RMContainerImpl: container_1471639269423_0001_01_000003 Container Transitioned from NEW to ALLOCATED
2016-08-19 14:46:27,005 INFO org.apache.hadoop.yarn.server.resourcemanager.RMAuditLogger: USER=tanle	OPERATION=AM Allocated Container	TARGET=SchedulerApp	RESULT=SUCCESS	APPID=application_1471639269423_0001	CONTAINERID=container_1471639269423_0001_01_000003
2016-08-19 14:46:27,006 INFO org.apache.hadoop.yarn.server.resourcemanager.scheduler.SchedulerNode: Assigned container container_1471639269423_0001_01_000003 of capacity <memory:2048, vCores:1> on host cp-1.yarn-perf.yarnrm-PG0.wisc.cloudlab.us:33756, which has 4 containers, <memory:8192, vCores:4> used and <memory:0, vCores:0> available after allocation
2016-08-19 14:46:27,010 INFO org.apache.hadoop.yarn.server.resourcemanager.scheduler.fair.FSAppAttempt: assignContainer(FSSchedulerNode node:c220g1-031106.wisc.cloudlab.us, boolean reserved=false) for appattempt_1471639269423_0002_000001
2016-08-19 14:46:27,011 INFO org.apache.hadoop.yarn.server.resourcemanager.scheduler.fair.FSAppAttempt: assignContainer(FSSchedulerNode node:c220g1-031106.wisc.cloudlab.us, boolean reserved=false) for appattempt_1471639269423_0001_000001
2016-08-19 14:46:27,011 INFO org.apache.hadoop.yarn.server.resourcemanager.scheduler.fair.FSAppAttempt: assignContainer(FSSchedulerNode:c220g1-031106.wisc.cloudlab.us, ResourceRequest request, NodeType type, boolean reserved=false
2016-08-19 14:46:27,011 INFO org.apache.hadoop.yarn.server.resourcemanager.scheduler.fair.FSAppAttempt: allocate container: container_1471639269423_0001_01_000004 priority 1
2016-08-19 14:46:27,011 INFO org.apache.hadoop.yarn.server.resourcemanager.rmcontainer.RMContainerImpl: Processing container_1471639269423_0001_01_000004 of event START
2016-08-19 14:46:27,011 INFO org.apache.hadoop.yarn.server.resourcemanager.rmcontainer.RMContainerImpl: container_1471639269423_0001_01_000004 Container Transitioned from NEW to ALLOCATED
2016-08-19 14:46:27,011 INFO org.apache.hadoop.yarn.server.resourcemanager.RMAuditLogger: USER=tanle	OPERATION=AM Allocated Container	TARGET=SchedulerApp	RESULT=SUCCESS	APPID=application_1471639269423_0001	CONTAINERID=container_1471639269423_0001_01_000004
2016-08-19 14:46:27,011 INFO org.apache.hadoop.yarn.server.resourcemanager.scheduler.SchedulerNode: Assigned container container_1471639269423_0001_01_000004 of capacity <memory:2048, vCores:1> on host c220g1-031106.wisc.cloudlab.us:43516, which has 1 containers, <memory:2048, vCores:1> used and <memory:6144, vCores:3> available after allocation
2016-08-19 14:46:27,749 INFO org.apache.hadoop.yarn.server.resourcemanager.scheduler.fair.FairScheduler: allocate(appattempt_1471639269423_0001_000001 [] [] [] []
2016-08-19 14:46:27,749 INFO org.apache.hadoop.yarn.server.resourcemanager.scheduler.fair.FSAppAttempt: appattempt_1471639269423_0001_000001 minReqResource: <memory:0, vCores:0> flexibleResource: <memory:16384, vCores:8>
2016-08-19 14:46:27,752 INFO org.apache.hadoop.yarn.server.resourcemanager.rmcontainer.RMContainerImpl: Processing container_1471639269423_0001_01_000003 of event ACQUIRED
2016-08-19 14:46:27,752 INFO org.apache.hadoop.yarn.server.resourcemanager.rmcontainer.RMContainerImpl: container_1471639269423_0001_01_000003 Container Transitioned from ALLOCATED to ACQUIRED
2016-08-19 14:46:27,754 INFO org.apache.hadoop.yarn.server.resourcemanager.security.NMTokenSecretManagerInRM: Sending NMToken for nodeId : c220g1-031106.wisc.cloudlab.us:43516 for container : container_1471639269423_0001_01_000004
2016-08-19 14:46:27,756 INFO org.apache.hadoop.yarn.server.resourcemanager.rmcontainer.RMContainerImpl: Processing container_1471639269423_0001_01_000004 of event ACQUIRED
2016-08-19 14:46:27,756 INFO org.apache.hadoop.yarn.server.resourcemanager.rmcontainer.RMContainerImpl: container_1471639269423_0001_01_000004 Container Transitioned from ALLOCATED to ACQUIRED
2016-08-19 14:46:27,756 INFO org.apache.hadoop.yarn.server.resourcemanager.scheduler.fair.FairScheduler: iglf: 1.getHeadroom()=<memory:6144, vCores:3>
2016-08-19 14:46:28,008 INFO org.apache.hadoop.yarn.server.resourcemanager.rmcontainer.RMContainerImpl: Processing container_1471639269423_0001_01_000003 of event LAUNCHED
2016-08-19 14:46:28,008 INFO org.apache.hadoop.yarn.server.resourcemanager.rmcontainer.RMContainerImpl: container_1471639269423_0001_01_000003 Container Transitioned from ACQUIRED to RUNNING
2016-08-19 14:46:28,009 INFO org.apache.hadoop.yarn.server.resourcemanager.scheduler.fair.FSAppAttempt: assignContainer(FSSchedulerNode node:cp-1.yarn-perf.yarnrm-PG0.wisc.cloudlab.us, boolean reserved=false) for appattempt_1471639269423_0002_000001
2016-08-19 14:46:28,009 INFO org.apache.hadoop.yarn.server.resourcemanager.scheduler.fair.FSAppAttempt: assignContainer(FSSchedulerNode node:cp-1.yarn-perf.yarnrm-PG0.wisc.cloudlab.us, boolean reserved=false) for appattempt_1471639269423_0001_000001
2016-08-19 14:46:28,013 INFO org.apache.hadoop.yarn.server.resourcemanager.scheduler.fair.FSAppAttempt: assignContainer(FSSchedulerNode node:c220g1-031106.wisc.cloudlab.us, boolean reserved=false) for appattempt_1471639269423_0002_000001
2016-08-19 14:46:28,013 INFO org.apache.hadoop.yarn.server.resourcemanager.scheduler.fair.FSAppAttempt: assignContainer(FSSchedulerNode node:c220g1-031106.wisc.cloudlab.us, boolean reserved=false) for appattempt_1471639269423_0001_000001
2016-08-19 14:46:29,011 INFO org.apache.hadoop.yarn.server.resourcemanager.scheduler.fair.FSAppAttempt: assignContainer(FSSchedulerNode node:cp-1.yarn-perf.yarnrm-PG0.wisc.cloudlab.us, boolean reserved=false) for appattempt_1471639269423_0002_000001
2016-08-19 14:46:29,012 INFO org.apache.hadoop.yarn.server.resourcemanager.scheduler.fair.FSAppAttempt: assignContainer(FSSchedulerNode node:cp-1.yarn-perf.yarnrm-PG0.wisc.cloudlab.us, boolean reserved=false) for appattempt_1471639269423_0001_000001
2016-08-19 14:46:29,027 INFO org.apache.hadoop.yarn.server.resourcemanager.rmcontainer.RMContainerImpl: Processing container_1471639269423_0001_01_000004 of event LAUNCHED
2016-08-19 14:46:29,027 INFO org.apache.hadoop.yarn.server.resourcemanager.rmcontainer.RMContainerImpl: container_1471639269423_0001_01_000004 Container Transitioned from ACQUIRED to RUNNING
2016-08-19 14:46:29,028 INFO org.apache.hadoop.yarn.server.resourcemanager.scheduler.fair.FSAppAttempt: assignContainer(FSSchedulerNode node:c220g1-031106.wisc.cloudlab.us, boolean reserved=false) for appattempt_1471639269423_0002_000001
2016-08-19 14:46:29,028 INFO org.apache.hadoop.yarn.server.resourcemanager.scheduler.fair.FSAppAttempt: assignContainer(FSSchedulerNode node:c220g1-031106.wisc.cloudlab.us, boolean reserved=false) for appattempt_1471639269423_0001_000001
2016-08-19 14:46:30,015 INFO org.apache.hadoop.yarn.server.resourcemanager.scheduler.fair.FSAppAttempt: assignContainer(FSSchedulerNode node:cp-1.yarn-perf.yarnrm-PG0.wisc.cloudlab.us, boolean reserved=false) for appattempt_1471639269423_0002_000001
2016-08-19 14:46:30,015 INFO org.apache.hadoop.yarn.server.resourcemanager.scheduler.fair.FSAppAttempt: assignContainer(FSSchedulerNode node:cp-1.yarn-perf.yarnrm-PG0.wisc.cloudlab.us, boolean reserved=false) for appattempt_1471639269423_0001_000001
2016-08-19 14:46:30,029 INFO org.apache.hadoop.yarn.server.resourcemanager.scheduler.fair.FSAppAttempt: assignContainer(FSSchedulerNode node:c220g1-031106.wisc.cloudlab.us, boolean reserved=false) for appattempt_1471639269423_0002_000001
2016-08-19 14:46:30,029 INFO org.apache.hadoop.yarn.server.resourcemanager.scheduler.fair.FSAppAttempt: assignContainer(FSSchedulerNode node:c220g1-031106.wisc.cloudlab.us, boolean reserved=false) for appattempt_1471639269423_0001_000001
2016-08-19 14:46:30,774 INFO org.apache.hadoop.yarn.server.resourcemanager.scheduler.fair.FairScheduler: allocate(appattempt_1471639269423_0001_000001 [{Priority: 1, Capability: <memory:1920, vCores:1>, # Containers: 0, Location: *, Relax Locality: true}] [] [] []
2016-08-19 14:46:30,774 INFO org.apache.hadoop.yarn.server.resourcemanager.scheduler.fair.FSAppAttempt: appattempt_1471639269423_0001_000001 minReqResource: <memory:0, vCores:0> flexibleResource: <memory:16384, vCores:8>
2016-08-19 14:46:30,775 INFO org.apache.hadoop.yarn.server.resourcemanager.scheduler.AppSchedulingInfo: checking for deactivate of application :application_1471639269423_0001
2016-08-19 14:46:30,775 INFO org.apache.hadoop.yarn.server.resourcemanager.scheduler.fair.FairScheduler: iglf: 1.getHeadroom()=<memory:6144, vCores:3>
2016-08-19 14:46:31,018 INFO org.apache.hadoop.yarn.server.resourcemanager.scheduler.fair.FSAppAttempt: assignContainer(FSSchedulerNode node:cp-1.yarn-perf.yarnrm-PG0.wisc.cloudlab.us, boolean reserved=false) for appattempt_1471639269423_0002_000001
2016-08-19 14:46:31,018 INFO org.apache.hadoop.yarn.server.resourcemanager.scheduler.fair.FSAppAttempt: assignContainer(FSSchedulerNode node:cp-1.yarn-perf.yarnrm-PG0.wisc.cloudlab.us, boolean reserved=false) for appattempt_1471639269423_0001_000001
2016-08-19 14:46:31,034 INFO org.apache.hadoop.yarn.server.resourcemanager.scheduler.fair.FSAppAttempt: assignContainer(FSSchedulerNode node:c220g1-031106.wisc.cloudlab.us, boolean reserved=false) for appattempt_1471639269423_0002_000001
2016-08-19 14:46:31,034 INFO org.apache.hadoop.yarn.server.resourcemanager.scheduler.fair.FSAppAttempt: assignContainer(FSSchedulerNode node:c220g1-031106.wisc.cloudlab.us, boolean reserved=false) for appattempt_1471639269423_0001_000001
2016-08-19 14:46:31,338 INFO org.apache.hadoop.yarn.server.resourcemanager.scheduler.fair.FairScheduler: allocate(appattempt_1471639269423_0001_000001 [{Priority: 1, Capability: <memory:1920, vCores:1>, # Containers: 4, Location: *, Relax Locality: true}] [] [] []
2016-08-19 14:46:31,338 INFO org.apache.hadoop.yarn.server.resourcemanager.scheduler.fair.FSAppAttempt: appattempt_1471639269423_0001_000001 minReqResource: <memory:0, vCores:0> flexibleResource: <memory:16384, vCores:8>
2016-08-19 14:46:31,338 INFO org.apache.hadoop.yarn.server.resourcemanager.scheduler.fair.FairScheduler: iglf: 1.getHeadroom()=<memory:6144, vCores:3>
2016-08-19 14:46:31,542 INFO org.apache.hadoop.yarn.server.resourcemanager.scheduler.fair.FairScheduler: allocate(appattempt_1471639269423_0001_000001 [] [] [] []
2016-08-19 14:46:31,543 INFO org.apache.hadoop.yarn.server.resourcemanager.scheduler.fair.FSAppAttempt: appattempt_1471639269423_0001_000001 minReqResource: <memory:0, vCores:0> flexibleResource: <memory:16384, vCores:8>
2016-08-19 14:46:31,543 INFO org.apache.hadoop.yarn.server.resourcemanager.scheduler.fair.FairScheduler: iglf: 1.getHeadroom()=<memory:6144, vCores:3>
2016-08-19 14:46:31,948 INFO org.apache.hadoop.yarn.server.resourcemanager.scheduler.fair.FairScheduler: allocate(appattempt_1471639269423_0001_000001 [] [] [] []
2016-08-19 14:46:31,949 INFO org.apache.hadoop.yarn.server.resourcemanager.scheduler.fair.FSAppAttempt: appattempt_1471639269423_0001_000001 minReqResource: <memory:0, vCores:0> flexibleResource: <memory:16384, vCores:8>
2016-08-19 14:46:31,949 INFO org.apache.hadoop.yarn.server.resourcemanager.scheduler.fair.FairScheduler: iglf: 1.getHeadroom()=<memory:6144, vCores:3>
2016-08-19 14:46:32,021 INFO org.apache.hadoop.yarn.server.resourcemanager.scheduler.fair.FSAppAttempt: assignContainer(FSSchedulerNode node:cp-1.yarn-perf.yarnrm-PG0.wisc.cloudlab.us, boolean reserved=false) for appattempt_1471639269423_0002_000001
2016-08-19 14:46:32,021 INFO org.apache.hadoop.yarn.server.resourcemanager.scheduler.fair.FSAppAttempt: assignContainer(FSSchedulerNode node:cp-1.yarn-perf.yarnrm-PG0.wisc.cloudlab.us, boolean reserved=false) for appattempt_1471639269423_0001_000001
2016-08-19 14:46:32,021 INFO org.apache.hadoop.yarn.server.resourcemanager.scheduler.fair.FSAppAttempt: assignContainer(FSSchedulerNode:cp-1.yarn-perf.yarnrm-PG0.wisc.cloudlab.us, ResourceRequest request, NodeType type, boolean reserved=false
2016-08-19 14:46:32,022 INFO org.apache.hadoop.yarn.server.resourcemanager.scheduler.fair.FSAppAttempt: Making reservation: node=cp-1.yarn-perf.yarnrm-PG0.wisc.cloudlab.us app_id=application_1471639269423_0001
2016-08-19 14:46:32,024 INFO org.apache.hadoop.yarn.server.resourcemanager.rmcontainer.RMContainerImpl: Processing container_1471639269423_0001_01_000005 of event RESERVED
2016-08-19 14:46:32,024 INFO org.apache.hadoop.yarn.server.resourcemanager.rmcontainer.RMContainerImpl: container_1471639269423_0001_01_000005 Container Transitioned from NEW to RESERVED
2016-08-19 14:46:32,024 INFO org.apache.hadoop.yarn.server.resourcemanager.scheduler.fair.FSSchedulerNode: Reserved container container_1471639269423_0001_01_000005 on node host: cp-1.yarn-perf.yarnrm-PG0.wisc.cloudlab.us:33756 #containers=4 available=<memory:0, vCores:0> used=<memory:8192, vCores:4> for application org.apache.hadoop.yarn.server.resourcemanager.scheduler.fair.FSAppAttempt@475e2446
2016-08-19 14:46:32,037 INFO org.apache.hadoop.yarn.server.resourcemanager.scheduler.fair.FSAppAttempt: assignContainer(FSSchedulerNode node:c220g1-031106.wisc.cloudlab.us, boolean reserved=false) for appattempt_1471639269423_0002_000001
2016-08-19 14:46:32,037 INFO org.apache.hadoop.yarn.server.resourcemanager.scheduler.fair.FSAppAttempt: assignContainer(FSSchedulerNode node:c220g1-031106.wisc.cloudlab.us, boolean reserved=false) for appattempt_1471639269423_0001_000001
2016-08-19 14:46:32,038 INFO org.apache.hadoop.yarn.server.resourcemanager.scheduler.fair.FSAppAttempt: assignContainer(FSSchedulerNode:c220g1-031106.wisc.cloudlab.us, ResourceRequest request, NodeType type, boolean reserved=false
2016-08-19 14:46:32,038 INFO org.apache.hadoop.yarn.server.resourcemanager.scheduler.fair.FSAppAttempt: allocate container: container_1471639269423_0001_01_000006 priority 1
2016-08-19 14:46:32,038 INFO org.apache.hadoop.yarn.server.resourcemanager.rmcontainer.RMContainerImpl: Processing container_1471639269423_0001_01_000006 of event START
2016-08-19 14:46:32,038 INFO org.apache.hadoop.yarn.server.resourcemanager.rmcontainer.RMContainerImpl: container_1471639269423_0001_01_000006 Container Transitioned from NEW to ALLOCATED
2016-08-19 14:46:32,038 INFO org.apache.hadoop.yarn.server.resourcemanager.RMAuditLogger: USER=tanle	OPERATION=AM Allocated Container	TARGET=SchedulerApp	RESULT=SUCCESS	APPID=application_1471639269423_0001	CONTAINERID=container_1471639269423_0001_01_000006
2016-08-19 14:46:32,038 INFO org.apache.hadoop.yarn.server.resourcemanager.scheduler.SchedulerNode: Assigned container container_1471639269423_0001_01_000006 of capacity <memory:2048, vCores:1> on host c220g1-031106.wisc.cloudlab.us:43516, which has 2 containers, <memory:4096, vCores:2> used and <memory:4096, vCores:2> available after allocation
2016-08-19 14:46:32,617 INFO SecurityLogger.org.apache.hadoop.ipc.Server: Auth successful for appattempt_1471639269423_0002_000001 (auth:SIMPLE)
2016-08-19 14:46:32,620 INFO org.apache.hadoop.yarn.server.resourcemanager.ApplicationMasterService: AM registration appattempt_1471639269423_0002_000001
2016-08-19 14:46:32,621 INFO org.apache.hadoop.yarn.server.resourcemanager.RMAuditLogger: USER=tanle	IP=128.104.222.17	OPERATION=Register App Master	TARGET=ApplicationMasterService	RESULT=SUCCESS	APPID=application_1471639269423_0002	APPATTEMPTID=appattempt_1471639269423_0002_000001
2016-08-19 14:46:32,621 INFO org.apache.hadoop.yarn.server.resourcemanager.rmapp.attempt.RMAppAttemptImpl: appattempt_1471639269423_0002_000001 State change from LAUNCHED to RUNNING
2016-08-19 14:46:32,621 INFO org.apache.hadoop.yarn.server.resourcemanager.rmapp.RMAppImpl: application_1471639269423_0002 State change from ACCEPTED to RUNNING
2016-08-19 14:46:32,684 INFO org.apache.hadoop.yarn.server.resourcemanager.scheduler.fair.FairScheduler: allocate(appattempt_1471639269423_0002_000001 [] [] [] []
2016-08-19 14:46:32,684 INFO org.apache.hadoop.yarn.server.resourcemanager.scheduler.fair.FSAppAttempt: appattempt_1471639269423_0002_000001 minReqResource: <memory:0, vCores:0> flexibleResource: <memory:16384, vCores:8>
2016-08-19 14:46:32,684 INFO org.apache.hadoop.yarn.server.resourcemanager.scheduler.fair.FairScheduler: iglf: 2.getHeadroom()=<memory:4096, vCores:2>
2016-08-19 14:46:32,715 INFO org.apache.hadoop.yarn.server.resourcemanager.scheduler.fair.FairScheduler: allocate(appattempt_1471639269423_0002_000001 [] [] [] []
2016-08-19 14:46:32,715 INFO org.apache.hadoop.yarn.server.resourcemanager.scheduler.fair.FSAppAttempt: appattempt_1471639269423_0002_000001 minReqResource: <memory:0, vCores:0> flexibleResource: <memory:16384, vCores:8>
2016-08-19 14:46:32,715 INFO org.apache.hadoop.yarn.server.resourcemanager.scheduler.fair.FairScheduler: iglf: 2.getHeadroom()=<memory:4096, vCores:2>
2016-08-19 14:46:32,753 INFO org.apache.hadoop.yarn.server.resourcemanager.scheduler.fair.FairScheduler: allocate(appattempt_1471639269423_0001_000001 [] [] [] []
2016-08-19 14:46:32,753 INFO org.apache.hadoop.yarn.server.resourcemanager.scheduler.fair.FSAppAttempt: appattempt_1471639269423_0001_000001 minReqResource: <memory:0, vCores:0> flexibleResource: <memory:16384, vCores:8>
2016-08-19 14:46:32,756 INFO org.apache.hadoop.yarn.server.resourcemanager.rmcontainer.RMContainerImpl: Processing container_1471639269423_0001_01_000006 of event ACQUIRED
2016-08-19 14:46:32,756 INFO org.apache.hadoop.yarn.server.resourcemanager.rmcontainer.RMContainerImpl: container_1471639269423_0001_01_000006 Container Transitioned from ALLOCATED to ACQUIRED
2016-08-19 14:46:32,757 INFO org.apache.hadoop.yarn.server.resourcemanager.scheduler.fair.FairScheduler: iglf: 1.getHeadroom()=<memory:4096, vCores:2>
2016-08-19 14:46:33,040 INFO org.apache.hadoop.yarn.server.resourcemanager.rmcontainer.RMContainerImpl: Processing container_1471639269423_0001_01_000006 of event LAUNCHED
2016-08-19 14:46:33,041 INFO org.apache.hadoop.yarn.server.resourcemanager.rmcontainer.RMContainerImpl: container_1471639269423_0001_01_000006 Container Transitioned from ACQUIRED to RUNNING
2016-08-19 14:46:33,041 INFO org.apache.hadoop.yarn.server.resourcemanager.scheduler.fair.FSAppAttempt: assignContainer(FSSchedulerNode node:c220g1-031106.wisc.cloudlab.us, boolean reserved=false) for appattempt_1471639269423_0002_000001
2016-08-19 14:46:33,041 INFO org.apache.hadoop.yarn.server.resourcemanager.scheduler.fair.FSAppAttempt: assignContainer(FSSchedulerNode node:c220g1-031106.wisc.cloudlab.us, boolean reserved=false) for appattempt_1471639269423_0001_000001
2016-08-19 14:46:33,042 INFO org.apache.hadoop.yarn.server.resourcemanager.scheduler.fair.FSAppAttempt: assignContainer(FSSchedulerNode:c220g1-031106.wisc.cloudlab.us, ResourceRequest request, NodeType type, boolean reserved=false
2016-08-19 14:46:33,042 INFO org.apache.hadoop.yarn.server.resourcemanager.scheduler.fair.FSAppAttempt: allocate container: container_1471639269423_0001_01_000007 priority 1
2016-08-19 14:46:33,042 INFO org.apache.hadoop.yarn.server.resourcemanager.rmcontainer.RMContainerImpl: Processing container_1471639269423_0001_01_000007 of event START
2016-08-19 14:46:33,042 INFO org.apache.hadoop.yarn.server.resourcemanager.rmcontainer.RMContainerImpl: container_1471639269423_0001_01_000007 Container Transitioned from NEW to ALLOCATED
2016-08-19 14:46:33,042 INFO org.apache.hadoop.yarn.server.resourcemanager.RMAuditLogger: USER=tanle	OPERATION=AM Allocated Container	TARGET=SchedulerApp	RESULT=SUCCESS	APPID=application_1471639269423_0001	CONTAINERID=container_1471639269423_0001_01_000007
2016-08-19 14:46:33,042 INFO org.apache.hadoop.yarn.server.resourcemanager.scheduler.SchedulerNode: Assigned container container_1471639269423_0001_01_000007 of capacity <memory:2048, vCores:1> on host c220g1-031106.wisc.cloudlab.us:43516, which has 3 containers, <memory:6144, vCores:3> used and <memory:2048, vCores:1> available after allocation
2016-08-19 14:46:34,043 INFO org.apache.hadoop.yarn.server.resourcemanager.scheduler.fair.FSAppAttempt: assignContainer(FSSchedulerNode node:c220g1-031106.wisc.cloudlab.us, boolean reserved=false) for appattempt_1471639269423_0002_000001
2016-08-19 14:46:34,044 INFO org.apache.hadoop.yarn.server.resourcemanager.scheduler.fair.FSAppAttempt: assignContainer(FSSchedulerNode node:c220g1-031106.wisc.cloudlab.us, boolean reserved=false) for appattempt_1471639269423_0001_000001
2016-08-19 14:46:34,044 INFO org.apache.hadoop.yarn.server.resourcemanager.scheduler.fair.FSAppAttempt: assignContainer(FSSchedulerNode:c220g1-031106.wisc.cloudlab.us, ResourceRequest request, NodeType type, boolean reserved=false
2016-08-19 14:46:34,044 INFO org.apache.hadoop.yarn.server.resourcemanager.scheduler.fair.FSAppAttempt: allocate container: container_1471639269423_0001_01_000008 priority 1
2016-08-19 14:46:34,044 INFO org.apache.hadoop.yarn.server.resourcemanager.rmcontainer.RMContainerImpl: Processing container_1471639269423_0001_01_000008 of event START
2016-08-19 14:46:34,044 INFO org.apache.hadoop.yarn.server.resourcemanager.rmcontainer.RMContainerImpl: container_1471639269423_0001_01_000008 Container Transitioned from NEW to ALLOCATED
2016-08-19 14:46:34,044 INFO org.apache.hadoop.yarn.server.resourcemanager.RMAuditLogger: USER=tanle	OPERATION=AM Allocated Container	TARGET=SchedulerApp	RESULT=SUCCESS	APPID=application_1471639269423_0001	CONTAINERID=container_1471639269423_0001_01_000008
2016-08-19 14:46:34,045 INFO org.apache.hadoop.yarn.server.resourcemanager.scheduler.SchedulerNode: Assigned container container_1471639269423_0001_01_000008 of capacity <memory:2048, vCores:1> on host c220g1-031106.wisc.cloudlab.us:43516, which has 4 containers, <memory:8192, vCores:4> used and <memory:0, vCores:0> available after allocation
2016-08-19 14:46:34,363 INFO org.apache.hadoop.yarn.server.resourcemanager.scheduler.fair.FairScheduler: allocate(appattempt_1471639269423_0001_000001 [{Priority: 1, Capability: <memory:1920, vCores:1>, # Containers: 3, Location: *, Relax Locality: true}] [] [] []
2016-08-19 14:46:34,364 INFO org.apache.hadoop.yarn.server.resourcemanager.scheduler.fair.FSAppAttempt: appattempt_1471639269423_0001_000001 minReqResource: <memory:0, vCores:0> flexibleResource: <memory:16384, vCores:8>
2016-08-19 14:46:34,369 INFO org.apache.hadoop.yarn.server.resourcemanager.rmcontainer.RMContainerImpl: Processing container_1471639269423_0001_01_000007 of event ACQUIRED
2016-08-19 14:46:34,370 INFO org.apache.hadoop.yarn.server.resourcemanager.rmcontainer.RMContainerImpl: container_1471639269423_0001_01_000007 Container Transitioned from ALLOCATED to ACQUIRED
2016-08-19 14:46:34,385 INFO org.apache.hadoop.yarn.server.resourcemanager.rmcontainer.RMContainerImpl: Processing container_1471639269423_0001_01_000008 of event ACQUIRED
2016-08-19 14:46:34,385 INFO org.apache.hadoop.yarn.server.resourcemanager.rmcontainer.RMContainerImpl: container_1471639269423_0001_01_000008 Container Transitioned from ALLOCATED to ACQUIRED
2016-08-19 14:46:34,385 INFO org.apache.hadoop.yarn.server.resourcemanager.scheduler.fair.FairScheduler: iglf: 1.getHeadroom()=<memory:0, vCores:0>
2016-08-19 14:46:35,047 INFO org.apache.hadoop.yarn.server.resourcemanager.rmcontainer.RMContainerImpl: Processing container_1471639269423_0001_01_000007 of event LAUNCHED
2016-08-19 14:46:35,047 INFO org.apache.hadoop.yarn.server.resourcemanager.rmcontainer.RMContainerImpl: container_1471639269423_0001_01_000007 Container Transitioned from ACQUIRED to RUNNING
2016-08-19 14:46:35,048 INFO org.apache.hadoop.yarn.server.resourcemanager.rmcontainer.RMContainerImpl: Processing container_1471639269423_0001_01_000008 of event LAUNCHED
2016-08-19 14:46:35,048 INFO org.apache.hadoop.yarn.server.resourcemanager.rmcontainer.RMContainerImpl: container_1471639269423_0001_01_000008 Container Transitioned from ACQUIRED to RUNNING
2016-08-19 14:46:35,048 INFO org.apache.hadoop.yarn.server.resourcemanager.scheduler.fair.FSAppAttempt: assignContainer(FSSchedulerNode node:c220g1-031106.wisc.cloudlab.us, boolean reserved=false) for appattempt_1471639269423_0002_000001
2016-08-19 14:46:35,048 INFO org.apache.hadoop.yarn.server.resourcemanager.scheduler.fair.FSAppAttempt: assignContainer(FSSchedulerNode node:c220g1-031106.wisc.cloudlab.us, boolean reserved=false) for appattempt_1471639269423_0001_000001
2016-08-19 14:46:35,048 INFO org.apache.hadoop.yarn.server.resourcemanager.scheduler.fair.FSAppAttempt: assignContainer(FSSchedulerNode:c220g1-031106.wisc.cloudlab.us, ResourceRequest request, NodeType type, boolean reserved=false
2016-08-19 14:46:35,049 INFO org.apache.hadoop.yarn.server.resourcemanager.scheduler.fair.FSAppAttempt: Making reservation: node=c220g1-031106.wisc.cloudlab.us app_id=application_1471639269423_0001
2016-08-19 14:46:35,049 INFO org.apache.hadoop.yarn.server.resourcemanager.rmcontainer.RMContainerImpl: Processing container_1471639269423_0001_01_000009 of event RESERVED
2016-08-19 14:46:35,049 INFO org.apache.hadoop.yarn.server.resourcemanager.rmcontainer.RMContainerImpl: container_1471639269423_0001_01_000009 Container Transitioned from NEW to RESERVED
2016-08-19 14:46:35,049 INFO org.apache.hadoop.yarn.server.resourcemanager.scheduler.fair.FSSchedulerNode: Reserved container container_1471639269423_0001_01_000009 on node host: c220g1-031106.wisc.cloudlab.us:43516 #containers=4 available=<memory:0, vCores:0> used=<memory:8192, vCores:4> for application org.apache.hadoop.yarn.server.resourcemanager.scheduler.fair.FSAppAttempt@475e2446
2016-08-19 14:46:35,721 INFO org.apache.hadoop.yarn.server.resourcemanager.scheduler.fair.FairScheduler: allocate(appattempt_1471639269423_0002_000001 [] [] [] []
2016-08-19 14:46:35,721 INFO org.apache.hadoop.yarn.server.resourcemanager.scheduler.fair.FSAppAttempt: appattempt_1471639269423_0002_000001 minReqResource: <memory:0, vCores:0> flexibleResource: <memory:16384, vCores:8>
2016-08-19 14:46:35,721 INFO org.apache.hadoop.yarn.server.resourcemanager.scheduler.fair.FairScheduler: iglf: 2.getHeadroom()=<memory:0, vCores:0>
2016-08-19 14:46:36,339 INFO org.apache.hadoop.yarn.server.resourcemanager.scheduler.fair.FairScheduler: allocate(appattempt_1471639269423_0001_000001 [{Priority: 1, Capability: <memory:1920, vCores:1>, # Containers: 9, Location: *, Relax Locality: true}] [] [] []
2016-08-19 14:46:36,340 INFO org.apache.hadoop.yarn.server.resourcemanager.scheduler.fair.FSAppAttempt: appattempt_1471639269423_0001_000001 minReqResource: <memory:0, vCores:0> flexibleResource: <memory:16384, vCores:8>
2016-08-19 14:46:36,340 INFO org.apache.hadoop.yarn.server.resourcemanager.scheduler.fair.FairScheduler: iglf: 1.getHeadroom()=<memory:0, vCores:0>
2016-08-19 14:46:36,544 INFO org.apache.hadoop.yarn.server.resourcemanager.scheduler.fair.FairScheduler: allocate(appattempt_1471639269423_0001_000001 [] [] [] []
2016-08-19 14:46:36,544 INFO org.apache.hadoop.yarn.server.resourcemanager.scheduler.fair.FSAppAttempt: appattempt_1471639269423_0001_000001 minReqResource: <memory:0, vCores:0> flexibleResource: <memory:16384, vCores:8>
2016-08-19 14:46:36,544 INFO org.apache.hadoop.yarn.server.resourcemanager.scheduler.fair.FairScheduler: iglf: 1.getHeadroom()=<memory:0, vCores:0>
2016-08-19 14:46:36,948 INFO org.apache.hadoop.yarn.server.resourcemanager.scheduler.fair.FairScheduler: allocate(appattempt_1471639269423_0001_000001 [] [] [] []
2016-08-19 14:46:36,948 INFO org.apache.hadoop.yarn.server.resourcemanager.scheduler.fair.FSAppAttempt: appattempt_1471639269423_0001_000001 minReqResource: <memory:0, vCores:0> flexibleResource: <memory:16384, vCores:8>
2016-08-19 14:46:36,948 INFO org.apache.hadoop.yarn.server.resourcemanager.scheduler.fair.FairScheduler: iglf: 1.getHeadroom()=<memory:0, vCores:0>
2016-08-19 14:46:37,752 INFO org.apache.hadoop.yarn.server.resourcemanager.scheduler.fair.FairScheduler: allocate(appattempt_1471639269423_0001_000001 [] [] [] []
2016-08-19 14:46:37,752 INFO org.apache.hadoop.yarn.server.resourcemanager.scheduler.fair.FSAppAttempt: appattempt_1471639269423_0001_000001 minReqResource: <memory:0, vCores:0> flexibleResource: <memory:16384, vCores:8>
2016-08-19 14:46:37,752 INFO org.apache.hadoop.yarn.server.resourcemanager.scheduler.fair.FairScheduler: iglf: 1.getHeadroom()=<memory:0, vCores:0>
2016-08-19 14:46:38,519 INFO org.apache.hadoop.yarn.server.resourcemanager.scheduler.fair.FairScheduler: allocate(appattempt_1471639269423_0002_000001 [{Priority: 1, Capability: <memory:1920, vCores:1>, # Containers: 1, Location: *, Relax Locality: true}] [] [] []
2016-08-19 14:46:38,520 INFO org.apache.hadoop.yarn.server.resourcemanager.scheduler.fair.FSAppAttempt: appattempt_1471639269423_0002_000001 minReqResource: <memory:0, vCores:0> flexibleResource: <memory:16384, vCores:8>
2016-08-19 14:46:38,520 INFO org.apache.hadoop.yarn.server.resourcemanager.scheduler.fair.FairScheduler: iglf: 2.getHeadroom()=<memory:0, vCores:0>
2016-08-19 14:46:38,724 INFO org.apache.hadoop.yarn.server.resourcemanager.scheduler.fair.FairScheduler: allocate(appattempt_1471639269423_0002_000001 [] [] [] []
2016-08-19 14:46:38,724 INFO org.apache.hadoop.yarn.server.resourcemanager.scheduler.fair.FSAppAttempt: appattempt_1471639269423_0002_000001 minReqResource: <memory:0, vCores:0> flexibleResource: <memory:16384, vCores:8>
2016-08-19 14:46:38,724 INFO org.apache.hadoop.yarn.server.resourcemanager.scheduler.fair.FairScheduler: iglf: 2.getHeadroom()=<memory:0, vCores:0>
2016-08-19 14:46:39,128 INFO org.apache.hadoop.yarn.server.resourcemanager.scheduler.fair.FairScheduler: allocate(appattempt_1471639269423_0002_000001 [] [] [] []
2016-08-19 14:46:39,129 INFO org.apache.hadoop.yarn.server.resourcemanager.scheduler.fair.FSAppAttempt: appattempt_1471639269423_0002_000001 minReqResource: <memory:0, vCores:0> flexibleResource: <memory:16384, vCores:8>
2016-08-19 14:46:39,129 INFO org.apache.hadoop.yarn.server.resourcemanager.scheduler.fair.FairScheduler: iglf: 2.getHeadroom()=<memory:0, vCores:0>
2016-08-19 14:46:39,357 INFO org.apache.hadoop.yarn.server.resourcemanager.scheduler.fair.FairScheduler: allocate(appattempt_1471639269423_0001_000001 [] [] [] []
2016-08-19 14:46:39,357 INFO org.apache.hadoop.yarn.server.resourcemanager.scheduler.fair.FSAppAttempt: appattempt_1471639269423_0001_000001 minReqResource: <memory:0, vCores:0> flexibleResource: <memory:16384, vCores:8>
2016-08-19 14:46:39,357 INFO org.apache.hadoop.yarn.server.resourcemanager.scheduler.fair.FairScheduler: iglf: 1.getHeadroom()=<memory:0, vCores:0>
2016-08-19 14:46:39,933 INFO org.apache.hadoop.yarn.server.resourcemanager.scheduler.fair.FairScheduler: allocate(appattempt_1471639269423_0002_000001 [] [] [] []
2016-08-19 14:46:39,933 INFO org.apache.hadoop.yarn.server.resourcemanager.scheduler.fair.FSAppAttempt: appattempt_1471639269423_0002_000001 minReqResource: <memory:0, vCores:0> flexibleResource: <memory:16384, vCores:8>
2016-08-19 14:46:39,933 INFO org.apache.hadoop.yarn.server.resourcemanager.scheduler.fair.FairScheduler: iglf: 2.getHeadroom()=<memory:0, vCores:0>
2016-08-19 14:46:41,338 INFO org.apache.hadoop.yarn.server.resourcemanager.scheduler.fair.FairScheduler: allocate(appattempt_1471639269423_0001_000001 [{Priority: 1, Capability: <memory:1920, vCores:1>, # Containers: 25, Location: *, Relax Locality: true}] [] [] []
2016-08-19 14:46:41,339 INFO org.apache.hadoop.yarn.server.resourcemanager.scheduler.fair.FSAppAttempt: appattempt_1471639269423_0001_000001 minReqResource: <memory:0, vCores:0> flexibleResource: <memory:16384, vCores:8>
2016-08-19 14:46:41,339 INFO org.apache.hadoop.yarn.server.resourcemanager.scheduler.fair.FairScheduler: iglf: 1.getHeadroom()=<memory:0, vCores:0>
2016-08-19 14:46:41,538 INFO org.apache.hadoop.yarn.server.resourcemanager.scheduler.fair.FairScheduler: allocate(appattempt_1471639269423_0002_000001 [] [] [] []
2016-08-19 14:46:41,538 INFO org.apache.hadoop.yarn.server.resourcemanager.scheduler.fair.FSAppAttempt: appattempt_1471639269423_0002_000001 minReqResource: <memory:0, vCores:0> flexibleResource: <memory:16384, vCores:8>
2016-08-19 14:46:41,538 INFO org.apache.hadoop.yarn.server.resourcemanager.scheduler.fair.FairScheduler: iglf: 2.getHeadroom()=<memory:0, vCores:0>
2016-08-19 14:46:41,542 INFO org.apache.hadoop.yarn.server.resourcemanager.scheduler.fair.FairScheduler: allocate(appattempt_1471639269423_0001_000001 [] [] [] []
2016-08-19 14:46:41,543 INFO org.apache.hadoop.yarn.server.resourcemanager.scheduler.fair.FSAppAttempt: appattempt_1471639269423_0001_000001 minReqResource: <memory:0, vCores:0> flexibleResource: <memory:16384, vCores:8>
2016-08-19 14:46:41,543 INFO org.apache.hadoop.yarn.server.resourcemanager.scheduler.fair.FairScheduler: iglf: 1.getHeadroom()=<memory:0, vCores:0>
2016-08-19 14:46:41,947 INFO org.apache.hadoop.yarn.server.resourcemanager.scheduler.fair.FairScheduler: allocate(appattempt_1471639269423_0001_000001 [] [] [] []
2016-08-19 14:46:41,947 INFO org.apache.hadoop.yarn.server.resourcemanager.scheduler.fair.FSAppAttempt: appattempt_1471639269423_0001_000001 minReqResource: <memory:0, vCores:0> flexibleResource: <memory:16384, vCores:8>
2016-08-19 14:46:41,947 INFO org.apache.hadoop.yarn.server.resourcemanager.scheduler.fair.FairScheduler: iglf: 1.getHeadroom()=<memory:0, vCores:0>
2016-08-19 14:46:42,751 INFO org.apache.hadoop.yarn.server.resourcemanager.scheduler.fair.FairScheduler: allocate(appattempt_1471639269423_0001_000001 [] [] [] []
2016-08-19 14:46:42,751 INFO org.apache.hadoop.yarn.server.resourcemanager.scheduler.fair.FSAppAttempt: appattempt_1471639269423_0001_000001 minReqResource: <memory:0, vCores:0> flexibleResource: <memory:16384, vCores:8>
2016-08-19 14:46:42,752 INFO org.apache.hadoop.yarn.server.resourcemanager.scheduler.fair.FairScheduler: iglf: 1.getHeadroom()=<memory:0, vCores:0>
2016-08-19 14:46:43,492 INFO org.apache.hadoop.yarn.server.resourcemanager.scheduler.fair.FairScheduler: allocate(appattempt_1471639269423_0002_000001 [{Priority: 1, Capability: <memory:1920, vCores:1>, # Containers: 3, Location: *, Relax Locality: true}] [] [] []
2016-08-19 14:46:43,492 INFO org.apache.hadoop.yarn.server.resourcemanager.scheduler.fair.FSAppAttempt: appattempt_1471639269423_0002_000001 minReqResource: <memory:0, vCores:0> flexibleResource: <memory:16384, vCores:8>
2016-08-19 14:46:43,492 INFO org.apache.hadoop.yarn.server.resourcemanager.scheduler.fair.FairScheduler: iglf: 2.getHeadroom()=<memory:0, vCores:0>
2016-08-19 14:46:43,696 INFO org.apache.hadoop.yarn.server.resourcemanager.scheduler.fair.FairScheduler: allocate(appattempt_1471639269423_0002_000001 [] [] [] []
2016-08-19 14:46:43,697 INFO org.apache.hadoop.yarn.server.resourcemanager.scheduler.fair.FSAppAttempt: appattempt_1471639269423_0002_000001 minReqResource: <memory:0, vCores:0> flexibleResource: <memory:16384, vCores:8>
2016-08-19 14:46:43,697 INFO org.apache.hadoop.yarn.server.resourcemanager.scheduler.fair.FairScheduler: iglf: 2.getHeadroom()=<memory:0, vCores:0>
2016-08-19 14:46:44,100 INFO org.apache.hadoop.yarn.server.resourcemanager.scheduler.fair.FairScheduler: allocate(appattempt_1471639269423_0002_000001 [] [] [] []
2016-08-19 14:46:44,100 INFO org.apache.hadoop.yarn.server.resourcemanager.scheduler.fair.FSAppAttempt: appattempt_1471639269423_0002_000001 minReqResource: <memory:0, vCores:0> flexibleResource: <memory:16384, vCores:8>
2016-08-19 14:46:44,100 INFO org.apache.hadoop.yarn.server.resourcemanager.scheduler.fair.FairScheduler: iglf: 2.getHeadroom()=<memory:0, vCores:0>
2016-08-19 14:46:44,355 INFO org.apache.hadoop.yarn.server.resourcemanager.scheduler.fair.FairScheduler: allocate(appattempt_1471639269423_0001_000001 [] [] [] []
2016-08-19 14:46:44,355 INFO org.apache.hadoop.yarn.server.resourcemanager.scheduler.fair.FSAppAttempt: appattempt_1471639269423_0001_000001 minReqResource: <memory:0, vCores:0> flexibleResource: <memory:16384, vCores:8>
2016-08-19 14:46:44,355 INFO org.apache.hadoop.yarn.server.resourcemanager.scheduler.fair.FairScheduler: iglf: 1.getHeadroom()=<memory:0, vCores:0>
2016-08-19 14:46:44,904 INFO org.apache.hadoop.yarn.server.resourcemanager.scheduler.fair.FairScheduler: allocate(appattempt_1471639269423_0002_000001 [] [] [] []
2016-08-19 14:46:44,905 INFO org.apache.hadoop.yarn.server.resourcemanager.scheduler.fair.FSAppAttempt: appattempt_1471639269423_0002_000001 minReqResource: <memory:0, vCores:0> flexibleResource: <memory:16384, vCores:8>
2016-08-19 14:46:44,905 INFO org.apache.hadoop.yarn.server.resourcemanager.scheduler.fair.FairScheduler: iglf: 2.getHeadroom()=<memory:0, vCores:0>
2016-08-19 14:46:46,339 INFO org.apache.hadoop.yarn.server.resourcemanager.scheduler.fair.FairScheduler: allocate(appattempt_1471639269423_0001_000001 [{Priority: 1, Capability: <memory:1920, vCores:1>, # Containers: 57, Location: *, Relax Locality: true}] [] [] []
2016-08-19 14:46:46,339 INFO org.apache.hadoop.yarn.server.resourcemanager.scheduler.fair.FSAppAttempt: appattempt_1471639269423_0001_000001 minReqResource: <memory:0, vCores:0> flexibleResource: <memory:16384, vCores:8>
2016-08-19 14:46:46,339 INFO org.apache.hadoop.yarn.server.resourcemanager.scheduler.fair.FairScheduler: iglf: 1.getHeadroom()=<memory:0, vCores:0>
2016-08-19 14:46:46,509 INFO org.apache.hadoop.yarn.server.resourcemanager.scheduler.fair.FairScheduler: allocate(appattempt_1471639269423_0002_000001 [] [] [] []
2016-08-19 14:46:46,509 INFO org.apache.hadoop.yarn.server.resourcemanager.scheduler.fair.FSAppAttempt: appattempt_1471639269423_0002_000001 minReqResource: <memory:0, vCores:0> flexibleResource: <memory:16384, vCores:8>
2016-08-19 14:46:46,509 INFO org.apache.hadoop.yarn.server.resourcemanager.scheduler.fair.FairScheduler: iglf: 2.getHeadroom()=<memory:0, vCores:0>
2016-08-19 14:46:46,543 INFO org.apache.hadoop.yarn.server.resourcemanager.scheduler.fair.FairScheduler: allocate(appattempt_1471639269423_0001_000001 [] [] [] []
2016-08-19 14:46:46,543 INFO org.apache.hadoop.yarn.server.resourcemanager.scheduler.fair.FSAppAttempt: appattempt_1471639269423_0001_000001 minReqResource: <memory:0, vCores:0> flexibleResource: <memory:16384, vCores:8>
2016-08-19 14:46:46,543 INFO org.apache.hadoop.yarn.server.resourcemanager.scheduler.fair.FairScheduler: iglf: 1.getHeadroom()=<memory:0, vCores:0>
2016-08-19 14:46:46,947 INFO org.apache.hadoop.yarn.server.resourcemanager.scheduler.fair.FairScheduler: allocate(appattempt_1471639269423_0001_000001 [] [] [] []
2016-08-19 14:46:46,947 INFO org.apache.hadoop.yarn.server.resourcemanager.scheduler.fair.FSAppAttempt: appattempt_1471639269423_0001_000001 minReqResource: <memory:0, vCores:0> flexibleResource: <memory:16384, vCores:8>
2016-08-19 14:46:46,947 INFO org.apache.hadoop.yarn.server.resourcemanager.scheduler.fair.FairScheduler: iglf: 1.getHeadroom()=<memory:0, vCores:0>
2016-08-19 14:46:47,751 INFO org.apache.hadoop.yarn.server.resourcemanager.scheduler.fair.FairScheduler: allocate(appattempt_1471639269423_0001_000001 [] [] [] []
2016-08-19 14:46:47,751 INFO org.apache.hadoop.yarn.server.resourcemanager.scheduler.fair.FSAppAttempt: appattempt_1471639269423_0001_000001 minReqResource: <memory:0, vCores:0> flexibleResource: <memory:16384, vCores:8>
2016-08-19 14:46:47,751 INFO org.apache.hadoop.yarn.server.resourcemanager.scheduler.fair.FairScheduler: iglf: 1.getHeadroom()=<memory:0, vCores:0>
2016-08-19 14:46:48,243 INFO org.apache.hadoop.yarn.server.resourcemanager.ClientRMService: Allocated new applicationId: 3
2016-08-19 14:46:48,309 INFO org.apache.hadoop.yarn.server.resourcemanager.ClientRMService: Allocated new applicationId: 4
2016-08-19 14:46:48,311 INFO org.apache.hadoop.yarn.server.resourcemanager.ClientRMService: Allocated new applicationId: 5
2016-08-19 14:46:48,492 INFO org.apache.hadoop.yarn.server.resourcemanager.scheduler.fair.FairScheduler: allocate(appattempt_1471639269423_0002_000001 [{Priority: 1, Capability: <memory:1920, vCores:1>, # Containers: 7, Location: *, Relax Locality: true}] [] [] []
2016-08-19 14:46:48,492 INFO org.apache.hadoop.yarn.server.resourcemanager.scheduler.fair.FSAppAttempt: appattempt_1471639269423_0002_000001 minReqResource: <memory:0, vCores:0> flexibleResource: <memory:16384, vCores:8>
2016-08-19 14:46:48,492 INFO org.apache.hadoop.yarn.server.resourcemanager.scheduler.fair.FairScheduler: iglf: 2.getHeadroom()=<memory:0, vCores:0>
2016-08-19 14:46:48,697 INFO org.apache.hadoop.yarn.server.resourcemanager.scheduler.fair.FairScheduler: allocate(appattempt_1471639269423_0002_000001 [] [] [] []
2016-08-19 14:46:48,697 INFO org.apache.hadoop.yarn.server.resourcemanager.scheduler.fair.FSAppAttempt: appattempt_1471639269423_0002_000001 minReqResource: <memory:0, vCores:0> flexibleResource: <memory:16384, vCores:8>
2016-08-19 14:46:48,697 INFO org.apache.hadoop.yarn.server.resourcemanager.scheduler.fair.FairScheduler: iglf: 2.getHeadroom()=<memory:0, vCores:0>
2016-08-19 14:46:49,102 INFO org.apache.hadoop.yarn.server.resourcemanager.scheduler.fair.FairScheduler: allocate(appattempt_1471639269423_0002_000001 [] [] [] []
2016-08-19 14:46:49,102 INFO org.apache.hadoop.yarn.server.resourcemanager.scheduler.fair.FSAppAttempt: appattempt_1471639269423_0002_000001 minReqResource: <memory:0, vCores:0> flexibleResource: <memory:16384, vCores:8>
2016-08-19 14:46:49,102 INFO org.apache.hadoop.yarn.server.resourcemanager.scheduler.fair.FairScheduler: iglf: 2.getHeadroom()=<memory:0, vCores:0>
2016-08-19 14:46:49,357 INFO org.apache.hadoop.yarn.server.resourcemanager.scheduler.fair.FairScheduler: allocate(appattempt_1471639269423_0001_000001 [] [] [] []
2016-08-19 14:46:49,357 INFO org.apache.hadoop.yarn.server.resourcemanager.scheduler.fair.FSAppAttempt: appattempt_1471639269423_0001_000001 minReqResource: <memory:0, vCores:0> flexibleResource: <memory:16384, vCores:8>
2016-08-19 14:46:49,357 INFO org.apache.hadoop.yarn.server.resourcemanager.scheduler.fair.FairScheduler: iglf: 1.getHeadroom()=<memory:0, vCores:0>
2016-08-19 14:46:49,907 INFO org.apache.hadoop.yarn.server.resourcemanager.scheduler.fair.FairScheduler: allocate(appattempt_1471639269423_0002_000001 [] [] [] []
2016-08-19 14:46:49,907 INFO org.apache.hadoop.yarn.server.resourcemanager.scheduler.fair.FSAppAttempt: appattempt_1471639269423_0002_000001 minReqResource: <memory:0, vCores:0> flexibleResource: <memory:16384, vCores:8>
2016-08-19 14:46:49,907 INFO org.apache.hadoop.yarn.server.resourcemanager.scheduler.fair.FairScheduler: iglf: 2.getHeadroom()=<memory:0, vCores:0>
2016-08-19 14:46:51,341 INFO org.apache.hadoop.yarn.server.resourcemanager.scheduler.fair.FairScheduler: allocate(appattempt_1471639269423_0001_000001 [{Priority: 1, Capability: <memory:1920, vCores:1>, # Containers: 121, Location: *, Relax Locality: true}] [] [] []
2016-08-19 14:46:51,342 INFO org.apache.hadoop.yarn.server.resourcemanager.scheduler.fair.FSAppAttempt: appattempt_1471639269423_0001_000001 minReqResource: <memory:0, vCores:0> flexibleResource: <memory:16384, vCores:8>
2016-08-19 14:46:51,342 INFO org.apache.hadoop.yarn.server.resourcemanager.scheduler.fair.FairScheduler: iglf: 1.getHeadroom()=<memory:0, vCores:0>
2016-08-19 14:46:51,511 INFO org.apache.hadoop.yarn.server.resourcemanager.scheduler.fair.FairScheduler: allocate(appattempt_1471639269423_0002_000001 [] [] [] []
2016-08-19 14:46:51,511 INFO org.apache.hadoop.yarn.server.resourcemanager.scheduler.fair.FSAppAttempt: appattempt_1471639269423_0002_000001 minReqResource: <memory:0, vCores:0> flexibleResource: <memory:16384, vCores:8>
2016-08-19 14:46:51,511 INFO org.apache.hadoop.yarn.server.resourcemanager.scheduler.fair.FairScheduler: iglf: 2.getHeadroom()=<memory:0, vCores:0>
2016-08-19 14:46:51,545 INFO org.apache.hadoop.yarn.server.resourcemanager.scheduler.fair.FairScheduler: allocate(appattempt_1471639269423_0001_000001 [] [] [] []
2016-08-19 14:46:51,545 INFO org.apache.hadoop.yarn.server.resourcemanager.scheduler.fair.FSAppAttempt: appattempt_1471639269423_0001_000001 minReqResource: <memory:0, vCores:0> flexibleResource: <memory:16384, vCores:8>
2016-08-19 14:46:51,545 INFO org.apache.hadoop.yarn.server.resourcemanager.scheduler.fair.FairScheduler: iglf: 1.getHeadroom()=<memory:0, vCores:0>
2016-08-19 14:46:51,948 INFO org.apache.hadoop.yarn.server.resourcemanager.scheduler.fair.FairScheduler: allocate(appattempt_1471639269423_0001_000001 [] [] [] []
2016-08-19 14:46:51,949 INFO org.apache.hadoop.yarn.server.resourcemanager.scheduler.fair.FSAppAttempt: appattempt_1471639269423_0001_000001 minReqResource: <memory:0, vCores:0> flexibleResource: <memory:16384, vCores:8>
2016-08-19 14:46:51,949 INFO org.apache.hadoop.yarn.server.resourcemanager.scheduler.fair.FairScheduler: iglf: 1.getHeadroom()=<memory:0, vCores:0>
2016-08-19 14:46:52,752 INFO org.apache.hadoop.yarn.server.resourcemanager.scheduler.fair.FairScheduler: allocate(appattempt_1471639269423_0001_000001 [] [] [] []
2016-08-19 14:46:52,753 INFO org.apache.hadoop.yarn.server.resourcemanager.scheduler.fair.FSAppAttempt: appattempt_1471639269423_0001_000001 minReqResource: <memory:0, vCores:0> flexibleResource: <memory:16384, vCores:8>
2016-08-19 14:46:52,753 INFO org.apache.hadoop.yarn.server.resourcemanager.scheduler.fair.FairScheduler: iglf: 1.getHeadroom()=<memory:0, vCores:0>
2016-08-19 14:46:53,492 INFO org.apache.hadoop.yarn.server.resourcemanager.scheduler.fair.FairScheduler: allocate(appattempt_1471639269423_0002_000001 [{Priority: 1, Capability: <memory:1920, vCores:1>, # Containers: 15, Location: *, Relax Locality: true}] [] [] []
2016-08-19 14:46:53,492 INFO org.apache.hadoop.yarn.server.resourcemanager.scheduler.fair.FSAppAttempt: appattempt_1471639269423_0002_000001 minReqResource: <memory:0, vCores:0> flexibleResource: <memory:16384, vCores:8>
2016-08-19 14:46:53,492 INFO org.apache.hadoop.yarn.server.resourcemanager.scheduler.fair.FairScheduler: iglf: 2.getHeadroom()=<memory:0, vCores:0>
2016-08-19 14:46:53,696 INFO org.apache.hadoop.yarn.server.resourcemanager.scheduler.fair.FairScheduler: allocate(appattempt_1471639269423_0002_000001 [] [] [] []
2016-08-19 14:46:53,696 INFO org.apache.hadoop.yarn.server.resourcemanager.scheduler.fair.FSAppAttempt: appattempt_1471639269423_0002_000001 minReqResource: <memory:0, vCores:0> flexibleResource: <memory:16384, vCores:8>
2016-08-19 14:46:53,696 INFO org.apache.hadoop.yarn.server.resourcemanager.scheduler.fair.FairScheduler: iglf: 2.getHeadroom()=<memory:0, vCores:0>
2016-08-19 14:46:54,099 INFO org.apache.hadoop.yarn.server.resourcemanager.scheduler.fair.FairScheduler: allocate(appattempt_1471639269423_0002_000001 [] [] [] []
2016-08-19 14:46:54,100 INFO org.apache.hadoop.yarn.server.resourcemanager.scheduler.fair.FSAppAttempt: appattempt_1471639269423_0002_000001 minReqResource: <memory:0, vCores:0> flexibleResource: <memory:16384, vCores:8>
2016-08-19 14:46:54,100 INFO org.apache.hadoop.yarn.server.resourcemanager.scheduler.fair.FairScheduler: iglf: 2.getHeadroom()=<memory:0, vCores:0>
2016-08-19 14:46:54,356 INFO org.apache.hadoop.yarn.server.resourcemanager.scheduler.fair.FairScheduler: allocate(appattempt_1471639269423_0001_000001 [] [] [] []
2016-08-19 14:46:54,356 INFO org.apache.hadoop.yarn.server.resourcemanager.scheduler.fair.FSAppAttempt: appattempt_1471639269423_0001_000001 minReqResource: <memory:0, vCores:0> flexibleResource: <memory:16384, vCores:8>
2016-08-19 14:46:54,356 INFO org.apache.hadoop.yarn.server.resourcemanager.scheduler.fair.FairScheduler: iglf: 1.getHeadroom()=<memory:0, vCores:0>
2016-08-19 14:46:54,903 INFO org.apache.hadoop.yarn.server.resourcemanager.scheduler.fair.FairScheduler: allocate(appattempt_1471639269423_0002_000001 [] [] [] []
2016-08-19 14:46:54,904 INFO org.apache.hadoop.yarn.server.resourcemanager.scheduler.fair.FSAppAttempt: appattempt_1471639269423_0002_000001 minReqResource: <memory:0, vCores:0> flexibleResource: <memory:16384, vCores:8>
2016-08-19 14:46:54,904 INFO org.apache.hadoop.yarn.server.resourcemanager.scheduler.fair.FairScheduler: iglf: 2.getHeadroom()=<memory:0, vCores:0>
2016-08-19 14:46:56,347 INFO org.apache.hadoop.yarn.server.resourcemanager.scheduler.fair.FairScheduler: allocate(appattempt_1471639269423_0001_000001 [{Priority: 1, Capability: <memory:1920, vCores:1>, # Containers: 249, Location: *, Relax Locality: true}] [] [] []
2016-08-19 14:46:56,347 INFO org.apache.hadoop.yarn.server.resourcemanager.scheduler.fair.FSAppAttempt: appattempt_1471639269423_0001_000001 minReqResource: <memory:0, vCores:0> flexibleResource: <memory:16384, vCores:8>
2016-08-19 14:46:56,348 INFO org.apache.hadoop.yarn.server.resourcemanager.scheduler.fair.FairScheduler: iglf: 1.getHeadroom()=<memory:0, vCores:0>
2016-08-19 14:46:56,507 INFO org.apache.hadoop.yarn.server.resourcemanager.scheduler.fair.FairScheduler: allocate(appattempt_1471639269423_0002_000001 [] [] [] []
2016-08-19 14:46:56,508 INFO org.apache.hadoop.yarn.server.resourcemanager.scheduler.fair.FSAppAttempt: appattempt_1471639269423_0002_000001 minReqResource: <memory:0, vCores:0> flexibleResource: <memory:16384, vCores:8>
2016-08-19 14:46:56,508 INFO org.apache.hadoop.yarn.server.resourcemanager.scheduler.fair.FairScheduler: iglf: 2.getHeadroom()=<memory:0, vCores:0>
2016-08-19 14:46:56,551 INFO org.apache.hadoop.yarn.server.resourcemanager.scheduler.fair.FairScheduler: allocate(appattempt_1471639269423_0001_000001 [] [] [] []
2016-08-19 14:46:56,552 INFO org.apache.hadoop.yarn.server.resourcemanager.scheduler.fair.FSAppAttempt: appattempt_1471639269423_0001_000001 minReqResource: <memory:0, vCores:0> flexibleResource: <memory:16384, vCores:8>
2016-08-19 14:46:56,552 INFO org.apache.hadoop.yarn.server.resourcemanager.scheduler.fair.FairScheduler: iglf: 1.getHeadroom()=<memory:0, vCores:0>
2016-08-19 14:46:56,955 INFO org.apache.hadoop.yarn.server.resourcemanager.scheduler.fair.FairScheduler: allocate(appattempt_1471639269423_0001_000001 [] [] [] []
2016-08-19 14:46:56,956 INFO org.apache.hadoop.yarn.server.resourcemanager.scheduler.fair.FSAppAttempt: appattempt_1471639269423_0001_000001 minReqResource: <memory:0, vCores:0> flexibleResource: <memory:16384, vCores:8>
2016-08-19 14:46:56,956 INFO org.apache.hadoop.yarn.server.resourcemanager.scheduler.fair.FairScheduler: iglf: 1.getHeadroom()=<memory:0, vCores:0>
2016-08-19 14:46:57,759 INFO org.apache.hadoop.yarn.server.resourcemanager.scheduler.fair.FairScheduler: allocate(appattempt_1471639269423_0001_000001 [] [] [] []
2016-08-19 14:46:57,760 INFO org.apache.hadoop.yarn.server.resourcemanager.scheduler.fair.FSAppAttempt: appattempt_1471639269423_0001_000001 minReqResource: <memory:0, vCores:0> flexibleResource: <memory:16384, vCores:8>
2016-08-19 14:46:57,760 INFO org.apache.hadoop.yarn.server.resourcemanager.scheduler.fair.FairScheduler: iglf: 1.getHeadroom()=<memory:0, vCores:0>
2016-08-19 14:46:58,494 INFO org.apache.hadoop.yarn.server.resourcemanager.scheduler.fair.FairScheduler: allocate(appattempt_1471639269423_0002_000001 [{Priority: 1, Capability: <memory:1920, vCores:1>, # Containers: 31, Location: *, Relax Locality: true}] [] [] []
2016-08-19 14:46:58,494 INFO org.apache.hadoop.yarn.server.resourcemanager.scheduler.fair.FSAppAttempt: appattempt_1471639269423_0002_000001 minReqResource: <memory:0, vCores:0> flexibleResource: <memory:16384, vCores:8>
2016-08-19 14:46:58,494 INFO org.apache.hadoop.yarn.server.resourcemanager.scheduler.fair.FairScheduler: iglf: 2.getHeadroom()=<memory:0, vCores:0>
2016-08-19 14:46:58,698 INFO org.apache.hadoop.yarn.server.resourcemanager.scheduler.fair.FairScheduler: allocate(appattempt_1471639269423_0002_000001 [] [] [] []
2016-08-19 14:46:58,698 INFO org.apache.hadoop.yarn.server.resourcemanager.scheduler.fair.FSAppAttempt: appattempt_1471639269423_0002_000001 minReqResource: <memory:0, vCores:0> flexibleResource: <memory:16384, vCores:8>
2016-08-19 14:46:58,698 INFO org.apache.hadoop.yarn.server.resourcemanager.scheduler.fair.FairScheduler: iglf: 2.getHeadroom()=<memory:0, vCores:0>
2016-08-19 14:46:59,101 INFO org.apache.hadoop.yarn.server.resourcemanager.scheduler.fair.FairScheduler: allocate(appattempt_1471639269423_0002_000001 [] [] [] []
2016-08-19 14:46:59,101 INFO org.apache.hadoop.yarn.server.resourcemanager.scheduler.fair.FSAppAttempt: appattempt_1471639269423_0002_000001 minReqResource: <memory:0, vCores:0> flexibleResource: <memory:16384, vCores:8>
2016-08-19 14:46:59,101 INFO org.apache.hadoop.yarn.server.resourcemanager.scheduler.fair.FairScheduler: iglf: 2.getHeadroom()=<memory:0, vCores:0>
2016-08-19 14:46:59,364 INFO org.apache.hadoop.yarn.server.resourcemanager.scheduler.fair.FairScheduler: allocate(appattempt_1471639269423_0001_000001 [] [] [] []
2016-08-19 14:46:59,364 INFO org.apache.hadoop.yarn.server.resourcemanager.scheduler.fair.FSAppAttempt: appattempt_1471639269423_0001_000001 minReqResource: <memory:0, vCores:0> flexibleResource: <memory:16384, vCores:8>
2016-08-19 14:46:59,364 INFO org.apache.hadoop.yarn.server.resourcemanager.scheduler.fair.FairScheduler: iglf: 1.getHeadroom()=<memory:0, vCores:0>
2016-08-19 14:46:59,905 INFO org.apache.hadoop.yarn.server.resourcemanager.scheduler.fair.FairScheduler: allocate(appattempt_1471639269423_0002_000001 [] [] [] []
2016-08-19 14:46:59,905 INFO org.apache.hadoop.yarn.server.resourcemanager.scheduler.fair.FSAppAttempt: appattempt_1471639269423_0002_000001 minReqResource: <memory:0, vCores:0> flexibleResource: <memory:16384, vCores:8>
2016-08-19 14:46:59,905 INFO org.apache.hadoop.yarn.server.resourcemanager.scheduler.fair.FairScheduler: iglf: 2.getHeadroom()=<memory:0, vCores:0>
2016-08-19 14:47:00,339 INFO org.apache.hadoop.yarn.server.resourcemanager.scheduler.fair.FairScheduler: allocate(appattempt_1471639269423_0001_000001 [{Priority: 1, Capability: <memory:1920, vCores:1>, # Containers: 242, Location: *, Relax Locality: true}] [] [] []
2016-08-19 14:47:00,339 INFO org.apache.hadoop.yarn.server.resourcemanager.scheduler.fair.FSAppAttempt: appattempt_1471639269423_0001_000001 minReqResource: <memory:0, vCores:0> flexibleResource: <memory:16384, vCores:8>
2016-08-19 14:47:00,340 INFO org.apache.hadoop.yarn.server.resourcemanager.scheduler.fair.FairScheduler: iglf: 1.getHeadroom()=<memory:0, vCores:0>
2016-08-19 14:47:00,437 INFO org.apache.hadoop.yarn.server.resourcemanager.scheduler.fair.FairScheduler: allocate(appattempt_1471639269423_0001_000001 [{Priority: 1, Capability: <memory:1920, vCores:1>, # Containers: 198, Location: *, Relax Locality: true}] [] [] []
2016-08-19 14:47:00,438 INFO org.apache.hadoop.yarn.server.resourcemanager.scheduler.fair.FSAppAttempt: appattempt_1471639269423_0001_000001 minReqResource: <memory:0, vCores:0> flexibleResource: <memory:16384, vCores:8>
2016-08-19 14:47:00,438 INFO org.apache.hadoop.yarn.server.resourcemanager.scheduler.fair.FairScheduler: iglf: 1.getHeadroom()=<memory:0, vCores:0>
2016-08-19 14:47:00,537 INFO org.apache.hadoop.yarn.server.resourcemanager.scheduler.fair.FairScheduler: allocate(appattempt_1471639269423_0001_000001 [{Priority: 1, Capability: <memory:1920, vCores:1>, # Containers: 154, Location: *, Relax Locality: true}] [] [] []
2016-08-19 14:47:00,537 INFO org.apache.hadoop.yarn.server.resourcemanager.scheduler.fair.FSAppAttempt: appattempt_1471639269423_0001_000001 minReqResource: <memory:0, vCores:0> flexibleResource: <memory:16384, vCores:8>
2016-08-19 14:47:00,539 INFO org.apache.hadoop.yarn.server.resourcemanager.scheduler.fair.FairScheduler: iglf: 1.getHeadroom()=<memory:0, vCores:0>
2016-08-19 14:47:00,636 INFO org.apache.hadoop.yarn.server.resourcemanager.scheduler.fair.FairScheduler: allocate(appattempt_1471639269423_0001_000001 [{Priority: 1, Capability: <memory:1920, vCores:1>, # Containers: 112, Location: *, Relax Locality: true}] [] [] []
2016-08-19 14:47:00,636 INFO org.apache.hadoop.yarn.server.resourcemanager.scheduler.fair.FSAppAttempt: appattempt_1471639269423_0001_000001 minReqResource: <memory:0, vCores:0> flexibleResource: <memory:16384, vCores:8>
2016-08-19 14:47:00,636 INFO org.apache.hadoop.yarn.server.resourcemanager.scheduler.fair.FairScheduler: iglf: 1.getHeadroom()=<memory:0, vCores:0>
2016-08-19 14:47:00,736 INFO org.apache.hadoop.yarn.server.resourcemanager.scheduler.fair.FairScheduler: allocate(appattempt_1471639269423_0001_000001 [{Priority: 1, Capability: <memory:1920, vCores:1>, # Containers: 69, Location: *, Relax Locality: true}] [] [] []
2016-08-19 14:47:00,736 INFO org.apache.hadoop.yarn.server.resourcemanager.scheduler.fair.FSAppAttempt: appattempt_1471639269423_0001_000001 minReqResource: <memory:0, vCores:0> flexibleResource: <memory:16384, vCores:8>
2016-08-19 14:47:00,736 INFO org.apache.hadoop.yarn.server.resourcemanager.scheduler.fair.FairScheduler: iglf: 1.getHeadroom()=<memory:0, vCores:0>
2016-08-19 14:47:00,836 INFO org.apache.hadoop.yarn.server.resourcemanager.scheduler.fair.FairScheduler: allocate(appattempt_1471639269423_0001_000001 [{Priority: 1, Capability: <memory:1920, vCores:1>, # Containers: 28, Location: *, Relax Locality: true}] [] [] []
2016-08-19 14:47:00,836 INFO org.apache.hadoop.yarn.server.resourcemanager.scheduler.fair.FSAppAttempt: appattempt_1471639269423_0001_000001 minReqResource: <memory:0, vCores:0> flexibleResource: <memory:16384, vCores:8>
2016-08-19 14:47:00,836 INFO org.apache.hadoop.yarn.server.resourcemanager.scheduler.fair.FairScheduler: iglf: 1.getHeadroom()=<memory:0, vCores:0>
2016-08-19 14:47:00,937 INFO org.apache.hadoop.yarn.server.resourcemanager.scheduler.fair.FairScheduler: allocate(appattempt_1471639269423_0001_000001 [{Priority: 1, Capability: <memory:1920, vCores:1>, # Containers: 0, Location: *, Relax Locality: true}] [] [] []
2016-08-19 14:47:00,937 INFO org.apache.hadoop.yarn.server.resourcemanager.scheduler.fair.FSAppAttempt: appattempt_1471639269423_0001_000001 minReqResource: <memory:0, vCores:0> flexibleResource: <memory:16384, vCores:8>
2016-08-19 14:47:00,937 INFO org.apache.hadoop.yarn.server.resourcemanager.scheduler.AppSchedulingInfo: checking for deactivate of application :application_1471639269423_0001
2016-08-19 14:47:00,938 INFO org.apache.hadoop.yarn.server.resourcemanager.scheduler.fair.FairScheduler: iglf: 1.getHeadroom()=<memory:0, vCores:0>
2016-08-19 14:47:01,028 INFO org.apache.hadoop.yarn.server.resourcemanager.rmapp.attempt.RMAppAttemptImpl: Updating application attempt appattempt_1471639269423_0001_000001 with final state: FINISHING, and exit status: -1000
2016-08-19 14:47:01,029 INFO org.apache.hadoop.yarn.server.resourcemanager.rmapp.attempt.RMAppAttemptImpl: appattempt_1471639269423_0001_000001 State change from RUNNING to FINAL_SAVING
2016-08-19 14:47:01,030 INFO org.apache.hadoop.yarn.server.resourcemanager.rmapp.RMAppImpl: Updating application application_1471639269423_0001 with final state: FINISHING
2016-08-19 14:47:01,031 INFO org.apache.hadoop.yarn.server.resourcemanager.rmapp.RMAppImpl: application_1471639269423_0001 State change from RUNNING to FINAL_SAVING
2016-08-19 14:47:01,031 INFO org.apache.hadoop.yarn.server.resourcemanager.recovery.RMStateStore: Updating info for app: application_1471639269423_0001
2016-08-19 14:47:01,031 INFO org.apache.hadoop.yarn.server.resourcemanager.rmapp.attempt.RMAppAttemptImpl: appattempt_1471639269423_0001_000001 State change from FINAL_SAVING to FINISHING
2016-08-19 14:47:01,031 INFO org.apache.hadoop.yarn.server.resourcemanager.rmapp.RMAppImpl: application_1471639269423_0001 State change from FINAL_SAVING to FINISHING
2016-08-19 14:47:01,124 INFO org.apache.hadoop.yarn.server.resourcemanager.rmcontainer.RMContainerImpl: Processing container_1471639269423_0001_01_000003 of event FINISHED
2016-08-19 14:47:01,125 INFO org.apache.hadoop.yarn.server.resourcemanager.rmcontainer.RMContainerImpl: container_1471639269423_0001_01_000003 Container Transitioned from RUNNING to COMPLETED
2016-08-19 14:47:01,125 INFO org.apache.hadoop.yarn.server.resourcemanager.scheduler.fair.FSAppAttempt: Completed container: container_1471639269423_0001_01_000003 in state: COMPLETED event:FINISHED
2016-08-19 14:47:01,125 INFO org.apache.hadoop.yarn.server.resourcemanager.RMAuditLogger: USER=tanle	OPERATION=AM Released Container	TARGET=SchedulerApp	RESULT=SUCCESS	APPID=application_1471639269423_0001	CONTAINERID=container_1471639269423_0001_01_000003
2016-08-19 14:47:01,125 INFO org.apache.hadoop.yarn.server.resourcemanager.scheduler.SchedulerNode: Released container container_1471639269423_0001_01_000003 of capacity <memory:2048, vCores:1> on host cp-1.yarn-perf.yarnrm-PG0.wisc.cloudlab.us:33756, which currently has 3 containers, <memory:6144, vCores:3> used and <memory:2048, vCores:1> available, release resources=true
2016-08-19 14:47:01,125 INFO org.apache.hadoop.yarn.server.resourcemanager.scheduler.fair.FairScheduler: Application attempt appattempt_1471639269423_0001_000001 released container container_1471639269423_0001_01_000003 on node: host: cp-1.yarn-perf.yarnrm-PG0.wisc.cloudlab.us:33756 #containers=3 available=<memory:2048, vCores:1> used=<memory:6144, vCores:3> with event: FINISHED
2016-08-19 14:47:01,125 INFO org.apache.hadoop.yarn.server.resourcemanager.scheduler.fair.FairScheduler: Releasing reservation that cannot be satisfied for application appattempt_1471639269423_0001_000001 on node host: cp-1.yarn-perf.yarnrm-PG0.wisc.cloudlab.us:33756 #containers=3 available=<memory:2048, vCores:1> used=<memory:6144, vCores:3>
2016-08-19 14:47:01,126 INFO org.apache.hadoop.yarn.server.resourcemanager.scheduler.fair.FSAppAttempt: Application application_1471639269423_0001 unreserved  on node host: cp-1.yarn-perf.yarnrm-PG0.wisc.cloudlab.us:33756 #containers=3 available=<memory:2048, vCores:1> used=<memory:6144, vCores:3>, currently has 1 at priority 1; currentReservation <memory:2048, vCores:1>
2016-08-19 14:47:01,126 INFO org.apache.hadoop.yarn.server.resourcemanager.scheduler.fair.FSAppAttempt: assignContainer(FSSchedulerNode node:cp-1.yarn-perf.yarnrm-PG0.wisc.cloudlab.us, boolean reserved=false) for appattempt_1471639269423_0002_000001
2016-08-19 14:47:01,126 INFO org.apache.hadoop.yarn.server.resourcemanager.scheduler.fair.FSAppAttempt: assignContainer(FSSchedulerNode:cp-1.yarn-perf.yarnrm-PG0.wisc.cloudlab.us, ResourceRequest request, NodeType type, boolean reserved=false
2016-08-19 14:47:01,126 INFO org.apache.hadoop.yarn.server.resourcemanager.scheduler.fair.FSAppAttempt: allocate container: container_1471639269423_0002_01_000002 priority 1
2016-08-19 14:47:01,127 INFO org.apache.hadoop.yarn.server.resourcemanager.rmcontainer.RMContainerImpl: Processing container_1471639269423_0002_01_000002 of event START
2016-08-19 14:47:01,127 INFO org.apache.hadoop.yarn.server.resourcemanager.rmcontainer.RMContainerImpl: container_1471639269423_0002_01_000002 Container Transitioned from NEW to ALLOCATED
2016-08-19 14:47:01,127 INFO org.apache.hadoop.yarn.server.resourcemanager.RMAuditLogger: USER=tanle	OPERATION=AM Allocated Container	TARGET=SchedulerApp	RESULT=SUCCESS	APPID=application_1471639269423_0002	CONTAINERID=container_1471639269423_0002_01_000002
2016-08-19 14:47:01,127 INFO org.apache.hadoop.yarn.server.resourcemanager.scheduler.SchedulerNode: Assigned container container_1471639269423_0002_01_000002 of capacity <memory:2048, vCores:1> on host cp-1.yarn-perf.yarnrm-PG0.wisc.cloudlab.us:33756, which has 4 containers, <memory:8192, vCores:4> used and <memory:0, vCores:0> available after allocation
2016-08-19 14:47:01,127 INFO org.apache.hadoop.yarn.server.resourcemanager.rmcontainer.RMContainerImpl: Processing container_1471639269423_0001_01_000007 of event FINISHED
2016-08-19 14:47:01,127 INFO org.apache.hadoop.yarn.server.resourcemanager.rmcontainer.RMContainerImpl: container_1471639269423_0001_01_000007 Container Transitioned from RUNNING to COMPLETED
2016-08-19 14:47:01,127 INFO org.apache.hadoop.yarn.server.resourcemanager.scheduler.fair.FSAppAttempt: Completed container: container_1471639269423_0001_01_000007 in state: COMPLETED event:FINISHED
2016-08-19 14:47:01,128 INFO org.apache.hadoop.yarn.server.resourcemanager.RMAuditLogger: USER=tanle	OPERATION=AM Released Container	TARGET=SchedulerApp	RESULT=SUCCESS	APPID=application_1471639269423_0001	CONTAINERID=container_1471639269423_0001_01_000007
2016-08-19 14:47:01,128 INFO org.apache.hadoop.yarn.server.resourcemanager.scheduler.SchedulerNode: Released container container_1471639269423_0001_01_000007 of capacity <memory:2048, vCores:1> on host c220g1-031106.wisc.cloudlab.us:43516, which currently has 3 containers, <memory:6144, vCores:3> used and <memory:2048, vCores:1> available, release resources=true
2016-08-19 14:47:01,128 INFO org.apache.hadoop.yarn.server.resourcemanager.scheduler.fair.FairScheduler: Application attempt appattempt_1471639269423_0001_000001 released container container_1471639269423_0001_01_000007 on node: host: c220g1-031106.wisc.cloudlab.us:43516 #containers=3 available=<memory:2048, vCores:1> used=<memory:6144, vCores:3> with event: FINISHED
2016-08-19 14:47:01,128 INFO org.apache.hadoop.yarn.server.resourcemanager.rmcontainer.RMContainerImpl: Processing container_1471639269423_0001_01_000008 of event FINISHED
2016-08-19 14:47:01,128 INFO org.apache.hadoop.yarn.server.resourcemanager.rmcontainer.RMContainerImpl: container_1471639269423_0001_01_000008 Container Transitioned from RUNNING to COMPLETED
2016-08-19 14:47:01,128 INFO org.apache.hadoop.yarn.server.resourcemanager.scheduler.fair.FSAppAttempt: Completed container: container_1471639269423_0001_01_000008 in state: COMPLETED event:FINISHED
2016-08-19 14:47:01,128 INFO org.apache.hadoop.yarn.server.resourcemanager.RMAuditLogger: USER=tanle	OPERATION=AM Released Container	TARGET=SchedulerApp	RESULT=SUCCESS	APPID=application_1471639269423_0001	CONTAINERID=container_1471639269423_0001_01_000008
2016-08-19 14:47:01,128 INFO org.apache.hadoop.yarn.server.resourcemanager.scheduler.SchedulerNode: Released container container_1471639269423_0001_01_000008 of capacity <memory:2048, vCores:1> on host c220g1-031106.wisc.cloudlab.us:43516, which currently has 2 containers, <memory:4096, vCores:2> used and <memory:4096, vCores:2> available, release resources=true
2016-08-19 14:47:01,129 INFO org.apache.hadoop.yarn.server.resourcemanager.scheduler.fair.FairScheduler: Application attempt appattempt_1471639269423_0001_000001 released container container_1471639269423_0001_01_000008 on node: host: c220g1-031106.wisc.cloudlab.us:43516 #containers=2 available=<memory:4096, vCores:2> used=<memory:4096, vCores:2> with event: FINISHED
2016-08-19 14:47:01,129 INFO org.apache.hadoop.yarn.server.resourcemanager.scheduler.fair.FairScheduler: Releasing reservation that cannot be satisfied for application appattempt_1471639269423_0001_000001 on node host: c220g1-031106.wisc.cloudlab.us:43516 #containers=2 available=<memory:4096, vCores:2> used=<memory:4096, vCores:2>
2016-08-19 14:47:01,129 INFO org.apache.hadoop.yarn.server.resourcemanager.scheduler.fair.FSAppAttempt: Application application_1471639269423_0001 unreserved  on node host: c220g1-031106.wisc.cloudlab.us:43516 #containers=2 available=<memory:4096, vCores:2> used=<memory:4096, vCores:2>, currently has 0 at priority 1; currentReservation <memory:0, vCores:0>
2016-08-19 14:47:01,129 INFO org.apache.hadoop.yarn.server.resourcemanager.scheduler.fair.FSAppAttempt: assignContainer(FSSchedulerNode node:c220g1-031106.wisc.cloudlab.us, boolean reserved=false) for appattempt_1471639269423_0002_000001
2016-08-19 14:47:01,129 INFO org.apache.hadoop.yarn.server.resourcemanager.scheduler.fair.FSAppAttempt: assignContainer(FSSchedulerNode:c220g1-031106.wisc.cloudlab.us, ResourceRequest request, NodeType type, boolean reserved=false
2016-08-19 14:47:01,129 INFO org.apache.hadoop.yarn.server.resourcemanager.scheduler.fair.FSAppAttempt: allocate container: container_1471639269423_0002_01_000003 priority 1
2016-08-19 14:47:01,129 INFO org.apache.hadoop.yarn.server.resourcemanager.rmcontainer.RMContainerImpl: Processing container_1471639269423_0002_01_000003 of event START
2016-08-19 14:47:01,130 INFO org.apache.hadoop.yarn.server.resourcemanager.rmcontainer.RMContainerImpl: container_1471639269423_0002_01_000003 Container Transitioned from NEW to ALLOCATED
2016-08-19 14:47:01,130 INFO org.apache.hadoop.yarn.server.resourcemanager.RMAuditLogger: USER=tanle	OPERATION=AM Allocated Container	TARGET=SchedulerApp	RESULT=SUCCESS	APPID=application_1471639269423_0002	CONTAINERID=container_1471639269423_0002_01_000003
2016-08-19 14:47:01,130 INFO org.apache.hadoop.yarn.server.resourcemanager.scheduler.SchedulerNode: Assigned container container_1471639269423_0002_01_000003 of capacity <memory:2048, vCores:1> on host c220g1-031106.wisc.cloudlab.us:43516, which has 3 containers, <memory:6144, vCores:3> used and <memory:2048, vCores:1> available after allocation
2016-08-19 14:47:01,135 INFO org.apache.hadoop.yarn.server.resourcemanager.ApplicationMasterService: application_1471639269423_0001 unregistered successfully. 
2016-08-19 14:47:01,508 INFO org.apache.hadoop.yarn.server.resourcemanager.scheduler.fair.FairScheduler: allocate(appattempt_1471639269423_0002_000001 [] [] [] []
2016-08-19 14:47:01,508 INFO org.apache.hadoop.yarn.server.resourcemanager.scheduler.fair.FSAppAttempt: appattempt_1471639269423_0002_000001 minReqResource: <memory:0, vCores:0> flexibleResource: <memory:16384, vCores:8>
2016-08-19 14:47:01,511 INFO org.apache.hadoop.yarn.server.resourcemanager.security.NMTokenSecretManagerInRM: Sending NMToken for nodeId : cp-1.yarn-perf.yarnrm-PG0.wisc.cloudlab.us:33756 for container : container_1471639269423_0002_01_000002
2016-08-19 14:47:01,513 INFO org.apache.hadoop.yarn.server.resourcemanager.rmcontainer.RMContainerImpl: Processing container_1471639269423_0002_01_000002 of event ACQUIRED
2016-08-19 14:47:01,513 INFO org.apache.hadoop.yarn.server.resourcemanager.rmcontainer.RMContainerImpl: container_1471639269423_0002_01_000002 Container Transitioned from ALLOCATED to ACQUIRED
2016-08-19 14:47:01,516 INFO org.apache.hadoop.yarn.server.resourcemanager.security.NMTokenSecretManagerInRM: Sending NMToken for nodeId : c220g1-031106.wisc.cloudlab.us:43516 for container : container_1471639269423_0002_01_000003
2016-08-19 14:47:01,522 INFO org.apache.hadoop.yarn.server.resourcemanager.rmcontainer.RMContainerImpl: Processing container_1471639269423_0002_01_000003 of event ACQUIRED
2016-08-19 14:47:01,522 INFO org.apache.hadoop.yarn.server.resourcemanager.rmcontainer.RMContainerImpl: container_1471639269423_0002_01_000003 Container Transitioned from ALLOCATED to ACQUIRED
2016-08-19 14:47:01,522 INFO org.apache.hadoop.yarn.server.resourcemanager.scheduler.fair.FairScheduler: iglf: 2.getHeadroom()=<memory:2048, vCores:1>
2016-08-19 14:47:02,128 INFO org.apache.hadoop.yarn.server.resourcemanager.rmcontainer.RMContainerImpl: Processing container_1471639269423_0002_01_000002 of event LAUNCHED
2016-08-19 14:47:02,128 INFO org.apache.hadoop.yarn.server.resourcemanager.rmcontainer.RMContainerImpl: container_1471639269423_0002_01_000002 Container Transitioned from ACQUIRED to RUNNING
2016-08-19 14:47:02,129 INFO org.apache.hadoop.yarn.server.resourcemanager.rmcontainer.RMContainerImpl: Processing container_1471639269423_0001_01_000002 of event FINISHED
2016-08-19 14:47:02,129 INFO org.apache.hadoop.yarn.server.resourcemanager.rmcontainer.RMContainerImpl: container_1471639269423_0001_01_000002 Container Transitioned from RUNNING to COMPLETED
2016-08-19 14:47:02,129 INFO org.apache.hadoop.yarn.server.resourcemanager.scheduler.fair.FSAppAttempt: Completed container: container_1471639269423_0001_01_000002 in state: COMPLETED event:FINISHED
2016-08-19 14:47:02,129 INFO org.apache.hadoop.yarn.server.resourcemanager.RMAuditLogger: USER=tanle	OPERATION=AM Released Container	TARGET=SchedulerApp	RESULT=SUCCESS	APPID=application_1471639269423_0001	CONTAINERID=container_1471639269423_0001_01_000002
2016-08-19 14:47:02,129 INFO org.apache.hadoop.yarn.server.resourcemanager.scheduler.SchedulerNode: Released container container_1471639269423_0001_01_000002 of capacity <memory:2048, vCores:1> on host cp-1.yarn-perf.yarnrm-PG0.wisc.cloudlab.us:33756, which currently has 3 containers, <memory:6144, vCores:3> used and <memory:2048, vCores:1> available, release resources=true
2016-08-19 14:47:02,129 INFO org.apache.hadoop.yarn.server.resourcemanager.scheduler.fair.FairScheduler: Application attempt appattempt_1471639269423_0001_000001 released container container_1471639269423_0001_01_000002 on node: host: cp-1.yarn-perf.yarnrm-PG0.wisc.cloudlab.us:33756 #containers=3 available=<memory:2048, vCores:1> used=<memory:6144, vCores:3> with event: FINISHED
2016-08-19 14:47:02,130 INFO org.apache.hadoop.yarn.server.resourcemanager.rmcontainer.RMContainerImpl: Processing container_1471639269423_0001_01_000001 of event FINISHED
2016-08-19 14:47:02,130 INFO org.apache.hadoop.yarn.server.resourcemanager.rmcontainer.RMContainerImpl: container_1471639269423_0001_01_000001 Container Transitioned from RUNNING to COMPLETED
2016-08-19 14:47:02,130 INFO org.apache.hadoop.yarn.server.resourcemanager.scheduler.fair.FSAppAttempt: Completed container: container_1471639269423_0001_01_000001 in state: COMPLETED event:FINISHED
2016-08-19 14:47:02,130 INFO org.apache.hadoop.yarn.server.resourcemanager.ApplicationMasterService: Unregistering app attempt : appattempt_1471639269423_0001_000001
2016-08-19 14:47:02,130 INFO org.apache.hadoop.yarn.server.resourcemanager.RMAuditLogger: USER=tanle	OPERATION=AM Released Container	TARGET=SchedulerApp	RESULT=SUCCESS	APPID=application_1471639269423_0001	CONTAINERID=container_1471639269423_0001_01_000001
2016-08-19 14:47:02,130 INFO org.apache.hadoop.yarn.server.resourcemanager.scheduler.SchedulerNode: Released container container_1471639269423_0001_01_000001 of capacity <memory:2048, vCores:1> on host cp-1.yarn-perf.yarnrm-PG0.wisc.cloudlab.us:33756, which currently has 2 containers, <memory:4096, vCores:2> used and <memory:4096, vCores:2> available, release resources=true
2016-08-19 14:47:02,130 INFO org.apache.hadoop.yarn.server.resourcemanager.scheduler.fair.FairScheduler: Application attempt appattempt_1471639269423_0001_000001 released container container_1471639269423_0001_01_000001 on node: host: cp-1.yarn-perf.yarnrm-PG0.wisc.cloudlab.us:33756 #containers=2 available=<memory:4096, vCores:2> used=<memory:4096, vCores:2> with event: FINISHED
2016-08-19 14:47:02,130 INFO org.apache.hadoop.yarn.server.resourcemanager.scheduler.fair.FSAppAttempt: assignContainer(FSSchedulerNode node:cp-1.yarn-perf.yarnrm-PG0.wisc.cloudlab.us, boolean reserved=false) for appattempt_1471639269423_0001_000001
2016-08-19 14:47:02,131 INFO org.apache.hadoop.yarn.server.resourcemanager.scheduler.fair.FSAppAttempt: assignContainer(FSSchedulerNode node:cp-1.yarn-perf.yarnrm-PG0.wisc.cloudlab.us, boolean reserved=false) for appattempt_1471639269423_0002_000001
2016-08-19 14:47:02,131 INFO org.apache.hadoop.yarn.server.resourcemanager.scheduler.fair.FSAppAttempt: assignContainer(FSSchedulerNode:cp-1.yarn-perf.yarnrm-PG0.wisc.cloudlab.us, ResourceRequest request, NodeType type, boolean reserved=false
2016-08-19 14:47:02,131 INFO org.apache.hadoop.yarn.server.resourcemanager.scheduler.fair.FSAppAttempt: allocate container: container_1471639269423_0002_01_000004 priority 1
2016-08-19 14:47:02,131 INFO org.apache.hadoop.yarn.server.resourcemanager.rmcontainer.RMContainerImpl: Processing container_1471639269423_0002_01_000004 of event START
2016-08-19 14:47:02,131 INFO org.apache.hadoop.yarn.server.resourcemanager.rmcontainer.RMContainerImpl: container_1471639269423_0002_01_000004 Container Transitioned from NEW to ALLOCATED
2016-08-19 14:47:02,131 INFO org.apache.hadoop.yarn.server.resourcemanager.security.AMRMTokenSecretManager: Application finished, removing password for appattempt_1471639269423_0001_000001
2016-08-19 14:47:02,131 INFO org.apache.hadoop.yarn.server.resourcemanager.RMAuditLogger: USER=tanle	OPERATION=AM Allocated Container	TARGET=SchedulerApp	RESULT=SUCCESS	APPID=application_1471639269423_0002	CONTAINERID=container_1471639269423_0002_01_000004
2016-08-19 14:47:02,132 INFO org.apache.hadoop.yarn.server.resourcemanager.scheduler.SchedulerNode: Assigned container container_1471639269423_0002_01_000004 of capacity <memory:2048, vCores:1> on host cp-1.yarn-perf.yarnrm-PG0.wisc.cloudlab.us:33756, which has 3 containers, <memory:6144, vCores:3> used and <memory:2048, vCores:1> available after allocation
2016-08-19 14:47:02,132 INFO org.apache.hadoop.yarn.server.resourcemanager.rmcontainer.RMContainerImpl: Processing container_1471639269423_0002_01_000003 of event LAUNCHED
2016-08-19 14:47:02,132 INFO org.apache.hadoop.yarn.server.resourcemanager.rmcontainer.RMContainerImpl: container_1471639269423_0002_01_000003 Container Transitioned from ACQUIRED to RUNNING
2016-08-19 14:47:02,132 INFO org.apache.hadoop.yarn.server.resourcemanager.rmcontainer.RMContainerImpl: Processing container_1471639269423_0001_01_000004 of event FINISHED
2016-08-19 14:47:02,133 INFO org.apache.hadoop.yarn.server.resourcemanager.rmcontainer.RMContainerImpl: container_1471639269423_0001_01_000004 Container Transitioned from RUNNING to COMPLETED
2016-08-19 14:47:02,133 INFO org.apache.hadoop.yarn.server.resourcemanager.scheduler.fair.FSAppAttempt: Completed container: container_1471639269423_0001_01_000004 in state: COMPLETED event:FINISHED
2016-08-19 14:47:02,133 INFO org.apache.hadoop.yarn.server.resourcemanager.RMAuditLogger: USER=tanle	OPERATION=AM Released Container	TARGET=SchedulerApp	RESULT=SUCCESS	APPID=application_1471639269423_0001	CONTAINERID=container_1471639269423_0001_01_000004
2016-08-19 14:47:02,133 INFO org.apache.hadoop.yarn.server.resourcemanager.rmapp.attempt.RMAppAttemptImpl: appattempt_1471639269423_0001_000001 State change from FINISHING to FINISHED
2016-08-19 14:47:02,133 INFO org.apache.hadoop.yarn.server.resourcemanager.scheduler.SchedulerNode: Released container container_1471639269423_0001_01_000004 of capacity <memory:2048, vCores:1> on host c220g1-031106.wisc.cloudlab.us:43516, which currently has 2 containers, <memory:4096, vCores:2> used and <memory:4096, vCores:2> available, release resources=true
2016-08-19 14:47:02,133 INFO org.apache.hadoop.yarn.server.resourcemanager.scheduler.fair.FairScheduler: Application attempt appattempt_1471639269423_0001_000001 released container container_1471639269423_0001_01_000004 on node: host: c220g1-031106.wisc.cloudlab.us:43516 #containers=2 available=<memory:4096, vCores:2> used=<memory:4096, vCores:2> with event: FINISHED
2016-08-19 14:47:02,133 INFO org.apache.hadoop.yarn.server.resourcemanager.rmcontainer.RMContainerImpl: Processing container_1471639269423_0001_01_000006 of event FINISHED
2016-08-19 14:47:02,134 INFO org.apache.hadoop.yarn.server.resourcemanager.rmcontainer.RMContainerImpl: container_1471639269423_0001_01_000006 Container Transitioned from RUNNING to COMPLETED
2016-08-19 14:47:02,134 INFO org.apache.hadoop.yarn.server.resourcemanager.scheduler.fair.FSAppAttempt: Completed container: container_1471639269423_0001_01_000006 in state: COMPLETED event:FINISHED
2016-08-19 14:47:02,134 INFO org.apache.hadoop.yarn.server.resourcemanager.RMAuditLogger: USER=tanle	OPERATION=AM Released Container	TARGET=SchedulerApp	RESULT=SUCCESS	APPID=application_1471639269423_0001	CONTAINERID=container_1471639269423_0001_01_000006
2016-08-19 14:47:02,134 INFO org.apache.hadoop.yarn.server.resourcemanager.scheduler.SchedulerNode: Released container container_1471639269423_0001_01_000006 of capacity <memory:2048, vCores:1> on host c220g1-031106.wisc.cloudlab.us:43516, which currently has 1 containers, <memory:2048, vCores:1> used and <memory:6144, vCores:3> available, release resources=true
2016-08-19 14:47:02,134 INFO org.apache.hadoop.yarn.server.resourcemanager.scheduler.fair.FairScheduler: Application attempt appattempt_1471639269423_0001_000001 released container container_1471639269423_0001_01_000006 on node: host: c220g1-031106.wisc.cloudlab.us:43516 #containers=1 available=<memory:6144, vCores:3> used=<memory:2048, vCores:1> with event: FINISHED
2016-08-19 14:47:02,134 INFO org.apache.hadoop.yarn.server.resourcemanager.scheduler.fair.FSAppAttempt: assignContainer(FSSchedulerNode node:c220g1-031106.wisc.cloudlab.us, boolean reserved=false) for appattempt_1471639269423_0001_000001
2016-08-19 14:47:02,134 INFO org.apache.hadoop.yarn.server.resourcemanager.scheduler.fair.FSAppAttempt: assignContainer(FSSchedulerNode node:c220g1-031106.wisc.cloudlab.us, boolean reserved=false) for appattempt_1471639269423_0002_000001
2016-08-19 14:47:02,135 INFO org.apache.hadoop.yarn.server.resourcemanager.scheduler.fair.FSAppAttempt: assignContainer(FSSchedulerNode:c220g1-031106.wisc.cloudlab.us, ResourceRequest request, NodeType type, boolean reserved=false
2016-08-19 14:47:02,135 INFO org.apache.hadoop.yarn.server.resourcemanager.scheduler.fair.FSAppAttempt: allocate container: container_1471639269423_0002_01_000005 priority 1
2016-08-19 14:47:02,135 INFO org.apache.hadoop.yarn.server.resourcemanager.rmcontainer.RMContainerImpl: Processing container_1471639269423_0002_01_000005 of event START
2016-08-19 14:47:02,135 INFO org.apache.hadoop.yarn.server.resourcemanager.rmcontainer.RMContainerImpl: container_1471639269423_0002_01_000005 Container Transitioned from NEW to ALLOCATED
2016-08-19 14:47:02,135 INFO org.apache.hadoop.yarn.server.resourcemanager.RMAuditLogger: USER=tanle	OPERATION=AM Allocated Container	TARGET=SchedulerApp	RESULT=SUCCESS	APPID=application_1471639269423_0002	CONTAINERID=container_1471639269423_0002_01_000005
2016-08-19 14:47:02,135 INFO org.apache.hadoop.yarn.server.resourcemanager.scheduler.SchedulerNode: Assigned container container_1471639269423_0002_01_000005 of capacity <memory:2048, vCores:1> on host c220g1-031106.wisc.cloudlab.us:43516, which has 2 containers, <memory:4096, vCores:2> used and <memory:4096, vCores:2> available after allocation
2016-08-19 14:47:02,136 INFO org.apache.hadoop.yarn.server.resourcemanager.rmapp.RMAppImpl: application_1471639269423_0001 State change from FINISHING to FINISHED
2016-08-19 14:47:02,136 INFO org.apache.hadoop.yarn.server.resourcemanager.scheduler.fair.FairScheduler: Application appattempt_1471639269423_0001_000001 is done. finalState=FINISHED
2016-08-19 14:47:02,136 INFO org.apache.hadoop.yarn.server.resourcemanager.scheduler.AppSchedulingInfo: Application application_1471639269423_0001 requests cleared
2016-08-19 14:47:02,137 INFO org.apache.hadoop.yarn.server.resourcemanager.amlauncher.AMLauncher: Cleaning master appattempt_1471639269423_0001_000001
2016-08-19 14:47:02,137 INFO org.apache.hadoop.yarn.server.resourcemanager.RMAuditLogger: USER=tanle	OPERATION=Application Finished - Succeeded	TARGET=RMAppManager	RESULT=SUCCESS	APPID=application_1471639269423_0001
2016-08-19 14:47:02,141 INFO org.apache.hadoop.yarn.server.resourcemanager.RMAppManager$ApplicationSummary: appId=application_1471639269423_0001,name=org.apache.spark.examples.SparkPi,user=tanle,queue=root.batch,state=FINISHED,trackingUrl=http://nm.yarn-perf.yarnrm-pg0.wisc.cloudlab.us:8088/proxy/application_1471639269423_0001/,appMasterHost=128.104.222.17,startTime=1471639558178,finishTime=1471639621030,finalStatus=SUCCEEDED,memorySeconds=528061,vcoreSeconds=257,preemptedAMContainers=0,preemptedNonAMContainers=0,preemptedResources=<memory:0\, vCores:0>,applicationType=SPARK
2016-08-19 14:47:02,164 INFO org.apache.hadoop.yarn.server.resourcemanager.scheduler.fair.FSAppAttempt: assignContainer(FSSchedulerNode node:cp-1.yarn-perf.yarnrm-PG0.wisc.cloudlab.us, boolean reserved=false) for appattempt_1471639269423_0002_000001
2016-08-19 14:47:02,164 INFO org.apache.hadoop.yarn.server.resourcemanager.scheduler.fair.FSAppAttempt: assignContainer(FSSchedulerNode:cp-1.yarn-perf.yarnrm-PG0.wisc.cloudlab.us, ResourceRequest request, NodeType type, boolean reserved=false
2016-08-19 14:47:02,164 INFO org.apache.hadoop.yarn.server.resourcemanager.scheduler.fair.FSAppAttempt: allocate container: container_1471639269423_0002_01_000006 priority 1
2016-08-19 14:47:02,164 INFO org.apache.hadoop.yarn.server.resourcemanager.rmcontainer.RMContainerImpl: Processing container_1471639269423_0002_01_000006 of event START
2016-08-19 14:47:02,164 INFO org.apache.hadoop.yarn.server.resourcemanager.rmcontainer.RMContainerImpl: container_1471639269423_0002_01_000006 Container Transitioned from NEW to ALLOCATED
2016-08-19 14:47:02,164 INFO org.apache.hadoop.yarn.server.resourcemanager.RMAuditLogger: USER=tanle	OPERATION=AM Allocated Container	TARGET=SchedulerApp	RESULT=SUCCESS	APPID=application_1471639269423_0002	CONTAINERID=container_1471639269423_0002_01_000006
2016-08-19 14:47:02,165 INFO org.apache.hadoop.yarn.server.resourcemanager.scheduler.SchedulerNode: Assigned container container_1471639269423_0002_01_000006 of capacity <memory:2048, vCores:1> on host cp-1.yarn-perf.yarnrm-PG0.wisc.cloudlab.us:33756, which has 4 containers, <memory:8192, vCores:4> used and <memory:0, vCores:0> available after allocation
2016-08-19 14:47:03,133 INFO org.apache.hadoop.yarn.server.resourcemanager.scheduler.fair.FSAppAttempt: assignContainer(FSSchedulerNode node:c220g1-031106.wisc.cloudlab.us, boolean reserved=false) for appattempt_1471639269423_0002_000001
2016-08-19 14:47:03,133 INFO org.apache.hadoop.yarn.server.resourcemanager.scheduler.fair.FSAppAttempt: assignContainer(FSSchedulerNode:c220g1-031106.wisc.cloudlab.us, ResourceRequest request, NodeType type, boolean reserved=false
2016-08-19 14:47:03,134 INFO org.apache.hadoop.yarn.server.resourcemanager.scheduler.fair.FSAppAttempt: allocate container: container_1471639269423_0002_01_000007 priority 1
2016-08-19 14:47:03,135 INFO org.apache.hadoop.yarn.server.resourcemanager.rmcontainer.RMContainerImpl: Processing container_1471639269423_0002_01_000007 of event START
2016-08-19 14:47:03,135 INFO org.apache.hadoop.yarn.server.resourcemanager.rmcontainer.RMContainerImpl: container_1471639269423_0002_01_000007 Container Transitioned from NEW to ALLOCATED
2016-08-19 14:47:03,135 INFO org.apache.hadoop.yarn.server.resourcemanager.RMAuditLogger: USER=tanle	OPERATION=AM Allocated Container	TARGET=SchedulerApp	RESULT=SUCCESS	APPID=application_1471639269423_0002	CONTAINERID=container_1471639269423_0002_01_000007
2016-08-19 14:47:03,135 INFO org.apache.hadoop.yarn.server.resourcemanager.scheduler.SchedulerNode: Assigned container container_1471639269423_0002_01_000007 of capacity <memory:2048, vCores:1> on host c220g1-031106.wisc.cloudlab.us:43516, which has 3 containers, <memory:6144, vCores:3> used and <memory:2048, vCores:1> available after allocation
2016-08-19 14:47:03,169 INFO org.apache.hadoop.yarn.server.resourcemanager.scheduler.fair.FairScheduler: Null container completed...
2016-08-19 14:47:03,169 INFO org.apache.hadoop.yarn.server.resourcemanager.scheduler.fair.FairScheduler: Null container completed...
2016-08-19 14:47:03,169 INFO org.apache.hadoop.yarn.server.resourcemanager.scheduler.fair.FSAppAttempt: assignContainer(FSSchedulerNode node:cp-1.yarn-perf.yarnrm-PG0.wisc.cloudlab.us, boolean reserved=false) for appattempt_1471639269423_0002_000001
2016-08-19 14:47:03,169 INFO org.apache.hadoop.yarn.server.resourcemanager.scheduler.fair.FSAppAttempt: assignContainer(FSSchedulerNode:cp-1.yarn-perf.yarnrm-PG0.wisc.cloudlab.us, ResourceRequest request, NodeType type, boolean reserved=false
2016-08-19 14:47:03,169 INFO org.apache.hadoop.yarn.server.resourcemanager.scheduler.fair.FSAppAttempt: Making reservation: node=cp-1.yarn-perf.yarnrm-PG0.wisc.cloudlab.us app_id=application_1471639269423_0002
2016-08-19 14:47:03,170 INFO org.apache.hadoop.yarn.server.resourcemanager.rmcontainer.RMContainerImpl: Processing container_1471639269423_0002_01_000008 of event RESERVED
2016-08-19 14:47:03,170 INFO org.apache.hadoop.yarn.server.resourcemanager.rmcontainer.RMContainerImpl: container_1471639269423_0002_01_000008 Container Transitioned from NEW to RESERVED
2016-08-19 14:47:03,170 INFO org.apache.hadoop.yarn.server.resourcemanager.scheduler.fair.FSSchedulerNode: Reserved container container_1471639269423_0002_01_000008 on node host: cp-1.yarn-perf.yarnrm-PG0.wisc.cloudlab.us:33756 #containers=4 available=<memory:0, vCores:0> used=<memory:8192, vCores:4> for application org.apache.hadoop.yarn.server.resourcemanager.scheduler.fair.FSAppAttempt@5d30a38e
2016-08-19 14:47:03,496 INFO org.apache.hadoop.yarn.server.resourcemanager.scheduler.fair.FairScheduler: allocate(appattempt_1471639269423_0002_000001 [{Priority: 1, Capability: <memory:1920, vCores:1>, # Containers: 61, Location: *, Relax Locality: true}] [] [] []
2016-08-19 14:47:03,497 INFO org.apache.hadoop.yarn.server.resourcemanager.scheduler.fair.FSAppAttempt: appattempt_1471639269423_0002_000001 minReqResource: <memory:0, vCores:0> flexibleResource: <memory:16384, vCores:8>
2016-08-19 14:47:03,500 INFO org.apache.hadoop.yarn.server.resourcemanager.rmcontainer.RMContainerImpl: Processing container_1471639269423_0002_01_000004 of event ACQUIRED
2016-08-19 14:47:03,500 INFO org.apache.hadoop.yarn.server.resourcemanager.rmcontainer.RMContainerImpl: container_1471639269423_0002_01_000004 Container Transitioned from ALLOCATED to ACQUIRED
2016-08-19 14:47:03,501 INFO org.apache.hadoop.yarn.server.resourcemanager.rmcontainer.RMContainerImpl: Processing container_1471639269423_0002_01_000005 of event ACQUIRED
2016-08-19 14:47:03,502 INFO org.apache.hadoop.yarn.server.resourcemanager.rmcontainer.RMContainerImpl: container_1471639269423_0002_01_000005 Container Transitioned from ALLOCATED to ACQUIRED
2016-08-19 14:47:03,503 INFO org.apache.hadoop.yarn.server.resourcemanager.rmcontainer.RMContainerImpl: Processing container_1471639269423_0002_01_000006 of event ACQUIRED
2016-08-19 14:47:03,503 INFO org.apache.hadoop.yarn.server.resourcemanager.rmcontainer.RMContainerImpl: container_1471639269423_0002_01_000006 Container Transitioned from ALLOCATED to ACQUIRED
2016-08-19 14:47:03,505 INFO org.apache.hadoop.yarn.server.resourcemanager.rmcontainer.RMContainerImpl: Processing container_1471639269423_0002_01_000007 of event ACQUIRED
2016-08-19 14:47:03,505 INFO org.apache.hadoop.yarn.server.resourcemanager.rmcontainer.RMContainerImpl: container_1471639269423_0002_01_000007 Container Transitioned from ALLOCATED to ACQUIRED
2016-08-19 14:47:03,505 INFO org.apache.hadoop.yarn.server.resourcemanager.scheduler.fair.FairScheduler: iglf: 2.getHeadroom()=<memory:2048, vCores:1>
2016-08-19 14:47:03,720 INFO org.apache.hadoop.yarn.server.resourcemanager.scheduler.fair.FairScheduler: allocate(appattempt_1471639269423_0002_000001 [{Priority: 1, Capability: <memory:1920, vCores:1>, # Containers: 57, Location: *, Relax Locality: true}] [] [] []
2016-08-19 14:47:03,720 INFO org.apache.hadoop.yarn.server.resourcemanager.scheduler.fair.FSAppAttempt: appattempt_1471639269423_0002_000001 minReqResource: <memory:0, vCores:0> flexibleResource: <memory:16384, vCores:8>
2016-08-19 14:47:03,721 INFO org.apache.hadoop.yarn.server.resourcemanager.scheduler.fair.FairScheduler: iglf: 2.getHeadroom()=<memory:2048, vCores:1>
2016-08-19 14:47:04,124 INFO org.apache.hadoop.yarn.server.resourcemanager.scheduler.fair.FairScheduler: allocate(appattempt_1471639269423_0002_000001 [] [] [] []
2016-08-19 14:47:04,125 INFO org.apache.hadoop.yarn.server.resourcemanager.scheduler.fair.FSAppAttempt: appattempt_1471639269423_0002_000001 minReqResource: <memory:0, vCores:0> flexibleResource: <memory:16384, vCores:8>
2016-08-19 14:47:04,125 INFO org.apache.hadoop.yarn.server.resourcemanager.scheduler.fair.FairScheduler: iglf: 2.getHeadroom()=<memory:2048, vCores:1>
2016-08-19 14:47:04,139 INFO org.apache.hadoop.yarn.server.resourcemanager.rmcontainer.RMContainerImpl: Processing container_1471639269423_0002_01_000005 of event LAUNCHED
2016-08-19 14:47:04,139 INFO org.apache.hadoop.yarn.server.resourcemanager.rmcontainer.RMContainerImpl: container_1471639269423_0002_01_000005 Container Transitioned from ACQUIRED to RUNNING
2016-08-19 14:47:04,140 INFO org.apache.hadoop.yarn.server.resourcemanager.rmcontainer.RMContainerImpl: Processing container_1471639269423_0002_01_000007 of event LAUNCHED
2016-08-19 14:47:04,140 INFO org.apache.hadoop.yarn.server.resourcemanager.rmcontainer.RMContainerImpl: container_1471639269423_0002_01_000007 Container Transitioned from ACQUIRED to RUNNING
2016-08-19 14:47:04,140 INFO org.apache.hadoop.yarn.server.resourcemanager.scheduler.fair.FairScheduler: Null container completed...
2016-08-19 14:47:04,140 INFO org.apache.hadoop.yarn.server.resourcemanager.scheduler.fair.FairScheduler: Null container completed...
2016-08-19 14:47:04,140 INFO org.apache.hadoop.yarn.server.resourcemanager.scheduler.fair.FairScheduler: Null container completed...
2016-08-19 14:47:04,140 INFO org.apache.hadoop.yarn.server.resourcemanager.scheduler.fair.FairScheduler: Null container completed...
2016-08-19 14:47:04,140 INFO org.apache.hadoop.yarn.server.resourcemanager.scheduler.fair.FSAppAttempt: assignContainer(FSSchedulerNode node:c220g1-031106.wisc.cloudlab.us, boolean reserved=false) for appattempt_1471639269423_0002_000001
2016-08-19 14:47:04,140 INFO org.apache.hadoop.yarn.server.resourcemanager.scheduler.fair.FSAppAttempt: assignContainer(FSSchedulerNode:c220g1-031106.wisc.cloudlab.us, ResourceRequest request, NodeType type, boolean reserved=false
2016-08-19 14:47:04,141 INFO org.apache.hadoop.yarn.server.resourcemanager.scheduler.fair.FSAppAttempt: allocate container: container_1471639269423_0002_01_000009 priority 1
2016-08-19 14:47:04,141 INFO org.apache.hadoop.yarn.server.resourcemanager.rmcontainer.RMContainerImpl: Processing container_1471639269423_0002_01_000009 of event START
2016-08-19 14:47:04,141 INFO org.apache.hadoop.yarn.server.resourcemanager.rmcontainer.RMContainerImpl: container_1471639269423_0002_01_000009 Container Transitioned from NEW to ALLOCATED
2016-08-19 14:47:04,141 INFO org.apache.hadoop.yarn.server.resourcemanager.RMAuditLogger: USER=tanle	OPERATION=AM Allocated Container	TARGET=SchedulerApp	RESULT=SUCCESS	APPID=application_1471639269423_0002	CONTAINERID=container_1471639269423_0002_01_000009
2016-08-19 14:47:04,141 INFO org.apache.hadoop.yarn.server.resourcemanager.scheduler.SchedulerNode: Assigned container container_1471639269423_0002_01_000009 of capacity <memory:2048, vCores:1> on host c220g1-031106.wisc.cloudlab.us:43516, which has 4 containers, <memory:8192, vCores:4> used and <memory:0, vCores:0> available after allocation
2016-08-19 14:47:04,171 INFO org.apache.hadoop.yarn.server.resourcemanager.rmcontainer.RMContainerImpl: Processing container_1471639269423_0002_01_000004 of event LAUNCHED
2016-08-19 14:47:04,171 INFO org.apache.hadoop.yarn.server.resourcemanager.rmcontainer.RMContainerImpl: container_1471639269423_0002_01_000004 Container Transitioned from ACQUIRED to RUNNING
2016-08-19 14:47:04,171 INFO org.apache.hadoop.yarn.server.resourcemanager.rmcontainer.RMContainerImpl: Processing container_1471639269423_0002_01_000006 of event LAUNCHED
2016-08-19 14:47:04,172 INFO org.apache.hadoop.yarn.server.resourcemanager.rmcontainer.RMContainerImpl: container_1471639269423_0002_01_000006 Container Transitioned from ACQUIRED to RUNNING
2016-08-19 14:47:04,431 INFO org.apache.hadoop.yarn.server.resourcemanager.ClientRMService: Allocated new applicationId: 6
2016-08-19 14:47:04,928 INFO org.apache.hadoop.yarn.server.resourcemanager.scheduler.fair.FairScheduler: allocate(appattempt_1471639269423_0002_000001 [] [] [] []
2016-08-19 14:47:04,928 INFO org.apache.hadoop.yarn.server.resourcemanager.scheduler.fair.FSAppAttempt: appattempt_1471639269423_0002_000001 minReqResource: <memory:0, vCores:0> flexibleResource: <memory:16384, vCores:8>
2016-08-19 14:47:04,930 INFO org.apache.hadoop.yarn.server.resourcemanager.rmcontainer.RMContainerImpl: Processing container_1471639269423_0002_01_000009 of event ACQUIRED
2016-08-19 14:47:04,930 INFO org.apache.hadoop.yarn.server.resourcemanager.rmcontainer.RMContainerImpl: container_1471639269423_0002_01_000009 Container Transitioned from ALLOCATED to ACQUIRED
2016-08-19 14:47:04,930 INFO org.apache.hadoop.yarn.server.resourcemanager.scheduler.fair.FairScheduler: iglf: 2.getHeadroom()=<memory:0, vCores:0>
2016-08-19 14:47:05,141 INFO org.apache.hadoop.yarn.server.resourcemanager.rmcontainer.RMContainerImpl: Processing container_1471639269423_0002_01_000009 of event LAUNCHED
2016-08-19 14:47:05,141 INFO org.apache.hadoop.yarn.server.resourcemanager.rmcontainer.RMContainerImpl: container_1471639269423_0002_01_000009 Container Transitioned from ACQUIRED to RUNNING
2016-08-19 14:47:05,141 INFO org.apache.hadoop.yarn.server.resourcemanager.scheduler.fair.FSAppAttempt: assignContainer(FSSchedulerNode node:c220g1-031106.wisc.cloudlab.us, boolean reserved=false) for appattempt_1471639269423_0002_000001
2016-08-19 14:47:05,141 INFO org.apache.hadoop.yarn.server.resourcemanager.scheduler.fair.FSAppAttempt: assignContainer(FSSchedulerNode:c220g1-031106.wisc.cloudlab.us, ResourceRequest request, NodeType type, boolean reserved=false
2016-08-19 14:47:05,142 INFO org.apache.hadoop.yarn.server.resourcemanager.scheduler.fair.FSAppAttempt: Making reservation: node=c220g1-031106.wisc.cloudlab.us app_id=application_1471639269423_0002
2016-08-19 14:47:05,142 INFO org.apache.hadoop.yarn.server.resourcemanager.rmcontainer.RMContainerImpl: Processing container_1471639269423_0002_01_000010 of event RESERVED
2016-08-19 14:47:05,142 INFO org.apache.hadoop.yarn.server.resourcemanager.rmcontainer.RMContainerImpl: container_1471639269423_0002_01_000010 Container Transitioned from NEW to RESERVED
2016-08-19 14:47:05,142 INFO org.apache.hadoop.yarn.server.resourcemanager.scheduler.fair.FSSchedulerNode: Reserved container container_1471639269423_0002_01_000010 on node host: c220g1-031106.wisc.cloudlab.us:43516 #containers=4 available=<memory:0, vCores:0> used=<memory:8192, vCores:4> for application org.apache.hadoop.yarn.server.resourcemanager.scheduler.fair.FSAppAttempt@5d30a38e
2016-08-19 14:47:06,536 INFO org.apache.hadoop.yarn.server.resourcemanager.scheduler.fair.FairScheduler: allocate(appattempt_1471639269423_0002_000001 [{Priority: 1, Capability: <memory:1920, vCores:1>, # Containers: 56, Location: *, Relax Locality: true}] [] [] []
2016-08-19 14:47:06,537 INFO org.apache.hadoop.yarn.server.resourcemanager.scheduler.fair.FSAppAttempt: appattempt_1471639269423_0002_000001 minReqResource: <memory:0, vCores:0> flexibleResource: <memory:16384, vCores:8>
2016-08-19 14:47:06,537 INFO org.apache.hadoop.yarn.server.resourcemanager.scheduler.fair.FairScheduler: iglf: 2.getHeadroom()=<memory:0, vCores:0>
2016-08-19 14:47:06,818 WARN org.apache.hadoop.yarn.server.resourcemanager.rmapp.RMAppImpl: The specific max attempts: 0 for application: 3 is invalid, because it is out of the range [1, 2]. Use the global max attempts instead.
2016-08-19 14:47:06,818 INFO org.apache.hadoop.yarn.server.resourcemanager.ClientRMService: Application with id 3 submitted by user tanle
2016-08-19 14:47:06,818 INFO org.apache.hadoop.yarn.server.resourcemanager.RMAuditLogger: USER=tanle	IP=128.104.222.71	OPERATION=Submit Application Request	TARGET=ClientRMService	RESULT=SUCCESS	APPID=application_1471639269423_0003
2016-08-19 14:47:06,819 INFO org.apache.hadoop.yarn.server.resourcemanager.rmapp.RMAppImpl: Storing application with id application_1471639269423_0003
2016-08-19 14:47:06,819 INFO org.apache.hadoop.yarn.server.resourcemanager.rmapp.RMAppImpl: application_1471639269423_0003 State change from NEW to NEW_SAVING
2016-08-19 14:47:06,819 INFO org.apache.hadoop.yarn.server.resourcemanager.recovery.RMStateStore: Storing info for app: application_1471639269423_0003
2016-08-19 14:47:06,819 INFO org.apache.hadoop.yarn.server.resourcemanager.rmapp.RMAppImpl: application_1471639269423_0003 State change from NEW_SAVING to SUBMITTED
2016-08-19 14:47:06,824 INFO org.apache.hadoop.yarn.server.resourcemanager.scheduler.fair.FairScheduler: Accepted application application_1471639269423_0003 from user: tanle, in queue: interactive1, currently num of applications: 2
2016-08-19 14:47:06,825 INFO org.apache.hadoop.yarn.server.resourcemanager.rmapp.RMAppImpl: application_1471639269423_0003 State change from SUBMITTED to ACCEPTED
2016-08-19 14:47:06,825 INFO org.apache.hadoop.yarn.server.resourcemanager.ApplicationMasterService: Registering app attempt : appattempt_1471639269423_0003_000001
2016-08-19 14:47:06,825 INFO org.apache.hadoop.yarn.server.resourcemanager.rmapp.attempt.RMAppAttemptImpl: appattempt_1471639269423_0003_000001 State change from NEW to SUBMITTED
2016-08-19 14:47:06,825 INFO org.apache.hadoop.yarn.server.resourcemanager.scheduler.fair.FairScheduler: Added Application Attempt appattempt_1471639269423_0003_000001 to scheduler from user: tanle
2016-08-19 14:47:06,826 INFO org.apache.hadoop.yarn.server.resourcemanager.rmapp.attempt.RMAppAttemptImpl: ScheduleTransition.transition(appattempt_1471639269423_0003_000001,EventType: ATTEMPT_ADDED)
2016-08-19 14:47:06,826 INFO org.apache.hadoop.yarn.server.resourcemanager.scheduler.fair.FairScheduler: allocate(appattempt_1471639269423_0003_000001 [{Priority: 0, Capability: <memory:2048, vCores:1>, # Containers: 1, Location: *, Relax Locality: true}] [] null null
2016-08-19 14:47:06,826 INFO org.apache.hadoop.yarn.server.resourcemanager.scheduler.fair.FSAppAttempt: appattempt_1471639269423_0003_000001 minReqResource: <memory:0, vCores:0> flexibleResource: <memory:16384, vCores:8>
2016-08-19 14:47:06,826 INFO org.apache.hadoop.yarn.server.resourcemanager.scheduler.fair.FairScheduler: iglf: 3.getHeadroom()=<memory:0, vCores:0>
2016-08-19 14:47:06,827 INFO org.apache.hadoop.yarn.server.resourcemanager.rmapp.attempt.RMAppAttemptImpl: appattempt_1471639269423_0003_000001 State change from SUBMITTED to SCHEDULED
2016-08-19 14:47:08,325 WARN org.apache.hadoop.yarn.server.resourcemanager.rmapp.RMAppImpl: The specific max attempts: 0 for application: 5 is invalid, because it is out of the range [1, 2]. Use the global max attempts instead.
2016-08-19 14:47:08,326 INFO org.apache.hadoop.yarn.server.resourcemanager.ClientRMService: Application with id 5 submitted by user tanle
2016-08-19 14:47:08,326 INFO org.apache.hadoop.yarn.server.resourcemanager.RMAuditLogger: USER=tanle	IP=128.104.222.71	OPERATION=Submit Application Request	TARGET=ClientRMService	RESULT=SUCCESS	APPID=application_1471639269423_0005
2016-08-19 14:47:08,326 INFO org.apache.hadoop.yarn.server.resourcemanager.rmapp.RMAppImpl: Storing application with id application_1471639269423_0005
2016-08-19 14:47:08,326 INFO org.apache.hadoop.yarn.server.resourcemanager.rmapp.RMAppImpl: application_1471639269423_0005 State change from NEW to NEW_SAVING
2016-08-19 14:47:08,326 INFO org.apache.hadoop.yarn.server.resourcemanager.recovery.RMStateStore: Storing info for app: application_1471639269423_0005
2016-08-19 14:47:08,326 INFO org.apache.hadoop.yarn.server.resourcemanager.rmapp.RMAppImpl: application_1471639269423_0005 State change from NEW_SAVING to SUBMITTED
2016-08-19 14:47:08,331 INFO org.apache.hadoop.yarn.server.resourcemanager.scheduler.fair.FairScheduler: Accepted application application_1471639269423_0005 from user: tanle, in queue: interactive3, currently num of applications: 3
2016-08-19 14:47:08,332 INFO org.apache.hadoop.yarn.server.resourcemanager.rmapp.RMAppImpl: application_1471639269423_0005 State change from SUBMITTED to ACCEPTED
2016-08-19 14:47:08,332 INFO org.apache.hadoop.yarn.server.resourcemanager.ApplicationMasterService: Registering app attempt : appattempt_1471639269423_0005_000001
2016-08-19 14:47:08,332 INFO org.apache.hadoop.yarn.server.resourcemanager.rmapp.attempt.RMAppAttemptImpl: appattempt_1471639269423_0005_000001 State change from NEW to SUBMITTED
2016-08-19 14:47:08,332 INFO org.apache.hadoop.yarn.server.resourcemanager.scheduler.fair.FairScheduler: Added Application Attempt appattempt_1471639269423_0005_000001 to scheduler from user: tanle
2016-08-19 14:47:08,333 INFO org.apache.hadoop.yarn.server.resourcemanager.rmapp.attempt.RMAppAttemptImpl: ScheduleTransition.transition(appattempt_1471639269423_0005_000001,EventType: ATTEMPT_ADDED)
2016-08-19 14:47:08,333 INFO org.apache.hadoop.yarn.server.resourcemanager.scheduler.fair.FairScheduler: allocate(appattempt_1471639269423_0005_000001 [{Priority: 0, Capability: <memory:2048, vCores:1>, # Containers: 1, Location: *, Relax Locality: true}] [] null null
2016-08-19 14:47:08,333 INFO org.apache.hadoop.yarn.server.resourcemanager.scheduler.fair.FSAppAttempt: appattempt_1471639269423_0005_000001 minReqResource: <memory:0, vCores:0> flexibleResource: <memory:16384, vCores:8>
2016-08-19 14:47:08,334 INFO org.apache.hadoop.yarn.server.resourcemanager.scheduler.fair.FairScheduler: iglf: 5.getHeadroom()=<memory:0, vCores:0>
2016-08-19 14:47:08,334 INFO org.apache.hadoop.yarn.server.resourcemanager.rmapp.attempt.RMAppAttemptImpl: appattempt_1471639269423_0005_000001 State change from SUBMITTED to SCHEDULED
2016-08-19 14:47:08,500 INFO org.apache.hadoop.yarn.server.resourcemanager.scheduler.fair.FairScheduler: allocate(appattempt_1471639269423_0002_000001 [{Priority: 1, Capability: <memory:1920, vCores:1>, # Containers: 120, Location: *, Relax Locality: true}] [] [] []
2016-08-19 14:47:08,500 INFO org.apache.hadoop.yarn.server.resourcemanager.scheduler.fair.FSAppAttempt: appattempt_1471639269423_0002_000001 minReqResource: <memory:0, vCores:0> flexibleResource: <memory:16384, vCores:8>
2016-08-19 14:47:08,500 INFO org.apache.hadoop.yarn.server.resourcemanager.scheduler.fair.FairScheduler: iglf: 2.getHeadroom()=<memory:0, vCores:0>
2016-08-19 14:47:08,704 INFO org.apache.hadoop.yarn.server.resourcemanager.scheduler.fair.FairScheduler: allocate(appattempt_1471639269423_0002_000001 [] [] [] []
2016-08-19 14:47:08,704 INFO org.apache.hadoop.yarn.server.resourcemanager.scheduler.fair.FSAppAttempt: appattempt_1471639269423_0002_000001 minReqResource: <memory:0, vCores:0> flexibleResource: <memory:16384, vCores:8>
2016-08-19 14:47:08,705 INFO org.apache.hadoop.yarn.server.resourcemanager.scheduler.fair.FairScheduler: iglf: 2.getHeadroom()=<memory:0, vCores:0>
2016-08-19 14:47:09,109 INFO org.apache.hadoop.yarn.server.resourcemanager.scheduler.fair.FairScheduler: allocate(appattempt_1471639269423_0002_000001 [] [] [] []
2016-08-19 14:47:09,109 INFO org.apache.hadoop.yarn.server.resourcemanager.scheduler.fair.FSAppAttempt: appattempt_1471639269423_0002_000001 minReqResource: <memory:0, vCores:0> flexibleResource: <memory:16384, vCores:8>
2016-08-19 14:47:09,109 INFO org.apache.hadoop.yarn.server.resourcemanager.scheduler.fair.FairScheduler: iglf: 2.getHeadroom()=<memory:0, vCores:0>
2016-08-19 14:47:09,673 WARN org.apache.hadoop.yarn.server.resourcemanager.rmapp.RMAppImpl: The specific max attempts: 0 for application: 4 is invalid, because it is out of the range [1, 2]. Use the global max attempts instead.
2016-08-19 14:47:09,673 INFO org.apache.hadoop.yarn.server.resourcemanager.ClientRMService: Application with id 4 submitted by user tanle
2016-08-19 14:47:09,674 INFO org.apache.hadoop.yarn.server.resourcemanager.RMAuditLogger: USER=tanle	IP=128.104.222.71	OPERATION=Submit Application Request	TARGET=ClientRMService	RESULT=SUCCESS	APPID=application_1471639269423_0004
2016-08-19 14:47:09,674 INFO org.apache.hadoop.yarn.server.resourcemanager.rmapp.RMAppImpl: Storing application with id application_1471639269423_0004
2016-08-19 14:47:09,674 INFO org.apache.hadoop.yarn.server.resourcemanager.rmapp.RMAppImpl: application_1471639269423_0004 State change from NEW to NEW_SAVING
2016-08-19 14:47:09,674 INFO org.apache.hadoop.yarn.server.resourcemanager.recovery.RMStateStore: Storing info for app: application_1471639269423_0004
2016-08-19 14:47:09,674 INFO org.apache.hadoop.yarn.server.resourcemanager.rmapp.RMAppImpl: application_1471639269423_0004 State change from NEW_SAVING to SUBMITTED
2016-08-19 14:47:09,680 INFO org.apache.hadoop.yarn.server.resourcemanager.scheduler.fair.FairScheduler: Accepted application application_1471639269423_0004 from user: tanle, in queue: interactive2, currently num of applications: 4
2016-08-19 14:47:09,680 INFO org.apache.hadoop.yarn.server.resourcemanager.rmapp.RMAppImpl: application_1471639269423_0004 State change from SUBMITTED to ACCEPTED
2016-08-19 14:47:09,681 INFO org.apache.hadoop.yarn.server.resourcemanager.ApplicationMasterService: Registering app attempt : appattempt_1471639269423_0004_000001
2016-08-19 14:47:09,681 INFO org.apache.hadoop.yarn.server.resourcemanager.rmapp.attempt.RMAppAttemptImpl: appattempt_1471639269423_0004_000001 State change from NEW to SUBMITTED
2016-08-19 14:47:09,681 INFO org.apache.hadoop.yarn.server.resourcemanager.scheduler.fair.FairScheduler: Added Application Attempt appattempt_1471639269423_0004_000001 to scheduler from user: tanle
2016-08-19 14:47:09,682 INFO org.apache.hadoop.yarn.server.resourcemanager.rmapp.attempt.RMAppAttemptImpl: ScheduleTransition.transition(appattempt_1471639269423_0004_000001,EventType: ATTEMPT_ADDED)
2016-08-19 14:47:09,682 INFO org.apache.hadoop.yarn.server.resourcemanager.scheduler.fair.FairScheduler: allocate(appattempt_1471639269423_0004_000001 [{Priority: 0, Capability: <memory:2048, vCores:1>, # Containers: 1, Location: *, Relax Locality: true}] [] null null
2016-08-19 14:47:09,682 INFO org.apache.hadoop.yarn.server.resourcemanager.scheduler.fair.FSAppAttempt: appattempt_1471639269423_0004_000001 minReqResource: <memory:0, vCores:0> flexibleResource: <memory:16384, vCores:8>
2016-08-19 14:47:09,682 INFO org.apache.hadoop.yarn.server.resourcemanager.scheduler.fair.FairScheduler: iglf: 4.getHeadroom()=<memory:0, vCores:0>
2016-08-19 14:47:09,683 INFO org.apache.hadoop.yarn.server.resourcemanager.rmapp.attempt.RMAppAttemptImpl: appattempt_1471639269423_0004_000001 State change from SUBMITTED to SCHEDULED
2016-08-19 14:47:09,912 INFO org.apache.hadoop.yarn.server.resourcemanager.scheduler.fair.FairScheduler: allocate(appattempt_1471639269423_0002_000001 [] [] [] []
2016-08-19 14:47:09,912 INFO org.apache.hadoop.yarn.server.resourcemanager.scheduler.fair.FSAppAttempt: appattempt_1471639269423_0002_000001 minReqResource: <memory:0, vCores:0> flexibleResource: <memory:16384, vCores:8>
2016-08-19 14:47:09,912 INFO org.apache.hadoop.yarn.server.resourcemanager.scheduler.fair.FairScheduler: iglf: 2.getHeadroom()=<memory:0, vCores:0>
2016-08-19 14:47:11,516 INFO org.apache.hadoop.yarn.server.resourcemanager.scheduler.fair.FairScheduler: allocate(appattempt_1471639269423_0002_000001 [] [] [] []
2016-08-19 14:47:11,516 INFO org.apache.hadoop.yarn.server.resourcemanager.scheduler.fair.FSAppAttempt: appattempt_1471639269423_0002_000001 minReqResource: <memory:0, vCores:0> flexibleResource: <memory:16384, vCores:8>
2016-08-19 14:47:11,516 INFO org.apache.hadoop.yarn.server.resourcemanager.scheduler.fair.FairScheduler: iglf: 2.getHeadroom()=<memory:0, vCores:0>
2016-08-19 14:47:13,505 INFO org.apache.hadoop.yarn.server.resourcemanager.scheduler.fair.FairScheduler: allocate(appattempt_1471639269423_0002_000001 [{Priority: 1, Capability: <memory:1920, vCores:1>, # Containers: 248, Location: *, Relax Locality: true}] [] [] []
2016-08-19 14:47:13,505 INFO org.apache.hadoop.yarn.server.resourcemanager.scheduler.fair.FSAppAttempt: appattempt_1471639269423_0002_000001 minReqResource: <memory:0, vCores:0> flexibleResource: <memory:16384, vCores:8>
2016-08-19 14:47:13,506 INFO org.apache.hadoop.yarn.server.resourcemanager.scheduler.fair.FairScheduler: iglf: 2.getHeadroom()=<memory:0, vCores:0>
2016-08-19 14:47:13,726 INFO org.apache.hadoop.yarn.server.resourcemanager.scheduler.fair.FairScheduler: allocate(appattempt_1471639269423_0002_000001 [] [] [] []
2016-08-19 14:47:13,727 INFO org.apache.hadoop.yarn.server.resourcemanager.scheduler.fair.FSAppAttempt: appattempt_1471639269423_0002_000001 minReqResource: <memory:0, vCores:0> flexibleResource: <memory:16384, vCores:8>
2016-08-19 14:47:13,727 INFO org.apache.hadoop.yarn.server.resourcemanager.scheduler.fair.FairScheduler: iglf: 2.getHeadroom()=<memory:0, vCores:0>
2016-08-19 14:47:13,791 WARN org.apache.hadoop.yarn.server.resourcemanager.rmapp.RMAppImpl: The specific max attempts: 0 for application: 6 is invalid, because it is out of the range [1, 2]. Use the global max attempts instead.
2016-08-19 14:47:13,792 INFO org.apache.hadoop.yarn.server.resourcemanager.ClientRMService: Application with id 6 submitted by user tanle
2016-08-19 14:47:13,792 INFO org.apache.hadoop.yarn.server.resourcemanager.RMAuditLogger: USER=tanle	IP=128.104.222.71	OPERATION=Submit Application Request	TARGET=ClientRMService	RESULT=SUCCESS	APPID=application_1471639269423_0006
2016-08-19 14:47:13,792 INFO org.apache.hadoop.yarn.server.resourcemanager.rmapp.RMAppImpl: Storing application with id application_1471639269423_0006
2016-08-19 14:47:13,793 INFO org.apache.hadoop.yarn.server.resourcemanager.rmapp.RMAppImpl: application_1471639269423_0006 State change from NEW to NEW_SAVING
2016-08-19 14:47:13,793 INFO org.apache.hadoop.yarn.server.resourcemanager.recovery.RMStateStore: Storing info for app: application_1471639269423_0006
2016-08-19 14:47:13,793 INFO org.apache.hadoop.yarn.server.resourcemanager.rmapp.RMAppImpl: application_1471639269423_0006 State change from NEW_SAVING to SUBMITTED
2016-08-19 14:47:13,793 INFO org.apache.hadoop.yarn.server.resourcemanager.scheduler.fair.FairScheduler: Accepted application application_1471639269423_0006 from user: tanle, in queue: batch, currently num of applications: 5
2016-08-19 14:47:13,794 INFO org.apache.hadoop.yarn.server.resourcemanager.rmapp.RMAppImpl: application_1471639269423_0006 State change from SUBMITTED to ACCEPTED
2016-08-19 14:47:13,795 INFO org.apache.hadoop.yarn.server.resourcemanager.ApplicationMasterService: Registering app attempt : appattempt_1471639269423_0006_000001
2016-08-19 14:47:13,795 INFO org.apache.hadoop.yarn.server.resourcemanager.rmapp.attempt.RMAppAttemptImpl: appattempt_1471639269423_0006_000001 State change from NEW to SUBMITTED
2016-08-19 14:47:13,796 INFO org.apache.hadoop.yarn.server.resourcemanager.scheduler.fair.FairScheduler: Added Application Attempt appattempt_1471639269423_0006_000001 to scheduler from user: tanle
2016-08-19 14:47:13,796 INFO org.apache.hadoop.yarn.server.resourcemanager.rmapp.attempt.RMAppAttemptImpl: ScheduleTransition.transition(appattempt_1471639269423_0006_000001,EventType: ATTEMPT_ADDED)
2016-08-19 14:47:13,796 INFO org.apache.hadoop.yarn.server.resourcemanager.scheduler.fair.FairScheduler: allocate(appattempt_1471639269423_0006_000001 [{Priority: 0, Capability: <memory:2048, vCores:1>, # Containers: 1, Location: *, Relax Locality: true}] [] null null
2016-08-19 14:47:13,796 INFO org.apache.hadoop.yarn.server.resourcemanager.scheduler.fair.FSAppAttempt: appattempt_1471639269423_0006_000001 minReqResource: <memory:0, vCores:0> flexibleResource: <memory:16384, vCores:8>
2016-08-19 14:47:13,797 INFO org.apache.hadoop.yarn.server.resourcemanager.scheduler.fair.FairScheduler: iglf: 6.getHeadroom()=<memory:0, vCores:0>
2016-08-19 14:47:13,797 INFO org.apache.hadoop.yarn.server.resourcemanager.rmapp.attempt.RMAppAttemptImpl: appattempt_1471639269423_0006_000001 State change from SUBMITTED to SCHEDULED
2016-08-19 14:47:14,130 INFO org.apache.hadoop.yarn.server.resourcemanager.scheduler.fair.FairScheduler: allocate(appattempt_1471639269423_0002_000001 [] [] [] []
2016-08-19 14:47:14,130 INFO org.apache.hadoop.yarn.server.resourcemanager.scheduler.fair.FSAppAttempt: appattempt_1471639269423_0002_000001 minReqResource: <memory:0, vCores:0> flexibleResource: <memory:16384, vCores:8>
2016-08-19 14:47:14,131 INFO org.apache.hadoop.yarn.server.resourcemanager.scheduler.fair.FairScheduler: iglf: 2.getHeadroom()=<memory:0, vCores:0>
2016-08-19 14:47:14,934 INFO org.apache.hadoop.yarn.server.resourcemanager.scheduler.fair.FairScheduler: allocate(appattempt_1471639269423_0002_000001 [] [] [] []
2016-08-19 14:47:14,934 INFO org.apache.hadoop.yarn.server.resourcemanager.scheduler.fair.FSAppAttempt: appattempt_1471639269423_0002_000001 minReqResource: <memory:0, vCores:0> flexibleResource: <memory:16384, vCores:8>
2016-08-19 14:47:14,935 INFO org.apache.hadoop.yarn.server.resourcemanager.scheduler.fair.FairScheduler: iglf: 2.getHeadroom()=<memory:0, vCores:0>
2016-08-19 14:47:16,539 INFO org.apache.hadoop.yarn.server.resourcemanager.scheduler.fair.FairScheduler: allocate(appattempt_1471639269423_0002_000001 [] [] [] []
2016-08-19 14:47:16,539 INFO org.apache.hadoop.yarn.server.resourcemanager.scheduler.fair.FSAppAttempt: appattempt_1471639269423_0002_000001 minReqResource: <memory:0, vCores:0> flexibleResource: <memory:16384, vCores:8>
2016-08-19 14:47:16,539 INFO org.apache.hadoop.yarn.server.resourcemanager.scheduler.fair.FairScheduler: iglf: 2.getHeadroom()=<memory:0, vCores:0>
2016-08-19 14:47:18,435 INFO org.apache.hadoop.yarn.server.resourcemanager.scheduler.fair.FairScheduler: Should preempt <memory:2048, vCores:1> res for queue root.interactive1: resDueToMinShare = <memory:2048, vCores:1>, resDueToFairShare = <memory:2048, vCores:1>
2016-08-19 14:47:18,435 INFO org.apache.hadoop.yarn.server.resourcemanager.scheduler.fair.FairScheduler: Should preempt <memory:2048, vCores:1> res for queue root.interactive3: resDueToMinShare = <memory:2048, vCores:1>, resDueToFairShare = <memory:2048, vCores:1>
2016-08-19 14:47:18,436 INFO org.apache.hadoop.yarn.server.resourcemanager.scheduler.fair.FairScheduler: Preempting container (prio=1res=<memory:2048, vCores:1>) from queue root.batch
2016-08-19 14:47:18,436 INFO org.apache.hadoop.yarn.server.resourcemanager.scheduler.fair.FairScheduler: Preempting container (prio=1res=<memory:2048, vCores:1>) from queue root.batch
2016-08-19 14:47:18,520 INFO org.apache.hadoop.yarn.server.resourcemanager.scheduler.fair.FairScheduler: allocate(appattempt_1471639269423_0002_000001 [{Priority: 1, Capability: <memory:1920, vCores:1>, # Containers: 504, Location: *, Relax Locality: true}] [] [] []
2016-08-19 14:47:18,520 INFO org.apache.hadoop.yarn.server.resourcemanager.scheduler.fair.FSAppAttempt: appattempt_1471639269423_0002_000001 minReqResource: <memory:0, vCores:0> flexibleResource: <memory:16384, vCores:8>
2016-08-19 14:47:18,520 INFO org.apache.hadoop.yarn.server.resourcemanager.scheduler.fair.FairScheduler: iglf: 2.getHeadroom()=<memory:0, vCores:0>
2016-08-19 14:47:18,737 INFO org.apache.hadoop.yarn.server.resourcemanager.scheduler.fair.FairScheduler: allocate(appattempt_1471639269423_0002_000001 [] [] [] []
2016-08-19 14:47:18,738 INFO org.apache.hadoop.yarn.server.resourcemanager.scheduler.fair.FSAppAttempt: appattempt_1471639269423_0002_000001 minReqResource: <memory:0, vCores:0> flexibleResource: <memory:16384, vCores:8>
2016-08-19 14:47:18,738 INFO org.apache.hadoop.yarn.server.resourcemanager.scheduler.fair.FairScheduler: iglf: 2.getHeadroom()=<memory:0, vCores:0>
2016-08-19 14:47:19,142 INFO org.apache.hadoop.yarn.server.resourcemanager.scheduler.fair.FairScheduler: allocate(appattempt_1471639269423_0002_000001 [] [] [] []
2016-08-19 14:47:19,142 INFO org.apache.hadoop.yarn.server.resourcemanager.scheduler.fair.FSAppAttempt: appattempt_1471639269423_0002_000001 minReqResource: <memory:0, vCores:0> flexibleResource: <memory:16384, vCores:8>
2016-08-19 14:47:19,142 INFO org.apache.hadoop.yarn.server.resourcemanager.scheduler.fair.FairScheduler: iglf: 2.getHeadroom()=<memory:0, vCores:0>
2016-08-19 14:47:19,946 INFO org.apache.hadoop.yarn.server.resourcemanager.scheduler.fair.FairScheduler: allocate(appattempt_1471639269423_0002_000001 [] [] [] []
2016-08-19 14:47:19,946 INFO org.apache.hadoop.yarn.server.resourcemanager.scheduler.fair.FSAppAttempt: appattempt_1471639269423_0002_000001 minReqResource: <memory:0, vCores:0> flexibleResource: <memory:16384, vCores:8>
2016-08-19 14:47:19,946 INFO org.apache.hadoop.yarn.server.resourcemanager.scheduler.fair.FairScheduler: iglf: 2.getHeadroom()=<memory:0, vCores:0>
2016-08-19 14:47:21,551 INFO org.apache.hadoop.yarn.server.resourcemanager.scheduler.fair.FairScheduler: allocate(appattempt_1471639269423_0002_000001 [] [] [] []
2016-08-19 14:47:21,551 INFO org.apache.hadoop.yarn.server.resourcemanager.scheduler.fair.FSAppAttempt: appattempt_1471639269423_0002_000001 minReqResource: <memory:0, vCores:0> flexibleResource: <memory:16384, vCores:8>
2016-08-19 14:47:21,551 INFO org.apache.hadoop.yarn.server.resourcemanager.scheduler.fair.FairScheduler: iglf: 2.getHeadroom()=<memory:0, vCores:0>
2016-08-19 14:47:23,443 INFO org.apache.hadoop.yarn.server.resourcemanager.scheduler.fair.FairScheduler: Should preempt <memory:2048, vCores:1> res for queue root.interactive1: resDueToMinShare = <memory:2048, vCores:1>, resDueToFairShare = <memory:2048, vCores:1>
2016-08-19 14:47:23,444 INFO org.apache.hadoop.yarn.server.resourcemanager.scheduler.fair.FairScheduler: Should preempt <memory:2048, vCores:1> res for queue root.interactive3: resDueToMinShare = <memory:2048, vCores:1>, resDueToFairShare = <memory:2048, vCores:1>
2016-08-19 14:47:23,444 INFO org.apache.hadoop.yarn.server.resourcemanager.scheduler.fair.FairScheduler: Should preempt <memory:2048, vCores:1> res for queue root.interactive2: resDueToMinShare = <memory:2048, vCores:1>, resDueToFairShare = <memory:2048, vCores:1>
2016-08-19 14:47:23,444 INFO org.apache.hadoop.yarn.server.resourcemanager.scheduler.fair.FairScheduler: Preempting container (prio=1res=<memory:2048, vCores:1>) from queue root.batch
2016-08-19 14:47:23,444 INFO org.apache.hadoop.yarn.server.resourcemanager.scheduler.fair.FairScheduler: Preempting container (prio=1res=<memory:2048, vCores:1>) from queue root.batch
2016-08-19 14:47:23,444 INFO org.apache.hadoop.yarn.server.resourcemanager.scheduler.fair.FairScheduler: Preempting container (prio=1res=<memory:2048, vCores:1>) from queue root.batch
2016-08-19 14:47:23,531 INFO org.apache.hadoop.yarn.server.resourcemanager.scheduler.fair.FairScheduler: allocate(appattempt_1471639269423_0002_000001 [{Priority: 1, Capability: <memory:1920, vCores:1>, # Containers: 1016, Location: *, Relax Locality: true}] [] [] []
2016-08-19 14:47:23,546 INFO org.apache.hadoop.yarn.server.resourcemanager.scheduler.fair.FSAppAttempt: appattempt_1471639269423_0002_000001 minReqResource: <memory:0, vCores:0> flexibleResource: <memory:16384, vCores:8>
2016-08-19 14:47:23,546 INFO org.apache.hadoop.yarn.server.resourcemanager.scheduler.fair.FairScheduler: iglf: 2.getHeadroom()=<memory:0, vCores:0>
2016-08-19 14:47:23,751 INFO org.apache.hadoop.yarn.server.resourcemanager.scheduler.fair.FairScheduler: allocate(appattempt_1471639269423_0002_000001 [] [] [] []
2016-08-19 14:47:23,751 INFO org.apache.hadoop.yarn.server.resourcemanager.scheduler.fair.FSAppAttempt: appattempt_1471639269423_0002_000001 minReqResource: <memory:0, vCores:0> flexibleResource: <memory:16384, vCores:8>
2016-08-19 14:47:23,751 INFO org.apache.hadoop.yarn.server.resourcemanager.scheduler.fair.FairScheduler: iglf: 2.getHeadroom()=<memory:0, vCores:0>
2016-08-19 14:47:24,156 INFO org.apache.hadoop.yarn.server.resourcemanager.scheduler.fair.FairScheduler: allocate(appattempt_1471639269423_0002_000001 [] [] [] []
2016-08-19 14:47:24,157 INFO org.apache.hadoop.yarn.server.resourcemanager.scheduler.fair.FSAppAttempt: appattempt_1471639269423_0002_000001 minReqResource: <memory:0, vCores:0> flexibleResource: <memory:16384, vCores:8>
2016-08-19 14:47:24,157 INFO org.apache.hadoop.yarn.server.resourcemanager.scheduler.fair.FairScheduler: iglf: 2.getHeadroom()=<memory:0, vCores:0>
2016-08-19 14:47:24,542 INFO org.apache.hadoop.yarn.server.resourcemanager.ClientRMService: Allocated new applicationId: 7
2016-08-19 14:47:24,960 INFO org.apache.hadoop.yarn.server.resourcemanager.scheduler.fair.FairScheduler: allocate(appattempt_1471639269423_0002_000001 [] [] [] []
2016-08-19 14:47:24,961 INFO org.apache.hadoop.yarn.server.resourcemanager.scheduler.fair.FSAppAttempt: appattempt_1471639269423_0002_000001 minReqResource: <memory:0, vCores:0> flexibleResource: <memory:16384, vCores:8>
2016-08-19 14:47:24,961 INFO org.apache.hadoop.yarn.server.resourcemanager.scheduler.fair.FairScheduler: iglf: 2.getHeadroom()=<memory:0, vCores:0>
2016-08-19 14:47:26,565 INFO org.apache.hadoop.yarn.server.resourcemanager.scheduler.fair.FairScheduler: allocate(appattempt_1471639269423_0002_000001 [] [] [] []
2016-08-19 14:47:26,565 INFO org.apache.hadoop.yarn.server.resourcemanager.scheduler.fair.FSAppAttempt: appattempt_1471639269423_0002_000001 minReqResource: <memory:0, vCores:0> flexibleResource: <memory:16384, vCores:8>
2016-08-19 14:47:26,566 INFO org.apache.hadoop.yarn.server.resourcemanager.scheduler.fair.FairScheduler: iglf: 2.getHeadroom()=<memory:0, vCores:0>
2016-08-19 14:47:28,450 INFO org.apache.hadoop.yarn.server.resourcemanager.scheduler.fair.FairScheduler: Should preempt <memory:2048, vCores:1> res for queue root.interactive1: resDueToMinShare = <memory:2048, vCores:1>, resDueToFairShare = <memory:2048, vCores:1>
2016-08-19 14:47:28,450 INFO org.apache.hadoop.yarn.server.resourcemanager.scheduler.fair.FairScheduler: Should preempt <memory:2048, vCores:1> res for queue root.interactive3: resDueToMinShare = <memory:2048, vCores:1>, resDueToFairShare = <memory:2048, vCores:1>
2016-08-19 14:47:28,450 INFO org.apache.hadoop.yarn.server.resourcemanager.scheduler.fair.FairScheduler: Should preempt <memory:2048, vCores:1> res for queue root.interactive2: resDueToMinShare = <memory:2048, vCores:1>, resDueToFairShare = <memory:2048, vCores:1>
2016-08-19 14:47:28,450 INFO org.apache.hadoop.yarn.server.resourcemanager.scheduler.fair.FairScheduler: Preempting container (prio=1res=<memory:2048, vCores:1>) from queue root.batch
2016-08-19 14:47:28,450 INFO org.apache.hadoop.yarn.server.resourcemanager.scheduler.fair.FairScheduler: Preempting container (prio=1res=<memory:2048, vCores:1>) from queue root.batch
2016-08-19 14:47:28,450 INFO org.apache.hadoop.yarn.server.resourcemanager.scheduler.fair.FairScheduler: Preempting container (prio=1res=<memory:2048, vCores:1>) from queue root.batch
2016-08-19 14:47:28,511 INFO org.apache.hadoop.yarn.server.resourcemanager.scheduler.fair.FairScheduler: allocate(appattempt_1471639269423_0002_000001 [{Priority: 1, Capability: <memory:1920, vCores:1>, # Containers: 1370, Location: *, Relax Locality: true}] [] [] []
2016-08-19 14:47:28,511 INFO org.apache.hadoop.yarn.server.resourcemanager.scheduler.fair.FSAppAttempt: appattempt_1471639269423_0002_000001 minReqResource: <memory:0, vCores:0> flexibleResource: <memory:16384, vCores:8>
2016-08-19 14:47:28,511 INFO org.apache.hadoop.yarn.server.resourcemanager.scheduler.fair.FairScheduler: iglf: 2.getHeadroom()=<memory:0, vCores:0>
2016-08-19 14:47:28,593 INFO org.apache.hadoop.yarn.server.resourcemanager.scheduler.fair.FairScheduler: allocate(appattempt_1471639269423_0002_000001 [{Priority: 1, Capability: <memory:1920, vCores:1>, # Containers: 1325, Location: *, Relax Locality: true}] [] [] []
2016-08-19 14:47:28,594 INFO org.apache.hadoop.yarn.server.resourcemanager.scheduler.fair.FSAppAttempt: appattempt_1471639269423_0002_000001 minReqResource: <memory:0, vCores:0> flexibleResource: <memory:16384, vCores:8>
2016-08-19 14:47:28,595 INFO org.apache.hadoop.yarn.server.resourcemanager.scheduler.fair.FairScheduler: iglf: 2.getHeadroom()=<memory:0, vCores:0>
2016-08-19 14:47:28,690 INFO org.apache.hadoop.yarn.server.resourcemanager.scheduler.fair.FairScheduler: allocate(appattempt_1471639269423_0002_000001 [{Priority: 1, Capability: <memory:1920, vCores:1>, # Containers: 1277, Location: *, Relax Locality: true}] [] [] []
2016-08-19 14:47:28,691 INFO org.apache.hadoop.yarn.server.resourcemanager.scheduler.fair.FSAppAttempt: appattempt_1471639269423_0002_000001 minReqResource: <memory:0, vCores:0> flexibleResource: <memory:16384, vCores:8>
2016-08-19 14:47:28,691 INFO org.apache.hadoop.yarn.server.resourcemanager.scheduler.fair.FairScheduler: iglf: 2.getHeadroom()=<memory:0, vCores:0>
2016-08-19 14:47:28,790 INFO org.apache.hadoop.yarn.server.resourcemanager.scheduler.fair.FairScheduler: allocate(appattempt_1471639269423_0002_000001 [{Priority: 1, Capability: <memory:1920, vCores:1>, # Containers: 1234, Location: *, Relax Locality: true}] [] [] []
2016-08-19 14:47:28,790 INFO org.apache.hadoop.yarn.server.resourcemanager.scheduler.fair.FSAppAttempt: appattempt_1471639269423_0002_000001 minReqResource: <memory:0, vCores:0> flexibleResource: <memory:16384, vCores:8>
2016-08-19 14:47:28,790 INFO org.apache.hadoop.yarn.server.resourcemanager.scheduler.fair.FairScheduler: iglf: 2.getHeadroom()=<memory:0, vCores:0>
2016-08-19 14:47:28,890 INFO org.apache.hadoop.yarn.server.resourcemanager.scheduler.fair.FairScheduler: allocate(appattempt_1471639269423_0002_000001 [{Priority: 1, Capability: <memory:1920, vCores:1>, # Containers: 1189, Location: *, Relax Locality: true}] [] [] []
2016-08-19 14:47:28,890 INFO org.apache.hadoop.yarn.server.resourcemanager.scheduler.fair.FSAppAttempt: appattempt_1471639269423_0002_000001 minReqResource: <memory:0, vCores:0> flexibleResource: <memory:16384, vCores:8>
2016-08-19 14:47:28,890 INFO org.apache.hadoop.yarn.server.resourcemanager.scheduler.fair.FairScheduler: iglf: 2.getHeadroom()=<memory:0, vCores:0>
2016-08-19 14:47:28,990 INFO org.apache.hadoop.yarn.server.resourcemanager.scheduler.fair.FairScheduler: allocate(appattempt_1471639269423_0002_000001 [{Priority: 1, Capability: <memory:1920, vCores:1>, # Containers: 1146, Location: *, Relax Locality: true}] [] [] []
2016-08-19 14:47:28,990 INFO org.apache.hadoop.yarn.server.resourcemanager.scheduler.fair.FSAppAttempt: appattempt_1471639269423_0002_000001 minReqResource: <memory:0, vCores:0> flexibleResource: <memory:16384, vCores:8>
2016-08-19 14:47:28,990 INFO org.apache.hadoop.yarn.server.resourcemanager.scheduler.fair.FairScheduler: iglf: 2.getHeadroom()=<memory:0, vCores:0>
2016-08-19 14:47:29,092 INFO org.apache.hadoop.yarn.server.resourcemanager.scheduler.fair.FairScheduler: allocate(appattempt_1471639269423_0002_000001 [{Priority: 1, Capability: <memory:1920, vCores:1>, # Containers: 1103, Location: *, Relax Locality: true}] [] [] []
2016-08-19 14:47:29,092 INFO org.apache.hadoop.yarn.server.resourcemanager.scheduler.fair.FSAppAttempt: appattempt_1471639269423_0002_000001 minReqResource: <memory:0, vCores:0> flexibleResource: <memory:16384, vCores:8>
2016-08-19 14:47:29,093 INFO org.apache.hadoop.yarn.server.resourcemanager.scheduler.fair.FairScheduler: iglf: 2.getHeadroom()=<memory:0, vCores:0>
2016-08-19 14:47:29,190 INFO org.apache.hadoop.yarn.server.resourcemanager.scheduler.fair.FairScheduler: allocate(appattempt_1471639269423_0002_000001 [{Priority: 1, Capability: <memory:1920, vCores:1>, # Containers: 1060, Location: *, Relax Locality: true}] [] [] []
2016-08-19 14:47:29,190 INFO org.apache.hadoop.yarn.server.resourcemanager.scheduler.fair.FSAppAttempt: appattempt_1471639269423_0002_000001 minReqResource: <memory:0, vCores:0> flexibleResource: <memory:16384, vCores:8>
2016-08-19 14:47:29,191 INFO org.apache.hadoop.yarn.server.resourcemanager.scheduler.fair.FairScheduler: iglf: 2.getHeadroom()=<memory:0, vCores:0>
2016-08-19 14:47:29,289 INFO org.apache.hadoop.yarn.server.resourcemanager.scheduler.fair.FairScheduler: allocate(appattempt_1471639269423_0002_000001 [{Priority: 1, Capability: <memory:1920, vCores:1>, # Containers: 1015, Location: *, Relax Locality: true}] [] [] []
2016-08-19 14:47:29,289 INFO org.apache.hadoop.yarn.server.resourcemanager.scheduler.fair.FSAppAttempt: appattempt_1471639269423_0002_000001 minReqResource: <memory:0, vCores:0> flexibleResource: <memory:16384, vCores:8>
2016-08-19 14:47:29,289 INFO org.apache.hadoop.yarn.server.resourcemanager.scheduler.fair.FairScheduler: iglf: 2.getHeadroom()=<memory:0, vCores:0>
2016-08-19 14:47:29,389 INFO org.apache.hadoop.yarn.server.resourcemanager.scheduler.fair.FairScheduler: allocate(appattempt_1471639269423_0002_000001 [{Priority: 1, Capability: <memory:1920, vCores:1>, # Containers: 973, Location: *, Relax Locality: true}] [] [] []
2016-08-19 14:47:29,389 INFO org.apache.hadoop.yarn.server.resourcemanager.scheduler.fair.FSAppAttempt: appattempt_1471639269423_0002_000001 minReqResource: <memory:0, vCores:0> flexibleResource: <memory:16384, vCores:8>
2016-08-19 14:47:29,390 INFO org.apache.hadoop.yarn.server.resourcemanager.scheduler.fair.FairScheduler: iglf: 2.getHeadroom()=<memory:0, vCores:0>
2016-08-19 14:47:29,490 INFO org.apache.hadoop.yarn.server.resourcemanager.scheduler.fair.FairScheduler: allocate(appattempt_1471639269423_0002_000001 [{Priority: 1, Capability: <memory:1920, vCores:1>, # Containers: 924, Location: *, Relax Locality: true}] [] [] []
2016-08-19 14:47:29,490 INFO org.apache.hadoop.yarn.server.resourcemanager.scheduler.fair.FSAppAttempt: appattempt_1471639269423_0002_000001 minReqResource: <memory:0, vCores:0> flexibleResource: <memory:16384, vCores:8>
2016-08-19 14:47:29,490 INFO org.apache.hadoop.yarn.server.resourcemanager.scheduler.fair.FairScheduler: iglf: 2.getHeadroom()=<memory:0, vCores:0>
2016-08-19 14:47:29,589 INFO org.apache.hadoop.yarn.server.resourcemanager.scheduler.fair.FairScheduler: allocate(appattempt_1471639269423_0002_000001 [{Priority: 1, Capability: <memory:1920, vCores:1>, # Containers: 873, Location: *, Relax Locality: true}] [] [] []
2016-08-19 14:47:29,589 INFO org.apache.hadoop.yarn.server.resourcemanager.scheduler.fair.FSAppAttempt: appattempt_1471639269423_0002_000001 minReqResource: <memory:0, vCores:0> flexibleResource: <memory:16384, vCores:8>
2016-08-19 14:47:29,590 INFO org.apache.hadoop.yarn.server.resourcemanager.scheduler.fair.FairScheduler: iglf: 2.getHeadroom()=<memory:0, vCores:0>
2016-08-19 14:47:29,689 INFO org.apache.hadoop.yarn.server.resourcemanager.scheduler.fair.FairScheduler: allocate(appattempt_1471639269423_0002_000001 [{Priority: 1, Capability: <memory:1920, vCores:1>, # Containers: 829, Location: *, Relax Locality: true}] [] [] []
2016-08-19 14:47:29,689 INFO org.apache.hadoop.yarn.server.resourcemanager.scheduler.fair.FSAppAttempt: appattempt_1471639269423_0002_000001 minReqResource: <memory:0, vCores:0> flexibleResource: <memory:16384, vCores:8>
2016-08-19 14:47:29,689 INFO org.apache.hadoop.yarn.server.resourcemanager.scheduler.fair.FairScheduler: iglf: 2.getHeadroom()=<memory:0, vCores:0>
2016-08-19 14:47:29,789 INFO org.apache.hadoop.yarn.server.resourcemanager.scheduler.fair.FairScheduler: allocate(appattempt_1471639269423_0002_000001 [{Priority: 1, Capability: <memory:1920, vCores:1>, # Containers: 788, Location: *, Relax Locality: true}] [] [] []
2016-08-19 14:47:29,789 INFO org.apache.hadoop.yarn.server.resourcemanager.scheduler.fair.FSAppAttempt: appattempt_1471639269423_0002_000001 minReqResource: <memory:0, vCores:0> flexibleResource: <memory:16384, vCores:8>
2016-08-19 14:47:29,790 INFO org.apache.hadoop.yarn.server.resourcemanager.scheduler.fair.FairScheduler: iglf: 2.getHeadroom()=<memory:0, vCores:0>
2016-08-19 14:47:29,889 INFO org.apache.hadoop.yarn.server.resourcemanager.scheduler.fair.FairScheduler: allocate(appattempt_1471639269423_0002_000001 [{Priority: 1, Capability: <memory:1920, vCores:1>, # Containers: 744, Location: *, Relax Locality: true}] [] [] []
2016-08-19 14:47:29,889 INFO org.apache.hadoop.yarn.server.resourcemanager.scheduler.fair.FSAppAttempt: appattempt_1471639269423_0002_000001 minReqResource: <memory:0, vCores:0> flexibleResource: <memory:16384, vCores:8>
2016-08-19 14:47:29,890 INFO org.apache.hadoop.yarn.server.resourcemanager.scheduler.fair.FairScheduler: iglf: 2.getHeadroom()=<memory:0, vCores:0>
2016-08-19 14:47:29,989 INFO org.apache.hadoop.yarn.server.resourcemanager.scheduler.fair.FairScheduler: allocate(appattempt_1471639269423_0002_000001 [{Priority: 1, Capability: <memory:1920, vCores:1>, # Containers: 697, Location: *, Relax Locality: true}] [] [] []
2016-08-19 14:47:29,989 INFO org.apache.hadoop.yarn.server.resourcemanager.scheduler.fair.FSAppAttempt: appattempt_1471639269423_0002_000001 minReqResource: <memory:0, vCores:0> flexibleResource: <memory:16384, vCores:8>
2016-08-19 14:47:29,989 INFO org.apache.hadoop.yarn.server.resourcemanager.scheduler.fair.FairScheduler: iglf: 2.getHeadroom()=<memory:0, vCores:0>
2016-08-19 14:47:30,089 INFO org.apache.hadoop.yarn.server.resourcemanager.scheduler.fair.FairScheduler: allocate(appattempt_1471639269423_0002_000001 [{Priority: 1, Capability: <memory:1920, vCores:1>, # Containers: 653, Location: *, Relax Locality: true}] [] [] []
2016-08-19 14:47:30,090 INFO org.apache.hadoop.yarn.server.resourcemanager.scheduler.fair.FSAppAttempt: appattempt_1471639269423_0002_000001 minReqResource: <memory:0, vCores:0> flexibleResource: <memory:16384, vCores:8>
2016-08-19 14:47:30,090 INFO org.apache.hadoop.yarn.server.resourcemanager.scheduler.fair.FairScheduler: iglf: 2.getHeadroom()=<memory:0, vCores:0>
2016-08-19 14:47:30,190 INFO org.apache.hadoop.yarn.server.resourcemanager.scheduler.fair.FairScheduler: allocate(appattempt_1471639269423_0002_000001 [{Priority: 1, Capability: <memory:1920, vCores:1>, # Containers: 607, Location: *, Relax Locality: true}] [] [] []
2016-08-19 14:47:30,190 INFO org.apache.hadoop.yarn.server.resourcemanager.scheduler.fair.FSAppAttempt: appattempt_1471639269423_0002_000001 minReqResource: <memory:0, vCores:0> flexibleResource: <memory:16384, vCores:8>
2016-08-19 14:47:30,190 INFO org.apache.hadoop.yarn.server.resourcemanager.scheduler.fair.FairScheduler: iglf: 2.getHeadroom()=<memory:0, vCores:0>
2016-08-19 14:47:30,289 INFO org.apache.hadoop.yarn.server.resourcemanager.scheduler.fair.FairScheduler: allocate(appattempt_1471639269423_0002_000001 [{Priority: 1, Capability: <memory:1920, vCores:1>, # Containers: 562, Location: *, Relax Locality: true}] [] [] []
2016-08-19 14:47:30,289 INFO org.apache.hadoop.yarn.server.resourcemanager.scheduler.fair.FSAppAttempt: appattempt_1471639269423_0002_000001 minReqResource: <memory:0, vCores:0> flexibleResource: <memory:16384, vCores:8>
2016-08-19 14:47:30,289 INFO org.apache.hadoop.yarn.server.resourcemanager.scheduler.fair.FairScheduler: iglf: 2.getHeadroom()=<memory:0, vCores:0>
2016-08-19 14:47:30,389 INFO org.apache.hadoop.yarn.server.resourcemanager.scheduler.fair.FairScheduler: allocate(appattempt_1471639269423_0002_000001 [{Priority: 1, Capability: <memory:1920, vCores:1>, # Containers: 519, Location: *, Relax Locality: true}] [] [] []
2016-08-19 14:47:30,389 INFO org.apache.hadoop.yarn.server.resourcemanager.scheduler.fair.FSAppAttempt: appattempt_1471639269423_0002_000001 minReqResource: <memory:0, vCores:0> flexibleResource: <memory:16384, vCores:8>
2016-08-19 14:47:30,390 INFO org.apache.hadoop.yarn.server.resourcemanager.scheduler.fair.FairScheduler: iglf: 2.getHeadroom()=<memory:0, vCores:0>
2016-08-19 14:47:30,489 INFO org.apache.hadoop.yarn.server.resourcemanager.scheduler.fair.FairScheduler: allocate(appattempt_1471639269423_0002_000001 [{Priority: 1, Capability: <memory:1920, vCores:1>, # Containers: 474, Location: *, Relax Locality: true}] [] [] []
2016-08-19 14:47:30,489 INFO org.apache.hadoop.yarn.server.resourcemanager.scheduler.fair.FSAppAttempt: appattempt_1471639269423_0002_000001 minReqResource: <memory:0, vCores:0> flexibleResource: <memory:16384, vCores:8>
2016-08-19 14:47:30,489 INFO org.apache.hadoop.yarn.server.resourcemanager.scheduler.fair.FairScheduler: iglf: 2.getHeadroom()=<memory:0, vCores:0>
2016-08-19 14:47:30,589 INFO org.apache.hadoop.yarn.server.resourcemanager.scheduler.fair.FairScheduler: allocate(appattempt_1471639269423_0002_000001 [{Priority: 1, Capability: <memory:1920, vCores:1>, # Containers: 430, Location: *, Relax Locality: true}] [] [] []
2016-08-19 14:47:30,589 INFO org.apache.hadoop.yarn.server.resourcemanager.scheduler.fair.FSAppAttempt: appattempt_1471639269423_0002_000001 minReqResource: <memory:0, vCores:0> flexibleResource: <memory:16384, vCores:8>
2016-08-19 14:47:30,590 INFO org.apache.hadoop.yarn.server.resourcemanager.scheduler.fair.FairScheduler: iglf: 2.getHeadroom()=<memory:0, vCores:0>
2016-08-19 14:47:30,689 INFO org.apache.hadoop.yarn.server.resourcemanager.scheduler.fair.FairScheduler: allocate(appattempt_1471639269423_0002_000001 [{Priority: 1, Capability: <memory:1920, vCores:1>, # Containers: 389, Location: *, Relax Locality: true}] [] [] []
2016-08-19 14:47:30,689 INFO org.apache.hadoop.yarn.server.resourcemanager.scheduler.fair.FSAppAttempt: appattempt_1471639269423_0002_000001 minReqResource: <memory:0, vCores:0> flexibleResource: <memory:16384, vCores:8>
2016-08-19 14:47:30,689 INFO org.apache.hadoop.yarn.server.resourcemanager.scheduler.fair.FairScheduler: iglf: 2.getHeadroom()=<memory:0, vCores:0>
2016-08-19 14:47:30,789 INFO org.apache.hadoop.yarn.server.resourcemanager.scheduler.fair.FairScheduler: allocate(appattempt_1471639269423_0002_000001 [{Priority: 1, Capability: <memory:1920, vCores:1>, # Containers: 346, Location: *, Relax Locality: true}] [] [] []
2016-08-19 14:47:30,789 INFO org.apache.hadoop.yarn.server.resourcemanager.scheduler.fair.FSAppAttempt: appattempt_1471639269423_0002_000001 minReqResource: <memory:0, vCores:0> flexibleResource: <memory:16384, vCores:8>
2016-08-19 14:47:30,789 INFO org.apache.hadoop.yarn.server.resourcemanager.scheduler.fair.FairScheduler: iglf: 2.getHeadroom()=<memory:0, vCores:0>
2016-08-19 14:47:30,889 INFO org.apache.hadoop.yarn.server.resourcemanager.scheduler.fair.FairScheduler: allocate(appattempt_1471639269423_0002_000001 [{Priority: 1, Capability: <memory:1920, vCores:1>, # Containers: 304, Location: *, Relax Locality: true}] [] [] []
2016-08-19 14:47:30,889 INFO org.apache.hadoop.yarn.server.resourcemanager.scheduler.fair.FSAppAttempt: appattempt_1471639269423_0002_000001 minReqResource: <memory:0, vCores:0> flexibleResource: <memory:16384, vCores:8>
2016-08-19 14:47:30,890 INFO org.apache.hadoop.yarn.server.resourcemanager.scheduler.fair.FairScheduler: iglf: 2.getHeadroom()=<memory:0, vCores:0>
2016-08-19 14:47:30,989 INFO org.apache.hadoop.yarn.server.resourcemanager.scheduler.fair.FairScheduler: allocate(appattempt_1471639269423_0002_000001 [{Priority: 1, Capability: <memory:1920, vCores:1>, # Containers: 262, Location: *, Relax Locality: true}] [] [] []
2016-08-19 14:47:30,990 INFO org.apache.hadoop.yarn.server.resourcemanager.scheduler.fair.FSAppAttempt: appattempt_1471639269423_0002_000001 minReqResource: <memory:0, vCores:0> flexibleResource: <memory:16384, vCores:8>
2016-08-19 14:47:30,990 INFO org.apache.hadoop.yarn.server.resourcemanager.scheduler.fair.FairScheduler: iglf: 2.getHeadroom()=<memory:0, vCores:0>
2016-08-19 14:47:31,090 INFO org.apache.hadoop.yarn.server.resourcemanager.scheduler.fair.FairScheduler: allocate(appattempt_1471639269423_0002_000001 [{Priority: 1, Capability: <memory:1920, vCores:1>, # Containers: 217, Location: *, Relax Locality: true}] [] [] []
2016-08-19 14:47:31,090 INFO org.apache.hadoop.yarn.server.resourcemanager.scheduler.fair.FSAppAttempt: appattempt_1471639269423_0002_000001 minReqResource: <memory:0, vCores:0> flexibleResource: <memory:16384, vCores:8>
2016-08-19 14:47:31,090 INFO org.apache.hadoop.yarn.server.resourcemanager.scheduler.fair.FairScheduler: iglf: 2.getHeadroom()=<memory:0, vCores:0>
2016-08-19 14:47:31,189 INFO org.apache.hadoop.yarn.server.resourcemanager.scheduler.fair.FairScheduler: allocate(appattempt_1471639269423_0002_000001 [{Priority: 1, Capability: <memory:1920, vCores:1>, # Containers: 175, Location: *, Relax Locality: true}] [] [] []
2016-08-19 14:47:31,189 INFO org.apache.hadoop.yarn.server.resourcemanager.scheduler.fair.FSAppAttempt: appattempt_1471639269423_0002_000001 minReqResource: <memory:0, vCores:0> flexibleResource: <memory:16384, vCores:8>
2016-08-19 14:47:31,190 INFO org.apache.hadoop.yarn.server.resourcemanager.scheduler.fair.FairScheduler: iglf: 2.getHeadroom()=<memory:0, vCores:0>
2016-08-19 14:47:31,289 INFO org.apache.hadoop.yarn.server.resourcemanager.scheduler.fair.FairScheduler: allocate(appattempt_1471639269423_0002_000001 [{Priority: 1, Capability: <memory:1920, vCores:1>, # Containers: 131, Location: *, Relax Locality: true}] [] [] []
2016-08-19 14:47:31,290 INFO org.apache.hadoop.yarn.server.resourcemanager.scheduler.fair.FSAppAttempt: appattempt_1471639269423_0002_000001 minReqResource: <memory:0, vCores:0> flexibleResource: <memory:16384, vCores:8>
2016-08-19 14:47:31,290 INFO org.apache.hadoop.yarn.server.resourcemanager.scheduler.fair.FairScheduler: iglf: 2.getHeadroom()=<memory:0, vCores:0>
2016-08-19 14:47:31,400 INFO org.apache.hadoop.yarn.server.resourcemanager.scheduler.fair.FairScheduler: allocate(appattempt_1471639269423_0002_000001 [{Priority: 1, Capability: <memory:1920, vCores:1>, # Containers: 91, Location: *, Relax Locality: true}] [] [] []
2016-08-19 14:47:31,400 INFO org.apache.hadoop.yarn.server.resourcemanager.scheduler.fair.FSAppAttempt: appattempt_1471639269423_0002_000001 minReqResource: <memory:0, vCores:0> flexibleResource: <memory:16384, vCores:8>
2016-08-19 14:47:31,401 INFO org.apache.hadoop.yarn.server.resourcemanager.scheduler.fair.FairScheduler: iglf: 2.getHeadroom()=<memory:0, vCores:0>
2016-08-19 14:47:31,489 INFO org.apache.hadoop.yarn.server.resourcemanager.scheduler.fair.FairScheduler: allocate(appattempt_1471639269423_0002_000001 [{Priority: 1, Capability: <memory:1920, vCores:1>, # Containers: 53, Location: *, Relax Locality: true}] [] [] []
2016-08-19 14:47:31,490 INFO org.apache.hadoop.yarn.server.resourcemanager.scheduler.fair.FSAppAttempt: appattempt_1471639269423_0002_000001 minReqResource: <memory:0, vCores:0> flexibleResource: <memory:16384, vCores:8>
2016-08-19 14:47:31,490 INFO org.apache.hadoop.yarn.server.resourcemanager.scheduler.fair.FairScheduler: iglf: 2.getHeadroom()=<memory:0, vCores:0>
2016-08-19 14:47:31,589 INFO org.apache.hadoop.yarn.server.resourcemanager.scheduler.fair.FairScheduler: allocate(appattempt_1471639269423_0002_000001 [{Priority: 1, Capability: <memory:1920, vCores:1>, # Containers: 10, Location: *, Relax Locality: true}] [] [] []
2016-08-19 14:47:31,590 INFO org.apache.hadoop.yarn.server.resourcemanager.scheduler.fair.FSAppAttempt: appattempt_1471639269423_0002_000001 minReqResource: <memory:0, vCores:0> flexibleResource: <memory:16384, vCores:8>
2016-08-19 14:47:31,590 INFO org.apache.hadoop.yarn.server.resourcemanager.scheduler.fair.FairScheduler: iglf: 2.getHeadroom()=<memory:0, vCores:0>
2016-08-19 14:47:31,681 INFO org.apache.hadoop.yarn.server.resourcemanager.scheduler.fair.FairScheduler: allocate(appattempt_1471639269423_0002_000001 [{Priority: 1, Capability: <memory:1920, vCores:1>, # Containers: 0, Location: *, Relax Locality: true}] [] [] []
2016-08-19 14:47:31,682 INFO org.apache.hadoop.yarn.server.resourcemanager.scheduler.fair.FSAppAttempt: appattempt_1471639269423_0002_000001 minReqResource: <memory:0, vCores:0> flexibleResource: <memory:16384, vCores:8>
2016-08-19 14:47:31,682 INFO org.apache.hadoop.yarn.server.resourcemanager.scheduler.AppSchedulingInfo: checking for deactivate of application :application_1471639269423_0002
2016-08-19 14:47:31,682 INFO org.apache.hadoop.yarn.server.resourcemanager.scheduler.fair.FairScheduler: iglf: 2.getHeadroom()=<memory:0, vCores:0>
2016-08-19 14:47:31,741 INFO org.apache.hadoop.yarn.server.resourcemanager.rmapp.attempt.RMAppAttemptImpl: Updating application attempt appattempt_1471639269423_0002_000001 with final state: FINISHING, and exit status: -1000
2016-08-19 14:47:31,741 INFO org.apache.hadoop.yarn.server.resourcemanager.rmapp.attempt.RMAppAttemptImpl: appattempt_1471639269423_0002_000001 State change from RUNNING to FINAL_SAVING
2016-08-19 14:47:31,741 INFO org.apache.hadoop.yarn.server.resourcemanager.rmapp.RMAppImpl: Updating application application_1471639269423_0002 with final state: FINISHING
2016-08-19 14:47:31,741 INFO org.apache.hadoop.yarn.server.resourcemanager.rmapp.RMAppImpl: application_1471639269423_0002 State change from RUNNING to FINAL_SAVING
2016-08-19 14:47:31,741 INFO org.apache.hadoop.yarn.server.resourcemanager.recovery.RMStateStore: Updating info for app: application_1471639269423_0002
2016-08-19 14:47:31,741 INFO org.apache.hadoop.yarn.server.resourcemanager.rmapp.attempt.RMAppAttemptImpl: appattempt_1471639269423_0002_000001 State change from FINAL_SAVING to FINISHING
2016-08-19 14:47:31,742 INFO org.apache.hadoop.yarn.server.resourcemanager.rmapp.RMAppImpl: application_1471639269423_0002 State change from FINAL_SAVING to FINISHING
2016-08-19 14:47:31,844 INFO org.apache.hadoop.yarn.server.resourcemanager.ApplicationMasterService: application_1471639269423_0002 unregistered successfully. 
2016-08-19 14:47:32,231 INFO org.apache.hadoop.yarn.server.resourcemanager.rmcontainer.RMContainerImpl: Processing container_1471639269423_0002_01_000007 of event FINISHED
2016-08-19 14:47:32,232 INFO org.apache.hadoop.yarn.server.resourcemanager.rmcontainer.RMContainerImpl: container_1471639269423_0002_01_000007 Container Transitioned from RUNNING to COMPLETED
2016-08-19 14:47:32,232 INFO org.apache.hadoop.yarn.server.resourcemanager.scheduler.fair.FSAppAttempt: Completed container: container_1471639269423_0002_01_000007 in state: COMPLETED event:FINISHED
2016-08-19 14:47:32,232 INFO org.apache.hadoop.yarn.server.resourcemanager.RMAuditLogger: USER=tanle	OPERATION=AM Released Container	TARGET=SchedulerApp	RESULT=SUCCESS	APPID=application_1471639269423_0002	CONTAINERID=container_1471639269423_0002_01_000007
2016-08-19 14:47:32,232 INFO org.apache.hadoop.yarn.server.resourcemanager.scheduler.SchedulerNode: Released container container_1471639269423_0002_01_000007 of capacity <memory:2048, vCores:1> on host c220g1-031106.wisc.cloudlab.us:43516, which currently has 3 containers, <memory:6144, vCores:3> used and <memory:2048, vCores:1> available, release resources=true
2016-08-19 14:47:32,232 INFO org.apache.hadoop.yarn.server.resourcemanager.scheduler.fair.FairScheduler: Application attempt appattempt_1471639269423_0002_000001 released container container_1471639269423_0002_01_000007 on node: host: c220g1-031106.wisc.cloudlab.us:43516 #containers=3 available=<memory:2048, vCores:1> used=<memory:6144, vCores:3> with event: FINISHED
2016-08-19 14:47:32,232 INFO org.apache.hadoop.yarn.server.resourcemanager.rmcontainer.RMContainerImpl: Processing container_1471639269423_0002_01_000005 of event FINISHED
2016-08-19 14:47:32,233 INFO org.apache.hadoop.yarn.server.resourcemanager.rmcontainer.RMContainerImpl: container_1471639269423_0002_01_000005 Container Transitioned from RUNNING to COMPLETED
2016-08-19 14:47:32,233 INFO org.apache.hadoop.yarn.server.resourcemanager.scheduler.fair.FSAppAttempt: Completed container: container_1471639269423_0002_01_000005 in state: COMPLETED event:FINISHED
2016-08-19 14:47:32,233 INFO org.apache.hadoop.yarn.server.resourcemanager.RMAuditLogger: USER=tanle	OPERATION=AM Released Container	TARGET=SchedulerApp	RESULT=SUCCESS	APPID=application_1471639269423_0002	CONTAINERID=container_1471639269423_0002_01_000005
2016-08-19 14:47:32,233 INFO org.apache.hadoop.yarn.server.resourcemanager.scheduler.SchedulerNode: Released container container_1471639269423_0002_01_000005 of capacity <memory:2048, vCores:1> on host c220g1-031106.wisc.cloudlab.us:43516, which currently has 2 containers, <memory:4096, vCores:2> used and <memory:4096, vCores:2> available, release resources=true
2016-08-19 14:47:32,233 INFO org.apache.hadoop.yarn.server.resourcemanager.scheduler.fair.FairScheduler: Application attempt appattempt_1471639269423_0002_000001 released container container_1471639269423_0002_01_000005 on node: host: c220g1-031106.wisc.cloudlab.us:43516 #containers=2 available=<memory:4096, vCores:2> used=<memory:4096, vCores:2> with event: FINISHED
2016-08-19 14:47:32,233 INFO org.apache.hadoop.yarn.server.resourcemanager.rmcontainer.RMContainerImpl: Processing container_1471639269423_0002_01_000009 of event FINISHED
2016-08-19 14:47:32,233 INFO org.apache.hadoop.yarn.server.resourcemanager.rmcontainer.RMContainerImpl: container_1471639269423_0002_01_000009 Container Transitioned from RUNNING to COMPLETED
2016-08-19 14:47:32,233 INFO org.apache.hadoop.yarn.server.resourcemanager.scheduler.fair.FSAppAttempt: Completed container: container_1471639269423_0002_01_000009 in state: COMPLETED event:FINISHED
2016-08-19 14:47:32,234 INFO org.apache.hadoop.yarn.server.resourcemanager.RMAuditLogger: USER=tanle	OPERATION=AM Released Container	TARGET=SchedulerApp	RESULT=SUCCESS	APPID=application_1471639269423_0002	CONTAINERID=container_1471639269423_0002_01_000009
2016-08-19 14:47:32,234 INFO org.apache.hadoop.yarn.server.resourcemanager.scheduler.SchedulerNode: Released container container_1471639269423_0002_01_000009 of capacity <memory:2048, vCores:1> on host c220g1-031106.wisc.cloudlab.us:43516, which currently has 1 containers, <memory:2048, vCores:1> used and <memory:6144, vCores:3> available, release resources=true
2016-08-19 14:47:32,234 INFO org.apache.hadoop.yarn.server.resourcemanager.scheduler.fair.FairScheduler: Application attempt appattempt_1471639269423_0002_000001 released container container_1471639269423_0002_01_000009 on node: host: c220g1-031106.wisc.cloudlab.us:43516 #containers=1 available=<memory:6144, vCores:3> used=<memory:2048, vCores:1> with event: FINISHED
2016-08-19 14:47:32,234 INFO org.apache.hadoop.yarn.server.resourcemanager.rmcontainer.RMContainerImpl: Processing container_1471639269423_0002_01_000003 of event FINISHED
2016-08-19 14:47:32,234 INFO org.apache.hadoop.yarn.server.resourcemanager.rmcontainer.RMContainerImpl: container_1471639269423_0002_01_000003 Container Transitioned from RUNNING to COMPLETED
2016-08-19 14:47:32,234 INFO org.apache.hadoop.yarn.server.resourcemanager.scheduler.fair.FSAppAttempt: Completed container: container_1471639269423_0002_01_000003 in state: COMPLETED event:FINISHED
2016-08-19 14:47:32,234 INFO org.apache.hadoop.yarn.server.resourcemanager.RMAuditLogger: USER=tanle	OPERATION=AM Released Container	TARGET=SchedulerApp	RESULT=SUCCESS	APPID=application_1471639269423_0002	CONTAINERID=container_1471639269423_0002_01_000003
2016-08-19 14:47:32,235 INFO org.apache.hadoop.yarn.server.resourcemanager.scheduler.SchedulerNode: Released container container_1471639269423_0002_01_000003 of capacity <memory:2048, vCores:1> on host c220g1-031106.wisc.cloudlab.us:43516, which currently has 0 containers, <memory:0, vCores:0> used and <memory:8192, vCores:4> available, release resources=true
2016-08-19 14:47:32,235 INFO org.apache.hadoop.yarn.server.resourcemanager.scheduler.fair.FairScheduler: Application attempt appattempt_1471639269423_0002_000001 released container container_1471639269423_0002_01_000003 on node: host: c220g1-031106.wisc.cloudlab.us:43516 #containers=0 available=<memory:8192, vCores:4> used=<memory:0, vCores:0> with event: FINISHED
2016-08-19 14:47:32,235 INFO org.apache.hadoop.yarn.server.resourcemanager.scheduler.fair.FairScheduler: Releasing reservation that cannot be satisfied for application appattempt_1471639269423_0002_000001 on node host: c220g1-031106.wisc.cloudlab.us:43516 #containers=0 available=<memory:8192, vCores:4> used=<memory:0, vCores:0>
2016-08-19 14:47:32,235 INFO org.apache.hadoop.yarn.server.resourcemanager.scheduler.fair.FSAppAttempt: Application application_1471639269423_0002 unreserved  on node host: c220g1-031106.wisc.cloudlab.us:43516 #containers=0 available=<memory:8192, vCores:4> used=<memory:0, vCores:0>, currently has 1 at priority 1; currentReservation <memory:2048, vCores:1>
2016-08-19 14:47:32,235 INFO org.apache.hadoop.yarn.server.resourcemanager.scheduler.fair.FSAppAttempt: assignContainer(FSSchedulerNode node:c220g1-031106.wisc.cloudlab.us, boolean reserved=false) for appattempt_1471639269423_0003_000001
2016-08-19 14:47:32,235 INFO org.apache.hadoop.yarn.server.resourcemanager.scheduler.fair.FSAppAttempt: assignContainer(FSSchedulerNode:c220g1-031106.wisc.cloudlab.us, ResourceRequest request, NodeType type, boolean reserved=false
2016-08-19 14:47:32,235 INFO org.apache.hadoop.yarn.server.resourcemanager.scheduler.fair.FSAppAttempt: allocate container: container_1471639269423_0003_01_000001 priority 0
2016-08-19 14:47:32,236 INFO org.apache.hadoop.yarn.server.resourcemanager.rmcontainer.RMContainerImpl: Processing container_1471639269423_0003_01_000001 of event START
2016-08-19 14:47:32,236 INFO org.apache.hadoop.yarn.server.resourcemanager.rmcontainer.RMContainerImpl: container_1471639269423_0003_01_000001 Container Transitioned from NEW to ALLOCATED
2016-08-19 14:47:32,236 INFO org.apache.hadoop.yarn.server.resourcemanager.RMAuditLogger: USER=tanle	OPERATION=AM Allocated Container	TARGET=SchedulerApp	RESULT=SUCCESS	APPID=application_1471639269423_0003	CONTAINERID=container_1471639269423_0003_01_000001
2016-08-19 14:47:32,236 INFO org.apache.hadoop.yarn.server.resourcemanager.rmapp.attempt.RMAppAttemptImpl: AMContainerAllocatedTransition.transition(appattempt_1471639269423_0003_000001,EventType: CONTAINER_ALLOCATED)
2016-08-19 14:47:32,236 INFO org.apache.hadoop.yarn.server.resourcemanager.scheduler.SchedulerNode: Assigned container container_1471639269423_0003_01_000001 of capacity <memory:2048, vCores:1> on host c220g1-031106.wisc.cloudlab.us:43516, which has 1 containers, <memory:2048, vCores:1> used and <memory:6144, vCores:3> available after allocation
2016-08-19 14:47:32,236 INFO org.apache.hadoop.yarn.server.resourcemanager.scheduler.fair.FairScheduler: allocate(appattempt_1471639269423_0003_000001 [] [] null null
2016-08-19 14:47:32,236 INFO org.apache.hadoop.yarn.server.resourcemanager.scheduler.fair.FSAppAttempt: appattempt_1471639269423_0003_000001 minReqResource: <memory:8192, vCores:4> flexibleResource: <memory:8192, vCores:4>
2016-08-19 14:47:32,238 INFO org.apache.hadoop.yarn.server.resourcemanager.security.NMTokenSecretManagerInRM: Sending NMToken for nodeId : c220g1-031106.wisc.cloudlab.us:43516 for container : container_1471639269423_0003_01_000001
2016-08-19 14:47:32,240 INFO org.apache.hadoop.yarn.server.resourcemanager.rmcontainer.RMContainerImpl: Processing container_1471639269423_0003_01_000001 of event ACQUIRED
2016-08-19 14:47:32,240 INFO org.apache.hadoop.yarn.server.resourcemanager.rmcontainer.RMContainerImpl: container_1471639269423_0003_01_000001 Container Transitioned from ALLOCATED to ACQUIRED
2016-08-19 14:47:32,240 INFO org.apache.hadoop.yarn.server.resourcemanager.scheduler.fair.FairScheduler: iglf: 3.getHeadroom()=<memory:6144, vCores:3>
2016-08-19 14:47:32,240 INFO org.apache.hadoop.yarn.server.resourcemanager.security.NMTokenSecretManagerInRM: Clear node set for appattempt_1471639269423_0003_000001
2016-08-19 14:47:32,240 INFO org.apache.hadoop.yarn.server.resourcemanager.rmapp.attempt.RMAppAttemptImpl: Storing attempt: AppId: application_1471639269423_0003 AttemptId: appattempt_1471639269423_0003_000001 MasterContainer: Container: [ContainerId: container_1471639269423_0003_01_000001, NodeId: c220g1-031106.wisc.cloudlab.us:43516, NodeHttpAddress: c220g1-031106.wisc.cloudlab.us:8042, Resource: <memory:2048, vCores:1>, Priority: 0, Token: Token { kind: ContainerToken, service: 128.104.222.16:43516 }, ]
2016-08-19 14:47:32,241 INFO org.apache.hadoop.yarn.server.resourcemanager.rmapp.attempt.RMAppAttemptImpl: appattempt_1471639269423_0003_000001 State change from SCHEDULED to ALLOCATED_SAVING
2016-08-19 14:47:32,241 INFO org.apache.hadoop.yarn.server.resourcemanager.rmapp.attempt.RMAppAttemptImpl: appattempt_1471639269423_0003_000001 State change from ALLOCATED_SAVING to ALLOCATED
2016-08-19 14:47:32,242 INFO org.apache.hadoop.yarn.server.resourcemanager.amlauncher.AMLauncher: Launching masterappattempt_1471639269423_0003_000001
2016-08-19 14:47:32,244 INFO org.apache.hadoop.yarn.server.resourcemanager.amlauncher.AMLauncher: Setting up container Container: [ContainerId: container_1471639269423_0003_01_000001, NodeId: c220g1-031106.wisc.cloudlab.us:43516, NodeHttpAddress: c220g1-031106.wisc.cloudlab.us:8042, Resource: <memory:2048, vCores:1>, Priority: 0, Token: Token { kind: ContainerToken, service: 128.104.222.16:43516 }, ] for AM appattempt_1471639269423_0003_000001
2016-08-19 14:47:32,244 INFO org.apache.hadoop.yarn.server.resourcemanager.amlauncher.AMLauncher: Command to launch container container_1471639269423_0003_01_000001 : {{JAVA_HOME}}/bin/java,-server,-Xmx1536m,-Djava.io.tmpdir={{PWD}}/tmp,-Dspark.yarn.app.container.log.dir=<LOG_DIR>,-XX:MaxPermSize=256m,org.apache.spark.deploy.yarn.ApplicationMaster,--class,'org.apache.spark.examples.SparkPi',--jar,file:/users/tanle/./spark/examples/jars/spark-examples_2.11-2.0.0-preview.jar,--arg,'10000',--properties-file,{{PWD}}/__spark_conf__/__spark_conf__.properties,1>,<LOG_DIR>/stdout,2>,<LOG_DIR>/stderr
2016-08-19 14:47:32,244 INFO org.apache.hadoop.yarn.server.resourcemanager.security.AMRMTokenSecretManager: Create AMRMToken for ApplicationAttempt: appattempt_1471639269423_0003_000001
2016-08-19 14:47:32,245 INFO org.apache.hadoop.yarn.server.resourcemanager.security.AMRMTokenSecretManager: Creating password for appattempt_1471639269423_0003_000001
2016-08-19 14:47:32,248 INFO org.apache.hadoop.yarn.server.resourcemanager.rmcontainer.RMContainerImpl: Processing container_1471639269423_0002_01_000006 of event FINISHED
2016-08-19 14:47:32,249 INFO org.apache.hadoop.yarn.server.resourcemanager.rmcontainer.RMContainerImpl: container_1471639269423_0002_01_000006 Container Transitioned from RUNNING to COMPLETED
2016-08-19 14:47:32,249 INFO org.apache.hadoop.yarn.server.resourcemanager.scheduler.fair.FSAppAttempt: Completed container: container_1471639269423_0002_01_000006 in state: COMPLETED event:FINISHED
2016-08-19 14:47:32,249 INFO org.apache.hadoop.yarn.server.resourcemanager.RMAuditLogger: USER=tanle	OPERATION=AM Released Container	TARGET=SchedulerApp	RESULT=SUCCESS	APPID=application_1471639269423_0002	CONTAINERID=container_1471639269423_0002_01_000006
2016-08-19 14:47:32,249 INFO org.apache.hadoop.yarn.server.resourcemanager.scheduler.SchedulerNode: Released container container_1471639269423_0002_01_000006 of capacity <memory:2048, vCores:1> on host cp-1.yarn-perf.yarnrm-PG0.wisc.cloudlab.us:33756, which currently has 3 containers, <memory:6144, vCores:3> used and <memory:2048, vCores:1> available, release resources=true
2016-08-19 14:47:32,249 INFO org.apache.hadoop.yarn.server.resourcemanager.scheduler.fair.FairScheduler: Application attempt appattempt_1471639269423_0002_000001 released container container_1471639269423_0002_01_000006 on node: host: cp-1.yarn-perf.yarnrm-PG0.wisc.cloudlab.us:33756 #containers=3 available=<memory:2048, vCores:1> used=<memory:6144, vCores:3> with event: FINISHED
2016-08-19 14:47:32,250 INFO org.apache.hadoop.yarn.server.resourcemanager.rmcontainer.RMContainerImpl: Processing container_1471639269423_0002_01_000004 of event FINISHED
2016-08-19 14:47:32,250 INFO org.apache.hadoop.yarn.server.resourcemanager.rmcontainer.RMContainerImpl: container_1471639269423_0002_01_000004 Container Transitioned from RUNNING to COMPLETED
2016-08-19 14:47:32,250 INFO org.apache.hadoop.yarn.server.resourcemanager.scheduler.fair.FSAppAttempt: Completed container: container_1471639269423_0002_01_000004 in state: COMPLETED event:FINISHED
2016-08-19 14:47:32,250 INFO org.apache.hadoop.yarn.server.resourcemanager.RMAuditLogger: USER=tanle	OPERATION=AM Released Container	TARGET=SchedulerApp	RESULT=SUCCESS	APPID=application_1471639269423_0002	CONTAINERID=container_1471639269423_0002_01_000004
2016-08-19 14:47:32,250 INFO org.apache.hadoop.yarn.server.resourcemanager.scheduler.SchedulerNode: Released container container_1471639269423_0002_01_000004 of capacity <memory:2048, vCores:1> on host cp-1.yarn-perf.yarnrm-PG0.wisc.cloudlab.us:33756, which currently has 2 containers, <memory:4096, vCores:2> used and <memory:4096, vCores:2> available, release resources=true
2016-08-19 14:47:32,250 INFO org.apache.hadoop.yarn.server.resourcemanager.scheduler.fair.FairScheduler: Application attempt appattempt_1471639269423_0002_000001 released container container_1471639269423_0002_01_000004 on node: host: cp-1.yarn-perf.yarnrm-PG0.wisc.cloudlab.us:33756 #containers=2 available=<memory:4096, vCores:2> used=<memory:4096, vCores:2> with event: FINISHED
2016-08-19 14:47:32,250 INFO org.apache.hadoop.yarn.server.resourcemanager.rmcontainer.RMContainerImpl: Processing container_1471639269423_0002_01_000001 of event FINISHED
2016-08-19 14:47:32,251 INFO org.apache.hadoop.yarn.server.resourcemanager.rmcontainer.RMContainerImpl: container_1471639269423_0002_01_000001 Container Transitioned from RUNNING to COMPLETED
2016-08-19 14:47:32,251 INFO org.apache.hadoop.yarn.server.resourcemanager.scheduler.fair.FSAppAttempt: Completed container: container_1471639269423_0002_01_000001 in state: COMPLETED event:FINISHED
2016-08-19 14:47:32,251 INFO org.apache.hadoop.yarn.server.resourcemanager.ApplicationMasterService: Unregistering app attempt : appattempt_1471639269423_0002_000001
2016-08-19 14:47:32,251 INFO org.apache.hadoop.yarn.server.resourcemanager.RMAuditLogger: USER=tanle	OPERATION=AM Released Container	TARGET=SchedulerApp	RESULT=SUCCESS	APPID=application_1471639269423_0002	CONTAINERID=container_1471639269423_0002_01_000001
2016-08-19 14:47:32,251 INFO org.apache.hadoop.yarn.server.resourcemanager.security.AMRMTokenSecretManager: Application finished, removing password for appattempt_1471639269423_0002_000001
2016-08-19 14:47:32,251 INFO org.apache.hadoop.yarn.server.resourcemanager.scheduler.SchedulerNode: Released container container_1471639269423_0002_01_000001 of capacity <memory:2048, vCores:1> on host cp-1.yarn-perf.yarnrm-PG0.wisc.cloudlab.us:33756, which currently has 1 containers, <memory:2048, vCores:1> used and <memory:6144, vCores:3> available, release resources=true
2016-08-19 14:47:32,251 INFO org.apache.hadoop.yarn.server.resourcemanager.rmapp.attempt.RMAppAttemptImpl: appattempt_1471639269423_0002_000001 State change from FINISHING to FINISHED
2016-08-19 14:47:32,251 INFO org.apache.hadoop.yarn.server.resourcemanager.scheduler.fair.FairScheduler: Application attempt appattempt_1471639269423_0002_000001 released container container_1471639269423_0002_01_000001 on node: host: cp-1.yarn-perf.yarnrm-PG0.wisc.cloudlab.us:33756 #containers=1 available=<memory:6144, vCores:3> used=<memory:2048, vCores:1> with event: FINISHED
2016-08-19 14:47:32,251 INFO org.apache.hadoop.yarn.server.resourcemanager.rmapp.RMAppImpl: application_1471639269423_0002 State change from FINISHING to FINISHED
2016-08-19 14:47:32,252 INFO org.apache.hadoop.yarn.server.resourcemanager.rmcontainer.RMContainerImpl: Processing container_1471639269423_0002_01_000002 of event FINISHED
2016-08-19 14:47:32,252 INFO org.apache.hadoop.yarn.server.resourcemanager.rmcontainer.RMContainerImpl: container_1471639269423_0002_01_000002 Container Transitioned from RUNNING to COMPLETED
2016-08-19 14:47:32,252 INFO org.apache.hadoop.yarn.server.resourcemanager.RMAuditLogger: USER=tanle	OPERATION=Application Finished - Succeeded	TARGET=RMAppManager	RESULT=SUCCESS	APPID=application_1471639269423_0002
2016-08-19 14:47:32,252 INFO org.apache.hadoop.yarn.server.resourcemanager.scheduler.fair.FSAppAttempt: Completed container: container_1471639269423_0002_01_000002 in state: COMPLETED event:FINISHED
2016-08-19 14:47:32,252 INFO org.apache.hadoop.yarn.server.resourcemanager.RMAuditLogger: USER=tanle	OPERATION=AM Released Container	TARGET=SchedulerApp	RESULT=SUCCESS	APPID=application_1471639269423_0002	CONTAINERID=container_1471639269423_0002_01_000002
2016-08-19 14:47:32,252 INFO org.apache.hadoop.yarn.server.resourcemanager.scheduler.SchedulerNode: Released container container_1471639269423_0002_01_000002 of capacity <memory:2048, vCores:1> on host cp-1.yarn-perf.yarnrm-PG0.wisc.cloudlab.us:33756, which currently has 0 containers, <memory:0, vCores:0> used and <memory:8192, vCores:4> available, release resources=true
2016-08-19 14:47:32,252 INFO org.apache.hadoop.yarn.server.resourcemanager.amlauncher.AMLauncher: Cleaning master appattempt_1471639269423_0002_000001
2016-08-19 14:47:32,252 INFO org.apache.hadoop.yarn.server.resourcemanager.scheduler.fair.FairScheduler: Application attempt appattempt_1471639269423_0002_000001 released container container_1471639269423_0002_01_000002 on node: host: cp-1.yarn-perf.yarnrm-PG0.wisc.cloudlab.us:33756 #containers=0 available=<memory:8192, vCores:4> used=<memory:0, vCores:0> with event: FINISHED
2016-08-19 14:47:32,252 INFO org.apache.hadoop.yarn.server.resourcemanager.scheduler.fair.FairScheduler: Releasing reservation that cannot be satisfied for application appattempt_1471639269423_0002_000001 on node host: cp-1.yarn-perf.yarnrm-PG0.wisc.cloudlab.us:33756 #containers=0 available=<memory:8192, vCores:4> used=<memory:0, vCores:0>
2016-08-19 14:47:32,253 INFO org.apache.hadoop.yarn.server.resourcemanager.scheduler.fair.FSAppAttempt: Application application_1471639269423_0002 unreserved  on node host: cp-1.yarn-perf.yarnrm-PG0.wisc.cloudlab.us:33756 #containers=0 available=<memory:8192, vCores:4> used=<memory:0, vCores:0>, currently has 0 at priority 1; currentReservation <memory:0, vCores:0>
2016-08-19 14:47:32,253 INFO org.apache.hadoop.yarn.server.resourcemanager.RMAppManager$ApplicationSummary: appId=application_1471639269423_0002,name=org.apache.spark.examples.SparkPi,user=tanle,queue=root.batch,state=FINISHED,trackingUrl=http://nm.yarn-perf.yarnrm-pg0.wisc.cloudlab.us:8088/proxy/application_1471639269423_0002/,appMasterHost=128.104.222.17,startTime=1471639577143,finishTime=1471639651741,finalStatus=SUCCEEDED,memorySeconds=581619,vcoreSeconds=283,preemptedAMContainers=0,preemptedNonAMContainers=0,preemptedResources=<memory:0\, vCores:0>,applicationType=SPARK
2016-08-19 14:47:32,253 INFO org.apache.hadoop.yarn.server.resourcemanager.scheduler.fair.FSAppAttempt: assignContainer(FSSchedulerNode node:cp-1.yarn-perf.yarnrm-PG0.wisc.cloudlab.us, boolean reserved=false) for appattempt_1471639269423_0005_000001
2016-08-19 14:47:32,253 INFO org.apache.hadoop.yarn.server.resourcemanager.scheduler.fair.FSAppAttempt: assignContainer(FSSchedulerNode:cp-1.yarn-perf.yarnrm-PG0.wisc.cloudlab.us, ResourceRequest request, NodeType type, boolean reserved=false
2016-08-19 14:47:32,253 INFO org.apache.hadoop.yarn.server.resourcemanager.scheduler.fair.FSAppAttempt: allocate container: container_1471639269423_0005_01_000001 priority 0
2016-08-19 14:47:32,254 INFO org.apache.hadoop.yarn.server.resourcemanager.rmcontainer.RMContainerImpl: Processing container_1471639269423_0005_01_000001 of event START
2016-08-19 14:47:32,254 INFO org.apache.hadoop.yarn.server.resourcemanager.rmcontainer.RMContainerImpl: container_1471639269423_0005_01_000001 Container Transitioned from NEW to ALLOCATED
2016-08-19 14:47:32,254 INFO org.apache.hadoop.yarn.server.resourcemanager.RMAuditLogger: USER=tanle	OPERATION=AM Allocated Container	TARGET=SchedulerApp	RESULT=SUCCESS	APPID=application_1471639269423_0005	CONTAINERID=container_1471639269423_0005_01_000001
2016-08-19 14:47:32,254 INFO org.apache.hadoop.yarn.server.resourcemanager.rmapp.attempt.RMAppAttemptImpl: AMContainerAllocatedTransition.transition(appattempt_1471639269423_0005_000001,EventType: CONTAINER_ALLOCATED)
2016-08-19 14:47:32,254 INFO org.apache.hadoop.yarn.server.resourcemanager.scheduler.SchedulerNode: Assigned container container_1471639269423_0005_01_000001 of capacity <memory:2048, vCores:1> on host cp-1.yarn-perf.yarnrm-PG0.wisc.cloudlab.us:33756, which has 1 containers, <memory:2048, vCores:1> used and <memory:6144, vCores:3> available after allocation
2016-08-19 14:47:32,254 INFO org.apache.hadoop.yarn.server.resourcemanager.scheduler.fair.FairScheduler: allocate(appattempt_1471639269423_0005_000001 [] [] null null
2016-08-19 14:47:32,254 INFO org.apache.hadoop.yarn.server.resourcemanager.scheduler.fair.FairScheduler: Application appattempt_1471639269423_0002_000001 is done. finalState=FINISHED
2016-08-19 14:47:32,254 INFO org.apache.hadoop.yarn.server.resourcemanager.scheduler.fair.FSAppAttempt: appattempt_1471639269423_0005_000001 minReqResource: <memory:16384, vCores:8> flexibleResource: <memory:0, vCores:0>
2016-08-19 14:47:32,254 INFO org.apache.hadoop.yarn.server.resourcemanager.scheduler.fair.FairScheduler: Cannot allocate resource to appattempt_1471639269423_0005_000001 because there is NO flexible resource left
2016-08-19 14:47:32,254 INFO org.apache.hadoop.yarn.server.resourcemanager.scheduler.AppSchedulingInfo: Application application_1471639269423_0002 requests cleared
2016-08-19 14:47:32,263 INFO org.apache.hadoop.yarn.server.resourcemanager.amlauncher.AMLauncher: Done launching container Container: [ContainerId: container_1471639269423_0003_01_000001, NodeId: c220g1-031106.wisc.cloudlab.us:43516, NodeHttpAddress: c220g1-031106.wisc.cloudlab.us:8042, Resource: <memory:2048, vCores:1>, Priority: 0, Token: Token { kind: ContainerToken, service: 128.104.222.16:43516 }, ] for AM appattempt_1471639269423_0003_000001
2016-08-19 14:47:32,263 INFO org.apache.hadoop.yarn.server.resourcemanager.rmapp.attempt.RMAppAttemptImpl: appattempt_1471639269423_0003_000001 State change from ALLOCATED to LAUNCHED
2016-08-19 14:47:32,272 INFO org.apache.hadoop.yarn.server.resourcemanager.scheduler.fair.FSAppAttempt: assignContainer(FSSchedulerNode node:cp-1.yarn-perf.yarnrm-PG0.wisc.cloudlab.us, boolean reserved=false) for appattempt_1471639269423_0004_000001
2016-08-19 14:47:32,272 INFO org.apache.hadoop.yarn.server.resourcemanager.scheduler.fair.FSAppAttempt: assignContainer(FSSchedulerNode:cp-1.yarn-perf.yarnrm-PG0.wisc.cloudlab.us, ResourceRequest request, NodeType type, boolean reserved=false
2016-08-19 14:47:32,272 INFO org.apache.hadoop.yarn.server.resourcemanager.scheduler.fair.FSAppAttempt: allocate container: container_1471639269423_0004_01_000001 priority 0
2016-08-19 14:47:32,272 INFO org.apache.hadoop.yarn.server.resourcemanager.rmcontainer.RMContainerImpl: Processing container_1471639269423_0004_01_000001 of event START
2016-08-19 14:47:32,273 INFO org.apache.hadoop.yarn.server.resourcemanager.rmcontainer.RMContainerImpl: container_1471639269423_0004_01_000001 Container Transitioned from NEW to ALLOCATED
2016-08-19 14:47:32,273 INFO org.apache.hadoop.yarn.server.resourcemanager.RMAuditLogger: USER=tanle	OPERATION=AM Allocated Container	TARGET=SchedulerApp	RESULT=SUCCESS	APPID=application_1471639269423_0004	CONTAINERID=container_1471639269423_0004_01_000001
2016-08-19 14:47:32,273 INFO org.apache.hadoop.yarn.server.resourcemanager.rmapp.attempt.RMAppAttemptImpl: AMContainerAllocatedTransition.transition(appattempt_1471639269423_0004_000001,EventType: CONTAINER_ALLOCATED)
2016-08-19 14:47:32,273 INFO org.apache.hadoop.yarn.server.resourcemanager.scheduler.SchedulerNode: Assigned container container_1471639269423_0004_01_000001 of capacity <memory:2048, vCores:1> on host cp-1.yarn-perf.yarnrm-PG0.wisc.cloudlab.us:33756, which has 2 containers, <memory:4096, vCores:2> used and <memory:4096, vCores:2> available after allocation
2016-08-19 14:47:32,273 INFO org.apache.hadoop.yarn.server.resourcemanager.scheduler.fair.FairScheduler: allocate(appattempt_1471639269423_0004_000001 [] [] null null
2016-08-19 14:47:32,273 INFO org.apache.hadoop.yarn.server.resourcemanager.scheduler.fair.FSAppAttempt: appattempt_1471639269423_0004_000001 minReqResource: <memory:24576, vCores:12> flexibleResource: <memory:-8192, vCores:-4>
2016-08-19 14:47:32,273 INFO org.apache.hadoop.yarn.server.resourcemanager.scheduler.fair.FairScheduler: Cannot allocate resource to appattempt_1471639269423_0004_000001 because there is NO flexible resource left
2016-08-19 14:47:32,757 INFO org.apache.hadoop.yarn.server.resourcemanager.rmapp.attempt.RMAppAttemptImpl: AMContainerAllocatedTransition.transition(appattempt_1471639269423_0005_000001,EventType: CONTAINER_ALLOCATED)
2016-08-19 14:47:32,758 INFO org.apache.hadoop.yarn.server.resourcemanager.scheduler.fair.FairScheduler: allocate(appattempt_1471639269423_0005_000001 [] [] null null
2016-08-19 14:47:32,758 INFO org.apache.hadoop.yarn.server.resourcemanager.scheduler.fair.FSAppAttempt: appattempt_1471639269423_0005_000001 minReqResource: <memory:24576, vCores:12> flexibleResource: <memory:-8192, vCores:-4>
2016-08-19 14:47:32,758 INFO org.apache.hadoop.yarn.server.resourcemanager.scheduler.fair.FairScheduler: Cannot allocate resource to appattempt_1471639269423_0005_000001 because there is NO flexible resource left
2016-08-19 14:47:32,774 INFO org.apache.hadoop.yarn.server.resourcemanager.rmapp.attempt.RMAppAttemptImpl: AMContainerAllocatedTransition.transition(appattempt_1471639269423_0004_000001,EventType: CONTAINER_ALLOCATED)
2016-08-19 14:47:32,774 INFO org.apache.hadoop.yarn.server.resourcemanager.scheduler.fair.FairScheduler: allocate(appattempt_1471639269423_0004_000001 [] [] null null
2016-08-19 14:47:32,774 INFO org.apache.hadoop.yarn.server.resourcemanager.scheduler.fair.FSAppAttempt: appattempt_1471639269423_0004_000001 minReqResource: <memory:24576, vCores:12> flexibleResource: <memory:-8192, vCores:-4>
2016-08-19 14:47:32,774 INFO org.apache.hadoop.yarn.server.resourcemanager.scheduler.fair.FairScheduler: Cannot allocate resource to appattempt_1471639269423_0004_000001 because there is NO flexible resource left
2016-08-19 14:47:33,236 INFO org.apache.hadoop.yarn.server.resourcemanager.rmcontainer.RMContainerImpl: Processing container_1471639269423_0003_01_000001 of event LAUNCHED
2016-08-19 14:47:33,236 INFO org.apache.hadoop.yarn.server.resourcemanager.rmcontainer.RMContainerImpl: container_1471639269423_0003_01_000001 Container Transitioned from ACQUIRED to RUNNING
2016-08-19 14:47:33,236 INFO org.apache.hadoop.yarn.server.resourcemanager.scheduler.fair.FSAppAttempt: assignContainer(FSSchedulerNode node:c220g1-031106.wisc.cloudlab.us, boolean reserved=false) for appattempt_1471639269423_0003_000001
2016-08-19 14:47:33,237 INFO org.apache.hadoop.yarn.server.resourcemanager.scheduler.fair.FSAppAttempt: assignContainer(FSSchedulerNode node:c220g1-031106.wisc.cloudlab.us, boolean reserved=false) for appattempt_1471639269423_0005_000001
2016-08-19 14:47:33,237 INFO org.apache.hadoop.yarn.server.resourcemanager.scheduler.fair.FSAppAttempt: assignContainer(FSSchedulerNode node:c220g1-031106.wisc.cloudlab.us, boolean reserved=false) for appattempt_1471639269423_0004_000001
2016-08-19 14:47:33,237 INFO org.apache.hadoop.yarn.server.resourcemanager.scheduler.fair.FSAppAttempt: assignContainer(FSSchedulerNode node:c220g1-031106.wisc.cloudlab.us, boolean reserved=false) for appattempt_1471639269423_0006_000001
2016-08-19 14:47:33,259 INFO org.apache.hadoop.yarn.server.resourcemanager.rmapp.attempt.RMAppAttemptImpl: AMContainerAllocatedTransition.transition(appattempt_1471639269423_0005_000001,EventType: CONTAINER_ALLOCATED)
2016-08-19 14:47:33,259 INFO org.apache.hadoop.yarn.server.resourcemanager.scheduler.fair.FairScheduler: allocate(appattempt_1471639269423_0005_000001 [] [] null null
2016-08-19 14:47:33,259 INFO org.apache.hadoop.yarn.server.resourcemanager.scheduler.fair.FSAppAttempt: appattempt_1471639269423_0005_000001 minReqResource: <memory:24576, vCores:12> flexibleResource: <memory:-8192, vCores:-4>
2016-08-19 14:47:33,259 INFO org.apache.hadoop.yarn.server.resourcemanager.scheduler.fair.FairScheduler: Cannot allocate resource to appattempt_1471639269423_0005_000001 because there is NO flexible resource left
2016-08-19 14:47:33,275 INFO org.apache.hadoop.yarn.server.resourcemanager.rmapp.attempt.RMAppAttemptImpl: AMContainerAllocatedTransition.transition(appattempt_1471639269423_0004_000001,EventType: CONTAINER_ALLOCATED)
2016-08-19 14:47:33,275 INFO org.apache.hadoop.yarn.server.resourcemanager.scheduler.fair.FairScheduler: allocate(appattempt_1471639269423_0004_000001 [] [] null null
2016-08-19 14:47:33,275 INFO org.apache.hadoop.yarn.server.resourcemanager.scheduler.fair.FSAppAttempt: appattempt_1471639269423_0004_000001 minReqResource: <memory:24576, vCores:12> flexibleResource: <memory:-8192, vCores:-4>
2016-08-19 14:47:33,276 INFO org.apache.hadoop.yarn.server.resourcemanager.scheduler.fair.FairScheduler: Cannot allocate resource to appattempt_1471639269423_0004_000001 because there is NO flexible resource left
2016-08-19 14:47:33,277 INFO org.apache.hadoop.yarn.server.resourcemanager.scheduler.fair.FairScheduler: Null container completed...
2016-08-19 14:47:33,277 INFO org.apache.hadoop.yarn.server.resourcemanager.scheduler.fair.FairScheduler: Null container completed...
2016-08-19 14:47:33,277 INFO org.apache.hadoop.yarn.server.resourcemanager.scheduler.fair.FairScheduler: Null container completed...
2016-08-19 14:47:33,278 INFO org.apache.hadoop.yarn.server.resourcemanager.scheduler.fair.FSAppAttempt: assignContainer(FSSchedulerNode node:cp-1.yarn-perf.yarnrm-PG0.wisc.cloudlab.us, boolean reserved=false) for appattempt_1471639269423_0003_000001
2016-08-19 14:47:33,278 INFO org.apache.hadoop.yarn.server.resourcemanager.scheduler.fair.FSAppAttempt: assignContainer(FSSchedulerNode node:cp-1.yarn-perf.yarnrm-PG0.wisc.cloudlab.us, boolean reserved=false) for appattempt_1471639269423_0005_000001
2016-08-19 14:47:33,278 INFO org.apache.hadoop.yarn.server.resourcemanager.scheduler.fair.FSAppAttempt: assignContainer(FSSchedulerNode node:cp-1.yarn-perf.yarnrm-PG0.wisc.cloudlab.us, boolean reserved=false) for appattempt_1471639269423_0004_000001
2016-08-19 14:47:33,278 INFO org.apache.hadoop.yarn.server.resourcemanager.scheduler.fair.FSAppAttempt: assignContainer(FSSchedulerNode node:cp-1.yarn-perf.yarnrm-PG0.wisc.cloudlab.us, boolean reserved=false) for appattempt_1471639269423_0006_000001
2016-08-19 14:47:33,423 WARN org.apache.hadoop.yarn.server.resourcemanager.rmapp.RMAppImpl: The specific max attempts: 0 for application: 7 is invalid, because it is out of the range [1, 2]. Use the global max attempts instead.
2016-08-19 14:47:33,424 INFO org.apache.hadoop.yarn.server.resourcemanager.ClientRMService: Application with id 7 submitted by user tanle
2016-08-19 14:47:33,424 INFO org.apache.hadoop.yarn.server.resourcemanager.RMAuditLogger: USER=tanle	IP=128.104.222.71	OPERATION=Submit Application Request	TARGET=ClientRMService	RESULT=SUCCESS	APPID=application_1471639269423_0007
2016-08-19 14:47:33,424 INFO org.apache.hadoop.yarn.server.resourcemanager.rmapp.RMAppImpl: Storing application with id application_1471639269423_0007
2016-08-19 14:47:33,424 INFO org.apache.hadoop.yarn.server.resourcemanager.rmapp.RMAppImpl: application_1471639269423_0007 State change from NEW to NEW_SAVING
2016-08-19 14:47:33,424 INFO org.apache.hadoop.yarn.server.resourcemanager.recovery.RMStateStore: Storing info for app: application_1471639269423_0007
2016-08-19 14:47:33,425 INFO org.apache.hadoop.yarn.server.resourcemanager.rmapp.RMAppImpl: application_1471639269423_0007 State change from NEW_SAVING to SUBMITTED
2016-08-19 14:47:33,425 INFO org.apache.hadoop.yarn.server.resourcemanager.scheduler.fair.FairScheduler: Accepted application application_1471639269423_0007 from user: tanle, in queue: batch, currently num of applications: 5
2016-08-19 14:47:33,426 INFO org.apache.hadoop.yarn.server.resourcemanager.rmapp.RMAppImpl: application_1471639269423_0007 State change from SUBMITTED to ACCEPTED
2016-08-19 14:47:33,426 INFO org.apache.hadoop.yarn.server.resourcemanager.ApplicationMasterService: Registering app attempt : appattempt_1471639269423_0007_000001
2016-08-19 14:47:33,426 INFO org.apache.hadoop.yarn.server.resourcemanager.rmapp.attempt.RMAppAttemptImpl: appattempt_1471639269423_0007_000001 State change from NEW to SUBMITTED
2016-08-19 14:47:33,426 INFO org.apache.hadoop.yarn.server.resourcemanager.scheduler.fair.FairScheduler: Added Application Attempt appattempt_1471639269423_0007_000001 to scheduler from user: tanle
2016-08-19 14:47:33,426 INFO org.apache.hadoop.yarn.server.resourcemanager.rmapp.attempt.RMAppAttemptImpl: ScheduleTransition.transition(appattempt_1471639269423_0007_000001,EventType: ATTEMPT_ADDED)
2016-08-19 14:47:33,427 INFO org.apache.hadoop.yarn.server.resourcemanager.scheduler.fair.FairScheduler: allocate(appattempt_1471639269423_0007_000001 [{Priority: 0, Capability: <memory:2048, vCores:1>, # Containers: 1, Location: *, Relax Locality: true}] [] null null
2016-08-19 14:47:33,427 INFO org.apache.hadoop.yarn.server.resourcemanager.scheduler.fair.FSAppAttempt: appattempt_1471639269423_0007_000001 minReqResource: <memory:24576, vCores:12> flexibleResource: <memory:-8192, vCores:-4>
2016-08-19 14:47:33,427 INFO org.apache.hadoop.yarn.server.resourcemanager.scheduler.fair.FairScheduler: Cannot allocate resource to appattempt_1471639269423_0007_000001 because there is NO flexible resource left
2016-08-19 14:47:33,427 INFO org.apache.hadoop.yarn.server.resourcemanager.rmapp.attempt.RMAppAttemptImpl: appattempt_1471639269423_0007_000001 State change from SUBMITTED to SCHEDULED
2016-08-19 14:47:33,760 INFO org.apache.hadoop.yarn.server.resourcemanager.rmapp.attempt.RMAppAttemptImpl: AMContainerAllocatedTransition.transition(appattempt_1471639269423_0005_000001,EventType: CONTAINER_ALLOCATED)
2016-08-19 14:47:33,761 INFO org.apache.hadoop.yarn.server.resourcemanager.scheduler.fair.FairScheduler: allocate(appattempt_1471639269423_0005_000001 [] [] null null
2016-08-19 14:47:33,761 INFO org.apache.hadoop.yarn.server.resourcemanager.scheduler.fair.FSAppAttempt: appattempt_1471639269423_0005_000001 minReqResource: <memory:24576, vCores:12> flexibleResource: <memory:-8192, vCores:-4>
2016-08-19 14:47:33,761 INFO org.apache.hadoop.yarn.server.resourcemanager.scheduler.fair.FairScheduler: Cannot allocate resource to appattempt_1471639269423_0005_000001 because there is NO flexible resource left
2016-08-19 14:47:33,777 INFO org.apache.hadoop.yarn.server.resourcemanager.rmapp.attempt.RMAppAttemptImpl: AMContainerAllocatedTransition.transition(appattempt_1471639269423_0004_000001,EventType: CONTAINER_ALLOCATED)
2016-08-19 14:47:33,777 INFO org.apache.hadoop.yarn.server.resourcemanager.scheduler.fair.FairScheduler: allocate(appattempt_1471639269423_0004_000001 [] [] null null
2016-08-19 14:47:33,777 INFO org.apache.hadoop.yarn.server.resourcemanager.scheduler.fair.FSAppAttempt: appattempt_1471639269423_0004_000001 minReqResource: <memory:24576, vCores:12> flexibleResource: <memory:-8192, vCores:-4>
2016-08-19 14:47:33,777 INFO org.apache.hadoop.yarn.server.resourcemanager.scheduler.fair.FairScheduler: Cannot allocate resource to appattempt_1471639269423_0004_000001 because there is NO flexible resource left
2016-08-19 14:47:34,240 INFO org.apache.hadoop.yarn.server.resourcemanager.scheduler.fair.FairScheduler: Null container completed...
2016-08-19 14:47:34,240 INFO org.apache.hadoop.yarn.server.resourcemanager.scheduler.fair.FairScheduler: Null container completed...
2016-08-19 14:47:34,240 INFO org.apache.hadoop.yarn.server.resourcemanager.scheduler.fair.FairScheduler: Null container completed...
2016-08-19 14:47:34,240 INFO org.apache.hadoop.yarn.server.resourcemanager.scheduler.fair.FairScheduler: Null container completed...
2016-08-19 14:47:34,241 INFO org.apache.hadoop.yarn.server.resourcemanager.scheduler.fair.FSAppAttempt: assignContainer(FSSchedulerNode node:c220g1-031106.wisc.cloudlab.us, boolean reserved=false) for appattempt_1471639269423_0003_000001
2016-08-19 14:47:34,241 INFO org.apache.hadoop.yarn.server.resourcemanager.scheduler.fair.FSAppAttempt: assignContainer(FSSchedulerNode node:c220g1-031106.wisc.cloudlab.us, boolean reserved=false) for appattempt_1471639269423_0005_000001
2016-08-19 14:47:34,241 INFO org.apache.hadoop.yarn.server.resourcemanager.scheduler.fair.FSAppAttempt: assignContainer(FSSchedulerNode node:c220g1-031106.wisc.cloudlab.us, boolean reserved=false) for appattempt_1471639269423_0004_000001
2016-08-19 14:47:34,241 INFO org.apache.hadoop.yarn.server.resourcemanager.scheduler.fair.FSAppAttempt: assignContainer(FSSchedulerNode node:c220g1-031106.wisc.cloudlab.us, boolean reserved=false) for appattempt_1471639269423_0006_000001
2016-08-19 14:47:34,241 INFO org.apache.hadoop.yarn.server.resourcemanager.scheduler.fair.FSAppAttempt: assignContainer(FSSchedulerNode node:c220g1-031106.wisc.cloudlab.us, boolean reserved=false) for appattempt_1471639269423_0007_000001
2016-08-19 14:47:34,262 INFO org.apache.hadoop.yarn.server.resourcemanager.rmapp.attempt.RMAppAttemptImpl: AMContainerAllocatedTransition.transition(appattempt_1471639269423_0005_000001,EventType: CONTAINER_ALLOCATED)
2016-08-19 14:47:34,262 INFO org.apache.hadoop.yarn.server.resourcemanager.scheduler.fair.FairScheduler: allocate(appattempt_1471639269423_0005_000001 [] [] null null
2016-08-19 14:47:34,262 INFO org.apache.hadoop.yarn.server.resourcemanager.scheduler.fair.FSAppAttempt: appattempt_1471639269423_0005_000001 minReqResource: <memory:24576, vCores:12> flexibleResource: <memory:-8192, vCores:-4>
2016-08-19 14:47:34,262 INFO org.apache.hadoop.yarn.server.resourcemanager.scheduler.fair.FairScheduler: Cannot allocate resource to appattempt_1471639269423_0005_000001 because there is NO flexible resource left
2016-08-19 14:47:34,278 INFO org.apache.hadoop.yarn.server.resourcemanager.rmapp.attempt.RMAppAttemptImpl: AMContainerAllocatedTransition.transition(appattempt_1471639269423_0004_000001,EventType: CONTAINER_ALLOCATED)
2016-08-19 14:47:34,278 INFO org.apache.hadoop.yarn.server.resourcemanager.scheduler.fair.FairScheduler: allocate(appattempt_1471639269423_0004_000001 [] [] null null
2016-08-19 14:47:34,278 INFO org.apache.hadoop.yarn.server.resourcemanager.scheduler.fair.FSAppAttempt: appattempt_1471639269423_0004_000001 minReqResource: <memory:24576, vCores:12> flexibleResource: <memory:-8192, vCores:-4>
2016-08-19 14:47:34,278 INFO org.apache.hadoop.yarn.server.resourcemanager.scheduler.fair.FairScheduler: Cannot allocate resource to appattempt_1471639269423_0004_000001 because there is NO flexible resource left
2016-08-19 14:47:34,279 INFO org.apache.hadoop.yarn.server.resourcemanager.scheduler.fair.FSAppAttempt: assignContainer(FSSchedulerNode node:cp-1.yarn-perf.yarnrm-PG0.wisc.cloudlab.us, boolean reserved=false) for appattempt_1471639269423_0003_000001
2016-08-19 14:47:34,279 INFO org.apache.hadoop.yarn.server.resourcemanager.scheduler.fair.FSAppAttempt: assignContainer(FSSchedulerNode node:cp-1.yarn-perf.yarnrm-PG0.wisc.cloudlab.us, boolean reserved=false) for appattempt_1471639269423_0005_000001
2016-08-19 14:47:34,279 INFO org.apache.hadoop.yarn.server.resourcemanager.scheduler.fair.FSAppAttempt: assignContainer(FSSchedulerNode node:cp-1.yarn-perf.yarnrm-PG0.wisc.cloudlab.us, boolean reserved=false) for appattempt_1471639269423_0004_000001
2016-08-19 14:47:34,280 INFO org.apache.hadoop.yarn.server.resourcemanager.scheduler.fair.FSAppAttempt: assignContainer(FSSchedulerNode node:cp-1.yarn-perf.yarnrm-PG0.wisc.cloudlab.us, boolean reserved=false) for appattempt_1471639269423_0006_000001
2016-08-19 14:47:34,280 INFO org.apache.hadoop.yarn.server.resourcemanager.scheduler.fair.FSAppAttempt: assignContainer(FSSchedulerNode node:cp-1.yarn-perf.yarnrm-PG0.wisc.cloudlab.us, boolean reserved=false) for appattempt_1471639269423_0007_000001
2016-08-19 14:47:34,763 INFO org.apache.hadoop.yarn.server.resourcemanager.rmapp.attempt.RMAppAttemptImpl: AMContainerAllocatedTransition.transition(appattempt_1471639269423_0005_000001,EventType: CONTAINER_ALLOCATED)
2016-08-19 14:47:34,763 INFO org.apache.hadoop.yarn.server.resourcemanager.scheduler.fair.FairScheduler: allocate(appattempt_1471639269423_0005_000001 [] [] null null
2016-08-19 14:47:34,763 INFO org.apache.hadoop.yarn.server.resourcemanager.scheduler.fair.FSAppAttempt: appattempt_1471639269423_0005_000001 minReqResource: <memory:24576, vCores:12> flexibleResource: <memory:-8192, vCores:-4>
2016-08-19 14:47:34,764 INFO org.apache.hadoop.yarn.server.resourcemanager.scheduler.fair.FairScheduler: Cannot allocate resource to appattempt_1471639269423_0005_000001 because there is NO flexible resource left
2016-08-19 14:47:34,779 INFO org.apache.hadoop.yarn.server.resourcemanager.rmapp.attempt.RMAppAttemptImpl: AMContainerAllocatedTransition.transition(appattempt_1471639269423_0004_000001,EventType: CONTAINER_ALLOCATED)
2016-08-19 14:47:34,779 INFO org.apache.hadoop.yarn.server.resourcemanager.scheduler.fair.FairScheduler: allocate(appattempt_1471639269423_0004_000001 [] [] null null
2016-08-19 14:47:34,779 INFO org.apache.hadoop.yarn.server.resourcemanager.scheduler.fair.FSAppAttempt: appattempt_1471639269423_0004_000001 minReqResource: <memory:24576, vCores:12> flexibleResource: <memory:-8192, vCores:-4>
2016-08-19 14:47:34,779 INFO org.apache.hadoop.yarn.server.resourcemanager.scheduler.fair.FairScheduler: Cannot allocate resource to appattempt_1471639269423_0004_000001 because there is NO flexible resource left
2016-08-19 14:47:35,243 INFO org.apache.hadoop.yarn.server.resourcemanager.scheduler.fair.FSAppAttempt: assignContainer(FSSchedulerNode node:c220g1-031106.wisc.cloudlab.us, boolean reserved=false) for appattempt_1471639269423_0003_000001
2016-08-19 14:47:35,243 INFO org.apache.hadoop.yarn.server.resourcemanager.scheduler.fair.FSAppAttempt: assignContainer(FSSchedulerNode node:c220g1-031106.wisc.cloudlab.us, boolean reserved=false) for appattempt_1471639269423_0005_000001
2016-08-19 14:47:35,243 INFO org.apache.hadoop.yarn.server.resourcemanager.scheduler.fair.FSAppAttempt: assignContainer(FSSchedulerNode node:c220g1-031106.wisc.cloudlab.us, boolean reserved=false) for appattempt_1471639269423_0004_000001
2016-08-19 14:47:35,244 INFO org.apache.hadoop.yarn.server.resourcemanager.scheduler.fair.FSAppAttempt: assignContainer(FSSchedulerNode node:c220g1-031106.wisc.cloudlab.us, boolean reserved=false) for appattempt_1471639269423_0006_000001
2016-08-19 14:47:35,244 INFO org.apache.hadoop.yarn.server.resourcemanager.scheduler.fair.FSAppAttempt: assignContainer(FSSchedulerNode node:c220g1-031106.wisc.cloudlab.us, boolean reserved=false) for appattempt_1471639269423_0007_000001
2016-08-19 14:47:35,265 INFO org.apache.hadoop.yarn.server.resourcemanager.rmapp.attempt.RMAppAttemptImpl: AMContainerAllocatedTransition.transition(appattempt_1471639269423_0005_000001,EventType: CONTAINER_ALLOCATED)
2016-08-19 14:47:35,265 INFO org.apache.hadoop.yarn.server.resourcemanager.scheduler.fair.FairScheduler: allocate(appattempt_1471639269423_0005_000001 [] [] null null
2016-08-19 14:47:35,265 INFO org.apache.hadoop.yarn.server.resourcemanager.scheduler.fair.FSAppAttempt: appattempt_1471639269423_0005_000001 minReqResource: <memory:24576, vCores:12> flexibleResource: <memory:-8192, vCores:-4>
2016-08-19 14:47:35,265 INFO org.apache.hadoop.yarn.server.resourcemanager.scheduler.fair.FairScheduler: Cannot allocate resource to appattempt_1471639269423_0005_000001 because there is NO flexible resource left
2016-08-19 14:47:35,280 INFO org.apache.hadoop.yarn.server.resourcemanager.rmapp.attempt.RMAppAttemptImpl: AMContainerAllocatedTransition.transition(appattempt_1471639269423_0004_000001,EventType: CONTAINER_ALLOCATED)
2016-08-19 14:47:35,280 INFO org.apache.hadoop.yarn.server.resourcemanager.scheduler.fair.FairScheduler: allocate(appattempt_1471639269423_0004_000001 [] [] null null
2016-08-19 14:47:35,280 INFO org.apache.hadoop.yarn.server.resourcemanager.scheduler.fair.FSAppAttempt: appattempt_1471639269423_0004_000001 minReqResource: <memory:24576, vCores:12> flexibleResource: <memory:-8192, vCores:-4>
2016-08-19 14:47:35,280 INFO org.apache.hadoop.yarn.server.resourcemanager.scheduler.fair.FairScheduler: Cannot allocate resource to appattempt_1471639269423_0004_000001 because there is NO flexible resource left
2016-08-19 14:47:35,281 INFO org.apache.hadoop.yarn.server.resourcemanager.scheduler.fair.FSAppAttempt: assignContainer(FSSchedulerNode node:cp-1.yarn-perf.yarnrm-PG0.wisc.cloudlab.us, boolean reserved=false) for appattempt_1471639269423_0003_000001
2016-08-19 14:47:35,282 INFO org.apache.hadoop.yarn.server.resourcemanager.scheduler.fair.FSAppAttempt: assignContainer(FSSchedulerNode node:cp-1.yarn-perf.yarnrm-PG0.wisc.cloudlab.us, boolean reserved=false) for appattempt_1471639269423_0005_000001
2016-08-19 14:47:35,282 INFO org.apache.hadoop.yarn.server.resourcemanager.scheduler.fair.FSAppAttempt: assignContainer(FSSchedulerNode node:cp-1.yarn-perf.yarnrm-PG0.wisc.cloudlab.us, boolean reserved=false) for appattempt_1471639269423_0004_000001
2016-08-19 14:47:35,282 INFO org.apache.hadoop.yarn.server.resourcemanager.scheduler.fair.FSAppAttempt: assignContainer(FSSchedulerNode node:cp-1.yarn-perf.yarnrm-PG0.wisc.cloudlab.us, boolean reserved=false) for appattempt_1471639269423_0006_000001
2016-08-19 14:47:35,282 INFO org.apache.hadoop.yarn.server.resourcemanager.scheduler.fair.FSAppAttempt: assignContainer(FSSchedulerNode node:cp-1.yarn-perf.yarnrm-PG0.wisc.cloudlab.us, boolean reserved=false) for appattempt_1471639269423_0007_000001
2016-08-19 14:47:35,767 INFO org.apache.hadoop.yarn.server.resourcemanager.rmapp.attempt.RMAppAttemptImpl: AMContainerAllocatedTransition.transition(appattempt_1471639269423_0005_000001,EventType: CONTAINER_ALLOCATED)
2016-08-19 14:47:35,767 INFO org.apache.hadoop.yarn.server.resourcemanager.scheduler.fair.FairScheduler: allocate(appattempt_1471639269423_0005_000001 [] [] null null
2016-08-19 14:47:35,767 INFO org.apache.hadoop.yarn.server.resourcemanager.scheduler.fair.FSAppAttempt: appattempt_1471639269423_0005_000001 minReqResource: <memory:24576, vCores:12> flexibleResource: <memory:-8192, vCores:-4>
2016-08-19 14:47:35,767 INFO org.apache.hadoop.yarn.server.resourcemanager.scheduler.fair.FairScheduler: Cannot allocate resource to appattempt_1471639269423_0005_000001 because there is NO flexible resource left
2016-08-19 14:47:35,781 INFO org.apache.hadoop.yarn.server.resourcemanager.rmapp.attempt.RMAppAttemptImpl: AMContainerAllocatedTransition.transition(appattempt_1471639269423_0004_000001,EventType: CONTAINER_ALLOCATED)
2016-08-19 14:47:35,781 INFO org.apache.hadoop.yarn.server.resourcemanager.scheduler.fair.FairScheduler: allocate(appattempt_1471639269423_0004_000001 [] [] null null
2016-08-19 14:47:35,781 INFO org.apache.hadoop.yarn.server.resourcemanager.scheduler.fair.FSAppAttempt: appattempt_1471639269423_0004_000001 minReqResource: <memory:24576, vCores:12> flexibleResource: <memory:-8192, vCores:-4>
2016-08-19 14:47:35,781 INFO org.apache.hadoop.yarn.server.resourcemanager.scheduler.fair.FairScheduler: Cannot allocate resource to appattempt_1471639269423_0004_000001 because there is NO flexible resource left
2016-08-19 14:47:36,246 INFO org.apache.hadoop.yarn.server.resourcemanager.scheduler.fair.FSAppAttempt: assignContainer(FSSchedulerNode node:c220g1-031106.wisc.cloudlab.us, boolean reserved=false) for appattempt_1471639269423_0003_000001
2016-08-19 14:47:36,246 INFO org.apache.hadoop.yarn.server.resourcemanager.scheduler.fair.FSAppAttempt: assignContainer(FSSchedulerNode node:c220g1-031106.wisc.cloudlab.us, boolean reserved=false) for appattempt_1471639269423_0005_000001
2016-08-19 14:47:36,246 INFO org.apache.hadoop.yarn.server.resourcemanager.scheduler.fair.FSAppAttempt: assignContainer(FSSchedulerNode node:c220g1-031106.wisc.cloudlab.us, boolean reserved=false) for appattempt_1471639269423_0004_000001
2016-08-19 14:47:36,246 INFO org.apache.hadoop.yarn.server.resourcemanager.scheduler.fair.FSAppAttempt: assignContainer(FSSchedulerNode node:c220g1-031106.wisc.cloudlab.us, boolean reserved=false) for appattempt_1471639269423_0006_000001
2016-08-19 14:47:36,247 INFO org.apache.hadoop.yarn.server.resourcemanager.scheduler.fair.FSAppAttempt: assignContainer(FSSchedulerNode node:c220g1-031106.wisc.cloudlab.us, boolean reserved=false) for appattempt_1471639269423_0007_000001
2016-08-19 14:47:36,268 INFO org.apache.hadoop.yarn.server.resourcemanager.rmapp.attempt.RMAppAttemptImpl: AMContainerAllocatedTransition.transition(appattempt_1471639269423_0005_000001,EventType: CONTAINER_ALLOCATED)
2016-08-19 14:47:36,269 INFO org.apache.hadoop.yarn.server.resourcemanager.scheduler.fair.FairScheduler: allocate(appattempt_1471639269423_0005_000001 [] [] null null
2016-08-19 14:47:36,269 INFO org.apache.hadoop.yarn.server.resourcemanager.scheduler.fair.FSAppAttempt: appattempt_1471639269423_0005_000001 minReqResource: <memory:24576, vCores:12> flexibleResource: <memory:-8192, vCores:-4>
2016-08-19 14:47:36,269 INFO org.apache.hadoop.yarn.server.resourcemanager.scheduler.fair.FairScheduler: Cannot allocate resource to appattempt_1471639269423_0005_000001 because there is NO flexible resource left
2016-08-19 14:47:36,282 INFO org.apache.hadoop.yarn.server.resourcemanager.rmapp.attempt.RMAppAttemptImpl: AMContainerAllocatedTransition.transition(appattempt_1471639269423_0004_000001,EventType: CONTAINER_ALLOCATED)
2016-08-19 14:47:36,282 INFO org.apache.hadoop.yarn.server.resourcemanager.scheduler.fair.FairScheduler: allocate(appattempt_1471639269423_0004_000001 [] [] null null
2016-08-19 14:47:36,282 INFO org.apache.hadoop.yarn.server.resourcemanager.scheduler.fair.FSAppAttempt: appattempt_1471639269423_0004_000001 minReqResource: <memory:24576, vCores:12> flexibleResource: <memory:-8192, vCores:-4>
2016-08-19 14:47:36,282 INFO org.apache.hadoop.yarn.server.resourcemanager.scheduler.fair.FairScheduler: Cannot allocate resource to appattempt_1471639269423_0004_000001 because there is NO flexible resource left
2016-08-19 14:47:36,284 INFO org.apache.hadoop.yarn.server.resourcemanager.scheduler.fair.FSAppAttempt: assignContainer(FSSchedulerNode node:cp-1.yarn-perf.yarnrm-PG0.wisc.cloudlab.us, boolean reserved=false) for appattempt_1471639269423_0003_000001
2016-08-19 14:47:36,284 INFO org.apache.hadoop.yarn.server.resourcemanager.scheduler.fair.FSAppAttempt: assignContainer(FSSchedulerNode node:cp-1.yarn-perf.yarnrm-PG0.wisc.cloudlab.us, boolean reserved=false) for appattempt_1471639269423_0005_000001
2016-08-19 14:47:36,284 INFO org.apache.hadoop.yarn.server.resourcemanager.scheduler.fair.FSAppAttempt: assignContainer(FSSchedulerNode node:cp-1.yarn-perf.yarnrm-PG0.wisc.cloudlab.us, boolean reserved=false) for appattempt_1471639269423_0004_000001
2016-08-19 14:47:36,284 INFO org.apache.hadoop.yarn.server.resourcemanager.scheduler.fair.FSAppAttempt: assignContainer(FSSchedulerNode node:cp-1.yarn-perf.yarnrm-PG0.wisc.cloudlab.us, boolean reserved=false) for appattempt_1471639269423_0006_000001
2016-08-19 14:47:36,284 INFO org.apache.hadoop.yarn.server.resourcemanager.scheduler.fair.FSAppAttempt: assignContainer(FSSchedulerNode node:cp-1.yarn-perf.yarnrm-PG0.wisc.cloudlab.us, boolean reserved=false) for appattempt_1471639269423_0007_000001
2016-08-19 14:47:36,770 INFO org.apache.hadoop.yarn.server.resourcemanager.rmapp.attempt.RMAppAttemptImpl: AMContainerAllocatedTransition.transition(appattempt_1471639269423_0005_000001,EventType: CONTAINER_ALLOCATED)
2016-08-19 14:47:36,770 INFO org.apache.hadoop.yarn.server.resourcemanager.scheduler.fair.FairScheduler: allocate(appattempt_1471639269423_0005_000001 [] [] null null
2016-08-19 14:47:36,770 INFO org.apache.hadoop.yarn.server.resourcemanager.scheduler.fair.FSAppAttempt: appattempt_1471639269423_0005_000001 minReqResource: <memory:24576, vCores:12> flexibleResource: <memory:-8192, vCores:-4>
2016-08-19 14:47:36,770 INFO org.apache.hadoop.yarn.server.resourcemanager.scheduler.fair.FairScheduler: Cannot allocate resource to appattempt_1471639269423_0005_000001 because there is NO flexible resource left
2016-08-19 14:47:36,783 INFO org.apache.hadoop.yarn.server.resourcemanager.rmapp.attempt.RMAppAttemptImpl: AMContainerAllocatedTransition.transition(appattempt_1471639269423_0004_000001,EventType: CONTAINER_ALLOCATED)
2016-08-19 14:47:36,783 INFO org.apache.hadoop.yarn.server.resourcemanager.scheduler.fair.FairScheduler: allocate(appattempt_1471639269423_0004_000001 [] [] null null
2016-08-19 14:47:36,783 INFO org.apache.hadoop.yarn.server.resourcemanager.scheduler.fair.FSAppAttempt: appattempt_1471639269423_0004_000001 minReqResource: <memory:24576, vCores:12> flexibleResource: <memory:-8192, vCores:-4>
2016-08-19 14:47:36,784 INFO org.apache.hadoop.yarn.server.resourcemanager.scheduler.fair.FairScheduler: Cannot allocate resource to appattempt_1471639269423_0004_000001 because there is NO flexible resource left
2016-08-19 14:47:37,249 INFO org.apache.hadoop.yarn.server.resourcemanager.scheduler.fair.FSAppAttempt: assignContainer(FSSchedulerNode node:c220g1-031106.wisc.cloudlab.us, boolean reserved=false) for appattempt_1471639269423_0003_000001
2016-08-19 14:47:37,249 INFO org.apache.hadoop.yarn.server.resourcemanager.scheduler.fair.FSAppAttempt: assignContainer(FSSchedulerNode node:c220g1-031106.wisc.cloudlab.us, boolean reserved=false) for appattempt_1471639269423_0005_000001
2016-08-19 14:47:37,250 INFO org.apache.hadoop.yarn.server.resourcemanager.scheduler.fair.FSAppAttempt: assignContainer(FSSchedulerNode node:c220g1-031106.wisc.cloudlab.us, boolean reserved=false) for appattempt_1471639269423_0004_000001
2016-08-19 14:47:37,250 INFO org.apache.hadoop.yarn.server.resourcemanager.scheduler.fair.FSAppAttempt: assignContainer(FSSchedulerNode node:c220g1-031106.wisc.cloudlab.us, boolean reserved=false) for appattempt_1471639269423_0006_000001
2016-08-19 14:47:37,250 INFO org.apache.hadoop.yarn.server.resourcemanager.scheduler.fair.FSAppAttempt: assignContainer(FSSchedulerNode node:c220g1-031106.wisc.cloudlab.us, boolean reserved=false) for appattempt_1471639269423_0007_000001
2016-08-19 14:47:37,272 INFO org.apache.hadoop.yarn.server.resourcemanager.rmapp.attempt.RMAppAttemptImpl: AMContainerAllocatedTransition.transition(appattempt_1471639269423_0005_000001,EventType: CONTAINER_ALLOCATED)
2016-08-19 14:47:37,272 INFO org.apache.hadoop.yarn.server.resourcemanager.scheduler.fair.FairScheduler: allocate(appattempt_1471639269423_0005_000001 [] [] null null
2016-08-19 14:47:37,272 INFO org.apache.hadoop.yarn.server.resourcemanager.scheduler.fair.FSAppAttempt: appattempt_1471639269423_0005_000001 minReqResource: <memory:24576, vCores:12> flexibleResource: <memory:-8192, vCores:-4>
2016-08-19 14:47:37,272 INFO org.apache.hadoop.yarn.server.resourcemanager.scheduler.fair.FairScheduler: Cannot allocate resource to appattempt_1471639269423_0005_000001 because there is NO flexible resource left
2016-08-19 14:47:37,286 INFO org.apache.hadoop.yarn.server.resourcemanager.rmapp.attempt.RMAppAttemptImpl: AMContainerAllocatedTransition.transition(appattempt_1471639269423_0004_000001,EventType: CONTAINER_ALLOCATED)
2016-08-19 14:47:37,286 INFO org.apache.hadoop.yarn.server.resourcemanager.scheduler.fair.FairScheduler: allocate(appattempt_1471639269423_0004_000001 [] [] null null
2016-08-19 14:47:37,286 INFO org.apache.hadoop.yarn.server.resourcemanager.scheduler.fair.FSAppAttempt: appattempt_1471639269423_0004_000001 minReqResource: <memory:24576, vCores:12> flexibleResource: <memory:-8192, vCores:-4>
2016-08-19 14:47:37,286 INFO org.apache.hadoop.yarn.server.resourcemanager.scheduler.fair.FairScheduler: Cannot allocate resource to appattempt_1471639269423_0004_000001 because there is NO flexible resource left
2016-08-19 14:47:37,287 INFO org.apache.hadoop.yarn.server.resourcemanager.scheduler.fair.FSAppAttempt: assignContainer(FSSchedulerNode node:cp-1.yarn-perf.yarnrm-PG0.wisc.cloudlab.us, boolean reserved=false) for appattempt_1471639269423_0003_000001
2016-08-19 14:47:37,287 INFO org.apache.hadoop.yarn.server.resourcemanager.scheduler.fair.FSAppAttempt: assignContainer(FSSchedulerNode node:cp-1.yarn-perf.yarnrm-PG0.wisc.cloudlab.us, boolean reserved=false) for appattempt_1471639269423_0005_000001
2016-08-19 14:47:37,287 INFO org.apache.hadoop.yarn.server.resourcemanager.scheduler.fair.FSAppAttempt: assignContainer(FSSchedulerNode node:cp-1.yarn-perf.yarnrm-PG0.wisc.cloudlab.us, boolean reserved=false) for appattempt_1471639269423_0004_000001
2016-08-19 14:47:37,288 INFO org.apache.hadoop.yarn.server.resourcemanager.scheduler.fair.FSAppAttempt: assignContainer(FSSchedulerNode node:cp-1.yarn-perf.yarnrm-PG0.wisc.cloudlab.us, boolean reserved=false) for appattempt_1471639269423_0006_000001
2016-08-19 14:47:37,288 INFO org.apache.hadoop.yarn.server.resourcemanager.scheduler.fair.FSAppAttempt: assignContainer(FSSchedulerNode node:cp-1.yarn-perf.yarnrm-PG0.wisc.cloudlab.us, boolean reserved=false) for appattempt_1471639269423_0007_000001
2016-08-19 14:47:37,773 INFO org.apache.hadoop.yarn.server.resourcemanager.rmapp.attempt.RMAppAttemptImpl: AMContainerAllocatedTransition.transition(appattempt_1471639269423_0005_000001,EventType: CONTAINER_ALLOCATED)
2016-08-19 14:47:37,773 INFO org.apache.hadoop.yarn.server.resourcemanager.scheduler.fair.FairScheduler: allocate(appattempt_1471639269423_0005_000001 [] [] null null
2016-08-19 14:47:37,773 INFO org.apache.hadoop.yarn.server.resourcemanager.scheduler.fair.FSAppAttempt: appattempt_1471639269423_0005_000001 minReqResource: <memory:24576, vCores:12> flexibleResource: <memory:-8192, vCores:-4>
2016-08-19 14:47:37,773 INFO org.apache.hadoop.yarn.server.resourcemanager.scheduler.fair.FairScheduler: Cannot allocate resource to appattempt_1471639269423_0005_000001 because there is NO flexible resource left
2016-08-19 14:47:37,788 INFO org.apache.hadoop.yarn.server.resourcemanager.rmapp.attempt.RMAppAttemptImpl: AMContainerAllocatedTransition.transition(appattempt_1471639269423_0004_000001,EventType: CONTAINER_ALLOCATED)
2016-08-19 14:47:37,788 INFO org.apache.hadoop.yarn.server.resourcemanager.scheduler.fair.FairScheduler: allocate(appattempt_1471639269423_0004_000001 [] [] null null
2016-08-19 14:47:37,788 INFO org.apache.hadoop.yarn.server.resourcemanager.scheduler.fair.FSAppAttempt: appattempt_1471639269423_0004_000001 minReqResource: <memory:24576, vCores:12> flexibleResource: <memory:-8192, vCores:-4>
2016-08-19 14:47:37,788 INFO org.apache.hadoop.yarn.server.resourcemanager.scheduler.fair.FairScheduler: Cannot allocate resource to appattempt_1471639269423_0004_000001 because there is NO flexible resource left
2016-08-19 14:47:38,252 INFO org.apache.hadoop.yarn.server.resourcemanager.scheduler.fair.FSAppAttempt: assignContainer(FSSchedulerNode node:c220g1-031106.wisc.cloudlab.us, boolean reserved=false) for appattempt_1471639269423_0003_000001
2016-08-19 14:47:38,252 INFO org.apache.hadoop.yarn.server.resourcemanager.scheduler.fair.FSAppAttempt: assignContainer(FSSchedulerNode node:c220g1-031106.wisc.cloudlab.us, boolean reserved=false) for appattempt_1471639269423_0005_000001
2016-08-19 14:47:38,252 INFO org.apache.hadoop.yarn.server.resourcemanager.scheduler.fair.FSAppAttempt: assignContainer(FSSchedulerNode node:c220g1-031106.wisc.cloudlab.us, boolean reserved=false) for appattempt_1471639269423_0004_000001
2016-08-19 14:47:38,252 INFO org.apache.hadoop.yarn.server.resourcemanager.scheduler.fair.FSAppAttempt: assignContainer(FSSchedulerNode node:c220g1-031106.wisc.cloudlab.us, boolean reserved=false) for appattempt_1471639269423_0006_000001
2016-08-19 14:47:38,253 INFO org.apache.hadoop.yarn.server.resourcemanager.scheduler.fair.FSAppAttempt: assignContainer(FSSchedulerNode node:c220g1-031106.wisc.cloudlab.us, boolean reserved=false) for appattempt_1471639269423_0007_000001
2016-08-19 14:47:38,274 INFO org.apache.hadoop.yarn.server.resourcemanager.rmapp.attempt.RMAppAttemptImpl: AMContainerAllocatedTransition.transition(appattempt_1471639269423_0005_000001,EventType: CONTAINER_ALLOCATED)
2016-08-19 14:47:38,274 INFO org.apache.hadoop.yarn.server.resourcemanager.scheduler.fair.FairScheduler: allocate(appattempt_1471639269423_0005_000001 [] [] null null
2016-08-19 14:47:38,274 INFO org.apache.hadoop.yarn.server.resourcemanager.scheduler.fair.FSAppAttempt: appattempt_1471639269423_0005_000001 minReqResource: <memory:24576, vCores:12> flexibleResource: <memory:-8192, vCores:-4>
2016-08-19 14:47:38,274 INFO org.apache.hadoop.yarn.server.resourcemanager.scheduler.fair.FairScheduler: Cannot allocate resource to appattempt_1471639269423_0005_000001 because there is NO flexible resource left
2016-08-19 14:47:38,289 INFO org.apache.hadoop.yarn.server.resourcemanager.rmapp.attempt.RMAppAttemptImpl: AMContainerAllocatedTransition.transition(appattempt_1471639269423_0004_000001,EventType: CONTAINER_ALLOCATED)
2016-08-19 14:47:38,289 INFO org.apache.hadoop.yarn.server.resourcemanager.scheduler.fair.FairScheduler: allocate(appattempt_1471639269423_0004_000001 [] [] null null
2016-08-19 14:47:38,289 INFO org.apache.hadoop.yarn.server.resourcemanager.scheduler.fair.FSAppAttempt: appattempt_1471639269423_0004_000001 minReqResource: <memory:24576, vCores:12> flexibleResource: <memory:-8192, vCores:-4>
2016-08-19 14:47:38,290 INFO org.apache.hadoop.yarn.server.resourcemanager.scheduler.fair.FairScheduler: Cannot allocate resource to appattempt_1471639269423_0004_000001 because there is NO flexible resource left
2016-08-19 14:47:38,290 INFO org.apache.hadoop.yarn.server.resourcemanager.scheduler.fair.FSAppAttempt: assignContainer(FSSchedulerNode node:cp-1.yarn-perf.yarnrm-PG0.wisc.cloudlab.us, boolean reserved=false) for appattempt_1471639269423_0003_000001
2016-08-19 14:47:38,290 INFO org.apache.hadoop.yarn.server.resourcemanager.scheduler.fair.FSAppAttempt: assignContainer(FSSchedulerNode node:cp-1.yarn-perf.yarnrm-PG0.wisc.cloudlab.us, boolean reserved=false) for appattempt_1471639269423_0005_000001
2016-08-19 14:47:38,291 INFO org.apache.hadoop.yarn.server.resourcemanager.scheduler.fair.FSAppAttempt: assignContainer(FSSchedulerNode node:cp-1.yarn-perf.yarnrm-PG0.wisc.cloudlab.us, boolean reserved=false) for appattempt_1471639269423_0004_000001
2016-08-19 14:47:38,291 INFO org.apache.hadoop.yarn.server.resourcemanager.scheduler.fair.FSAppAttempt: assignContainer(FSSchedulerNode node:cp-1.yarn-perf.yarnrm-PG0.wisc.cloudlab.us, boolean reserved=false) for appattempt_1471639269423_0006_000001
2016-08-19 14:47:38,291 INFO org.apache.hadoop.yarn.server.resourcemanager.scheduler.fair.FSAppAttempt: assignContainer(FSSchedulerNode node:cp-1.yarn-perf.yarnrm-PG0.wisc.cloudlab.us, boolean reserved=false) for appattempt_1471639269423_0007_000001
2016-08-19 14:47:38,650 INFO SecurityLogger.org.apache.hadoop.ipc.Server: Auth successful for appattempt_1471639269423_0003_000001 (auth:SIMPLE)
2016-08-19 14:47:38,653 INFO org.apache.hadoop.yarn.server.resourcemanager.ApplicationMasterService: AM registration appattempt_1471639269423_0003_000001
2016-08-19 14:47:38,686 INFO org.apache.hadoop.yarn.server.resourcemanager.RMAuditLogger: USER=tanle	IP=128.104.222.16	OPERATION=Register App Master	TARGET=ApplicationMasterService	RESULT=SUCCESS	APPID=application_1471639269423_0003	APPATTEMPTID=appattempt_1471639269423_0003_000001
2016-08-19 14:47:38,686 INFO org.apache.hadoop.yarn.server.resourcemanager.rmapp.attempt.RMAppAttemptImpl: appattempt_1471639269423_0003_000001 State change from LAUNCHED to RUNNING
2016-08-19 14:47:38,686 INFO org.apache.hadoop.yarn.server.resourcemanager.rmapp.RMAppImpl: application_1471639269423_0003 State change from ACCEPTED to RUNNING
2016-08-19 14:47:38,754 INFO org.apache.hadoop.yarn.server.resourcemanager.scheduler.fair.FairScheduler: allocate(appattempt_1471639269423_0003_000001 [] [] [] []
2016-08-19 14:47:38,754 INFO org.apache.hadoop.yarn.server.resourcemanager.scheduler.fair.FSAppAttempt: appattempt_1471639269423_0003_000001 minReqResource: <memory:24576, vCores:12> flexibleResource: <memory:-8192, vCores:-4>
2016-08-19 14:47:38,754 INFO org.apache.hadoop.yarn.server.resourcemanager.scheduler.fair.FairScheduler: Cannot allocate resource to appattempt_1471639269423_0003_000001 because there is NO flexible resource left
2016-08-19 14:47:38,775 INFO org.apache.hadoop.yarn.server.resourcemanager.rmapp.attempt.RMAppAttemptImpl: AMContainerAllocatedTransition.transition(appattempt_1471639269423_0005_000001,EventType: CONTAINER_ALLOCATED)
2016-08-19 14:47:38,775 INFO org.apache.hadoop.yarn.server.resourcemanager.scheduler.fair.FairScheduler: allocate(appattempt_1471639269423_0005_000001 [] [] null null
2016-08-19 14:47:38,775 INFO org.apache.hadoop.yarn.server.resourcemanager.scheduler.fair.FSAppAttempt: appattempt_1471639269423_0005_000001 minReqResource: <memory:24576, vCores:12> flexibleResource: <memory:-8192, vCores:-4>
2016-08-19 14:47:38,775 INFO org.apache.hadoop.yarn.server.resourcemanager.scheduler.fair.FairScheduler: Cannot allocate resource to appattempt_1471639269423_0005_000001 because there is NO flexible resource left
2016-08-19 14:47:38,787 INFO org.apache.hadoop.yarn.server.resourcemanager.scheduler.fair.FairScheduler: allocate(appattempt_1471639269423_0003_000001 [] [] [] []
2016-08-19 14:47:38,787 INFO org.apache.hadoop.yarn.server.resourcemanager.scheduler.fair.FSAppAttempt: appattempt_1471639269423_0003_000001 minReqResource: <memory:24576, vCores:12> flexibleResource: <memory:-8192, vCores:-4>
2016-08-19 14:47:38,787 INFO org.apache.hadoop.yarn.server.resourcemanager.scheduler.fair.FairScheduler: Cannot allocate resource to appattempt_1471639269423_0003_000001 because there is NO flexible resource left
2016-08-19 14:47:38,791 INFO org.apache.hadoop.yarn.server.resourcemanager.rmapp.attempt.RMAppAttemptImpl: AMContainerAllocatedTransition.transition(appattempt_1471639269423_0004_000001,EventType: CONTAINER_ALLOCATED)
2016-08-19 14:47:38,791 INFO org.apache.hadoop.yarn.server.resourcemanager.scheduler.fair.FairScheduler: allocate(appattempt_1471639269423_0004_000001 [] [] null null
2016-08-19 14:47:38,791 INFO org.apache.hadoop.yarn.server.resourcemanager.scheduler.fair.FSAppAttempt: appattempt_1471639269423_0004_000001 minReqResource: <memory:24576, vCores:12> flexibleResource: <memory:-8192, vCores:-4>
2016-08-19 14:47:38,791 INFO org.apache.hadoop.yarn.server.resourcemanager.scheduler.fair.FairScheduler: Cannot allocate resource to appattempt_1471639269423_0004_000001 because there is NO flexible resource left
2016-08-19 14:47:39,255 INFO org.apache.hadoop.yarn.server.resourcemanager.scheduler.fair.FSAppAttempt: assignContainer(FSSchedulerNode node:c220g1-031106.wisc.cloudlab.us, boolean reserved=false) for appattempt_1471639269423_0003_000001
2016-08-19 14:47:39,255 INFO org.apache.hadoop.yarn.server.resourcemanager.scheduler.fair.FSAppAttempt: assignContainer(FSSchedulerNode node:c220g1-031106.wisc.cloudlab.us, boolean reserved=false) for appattempt_1471639269423_0005_000001
2016-08-19 14:47:39,256 INFO org.apache.hadoop.yarn.server.resourcemanager.scheduler.fair.FSAppAttempt: assignContainer(FSSchedulerNode node:c220g1-031106.wisc.cloudlab.us, boolean reserved=false) for appattempt_1471639269423_0004_000001
2016-08-19 14:47:39,256 INFO org.apache.hadoop.yarn.server.resourcemanager.scheduler.fair.FSAppAttempt: assignContainer(FSSchedulerNode node:c220g1-031106.wisc.cloudlab.us, boolean reserved=false) for appattempt_1471639269423_0006_000001
2016-08-19 14:47:39,256 INFO org.apache.hadoop.yarn.server.resourcemanager.scheduler.fair.FSAppAttempt: assignContainer(FSSchedulerNode node:c220g1-031106.wisc.cloudlab.us, boolean reserved=false) for appattempt_1471639269423_0007_000001
2016-08-19 14:47:39,276 INFO org.apache.hadoop.yarn.server.resourcemanager.rmapp.attempt.RMAppAttemptImpl: AMContainerAllocatedTransition.transition(appattempt_1471639269423_0005_000001,EventType: CONTAINER_ALLOCATED)
2016-08-19 14:47:39,277 INFO org.apache.hadoop.yarn.server.resourcemanager.scheduler.fair.FairScheduler: allocate(appattempt_1471639269423_0005_000001 [] [] null null
2016-08-19 14:47:39,277 INFO org.apache.hadoop.yarn.server.resourcemanager.scheduler.fair.FSAppAttempt: appattempt_1471639269423_0005_000001 minReqResource: <memory:24576, vCores:12> flexibleResource: <memory:-8192, vCores:-4>
2016-08-19 14:47:39,277 INFO org.apache.hadoop.yarn.server.resourcemanager.scheduler.fair.FairScheduler: Cannot allocate resource to appattempt_1471639269423_0005_000001 because there is NO flexible resource left
2016-08-19 14:47:39,292 INFO org.apache.hadoop.yarn.server.resourcemanager.rmapp.attempt.RMAppAttemptImpl: AMContainerAllocatedTransition.transition(appattempt_1471639269423_0004_000001,EventType: CONTAINER_ALLOCATED)
2016-08-19 14:47:39,292 INFO org.apache.hadoop.yarn.server.resourcemanager.scheduler.fair.FairScheduler: allocate(appattempt_1471639269423_0004_000001 [] [] null null
2016-08-19 14:47:39,293 INFO org.apache.hadoop.yarn.server.resourcemanager.scheduler.fair.FSAppAttempt: appattempt_1471639269423_0004_000001 minReqResource: <memory:24576, vCores:12> flexibleResource: <memory:-8192, vCores:-4>
2016-08-19 14:47:39,293 INFO org.apache.hadoop.yarn.server.resourcemanager.scheduler.fair.FairScheduler: Cannot allocate resource to appattempt_1471639269423_0004_000001 because there is NO flexible resource left
2016-08-19 14:47:39,293 INFO org.apache.hadoop.yarn.server.resourcemanager.scheduler.fair.FSAppAttempt: assignContainer(FSSchedulerNode node:cp-1.yarn-perf.yarnrm-PG0.wisc.cloudlab.us, boolean reserved=false) for appattempt_1471639269423_0003_000001
2016-08-19 14:47:39,293 INFO org.apache.hadoop.yarn.server.resourcemanager.scheduler.fair.FSAppAttempt: assignContainer(FSSchedulerNode node:cp-1.yarn-perf.yarnrm-PG0.wisc.cloudlab.us, boolean reserved=false) for appattempt_1471639269423_0005_000001
2016-08-19 14:47:39,294 INFO org.apache.hadoop.yarn.server.resourcemanager.scheduler.fair.FSAppAttempt: assignContainer(FSSchedulerNode node:cp-1.yarn-perf.yarnrm-PG0.wisc.cloudlab.us, boolean reserved=false) for appattempt_1471639269423_0004_000001
2016-08-19 14:47:39,294 INFO org.apache.hadoop.yarn.server.resourcemanager.scheduler.fair.FSAppAttempt: assignContainer(FSSchedulerNode node:cp-1.yarn-perf.yarnrm-PG0.wisc.cloudlab.us, boolean reserved=false) for appattempt_1471639269423_0006_000001
2016-08-19 14:47:39,294 INFO org.apache.hadoop.yarn.server.resourcemanager.scheduler.fair.FSAppAttempt: assignContainer(FSSchedulerNode node:cp-1.yarn-perf.yarnrm-PG0.wisc.cloudlab.us, boolean reserved=false) for appattempt_1471639269423_0007_000001
2016-08-19 14:47:39,778 INFO org.apache.hadoop.yarn.server.resourcemanager.rmapp.attempt.RMAppAttemptImpl: AMContainerAllocatedTransition.transition(appattempt_1471639269423_0005_000001,EventType: CONTAINER_ALLOCATED)
2016-08-19 14:47:39,778 INFO org.apache.hadoop.yarn.server.resourcemanager.scheduler.fair.FairScheduler: allocate(appattempt_1471639269423_0005_000001 [] [] null null
2016-08-19 14:47:39,778 INFO org.apache.hadoop.yarn.server.resourcemanager.scheduler.fair.FSAppAttempt: appattempt_1471639269423_0005_000001 minReqResource: <memory:24576, vCores:12> flexibleResource: <memory:-8192, vCores:-4>
2016-08-19 14:47:39,778 INFO org.apache.hadoop.yarn.server.resourcemanager.scheduler.fair.FairScheduler: Cannot allocate resource to appattempt_1471639269423_0005_000001 because there is NO flexible resource left
2016-08-19 14:47:39,794 INFO org.apache.hadoop.yarn.server.resourcemanager.rmapp.attempt.RMAppAttemptImpl: AMContainerAllocatedTransition.transition(appattempt_1471639269423_0004_000001,EventType: CONTAINER_ALLOCATED)
2016-08-19 14:47:39,794 INFO org.apache.hadoop.yarn.server.resourcemanager.scheduler.fair.FairScheduler: allocate(appattempt_1471639269423_0004_000001 [] [] null null
2016-08-19 14:47:39,794 INFO org.apache.hadoop.yarn.server.resourcemanager.scheduler.fair.FSAppAttempt: appattempt_1471639269423_0004_000001 minReqResource: <memory:24576, vCores:12> flexibleResource: <memory:-8192, vCores:-4>
2016-08-19 14:47:39,794 INFO org.apache.hadoop.yarn.server.resourcemanager.scheduler.fair.FairScheduler: Cannot allocate resource to appattempt_1471639269423_0004_000001 because there is NO flexible resource left
2016-08-19 14:47:40,258 INFO org.apache.hadoop.yarn.server.resourcemanager.scheduler.fair.FSAppAttempt: assignContainer(FSSchedulerNode node:c220g1-031106.wisc.cloudlab.us, boolean reserved=false) for appattempt_1471639269423_0003_000001
2016-08-19 14:47:40,258 INFO org.apache.hadoop.yarn.server.resourcemanager.scheduler.fair.FSAppAttempt: assignContainer(FSSchedulerNode node:c220g1-031106.wisc.cloudlab.us, boolean reserved=false) for appattempt_1471639269423_0005_000001
2016-08-19 14:47:40,258 INFO org.apache.hadoop.yarn.server.resourcemanager.scheduler.fair.FSAppAttempt: assignContainer(FSSchedulerNode node:c220g1-031106.wisc.cloudlab.us, boolean reserved=false) for appattempt_1471639269423_0004_000001
2016-08-19 14:47:40,259 INFO org.apache.hadoop.yarn.server.resourcemanager.scheduler.fair.FSAppAttempt: assignContainer(FSSchedulerNode node:c220g1-031106.wisc.cloudlab.us, boolean reserved=false) for appattempt_1471639269423_0006_000001
2016-08-19 14:47:40,259 INFO org.apache.hadoop.yarn.server.resourcemanager.scheduler.fair.FSAppAttempt: assignContainer(FSSchedulerNode node:c220g1-031106.wisc.cloudlab.us, boolean reserved=false) for appattempt_1471639269423_0007_000001
2016-08-19 14:47:40,279 INFO org.apache.hadoop.yarn.server.resourcemanager.rmapp.attempt.RMAppAttemptImpl: AMContainerAllocatedTransition.transition(appattempt_1471639269423_0005_000001,EventType: CONTAINER_ALLOCATED)
2016-08-19 14:47:40,279 INFO org.apache.hadoop.yarn.server.resourcemanager.scheduler.fair.FairScheduler: allocate(appattempt_1471639269423_0005_000001 [] [] null null
2016-08-19 14:47:40,279 INFO org.apache.hadoop.yarn.server.resourcemanager.scheduler.fair.FSAppAttempt: appattempt_1471639269423_0005_000001 minReqResource: <memory:24576, vCores:12> flexibleResource: <memory:-8192, vCores:-4>
2016-08-19 14:47:40,279 INFO org.apache.hadoop.yarn.server.resourcemanager.scheduler.fair.FairScheduler: Cannot allocate resource to appattempt_1471639269423_0005_000001 because there is NO flexible resource left
2016-08-19 14:47:40,295 INFO org.apache.hadoop.yarn.server.resourcemanager.rmapp.attempt.RMAppAttemptImpl: AMContainerAllocatedTransition.transition(appattempt_1471639269423_0004_000001,EventType: CONTAINER_ALLOCATED)
2016-08-19 14:47:40,295 INFO org.apache.hadoop.yarn.server.resourcemanager.scheduler.fair.FairScheduler: allocate(appattempt_1471639269423_0004_000001 [] [] null null
2016-08-19 14:47:40,295 INFO org.apache.hadoop.yarn.server.resourcemanager.scheduler.fair.FSAppAttempt: appattempt_1471639269423_0004_000001 minReqResource: <memory:24576, vCores:12> flexibleResource: <memory:-8192, vCores:-4>
2016-08-19 14:47:40,295 INFO org.apache.hadoop.yarn.server.resourcemanager.scheduler.fair.FairScheduler: Cannot allocate resource to appattempt_1471639269423_0004_000001 because there is NO flexible resource left
2016-08-19 14:47:40,296 INFO org.apache.hadoop.yarn.server.resourcemanager.scheduler.fair.FSAppAttempt: assignContainer(FSSchedulerNode node:cp-1.yarn-perf.yarnrm-PG0.wisc.cloudlab.us, boolean reserved=false) for appattempt_1471639269423_0003_000001
2016-08-19 14:47:40,296 INFO org.apache.hadoop.yarn.server.resourcemanager.scheduler.fair.FSAppAttempt: assignContainer(FSSchedulerNode node:cp-1.yarn-perf.yarnrm-PG0.wisc.cloudlab.us, boolean reserved=false) for appattempt_1471639269423_0005_000001
2016-08-19 14:47:40,296 INFO org.apache.hadoop.yarn.server.resourcemanager.scheduler.fair.FSAppAttempt: assignContainer(FSSchedulerNode node:cp-1.yarn-perf.yarnrm-PG0.wisc.cloudlab.us, boolean reserved=false) for appattempt_1471639269423_0004_000001
2016-08-19 14:47:40,297 INFO org.apache.hadoop.yarn.server.resourcemanager.scheduler.fair.FSAppAttempt: assignContainer(FSSchedulerNode node:cp-1.yarn-perf.yarnrm-PG0.wisc.cloudlab.us, boolean reserved=false) for appattempt_1471639269423_0006_000001
2016-08-19 14:47:40,297 INFO org.apache.hadoop.yarn.server.resourcemanager.scheduler.fair.FSAppAttempt: assignContainer(FSSchedulerNode node:cp-1.yarn-perf.yarnrm-PG0.wisc.cloudlab.us, boolean reserved=false) for appattempt_1471639269423_0007_000001
2016-08-19 14:47:40,780 INFO org.apache.hadoop.yarn.server.resourcemanager.rmapp.attempt.RMAppAttemptImpl: AMContainerAllocatedTransition.transition(appattempt_1471639269423_0005_000001,EventType: CONTAINER_ALLOCATED)
2016-08-19 14:47:40,780 INFO org.apache.hadoop.yarn.server.resourcemanager.scheduler.fair.FairScheduler: allocate(appattempt_1471639269423_0005_000001 [] [] null null
2016-08-19 14:47:40,781 INFO org.apache.hadoop.yarn.server.resourcemanager.scheduler.fair.FSAppAttempt: appattempt_1471639269423_0005_000001 minReqResource: <memory:24576, vCores:12> flexibleResource: <memory:-8192, vCores:-4>
2016-08-19 14:47:40,781 INFO org.apache.hadoop.yarn.server.resourcemanager.scheduler.fair.FairScheduler: Cannot allocate resource to appattempt_1471639269423_0005_000001 because there is NO flexible resource left
2016-08-19 14:47:40,796 INFO org.apache.hadoop.yarn.server.resourcemanager.rmapp.attempt.RMAppAttemptImpl: AMContainerAllocatedTransition.transition(appattempt_1471639269423_0004_000001,EventType: CONTAINER_ALLOCATED)
2016-08-19 14:47:40,796 INFO org.apache.hadoop.yarn.server.resourcemanager.scheduler.fair.FairScheduler: allocate(appattempt_1471639269423_0004_000001 [] [] null null
2016-08-19 14:47:40,797 INFO org.apache.hadoop.yarn.server.resourcemanager.scheduler.fair.FSAppAttempt: appattempt_1471639269423_0004_000001 minReqResource: <memory:24576, vCores:12> flexibleResource: <memory:-8192, vCores:-4>
2016-08-19 14:47:40,797 INFO org.apache.hadoop.yarn.server.resourcemanager.scheduler.fair.FairScheduler: Cannot allocate resource to appattempt_1471639269423_0004_000001 because there is NO flexible resource left
2016-08-19 14:47:41,261 INFO org.apache.hadoop.yarn.server.resourcemanager.scheduler.fair.FSAppAttempt: assignContainer(FSSchedulerNode node:c220g1-031106.wisc.cloudlab.us, boolean reserved=false) for appattempt_1471639269423_0003_000001
2016-08-19 14:47:41,262 INFO org.apache.hadoop.yarn.server.resourcemanager.scheduler.fair.FSAppAttempt: assignContainer(FSSchedulerNode node:c220g1-031106.wisc.cloudlab.us, boolean reserved=false) for appattempt_1471639269423_0005_000001
2016-08-19 14:47:41,262 INFO org.apache.hadoop.yarn.server.resourcemanager.scheduler.fair.FSAppAttempt: assignContainer(FSSchedulerNode node:c220g1-031106.wisc.cloudlab.us, boolean reserved=false) for appattempt_1471639269423_0004_000001
2016-08-19 14:47:41,262 INFO org.apache.hadoop.yarn.server.resourcemanager.scheduler.fair.FSAppAttempt: assignContainer(FSSchedulerNode node:c220g1-031106.wisc.cloudlab.us, boolean reserved=false) for appattempt_1471639269423_0006_000001
2016-08-19 14:47:41,262 INFO org.apache.hadoop.yarn.server.resourcemanager.scheduler.fair.FSAppAttempt: assignContainer(FSSchedulerNode node:c220g1-031106.wisc.cloudlab.us, boolean reserved=false) for appattempt_1471639269423_0007_000001
2016-08-19 14:47:41,282 INFO org.apache.hadoop.yarn.server.resourcemanager.rmapp.attempt.RMAppAttemptImpl: AMContainerAllocatedTransition.transition(appattempt_1471639269423_0005_000001,EventType: CONTAINER_ALLOCATED)
2016-08-19 14:47:41,282 INFO org.apache.hadoop.yarn.server.resourcemanager.scheduler.fair.FairScheduler: allocate(appattempt_1471639269423_0005_000001 [] [] null null
2016-08-19 14:47:41,282 INFO org.apache.hadoop.yarn.server.resourcemanager.scheduler.fair.FSAppAttempt: appattempt_1471639269423_0005_000001 minReqResource: <memory:24576, vCores:12> flexibleResource: <memory:-8192, vCores:-4>
2016-08-19 14:47:41,282 INFO org.apache.hadoop.yarn.server.resourcemanager.scheduler.fair.FairScheduler: Cannot allocate resource to appattempt_1471639269423_0005_000001 because there is NO flexible resource left
2016-08-19 14:47:41,298 INFO org.apache.hadoop.yarn.server.resourcemanager.rmapp.attempt.RMAppAttemptImpl: AMContainerAllocatedTransition.transition(appattempt_1471639269423_0004_000001,EventType: CONTAINER_ALLOCATED)
2016-08-19 14:47:41,298 INFO org.apache.hadoop.yarn.server.resourcemanager.scheduler.fair.FairScheduler: allocate(appattempt_1471639269423_0004_000001 [] [] null null
2016-08-19 14:47:41,298 INFO org.apache.hadoop.yarn.server.resourcemanager.scheduler.fair.FSAppAttempt: appattempt_1471639269423_0004_000001 minReqResource: <memory:24576, vCores:12> flexibleResource: <memory:-8192, vCores:-4>
2016-08-19 14:47:41,298 INFO org.apache.hadoop.yarn.server.resourcemanager.scheduler.fair.FairScheduler: Cannot allocate resource to appattempt_1471639269423_0004_000001 because there is NO flexible resource left
2016-08-19 14:47:41,299 INFO org.apache.hadoop.yarn.server.resourcemanager.scheduler.fair.FSAppAttempt: assignContainer(FSSchedulerNode node:cp-1.yarn-perf.yarnrm-PG0.wisc.cloudlab.us, boolean reserved=false) for appattempt_1471639269423_0003_000001
2016-08-19 14:47:41,299 INFO org.apache.hadoop.yarn.server.resourcemanager.scheduler.fair.FSAppAttempt: assignContainer(FSSchedulerNode node:cp-1.yarn-perf.yarnrm-PG0.wisc.cloudlab.us, boolean reserved=false) for appattempt_1471639269423_0005_000001
2016-08-19 14:47:41,300 INFO org.apache.hadoop.yarn.server.resourcemanager.scheduler.fair.FSAppAttempt: assignContainer(FSSchedulerNode node:cp-1.yarn-perf.yarnrm-PG0.wisc.cloudlab.us, boolean reserved=false) for appattempt_1471639269423_0004_000001
2016-08-19 14:47:41,300 INFO org.apache.hadoop.yarn.server.resourcemanager.scheduler.fair.FSAppAttempt: assignContainer(FSSchedulerNode node:cp-1.yarn-perf.yarnrm-PG0.wisc.cloudlab.us, boolean reserved=false) for appattempt_1471639269423_0006_000001
2016-08-19 14:47:41,300 INFO org.apache.hadoop.yarn.server.resourcemanager.scheduler.fair.FSAppAttempt: assignContainer(FSSchedulerNode node:cp-1.yarn-perf.yarnrm-PG0.wisc.cloudlab.us, boolean reserved=false) for appattempt_1471639269423_0007_000001
2016-08-19 14:47:41,783 INFO org.apache.hadoop.yarn.server.resourcemanager.rmapp.attempt.RMAppAttemptImpl: AMContainerAllocatedTransition.transition(appattempt_1471639269423_0005_000001,EventType: CONTAINER_ALLOCATED)
2016-08-19 14:47:41,784 INFO org.apache.hadoop.yarn.server.resourcemanager.scheduler.fair.FairScheduler: allocate(appattempt_1471639269423_0005_000001 [] [] null null
2016-08-19 14:47:41,784 INFO org.apache.hadoop.yarn.server.resourcemanager.scheduler.fair.FSAppAttempt: appattempt_1471639269423_0005_000001 minReqResource: <memory:24576, vCores:12> flexibleResource: <memory:-8192, vCores:-4>
2016-08-19 14:47:41,784 INFO org.apache.hadoop.yarn.server.resourcemanager.scheduler.fair.FairScheduler: Cannot allocate resource to appattempt_1471639269423_0005_000001 because there is NO flexible resource left
2016-08-19 14:47:41,791 INFO org.apache.hadoop.yarn.server.resourcemanager.scheduler.fair.FairScheduler: allocate(appattempt_1471639269423_0003_000001 [] [] [] []
2016-08-19 14:47:41,791 INFO org.apache.hadoop.yarn.server.resourcemanager.scheduler.fair.FSAppAttempt: appattempt_1471639269423_0003_000001 minReqResource: <memory:24576, vCores:12> flexibleResource: <memory:-8192, vCores:-4>
2016-08-19 14:47:41,791 INFO org.apache.hadoop.yarn.server.resourcemanager.scheduler.fair.FairScheduler: Cannot allocate resource to appattempt_1471639269423_0003_000001 because there is NO flexible resource left
2016-08-19 14:47:41,799 INFO org.apache.hadoop.yarn.server.resourcemanager.rmapp.attempt.RMAppAttemptImpl: AMContainerAllocatedTransition.transition(appattempt_1471639269423_0004_000001,EventType: CONTAINER_ALLOCATED)
2016-08-19 14:47:41,800 INFO org.apache.hadoop.yarn.server.resourcemanager.scheduler.fair.FairScheduler: allocate(appattempt_1471639269423_0004_000001 [] [] null null
2016-08-19 14:47:41,800 INFO org.apache.hadoop.yarn.server.resourcemanager.scheduler.fair.FSAppAttempt: appattempt_1471639269423_0004_000001 minReqResource: <memory:24576, vCores:12> flexibleResource: <memory:-8192, vCores:-4>
2016-08-19 14:47:41,800 INFO org.apache.hadoop.yarn.server.resourcemanager.scheduler.fair.FairScheduler: Cannot allocate resource to appattempt_1471639269423_0004_000001 because there is NO flexible resource left
2016-08-19 14:47:42,265 INFO org.apache.hadoop.yarn.server.resourcemanager.scheduler.fair.FSAppAttempt: assignContainer(FSSchedulerNode node:c220g1-031106.wisc.cloudlab.us, boolean reserved=false) for appattempt_1471639269423_0003_000001
2016-08-19 14:47:42,265 INFO org.apache.hadoop.yarn.server.resourcemanager.scheduler.fair.FSAppAttempt: assignContainer(FSSchedulerNode node:c220g1-031106.wisc.cloudlab.us, boolean reserved=false) for appattempt_1471639269423_0005_000001
2016-08-19 14:47:42,265 INFO org.apache.hadoop.yarn.server.resourcemanager.scheduler.fair.FSAppAttempt: assignContainer(FSSchedulerNode node:c220g1-031106.wisc.cloudlab.us, boolean reserved=false) for appattempt_1471639269423_0004_000001
2016-08-19 14:47:42,265 INFO org.apache.hadoop.yarn.server.resourcemanager.scheduler.fair.FSAppAttempt: assignContainer(FSSchedulerNode node:c220g1-031106.wisc.cloudlab.us, boolean reserved=false) for appattempt_1471639269423_0006_000001
2016-08-19 14:47:42,266 INFO org.apache.hadoop.yarn.server.resourcemanager.scheduler.fair.FSAppAttempt: assignContainer(FSSchedulerNode node:c220g1-031106.wisc.cloudlab.us, boolean reserved=false) for appattempt_1471639269423_0007_000001
2016-08-19 14:47:42,285 INFO org.apache.hadoop.yarn.server.resourcemanager.rmapp.attempt.RMAppAttemptImpl: AMContainerAllocatedTransition.transition(appattempt_1471639269423_0005_000001,EventType: CONTAINER_ALLOCATED)
2016-08-19 14:47:42,285 INFO org.apache.hadoop.yarn.server.resourcemanager.scheduler.fair.FairScheduler: allocate(appattempt_1471639269423_0005_000001 [] [] null null
2016-08-19 14:47:42,285 INFO org.apache.hadoop.yarn.server.resourcemanager.scheduler.fair.FSAppAttempt: appattempt_1471639269423_0005_000001 minReqResource: <memory:24576, vCores:12> flexibleResource: <memory:-8192, vCores:-4>
2016-08-19 14:47:42,285 INFO org.apache.hadoop.yarn.server.resourcemanager.scheduler.fair.FairScheduler: Cannot allocate resource to appattempt_1471639269423_0005_000001 because there is NO flexible resource left
2016-08-19 14:47:42,301 INFO org.apache.hadoop.yarn.server.resourcemanager.rmapp.attempt.RMAppAttemptImpl: AMContainerAllocatedTransition.transition(appattempt_1471639269423_0004_000001,EventType: CONTAINER_ALLOCATED)
2016-08-19 14:47:42,301 INFO org.apache.hadoop.yarn.server.resourcemanager.scheduler.fair.FairScheduler: allocate(appattempt_1471639269423_0004_000001 [] [] null null
2016-08-19 14:47:42,301 INFO org.apache.hadoop.yarn.server.resourcemanager.scheduler.fair.FSAppAttempt: appattempt_1471639269423_0004_000001 minReqResource: <memory:24576, vCores:12> flexibleResource: <memory:-8192, vCores:-4>
2016-08-19 14:47:42,301 INFO org.apache.hadoop.yarn.server.resourcemanager.scheduler.fair.FairScheduler: Cannot allocate resource to appattempt_1471639269423_0004_000001 because there is NO flexible resource left
2016-08-19 14:47:42,302 INFO org.apache.hadoop.yarn.server.resourcemanager.scheduler.fair.FSAppAttempt: assignContainer(FSSchedulerNode node:cp-1.yarn-perf.yarnrm-PG0.wisc.cloudlab.us, boolean reserved=false) for appattempt_1471639269423_0003_000001
2016-08-19 14:47:42,302 INFO org.apache.hadoop.yarn.server.resourcemanager.scheduler.fair.FSAppAttempt: assignContainer(FSSchedulerNode node:cp-1.yarn-perf.yarnrm-PG0.wisc.cloudlab.us, boolean reserved=false) for appattempt_1471639269423_0005_000001
2016-08-19 14:47:42,302 INFO org.apache.hadoop.yarn.server.resourcemanager.scheduler.fair.FSAppAttempt: assignContainer(FSSchedulerNode node:cp-1.yarn-perf.yarnrm-PG0.wisc.cloudlab.us, boolean reserved=false) for appattempt_1471639269423_0004_000001
2016-08-19 14:47:42,302 INFO org.apache.hadoop.yarn.server.resourcemanager.scheduler.fair.FSAppAttempt: assignContainer(FSSchedulerNode node:cp-1.yarn-perf.yarnrm-PG0.wisc.cloudlab.us, boolean reserved=false) for appattempt_1471639269423_0006_000001
2016-08-19 14:47:42,302 INFO org.apache.hadoop.yarn.server.resourcemanager.scheduler.fair.FSAppAttempt: assignContainer(FSSchedulerNode node:cp-1.yarn-perf.yarnrm-PG0.wisc.cloudlab.us, boolean reserved=false) for appattempt_1471639269423_0007_000001
2016-08-19 14:47:42,787 INFO org.apache.hadoop.yarn.server.resourcemanager.rmapp.attempt.RMAppAttemptImpl: AMContainerAllocatedTransition.transition(appattempt_1471639269423_0005_000001,EventType: CONTAINER_ALLOCATED)
2016-08-19 14:47:42,787 INFO org.apache.hadoop.yarn.server.resourcemanager.scheduler.fair.FairScheduler: allocate(appattempt_1471639269423_0005_000001 [] [] null null
2016-08-19 14:47:42,787 INFO org.apache.hadoop.yarn.server.resourcemanager.scheduler.fair.FSAppAttempt: appattempt_1471639269423_0005_000001 minReqResource: <memory:24576, vCores:12> flexibleResource: <memory:-8192, vCores:-4>
2016-08-19 14:47:42,787 INFO org.apache.hadoop.yarn.server.resourcemanager.scheduler.fair.FairScheduler: Cannot allocate resource to appattempt_1471639269423_0005_000001 because there is NO flexible resource left
2016-08-19 14:47:42,802 INFO org.apache.hadoop.yarn.server.resourcemanager.rmapp.attempt.RMAppAttemptImpl: AMContainerAllocatedTransition.transition(appattempt_1471639269423_0004_000001,EventType: CONTAINER_ALLOCATED)
2016-08-19 14:47:42,802 INFO org.apache.hadoop.yarn.server.resourcemanager.scheduler.fair.FairScheduler: allocate(appattempt_1471639269423_0004_000001 [] [] null null
2016-08-19 14:47:42,802 INFO org.apache.hadoop.yarn.server.resourcemanager.scheduler.fair.FSAppAttempt: appattempt_1471639269423_0004_000001 minReqResource: <memory:24576, vCores:12> flexibleResource: <memory:-8192, vCores:-4>
2016-08-19 14:47:42,802 INFO org.apache.hadoop.yarn.server.resourcemanager.scheduler.fair.FairScheduler: Cannot allocate resource to appattempt_1471639269423_0004_000001 because there is NO flexible resource left
2016-08-19 14:47:43,268 INFO org.apache.hadoop.yarn.server.resourcemanager.scheduler.fair.FSAppAttempt: assignContainer(FSSchedulerNode node:c220g1-031106.wisc.cloudlab.us, boolean reserved=false) for appattempt_1471639269423_0003_000001
2016-08-19 14:47:43,268 INFO org.apache.hadoop.yarn.server.resourcemanager.scheduler.fair.FSAppAttempt: assignContainer(FSSchedulerNode node:c220g1-031106.wisc.cloudlab.us, boolean reserved=false) for appattempt_1471639269423_0005_000001
2016-08-19 14:47:43,269 INFO org.apache.hadoop.yarn.server.resourcemanager.scheduler.fair.FSAppAttempt: assignContainer(FSSchedulerNode node:c220g1-031106.wisc.cloudlab.us, boolean reserved=false) for appattempt_1471639269423_0004_000001
2016-08-19 14:47:43,269 INFO org.apache.hadoop.yarn.server.resourcemanager.scheduler.fair.FSAppAttempt: assignContainer(FSSchedulerNode node:c220g1-031106.wisc.cloudlab.us, boolean reserved=false) for appattempt_1471639269423_0006_000001
2016-08-19 14:47:43,269 INFO org.apache.hadoop.yarn.server.resourcemanager.scheduler.fair.FSAppAttempt: assignContainer(FSSchedulerNode node:c220g1-031106.wisc.cloudlab.us, boolean reserved=false) for appattempt_1471639269423_0007_000001
2016-08-19 14:47:43,288 INFO org.apache.hadoop.yarn.server.resourcemanager.rmapp.attempt.RMAppAttemptImpl: AMContainerAllocatedTransition.transition(appattempt_1471639269423_0005_000001,EventType: CONTAINER_ALLOCATED)
2016-08-19 14:47:43,288 INFO org.apache.hadoop.yarn.server.resourcemanager.scheduler.fair.FairScheduler: allocate(appattempt_1471639269423_0005_000001 [] [] null null
2016-08-19 14:47:43,288 INFO org.apache.hadoop.yarn.server.resourcemanager.scheduler.fair.FSAppAttempt: appattempt_1471639269423_0005_000001 minReqResource: <memory:24576, vCores:12> flexibleResource: <memory:-8192, vCores:-4>
2016-08-19 14:47:43,288 INFO org.apache.hadoop.yarn.server.resourcemanager.scheduler.fair.FairScheduler: Cannot allocate resource to appattempt_1471639269423_0005_000001 because there is NO flexible resource left
2016-08-19 14:47:43,303 INFO org.apache.hadoop.yarn.server.resourcemanager.rmapp.attempt.RMAppAttemptImpl: AMContainerAllocatedTransition.transition(appattempt_1471639269423_0004_000001,EventType: CONTAINER_ALLOCATED)
2016-08-19 14:47:43,303 INFO org.apache.hadoop.yarn.server.resourcemanager.scheduler.fair.FairScheduler: allocate(appattempt_1471639269423_0004_000001 [] [] null null
2016-08-19 14:47:43,304 INFO org.apache.hadoop.yarn.server.resourcemanager.scheduler.fair.FSAppAttempt: appattempt_1471639269423_0004_000001 minReqResource: <memory:24576, vCores:12> flexibleResource: <memory:-8192, vCores:-4>
2016-08-19 14:47:43,304 INFO org.apache.hadoop.yarn.server.resourcemanager.scheduler.fair.FairScheduler: Cannot allocate resource to appattempt_1471639269423_0004_000001 because there is NO flexible resource left
2016-08-19 14:47:43,306 INFO org.apache.hadoop.yarn.server.resourcemanager.scheduler.fair.FSAppAttempt: assignContainer(FSSchedulerNode node:cp-1.yarn-perf.yarnrm-PG0.wisc.cloudlab.us, boolean reserved=false) for appattempt_1471639269423_0003_000001
2016-08-19 14:47:43,306 INFO org.apache.hadoop.yarn.server.resourcemanager.scheduler.fair.FSAppAttempt: assignContainer(FSSchedulerNode node:cp-1.yarn-perf.yarnrm-PG0.wisc.cloudlab.us, boolean reserved=false) for appattempt_1471639269423_0005_000001
2016-08-19 14:47:43,306 INFO org.apache.hadoop.yarn.server.resourcemanager.scheduler.fair.FSAppAttempt: assignContainer(FSSchedulerNode node:cp-1.yarn-perf.yarnrm-PG0.wisc.cloudlab.us, boolean reserved=false) for appattempt_1471639269423_0004_000001
2016-08-19 14:47:43,306 INFO org.apache.hadoop.yarn.server.resourcemanager.scheduler.fair.FSAppAttempt: assignContainer(FSSchedulerNode node:cp-1.yarn-perf.yarnrm-PG0.wisc.cloudlab.us, boolean reserved=false) for appattempt_1471639269423_0006_000001
2016-08-19 14:47:43,306 INFO org.apache.hadoop.yarn.server.resourcemanager.scheduler.fair.FSAppAttempt: assignContainer(FSSchedulerNode node:cp-1.yarn-perf.yarnrm-PG0.wisc.cloudlab.us, boolean reserved=false) for appattempt_1471639269423_0007_000001
2016-08-19 14:47:43,789 INFO org.apache.hadoop.yarn.server.resourcemanager.rmapp.attempt.RMAppAttemptImpl: AMContainerAllocatedTransition.transition(appattempt_1471639269423_0005_000001,EventType: CONTAINER_ALLOCATED)
2016-08-19 14:47:43,789 INFO org.apache.hadoop.yarn.server.resourcemanager.scheduler.fair.FairScheduler: allocate(appattempt_1471639269423_0005_000001 [] [] null null
2016-08-19 14:47:43,789 INFO org.apache.hadoop.yarn.server.resourcemanager.scheduler.fair.FSAppAttempt: appattempt_1471639269423_0005_000001 minReqResource: <memory:24576, vCores:12> flexibleResource: <memory:-8192, vCores:-4>
2016-08-19 14:47:43,789 INFO org.apache.hadoop.yarn.server.resourcemanager.scheduler.fair.FairScheduler: Cannot allocate resource to appattempt_1471639269423_0005_000001 because there is NO flexible resource left
2016-08-19 14:47:43,805 INFO org.apache.hadoop.yarn.server.resourcemanager.rmapp.attempt.RMAppAttemptImpl: AMContainerAllocatedTransition.transition(appattempt_1471639269423_0004_000001,EventType: CONTAINER_ALLOCATED)
2016-08-19 14:47:43,805 INFO org.apache.hadoop.yarn.server.resourcemanager.scheduler.fair.FairScheduler: allocate(appattempt_1471639269423_0004_000001 [] [] null null
2016-08-19 14:47:43,805 INFO org.apache.hadoop.yarn.server.resourcemanager.scheduler.fair.FSAppAttempt: appattempt_1471639269423_0004_000001 minReqResource: <memory:24576, vCores:12> flexibleResource: <memory:-8192, vCores:-4>
2016-08-19 14:47:43,805 INFO org.apache.hadoop.yarn.server.resourcemanager.scheduler.fair.FairScheduler: Cannot allocate resource to appattempt_1471639269423_0004_000001 because there is NO flexible resource left
2016-08-19 14:47:44,274 INFO org.apache.hadoop.yarn.server.resourcemanager.scheduler.fair.FSAppAttempt: assignContainer(FSSchedulerNode node:c220g1-031106.wisc.cloudlab.us, boolean reserved=false) for appattempt_1471639269423_0003_000001
2016-08-19 14:47:44,274 INFO org.apache.hadoop.yarn.server.resourcemanager.scheduler.fair.FSAppAttempt: assignContainer(FSSchedulerNode node:c220g1-031106.wisc.cloudlab.us, boolean reserved=false) for appattempt_1471639269423_0005_000001
2016-08-19 14:47:44,274 INFO org.apache.hadoop.yarn.server.resourcemanager.scheduler.fair.FSAppAttempt: assignContainer(FSSchedulerNode node:c220g1-031106.wisc.cloudlab.us, boolean reserved=false) for appattempt_1471639269423_0004_000001
2016-08-19 14:47:44,274 INFO org.apache.hadoop.yarn.server.resourcemanager.scheduler.fair.FSAppAttempt: assignContainer(FSSchedulerNode node:c220g1-031106.wisc.cloudlab.us, boolean reserved=false) for appattempt_1471639269423_0006_000001
2016-08-19 14:47:44,274 INFO org.apache.hadoop.yarn.server.resourcemanager.scheduler.fair.FSAppAttempt: assignContainer(FSSchedulerNode node:c220g1-031106.wisc.cloudlab.us, boolean reserved=false) for appattempt_1471639269423_0007_000001
2016-08-19 14:47:44,290 INFO org.apache.hadoop.yarn.server.resourcemanager.rmapp.attempt.RMAppAttemptImpl: AMContainerAllocatedTransition.transition(appattempt_1471639269423_0005_000001,EventType: CONTAINER_ALLOCATED)
2016-08-19 14:47:44,290 INFO org.apache.hadoop.yarn.server.resourcemanager.scheduler.fair.FairScheduler: allocate(appattempt_1471639269423_0005_000001 [] [] null null
2016-08-19 14:47:44,290 INFO org.apache.hadoop.yarn.server.resourcemanager.scheduler.fair.FSAppAttempt: appattempt_1471639269423_0005_000001 minReqResource: <memory:24576, vCores:12> flexibleResource: <memory:-8192, vCores:-4>
2016-08-19 14:47:44,291 INFO org.apache.hadoop.yarn.server.resourcemanager.scheduler.fair.FairScheduler: Cannot allocate resource to appattempt_1471639269423_0005_000001 because there is NO flexible resource left
2016-08-19 14:47:44,306 INFO org.apache.hadoop.yarn.server.resourcemanager.rmapp.attempt.RMAppAttemptImpl: AMContainerAllocatedTransition.transition(appattempt_1471639269423_0004_000001,EventType: CONTAINER_ALLOCATED)
2016-08-19 14:47:44,306 INFO org.apache.hadoop.yarn.server.resourcemanager.scheduler.fair.FairScheduler: allocate(appattempt_1471639269423_0004_000001 [] [] null null
2016-08-19 14:47:44,306 INFO org.apache.hadoop.yarn.server.resourcemanager.scheduler.fair.FSAppAttempt: appattempt_1471639269423_0004_000001 minReqResource: <memory:24576, vCores:12> flexibleResource: <memory:-8192, vCores:-4>
2016-08-19 14:47:44,306 INFO org.apache.hadoop.yarn.server.resourcemanager.scheduler.fair.FairScheduler: Cannot allocate resource to appattempt_1471639269423_0004_000001 because there is NO flexible resource left
2016-08-19 14:47:44,309 INFO org.apache.hadoop.yarn.server.resourcemanager.scheduler.fair.FSAppAttempt: assignContainer(FSSchedulerNode node:cp-1.yarn-perf.yarnrm-PG0.wisc.cloudlab.us, boolean reserved=false) for appattempt_1471639269423_0003_000001
2016-08-19 14:47:44,309 INFO org.apache.hadoop.yarn.server.resourcemanager.scheduler.fair.FSAppAttempt: assignContainer(FSSchedulerNode node:cp-1.yarn-perf.yarnrm-PG0.wisc.cloudlab.us, boolean reserved=false) for appattempt_1471639269423_0005_000001
2016-08-19 14:47:44,309 INFO org.apache.hadoop.yarn.server.resourcemanager.scheduler.fair.FSAppAttempt: assignContainer(FSSchedulerNode node:cp-1.yarn-perf.yarnrm-PG0.wisc.cloudlab.us, boolean reserved=false) for appattempt_1471639269423_0004_000001
2016-08-19 14:47:44,309 INFO org.apache.hadoop.yarn.server.resourcemanager.scheduler.fair.FSAppAttempt: assignContainer(FSSchedulerNode node:cp-1.yarn-perf.yarnrm-PG0.wisc.cloudlab.us, boolean reserved=false) for appattempt_1471639269423_0006_000001
2016-08-19 14:47:44,309 INFO org.apache.hadoop.yarn.server.resourcemanager.scheduler.fair.FSAppAttempt: assignContainer(FSSchedulerNode node:cp-1.yarn-perf.yarnrm-PG0.wisc.cloudlab.us, boolean reserved=false) for appattempt_1471639269423_0007_000001
2016-08-19 14:47:44,644 INFO org.apache.hadoop.yarn.server.resourcemanager.scheduler.fair.FairScheduler: allocate(appattempt_1471639269423_0003_000001 [{Priority: 1, Capability: <memory:1920, vCores:1>, # Containers: 1, Location: *, Relax Locality: true}] [] [] []
2016-08-19 14:47:44,644 INFO org.apache.hadoop.yarn.server.resourcemanager.scheduler.fair.FSAppAttempt: appattempt_1471639269423_0003_000001 minReqResource: <memory:24576, vCores:12> flexibleResource: <memory:-8192, vCores:-4>
2016-08-19 14:47:44,645 INFO org.apache.hadoop.yarn.server.resourcemanager.scheduler.fair.FairScheduler: Cannot allocate resource to appattempt_1471639269423_0003_000001 because there is NO flexible resource left
2016-08-19 14:47:44,791 INFO org.apache.hadoop.yarn.server.resourcemanager.rmapp.attempt.RMAppAttemptImpl: AMContainerAllocatedTransition.transition(appattempt_1471639269423_0005_000001,EventType: CONTAINER_ALLOCATED)
2016-08-19 14:47:44,791 INFO org.apache.hadoop.yarn.server.resourcemanager.scheduler.fair.FairScheduler: allocate(appattempt_1471639269423_0005_000001 [] [] null null
2016-08-19 14:47:44,791 INFO org.apache.hadoop.yarn.server.resourcemanager.scheduler.fair.FSAppAttempt: appattempt_1471639269423_0005_000001 minReqResource: <memory:24576, vCores:12> flexibleResource: <memory:-8192, vCores:-4>
2016-08-19 14:47:44,792 INFO org.apache.hadoop.yarn.server.resourcemanager.scheduler.fair.FairScheduler: Cannot allocate resource to appattempt_1471639269423_0005_000001 because there is NO flexible resource left
2016-08-19 14:47:44,807 INFO org.apache.hadoop.yarn.server.resourcemanager.rmapp.attempt.RMAppAttemptImpl: AMContainerAllocatedTransition.transition(appattempt_1471639269423_0004_000001,EventType: CONTAINER_ALLOCATED)
2016-08-19 14:47:44,807 INFO org.apache.hadoop.yarn.server.resourcemanager.scheduler.fair.FairScheduler: allocate(appattempt_1471639269423_0004_000001 [] [] null null
2016-08-19 14:47:44,807 INFO org.apache.hadoop.yarn.server.resourcemanager.scheduler.fair.FSAppAttempt: appattempt_1471639269423_0004_000001 minReqResource: <memory:24576, vCores:12> flexibleResource: <memory:-8192, vCores:-4>
2016-08-19 14:47:44,807 INFO org.apache.hadoop.yarn.server.resourcemanager.scheduler.fair.FairScheduler: Cannot allocate resource to appattempt_1471639269423_0004_000001 because there is NO flexible resource left
2016-08-19 14:47:44,848 INFO org.apache.hadoop.yarn.server.resourcemanager.scheduler.fair.FairScheduler: allocate(appattempt_1471639269423_0003_000001 [] [] [] []
2016-08-19 14:47:44,848 INFO org.apache.hadoop.yarn.server.resourcemanager.scheduler.fair.FSAppAttempt: appattempt_1471639269423_0003_000001 minReqResource: <memory:24576, vCores:12> flexibleResource: <memory:-8192, vCores:-4>
2016-08-19 14:47:44,848 INFO org.apache.hadoop.yarn.server.resourcemanager.scheduler.fair.FairScheduler: Cannot allocate resource to appattempt_1471639269423_0003_000001 because there is NO flexible resource left
2016-08-19 14:47:45,251 INFO org.apache.hadoop.yarn.server.resourcemanager.scheduler.fair.FairScheduler: allocate(appattempt_1471639269423_0003_000001 [] [] [] []
2016-08-19 14:47:45,251 INFO org.apache.hadoop.yarn.server.resourcemanager.scheduler.fair.FSAppAttempt: appattempt_1471639269423_0003_000001 minReqResource: <memory:24576, vCores:12> flexibleResource: <memory:-8192, vCores:-4>
2016-08-19 14:47:45,251 INFO org.apache.hadoop.yarn.server.resourcemanager.scheduler.fair.FairScheduler: Cannot allocate resource to appattempt_1471639269423_0003_000001 because there is NO flexible resource left
2016-08-19 14:47:45,277 INFO org.apache.hadoop.yarn.server.resourcemanager.scheduler.fair.FSAppAttempt: assignContainer(FSSchedulerNode node:c220g1-031106.wisc.cloudlab.us, boolean reserved=false) for appattempt_1471639269423_0003_000001
2016-08-19 14:47:45,277 INFO org.apache.hadoop.yarn.server.resourcemanager.scheduler.fair.FSAppAttempt: assignContainer(FSSchedulerNode node:c220g1-031106.wisc.cloudlab.us, boolean reserved=false) for appattempt_1471639269423_0005_000001
2016-08-19 14:47:45,277 INFO org.apache.hadoop.yarn.server.resourcemanager.scheduler.fair.FSAppAttempt: assignContainer(FSSchedulerNode node:c220g1-031106.wisc.cloudlab.us, boolean reserved=false) for appattempt_1471639269423_0004_000001
2016-08-19 14:47:45,277 INFO org.apache.hadoop.yarn.server.resourcemanager.scheduler.fair.FSAppAttempt: assignContainer(FSSchedulerNode node:c220g1-031106.wisc.cloudlab.us, boolean reserved=false) for appattempt_1471639269423_0006_000001
2016-08-19 14:47:45,277 INFO org.apache.hadoop.yarn.server.resourcemanager.scheduler.fair.FSAppAttempt: assignContainer(FSSchedulerNode node:c220g1-031106.wisc.cloudlab.us, boolean reserved=false) for appattempt_1471639269423_0007_000001
2016-08-19 14:47:45,292 INFO org.apache.hadoop.yarn.server.resourcemanager.rmapp.attempt.RMAppAttemptImpl: AMContainerAllocatedTransition.transition(appattempt_1471639269423_0005_000001,EventType: CONTAINER_ALLOCATED)
2016-08-19 14:47:45,293 INFO org.apache.hadoop.yarn.server.resourcemanager.scheduler.fair.FairScheduler: allocate(appattempt_1471639269423_0005_000001 [] [] null null
2016-08-19 14:47:45,293 INFO org.apache.hadoop.yarn.server.resourcemanager.scheduler.fair.FSAppAttempt: appattempt_1471639269423_0005_000001 minReqResource: <memory:24576, vCores:12> flexibleResource: <memory:-8192, vCores:-4>
2016-08-19 14:47:45,293 INFO org.apache.hadoop.yarn.server.resourcemanager.scheduler.fair.FairScheduler: Cannot allocate resource to appattempt_1471639269423_0005_000001 because there is NO flexible resource left
2016-08-19 14:47:45,308 INFO org.apache.hadoop.yarn.server.resourcemanager.rmapp.attempt.RMAppAttemptImpl: AMContainerAllocatedTransition.transition(appattempt_1471639269423_0004_000001,EventType: CONTAINER_ALLOCATED)
2016-08-19 14:47:45,308 INFO org.apache.hadoop.yarn.server.resourcemanager.scheduler.fair.FairScheduler: allocate(appattempt_1471639269423_0004_000001 [] [] null null
2016-08-19 14:47:45,308 INFO org.apache.hadoop.yarn.server.resourcemanager.scheduler.fair.FSAppAttempt: appattempt_1471639269423_0004_000001 minReqResource: <memory:24576, vCores:12> flexibleResource: <memory:-8192, vCores:-4>
2016-08-19 14:47:45,308 INFO org.apache.hadoop.yarn.server.resourcemanager.scheduler.fair.FairScheduler: Cannot allocate resource to appattempt_1471639269423_0004_000001 because there is NO flexible resource left
2016-08-19 14:47:45,312 INFO org.apache.hadoop.yarn.server.resourcemanager.scheduler.fair.FSAppAttempt: assignContainer(FSSchedulerNode node:cp-1.yarn-perf.yarnrm-PG0.wisc.cloudlab.us, boolean reserved=false) for appattempt_1471639269423_0003_000001
2016-08-19 14:47:45,312 INFO org.apache.hadoop.yarn.server.resourcemanager.scheduler.fair.FSAppAttempt: assignContainer(FSSchedulerNode node:cp-1.yarn-perf.yarnrm-PG0.wisc.cloudlab.us, boolean reserved=false) for appattempt_1471639269423_0005_000001
2016-08-19 14:47:45,312 INFO org.apache.hadoop.yarn.server.resourcemanager.scheduler.fair.FSAppAttempt: assignContainer(FSSchedulerNode node:cp-1.yarn-perf.yarnrm-PG0.wisc.cloudlab.us, boolean reserved=false) for appattempt_1471639269423_0004_000001
2016-08-19 14:47:45,312 INFO org.apache.hadoop.yarn.server.resourcemanager.scheduler.fair.FSAppAttempt: assignContainer(FSSchedulerNode node:cp-1.yarn-perf.yarnrm-PG0.wisc.cloudlab.us, boolean reserved=false) for appattempt_1471639269423_0006_000001
2016-08-19 14:47:45,312 INFO org.apache.hadoop.yarn.server.resourcemanager.scheduler.fair.FSAppAttempt: assignContainer(FSSchedulerNode node:cp-1.yarn-perf.yarnrm-PG0.wisc.cloudlab.us, boolean reserved=false) for appattempt_1471639269423_0007_000001
2016-08-19 14:47:45,794 INFO org.apache.hadoop.yarn.server.resourcemanager.rmapp.attempt.RMAppAttemptImpl: AMContainerAllocatedTransition.transition(appattempt_1471639269423_0005_000001,EventType: CONTAINER_ALLOCATED)
2016-08-19 14:47:45,794 INFO org.apache.hadoop.yarn.server.resourcemanager.scheduler.fair.FairScheduler: allocate(appattempt_1471639269423_0005_000001 [] [] null null
2016-08-19 14:47:45,794 INFO org.apache.hadoop.yarn.server.resourcemanager.scheduler.fair.FSAppAttempt: appattempt_1471639269423_0005_000001 minReqResource: <memory:24576, vCores:12> flexibleResource: <memory:-8192, vCores:-4>
2016-08-19 14:47:45,794 INFO org.apache.hadoop.yarn.server.resourcemanager.scheduler.fair.FairScheduler: Cannot allocate resource to appattempt_1471639269423_0005_000001 because there is NO flexible resource left
2016-08-19 14:47:45,809 INFO org.apache.hadoop.yarn.server.resourcemanager.rmapp.attempt.RMAppAttemptImpl: AMContainerAllocatedTransition.transition(appattempt_1471639269423_0004_000001,EventType: CONTAINER_ALLOCATED)
2016-08-19 14:47:45,809 INFO org.apache.hadoop.yarn.server.resourcemanager.scheduler.fair.FairScheduler: allocate(appattempt_1471639269423_0004_000001 [] [] null null
2016-08-19 14:47:45,809 INFO org.apache.hadoop.yarn.server.resourcemanager.scheduler.fair.FSAppAttempt: appattempt_1471639269423_0004_000001 minReqResource: <memory:24576, vCores:12> flexibleResource: <memory:-8192, vCores:-4>
2016-08-19 14:47:45,809 INFO org.apache.hadoop.yarn.server.resourcemanager.scheduler.fair.FairScheduler: Cannot allocate resource to appattempt_1471639269423_0004_000001 because there is NO flexible resource left
2016-08-19 14:47:46,054 INFO org.apache.hadoop.yarn.server.resourcemanager.scheduler.fair.FairScheduler: allocate(appattempt_1471639269423_0003_000001 [] [] [] []
2016-08-19 14:47:46,055 INFO org.apache.hadoop.yarn.server.resourcemanager.scheduler.fair.FSAppAttempt: appattempt_1471639269423_0003_000001 minReqResource: <memory:24576, vCores:12> flexibleResource: <memory:-8192, vCores:-4>
2016-08-19 14:47:46,055 INFO org.apache.hadoop.yarn.server.resourcemanager.scheduler.fair.FairScheduler: Cannot allocate resource to appattempt_1471639269423_0003_000001 because there is NO flexible resource left
2016-08-19 14:47:46,280 INFO org.apache.hadoop.yarn.server.resourcemanager.scheduler.fair.FSAppAttempt: assignContainer(FSSchedulerNode node:c220g1-031106.wisc.cloudlab.us, boolean reserved=false) for appattempt_1471639269423_0003_000001
2016-08-19 14:47:46,280 INFO org.apache.hadoop.yarn.server.resourcemanager.scheduler.fair.FSAppAttempt: assignContainer(FSSchedulerNode node:c220g1-031106.wisc.cloudlab.us, boolean reserved=false) for appattempt_1471639269423_0005_000001
2016-08-19 14:47:46,280 INFO org.apache.hadoop.yarn.server.resourcemanager.scheduler.fair.FSAppAttempt: assignContainer(FSSchedulerNode node:c220g1-031106.wisc.cloudlab.us, boolean reserved=false) for appattempt_1471639269423_0004_000001
2016-08-19 14:47:46,280 INFO org.apache.hadoop.yarn.server.resourcemanager.scheduler.fair.FSAppAttempt: assignContainer(FSSchedulerNode node:c220g1-031106.wisc.cloudlab.us, boolean reserved=false) for appattempt_1471639269423_0006_000001
2016-08-19 14:47:46,280 INFO org.apache.hadoop.yarn.server.resourcemanager.scheduler.fair.FSAppAttempt: assignContainer(FSSchedulerNode node:c220g1-031106.wisc.cloudlab.us, boolean reserved=false) for appattempt_1471639269423_0007_000001
2016-08-19 14:47:46,295 INFO org.apache.hadoop.yarn.server.resourcemanager.rmapp.attempt.RMAppAttemptImpl: AMContainerAllocatedTransition.transition(appattempt_1471639269423_0005_000001,EventType: CONTAINER_ALLOCATED)
2016-08-19 14:47:46,295 INFO org.apache.hadoop.yarn.server.resourcemanager.scheduler.fair.FairScheduler: allocate(appattempt_1471639269423_0005_000001 [] [] null null
2016-08-19 14:47:46,295 INFO org.apache.hadoop.yarn.server.resourcemanager.scheduler.fair.FSAppAttempt: appattempt_1471639269423_0005_000001 minReqResource: <memory:24576, vCores:12> flexibleResource: <memory:-8192, vCores:-4>
2016-08-19 14:47:46,295 INFO org.apache.hadoop.yarn.server.resourcemanager.scheduler.fair.FairScheduler: Cannot allocate resource to appattempt_1471639269423_0005_000001 because there is NO flexible resource left
2016-08-19 14:47:46,310 INFO org.apache.hadoop.yarn.server.resourcemanager.rmapp.attempt.RMAppAttemptImpl: AMContainerAllocatedTransition.transition(appattempt_1471639269423_0004_000001,EventType: CONTAINER_ALLOCATED)
2016-08-19 14:47:46,310 INFO org.apache.hadoop.yarn.server.resourcemanager.scheduler.fair.FairScheduler: allocate(appattempt_1471639269423_0004_000001 [] [] null null
2016-08-19 14:47:46,310 INFO org.apache.hadoop.yarn.server.resourcemanager.scheduler.fair.FSAppAttempt: appattempt_1471639269423_0004_000001 minReqResource: <memory:24576, vCores:12> flexibleResource: <memory:-8192, vCores:-4>
2016-08-19 14:47:46,310 INFO org.apache.hadoop.yarn.server.resourcemanager.scheduler.fair.FairScheduler: Cannot allocate resource to appattempt_1471639269423_0004_000001 because there is NO flexible resource left
2016-08-19 14:47:46,314 INFO org.apache.hadoop.yarn.server.resourcemanager.scheduler.fair.FSAppAttempt: assignContainer(FSSchedulerNode node:cp-1.yarn-perf.yarnrm-PG0.wisc.cloudlab.us, boolean reserved=false) for appattempt_1471639269423_0003_000001
2016-08-19 14:47:46,314 INFO org.apache.hadoop.yarn.server.resourcemanager.scheduler.fair.FSAppAttempt: assignContainer(FSSchedulerNode node:cp-1.yarn-perf.yarnrm-PG0.wisc.cloudlab.us, boolean reserved=false) for appattempt_1471639269423_0005_000001
2016-08-19 14:47:46,314 INFO org.apache.hadoop.yarn.server.resourcemanager.scheduler.fair.FSAppAttempt: assignContainer(FSSchedulerNode node:cp-1.yarn-perf.yarnrm-PG0.wisc.cloudlab.us, boolean reserved=false) for appattempt_1471639269423_0004_000001
2016-08-19 14:47:46,314 INFO org.apache.hadoop.yarn.server.resourcemanager.scheduler.fair.FSAppAttempt: assignContainer(FSSchedulerNode node:cp-1.yarn-perf.yarnrm-PG0.wisc.cloudlab.us, boolean reserved=false) for appattempt_1471639269423_0006_000001
2016-08-19 14:47:46,315 INFO org.apache.hadoop.yarn.server.resourcemanager.scheduler.fair.FSAppAttempt: assignContainer(FSSchedulerNode node:cp-1.yarn-perf.yarnrm-PG0.wisc.cloudlab.us, boolean reserved=false) for appattempt_1471639269423_0007_000001
2016-08-19 14:47:46,796 INFO org.apache.hadoop.yarn.server.resourcemanager.rmapp.attempt.RMAppAttemptImpl: AMContainerAllocatedTransition.transition(appattempt_1471639269423_0005_000001,EventType: CONTAINER_ALLOCATED)
2016-08-19 14:47:46,796 INFO org.apache.hadoop.yarn.server.resourcemanager.scheduler.fair.FairScheduler: allocate(appattempt_1471639269423_0005_000001 [] [] null null
2016-08-19 14:47:46,796 INFO org.apache.hadoop.yarn.server.resourcemanager.scheduler.fair.FSAppAttempt: appattempt_1471639269423_0005_000001 minReqResource: <memory:24576, vCores:12> flexibleResource: <memory:-8192, vCores:-4>
2016-08-19 14:47:46,796 INFO org.apache.hadoop.yarn.server.resourcemanager.scheduler.fair.FairScheduler: Cannot allocate resource to appattempt_1471639269423_0005_000001 because there is NO flexible resource left
2016-08-19 14:47:46,811 INFO org.apache.hadoop.yarn.server.resourcemanager.rmapp.attempt.RMAppAttemptImpl: AMContainerAllocatedTransition.transition(appattempt_1471639269423_0004_000001,EventType: CONTAINER_ALLOCATED)
2016-08-19 14:47:46,811 INFO org.apache.hadoop.yarn.server.resourcemanager.scheduler.fair.FairScheduler: allocate(appattempt_1471639269423_0004_000001 [] [] null null
2016-08-19 14:47:46,811 INFO org.apache.hadoop.yarn.server.resourcemanager.scheduler.fair.FSAppAttempt: appattempt_1471639269423_0004_000001 minReqResource: <memory:24576, vCores:12> flexibleResource: <memory:-8192, vCores:-4>
2016-08-19 14:47:46,811 INFO org.apache.hadoop.yarn.server.resourcemanager.scheduler.fair.FairScheduler: Cannot allocate resource to appattempt_1471639269423_0004_000001 because there is NO flexible resource left
2016-08-19 14:47:47,283 INFO org.apache.hadoop.yarn.server.resourcemanager.scheduler.fair.FSAppAttempt: assignContainer(FSSchedulerNode node:c220g1-031106.wisc.cloudlab.us, boolean reserved=false) for appattempt_1471639269423_0003_000001
2016-08-19 14:47:47,283 INFO org.apache.hadoop.yarn.server.resourcemanager.scheduler.fair.FSAppAttempt: assignContainer(FSSchedulerNode node:c220g1-031106.wisc.cloudlab.us, boolean reserved=false) for appattempt_1471639269423_0005_000001
2016-08-19 14:47:47,283 INFO org.apache.hadoop.yarn.server.resourcemanager.scheduler.fair.FSAppAttempt: assignContainer(FSSchedulerNode node:c220g1-031106.wisc.cloudlab.us, boolean reserved=false) for appattempt_1471639269423_0004_000001
2016-08-19 14:47:47,283 INFO org.apache.hadoop.yarn.server.resourcemanager.scheduler.fair.FSAppAttempt: assignContainer(FSSchedulerNode node:c220g1-031106.wisc.cloudlab.us, boolean reserved=false) for appattempt_1471639269423_0006_000001
2016-08-19 14:47:47,284 INFO org.apache.hadoop.yarn.server.resourcemanager.scheduler.fair.FSAppAttempt: assignContainer(FSSchedulerNode node:c220g1-031106.wisc.cloudlab.us, boolean reserved=false) for appattempt_1471639269423_0007_000001
2016-08-19 14:47:47,297 INFO org.apache.hadoop.yarn.server.resourcemanager.rmapp.attempt.RMAppAttemptImpl: AMContainerAllocatedTransition.transition(appattempt_1471639269423_0005_000001,EventType: CONTAINER_ALLOCATED)
2016-08-19 14:47:47,297 INFO org.apache.hadoop.yarn.server.resourcemanager.scheduler.fair.FairScheduler: allocate(appattempt_1471639269423_0005_000001 [] [] null null
2016-08-19 14:47:47,297 INFO org.apache.hadoop.yarn.server.resourcemanager.scheduler.fair.FSAppAttempt: appattempt_1471639269423_0005_000001 minReqResource: <memory:24576, vCores:12> flexibleResource: <memory:-8192, vCores:-4>
2016-08-19 14:47:47,297 INFO org.apache.hadoop.yarn.server.resourcemanager.scheduler.fair.FairScheduler: Cannot allocate resource to appattempt_1471639269423_0005_000001 because there is NO flexible resource left
2016-08-19 14:47:47,311 INFO org.apache.hadoop.yarn.server.resourcemanager.rmapp.attempt.RMAppAttemptImpl: AMContainerAllocatedTransition.transition(appattempt_1471639269423_0004_000001,EventType: CONTAINER_ALLOCATED)
2016-08-19 14:47:47,311 INFO org.apache.hadoop.yarn.server.resourcemanager.scheduler.fair.FairScheduler: allocate(appattempt_1471639269423_0004_000001 [] [] null null
2016-08-19 14:47:47,312 INFO org.apache.hadoop.yarn.server.resourcemanager.scheduler.fair.FSAppAttempt: appattempt_1471639269423_0004_000001 minReqResource: <memory:24576, vCores:12> flexibleResource: <memory:-8192, vCores:-4>
2016-08-19 14:47:47,312 INFO org.apache.hadoop.yarn.server.resourcemanager.scheduler.fair.FairScheduler: Cannot allocate resource to appattempt_1471639269423_0004_000001 because there is NO flexible resource left
2016-08-19 14:47:47,316 INFO org.apache.hadoop.yarn.server.resourcemanager.scheduler.fair.FSAppAttempt: assignContainer(FSSchedulerNode node:cp-1.yarn-perf.yarnrm-PG0.wisc.cloudlab.us, boolean reserved=false) for appattempt_1471639269423_0003_000001
2016-08-19 14:47:47,317 INFO org.apache.hadoop.yarn.server.resourcemanager.scheduler.fair.FSAppAttempt: assignContainer(FSSchedulerNode node:cp-1.yarn-perf.yarnrm-PG0.wisc.cloudlab.us, boolean reserved=false) for appattempt_1471639269423_0005_000001
2016-08-19 14:47:47,317 INFO org.apache.hadoop.yarn.server.resourcemanager.scheduler.fair.FSAppAttempt: assignContainer(FSSchedulerNode node:cp-1.yarn-perf.yarnrm-PG0.wisc.cloudlab.us, boolean reserved=false) for appattempt_1471639269423_0004_000001
2016-08-19 14:47:47,317 INFO org.apache.hadoop.yarn.server.resourcemanager.scheduler.fair.FSAppAttempt: assignContainer(FSSchedulerNode node:cp-1.yarn-perf.yarnrm-PG0.wisc.cloudlab.us, boolean reserved=false) for appattempt_1471639269423_0006_000001
2016-08-19 14:47:47,317 INFO org.apache.hadoop.yarn.server.resourcemanager.scheduler.fair.FSAppAttempt: assignContainer(FSSchedulerNode node:cp-1.yarn-perf.yarnrm-PG0.wisc.cloudlab.us, boolean reserved=false) for appattempt_1471639269423_0007_000001
2016-08-19 14:47:47,658 INFO org.apache.hadoop.yarn.server.resourcemanager.scheduler.fair.FairScheduler: allocate(appattempt_1471639269423_0003_000001 [] [] [] []
2016-08-19 14:47:47,658 INFO org.apache.hadoop.yarn.server.resourcemanager.scheduler.fair.FSAppAttempt: appattempt_1471639269423_0003_000001 minReqResource: <memory:24576, vCores:12> flexibleResource: <memory:-8192, vCores:-4>
2016-08-19 14:47:47,658 INFO org.apache.hadoop.yarn.server.resourcemanager.scheduler.fair.FairScheduler: Cannot allocate resource to appattempt_1471639269423_0003_000001 because there is NO flexible resource left
2016-08-19 14:47:47,798 INFO org.apache.hadoop.yarn.server.resourcemanager.rmapp.attempt.RMAppAttemptImpl: AMContainerAllocatedTransition.transition(appattempt_1471639269423_0005_000001,EventType: CONTAINER_ALLOCATED)
2016-08-19 14:47:47,798 INFO org.apache.hadoop.yarn.server.resourcemanager.scheduler.fair.FairScheduler: allocate(appattempt_1471639269423_0005_000001 [] [] null null
2016-08-19 14:47:47,798 INFO org.apache.hadoop.yarn.server.resourcemanager.scheduler.fair.FSAppAttempt: appattempt_1471639269423_0005_000001 minReqResource: <memory:24576, vCores:12> flexibleResource: <memory:-8192, vCores:-4>
2016-08-19 14:47:47,798 INFO org.apache.hadoop.yarn.server.resourcemanager.scheduler.fair.FairScheduler: Cannot allocate resource to appattempt_1471639269423_0005_000001 because there is NO flexible resource left
2016-08-19 14:47:47,812 INFO org.apache.hadoop.yarn.server.resourcemanager.rmapp.attempt.RMAppAttemptImpl: AMContainerAllocatedTransition.transition(appattempt_1471639269423_0004_000001,EventType: CONTAINER_ALLOCATED)
2016-08-19 14:47:47,812 INFO org.apache.hadoop.yarn.server.resourcemanager.scheduler.fair.FairScheduler: allocate(appattempt_1471639269423_0004_000001 [] [] null null
2016-08-19 14:47:47,812 INFO org.apache.hadoop.yarn.server.resourcemanager.scheduler.fair.FSAppAttempt: appattempt_1471639269423_0004_000001 minReqResource: <memory:24576, vCores:12> flexibleResource: <memory:-8192, vCores:-4>
2016-08-19 14:47:47,812 INFO org.apache.hadoop.yarn.server.resourcemanager.scheduler.fair.FairScheduler: Cannot allocate resource to appattempt_1471639269423_0004_000001 because there is NO flexible resource left
2016-08-19 14:47:48,286 INFO org.apache.hadoop.yarn.server.resourcemanager.scheduler.fair.FSAppAttempt: assignContainer(FSSchedulerNode node:c220g1-031106.wisc.cloudlab.us, boolean reserved=false) for appattempt_1471639269423_0003_000001
2016-08-19 14:47:48,286 INFO org.apache.hadoop.yarn.server.resourcemanager.scheduler.fair.FSAppAttempt: assignContainer(FSSchedulerNode node:c220g1-031106.wisc.cloudlab.us, boolean reserved=false) for appattempt_1471639269423_0005_000001
2016-08-19 14:47:48,286 INFO org.apache.hadoop.yarn.server.resourcemanager.scheduler.fair.FSAppAttempt: assignContainer(FSSchedulerNode node:c220g1-031106.wisc.cloudlab.us, boolean reserved=false) for appattempt_1471639269423_0004_000001
2016-08-19 14:47:48,286 INFO org.apache.hadoop.yarn.server.resourcemanager.scheduler.fair.FSAppAttempt: assignContainer(FSSchedulerNode node:c220g1-031106.wisc.cloudlab.us, boolean reserved=false) for appattempt_1471639269423_0006_000001
2016-08-19 14:47:48,286 INFO org.apache.hadoop.yarn.server.resourcemanager.scheduler.fair.FSAppAttempt: assignContainer(FSSchedulerNode node:c220g1-031106.wisc.cloudlab.us, boolean reserved=false) for appattempt_1471639269423_0007_000001
2016-08-19 14:47:48,299 INFO org.apache.hadoop.yarn.server.resourcemanager.rmapp.attempt.RMAppAttemptImpl: AMContainerAllocatedTransition.transition(appattempt_1471639269423_0005_000001,EventType: CONTAINER_ALLOCATED)
2016-08-19 14:47:48,299 INFO org.apache.hadoop.yarn.server.resourcemanager.scheduler.fair.FairScheduler: allocate(appattempt_1471639269423_0005_000001 [] [] null null
2016-08-19 14:47:48,299 INFO org.apache.hadoop.yarn.server.resourcemanager.scheduler.fair.FSAppAttempt: appattempt_1471639269423_0005_000001 minReqResource: <memory:24576, vCores:12> flexibleResource: <memory:-8192, vCores:-4>
2016-08-19 14:47:48,299 INFO org.apache.hadoop.yarn.server.resourcemanager.scheduler.fair.FairScheduler: Cannot allocate resource to appattempt_1471639269423_0005_000001 because there is NO flexible resource left
2016-08-19 14:47:48,313 INFO org.apache.hadoop.yarn.server.resourcemanager.rmapp.attempt.RMAppAttemptImpl: AMContainerAllocatedTransition.transition(appattempt_1471639269423_0004_000001,EventType: CONTAINER_ALLOCATED)
2016-08-19 14:47:48,313 INFO org.apache.hadoop.yarn.server.resourcemanager.scheduler.fair.FairScheduler: allocate(appattempt_1471639269423_0004_000001 [] [] null null
2016-08-19 14:47:48,313 INFO org.apache.hadoop.yarn.server.resourcemanager.scheduler.fair.FSAppAttempt: appattempt_1471639269423_0004_000001 minReqResource: <memory:24576, vCores:12> flexibleResource: <memory:-8192, vCores:-4>
2016-08-19 14:47:48,313 INFO org.apache.hadoop.yarn.server.resourcemanager.scheduler.fair.FairScheduler: Cannot allocate resource to appattempt_1471639269423_0004_000001 because there is NO flexible resource left
2016-08-19 14:47:48,319 INFO org.apache.hadoop.yarn.server.resourcemanager.scheduler.fair.FSAppAttempt: assignContainer(FSSchedulerNode node:cp-1.yarn-perf.yarnrm-PG0.wisc.cloudlab.us, boolean reserved=false) for appattempt_1471639269423_0003_000001
2016-08-19 14:47:48,319 INFO org.apache.hadoop.yarn.server.resourcemanager.scheduler.fair.FSAppAttempt: assignContainer(FSSchedulerNode node:cp-1.yarn-perf.yarnrm-PG0.wisc.cloudlab.us, boolean reserved=false) for appattempt_1471639269423_0005_000001
2016-08-19 14:47:48,319 INFO org.apache.hadoop.yarn.server.resourcemanager.scheduler.fair.FSAppAttempt: assignContainer(FSSchedulerNode node:cp-1.yarn-perf.yarnrm-PG0.wisc.cloudlab.us, boolean reserved=false) for appattempt_1471639269423_0004_000001
2016-08-19 14:47:48,319 INFO org.apache.hadoop.yarn.server.resourcemanager.scheduler.fair.FSAppAttempt: assignContainer(FSSchedulerNode node:cp-1.yarn-perf.yarnrm-PG0.wisc.cloudlab.us, boolean reserved=false) for appattempt_1471639269423_0006_000001
2016-08-19 14:47:48,319 INFO org.apache.hadoop.yarn.server.resourcemanager.scheduler.fair.FSAppAttempt: assignContainer(FSSchedulerNode node:cp-1.yarn-perf.yarnrm-PG0.wisc.cloudlab.us, boolean reserved=false) for appattempt_1471639269423_0007_000001
2016-08-19 14:47:48,800 INFO org.apache.hadoop.yarn.server.resourcemanager.rmapp.attempt.RMAppAttemptImpl: AMContainerAllocatedTransition.transition(appattempt_1471639269423_0005_000001,EventType: CONTAINER_ALLOCATED)
2016-08-19 14:47:48,800 INFO org.apache.hadoop.yarn.server.resourcemanager.scheduler.fair.FairScheduler: allocate(appattempt_1471639269423_0005_000001 [] [] null null
2016-08-19 14:47:48,800 INFO org.apache.hadoop.yarn.server.resourcemanager.scheduler.fair.FSAppAttempt: appattempt_1471639269423_0005_000001 minReqResource: <memory:24576, vCores:12> flexibleResource: <memory:-8192, vCores:-4>
2016-08-19 14:47:48,800 INFO org.apache.hadoop.yarn.server.resourcemanager.scheduler.fair.FairScheduler: Cannot allocate resource to appattempt_1471639269423_0005_000001 because there is NO flexible resource left
2016-08-19 14:47:48,814 INFO org.apache.hadoop.yarn.server.resourcemanager.rmapp.attempt.RMAppAttemptImpl: AMContainerAllocatedTransition.transition(appattempt_1471639269423_0004_000001,EventType: CONTAINER_ALLOCATED)
2016-08-19 14:47:48,814 INFO org.apache.hadoop.yarn.server.resourcemanager.scheduler.fair.FairScheduler: allocate(appattempt_1471639269423_0004_000001 [] [] null null
2016-08-19 14:47:48,814 INFO org.apache.hadoop.yarn.server.resourcemanager.scheduler.fair.FSAppAttempt: appattempt_1471639269423_0004_000001 minReqResource: <memory:24576, vCores:12> flexibleResource: <memory:-8192, vCores:-4>
2016-08-19 14:47:48,814 INFO org.apache.hadoop.yarn.server.resourcemanager.scheduler.fair.FairScheduler: Cannot allocate resource to appattempt_1471639269423_0004_000001 because there is NO flexible resource left
2016-08-19 14:47:49,290 INFO org.apache.hadoop.yarn.server.resourcemanager.scheduler.fair.FSAppAttempt: assignContainer(FSSchedulerNode node:c220g1-031106.wisc.cloudlab.us, boolean reserved=false) for appattempt_1471639269423_0003_000001
2016-08-19 14:47:49,291 INFO org.apache.hadoop.yarn.server.resourcemanager.scheduler.fair.FSAppAttempt: assignContainer(FSSchedulerNode node:c220g1-031106.wisc.cloudlab.us, boolean reserved=false) for appattempt_1471639269423_0005_000001
2016-08-19 14:47:49,291 INFO org.apache.hadoop.yarn.server.resourcemanager.scheduler.fair.FSAppAttempt: assignContainer(FSSchedulerNode node:c220g1-031106.wisc.cloudlab.us, boolean reserved=false) for appattempt_1471639269423_0004_000001
2016-08-19 14:47:49,291 INFO org.apache.hadoop.yarn.server.resourcemanager.scheduler.fair.FSAppAttempt: assignContainer(FSSchedulerNode node:c220g1-031106.wisc.cloudlab.us, boolean reserved=false) for appattempt_1471639269423_0006_000001
2016-08-19 14:47:49,291 INFO org.apache.hadoop.yarn.server.resourcemanager.scheduler.fair.FSAppAttempt: assignContainer(FSSchedulerNode node:c220g1-031106.wisc.cloudlab.us, boolean reserved=false) for appattempt_1471639269423_0007_000001
2016-08-19 14:47:49,301 INFO org.apache.hadoop.yarn.server.resourcemanager.rmapp.attempt.RMAppAttemptImpl: AMContainerAllocatedTransition.transition(appattempt_1471639269423_0005_000001,EventType: CONTAINER_ALLOCATED)
2016-08-19 14:47:49,301 INFO org.apache.hadoop.yarn.server.resourcemanager.scheduler.fair.FairScheduler: allocate(appattempt_1471639269423_0005_000001 [] [] null null
2016-08-19 14:47:49,301 INFO org.apache.hadoop.yarn.server.resourcemanager.scheduler.fair.FSAppAttempt: appattempt_1471639269423_0005_000001 minReqResource: <memory:24576, vCores:12> flexibleResource: <memory:-8192, vCores:-4>
2016-08-19 14:47:49,301 INFO org.apache.hadoop.yarn.server.resourcemanager.scheduler.fair.FairScheduler: Cannot allocate resource to appattempt_1471639269423_0005_000001 because there is NO flexible resource left
2016-08-19 14:47:49,315 INFO org.apache.hadoop.yarn.server.resourcemanager.rmapp.attempt.RMAppAttemptImpl: AMContainerAllocatedTransition.transition(appattempt_1471639269423_0004_000001,EventType: CONTAINER_ALLOCATED)
2016-08-19 14:47:49,315 INFO org.apache.hadoop.yarn.server.resourcemanager.scheduler.fair.FairScheduler: allocate(appattempt_1471639269423_0004_000001 [] [] null null
2016-08-19 14:47:49,315 INFO org.apache.hadoop.yarn.server.resourcemanager.scheduler.fair.FSAppAttempt: appattempt_1471639269423_0004_000001 minReqResource: <memory:24576, vCores:12> flexibleResource: <memory:-8192, vCores:-4>
2016-08-19 14:47:49,315 INFO org.apache.hadoop.yarn.server.resourcemanager.scheduler.fair.FairScheduler: Cannot allocate resource to appattempt_1471639269423_0004_000001 because there is NO flexible resource left
2016-08-19 14:47:49,321 INFO org.apache.hadoop.yarn.server.resourcemanager.scheduler.fair.FSAppAttempt: assignContainer(FSSchedulerNode node:cp-1.yarn-perf.yarnrm-PG0.wisc.cloudlab.us, boolean reserved=false) for appattempt_1471639269423_0003_000001
2016-08-19 14:47:49,321 INFO org.apache.hadoop.yarn.server.resourcemanager.scheduler.fair.FSAppAttempt: assignContainer(FSSchedulerNode node:cp-1.yarn-perf.yarnrm-PG0.wisc.cloudlab.us, boolean reserved=false) for appattempt_1471639269423_0005_000001
2016-08-19 14:47:49,321 INFO org.apache.hadoop.yarn.server.resourcemanager.scheduler.fair.FSAppAttempt: assignContainer(FSSchedulerNode node:cp-1.yarn-perf.yarnrm-PG0.wisc.cloudlab.us, boolean reserved=false) for appattempt_1471639269423_0004_000001
2016-08-19 14:47:49,321 INFO org.apache.hadoop.yarn.server.resourcemanager.scheduler.fair.FSAppAttempt: assignContainer(FSSchedulerNode node:cp-1.yarn-perf.yarnrm-PG0.wisc.cloudlab.us, boolean reserved=false) for appattempt_1471639269423_0006_000001
2016-08-19 14:47:49,322 INFO org.apache.hadoop.yarn.server.resourcemanager.scheduler.fair.FSAppAttempt: assignContainer(FSSchedulerNode node:cp-1.yarn-perf.yarnrm-PG0.wisc.cloudlab.us, boolean reserved=false) for appattempt_1471639269423_0007_000001
2016-08-19 14:47:49,612 INFO org.apache.hadoop.yarn.server.resourcemanager.scheduler.fair.FairScheduler: allocate(appattempt_1471639269423_0003_000001 [{Priority: 1, Capability: <memory:1920, vCores:1>, # Containers: 3, Location: *, Relax Locality: true}] [] [] []
2016-08-19 14:47:49,612 INFO org.apache.hadoop.yarn.server.resourcemanager.scheduler.fair.FSAppAttempt: appattempt_1471639269423_0003_000001 minReqResource: <memory:24576, vCores:12> flexibleResource: <memory:-8192, vCores:-4>
2016-08-19 14:47:49,612 INFO org.apache.hadoop.yarn.server.resourcemanager.scheduler.fair.FairScheduler: Cannot allocate resource to appattempt_1471639269423_0003_000001 because there is NO flexible resource left
2016-08-19 14:47:49,802 INFO org.apache.hadoop.yarn.server.resourcemanager.rmapp.attempt.RMAppAttemptImpl: AMContainerAllocatedTransition.transition(appattempt_1471639269423_0005_000001,EventType: CONTAINER_ALLOCATED)
2016-08-19 14:47:49,802 INFO org.apache.hadoop.yarn.server.resourcemanager.scheduler.fair.FairScheduler: allocate(appattempt_1471639269423_0005_000001 [] [] null null
2016-08-19 14:47:49,802 INFO org.apache.hadoop.yarn.server.resourcemanager.scheduler.fair.FSAppAttempt: appattempt_1471639269423_0005_000001 minReqResource: <memory:24576, vCores:12> flexibleResource: <memory:-8192, vCores:-4>
2016-08-19 14:47:49,802 INFO org.apache.hadoop.yarn.server.resourcemanager.scheduler.fair.FairScheduler: Cannot allocate resource to appattempt_1471639269423_0005_000001 because there is NO flexible resource left
2016-08-19 14:47:49,815 INFO org.apache.hadoop.yarn.server.resourcemanager.scheduler.fair.FairScheduler: allocate(appattempt_1471639269423_0003_000001 [] [] [] []
2016-08-19 14:47:49,816 INFO org.apache.hadoop.yarn.server.resourcemanager.scheduler.fair.FSAppAttempt: appattempt_1471639269423_0003_000001 minReqResource: <memory:24576, vCores:12> flexibleResource: <memory:-8192, vCores:-4>
2016-08-19 14:47:49,816 INFO org.apache.hadoop.yarn.server.resourcemanager.scheduler.fair.FairScheduler: Cannot allocate resource to appattempt_1471639269423_0003_000001 because there is NO flexible resource left
2016-08-19 14:47:49,816 INFO org.apache.hadoop.yarn.server.resourcemanager.rmapp.attempt.RMAppAttemptImpl: AMContainerAllocatedTransition.transition(appattempt_1471639269423_0004_000001,EventType: CONTAINER_ALLOCATED)
2016-08-19 14:47:49,816 INFO org.apache.hadoop.yarn.server.resourcemanager.scheduler.fair.FairScheduler: allocate(appattempt_1471639269423_0004_000001 [] [] null null
2016-08-19 14:47:49,816 INFO org.apache.hadoop.yarn.server.resourcemanager.scheduler.fair.FSAppAttempt: appattempt_1471639269423_0004_000001 minReqResource: <memory:24576, vCores:12> flexibleResource: <memory:-8192, vCores:-4>
2016-08-19 14:47:49,816 INFO org.apache.hadoop.yarn.server.resourcemanager.scheduler.fair.FairScheduler: Cannot allocate resource to appattempt_1471639269423_0004_000001 because there is NO flexible resource left
2016-08-19 14:47:50,218 INFO org.apache.hadoop.yarn.server.resourcemanager.scheduler.fair.FairScheduler: allocate(appattempt_1471639269423_0003_000001 [] [] [] []
2016-08-19 14:47:50,219 INFO org.apache.hadoop.yarn.server.resourcemanager.scheduler.fair.FSAppAttempt: appattempt_1471639269423_0003_000001 minReqResource: <memory:24576, vCores:12> flexibleResource: <memory:-8192, vCores:-4>
2016-08-19 14:47:50,219 INFO org.apache.hadoop.yarn.server.resourcemanager.scheduler.fair.FairScheduler: Cannot allocate resource to appattempt_1471639269423_0003_000001 because there is NO flexible resource left
2016-08-19 14:47:50,293 INFO org.apache.hadoop.yarn.server.resourcemanager.scheduler.fair.FSAppAttempt: assignContainer(FSSchedulerNode node:c220g1-031106.wisc.cloudlab.us, boolean reserved=false) for appattempt_1471639269423_0003_000001
2016-08-19 14:47:50,293 INFO org.apache.hadoop.yarn.server.resourcemanager.scheduler.fair.FSAppAttempt: assignContainer(FSSchedulerNode node:c220g1-031106.wisc.cloudlab.us, boolean reserved=false) for appattempt_1471639269423_0005_000001
2016-08-19 14:47:50,293 INFO org.apache.hadoop.yarn.server.resourcemanager.scheduler.fair.FSAppAttempt: assignContainer(FSSchedulerNode node:c220g1-031106.wisc.cloudlab.us, boolean reserved=false) for appattempt_1471639269423_0004_000001
2016-08-19 14:47:50,294 INFO org.apache.hadoop.yarn.server.resourcemanager.scheduler.fair.FSAppAttempt: assignContainer(FSSchedulerNode node:c220g1-031106.wisc.cloudlab.us, boolean reserved=false) for appattempt_1471639269423_0006_000001
2016-08-19 14:47:50,294 INFO org.apache.hadoop.yarn.server.resourcemanager.scheduler.fair.FSAppAttempt: assignContainer(FSSchedulerNode node:c220g1-031106.wisc.cloudlab.us, boolean reserved=false) for appattempt_1471639269423_0007_000001
2016-08-19 14:47:50,304 INFO org.apache.hadoop.yarn.server.resourcemanager.rmapp.attempt.RMAppAttemptImpl: AMContainerAllocatedTransition.transition(appattempt_1471639269423_0005_000001,EventType: CONTAINER_ALLOCATED)
2016-08-19 14:47:50,304 INFO org.apache.hadoop.yarn.server.resourcemanager.scheduler.fair.FairScheduler: allocate(appattempt_1471639269423_0005_000001 [] [] null null
2016-08-19 14:47:50,304 INFO org.apache.hadoop.yarn.server.resourcemanager.scheduler.fair.FSAppAttempt: appattempt_1471639269423_0005_000001 minReqResource: <memory:24576, vCores:12> flexibleResource: <memory:-8192, vCores:-4>
2016-08-19 14:47:50,304 INFO org.apache.hadoop.yarn.server.resourcemanager.scheduler.fair.FairScheduler: Cannot allocate resource to appattempt_1471639269423_0005_000001 because there is NO flexible resource left
2016-08-19 14:47:50,317 INFO org.apache.hadoop.yarn.server.resourcemanager.rmapp.attempt.RMAppAttemptImpl: AMContainerAllocatedTransition.transition(appattempt_1471639269423_0004_000001,EventType: CONTAINER_ALLOCATED)
2016-08-19 14:47:50,317 INFO org.apache.hadoop.yarn.server.resourcemanager.scheduler.fair.FairScheduler: allocate(appattempt_1471639269423_0004_000001 [] [] null null
2016-08-19 14:47:50,317 INFO org.apache.hadoop.yarn.server.resourcemanager.scheduler.fair.FSAppAttempt: appattempt_1471639269423_0004_000001 minReqResource: <memory:24576, vCores:12> flexibleResource: <memory:-8192, vCores:-4>
2016-08-19 14:47:50,317 INFO org.apache.hadoop.yarn.server.resourcemanager.scheduler.fair.FairScheduler: Cannot allocate resource to appattempt_1471639269423_0004_000001 because there is NO flexible resource left
2016-08-19 14:47:50,323 INFO org.apache.hadoop.yarn.server.resourcemanager.scheduler.fair.FSAppAttempt: assignContainer(FSSchedulerNode node:cp-1.yarn-perf.yarnrm-PG0.wisc.cloudlab.us, boolean reserved=false) for appattempt_1471639269423_0003_000001
2016-08-19 14:47:50,323 INFO org.apache.hadoop.yarn.server.resourcemanager.scheduler.fair.FSAppAttempt: assignContainer(FSSchedulerNode node:cp-1.yarn-perf.yarnrm-PG0.wisc.cloudlab.us, boolean reserved=false) for appattempt_1471639269423_0005_000001
2016-08-19 14:47:50,324 INFO org.apache.hadoop.yarn.server.resourcemanager.scheduler.fair.FSAppAttempt: assignContainer(FSSchedulerNode node:cp-1.yarn-perf.yarnrm-PG0.wisc.cloudlab.us, boolean reserved=false) for appattempt_1471639269423_0004_000001
2016-08-19 14:47:50,324 INFO org.apache.hadoop.yarn.server.resourcemanager.scheduler.fair.FSAppAttempt: assignContainer(FSSchedulerNode node:cp-1.yarn-perf.yarnrm-PG0.wisc.cloudlab.us, boolean reserved=false) for appattempt_1471639269423_0006_000001
2016-08-19 14:47:50,324 INFO org.apache.hadoop.yarn.server.resourcemanager.scheduler.fair.FSAppAttempt: assignContainer(FSSchedulerNode node:cp-1.yarn-perf.yarnrm-PG0.wisc.cloudlab.us, boolean reserved=false) for appattempt_1471639269423_0007_000001
2016-08-19 14:47:50,805 INFO org.apache.hadoop.yarn.server.resourcemanager.rmapp.attempt.RMAppAttemptImpl: AMContainerAllocatedTransition.transition(appattempt_1471639269423_0005_000001,EventType: CONTAINER_ALLOCATED)
2016-08-19 14:47:50,805 INFO org.apache.hadoop.yarn.server.resourcemanager.scheduler.fair.FairScheduler: allocate(appattempt_1471639269423_0005_000001 [] [] null null
2016-08-19 14:47:50,805 INFO org.apache.hadoop.yarn.server.resourcemanager.scheduler.fair.FSAppAttempt: appattempt_1471639269423_0005_000001 minReqResource: <memory:24576, vCores:12> flexibleResource: <memory:-8192, vCores:-4>
2016-08-19 14:47:50,805 INFO org.apache.hadoop.yarn.server.resourcemanager.scheduler.fair.FairScheduler: Cannot allocate resource to appattempt_1471639269423_0005_000001 because there is NO flexible resource left
2016-08-19 14:47:50,818 INFO org.apache.hadoop.yarn.server.resourcemanager.rmapp.attempt.RMAppAttemptImpl: AMContainerAllocatedTransition.transition(appattempt_1471639269423_0004_000001,EventType: CONTAINER_ALLOCATED)
2016-08-19 14:47:50,818 INFO org.apache.hadoop.yarn.server.resourcemanager.scheduler.fair.FairScheduler: allocate(appattempt_1471639269423_0004_000001 [] [] null null
2016-08-19 14:47:50,818 INFO org.apache.hadoop.yarn.server.resourcemanager.scheduler.fair.FSAppAttempt: appattempt_1471639269423_0004_000001 minReqResource: <memory:24576, vCores:12> flexibleResource: <memory:-8192, vCores:-4>
2016-08-19 14:47:50,818 INFO org.apache.hadoop.yarn.server.resourcemanager.scheduler.fair.FairScheduler: Cannot allocate resource to appattempt_1471639269423_0004_000001 because there is NO flexible resource left
2016-08-19 14:47:51,021 INFO org.apache.hadoop.yarn.server.resourcemanager.scheduler.fair.FairScheduler: allocate(appattempt_1471639269423_0003_000001 [] [] [] []
2016-08-19 14:47:51,022 INFO org.apache.hadoop.yarn.server.resourcemanager.scheduler.fair.FSAppAttempt: appattempt_1471639269423_0003_000001 minReqResource: <memory:24576, vCores:12> flexibleResource: <memory:-8192, vCores:-4>
2016-08-19 14:47:51,022 INFO org.apache.hadoop.yarn.server.resourcemanager.scheduler.fair.FairScheduler: Cannot allocate resource to appattempt_1471639269423_0003_000001 because there is NO flexible resource left
2016-08-19 14:47:51,296 INFO org.apache.hadoop.yarn.server.resourcemanager.scheduler.fair.FSAppAttempt: assignContainer(FSSchedulerNode node:c220g1-031106.wisc.cloudlab.us, boolean reserved=false) for appattempt_1471639269423_0003_000001
2016-08-19 14:47:51,297 INFO org.apache.hadoop.yarn.server.resourcemanager.scheduler.fair.FSAppAttempt: assignContainer(FSSchedulerNode node:c220g1-031106.wisc.cloudlab.us, boolean reserved=false) for appattempt_1471639269423_0005_000001
2016-08-19 14:47:51,297 INFO org.apache.hadoop.yarn.server.resourcemanager.scheduler.fair.FSAppAttempt: assignContainer(FSSchedulerNode node:c220g1-031106.wisc.cloudlab.us, boolean reserved=false) for appattempt_1471639269423_0004_000001
2016-08-19 14:47:51,297 INFO org.apache.hadoop.yarn.server.resourcemanager.scheduler.fair.FSAppAttempt: assignContainer(FSSchedulerNode node:c220g1-031106.wisc.cloudlab.us, boolean reserved=false) for appattempt_1471639269423_0006_000001
2016-08-19 14:47:51,297 INFO org.apache.hadoop.yarn.server.resourcemanager.scheduler.fair.FSAppAttempt: assignContainer(FSSchedulerNode node:c220g1-031106.wisc.cloudlab.us, boolean reserved=false) for appattempt_1471639269423_0007_000001
2016-08-19 14:47:51,306 INFO org.apache.hadoop.yarn.server.resourcemanager.rmapp.attempt.RMAppAttemptImpl: AMContainerAllocatedTransition.transition(appattempt_1471639269423_0005_000001,EventType: CONTAINER_ALLOCATED)
2016-08-19 14:47:51,306 INFO org.apache.hadoop.yarn.server.resourcemanager.scheduler.fair.FairScheduler: allocate(appattempt_1471639269423_0005_000001 [] [] null null
2016-08-19 14:47:51,306 INFO org.apache.hadoop.yarn.server.resourcemanager.scheduler.fair.FSAppAttempt: appattempt_1471639269423_0005_000001 minReqResource: <memory:24576, vCores:12> flexibleResource: <memory:-8192, vCores:-4>
2016-08-19 14:47:51,306 INFO org.apache.hadoop.yarn.server.resourcemanager.scheduler.fair.FairScheduler: Cannot allocate resource to appattempt_1471639269423_0005_000001 because there is NO flexible resource left
2016-08-19 14:47:51,318 INFO org.apache.hadoop.yarn.server.resourcemanager.rmapp.attempt.RMAppAttemptImpl: AMContainerAllocatedTransition.transition(appattempt_1471639269423_0004_000001,EventType: CONTAINER_ALLOCATED)
2016-08-19 14:47:51,319 INFO org.apache.hadoop.yarn.server.resourcemanager.scheduler.fair.FairScheduler: allocate(appattempt_1471639269423_0004_000001 [] [] null null
2016-08-19 14:47:51,319 INFO org.apache.hadoop.yarn.server.resourcemanager.scheduler.fair.FSAppAttempt: appattempt_1471639269423_0004_000001 minReqResource: <memory:24576, vCores:12> flexibleResource: <memory:-8192, vCores:-4>
2016-08-19 14:47:51,319 INFO org.apache.hadoop.yarn.server.resourcemanager.scheduler.fair.FairScheduler: Cannot allocate resource to appattempt_1471639269423_0004_000001 because there is NO flexible resource left
2016-08-19 14:47:51,325 INFO org.apache.hadoop.yarn.server.resourcemanager.scheduler.fair.FSAppAttempt: assignContainer(FSSchedulerNode node:cp-1.yarn-perf.yarnrm-PG0.wisc.cloudlab.us, boolean reserved=false) for appattempt_1471639269423_0003_000001
2016-08-19 14:47:51,326 INFO org.apache.hadoop.yarn.server.resourcemanager.scheduler.fair.FSAppAttempt: assignContainer(FSSchedulerNode node:cp-1.yarn-perf.yarnrm-PG0.wisc.cloudlab.us, boolean reserved=false) for appattempt_1471639269423_0005_000001
2016-08-19 14:47:51,326 INFO org.apache.hadoop.yarn.server.resourcemanager.scheduler.fair.FSAppAttempt: assignContainer(FSSchedulerNode node:cp-1.yarn-perf.yarnrm-PG0.wisc.cloudlab.us, boolean reserved=false) for appattempt_1471639269423_0004_000001
2016-08-19 14:47:51,326 INFO org.apache.hadoop.yarn.server.resourcemanager.scheduler.fair.FSAppAttempt: assignContainer(FSSchedulerNode node:cp-1.yarn-perf.yarnrm-PG0.wisc.cloudlab.us, boolean reserved=false) for appattempt_1471639269423_0006_000001
2016-08-19 14:47:51,326 INFO org.apache.hadoop.yarn.server.resourcemanager.scheduler.fair.FSAppAttempt: assignContainer(FSSchedulerNode node:cp-1.yarn-perf.yarnrm-PG0.wisc.cloudlab.us, boolean reserved=false) for appattempt_1471639269423_0007_000001
2016-08-19 14:47:51,807 INFO org.apache.hadoop.yarn.server.resourcemanager.rmapp.attempt.RMAppAttemptImpl: AMContainerAllocatedTransition.transition(appattempt_1471639269423_0005_000001,EventType: CONTAINER_ALLOCATED)
2016-08-19 14:47:51,807 INFO org.apache.hadoop.yarn.server.resourcemanager.scheduler.fair.FairScheduler: allocate(appattempt_1471639269423_0005_000001 [] [] null null
2016-08-19 14:47:51,807 INFO org.apache.hadoop.yarn.server.resourcemanager.scheduler.fair.FSAppAttempt: appattempt_1471639269423_0005_000001 minReqResource: <memory:24576, vCores:12> flexibleResource: <memory:-8192, vCores:-4>
2016-08-19 14:47:51,807 INFO org.apache.hadoop.yarn.server.resourcemanager.scheduler.fair.FairScheduler: Cannot allocate resource to appattempt_1471639269423_0005_000001 because there is NO flexible resource left
2016-08-19 14:47:51,819 INFO org.apache.hadoop.yarn.server.resourcemanager.rmapp.attempt.RMAppAttemptImpl: AMContainerAllocatedTransition.transition(appattempt_1471639269423_0004_000001,EventType: CONTAINER_ALLOCATED)
2016-08-19 14:47:51,819 INFO org.apache.hadoop.yarn.server.resourcemanager.scheduler.fair.FairScheduler: allocate(appattempt_1471639269423_0004_000001 [] [] null null
2016-08-19 14:47:51,820 INFO org.apache.hadoop.yarn.server.resourcemanager.scheduler.fair.FSAppAttempt: appattempt_1471639269423_0004_000001 minReqResource: <memory:24576, vCores:12> flexibleResource: <memory:-8192, vCores:-4>
2016-08-19 14:47:51,820 INFO org.apache.hadoop.yarn.server.resourcemanager.scheduler.fair.FairScheduler: Cannot allocate resource to appattempt_1471639269423_0004_000001 because there is NO flexible resource left
2016-08-19 14:47:52,299 INFO org.apache.hadoop.yarn.server.resourcemanager.scheduler.fair.FSAppAttempt: assignContainer(FSSchedulerNode node:c220g1-031106.wisc.cloudlab.us, boolean reserved=false) for appattempt_1471639269423_0003_000001
2016-08-19 14:47:52,300 INFO org.apache.hadoop.yarn.server.resourcemanager.scheduler.fair.FSAppAttempt: assignContainer(FSSchedulerNode node:c220g1-031106.wisc.cloudlab.us, boolean reserved=false) for appattempt_1471639269423_0005_000001
2016-08-19 14:47:52,300 INFO org.apache.hadoop.yarn.server.resourcemanager.scheduler.fair.FSAppAttempt: assignContainer(FSSchedulerNode node:c220g1-031106.wisc.cloudlab.us, boolean reserved=false) for appattempt_1471639269423_0004_000001
2016-08-19 14:47:52,300 INFO org.apache.hadoop.yarn.server.resourcemanager.scheduler.fair.FSAppAttempt: assignContainer(FSSchedulerNode node:c220g1-031106.wisc.cloudlab.us, boolean reserved=false) for appattempt_1471639269423_0006_000001
2016-08-19 14:47:52,300 INFO org.apache.hadoop.yarn.server.resourcemanager.scheduler.fair.FSAppAttempt: assignContainer(FSSchedulerNode node:c220g1-031106.wisc.cloudlab.us, boolean reserved=false) for appattempt_1471639269423_0007_000001
2016-08-19 14:47:52,308 INFO org.apache.hadoop.yarn.server.resourcemanager.rmapp.attempt.RMAppAttemptImpl: AMContainerAllocatedTransition.transition(appattempt_1471639269423_0005_000001,EventType: CONTAINER_ALLOCATED)
2016-08-19 14:47:52,308 INFO org.apache.hadoop.yarn.server.resourcemanager.scheduler.fair.FairScheduler: allocate(appattempt_1471639269423_0005_000001 [] [] null null
2016-08-19 14:47:52,308 INFO org.apache.hadoop.yarn.server.resourcemanager.scheduler.fair.FSAppAttempt: appattempt_1471639269423_0005_000001 minReqResource: <memory:24576, vCores:12> flexibleResource: <memory:-8192, vCores:-4>
2016-08-19 14:47:52,308 INFO org.apache.hadoop.yarn.server.resourcemanager.scheduler.fair.FairScheduler: Cannot allocate resource to appattempt_1471639269423_0005_000001 because there is NO flexible resource left
2016-08-19 14:47:52,320 INFO org.apache.hadoop.yarn.server.resourcemanager.rmapp.attempt.RMAppAttemptImpl: AMContainerAllocatedTransition.transition(appattempt_1471639269423_0004_000001,EventType: CONTAINER_ALLOCATED)
2016-08-19 14:47:52,320 INFO org.apache.hadoop.yarn.server.resourcemanager.scheduler.fair.FairScheduler: allocate(appattempt_1471639269423_0004_000001 [] [] null null
2016-08-19 14:47:52,321 INFO org.apache.hadoop.yarn.server.resourcemanager.scheduler.fair.FSAppAttempt: appattempt_1471639269423_0004_000001 minReqResource: <memory:24576, vCores:12> flexibleResource: <memory:-8192, vCores:-4>
2016-08-19 14:47:52,321 INFO org.apache.hadoop.yarn.server.resourcemanager.scheduler.fair.FairScheduler: Cannot allocate resource to appattempt_1471639269423_0004_000001 because there is NO flexible resource left
2016-08-19 14:47:52,328 INFO org.apache.hadoop.yarn.server.resourcemanager.scheduler.fair.FSAppAttempt: assignContainer(FSSchedulerNode node:cp-1.yarn-perf.yarnrm-PG0.wisc.cloudlab.us, boolean reserved=false) for appattempt_1471639269423_0003_000001
2016-08-19 14:47:52,328 INFO org.apache.hadoop.yarn.server.resourcemanager.scheduler.fair.FSAppAttempt: assignContainer(FSSchedulerNode node:cp-1.yarn-perf.yarnrm-PG0.wisc.cloudlab.us, boolean reserved=false) for appattempt_1471639269423_0005_000001
2016-08-19 14:47:52,328 INFO org.apache.hadoop.yarn.server.resourcemanager.scheduler.fair.FSAppAttempt: assignContainer(FSSchedulerNode node:cp-1.yarn-perf.yarnrm-PG0.wisc.cloudlab.us, boolean reserved=false) for appattempt_1471639269423_0004_000001
2016-08-19 14:47:52,328 INFO org.apache.hadoop.yarn.server.resourcemanager.scheduler.fair.FSAppAttempt: assignContainer(FSSchedulerNode node:cp-1.yarn-perf.yarnrm-PG0.wisc.cloudlab.us, boolean reserved=false) for appattempt_1471639269423_0006_000001
2016-08-19 14:47:52,328 INFO org.apache.hadoop.yarn.server.resourcemanager.scheduler.fair.FSAppAttempt: assignContainer(FSSchedulerNode node:cp-1.yarn-perf.yarnrm-PG0.wisc.cloudlab.us, boolean reserved=false) for appattempt_1471639269423_0007_000001
2016-08-19 14:47:52,625 INFO org.apache.hadoop.yarn.server.resourcemanager.scheduler.fair.FairScheduler: allocate(appattempt_1471639269423_0003_000001 [] [] [] []
2016-08-19 14:47:52,625 INFO org.apache.hadoop.yarn.server.resourcemanager.scheduler.fair.FSAppAttempt: appattempt_1471639269423_0003_000001 minReqResource: <memory:24576, vCores:12> flexibleResource: <memory:-8192, vCores:-4>
2016-08-19 14:47:52,625 INFO org.apache.hadoop.yarn.server.resourcemanager.scheduler.fair.FairScheduler: Cannot allocate resource to appattempt_1471639269423_0003_000001 because there is NO flexible resource left
2016-08-19 14:47:52,809 INFO org.apache.hadoop.yarn.server.resourcemanager.rmapp.attempt.RMAppAttemptImpl: AMContainerAllocatedTransition.transition(appattempt_1471639269423_0005_000001,EventType: CONTAINER_ALLOCATED)
2016-08-19 14:47:52,809 INFO org.apache.hadoop.yarn.server.resourcemanager.scheduler.fair.FairScheduler: allocate(appattempt_1471639269423_0005_000001 [] [] null null
2016-08-19 14:47:52,809 INFO org.apache.hadoop.yarn.server.resourcemanager.scheduler.fair.FSAppAttempt: appattempt_1471639269423_0005_000001 minReqResource: <memory:24576, vCores:12> flexibleResource: <memory:-8192, vCores:-4>
2016-08-19 14:47:52,809 INFO org.apache.hadoop.yarn.server.resourcemanager.scheduler.fair.FairScheduler: Cannot allocate resource to appattempt_1471639269423_0005_000001 because there is NO flexible resource left
2016-08-19 14:47:52,821 INFO org.apache.hadoop.yarn.server.resourcemanager.rmapp.attempt.RMAppAttemptImpl: AMContainerAllocatedTransition.transition(appattempt_1471639269423_0004_000001,EventType: CONTAINER_ALLOCATED)
2016-08-19 14:47:52,821 INFO org.apache.hadoop.yarn.server.resourcemanager.scheduler.fair.FairScheduler: allocate(appattempt_1471639269423_0004_000001 [] [] null null
2016-08-19 14:47:52,822 INFO org.apache.hadoop.yarn.server.resourcemanager.scheduler.fair.FSAppAttempt: appattempt_1471639269423_0004_000001 minReqResource: <memory:24576, vCores:12> flexibleResource: <memory:-8192, vCores:-4>
2016-08-19 14:47:52,822 INFO org.apache.hadoop.yarn.server.resourcemanager.scheduler.fair.FairScheduler: Cannot allocate resource to appattempt_1471639269423_0004_000001 because there is NO flexible resource left
2016-08-19 14:47:53,303 INFO org.apache.hadoop.yarn.server.resourcemanager.scheduler.fair.FSAppAttempt: assignContainer(FSSchedulerNode node:c220g1-031106.wisc.cloudlab.us, boolean reserved=false) for appattempt_1471639269423_0003_000001
2016-08-19 14:47:53,303 INFO org.apache.hadoop.yarn.server.resourcemanager.scheduler.fair.FSAppAttempt: assignContainer(FSSchedulerNode node:c220g1-031106.wisc.cloudlab.us, boolean reserved=false) for appattempt_1471639269423_0005_000001
2016-08-19 14:47:53,303 INFO org.apache.hadoop.yarn.server.resourcemanager.scheduler.fair.FSAppAttempt: assignContainer(FSSchedulerNode node:c220g1-031106.wisc.cloudlab.us, boolean reserved=false) for appattempt_1471639269423_0004_000001
2016-08-19 14:47:53,303 INFO org.apache.hadoop.yarn.server.resourcemanager.scheduler.fair.FSAppAttempt: assignContainer(FSSchedulerNode node:c220g1-031106.wisc.cloudlab.us, boolean reserved=false) for appattempt_1471639269423_0006_000001
2016-08-19 14:47:53,303 INFO org.apache.hadoop.yarn.server.resourcemanager.scheduler.fair.FSAppAttempt: assignContainer(FSSchedulerNode node:c220g1-031106.wisc.cloudlab.us, boolean reserved=false) for appattempt_1471639269423_0007_000001
2016-08-19 14:47:53,310 INFO org.apache.hadoop.yarn.server.resourcemanager.rmapp.attempt.RMAppAttemptImpl: AMContainerAllocatedTransition.transition(appattempt_1471639269423_0005_000001,EventType: CONTAINER_ALLOCATED)
2016-08-19 14:47:53,310 INFO org.apache.hadoop.yarn.server.resourcemanager.scheduler.fair.FairScheduler: allocate(appattempt_1471639269423_0005_000001 [] [] null null
2016-08-19 14:47:53,310 INFO org.apache.hadoop.yarn.server.resourcemanager.scheduler.fair.FSAppAttempt: appattempt_1471639269423_0005_000001 minReqResource: <memory:24576, vCores:12> flexibleResource: <memory:-8192, vCores:-4>
2016-08-19 14:47:53,310 INFO org.apache.hadoop.yarn.server.resourcemanager.scheduler.fair.FairScheduler: Cannot allocate resource to appattempt_1471639269423_0005_000001 because there is NO flexible resource left
2016-08-19 14:47:53,322 INFO org.apache.hadoop.yarn.server.resourcemanager.rmapp.attempt.RMAppAttemptImpl: AMContainerAllocatedTransition.transition(appattempt_1471639269423_0004_000001,EventType: CONTAINER_ALLOCATED)
2016-08-19 14:47:53,322 INFO org.apache.hadoop.yarn.server.resourcemanager.scheduler.fair.FairScheduler: allocate(appattempt_1471639269423_0004_000001 [] [] null null
2016-08-19 14:47:53,322 INFO org.apache.hadoop.yarn.server.resourcemanager.scheduler.fair.FSAppAttempt: appattempt_1471639269423_0004_000001 minReqResource: <memory:24576, vCores:12> flexibleResource: <memory:-8192, vCores:-4>
2016-08-19 14:47:53,322 INFO org.apache.hadoop.yarn.server.resourcemanager.scheduler.fair.FairScheduler: Cannot allocate resource to appattempt_1471639269423_0004_000001 because there is NO flexible resource left
2016-08-19 14:47:53,330 INFO org.apache.hadoop.yarn.server.resourcemanager.scheduler.fair.FSAppAttempt: assignContainer(FSSchedulerNode node:cp-1.yarn-perf.yarnrm-PG0.wisc.cloudlab.us, boolean reserved=false) for appattempt_1471639269423_0003_000001
2016-08-19 14:47:53,330 INFO org.apache.hadoop.yarn.server.resourcemanager.scheduler.fair.FSAppAttempt: assignContainer(FSSchedulerNode node:cp-1.yarn-perf.yarnrm-PG0.wisc.cloudlab.us, boolean reserved=false) for appattempt_1471639269423_0005_000001
2016-08-19 14:47:53,330 INFO org.apache.hadoop.yarn.server.resourcemanager.scheduler.fair.FSAppAttempt: assignContainer(FSSchedulerNode node:cp-1.yarn-perf.yarnrm-PG0.wisc.cloudlab.us, boolean reserved=false) for appattempt_1471639269423_0004_000001
2016-08-19 14:47:53,330 INFO org.apache.hadoop.yarn.server.resourcemanager.scheduler.fair.FSAppAttempt: assignContainer(FSSchedulerNode node:cp-1.yarn-perf.yarnrm-PG0.wisc.cloudlab.us, boolean reserved=false) for appattempt_1471639269423_0006_000001
2016-08-19 14:47:53,331 INFO org.apache.hadoop.yarn.server.resourcemanager.scheduler.fair.FSAppAttempt: assignContainer(FSSchedulerNode node:cp-1.yarn-perf.yarnrm-PG0.wisc.cloudlab.us, boolean reserved=false) for appattempt_1471639269423_0007_000001
2016-08-19 14:47:53,811 INFO org.apache.hadoop.yarn.server.resourcemanager.rmapp.attempt.RMAppAttemptImpl: AMContainerAllocatedTransition.transition(appattempt_1471639269423_0005_000001,EventType: CONTAINER_ALLOCATED)
2016-08-19 14:47:53,811 INFO org.apache.hadoop.yarn.server.resourcemanager.scheduler.fair.FairScheduler: allocate(appattempt_1471639269423_0005_000001 [] [] null null
2016-08-19 14:47:53,811 INFO org.apache.hadoop.yarn.server.resourcemanager.scheduler.fair.FSAppAttempt: appattempt_1471639269423_0005_000001 minReqResource: <memory:24576, vCores:12> flexibleResource: <memory:-8192, vCores:-4>
2016-08-19 14:47:53,811 INFO org.apache.hadoop.yarn.server.resourcemanager.scheduler.fair.FairScheduler: Cannot allocate resource to appattempt_1471639269423_0005_000001 because there is NO flexible resource left
2016-08-19 14:47:53,823 INFO org.apache.hadoop.yarn.server.resourcemanager.rmapp.attempt.RMAppAttemptImpl: AMContainerAllocatedTransition.transition(appattempt_1471639269423_0004_000001,EventType: CONTAINER_ALLOCATED)
2016-08-19 14:47:53,823 INFO org.apache.hadoop.yarn.server.resourcemanager.scheduler.fair.FairScheduler: allocate(appattempt_1471639269423_0004_000001 [] [] null null
2016-08-19 14:47:53,823 INFO org.apache.hadoop.yarn.server.resourcemanager.scheduler.fair.FSAppAttempt: appattempt_1471639269423_0004_000001 minReqResource: <memory:24576, vCores:12> flexibleResource: <memory:-8192, vCores:-4>
2016-08-19 14:47:53,823 INFO org.apache.hadoop.yarn.server.resourcemanager.scheduler.fair.FairScheduler: Cannot allocate resource to appattempt_1471639269423_0004_000001 because there is NO flexible resource left
2016-08-19 14:47:54,305 INFO org.apache.hadoop.yarn.server.resourcemanager.scheduler.fair.FSAppAttempt: assignContainer(FSSchedulerNode node:c220g1-031106.wisc.cloudlab.us, boolean reserved=false) for appattempt_1471639269423_0003_000001
2016-08-19 14:47:54,306 INFO org.apache.hadoop.yarn.server.resourcemanager.scheduler.fair.FSAppAttempt: assignContainer(FSSchedulerNode node:c220g1-031106.wisc.cloudlab.us, boolean reserved=false) for appattempt_1471639269423_0005_000001
2016-08-19 14:47:54,306 INFO org.apache.hadoop.yarn.server.resourcemanager.scheduler.fair.FSAppAttempt: assignContainer(FSSchedulerNode node:c220g1-031106.wisc.cloudlab.us, boolean reserved=false) for appattempt_1471639269423_0004_000001
2016-08-19 14:47:54,306 INFO org.apache.hadoop.yarn.server.resourcemanager.scheduler.fair.FSAppAttempt: assignContainer(FSSchedulerNode node:c220g1-031106.wisc.cloudlab.us, boolean reserved=false) for appattempt_1471639269423_0006_000001
2016-08-19 14:47:54,306 INFO org.apache.hadoop.yarn.server.resourcemanager.scheduler.fair.FSAppAttempt: assignContainer(FSSchedulerNode node:c220g1-031106.wisc.cloudlab.us, boolean reserved=false) for appattempt_1471639269423_0007_000001
2016-08-19 14:47:54,312 INFO org.apache.hadoop.yarn.server.resourcemanager.rmapp.attempt.RMAppAttemptImpl: AMContainerAllocatedTransition.transition(appattempt_1471639269423_0005_000001,EventType: CONTAINER_ALLOCATED)
2016-08-19 14:47:54,312 INFO org.apache.hadoop.yarn.server.resourcemanager.scheduler.fair.FairScheduler: allocate(appattempt_1471639269423_0005_000001 [] [] null null
2016-08-19 14:47:54,313 INFO org.apache.hadoop.yarn.server.resourcemanager.scheduler.fair.FSAppAttempt: appattempt_1471639269423_0005_000001 minReqResource: <memory:24576, vCores:12> flexibleResource: <memory:-8192, vCores:-4>
2016-08-19 14:47:54,313 INFO org.apache.hadoop.yarn.server.resourcemanager.scheduler.fair.FairScheduler: Cannot allocate resource to appattempt_1471639269423_0005_000001 because there is NO flexible resource left
2016-08-19 14:47:54,324 INFO org.apache.hadoop.yarn.server.resourcemanager.rmapp.attempt.RMAppAttemptImpl: AMContainerAllocatedTransition.transition(appattempt_1471639269423_0004_000001,EventType: CONTAINER_ALLOCATED)
2016-08-19 14:47:54,324 INFO org.apache.hadoop.yarn.server.resourcemanager.scheduler.fair.FairScheduler: allocate(appattempt_1471639269423_0004_000001 [] [] null null
2016-08-19 14:47:54,324 INFO org.apache.hadoop.yarn.server.resourcemanager.scheduler.fair.FSAppAttempt: appattempt_1471639269423_0004_000001 minReqResource: <memory:24576, vCores:12> flexibleResource: <memory:-8192, vCores:-4>
2016-08-19 14:47:54,324 INFO org.apache.hadoop.yarn.server.resourcemanager.scheduler.fair.FairScheduler: Cannot allocate resource to appattempt_1471639269423_0004_000001 because there is NO flexible resource left
2016-08-19 14:47:54,332 INFO org.apache.hadoop.yarn.server.resourcemanager.scheduler.fair.FSAppAttempt: assignContainer(FSSchedulerNode node:cp-1.yarn-perf.yarnrm-PG0.wisc.cloudlab.us, boolean reserved=false) for appattempt_1471639269423_0003_000001
2016-08-19 14:47:54,332 INFO org.apache.hadoop.yarn.server.resourcemanager.scheduler.fair.FSAppAttempt: assignContainer(FSSchedulerNode node:cp-1.yarn-perf.yarnrm-PG0.wisc.cloudlab.us, boolean reserved=false) for appattempt_1471639269423_0005_000001
2016-08-19 14:47:54,333 INFO org.apache.hadoop.yarn.server.resourcemanager.scheduler.fair.FSAppAttempt: assignContainer(FSSchedulerNode node:cp-1.yarn-perf.yarnrm-PG0.wisc.cloudlab.us, boolean reserved=false) for appattempt_1471639269423_0004_000001
2016-08-19 14:47:54,333 INFO org.apache.hadoop.yarn.server.resourcemanager.scheduler.fair.FSAppAttempt: assignContainer(FSSchedulerNode node:cp-1.yarn-perf.yarnrm-PG0.wisc.cloudlab.us, boolean reserved=false) for appattempt_1471639269423_0006_000001
2016-08-19 14:47:54,333 INFO org.apache.hadoop.yarn.server.resourcemanager.scheduler.fair.FSAppAttempt: assignContainer(FSSchedulerNode node:cp-1.yarn-perf.yarnrm-PG0.wisc.cloudlab.us, boolean reserved=false) for appattempt_1471639269423_0007_000001
2016-08-19 14:47:54,612 INFO org.apache.hadoop.yarn.server.resourcemanager.scheduler.fair.FairScheduler: allocate(appattempt_1471639269423_0003_000001 [{Priority: 1, Capability: <memory:1920, vCores:1>, # Containers: 7, Location: *, Relax Locality: true}] [] [] []
2016-08-19 14:47:54,612 INFO org.apache.hadoop.yarn.server.resourcemanager.scheduler.fair.FSAppAttempt: appattempt_1471639269423_0003_000001 minReqResource: <memory:24576, vCores:12> flexibleResource: <memory:-8192, vCores:-4>
2016-08-19 14:47:54,612 INFO org.apache.hadoop.yarn.server.resourcemanager.scheduler.fair.FairScheduler: Cannot allocate resource to appattempt_1471639269423_0003_000001 because there is NO flexible resource left
2016-08-19 14:47:54,813 INFO org.apache.hadoop.yarn.server.resourcemanager.rmapp.attempt.RMAppAttemptImpl: AMContainerAllocatedTransition.transition(appattempt_1471639269423_0005_000001,EventType: CONTAINER_ALLOCATED)
2016-08-19 14:47:54,813 INFO org.apache.hadoop.yarn.server.resourcemanager.scheduler.fair.FairScheduler: allocate(appattempt_1471639269423_0005_000001 [] [] null null
2016-08-19 14:47:54,813 INFO org.apache.hadoop.yarn.server.resourcemanager.scheduler.fair.FSAppAttempt: appattempt_1471639269423_0005_000001 minReqResource: <memory:24576, vCores:12> flexibleResource: <memory:-8192, vCores:-4>
2016-08-19 14:47:54,814 INFO org.apache.hadoop.yarn.server.resourcemanager.scheduler.fair.FairScheduler: Cannot allocate resource to appattempt_1471639269423_0005_000001 because there is NO flexible resource left
2016-08-19 14:47:54,815 INFO org.apache.hadoop.yarn.server.resourcemanager.scheduler.fair.FairScheduler: allocate(appattempt_1471639269423_0003_000001 [] [] [] []
2016-08-19 14:47:54,816 INFO org.apache.hadoop.yarn.server.resourcemanager.scheduler.fair.FSAppAttempt: appattempt_1471639269423_0003_000001 minReqResource: <memory:24576, vCores:12> flexibleResource: <memory:-8192, vCores:-4>
2016-08-19 14:47:54,816 INFO org.apache.hadoop.yarn.server.resourcemanager.scheduler.fair.FairScheduler: Cannot allocate resource to appattempt_1471639269423_0003_000001 because there is NO flexible resource left
2016-08-19 14:47:54,825 INFO org.apache.hadoop.yarn.server.resourcemanager.rmapp.attempt.RMAppAttemptImpl: AMContainerAllocatedTransition.transition(appattempt_1471639269423_0004_000001,EventType: CONTAINER_ALLOCATED)
2016-08-19 14:47:54,825 INFO org.apache.hadoop.yarn.server.resourcemanager.scheduler.fair.FairScheduler: allocate(appattempt_1471639269423_0004_000001 [] [] null null
2016-08-19 14:47:54,825 INFO org.apache.hadoop.yarn.server.resourcemanager.scheduler.fair.FSAppAttempt: appattempt_1471639269423_0004_000001 minReqResource: <memory:24576, vCores:12> flexibleResource: <memory:-8192, vCores:-4>
2016-08-19 14:47:54,825 INFO org.apache.hadoop.yarn.server.resourcemanager.scheduler.fair.FairScheduler: Cannot allocate resource to appattempt_1471639269423_0004_000001 because there is NO flexible resource left
2016-08-19 14:47:55,220 INFO org.apache.hadoop.yarn.server.resourcemanager.scheduler.fair.FairScheduler: allocate(appattempt_1471639269423_0003_000001 [] [] [] []
2016-08-19 14:47:55,220 INFO org.apache.hadoop.yarn.server.resourcemanager.scheduler.fair.FSAppAttempt: appattempt_1471639269423_0003_000001 minReqResource: <memory:24576, vCores:12> flexibleResource: <memory:-8192, vCores:-4>
2016-08-19 14:47:55,220 INFO org.apache.hadoop.yarn.server.resourcemanager.scheduler.fair.FairScheduler: Cannot allocate resource to appattempt_1471639269423_0003_000001 because there is NO flexible resource left
2016-08-19 14:47:55,308 INFO org.apache.hadoop.yarn.server.resourcemanager.scheduler.fair.FSAppAttempt: assignContainer(FSSchedulerNode node:c220g1-031106.wisc.cloudlab.us, boolean reserved=false) for appattempt_1471639269423_0003_000001
2016-08-19 14:47:55,309 INFO org.apache.hadoop.yarn.server.resourcemanager.scheduler.fair.FSAppAttempt: assignContainer(FSSchedulerNode node:c220g1-031106.wisc.cloudlab.us, boolean reserved=false) for appattempt_1471639269423_0005_000001
2016-08-19 14:47:55,309 INFO org.apache.hadoop.yarn.server.resourcemanager.scheduler.fair.FSAppAttempt: assignContainer(FSSchedulerNode node:c220g1-031106.wisc.cloudlab.us, boolean reserved=false) for appattempt_1471639269423_0004_000001
2016-08-19 14:47:55,309 INFO org.apache.hadoop.yarn.server.resourcemanager.scheduler.fair.FSAppAttempt: assignContainer(FSSchedulerNode node:c220g1-031106.wisc.cloudlab.us, boolean reserved=false) for appattempt_1471639269423_0006_000001
2016-08-19 14:47:55,309 INFO org.apache.hadoop.yarn.server.resourcemanager.scheduler.fair.FSAppAttempt: assignContainer(FSSchedulerNode node:c220g1-031106.wisc.cloudlab.us, boolean reserved=false) for appattempt_1471639269423_0007_000001
2016-08-19 14:47:55,314 INFO org.apache.hadoop.yarn.server.resourcemanager.rmapp.attempt.RMAppAttemptImpl: AMContainerAllocatedTransition.transition(appattempt_1471639269423_0005_000001,EventType: CONTAINER_ALLOCATED)
2016-08-19 14:47:55,314 INFO org.apache.hadoop.yarn.server.resourcemanager.scheduler.fair.FairScheduler: allocate(appattempt_1471639269423_0005_000001 [] [] null null
2016-08-19 14:47:55,314 INFO org.apache.hadoop.yarn.server.resourcemanager.scheduler.fair.FSAppAttempt: appattempt_1471639269423_0005_000001 minReqResource: <memory:24576, vCores:12> flexibleResource: <memory:-8192, vCores:-4>
2016-08-19 14:47:55,315 INFO org.apache.hadoop.yarn.server.resourcemanager.scheduler.fair.FairScheduler: Cannot allocate resource to appattempt_1471639269423_0005_000001 because there is NO flexible resource left
2016-08-19 14:47:55,326 INFO org.apache.hadoop.yarn.server.resourcemanager.rmapp.attempt.RMAppAttemptImpl: AMContainerAllocatedTransition.transition(appattempt_1471639269423_0004_000001,EventType: CONTAINER_ALLOCATED)
2016-08-19 14:47:55,326 INFO org.apache.hadoop.yarn.server.resourcemanager.scheduler.fair.FairScheduler: allocate(appattempt_1471639269423_0004_000001 [] [] null null
2016-08-19 14:47:55,326 INFO org.apache.hadoop.yarn.server.resourcemanager.scheduler.fair.FSAppAttempt: appattempt_1471639269423_0004_000001 minReqResource: <memory:24576, vCores:12> flexibleResource: <memory:-8192, vCores:-4>
2016-08-19 14:47:55,326 INFO org.apache.hadoop.yarn.server.resourcemanager.scheduler.fair.FairScheduler: Cannot allocate resource to appattempt_1471639269423_0004_000001 because there is NO flexible resource left
2016-08-19 14:47:55,335 INFO org.apache.hadoop.yarn.server.resourcemanager.scheduler.fair.FSAppAttempt: assignContainer(FSSchedulerNode node:cp-1.yarn-perf.yarnrm-PG0.wisc.cloudlab.us, boolean reserved=false) for appattempt_1471639269423_0003_000001
2016-08-19 14:47:55,335 INFO org.apache.hadoop.yarn.server.resourcemanager.scheduler.fair.FSAppAttempt: assignContainer(FSSchedulerNode node:cp-1.yarn-perf.yarnrm-PG0.wisc.cloudlab.us, boolean reserved=false) for appattempt_1471639269423_0005_000001
2016-08-19 14:47:55,335 INFO org.apache.hadoop.yarn.server.resourcemanager.scheduler.fair.FSAppAttempt: assignContainer(FSSchedulerNode node:cp-1.yarn-perf.yarnrm-PG0.wisc.cloudlab.us, boolean reserved=false) for appattempt_1471639269423_0004_000001
2016-08-19 14:47:55,335 INFO org.apache.hadoop.yarn.server.resourcemanager.scheduler.fair.FSAppAttempt: assignContainer(FSSchedulerNode node:cp-1.yarn-perf.yarnrm-PG0.wisc.cloudlab.us, boolean reserved=false) for appattempt_1471639269423_0006_000001
2016-08-19 14:47:55,335 INFO org.apache.hadoop.yarn.server.resourcemanager.scheduler.fair.FSAppAttempt: assignContainer(FSSchedulerNode node:cp-1.yarn-perf.yarnrm-PG0.wisc.cloudlab.us, boolean reserved=false) for appattempt_1471639269423_0007_000001
2016-08-19 14:47:55,815 INFO org.apache.hadoop.yarn.server.resourcemanager.rmapp.attempt.RMAppAttemptImpl: AMContainerAllocatedTransition.transition(appattempt_1471639269423_0005_000001,EventType: CONTAINER_ALLOCATED)
2016-08-19 14:47:55,815 INFO org.apache.hadoop.yarn.server.resourcemanager.scheduler.fair.FairScheduler: allocate(appattempt_1471639269423_0005_000001 [] [] null null
2016-08-19 14:47:55,816 INFO org.apache.hadoop.yarn.server.resourcemanager.scheduler.fair.FSAppAttempt: appattempt_1471639269423_0005_000001 minReqResource: <memory:24576, vCores:12> flexibleResource: <memory:-8192, vCores:-4>
2016-08-19 14:47:55,816 INFO org.apache.hadoop.yarn.server.resourcemanager.scheduler.fair.FairScheduler: Cannot allocate resource to appattempt_1471639269423_0005_000001 because there is NO flexible resource left
2016-08-19 14:47:55,827 INFO org.apache.hadoop.yarn.server.resourcemanager.rmapp.attempt.RMAppAttemptImpl: AMContainerAllocatedTransition.transition(appattempt_1471639269423_0004_000001,EventType: CONTAINER_ALLOCATED)
2016-08-19 14:47:55,827 INFO org.apache.hadoop.yarn.server.resourcemanager.scheduler.fair.FairScheduler: allocate(appattempt_1471639269423_0004_000001 [] [] null null
2016-08-19 14:47:55,827 INFO org.apache.hadoop.yarn.server.resourcemanager.scheduler.fair.FSAppAttempt: appattempt_1471639269423_0004_000001 minReqResource: <memory:24576, vCores:12> flexibleResource: <memory:-8192, vCores:-4>
2016-08-19 14:47:55,827 INFO org.apache.hadoop.yarn.server.resourcemanager.scheduler.fair.FairScheduler: Cannot allocate resource to appattempt_1471639269423_0004_000001 because there is NO flexible resource left
2016-08-19 14:47:56,024 INFO org.apache.hadoop.yarn.server.resourcemanager.scheduler.fair.FairScheduler: allocate(appattempt_1471639269423_0003_000001 [] [] [] []
2016-08-19 14:47:56,024 INFO org.apache.hadoop.yarn.server.resourcemanager.scheduler.fair.FSAppAttempt: appattempt_1471639269423_0003_000001 minReqResource: <memory:24576, vCores:12> flexibleResource: <memory:-8192, vCores:-4>
2016-08-19 14:47:56,024 INFO org.apache.hadoop.yarn.server.resourcemanager.scheduler.fair.FairScheduler: Cannot allocate resource to appattempt_1471639269423_0003_000001 because there is NO flexible resource left
2016-08-19 14:47:56,311 INFO org.apache.hadoop.yarn.server.resourcemanager.scheduler.fair.FSAppAttempt: assignContainer(FSSchedulerNode node:c220g1-031106.wisc.cloudlab.us, boolean reserved=false) for appattempt_1471639269423_0003_000001
2016-08-19 14:47:56,311 INFO org.apache.hadoop.yarn.server.resourcemanager.scheduler.fair.FSAppAttempt: assignContainer(FSSchedulerNode node:c220g1-031106.wisc.cloudlab.us, boolean reserved=false) for appattempt_1471639269423_0005_000001
2016-08-19 14:47:56,311 INFO org.apache.hadoop.yarn.server.resourcemanager.scheduler.fair.FSAppAttempt: assignContainer(FSSchedulerNode node:c220g1-031106.wisc.cloudlab.us, boolean reserved=false) for appattempt_1471639269423_0004_000001
2016-08-19 14:47:56,311 INFO org.apache.hadoop.yarn.server.resourcemanager.scheduler.fair.FSAppAttempt: assignContainer(FSSchedulerNode node:c220g1-031106.wisc.cloudlab.us, boolean reserved=false) for appattempt_1471639269423_0006_000001
2016-08-19 14:47:56,312 INFO org.apache.hadoop.yarn.server.resourcemanager.scheduler.fair.FSAppAttempt: assignContainer(FSSchedulerNode node:c220g1-031106.wisc.cloudlab.us, boolean reserved=false) for appattempt_1471639269423_0007_000001
2016-08-19 14:47:56,316 INFO org.apache.hadoop.yarn.server.resourcemanager.rmapp.attempt.RMAppAttemptImpl: AMContainerAllocatedTransition.transition(appattempt_1471639269423_0005_000001,EventType: CONTAINER_ALLOCATED)
2016-08-19 14:47:56,317 INFO org.apache.hadoop.yarn.server.resourcemanager.scheduler.fair.FairScheduler: allocate(appattempt_1471639269423_0005_000001 [] [] null null
2016-08-19 14:47:56,317 INFO org.apache.hadoop.yarn.server.resourcemanager.scheduler.fair.FSAppAttempt: appattempt_1471639269423_0005_000001 minReqResource: <memory:24576, vCores:12> flexibleResource: <memory:-8192, vCores:-4>
2016-08-19 14:47:56,317 INFO org.apache.hadoop.yarn.server.resourcemanager.scheduler.fair.FairScheduler: Cannot allocate resource to appattempt_1471639269423_0005_000001 because there is NO flexible resource left
2016-08-19 14:47:56,328 INFO org.apache.hadoop.yarn.server.resourcemanager.rmapp.attempt.RMAppAttemptImpl: AMContainerAllocatedTransition.transition(appattempt_1471639269423_0004_000001,EventType: CONTAINER_ALLOCATED)
2016-08-19 14:47:56,328 INFO org.apache.hadoop.yarn.server.resourcemanager.scheduler.fair.FairScheduler: allocate(appattempt_1471639269423_0004_000001 [] [] null null
2016-08-19 14:47:56,328 INFO org.apache.hadoop.yarn.server.resourcemanager.scheduler.fair.FSAppAttempt: appattempt_1471639269423_0004_000001 minReqResource: <memory:24576, vCores:12> flexibleResource: <memory:-8192, vCores:-4>
2016-08-19 14:47:56,328 INFO org.apache.hadoop.yarn.server.resourcemanager.scheduler.fair.FairScheduler: Cannot allocate resource to appattempt_1471639269423_0004_000001 because there is NO flexible resource left
2016-08-19 14:47:56,337 INFO org.apache.hadoop.yarn.server.resourcemanager.scheduler.fair.FSAppAttempt: assignContainer(FSSchedulerNode node:cp-1.yarn-perf.yarnrm-PG0.wisc.cloudlab.us, boolean reserved=false) for appattempt_1471639269423_0003_000001
2016-08-19 14:47:56,337 INFO org.apache.hadoop.yarn.server.resourcemanager.scheduler.fair.FSAppAttempt: assignContainer(FSSchedulerNode node:cp-1.yarn-perf.yarnrm-PG0.wisc.cloudlab.us, boolean reserved=false) for appattempt_1471639269423_0005_000001
2016-08-19 14:47:56,337 INFO org.apache.hadoop.yarn.server.resourcemanager.scheduler.fair.FSAppAttempt: assignContainer(FSSchedulerNode node:cp-1.yarn-perf.yarnrm-PG0.wisc.cloudlab.us, boolean reserved=false) for appattempt_1471639269423_0004_000001
2016-08-19 14:47:56,337 INFO org.apache.hadoop.yarn.server.resourcemanager.scheduler.fair.FSAppAttempt: assignContainer(FSSchedulerNode node:cp-1.yarn-perf.yarnrm-PG0.wisc.cloudlab.us, boolean reserved=false) for appattempt_1471639269423_0006_000001
2016-08-19 14:47:56,338 INFO org.apache.hadoop.yarn.server.resourcemanager.scheduler.fair.FSAppAttempt: assignContainer(FSSchedulerNode node:cp-1.yarn-perf.yarnrm-PG0.wisc.cloudlab.us, boolean reserved=false) for appattempt_1471639269423_0007_000001
2016-08-19 14:47:56,817 INFO org.apache.hadoop.yarn.server.resourcemanager.rmapp.attempt.RMAppAttemptImpl: AMContainerAllocatedTransition.transition(appattempt_1471639269423_0005_000001,EventType: CONTAINER_ALLOCATED)
2016-08-19 14:47:56,818 INFO org.apache.hadoop.yarn.server.resourcemanager.scheduler.fair.FairScheduler: allocate(appattempt_1471639269423_0005_000001 [] [] null null
2016-08-19 14:47:56,818 INFO org.apache.hadoop.yarn.server.resourcemanager.scheduler.fair.FSAppAttempt: appattempt_1471639269423_0005_000001 minReqResource: <memory:24576, vCores:12> flexibleResource: <memory:-8192, vCores:-4>
2016-08-19 14:47:56,818 INFO org.apache.hadoop.yarn.server.resourcemanager.scheduler.fair.FairScheduler: Cannot allocate resource to appattempt_1471639269423_0005_000001 because there is NO flexible resource left
2016-08-19 14:47:56,829 INFO org.apache.hadoop.yarn.server.resourcemanager.rmapp.attempt.RMAppAttemptImpl: AMContainerAllocatedTransition.transition(appattempt_1471639269423_0004_000001,EventType: CONTAINER_ALLOCATED)
2016-08-19 14:47:56,829 INFO org.apache.hadoop.yarn.server.resourcemanager.scheduler.fair.FairScheduler: allocate(appattempt_1471639269423_0004_000001 [] [] null null
2016-08-19 14:47:56,829 INFO org.apache.hadoop.yarn.server.resourcemanager.scheduler.fair.FSAppAttempt: appattempt_1471639269423_0004_000001 minReqResource: <memory:24576, vCores:12> flexibleResource: <memory:-8192, vCores:-4>
2016-08-19 14:47:56,829 INFO org.apache.hadoop.yarn.server.resourcemanager.scheduler.fair.FairScheduler: Cannot allocate resource to appattempt_1471639269423_0004_000001 because there is NO flexible resource left
2016-08-19 14:47:57,314 INFO org.apache.hadoop.yarn.server.resourcemanager.scheduler.fair.FSAppAttempt: assignContainer(FSSchedulerNode node:c220g1-031106.wisc.cloudlab.us, boolean reserved=false) for appattempt_1471639269423_0003_000001
2016-08-19 14:47:57,315 INFO org.apache.hadoop.yarn.server.resourcemanager.scheduler.fair.FSAppAttempt: assignContainer(FSSchedulerNode node:c220g1-031106.wisc.cloudlab.us, boolean reserved=false) for appattempt_1471639269423_0005_000001
2016-08-19 14:47:57,315 INFO org.apache.hadoop.yarn.server.resourcemanager.scheduler.fair.FSAppAttempt: assignContainer(FSSchedulerNode node:c220g1-031106.wisc.cloudlab.us, boolean reserved=false) for appattempt_1471639269423_0004_000001
2016-08-19 14:47:57,315 INFO org.apache.hadoop.yarn.server.resourcemanager.scheduler.fair.FSAppAttempt: assignContainer(FSSchedulerNode node:c220g1-031106.wisc.cloudlab.us, boolean reserved=false) for appattempt_1471639269423_0006_000001
2016-08-19 14:47:57,315 INFO org.apache.hadoop.yarn.server.resourcemanager.scheduler.fair.FSAppAttempt: assignContainer(FSSchedulerNode node:c220g1-031106.wisc.cloudlab.us, boolean reserved=false) for appattempt_1471639269423_0007_000001
2016-08-19 14:47:57,318 INFO org.apache.hadoop.yarn.server.resourcemanager.rmapp.attempt.RMAppAttemptImpl: AMContainerAllocatedTransition.transition(appattempt_1471639269423_0005_000001,EventType: CONTAINER_ALLOCATED)
2016-08-19 14:47:57,318 INFO org.apache.hadoop.yarn.server.resourcemanager.scheduler.fair.FairScheduler: allocate(appattempt_1471639269423_0005_000001 [] [] null null
2016-08-19 14:47:57,319 INFO org.apache.hadoop.yarn.server.resourcemanager.scheduler.fair.FSAppAttempt: appattempt_1471639269423_0005_000001 minReqResource: <memory:24576, vCores:12> flexibleResource: <memory:-8192, vCores:-4>
2016-08-19 14:47:57,319 INFO org.apache.hadoop.yarn.server.resourcemanager.scheduler.fair.FairScheduler: Cannot allocate resource to appattempt_1471639269423_0005_000001 because there is NO flexible resource left
2016-08-19 14:47:57,330 INFO org.apache.hadoop.yarn.server.resourcemanager.rmapp.attempt.RMAppAttemptImpl: AMContainerAllocatedTransition.transition(appattempt_1471639269423_0004_000001,EventType: CONTAINER_ALLOCATED)
2016-08-19 14:47:57,330 INFO org.apache.hadoop.yarn.server.resourcemanager.scheduler.fair.FairScheduler: allocate(appattempt_1471639269423_0004_000001 [] [] null null
2016-08-19 14:47:57,330 INFO org.apache.hadoop.yarn.server.resourcemanager.scheduler.fair.FSAppAttempt: appattempt_1471639269423_0004_000001 minReqResource: <memory:24576, vCores:12> flexibleResource: <memory:-8192, vCores:-4>
2016-08-19 14:47:57,330 INFO org.apache.hadoop.yarn.server.resourcemanager.scheduler.fair.FairScheduler: Cannot allocate resource to appattempt_1471639269423_0004_000001 because there is NO flexible resource left
2016-08-19 14:47:57,339 INFO org.apache.hadoop.yarn.server.resourcemanager.scheduler.fair.FSAppAttempt: assignContainer(FSSchedulerNode node:cp-1.yarn-perf.yarnrm-PG0.wisc.cloudlab.us, boolean reserved=false) for appattempt_1471639269423_0003_000001
2016-08-19 14:47:57,339 INFO org.apache.hadoop.yarn.server.resourcemanager.scheduler.fair.FSAppAttempt: assignContainer(FSSchedulerNode node:cp-1.yarn-perf.yarnrm-PG0.wisc.cloudlab.us, boolean reserved=false) for appattempt_1471639269423_0005_000001
2016-08-19 14:47:57,339 INFO org.apache.hadoop.yarn.server.resourcemanager.scheduler.fair.FSAppAttempt: assignContainer(FSSchedulerNode node:cp-1.yarn-perf.yarnrm-PG0.wisc.cloudlab.us, boolean reserved=false) for appattempt_1471639269423_0004_000001
2016-08-19 14:47:57,340 INFO org.apache.hadoop.yarn.server.resourcemanager.scheduler.fair.FSAppAttempt: assignContainer(FSSchedulerNode node:cp-1.yarn-perf.yarnrm-PG0.wisc.cloudlab.us, boolean reserved=false) for appattempt_1471639269423_0006_000001
2016-08-19 14:47:57,340 INFO org.apache.hadoop.yarn.server.resourcemanager.scheduler.fair.FSAppAttempt: assignContainer(FSSchedulerNode node:cp-1.yarn-perf.yarnrm-PG0.wisc.cloudlab.us, boolean reserved=false) for appattempt_1471639269423_0007_000001
2016-08-19 14:47:57,628 INFO org.apache.hadoop.yarn.server.resourcemanager.scheduler.fair.FairScheduler: allocate(appattempt_1471639269423_0003_000001 [] [] [] []
2016-08-19 14:47:57,628 INFO org.apache.hadoop.yarn.server.resourcemanager.scheduler.fair.FSAppAttempt: appattempt_1471639269423_0003_000001 minReqResource: <memory:24576, vCores:12> flexibleResource: <memory:-8192, vCores:-4>
2016-08-19 14:47:57,628 INFO org.apache.hadoop.yarn.server.resourcemanager.scheduler.fair.FairScheduler: Cannot allocate resource to appattempt_1471639269423_0003_000001 because there is NO flexible resource left
2016-08-19 14:47:57,819 INFO org.apache.hadoop.yarn.server.resourcemanager.rmapp.attempt.RMAppAttemptImpl: AMContainerAllocatedTransition.transition(appattempt_1471639269423_0005_000001,EventType: CONTAINER_ALLOCATED)
2016-08-19 14:47:57,819 INFO org.apache.hadoop.yarn.server.resourcemanager.scheduler.fair.FairScheduler: allocate(appattempt_1471639269423_0005_000001 [] [] null null
2016-08-19 14:47:57,819 INFO org.apache.hadoop.yarn.server.resourcemanager.scheduler.fair.FSAppAttempt: appattempt_1471639269423_0005_000001 minReqResource: <memory:24576, vCores:12> flexibleResource: <memory:-8192, vCores:-4>
